Workbook

Sheet 推广目标
A1: SKU：R0001EU ASIN：AXXX | I1: 关键词
A3: 上架销售时间： | B3: 45765
A4: 推广周期： | B4: 4月20日-6月31日 | I4: 关键词 | J4: 关键词翻译 | K4: 流量占比 | L4: 预估周曝光量 | M4: 关键词类型 | N4: 转化效果自然流量占比
A5: 排名目标： | B5: X #50 | K5: 0.497508 | L5: 13984 | M5: 主要流量词 | N5: 0.3471
A6: 目标销量： | B6: 25-50pcs/天 | K6: 0.294441 | L6: 8276 | M6: 主要流量词 | N6: 0.41862
K7: 0.059295 | L7: 1667 | N7: 0.61722
K8: 0.047246 | L8: 1328 | N8: 0.80955
K9: 0.02472 | L9: 695 | N9: 0.46301
A10: 目标管理 | B10: 目标 | C10: ASIN 1 | K10: 0.019301 | L10: 543 | N10: 0.06106
A11: 对标竞品 | B11: B0DXXX | C11: B0DXXX | K11: 0.017954 | L11: 505 | M11: 精准长尾词 | N11: 0.50632
A12: 目标排名 | B12: 21-24 | K12: 0.008428 | L12: 237 | N12: 0.28778
A13: 目标日销 | B13: 10-15 日销 | K13: 0.007424 | L13: 209 | N13: 15
A14: 价格 | B14: 109-129.99 | K14: 0.002209 | L14: 62 | M14: 、 | N14: 16
A15: rating | B15: 136 | K15: 0.001316 | L15: 37 | M15: 、 | N15: 6
A16: 评分 | B16: 4.7
A17: 主推词 | B17: 222
D20: 广泛 | E20: 词组 | F20: 精准
A21: 核心关键词 选取， | D21: 1.33 | E21: 1.2 | F21: 1.23
D22: 1.39 | E22: 1.24 | F22: 1.29
D23: 1.33 | E23: 1.2 | F23: 1.21
D24: 1.36 | E24: 1.22 | F24: 1.28
D25: 1.29 | E25: 1.16 | F25: 1.21
D26: 1.33 | E26: 1.2 | F26: 1.23
D27: 1.47 | E27: 1.3 | F27: 1.36
D28: 1.65 | E28: 1.33 | F28: 2.01
A29: 长尾词 选取
D30: 1.39 | E30: 1.2 | F30: 1.23
D31: 0.64 | E31: 0.58 | F31: 0.63
D32: 1.29 | E32: 1.16 | F32: 1.21
D33: 1.08 | E33: 0.97 | F33: 1.01
A35: 蓝海词 | D35: 1.01 | E35: 0.94 | F35: 0.89
A39: 关键词 | B39: 关键词翻译 | C39: 流量占比 | D39: 预估周曝光量 | E39: 关键词类型 | F39: 转化效果自然流量占比
C40: 0.497508 | D40: 13984 | E40: 主要流量词 | F40: 0.3471
C41: 0.294441 | D41: 8276 | E41: 主要流量词 | F41: 0.41862
C42: 0.059295 | D42: 1667 | F42: 0.61722
C43: 0.047246 | D43: 1328 | F43: 0.80955
C44: 0.02472 | D44: 695 | F44: 0.46301
C45: 0.019301 | D45: 543 | F45: 0.06106
C46: 0.017954 | D46: 505 | E46: 精准长尾词 | F46: 0.50632
C47: 0.008428 | D47: 237 | F47: 0.28778
...

Sheet 推广计划
A1: WEEK | B1: Date | C1: SKU | D1: 售价 | E1: COUPON | F1: Action | G1: 目标平均日销 | H1: 周销 | I1: 目标排名 | J1: Review星级/数量 | K1: REVIEW计划 | M1: 周消耗库存 | N1: 销售额 | O1: 日均流量 | P1: 转化率 | Q1: 主关键词自然搜索排名 | R1: 广告计划 | X1: 库存计划
K2: 送出数量 | L2: 措施 | R2: 广告日预算 | S2: 每日点击 | T2: CPC | U2: CVR | V2: 广告日订单 | W2: 广告订单占比 | Z2: LBS库存 | AA2: SZ | AB2: LBS在途 | AC2: LBS发货 | AD2: 采购计划
A3: WEEK1 | B3: 4.18-4.25 | C3: R0001EU | D3: 109.99 | E3: 20 | F3: 10 coupon+广告 | G3: =M3/7 -> 6.2857143 | H3: =G3*7 -> 44 | I3: 60 | J3: 4.7 | K3: 首单测评1单5星 | L3: 直评 10个 | M3: 44 | N3: =D3*H3 -> 4839.56 | O3: 66 | P3: =G3/O3 -> 0.095238095 | Q3: 主推关键词：111r,222 目标：第5页 | R3: =T3*S3 -> 48 | S3: =V3/U3 -> 40 | T3: 1.2 | U3: 0.11 | V3: =G3*W3 -> 4.4 | W3: 0.7 | X3: 1200 | Y3: 0 | Z3: 0 | AA3: 1310 | AB3: 2490海运
A4: WEEK2 | B4: 4.26-5.2 | C4: R0001EU | D4: 109.99 | E4: 20 | F4: coupon+广告 | G4: =M4/7 -> 11.571429 | H4: =G4*7 -> 81 | I4: 40 | J4: 4.7 | K4: 绿标10个 | L4: 直评补 3-5个 | M4: 81 | N4: =D4*H4 -> 8909.19 | O4: 88 | P4: =G4/O4 -> 0.13149351 | Q4: 主推关键词：1122 目标：第4页 | R4: =T4*S4 -> 75.214286 | S4: =V4/U4 -> 62.678571 | T4: 1.2 | U4: 0.12 | V4: =G4*W4 -> 7.5214286 | W4: 0.65 | X4: =X3-H3 -> 1156 | Y4: 0 | Z4: 0 | AA4: 1310 | AB4: 2490
A5: WEEK3 | B5: 5.3-5.9 | C5: R0001EU | D5: 109.99 | E5: 20 | F5: coupon+广告 | G5: =M5/7 -> 7.8571429 | H5: =G5*7 -> 55 | I5: 30 | J5: 4.7 | M5: 55 | N5: =D5*H5 -> 6049.45 | O5: 60 | P5: =G5/O5 -> 0.13095238 | Q5: 主推关键词：1122 目标：第3页 | R5: =T5*S5 -> 39.89011 | S5: =V5/U5 -> 36.263736 | T5: 1.1 | U5: 0.13 | V5: =G5*W5 -> 4.7142857 | W5: 0.6 | X5: =X4-H4 -> 1075 | Y5: 0 | Z5: 2490 | AA5: 0 | AB5: 1310卡派 | AC5: 720至TT 600至RUI备用
A6: WEEK4 | B6: 5.10-5.16 | C6: R0001EU | D6: 109.99 | E6: 20 | F6: 10 coupon+7DD+加大广告投放 | G6: =M6/7 -> 6.8571429 | H6: =G6*7 -> 48 | I6: 20 | J6: 4.6 | M6: 48 | N6: =D6*H6 -> 5279.52 | O6: 50 | P6: =G6/O6 -> 0.13714286 | Q6: 主推关键词：1122 目标：第3页 | R6: =T6*S6 -> 25.142857 | S6: =V6/U6 -> 22.857143 | T6: 1.1 | U6: 0.15 | V6: =G6*W6 -> 3.4285714 | W6: 0.5 | X6: =X5-H5+720 -> 1740 | Y6: 600 | Z6: 1170 | AA6: 0 | AB6: 1310 | AD6: 1500
A7: WEEK5 | B7: 5.17-5.23 | C7: R0001EU | D7: 119.99 | E7: 10 | F7: coupon+广告 | G7: =M7/7 -> 7.4285714 | H7: =G7*7 -> 52 | I7: 28 | J7: 4.6 | M7: 52 | N7: =D7*H7 -> 6239.48 | O7: 56 | P7: =G7/O7 -> 0.13265306 | Q7: 主推关键词：1122 目标：第2页 | R7: =T7*S7 -> 27.238095 | S7: =V7/U7 -> 27.238095 | T7: 1 | U7: 0.15 | V7: =G7*W7 -> 4.0857143 | W7: 0.55 | X7: =X6-H6 -> 1692 | Y7: 600 | Z7: 1170 | AA7: 0 | AB7: 1310
A8: WEEK6 | B8: 5.24-5.30 | C8: R0001EU | D8: 119.99 | E8: 10 | F8: coupon+广告 | G8: =M8/7 -> 7.1428571 | H8: =G8*7 -> 50 | I8: 26 | J8: 4.6 | M8: 50 | N8: =D8*H8 -> 5999.5 | O8: 60 | P8: =G8/O8 -> 0.11904762 | Q8: 主推关键词：1122 目标：第2页 | R8: =T8*S8 -> 23.809524 | S8: =V8/U8 -> 23.809524 | T8: 1 | U8: 0.15 | V8: =G8*W8 -> 3.5714286 | W8: 0.5 | X8: =X7-H7 -> 1640 | Y8: 600 | Z8: 1170 | AA8: 0 | AB8: 1310 | AC8: 900至TT
A9: WEEK7 | B9: 5.31-6.6 | C9: R0001EU | D9: 119.99 | E9: 10 | F9: 7DD+加大广告投放 | G9: =M9/7 -> 8.2857143 | H9: =G9*7 -> 58 | I9: 20 | J9: 4.6 | M9: 58 | N9: =D9*H9 -> 6959.42 | O9: 68 | P9: =G9/O9 -> 0.12184874 | Q9: 主推关键词：1122 目标：第2页 | R9: =T9*S9 -> 18.642857 | S9: =V9/U9 -> 20.714286 | T9: 0.9 | U9: 0.16 | V9: =G9*W9 -> 3.3142857 | W9: 0.4 | X9: =X8-H8+900 -> 2490 | Y9: 600 | Z9: =Z8-900 -> 270 | AA9: 0 | AB9: 1310 | AD9: 1980(PD)
A10: WEEK8 | B10: 6.7-6.13 | C10: R0001EU | D10: 119.99 | E10: 10 | F10: coupon+广告 | G10: =M10/7 -> 7.1428571 | H10: =G10*7 -> 50 | I10: 25 | J10: 4.6 | M10: 50 | N10: =D10*H10 -> 5999.5 | O10: 68 | P10: =G10/O10 -> 0.10504202 | Q10: 主推关键词：1122 目标：第1页 | R10: =T10*S10 -> 18.080357 | S10: =V10/U10 -> 20.089286 | T10: 0.9 | U10: 0.16 | V10: =G10*W10 -> 3.2142857 | W10: 0.45 | X10: =X9-H9 -> 2432 | Y10: 600 | Z10: 1580 | AA10: 1500 | AB10: 0 | AC10: 900至TT
A11: WEEK9 | B11: 6.14-6.20 | C11: R0001EU | D11: 119.99 | E11: 10 | F11: coupon+广告 | G11: =M11/7 -> 7.8571429 | H11: =G11*7 -> 55 | I11: 24 | J11: 4.6 | M11: 55 | N11: =D11*H11 -> 6599.45 | O11: 70 | P11: =G11/O11 -> 0.1122449 | Q11: 主推关键词：1122 目标：第1页 | R11: =T11*S11 -> 17.678571 | S11: =V11/U11 -> 19.642857 | T11: 0.9 | U11: 0.16 | V11: =G11*W11 -> 3.1428571 | W11: 0.4 | X11: =X10-H10+900 -> 3282 | Y11: 600 | Z11: 680 | AA11: 0 | AB11: 1500卡派 | AD11: 2100
A12: WEEK10 | B12: 6.21-6.27 | C12: R0001EU | D12: 119.99 | E12: 10 | F12: 7DD+加大广告投放 | G12: =M12/7 -> 9.2857143 | H12: =G12*7 -> 65 | I12: 20 | J12: 4.6 | M12: 65 | N12: =D12*H12 -> 7799.35 | O12: 75 | P12: =G12/O12 -> 0.12380952 | Q12: 主推关键词：1122 目标：第1页 | R12: =T12*S12 -> 18.28125 | S12: =V12/U12 -> 20.3125 | T12: 0.9 | U12: 0.16 | V12: =G12*W12 -> 3.25 | W12: 0.35 | X12: =X11-H11 -> 3227 | Y12: 600 | Z12: 680 | AA12: 0 | AB12: 1500 | AC12: 680至TT
A13: WEEK11 | B13: 6.28-7.4 | C13: R0001EU | D13: 119.99 | E13: 10 | F13: coupon+广告 | G13: =M13/7 -> 10.285714 | H13: =G13*7 -> 72 | I13: 22 | J13: 4.6 | M13: 72 | N13: =D13*H13 -> 8639.28 | O13: 75 | P13: =G13/O13 -> 0.13714286 | Q13: 主推关键词：1122 目标：第1页 | R13: =T13*S13 -> 20.25 | S13: =V13/U13 -> 22.5 | T13: 0.9 | U13: 0.16 | V13: =G13*W13 -> 3.6 | W13: 0.35 | X13: =X12-H12+680 -> 3842 | Y13: 600 | Z13: 0 | AA13: 1980 | AB13: 1500
A14: WEEK12 | B14: 7.5-7.11 | C14: R0001EU | D14: 119.99 | E14: 10 | F14: coupon+广告 | G14: =M14/7 -> 10.714286 | H14: =G14*7 -> 75 | I14: 21 | J14: 4.6 | M14: 75 | N14: =D14*H14 -> 8999.25 | O14: 75 | P14: =G14/O14 -> 0.14285714 | Q14: 主推关键词：1122 目标：第1页 | R14: =T14*S14 -> 18.080357 | S14: =V14/U14 -> 20.089286 | T14: 0.9 | U14: 0.16 | V14: =G14*W14 -> 3.2142857 | W14: 0.3 | X14: 1355 | Y14: =Y13-H13 -> 528 | Z14: 1500 | AA14: 0 | AB14: 1980卡派 | AE14: 切换到RUI卖
A15: WEEK13 | B15: 7.12-7.18 | C15: R0001EU | D15: 119.99 | E15: 10 | F15: 7DD+加大广告投放 | G15: =M15/7 -> 11.428571 | H15: =G15*7 -> 80 | I15: 20 | J15: 4.6 | M15: 80 | N15: =D15*H15 -> 9599.2 | O15: 75 | P15: =G15/O15 -> 0.15238095 | Q15: 主推关键词：1122 目标：第1页 | R15: =T15*S15 -> 18.151261 | S15: =V15/U15 -> 20.168067 | T15: 0.9 | U15: 0.17 | V15: =G15*W15 -> 3.4285714 | W15: 0.3 | X15: =X14-H14 -> 1280 | Y15: 264 | Z15: 1500 | AA15: 2100 | AB15: 1980
A16: WEEK14 | B16: 7.19-7.25 | C16: R0001EU | D16: 119.99 | E16: 0.1 | F16: 7DD+加大广告投放 | G16: =M16/7 -> 12.142857 | H16: =G16*7 -> 85 | I16: 20 | J16: 4.6 | M16: 85 | N16: =D16*H16 -> 10199.15 | O16: 75 | P16: =G16/O16 -> 0.16190476 | Q16: 主推关键词：1122 目标：第1页 | R16: =T16*S16 -> 19.285714 | S16: =V16/U16 -> 21.428571 | T16: 0.9 | U16: 0.17 | V16: =G16*W16 -> 3.6428571 | W16: 0.3 | X16: =X15-H15 -> 1200 | Y16: 264 | Z16: 1500 | AA16: 2100 | AB16: 1980
A17: WEEK15 | B17: 7.26--8.2 | C17: R0001EU | D17: 119.99 | E17: 0.1 | F17: 7DD+加大广告投放 | G17: =M17/7 -> 13.571429 | H17: =G17*7 -> 95 | I17: 20 | J17: 4.6 | M17: 95 | N17: =D17*H17 -> 11399.05 | O17: 80 | P17: =G17/O17 -> 0.16964286 | Q17: 主推关键词：1122 目标：第1页 | R17: =T17*S17 -> 21.554622 | S17: =V17/U17 -> 23.94958 | T17: 0.9 | U17: 0.17 | V17: =G17*W17 -> 4.0714286 | W17: 0.3 | X17: =X16-H16 -> 1115 | Y17: 264 | Z17: 1500 | AA17: 2100 | AB17: 1980
A18: WEEK16 | B18: 8.3-8.9 | C18: R0001EU | D18: 119.99 | E18: 0.1 | F18: 7DD+加大广告投放 | G18: =M18/7 -> 14.285714 | H18: =G18*7 -> 100 | I18: 20 | J18: 4.6 | M18: 100 | N18: =D18*H18 -> 11999 | O18: 80 | P18: =G18/O18 -> 0.17857143 | Q18: 主推关键词：1122 目标：第1页 | R18: =T18*S18 -> 22.689076 | S18: =V18/U18 -> 25.210084 | T18: 0.9 | U18: 0.17 | V18: =G18*W18 -> 4.2857143 | W18: 0.3 | X18: =X17-H17 -> 1020 | Y18: 264 | Z18: 1500 | AA18: 2100 | AB18: 1980
A19: WEEK17 | B19: 8.10-8.16 | C19: R0001EU | D19: 119.99 | E19: 0.1 | F19: 7DD+加大广告投放 | G19: =M19/7 -> 11.428571 | H19: =G19*7 -> 80 | I19: 20 | J19: 4.6 | M19: 80 | N19: =D19*H19 -> 9599.2 | O19: 80 | P19: =G19/O19 -> 0.14285714 | Q19: 主推关键词：1122 目标：第1页 | R19: =T19*S19 -> 18.151261 | S19: =V19/U19 -> 20.168067 | T19: 0.9 | U19: 0.17 | V19: =G19*W19 -> 3.4285714 | W19: 0.3 | X19: =X18-H18 -> 920 | Y19: 264 | Z19: 1500 | AA19: 2100 | AB19: 1980
A20: WEEK18 | B20: 8.17-8.23 | C20: R0001EU | D20: 119.99 | E20: 0.1 | F20: 7DD+加大广告投放 | G20: =M20/7 -> 8.5714286 | H20: =G20*7 -> 60 | I20: 20 | J20: 4.6 | M20: 60 | N20: =D20*H20 -> 7199.4 | O20: 60 | P20: =G20/O20 -> 0.14285714 | Q20: 主推关键词：1122 目标：第1页 | R20: =T20*S20 -> 13.613445 | S20: =V20/U20 -> 15.12605 | T20: 0.9 | U20: 0.17 | V20: =G20*W20 -> 2.5714286 | W20: 0.3 | X20: =X19-H19 -> 840 | Y20: 264 | Z20: 1500 | AA20: 2100 | AB20: 1980
A21: WEEK19 | B21: 8.24-8.30 | C21: R0001EU | D21: 119.99 | E21: 0.1 | F21: 7DD+加大广告投放 | G21: =M21/7 -> 9.2857143 | H21: =G21*7 -> 65 | I21: 20 | J21: 4.6 | M21: 65 | N21: =D21*H21 -> 7799.35 | O21: 60 | P21: =G21/O21 -> 0.1547619 | Q21: 主推关键词：1122 目标：第1页 | R21: =T21*S21 -> 14.747899 | S21: =V21/U21 -> 16.386555 | T21: 0.9 | U21: 0.17 | V21: =G21*W21 -> 2.7857143 | W21: 0.3 | X21: =X20-H20 -> 780 | Y21: 264 | Z21: 1500 | AA21: 2100 | AB21: 1980
A22: WEEK20 | B22: 8.24-8.30 | C22: R0001EU | D22: 119.99 | E22: 0.1 | F22: 7DD+加大广告投放 | G22: =M22/7 -> 10.714286 | H22: =G22*7 -> 75 | I22: 20 | J22: 4.6 | M22: 75 | N22: =D22*H22 -> 8999.25 | O22: 60 | P22: =G22/O22 -> 0.17857143 | Q22: 主推关键词：1122 目标：第1页 | R22: =T22*S22 -> 13.5 | S22: 15 | T22: 0.9 | U22: 0.17 | V22: 2 | W22: 0.3 | X22: =X21-H21 -> 715 | Y22: 264 | Z22: 1500 | AA22: 2100 | AB22: 1980
A23: WEEK21 | B23: 8.24-8.30 | C23: R0001EU | D23: 119.99 | E23: 0.1 | F23: 7DD+加大广告投放 | G23: =M23/7 -> 11.428571 | H23: =G23*7 -> 80 | I23: 20 | J23: 4.6 | M23: 80 | N23: =D23*H23 -> 9599.2 | O23: 60 | P23: =G23/O23 -> 0.19047619 | Q23: 主推关键词：1122 目标：第1页 | R23: =T23*S23 -> 13.5 | S23: 15 | T23: 0.9 | U23: 0.17 | V23: 2 | W23: 0.3 | X23: =X22-H22 -> 640 | Y23: 264 | Z23: 1500 | AA23: 2100 | AB23: 1980
A24: WEEK22 | B24: 8.24-8.30 | C24: R0001EU | D24: 119.99 | E24: 0.1 | F24: 7DD+加大广告投放 | G24: =M24/7 -> 12.857143 | H24: =G24*7 -> 90 | I24: 20 | J24: 4.6 | M24: 90 | N24: =D24*H24 -> 10799.1 | O24: 60 | P24: =G24/O24 -> 0.21428571 | Q24: 主推关键词：1122 目标：第1页 | R24: =T24*S24 -> 13.5 | S24: 15 | T24: 0.9 | U24: 0.17 | V24: 2 | W24: 0.3 | X24: =X23-H23 -> 560 | Y24: 264 | Z24: 1500 | AA24: 2100 | AB24: 1980
A25: WEEK23 | B25: 8.24-8.30 | C25: R0001EU | D25: 119.99 | E25: 0.1 | F25: 7DD+加大广告投放 | G25: =M25/7 -> 13.571429 | H25: =G25*7 -> 95 | I25: 20 | J25: 4.6 | M25: 95 | N25: =D25*H25 -> 11399.05 | O25: 60 | P25: =G25/O25 -> 0.22619048 | Q25: 主推关键词：1122 目标：第1页 | R25: =T25*S25 -> 13.5 | S25: 15 | T25: 0.9 | U25: 0.17 | V25: 2 | W25: 0.3 | X25: =X24-H24 -> 470 | Y25: 264 | Z25: 1500 | AA25: 2100 | AB25: 1980
A26: WEEK24 | B26: 8.24-8.30 | C26: R0001EU | D26: 119.99 | E26: 0.1 | F26: 7DD+加大广告投放 | G26: =M26/7 -> 14.285714 | H26: =G26*7 -> 100 | I26: 20 | J26: 4.6 | M26: 100 | N26: =D26*H26 -> 11999 | O26: 60 | P26: =G26/O26 -> 0.23809524 | Q26: 主推关键词：1122 目标：第1页 | R26: =T26*S26 -> 13.5 | S26: 15 | T26: 0.9 | U26: 0.17 | V26: 2 | W26: 0.3 | X26: =X25-H25 -> 375 | Y26: 264 | Z26: 1500 | AA26: 2100 | AB26: 1980
A27: WEEK25 | B27: 8.24-8.30 | C27: R0001EU | D27: 119.99 | E27: 0.1 | F27: 7DD+加大广告投放 | G27: =M27/7 -> 17.142857 | H27: =G27*7 -> 120 | I27: 20 | J27: 4.6 | M27: 120 | N27: =D27*H27 -> 14398.8 | O27: 60 | P27: =G27/O27 -> 0.28571429 | Q27: 主推关键词：1122 目标：第1页 | R27: =T27*S27 -> 13.5 | S27: 15 | T27: 0.9 | U27: 0.17 | V27: 2 | W27: 0.3 | X27: =X26-H26 -> 275 | Y27: 264 | Z27: 1500 | AA27: 2100 | AB27: 1980
A28: WEEK25 | B28: 8.24-8.30 | C28: R0001EU | D28: 119.99 | E28: 0.1 | F28: 7DD+加大广告投放 | G28: =M28/7 -> 17.142857 | H28: =G28*7 -> 120 | I28: 20 | J28: 4.6 | M28: 120 | N28: =D28*H28 -> 14398.8 | O28: 60 | P28: =G28/O28 -> 0.28571429 | Q28: 主推关键词：1122 目标：第1页 | R28: =T28*S28 -> 13.5 | S28: 15 | T28: 0.9 | U28: 0.17 | V28: 2 | W28: 0.3 | X28: =X27-H27 -> 155 | Y28: 264 | Z28: 1500 | AA28: 2100 | AB28: 1980
A29: WEEK25 | B29: 8.24-8.30 | C29: R0001EU | D29: 119.99 | E29: 0.1 | F29: 7DD+加大广告投放 | G29: =M29/7 -> 17.142857 | H29: =G29*7 -> 120 | I29: 20 | J29: 4.6 | M29: 120 | N29: =D29*H29 -> 14398.8 | O29: 60 | P29: =G29/O29 -> 0.28571429 | Q29: 主推关键词：1122 目标：第1页 | R29: =T29*S29 -> 13.5 | S29: 15 | T29: 0.9 | U29: 0.17 | V29: 2 | W29: 0.3 | X29: =X28-H28 -> 35 | Y29: 264 | Z29: 1500 | AA29: 2100 | AB29: 1980

Sheet 广告计划
A1: 预估量说明： 平均cpc和转化率的值的预估方法： 1.市场调研得到同行平均cpc的基础上适当上调； 2.正在做的同品类商品的历史cpc基础上适当上调； 平均cpc和转化率计划制定的说明： 新品期间波动大，采用梯度预估 eg:当cpc为2.5$,转化率为5%的时候，完成日销目标对应的广告费为105$/天； 当cpc为2.3$.转化率为7%的时候，完成日销目标对应的广告费为69$/天
A10: WEEK | B10: Date | C10: 售价 | D10: 目标平均日销 | E10: 销售额 | F10: 转化率 | G10: 日均流量 | H10: 广告销量 | I10: 广告销售额 | J10: 广告订单占比 | K10: 广告费 | L10: 点击量 | M10: 预估量 | O10: 广告结构 | P10: 广告目标及关注指标 | Q10: 广告关键词 | R10: 不同广告类型预算分配
L11: 点击量 | M11: 平均cpc | N11: 广告转化率
A12: WEEK1 | B12: 4.28-5.6 | C12: =推广计划!D3 -> 109.99 | D12: =推广计划!G3 -> 6.2857143 | E12: =C12*D12*7 -> 4839.56 | F12: =推广计划!P3 -> 0.095238095 | G12: =D12/F12 -> 66 | H12: =D12*J12 -> 4.4 | I12: =H12*C12 -> 483.956 | J12: 0.7 | K12: =L12*M12 -> 48 | L12: =$H$12/N12 -> 40 | M12: =推广计划!T3 -> 1.2 | N12: =推广计划!U3 -> 0.11 | O12: campaign1：自动广告 campaign2：手动广告测试组B campaign3：SD-categories campaign4：PT campaign5：手动广告核心关键词E | P12: 有效流量引入 点击率；转化率；订单量
K13: =L13*M13 -> 48 | L13: =$H$12/N13 -> 40 | M13: =推广计划!T3 -> 1.2 | N13: =推广计划!U3 -> 0.11
K14: =L14*M14 -> 48 | L14: =$H$12/N14 -> 40 | M14: =推广计划!T3 -> 1.2 | N14: =推广计划!U3 -> 0.11
K15: =L15*M15 -> 48 | L15: =$H$12/N15 -> 40 | M15: =推广计划!T3 -> 1.2 | N15: =推广计划!U3 -> 0.11
A16: WEEK2 | B16: 5.7-5.13 | C16: =推广计划!D4 -> 109.99 | D16: =推广计划!G4 -> 11.571429 | E16: =C16*D16*7 -> 8909.19 | F16: =推广计划!P4 -> 0.13149351 | G16: =D16/F16 -> 88 | H16: =D16*J16 -> 7.5214286 | I16: =H16*C16 -> 827.28193 | J16: 0.65 | K16: =L16*M16 -> 75.214286 | L16: =$H$16/N16 -> 62.678571 | M16: =推广计划!T4 -> 1.2 | N16: =推广计划!U4 -> 0.12 | O16: campaign1：自动广告 campaign2：手动广告测试组B campaign3：SD-categories campaign4：PT campaign5：手动广告核心关键词E campaign6：SBV-PT / SBV-KT | R16: SP:70% SD:15% SB:15% | S16: 关键词 | T16: 关键词翻译 | U16: 流量占比 | V16: 预估周曝光量 | W16: 关键词类型 | X16: 转化效果自然流量占比
K17: =L17*M17 -> 75.214286 | L17: =$H$16/N17 -> 62.678571 | M17: =推广计划!T4 -> 1.2 | N17: =推广计划!U4 -> 0.12 | U17: 0.497508 | V17: 13984 | W17: 主要流量词 | X17: 0.3471
K18: =L18*M18 -> 75.214286 | L18: =$H$16/N18 -> 62.678571 | M18: =推广计划!T4 -> 1.2 | N18: =推广计划!U4 -> 0.12 | U18: 0.294441 | V18: 8276 | W18: 主要流量词 | X18: 0.41862
K19: =L19*M19 -> 75.214286 | L19: =$H$16/N19 -> 62.678571 | M19: =推广计划!T4 -> 1.2 | N19: =推广计划!U4 -> 0.12 | U19: 0.059295 | V19: 1667 | X19: 0.61722
A20: WEEK3 | B20: 5.14-5.20 | C20: =推广计划!D5 -> 109.99 | D20: =推广计划!G5 -> 7.8571429 | E20: =C20*D20*7 -> 6049.45 | F20: =推广计划!P5 -> 0.13095238 | G20: =D20/F20 -> 60 | H20: =D20*J20 -> 4.7142857 | I20: =H20*C20 -> 518.52429 | J20: 0.6 | K20: =L20*M20 -> 39.89011 | L20: =$H$20/N20 -> 36.263736 | M20: =推广计划!T5 -> 1.1 | N20: =推广计划!U5 -> 0.13 | O20: campaign1：自动广告 campaign2：手动广告测试组B campaign3：SD-categories campaign4：PT campaign5：手动广告核心关键词E campaign6：SBV-PT / SBV-KT | U20: 0.047246 | V20: 1328 | X20: 0.80955
K21: =L21*M21 -> 39.89011 | L21: =$H$20/N21 -> 36.263736 | M21: =推广计划!T5 -> 1.1 | N21: =推广计划!U5 -> 0.13 | U21: 0.02472 | V21: 695 | X21: 0.46301
K22: =L22*M22 -> 39.89011 | L22: =$H$20/N22 -> 36.263736 | M22: =推广计划!T5 -> 1.1 | N22: =推广计划!U5 -> 0.13 | U22: 0.019301 | V22: 543 | X22: 0.06106
K23: =L23*M23 -> 39.89011 | L23: =$H$20/N23 -> 36.263736 | M23: =推广计划!T5 -> 1.1 | N23: =推广计划!U5 -> 0.13 | U23: 0.017954 | V23: 505 | W23: 精准长尾词 | X23: 0.50632
A24: WEEK4 | B24: 5.21-5.27 | C24: =推广计划!D6 -> 109.99 | D24: =推广计划!G6 -> 6.8571429 | E24: =C24*D24*7 -> 5279.52 | F24: =推广计划!P6 -> 0.13714286 | G24: =D24/F24 -> 50 | H24: =D24*J24 -> 3.7714286 | I24: =H24*C24 -> 414.81943 | J24: 0.55 | K24: =L24*M24 -> 27.657143 | L24: =$H$24/N24 -> 25.142857 | M24: =推广计划!T6 -> 1.1 | N24: =推广计划!U6 -> 0.15 | O24: campaign1：自动广告 campaign2：手动广告测试组B campaign3：SD-categories campaign4：PT campaign5：手动广告核心关键词E campaign6：SBV-PT / SBV-KT | R24: SP:70% SD:15% SB:15% | U24: 0.008428 | V24: 237 | X24: 0.28778
K25: =L25*M25 -> 27.657143 | L25: =$H$24/N25 -> 25.142857 | M25: =推广计划!T6 -> 1.1 | N25: =推广计划!U6 -> 0.15 | U25: 0.007424 | V25: 209
K26: =L26*M26 -> 27.657143 | L26: =$H$24/N26 -> 25.142857 | M26: =推广计划!T6 -> 1.1 | N26: =推广计划!U6 -> 0.15 | U26: 0.002209 | V26: 62
K27: =L27*M27 -> 27.657143 | L27: =$H$24/N27 -> 25.142857 | M27: =推广计划!T6 -> 1.1 | N27: =推广计划!U6 -> 0.15 | U27: 0.001316 | V27: 37
A28: WEEK5 | B28: 5.28-6.3 | C28: =推广计划!D7 -> 119.99 | D28: =推广计划!G7 -> 7.4285714 | E28: =C28*D28*7 -> 6239.48 | F28: =推广计划!P7 -> 0.13265306 | G28: =D28/F28 -> 56 | H28: =D28*J28 -> 3.7142857 | I28: =H28*C28 -> 445.67714 | J28: 0.5 | K28: =L28*M28 -> 24.761905 | L28: =$H$28/N28 -> 24.761905 | M28: =推广计划!T7 -> 1 | N28: =推广计划!U7 -> 0.15 | O28: campaign1：自动广告 campaign2：手动广告主推词BP campaign3：SD-categories campaign4：PT campaign5：手动广告核心关键词E campaign6：SBV-PT / SBV-KT | P28: 推动销售 点击率；转化率；订单量；Acos
K29: =L29*M29 -> 24.761905 | L29: =$H$28/N29 -> 24.761905 | M29: =推广计划!T7 -> 1 | N29: =推广计划!U7 -> 0.15
K30: =L30*M30 -> 24.761905 | L30: =$H$28/N30 -> 24.761905 | M30: =推广计划!T7 -> 1 | N30: =推广计划!U7 -> 0.15
K31: =L31*M31 -> 24.761905 | L31: =$H$28/N31 -> 24.761905 | M31: =推广计划!T7 -> 1 | N31: =推广计划!U7 -> 0.15
A32: WEEK6 | B32: 6.4-6.10 | C32: =推广计划!D8 -> 119.99 | D32: =推广计划!G8 -> 7.1428571 | E32: =C32*D32*7 -> 5999.5 | F32: =推广计划!P8 -> 0.11904762 | G32: =D32/F32 -> 60 | H32: =D32*J32 -> 3.5714286 | I32: =H32*C32 -> 428.53571 | J32: 0.5 | K32: =L32*M32 -> 23.809524 | L32: =$H$32/N32 -> 23.809524 | M32: =推广计划!T8 -> 1 | N32: =推广计划!U8 -> 0.15 | O32: campaign1：自动广告 campaign2：手动广告主推词BP campaign3：SD-categories campaign4：PT campaign5：手动广告核心关键词E campaign6：SBV-PT / SBV-KT | R32: SP:70% SD:15% SB:15%
K33: =L33*M33 -> 23.809524 | L33: =$H$32/N33 -> 23.809524 | M33: =推广计划!T8 -> 1 | N33: =推广计划!U8 -> 0.15
K34: =L34*M34 -> 23.809524 | L34: =$H$32/N34 -> 23.809524 | M34: =推广计划!T8 -> 1 | N34: =推广计划!U8 -> 0.15
K35: =L35*M35 -> 23.809524 | L35: =$H$32/N35 -> 23.809524 | M35: =推广计划!T8 -> 1 | N35: =推广计划!U8 -> 0.15
A36: WEEK7 | B36: 6.11-6.17 | C36: =推广计划!D9 -> 119.99 | D36: =推广计划!G9 -> 8.2857143 | E36: =C36*D36*7 -> 6959.42 | F36: =推广计划!P9 -> 0.12184874 | G36: =D36/F36 -> 68 | H36: =D36*J36 -> 4.1428571 | I36: =H36*C36 -> 497.10143 | J36: 0.5 | K36: =L36*M36 -> 23.303571 | L36: =$H$36/N36 -> 25.892857 | M36: =推广计划!T9 -> 0.9 | N36: =推广计划!U9 -> 0.16 | O36: campaign1：自动广告 campaign2：手动广告主推词BP campaign3：SD-categories campaign4：PT campaign5：手动广告核心关键词E campaign6：SBV-PT / SBV-KT
K37: =L37*M37 -> 23.303571 | L37: =$H$36/N37 -> 25.892857 | M37: =推广计划!T9 -> 0.9 | N37: =推广计划!U9 -> 0.16
K38: =L38*M38 -> 23.303571 | L38: =$H$36/N38 -> 25.892857 | M38: =推广计划!T9 -> 0.9 | N38: =推广计划!U9 -> 0.16
K39: =L39*M39 -> 23.303571 | L39: =$H$36/N39 -> 25.892857 | M39: =推广计划!T9 -> 0.9 | N39: =推广计划!U9 -> 0.16
A40: WEEK8 | B40: 6.18-6.24 | C40: =推广计划!D10 -> 119.99 | D40: =推广计划!G10 -> 7.1428571 | E40: =C40*D40*7 -> 5999.5 | F40: =推广计划!P10 -> 0.10504202 | G40: =D40/F40 -> 68 | H40: =D40*J40 -> 3.2142857 | I40: =H40*C40 -> 385.68214 | J40: 0.45 | K40: =L40*M40 -> 18.080357 | L40: =$H$40/N40 -> 20.089286 | M40: =推广计划!T10 -> 0.9 | N40: =推广计划!U10 -> 0.16 | O40: campaign1：自动广告 campaign2：手动广告主推词BP campaign3：SD-categories campaign4：PT campaign5：手动广告核心关键词E campaign6：SBV-PT / SBV-KT | R40: SP:70% SD:15% SB:15%
K41: =L41*M41 -> 18.080357 | L41: =$H$40/N41 -> 20.089286 | M41: =推广计划!T10 -> 0.9 | N41: =推广计划!U10 -> 0.16
K42: =L42*M42 -> 18.080357 | L42: =$H$40/N42 -> 20.089286 | M42: =推广计划!T10 -> 0.9 | N42: =推广计划!U10 -> 0.16
K43: =L43*M43 -> 18.080357 | L43: =$H$40/N43 -> 20.089286 | M43: =推广计划!T10 -> 0.9 | N43: =推广计划!U10 -> 0.16
A44: WEEK9 | B44: 6.25-7.1 | C44: =推广计划!D11 -> 119.99 | D44: =推广计划!G11 -> 7.8571429 | E44: =C44*D44*7 -> 6599.45 | F44: =推广计划!P11 -> 0.1122449 | G44: =D44/F44 -> 70 | H44: =D44*J44 -> 3.5357143 | I44: =H44*C44 -> 424.25036 | J44: 0.45 | K44: =L44*M44 -> 19.888393 | L44: =$H$44/N44 -> 22.098214 | M44: =推广计划!T11 -> 0.9 | N44: =推广计划!U11 -> 0.16 | O44: campaign1：自动广告 campaign2：手动广告主推词BP campaign3：SD-categories campaign4：PT campaign5：手动广告核心关键词E campaign6：SBV-PT / SBV-KT
K45: =L45*M45 -> 19.888393 | L45: =$H$44/N45 -> 22.098214 | M45: =推广计划!T11 -> 0.9 | N45: =推广计划!U11 -> 0.16
K46: =L46*M46 -> 19.888393 | L46: =$H$44/N46 -> 22.098214 | M46: =推广计划!T11 -> 0.9 | N46: =推广计划!U11 -> 0.16
K47: =L47*M47 -> 19.888393 | L47: =$H$44/N47 -> 22.098214 | M47: =推广计划!T11 -> 0.9 | N47: =推广计划!U11 -> 0.16
A48: WEEK10 | B48: 7.2-7.8 | C48: =推广计划!D12 -> 119.99 | D48: =推广计划!G12 -> 9.2857143 | E48: =C48*D48*7 -> 7799.35 | F48: =推广计划!P12 -> 0.12380952 | G48: =D48/F48 -> 75 | H48: =D48*J48 -> 3.7142857 | I48: =H48*C48 -> 445.67714 | J48: 0.4 | K48: =L48*M48 -> 20.892857 | L48: =$H$48/N48 -> 23.214286 | M48: =推广计划!T12 -> 0.9 | N48: =推广计划!U12 -> 0.16 | O48: campaign1：自动广告 campaign2：手动广告主推词BP campaign3：SD-categories campaign4：PT campaign5：手动广告核心关键词E campaign6：SBV-PT / SBV-KT | R48: SP:70% SD:15% SB:15%
...

Sheet 利润&ROI测算
A1: 细分项 | L1: 4月 | AB1: 5月 | AR1: 6月 | BH1: 达标后每月销售
A2: 状态 | B2: Asin | C2: Model# | D2: 国家 | E2: 佣金比例 | F2: RMA比例 | G2: 广告费占比 | H2: MC/个 | I2: FBA配送费 | J2: 退换货分摊 /个 | K2: VAT | L2: 待办操作 | M2: 售价 | N2: 月销量 | O2: 销售总额 | P2: MC | Q2: 佣金 | R2: 配送费 | S2: RMA扣减 | T2: 广告费 | U2: 促销费 | V2: VAT | W2: 成本总计 | X2: 回款额 UK | Y2: 回款率 | Z2: 净毛利 US | AA2: 净毛利率 | AB2: 操作 | AC2: 售价 | AD2: 月销量 | AE2: 销售总额 | AF2: MC | AG2: 佣金 | AH2: 配送费 | AI2: RMA扣减 | AJ2: 广告费 | AK2: 促销费 | AL2: VAT | AM2: 成本总计 | AN2: 回款额 US | AO2: 回款率 | AP2: 净毛利 US | AQ2: 净毛利率 | AR2: 操作 | AS2: 售价 | AT2: 月销量 | AU2: 销售总额 | AV2: MC | AW2: 佣金 | AX2: 配送费 | AY2: RMA扣减 | AZ2: 广告费 | BA2: 促销费 | BB2: VAT | BC2: 成本总计 | BD2: 回款额 US | BE2: 回款率 | BF2: 净毛利 US | BG2: 净毛利率 | BH2: 操作 | BI2: 售价 | BJ2: 月销量 | BK2: 销售总额 | BL2: 产品成本 | BM2: 佣金 | BN2: 配送费 | BO2: RMA扣减 | BP2: 广告费 | BQ2: 促销费 | BR2: VAT | BS2: 成本总计 | BT2: 回款额 EU | BU2: 回款率 | BV2: 净毛利 EU | BW2: 净毛利率
A3: 卡航 | B3: B0XXX | C3: R0001EU | D3: DE | E3: 0.15 | F3: 0.07 | G3: 0.15 | H3: =122.56/7.4 -> 16.562162 | I3: 5.69 | J3: =(H3+I3)*F3 -> 1.5576514 | K3: 0.16 | M3: =推广计划!D3 -> 109.99 | N3: 450 | O3: =M3*N3 -> 49495.5 | P3: =$H3*N3 -> 7452.973 | Q3: =M3*$E3*N3 -> 7424.325 | R3: =I3*N3 -> 2560.5 | S3: =$J3*N3 -> 700.94311 | T3: =O3*18% -> 8909.19 | U3: =O3*12% -> 5939.46 | V3: =O3*K3 -> 7919.28 | W3: =P3+Q3+R3+S3+T3+U3+V3 -> 40906.671 | X3: =O3-Q3-R3-T3-U3-V3 -> 16742.745 | Y3: =X3/O3 -> 0.33826802 | Z3: =O3-W3 -> 8588.8289 | AA3: =Z3/O3 -> 0.17352747 | AC3: 114.99 | AD3: 500 | AE3: =AC3*AD3 -> 57495 | AF3: =$H3*AD3 -> 8281.0811 | AG3: =AC3*$E3*AD3 -> 8624.25 | AH3: =AD3*I3 -> 2845 | AI3: =$J3*AD3 -> 778.82568 | AJ3: =AE3*10% -> 5749.5 | AK3: =AE3*6% -> 3449.7 | AL3: =AE3*K3 -> 9199.2 | AM3: =AF3+AG3+AH3+AI3+AJ3+AK3+AL3 -> 38927.557 | AN3: =AE3-AG3-AH3-AJ3-AL3 -> 31077.05 | AO3: =AN3/AE3 -> 0.54051744 | AP3: =AE3-AM3 -> 18567.443 | AQ3: =AP3/AE3 -> 0.32294014 | AS3: 116.99 | AT3: 700 | AU3: =AS3*AT3 -> 81893 | AV3: =$H3*AT3 -> 11593.514 | AW3: =AS3*$E3*AT3 -> 12283.95 | AX3: =AT3*I3 -> 3983 | AY3: =$J3*AT3 -> 1090.3559 | AZ3: =AU3*7% -> 5732.51 | BA3: =AU3*15% -> 12283.95 | BB3: =K3*AU3 -> 13102.88 | BC3: =AV3+AW3+AX3+AY3+AZ3+BA3+BB3 -> 60070.159 | BD3: =AU3-AW3-AX3-AZ3-BB3 -> 46790.66 | BE3: =BD3/AU3 -> 0.57136336 | BF3: =AU3-BC3 -> 21822.841 | BG3: =BF3/AU3 -> 0.26647993 | BI3: 119.99 | BJ3: 1500 | BK3: =BI3*BJ3 -> 179985 | BL3: =$H3*BJ3 -> 24843.243 | BM3: =E3*BK3 -> 26997.75 | BN3: =I3*BJ3 -> 8535 | BO3: =$J3*BJ3 -> 2336.477 | BP3: =BK3*5.5% -> 9899.175 | BQ3: =BK3*8% -> 14398.8 | BR3: =K3*BK3 -> 28797.6 | BS3: =BL3+BM3+BN3+BO3+BP3+BQ3+BR3 -> 115808.05 | BT3: =BK3-BM3-BN3-BP3-BR3 -> 105755.48 | BU3: =BT3/BK3 -> 0.58757938 | BV3: =BK3-BS3 -> 64176.955 | BW3: =BV3/BK3 -> 0.35656835
A4: 铁路 | B4: B0XXX | C4: R0001EU | D4: DE | E4: 0.15 | F4: 0.07 | G4: 0.15 | H4: =122.56/7.4 -> 16.562162 | I4: 5.69 | J4: =(H4+I4)*F4 -> 1.5576514 | K4: 0.16 | M4: =推广计划!D3 -> 109.99 | N4: 450 | O4: =M4*N4 -> 49495.5 | P4: =$H4*N4 -> 7452.973 | Q4: =M4*$E4*N4 -> 7424.325 | R4: =I4*N4 -> 2560.5 | S4: =$J4*N4 -> 700.94311 | T4: =O4*18% -> 8909.19 | U4: =O4*12% -> 5939.46 | V4: =O4*K4 -> 7919.28 | W4: =P4+Q4+R4+S4+T4+U4+V4 -> 40906.671 | X4: =O4-Q4-R4-T4-U4-V4 -> 16742.745 | Y4: =X4/O4 -> 0.33826802 | Z4: =O4-W4 -> 8588.8289 | AA4: =Z4/O4 -> 0.17352747 | AC4: 114.99 | AD4: 500 | AE4: =AC4*AD4 -> 57495 | AF4: =$H4*AD4 -> 8281.0811 | AG4: =AC4*$E4*AD4 -> 8624.25 | AH4: =AD4*I4 -> 2845 | AI4: =$J4*AD4 -> 778.82568 | AJ4: =AE4*10% -> 5749.5 | AK4: =AE4*6% -> 3449.7 | AL4: =AE4*K4 -> 9199.2 | AM4: =AF4+AG4+AH4+AI4+AJ4+AK4+AL4 -> 38927.557 | AN4: =AE4-AG4-AH4-AJ4-AL4 -> 31077.05 | AO4: =AN4/AE4 -> 0.54051744 | AP4: =AE4-AM4 -> 18567.443 | AQ4: =AP4/AE4 -> 0.32294014 | AS4: 116.99 | AT4: 700 | AU4: =AS4*AT4 -> 81893 | AV4: =$H4*AT4 -> 11593.514 | AW4: =AS4*$E4*AT4 -> 12283.95 | AX4: =AT4*I4 -> 3983 | AY4: =$J4*AT4 -> 1090.3559 | AZ4: =AU4*7% -> 5732.51 | BA4: =AU4*15% -> 12283.95 | BB4: =K4*AU4 -> 13102.88 | BC4: =AV4+AW4+AX4+AY4+AZ4+BA4+BB4 -> 60070.159 | BD4: =AU4-AW4-AX4-AZ4-BB4 -> 46790.66 | BE4: =BD4/AU4 -> 0.57136336 | BF4: =AU4-BC4 -> 21822.841 | BG4: =BF4/AU4 -> 0.26647993 | BI4: 119.99 | BJ4: 1500 | BK4: =BI4*BJ4 -> 179985 | BL4: =$H4*BJ4 -> 24843.243 | BM4: =E4*BK4 -> 26997.75 | BN4: =I4*BJ4 -> 8535 | BO4: =$J4*BJ4 -> 2336.477 | BP4: =BK4*5.5% -> 9899.175 | BQ4: =BK4*8% -> 14398.8 | BR4: =K4*BK4 -> 28797.6 | BS4: =BL4+BM4+BN4+BO4+BP4+BQ4+BR4 -> 115808.05 | BT4: =BK4-BM4-BN4-BP4-BR4 -> 105755.48 | BU4: =BT4/BK4 -> 0.58757938 | BV4: =BK4-BS4 -> 64176.955 | BW4: =BV4/BK4 -> 0.35656835
A5: 海运 | B5: B0XXX | C5: R0001EU | D5: DE | E5: 0.15 | F5: 0.07 | G5: 0.15 | H5: =122.56/7.4 -> 16.562162 | I5: 5.69 | J5: =(H5+I5)*F5 -> 1.5576514 | K5: 0.16 | M5: =推广计划!D4 -> 109.99 | N5: 450 | O5: =M5*N5 -> 49495.5 | P5: =$H5*N5 -> 7452.973 | Q5: =M5*$E5*N5 -> 7424.325 | R5: =I5*N5 -> 2560.5 | S5: =$J5*N5 -> 700.94311 | T5: =O5*18% -> 8909.19 | U5: =O5*12% -> 5939.46 | V5: =O5*K5 -> 7919.28 | W5: =P5+Q5+R5+S5+T5+U5+V5 -> 40906.671 | X5: =O5-Q5-R5-T5-U5-V5 -> 16742.745 | Y5: =X5/O5 -> 0.33826802 | Z5: =O5-W5 -> 8588.8289 | AA5: =Z5/O5 -> 0.17352747 | AC5: 114.99 | AD5: 500 | AE5: =AC5*AD5 -> 57495 | AF5: =$H5*AD5 -> 8281.0811 | AG5: =AC5*$E5*AD5 -> 8624.25 | AH5: =AD5*I5 -> 2845 | AI5: =$J5*AD5 -> 778.82568 | AJ5: =AE5*10% -> 5749.5 | AK5: =AE5*6% -> 3449.7 | AL5: =AE5*K5 -> 9199.2 | AM5: =AF5+AG5+AH5+AI5+AJ5+AK5+AL5 -> 38927.557 | AN5: =AE5-AG5-AH5-AJ5-AL5 -> 31077.05 | AO5: =AN5/AE5 -> 0.54051744 | AP5: =AE5-AM5 -> 18567.443 | AQ5: =AP5/AE5 -> 0.32294014 | AS5: 116.99 | AT5: 700 | AU5: =AS5*AT5 -> 81893 | AV5: =$H5*AT5 -> 11593.514 | AW5: =AS5*$E5*AT5 -> 12283.95 | AX5: =AT5*I5 -> 3983 | AY5: =$J5*AT5 -> 1090.3559 | AZ5: =AU5*7% -> 5732.51 | BA5: =AU5*15% -> 12283.95 | BB5: =K5*AU5 -> 13102.88 | BC5: =AV5+AW5+AX5+AY5+AZ5+BA5+BB5 -> 60070.159 | BD5: =AU5-AW5-AX5-AZ5-BB5 -> 46790.66 | BE5: =BD5/AU5 -> 0.57136336 | BF5: =AU5-BC5 -> 21822.841 | BG5: =BF5/AU5 -> 0.26647993 | BI5: 119.99 | BJ5: 1500 | BK5: =BI5*BJ5 -> 179985 | BL5: =$H5*BJ5 -> 24843.243 | BM5: =E5*BK5 -> 26997.75 | BN5: =I5*BJ5 -> 8535 | BO5: =$J5*BJ5 -> 2336.477 | BP5: =BK5*5.5% -> 9899.175 | BQ5: =BK5*8% -> 14398.8 | BR5: =K5*BK5 -> 28797.6 | BS5: =BL5+BM5+BN5+BO5+BP5+BQ5+BR5 -> 115808.05 | BT5: =BK5-BM5-BN5-BP5-BR5 -> 105755.48 | BU5: =BT5/BK5 -> 0.58757938 | BV5: =BK5-BS5 -> 64176.955 | BW5: =BV5/BK5 -> 0.35656835
A6: 空运 | B6: B0XXX | C6: R0001EU | D6: DE | E6: 0.15 | F6: 0.07 | G6: 0.15 | H6: =122.56/7.4 -> 16.562162 | I6: 5.69 | J6: =(H6+I6)*F6 -> 1.5576514 | K6: 0.16 | M6: =推广计划!D5 -> 109.99 | N6: 450 | O6: =M6*N6 -> 49495.5 | P6: =$H6*N6 -> 7452.973 | Q6: =M6*$E6*N6 -> 7424.325 | R6: =I6*N6 -> 2560.5 | S6: =$J6*N6 -> 700.94311 | T6: =O6*18% -> 8909.19 | U6: =O6*12% -> 5939.46 | V6: =O6*K6 -> 7919.28 | W6: =P6+Q6+R6+S6+T6+U6+V6 -> 40906.671 | X6: =O6-Q6-R6-T6-U6-V6 -> 16742.745 | Y6: =X6/O6 -> 0.33826802 | Z6: =O6-W6 -> 8588.8289 | AA6: =Z6/O6 -> 0.17352747 | AC6: 114.99 | AD6: 500 | AE6: =AC6*AD6 -> 57495 | AF6: =$H6*AD6 -> 8281.0811 | AG6: =AC6*$E6*AD6 -> 8624.25 | AH6: =AD6*I6 -> 2845 | AI6: =$J6*AD6 -> 778.82568 | AJ6: =AE6*10% -> 5749.5 | AK6: =AE6*6% -> 3449.7 | AL6: =AE6*K6 -> 9199.2 | AM6: =AF6+AG6+AH6+AI6+AJ6+AK6+AL6 -> 38927.557 | AN6: =AE6-AG6-AH6-AJ6-AL6 -> 31077.05 | AO6: =AN6/AE6 -> 0.54051744 | AP6: =AE6-AM6 -> 18567.443 | AQ6: =AP6/AE6 -> 0.32294014 | AS6: 116.99 | AT6: 700 | AU6: =AS6*AT6 -> 81893 | AV6: =$H6*AT6 -> 11593.514 | AW6: =AS6*$E6*AT6 -> 12283.95 | AX6: =AT6*I6 -> 3983 | AY6: =$J6*AT6 -> 1090.3559 | AZ6: =AU6*7% -> 5732.51 | BA6: =AU6*15% -> 12283.95 | BB6: =K6*AU6 -> 13102.88 | BC6: =AV6+AW6+AX6+AY6+AZ6+BA6+BB6 -> 60070.159 | BD6: =AU6-AW6-AX6-AZ6-BB6 -> 46790.66 | BE6: =BD6/AU6 -> 0.57136336 | BF6: =AU6-BC6 -> 21822.841 | BG6: =BF6/AU6 -> 0.26647993 | BI6: 119.99 | BJ6: 1500 | BK6: =BI6*BJ6 -> 179985 | BL6: =$H6*BJ6 -> 24843.243 | BM6: =E6*BK6 -> 26997.75 | BN6: =I6*BJ6 -> 8535 | BO6: =$J6*BJ6 -> 2336.477 | BP6: =BK6*5.5% -> 9899.175 | BQ6: =BK6*8% -> 14398.8 | BR6: =K6*BK6 -> 28797.6 | BS6: =BL6+BM6+BN6+BO6+BP6+BQ6+BR6 -> 115808.05 | BT6: =BK6-BM6-BN6-BP6-BR6 -> 105755.48 | BU6: =BT6/BK6 -> 0.58757938 | BV6: =BK6-BS6 -> 64176.955 | BW6: =BV6/BK6 -> 0.35656835
N8: =SUM(N3:N6) -> 1800 | O8: =SUM(O3:O6) -> 197982 | P8: =SUM(P3:P6) -> 29811.892 | Q8: =SUM(Q3:Q6) -> 29697.3 | R8: =SUM(R3:R6) -> 10242 | S8: =SUM(S3:S6) -> 2803.7724 | T8: =SUM(T3:T6) -> 35636.76 | U8: =SUM(U3:U6) -> 23757.84 | ... X8: =SUM(X3:X6) -> 66970.98 | Y8: =X8/O8 -> 0.33826802 | Z8: =SUM(Z3:Z6) -> 34355.316 | AA8: =Z8/O8 -> 0.17352747 | AD8: =SUM(AD3:AD6) -> 2000 | AE8: =SUM(AE3:AE6) -> 229980 | AF8: =SUM(AF3:AF6) -> 33124.324 | AG8: =SUM(AG3:AG6) -> 34497 | AH8: =SUM(AH3:AH6) -> 11380 | AI8: =SUM(AI3:AI6) -> 3115.3027 | AJ8: =SUM(AJ3:AJ6) -> 22998 | AK8: =SUM(AK3:AK6) -> 13798.8 | ... AN8: =SUM(AN3:AN6) -> 124308.2 | AO8: =AN8/AE8 -> 0.54051744 | AP8: =SUM(AP3:AP6) -> 74269.773 | AQ8: =AP8/AE8 -> 0.32294014 | AT8: =SUM(AT3:AT6) -> 2800 | AU8: =SUM(AU3:AU6) -> 327572 | AV8: =SUM(AV3:AV6) -> 46374.054 | AW8: =SUM(AW3:AW6) -> 49135.8 | AX8: =SUM(AX3:AX6) -> 15932 | AY8: =SUM(AY3:AY6) -> 4361.4238 | AZ8: =SUM(AZ3:AZ6) -> 22930.04 | BA8: =SUM(BA3:BA6) -> 49135.8 | ... BD8: =SUM(BD3:BD6) -> 187162.64 | BE8: =BD8/AU8 -> 0.57136336 | BF8: =SUM(BF3:BF6) -> 87291.362 | BG8: =BF8/AU8 -> 0.26647993 | BJ8: =SUM(BJ3:BJ6) -> 6000 | BK8: =SUM(BK3:BK6) -> 719940 | BL8: =SUM(BL3:BL6) -> 99372.973 | BM8: =SUM(BM3:BM6) -> 107991 | BN8: =SUM(BN3:BN6) -> 34140 | BO8: =SUM(BO3:BO6) -> 9345.9081 | BP8: =SUM(BP3:BP6) -> 39596.7 | BQ8: =SUM(BQ3:BQ6) -> 57595.2 | ... BT8: =SUM(BT3:BT6) -> 423021.9 | BU8: =BT8/BK8 -> 0.58757938 | BV8: =SUM(BV3:BV6) -> 256707.82 | BW8: =BV8/BK8 -> 0.35656835
A10: 价格利润测算
A12: Asin | B12: Model | C12: Price | D12: All cost | E12: Profit | F12: Profit% | G12: MC | H12: 佣金 | I12: 配送费 | J12: 退货均摊 | K12: VAT税率 | L12: 佣金率 | M12: 退货率 | N12: 折扣% off | O12: 底价
C13: =$M$3 -> 109.99 | D13: =G13+H13+I13+J13+K13*C13+C13*N13 -> 64.7552 | E13: =C13-D13 -> 45.2348 | F13: =E13/C13 -> 0.41126284 | G13: 6.27 | H13: =C13*L13 -> 16.4985 | I13: =$I$3 -> 5.69 | J13: =C13*M13 -> 7.6993 | K13: 0.16 | L13: =$E$3 -> 0.15 | M13: =$F$3 -> 0.07 | N13: 0.1 | O13: =(G13+I13)/(1-L13-M13-K13) -> 19.290323
C14: =$M$3 -> 109.99 | D14: =G14+H14+I14+J14+K14*C14+C14*N14 -> 59.2557 | E14: =C14-D14 -> 50.7343 | F14: =E14/C14 -> 0.46126284 | G14: 6.27 | H14: =C14*L14 -> 16.4985 | I14: =$I$3 -> 5.69 | J14: =C14*M14 -> 7.6993 | K14: 0.16 | L14: =$E$3 -> 0.15 | M14: =$F$3 -> 0.07 | N14: 0.05 | O14: =(G14+I14)/(1-L14-M14-K14) -> 19.290323
C15: =$M$3 -> 109.99 | D15: =G15+H15+I15+J15+K15*C15+C15*N15 -> 59.2557 | E15: =C15-D15 -> 50.7343 | F15: =E15/C15 -> 0.46126284 | G15: 6.27 | H15: =C15*L15 -> 16.4985 | I15: =$I$3 -> 5.69 | J15: =C15*M15 -> 7.6993 | K15: 0.16 | L15: =$E$3 -> 0.15 | M15: =$F$3 -> 0.07 | N15: 0.05 | O15: =(G15+I15)/(1-L15-M15-K15) -> 19.290323
C16: =$M$3 -> 109.99 | D16: =G16+H16+I16+J16+K16*C16+C16*N16 -> 59.2557 | E16: =C16-D16 -> 50.7343 | F16: =E16/C16 -> 0.46126284 | G16: 6.27 | H16: =C16*L16 -> 16.4985 | I16: =$I$3 -> 5.69 | J16: =C16*M16 -> 7.6993 | K16: 0.16 | L16: =$E$3 -> 0.15 | M16: =$F$3 -> 0.07 | N16: 0.05 | O16: =(G16+I16)/(1-L16-M16-K16) -> 19.290323
C17: =$M$3 -> 109.99 | D17: =G17+H17+I17+J17+K17*C17+C17*N17 -> 59.2557 | E17: =C17-D17 -> 50.7343 | F17: =E17/C17 -> 0.46126284 | G17: 6.27 | H17: =C17*L17 -> 16.4985 | I17: =$I$3 -> 5.69 | J17: =C17*M17 -> 7.6993 | K17: 0.16 | L17: =$E$3 -> 0.15 | M17: =$F$3 -> 0.07 | N17: 0.05 | O17: =(G17+I17)/(1-L17-M17-K17) -> 19.290323
C18: 116.99 | D18: =G18+H18+I18+J18+K18*C18+C18*N18 -> 56.4162 | E18: =C18-D18 -> 60.5738 | F18: =E18/C18 -> 0.51776904 | G18: 6.27 | H18: =C18*L18 -> 17.5485 | I18: =$I$3 -> 5.69 | J18: =C18*M18 -> 8.1893 | K18: 0.16 | L18: =$E$3 -> 0.15 | M18: =$F$3 -> 0.07 | N18: 0 | O18: =(G18+I18)/(1-L18-M18-K18) -> 19.290323
C19: 116.99 | D19: =G19+H19+I19+J19+K19*C19+C19*N19 -> 56.4162 | E19: =C19-D19 -> 60.5738 | F19: =E19/C19 -> 0.51776904 | G19: 6.27 | H19: =C19*L19 -> 17.5485 | I19: =$I$3 -> 5.69 | J19: =C19*M19 -> 8.1893 | K19: 0.16 | L19: =$E$3 -> 0.15 | M19: =$F$3 -> 0.07 | N19: 0 | O19: =(G19+I19)/(1-L19-M19-K19) -> 19.290323
A23: ROI测算
A24: 月份 | B24: 售价 | C24: 月销量 | D24: 总销售额 | E24: MC | F24: 佣金 | G24: 配送费 | H24: RMA扣减 | I24: 广告费 | J24: 促销费 | K24: VAT | L24: 成本总计 | M24: 回款额 US | N24: 回款率 | O24: 净毛利 US | P24: 净毛利率 | Q24: 累计净毛利
A25: 3月 | B25: =119.99 -> 119.99 | C25: =N3 -> 450 | D25: =O3 -> 49495.5 | E25: =P3 -> 7452.973 | F25: =Q3 -> 7424.325 | G25: =R3 -> 2560.5 | H25: =S3 -> 700.94311 | I25: =T3 -> 8909.19 | J25: =U3 -> 5939.46 | ... P25: =AA3 -> 0.17352747 | Q25: =O25 -> 8588.8289
A26: 4月 | B26: 119.99 | C26: 1500 | D26: =AE4 -> 57495 | E26: =AF4 -> 8281.0811 | F26: =AG4 -> 8624.25 | G26: =AH4 -> 2845 | H26: =AI4 -> 778.82568 | I26: =AJ4 -> 5749.5 | J26: =AK4 -> 3449.7 | K26: =AL4 -> 9199.2 | ... P26: =AQ4 -> 0.32294014 | Q26: =SUM(O25:O26) -> 27156.272
A27: 5月 | B27: 116.99 | C27: 1700 | D27: =AU4 -> 81893 | E27: =AV4 -> 11593.514 | F27: =AW4 -> 12283.95 | G27: =AX4 -> 3983 | H27: =AY4 -> 1090.3559 | I27: =AZ4 -> 5732.51 | J27: =BA4 -> 12283.95 | K27: =BB4 -> 13102.88 | ... P27: =BG4 -> 0.26647993 | Q27: =SUM(O25:O27) -> 48979.113
A28: 6月 | B28: 116.99 | C28: 1500 | D28: 25485 | E28: 8430 | F28: 3822.75 | G28: 2805 | H28: 561.75 | I28: 1401.675 | J28: 2038.8 | K28: 4247.5 | L28: 23307.475 | M28: 13208.075 | N28: 0.51826859 | O28: 2177.525 | P28: 0.085443398 | Q28: =SUM(O25:O28) -> 51156.638
A29: 7月 | B29: 119.99 | C29: 1500 | D29: 25485 | E29: 8430 | F29: 3822.75 | G29: 2805 | H29: 561.75 | I29: 1401.675 | J29: 2038.8 | K29: 4247.5 | L29: 23307.475 | M29: 13208.075 | N29: 0.51826859 | O29: 2177.525 | P29: 0.085443398 | Q29: =SUM(O26:O29) -> 44745.334
A30: 8月 | B30: 119.99 | C30: 1500 | D30: 25485 | E30: 8430 | F30: 3822.75 | G30: 2805 | H30: 561.75 | I30: 1401.675 | J30: 2038.8 | K30: 4247.5 | L30: 23307.475 | M30: 13208.075 | N30: 0.51826859 | O30: 2177.525 | P30: 0.085443398 | Q30: =SUM(O27:O30) -> 28355.416
A31: 9月 | B31: 119.99 | C31: 1500 | D31: 25485 | E31: 8430 | F31: 3822.75 | G31: 2805 | H31: 561.75 | I31: 1401.675 | J31: 2038.8 | K31: 4247.5 | L31: 23307.475 | M31: 13208.075 | N31: 0.51826859 | O31: 2177.525 | P31: 0.085443398 | Q31: =SUM(O28:O31) -> 8710.1
A32: 10月 | B32: 119.99 | C32: 1500 | D32: 25485 | E32: 8430 | F32: 3822.75 | G32: 2805 | H32: 561.75 | I32: 1401.675 | J32: 2038.8 | K32: 4247.5 | L32: 23307.475 | M32: 13208.075 | N32: 0.51826859 | O32: 2177.525 | P32: 0.085443398 | Q32: =SUM(O29:O32) -> 8710.1
A33: 11月 | B33: 119.99 | C33: 1500 | D33: 25485 | E33: 8430 | F33: 3822.75 | G33: 2805 | H33: 561.75 | I33: 1401.675 | J33: 2038.8 | K33: 4247.5 | L33: 23307.475 | M33: 13208.075 | N33: 0.51826859 | O33: 2177.525 | P33: 0.085443398 | Q33: =SUM(O30:O33) -> 8710.1
A34: 12月 | B34: 119.99 | C34: 1500 | D34: 25485 | E34: 8430 | F34: 3822.75 | G34: 2805 | H34: 561.75 | I34: 1401.675 | J34: 2038.8 | K34: 4247.5 | L34: 23307.475 | M34: 13208.075 | N34: 0.51826859 | O34: 2177.525 | P34: 0.085443398 | Q34: =SUM(O31:O34) -> 8710.1

Sheet 账号&备货规划
A1: 采购单 | D1: 中仓 | H1: FBA调拨
A2: 采购单类型 | B2: 下采购购单日期 | C2: 采购数量 | D2: 入中仓时间 | E2: 入仓数量 | F2: 是否备安全库存 | G2: 安全库存数量 | H2: 调拨时间 | I2: 物流方式 | J2: 调拨数量 | K2: 调拨账号
A3: 首单 | B3: 2021.12.7 | C3: 5000 | D3: 2022.1.16 | E3: 4988 | F3: 是 | G3: 1000 | H3: 2022.1.19 | I3: 海运 | J3: 2490 | K3: LBS
H4: 2022.2.11 | I4: 空派 | J4: 1200 | K4: TT
H5: 2022.3.18 | I5: 卡派 | J5: 1310 | K5: LBS
A6: 翻单1 | B6: 2022.3.22 | C6: 1500 | D6: 2022.4.22 | E6: 1500 | F6: 否 | G6: 0 | H6: 2022.4.23 | I6: 卡派 | J6: 1500
A7: 翻单2 | B7: 2022.4.12 | C7: 1980 | D7: 2022.5.12 | E7: 1980 | F7: 否 | G7: 0 | H7: 2022.5.13 | I7: 卡派 | J7: 1980
A8: 翻单3 | B8: 2022.4.28 | C8: 2100 | D8: 2022.5.28 | E8: 2100 | F8: 否 | G8: 0 | H8: 2022.5.29 | I8: 海运 | J8: 2100 | K8: LBS
A9: 翻单4 | B9: 2022.5.19 | C9: 3000 | D9: 2022.7.1 | E9: 3000 | F9: 否 | G9: 0 | H9: 2022.7.2 | I9: 海运 | J9: 3000 | K9: LBS
A11: 采购交期30-45天，翻单1，2，3由于时间关系需要催单30天交付，若无法提前交付时间，则需提前下单或走部分空运
A12: FBA详细备货见推广计划
C13: 安全库存
C14: 1. 备货数量较保守，可能会有销量上涨，此部分库存用来避免断货
C15: 2. 防止主要销售账号出现异常时，其他账号无货可售的情况
C16: 3. 安全库存遵循先进先出原则

Sheet ASIN 定投
A1: 图片 | B1: ASIN | C1: SKU | D1: 详细参数 | E1: 品牌 | F1: 品牌链接 | G1: 商品标题 | H1: 标题(翻译) | I1: 产品卖点 | J1: 产品卖点(翻译) | K1: 商品详情页链接 | L1: 商品主图 | M1: 父ASIN | N1: 类目路径 | O1: 大类目 | P1: 大类BSR | Q1: 大类BSR增长数 | R1: 大类BSR增长率 | S1: 小类目 | T1: 小类BSR | U1: 月销量 | V1: 月销量增长率 | W1: 月销售额(€) | X1: 子体销量 | Y1: 子体销售额(€) | Z1: 变体数 | AA1: 价格(€) | AB1: Prime价格(€) | AC1: Coupon | AD1: Q&A数 | AE1: 评分数 | AF1: 月新增 评分数 | AG1: 评分 | AH1: 留评率 | AI1: FBA(€) | AJ1: 毛利率 | AK1: 评级 | AL1: 上架时间 | AM1: 上架天数 | AN1: 配送方式 | AO1: LQS | AP1: 卖家数 | AQ1: Buybox卖家 | AR1: BuyBox类型 | AS1: 卖家所属地 | AT1: 卖家信息 | AU1: 卖家首页 | AV1: Best Seller标识 | AW1: Amazon's Choice | AX1: New Release标识 | AY1: A+页面 | AZ1: 视频介绍 | BA1: SP广告 | BB1: 品牌故事 | BC1: 品牌广告 | BD1: 7天促销 | BE1: AC关键词 | BF1: 重量 | BG1: 重量 | BH1: 体积 | BI1: 体积 | BJ1: 包装重量 | BK1: 包装体积
