Workbook

Sheet 词盘
A1: 流量 | B1: 大词 | C1: 中尾词 | D1: 长尾词 | H1: GPT关键词分析 | I1: https://chatgpt.com/g/g-RZEovC1BF-vikiguan-jian-ci-fen-xi-zhuan-jia/c/67362093-f224-8010-952b-e4f602764b30
A2: ABA不大于 | B2: 20000 | C2: 100000
A4: 流量大小 | B4: 关键词 | C4: 流量占比 | D4: 转化率 | E4: 竞价 | F4: 转化成本
A5: 大词 | B5: 311 | C5: 0.639 | D5: 0.046350677 | E5: 0.69737999 | F5: 15.045735
A6: 中尾词 | B6: 5 | C6: 0.3374 | D6: 0.062012674 | E6: 0.93455247 | F6: 15.070346
A7: 总计 | B7: 316 | C7: 0.9764 | D7: 0.050736673 | E7: 0.76379793 | F7: 15.054159
A11: 相关性 | B11: 关键词 | C11: 流量占比 | D11: 转化率 | E11: 竞价 | F11: 转化成本
A12: 1 | B12: 60 | C12: 0.3484 | D12: 0.072490363 | E12: 1.0328616 | F12: 14.248261
A13: (空白) | B13: 172 | C13: 0.1487 | D13: 0.040244514 | E13: 0.7659401 | F13: 19.032162
A14: 3 | B14: 43 | C14: 0.1151 | D14: 0.028883909 | E14: 0.52804333 | F14: 18.281575
A15: 2 | B15: 38 | C15: 0.3462 | D15: 0.07555346 | E15: 0.68069731 | F15: 9.009479
A16: 0 | B16: 3 | C16: 0.018 | D16: 0.012878634 | E16: 0.5221281 | F16: 40.542195
A17: 总计 | B17: 316 | C17: 0.9764 | D17: 0.050736673 | E17: 0.76379793 | F17: 15.054159
A19: 有序性 | B19: 关键词 | C19: 流量占比 | D19: 转化率 | E19: 竞价 | F19: 转化成本
A20: 无序 | B20: 262 | C20: 0.6366 | D20: 0.042857494 | E20: 0.69869536 | F20: 16.302758
A21: 有序 | B21: 54 | C21: 0.3398 | D21: 0.11517711 | E21: 1.296244 | F21: 11.254354
A22: 总计 | B22: 316 | C22: 0.9764 | D22: 0.050736673 | E22: 0.76379793 | F22: 15.054159
M24: 流量分配
A25: 词组 | B25: 关键词 | C25: 流量占比 | D25: 转化率 | E25: 竞价 | F25: 转化成本
A26: (空白) | B26: 262 | C26: 0.6366 | D26: 0.042857494 | E26: 0.69869536 | F26: 16.302758 | M26: 新品期
A27: meat thermometer | B27: 48 | C27: 0.2833 | D27: 0.11403542 | E27: 1.3681681 | F27: 11.997747
A28: food thermometer | B28: 6 | C28: 0.0565 | D28: 0.12243178 | E28: 0.83921548 | F28: 6.854556
A29: 总计 | B29: 316 | C29: 0.9764 | D29: 0.050736673 | E29: 0.76379793 | F29: 15.054159
A53: 一级分类 | B53: 关键词 | C53: 流量占比 | D53: 转化率 | E53: 竞价 | F53: 转化成本 | H53: 用户搜索意图标签 | I53: 关键词 | J53: 流量占比 | K53: 转化率 | L53: 竞价 | M53: 转化成本 | Q53: 词根一级分类 | R53: 词根 | S53: 流量占比 | T53: 转化率 | U53: 竞价 | V53: 转化成本 | X53: 词根用户搜索意图标签 | Y53: 词根 | Z53: 流量占比 | AA53: 转化率 | AB53: 竞价 | AC53: 转化成本
A54: 品名词 | B54: 11 | C54: 0.3688 | D54: 0.062431932 | E54: 0.74015247 | F54: 11.855351 | H54: 寻找电源站类型或购买电源站 | I54: 1 | J54: 0.14 | K54: 0.11399792 | L54: 1.786502 | M54: 15.671356 | Q54: (空白) | R54: 704 | S54: 0.47028185 | T54: 0.020350668 | U54: 0.87460421 | V54: 42.976683 | X54: (空白) | Y54: 758 | Z54: 0.60220026 | AA54: 0.023201846 | AB54: 0.86263472 | AC54: 37.179573
A55: 场景词 | B55: 15 | C55: 0.0983 | D55: 0.038522339 | E55: 1.0444286 | F55: 27.112283 | H55: (空白) | I55: 228 | J55: 0.1387 | K55: 0.044655472 | L55: 0.66777448 | M55: 14.953923 | Q55: 功能词 | R55: 21 | S55: 0.17246751 | T55: 0.018603339 | U55: 1.211879 | V55: 65.143092 | X55: 电力驱动 | Y55: 6 | Z55: 0.076449399 | AA55: 0.015468385 | AB55: 1.2780045 | AC55: 82.620422
A56: 功能词 | B56: 28 | C56: 0.1307 | D56: 0.037575658 | E56: 0.83257753 | F56: 22.157364 | H56: 寻找便携式电源站 | I56: 1 | J56: 0.1141 | K56: 0.087299475 | L56: 0.23378488 | M56: 2.6779643 | Q56: 品名词 | R56: 27 | S56: 0.16572555 | T56: 0.016024258 | U56: 1.0859367 | V56: 67.7683 | X56: 发电机 | Y56: 3 | Z56: 0.073066251 | AA56: 0.011070736 | AB56: 1.0251733 | AC56: 92.602085
A57: (空白) | B57: 228 | C57: 0.1387 | D57: 0.044655472 | E57: 0.66777448 | F57: 14.953923 | H57: 寻找太阳能发电机 | I57: 7 | J57: 0.1002 | K57: 0.020121169 | L57: 0.81372003 | M57: 40.440992 | Q57: 品牌词 | R57: 15 | S57: 0.094679453 | T57: 0.027735358 | U57: 1.5254579 | V57: 55.000475 | X57: 电源站 | Y57: 2 | Z57: 0.054982232 | AA57: 0.011324633 | AB57: 2.2192905 | AC57: 195.97018
A58: 品牌词 | B58: 30 | C58: 0.2237 | D58: 0.071724092 | E58: 0.70373669 | F58: 9.8117198 | H58: 了解或购买Jackery品牌的电源产品 | I58: 4 | J58: 0.0767 | K58: 0.12023776 | L58: 1.2959752 | M58: 10.778438 | Q58: 场景词 | R58: 17 | S58: 0.051501728 | T58: 0.034442636 | U58: 0.40707995 | V58: 11.819071 | X58: 太阳能 | Y58: 1 | Z58: 0.045684661 | AA58: 0.012658003 | AB58: 1.0585624 | AC58: 83.627913
A59: 属性词 | B59: 4 | C59: 0.0162 | D59: 0.1815744 | E59: 0.75248255 | F59: 4.1442106 | H59: 了解或购买Anker品牌的电源产品 | I59: 7 | J59: 0.051 | K59: 0.050838059 | L59: 0.50739338 | M59: 9.9805813 | Q59: 属性词 | R59: 22 | S59: 0.045343913 | T59: 0.022113661 | U59: 1.316347 | V59: 59.526418 | X59: 便携 | Y59: 3 | Z59: 0.03882101 | AA59: 0.019876563 | AB59: 1.3960977 | AC59: 70.238385
A60: 总计 | B60: 316 | C60: 0.9764 | D60: 0.050736673 | E60: 0.76379793 | F60: 15.054159 | H60: 寻找便携式发电机 | I60: 3 | J60: 0.0493 | K60: 0.097325285 | L60: 0.91161276 | M60: 9.3666591 | Q60: 总计 | R60: 806 | S60: 1 | T60: 0.022638783 | U60: 0.90751773 | V60: 40.08686 | X60: 交流电 | Y60: 2 | Z60: 0.026748771 | AA60: 0.022858441 | AB60: 1.1928742 | AC60: 52.185282
H61: 了解或购买EcoFlow品牌电源产品 | I61: 6 | J61: 0.047 | K61: 0.14234224 | L61: 0.92465961 | M61: 6.496031 | X61: 太阳能面板 | Y61: 2 | Z61: 0.022319038 | AA61: 0.0096331566 | AB61: 1.1794705 | AC61: 122.43863
H62: 寻找适合户外活动的电源或设备 | I62: 2 | J62: 0.0284 | K62: 0.071819523 | L62: 1.0841268 | M62: 15.095155 | X62: 户外 | Y62: 2 | Z62: 0.018595142 | AA62: 0.0067511937 | AB62: 0.77695581 | AC62: 115.08421
A63: 二级分类 | B63: 关键词 | C63: 流量占比 | D63: 转化率 | E63: 竞价 | F63: 转化成本 | H63: 了解或购买Bluetti品牌的电源产品 | I63: 3 | J63: 0.0266 | K63: 0.025044203 | L63: 0.32855262 | M63: 13.118909 | Q63: 词根二级分类 | R63: 词根 | S63: 流量占比 | T63: 转化率 | U63: 竞价 | V63: 转化成本 | X63: 电池 | Y63: 4 | Z63: 0.013045806 | AA63: 0.025408934 | AB63: 0.7948801 | AC63: 31.283488
A64: (空白) | B64: 269 | C64: 0.7312 | D64: 0.056357327 | E64: 0.69778096 | F64: 12.381371 | H64: 了解户外活动必备电源设备或其他装备 | I64: 3 | J64: 0.0262 | K64: 0.043483967 | L64: 1.371553 | M64: 31.541579 | Q64: (空白) | R64: 720 | S64: 0.57601129 | T64: 0.020782048 | U64: 0.93095755 | V64: 44.796238 | X64: 家庭 | Y64: 3 | Z64: 0.011926204 | AA64: 0.042939623 | AB64: 0.2691463 | AC64: 6.2680174
A65: 太阳能 | B65: 1 | C65: 0.0018 | D65: 0.030196022 | E65: 0.089322571 | F65: 2.9580907 | H65: 寻找带太阳能面板的太阳能发电机 | I65: 1 | J65: 0.022 | K65: 0.15359624 | L65: 0.83151202 | M65: 5.4136221 | Q65: 发电机 | R65: 3 | S65: 0.073066251 | T65: 0.011070736 | U65: 1.0251733 | V65: 92.602085 | X65: 备份 | Y65: 2 | Z65: 0.005476318 | AA65: 0.015755492 | AB65: 1.0311328 | AC65: 65.445926
A66: 包括太阳能面板 | B66: 1 | C66: 0.022 | D66: 0.15359624 | E66: 0.83151202 | F66: 5.4136221 | H66: 寻找家庭用发电机 | I66: 1 | J66: 0.0168 | K66: 0.11588691 | L66: 0.90997948 | M66: 7.8523059 | Q66: 电力 | R66: 1 | S66: 0.067200506 | T66: 0.015333407 | U66: 1.4012018 | V66: 91.382288 | X66: 专业版 | Y66: 1 | Z66: 0.0030180597 | AA66: 0.019525014 | AB66: 1.0702974 | AC66: 54.816727
A67: 户外活动场景 | B67: 1 | C67: 0.0206 | D67: 0.062696883 | E67: 1.1745185 | F67: 18.733285 | H67: 了解或购买便携式房屋及电源产品 | I67: 3 | J67: 0.0122 | K67: 0.0048734688 | L67: 0.45390327 | M67: 93.137616 | Q67: 电源站 | R67: 2 | S67: 0.054982232 | T67: 0.011324633 | U67: 2.2192905 | V67: 195.97018 | X67: 小型设备 | Y67: 2 | Z67: 0.0019714745 | AA67: 0.012385492 | AB67: 0.91032208 | AC67: 73.499067
A68: 户外活动必备品 | B68: 1 | C68: 0.017 | D68: 0.15359286 | E68: 0.86933277 | F68: 5.6599816 | H68: 寻找太阳能面板 | I68: 1 | J68: 0.0086 | K68: 0.13918898 | L68: 0.94905242 | M68: 6.8184449 | Q68: 太阳能 | R68: 1 | S68: 0.045684661 | T68: 0.012658003 | U68: 1.0585624 | V68: 83.627913 | X68: 充电 | Y68: 2 | Z68: 0.0017280826 | AA68: 0.025645074 | AB68: 1.3279707 | AC68: 51.782682
A69: 家庭使用场景 | B69: 1 | C69: 0.0168 | D69: 0.11588691 | E69: 0.90997948 | F69: 7.8523059 | H69: 寻找电动发电机 | I69: 1 | J69: 0.0065 | K69: 0.045595172 | L69: 0.96803926 | M69: 21.231179 | Q69: 便携性 | R69: 1 | S69: 0.03792046 | T69: 0.020357841 | U69: 1.4568378 | V69: 71.561507 | X69: 应急电源 | Y69: 3 | Z69: 0.0015820474 | AA69: 0.014394311 | AB69: 0.52974346 | AC69: 36.80228
...

Sheet 词根
A1: 词根 | B1: 词频 | C1: 一级分类 | D1: 二级分类 | E1: 用户搜索意图标签 | F1: 否定
A2: thermometer | B2: 1523 | C2: 功能词 | D2: 电力 | E2: 电力驱动
A3: meat | B3: 640 | C3: 属性词 | D3: 便携性 | E3: 便携
A4: probe | B4: 502 | C4: 品名词 | D4: 电池包 | E4: 电池包
A5: gifts | B5: 451 | C5: 功能词 | D5: 充电器 | E5: 充电器
A6: men | B6: 316 | C6: 品名词 | D6: 电池 | E6: 电池
A7: kitchen | B7: 309 | C7: 功能词 | D7: 太阳能 | E7: 太阳能
A8: temperature | B8: 308 | C8: 品名词 | D8: 电源站 | E8: 电源站 | F8: X
A9: wireless | B9: 306 | C9: 品名词 | D9: 发电机 | E9: 发电机 | F9: X
A10: digital | B10: 297 | C10: 品名词 | D10: 手机
A11: grill | B11: 263 | C11: 品名词 | D11: 手机
A12: accessories | B12: 211 | C12: 场景词 | D12: 露营 | E12: 户外
A13: cooking | B13: 210 | C13: 属性词 | D13: 包装
A14: day | B14: 185 | C14: 品牌词
A15: gadgets | B15: 172 | C15: 场景词 | D15: 家庭 | E15: 家庭
A16: oven | B16: 151 | C16: 品牌词
A17: gift | B17: 134 | C17: 功能词 | D17: 充电 | E17: 充电 | F17: X
A18: smoker | B18: 133 | C18: 品名词 | D18: 发电机 | E18: 发电机
A19: valentines | B19: 127 | C19: 品牌词
A20: bbq | B20: 122 | C20: 功能词 | D20: 面板 | E20: 太阳能面板
A21: food | B21: 118 | C21: 功能词 | D21: 备份 | E21: 备份
A22: thermopro | B22: 116 | C22: 功能词 | D22: USB接口 | F22: X
A23: thermometers | B23: 107 | C23: 功能词 | D23: 电源插座 | E23: 电源插座 | F23: X
A24: chef | B24: 104 | C24: 功能词 | D24: 电力驱动 | E24: 电力驱动
A25: smart | B25: 102 | C25: 属性词 | D25: 快速
A26: best | B26: 101 | C26: 品名词 | D26: 专业版 | E26: 专业版
A27: bluetooth | B27: 94 | C27: 功能词 | D27: 供电 | E27: 备份 | F27: X
A28: probes | B28: 85 | C28: 品牌词
A29: temp | B29: 84 | C29: 场景词 | D29: 用途
A30: fryer | B30: 80 | C30: 品牌词
A31: air | B31: 74 | C31: 品名词 | D31: 电池单元
A32: mens | B32: 71 | C32: 功能词 | D32: 交流电 | E32: 交流电
A33: him | B33: 69 | C33: 品牌词
A34: instant | B34: 68 | C34: 场景词 | D34: 呼吸机
A35: deals | B35: 67 | C35: 功能词 | D35: 逆变器 | E35: 电力驱动
A36: grilling | B36: 67 | C36: 品名词 | D36: 充电器 | E36: 充电器 | F36: X
A37: read | B37: 65 | C37: 功能词 | D37: 功率单位
A38: outdoor | B38: 63 | C38: 品名词 | D38: 安卓设备 | F38: X
A39: wifi | B39: 58 | C39: 属性词 | D39: 最大
A40: items | B40: 49 | C40: 品名词 | D40: 便携式设备 | E40: 便携
...

Sheet 词库
A1: ABA | B1: 流量大小 | C1: 相关性 | D1: 有序性 | E1: 词组 | F1: 一级分类 | G1: 二级分类 | H1: 用户搜索意图标签 | I1: 流量% | J1: SPR | K1: 辅助列 | L1: 追踪 | M1: 关键词 | N1: 关键词翻译 | O1: AC推荐词 | P1: 流量占比 | Q1: 流量词类型 | R1: 预估周曝光量 | S1: 相关产品 | T1: 相关ASIN | U1: ABA周排名 | V1: 月搜索量 | W1: 月购买量 | X1: 购买率 | Y1: 展示量 | Z1: 点击量 | AA1: SPR | AB1: 标题密度 | AC1: 商品数 | AD1: 需供比 | AE1: 广告竞品数 | AF1: 点击集中度 | AG1: 前三ASIN转化总占比 | AH1: PPC竞价 | AI1: 建议竞价范围 | AJ1: #1 前三ASIN | AK1: #1 点击共享 | AL1: #1 转化共享 | AM1: #2 前三ASIN | AN1: #2 点击共享 | AO1: #2 转化共享 | AP1: #3 前三ASIN | AQ1: #3 点击共享 | AR1: #3 转化共享 | AS1: 前十ASIN | AT1: #3 转化共享 | AU1: 前十ASIN
A2: =W2 -> 53815 | B2: =IF(A2="","",IF(A2<词盘!$B$2,"大词",IF(A2<词盘!$C$2,"中尾词","长尾词"))) -> 中尾词 | C2: =IF(S2/20>70%,1,IF(S2/20>40%,2,IF(S2/20>10%,3,0))) -> 1 | D2: =IF(M2="","",IF(OR(E2="/",E2=""),"无序",IF(COUNTIFS(E:E,E2)<4,"无序","有序"))) -> 有序 | E2: meat thermometer | F2: 品名词 | H2: 寻找电源站类型或购买电源站 | I2: =P2/SUM(P:P) -> 0.14007004 | J2: =AC2 -> 4481 | K2: =IFERROR(Z2*AH2,"") -> 843354 | L2: V | M2: meat thermometer | N2: 肉类温度计 | O2: Y | P2: 0.14 | Q2: 自然搜索词/AC推荐词/SP广告词 | R2: 890313 | S2: 16 | T2: B0DDXWY41V/B005KCG6CE/B096K2L985/B0CRY9V6LL/B01F59K0KA/B0BBR2RL6X/B0C7D27GV8/B017613C3C/B0BQ782XNW/B01IHHLB3W/B0BJK5W11R/B00GRFHXVQ/B07XXSYLL8/B09LSGPHT3/B00S93EQUK/B0C37ZWPZR | U2: 1066 | V2: 472070 | W2: 53815 | X2: 0.114 | Y2: 12434912 | Z2: 187412 | AA2: 1220 | AB2: 64 | AC2: 4481 | AD2: 105.35 | AE2: 252 | AF2: 0.4101 | AG2: 0.4083 | AH2: 4.5 | AI2: $3.38 - $5.53 | AJ2: B00S93EQUK | AK2: 0.219 | AL2: 0.2336 | AM2: B09C32DYV1 | AN2: 0.1088 | AO2: 0.0974 | AP2: B09LSGPHT3 | AQ2: 0.0823 | AR2: 0.0773 | AS2: B00S93EQUK,B0DHZTCNR5,B07XXSYLL8,B0DC87RW4R,B0D9QW8L6H,B0DFH64CCP,B0DHVGDCK2,B0DJY2PWTY,B07Y51PCW7,B09LSGPHT3 | AT2: 0.0128 | AU2: B0BPNMT5DM,B07HY3S811,B0CL9SXSBD,B0B8V6Y2X8,B0BC6G9Q35,B0982TPZTW,B07W76MV4Y,B082K8ZNQ1,B07J63KGNN,B07CMJ5186
A3: =W3 -> 64612 | B3: =IF(A3="","",IF(A3<词盘!$B$2,"大词",IF(A3<词盘!$C$2,"中尾词","长尾词"))) -> 中尾词 | C3: =IF(S3/20>70%,1,IF(S3/20>40%,2,IF(S3/20>10%,3,0))) -> 2 | D3: =IF(M3="","",IF(OR(E3="/",E3=""),"无序",IF(COUNTIFS(E:E,E3)<4,"无序","有序"))) -> 无序 | F3: 品名词 | H3: 寻找便携式电源站 | I3: =P3/SUM(P:P) -> 0.11415708 | J3: =AC3 -> 25416 | K3: =IFERROR(Z3*AH3,"") -> 173028.63 | L3: V | M3: thermometer | N3: 温度计 | P3: 0.1141 | Q3: 自然搜索词/SP广告词 | R3: 725764 | S3: 13 | T3: B00GRFHXVQ/B0BQ782XNW/B07XXSYLL8/B09LSGPHT3/B01F59K0KA/B0BBR2RL6X/B00S93EQUK/B01IHHLB3W/B096K2L985/B0BJK5W11R/B0CRY9V6LL/B017613C3C/B0C7D27GV8 | U3: 478 | V3: 740119 | W3: 64612 | X3: 0.0873 | Y3: 20919624 | Z3: 303559 | AA3: 1465 | AB3: 77 | AC3: 25416 | AD3: 29.12 | AE3: 234 | AF3: 0.4903 | AG3: 0.4279 | AH3: 0.57 | AI3: $0.43 - $0.73 | AJ3: B0824XNJSW | AK3: 0.2672 | AL3: 0.2436 | AM3: B08B8BDG42 | AN3: 0.1346 | AO3: 0.1261 | AP3: B0CGRB23YM | AQ3: 0.0885 | AR3: 0.0582 | AS3: B0CRYX9PMK,B0D8J22Q45,B08B8BDG42,B0DC8MWQ8K,B0824XNJSW,B0D8TMK95V,B0DC8776HK,B08B7V2RG3,B0D9VZ1MWH,B0DD7KZD1G | AT3: 0.0327 | AU3: B0B8V6Y2X8,B07SRRQS5B,B0CXHY4R34,B0C1GQ54QD,B0CFF2JG1N,B0982TPZTW,B07HY3S811,B0CSN2CZQR,B0BVR8F5W3,B07XGMMXY2
A4: =W4 -> 2595 | B4: =IF(A4="","",IF(A4<词盘!$B$2,"大词",IF(A4<词盘!$C$2,"中尾词","长尾词"))) -> 大词 | C4: =IF(S4/20>70%,1,IF(S4/20>40%,2,IF(S4/20>10%,3,0))) -> 3 | D4: =IF(M4="","",IF(OR(E4="/",E4=""),"无序",IF(COUNTIFS(E:E,E4)<4,"无序","有序"))) -> 无序 | F4: 品名词 | H4: 寻找太阳能发电机 | I4: =P4/SUM(P:P) -> 0.065132566 | J4: =AC4 -> 163176 | K4: =IFERROR(Z4*AH4,"") -> 240882.52 | M4: kitchen | N4: 厨房 | P4: 0.0651 | Q4: 自然搜索词/HR推荐词/SP广告词 | R4: 414330 | S4: 7 | T4: B07XXSYLL8/B09LSGPHT3/B00S93EQUK/B01IHHLB3W/B0BJK5W11R/B096K2L985/B0CRY9V6LL | U4: 385 | V4: 540748 | W4: 2595 | X4: 0.0048 | Y4: 13489824 | Z4: 256258 | AA4: 59 | AB4: 59 | AC4: 163176 | AD4: 3.31 | AE4: 1419 | AF4: 0.0815 | AG4: 0.0464 | AH4: 0.94 | AI4: $0.74 - $1.15 | AJ4: B0C3QZ7SNF | AK4: 0.0296 | AL4: 0.0305 | AM4: B0DLGBRSFM | AN4: 0.0289 | AO4: 0 | AP4: B0BKRVT66L | AQ4: 0.023 | AR4: 0.0159 | AS4: B0C7CV5CQR,B0CQJWVP8B,B08573DQ39,B0CR1RHMJY,B0CTKTPKV8,B09N4ZKCH6,B0C7CXGBLZ,B0D2P1HSCV,B0D5L9BHX6,B01ACUA8HC | AT4: 0.0284 | AU4: B08YZ633BY,B0C6X2VP9R,B00I5H5Z1O,B0CC3SQL47,B0BGWZN7MV,B0BZWM3JG4,B07GKVBQDG,B0B7BFMHNF,B07L87GPPT,B0BQDHTCCR
A5: =W5 -> 34912 | B5: =IF(A5="","",IF(A5<词盘!$B$2,"大词",IF(A5<词盘!$C$2,"中尾词","长尾词"))) -> 中尾词 | C5: =IF(S5/20>70%,1,IF(S5/20>40%,2,IF(S5/20>10%,3,0))) -> 1 | D5: =IF(M5="","",IF(OR(E5="/",E5=""),"无序",IF(COUNTIFS(E:E,E5)<4,"无序","有序"))) -> 有序 | E5: meat thermometer | F5: 品牌词 | H5: 了解或购买Jackery品牌的电源产品 | I5: =P5/SUM(P:P) -> 0.059729865 | J5: =AC5 -> 2478 | K5: =IFERROR(Z5*AH5,"") -> 189768.96 | L5: V | M5: meat thermometer digital | N5: 数字式肉类温度计 | P5: 0.0597 | Q5: 自然搜索词 | R5: 379969 | S5: 15 | T5: B01F59K0KA/B0BBR2RL6X/B017613C3C/B0BJK5W11R/B01IHHLB3W/B0BQ782XNW/B00GRFHXVQ/B096K2L985/B07XXSYLL8/B09LSGPHT3/B0CRY9V6LL/B00S93EQUK/B005KCG6CE/B0C7D27GV8/B0DDXWY41V | U5: 2849 | V5: 227297 | W5: 34912 | X5: 0.1536 | Y5: 6331995 | Z5: 87856 | AA5: 792 | AB5: 27 | AC5: 2478 | AD5: 91.73 | AE5: 183 | AF5: 0.4501 | AG5: 0.4422 | AH5: 2.16 | AI5: $1.82 - $2.51 | AJ5: B00S93EQUK | AK5: 0.2546 | AL5: 0.2662 | AM5: B09C32DYV1 | AN5: 0.1141 | AO5: 0.1022 | AP5: B09LSGPHT3 | AQ5: 0.0814 | AR5: 0.0738 | AS5: B00S93EQUK,B07XXSYLL8,B07Y51PCW7,B017613C3C,B01IHHLB3W,B09LSGPHT3,B0BQ782XNW,B0C37DLHWW,B0DHZTCNR5,B0DFW43B44 | AT5: 0.0431 | AU5: B07SRRQS5B,B07HY3S811,B0B8V6Y2X8,B0982TPZTW,B0CFF2JG1N,B01DODMU9I,B0B75JF6CM,B09N71WGLF,B0C6X3VPLC,B0BXCKKNN8
A6: =W6 -> 10419 | B6: =IF(A6="","",IF(A6<词盘!$B$2,"大词",IF(A6<词盘!$C$2,"中尾词","长尾词"))) -> 大词 | C6: =IF(S6/20>70%,1,IF(S6/20>40%,2,IF(S6/20>10%,3,0))) -> 2 | D6: =IF(M6="","",IF(OR(E6="/",E6=""),"无序",IF(COUNTIFS(E:E,E6)<4,"无序","有序"))) -> 有序 | E6: food thermometer | F6: 品名词 | H6: 寻找便携式发电机 | I6: =P6/SUM(P:P) -> 0.031615808 | J6: =AC6 -> 6721 | K6: =IFERROR(Z6*AH6,"") -> 85210 | L6: V | M6: food thermometer | N6: 食品温度计 | P6: 0.0316 | Q6: 自然搜索词/SP广告词 | R6: 200766 | S6: 14 | T6: B005KCG6CE/B096K2L985/B01F59K0KA/B0BBR2RL6X/B017613C3C/B0BQ782XNW/B0BJK5W11R/B01IHHLB3W/B00GRFHXVQ/B07XXSYLL8/B09LSGPHT3/B0CRY9V6LL/B00S93EQUK/B0C7D27GV8 | U6: 10192 | V6: 98116 | W6: 10419 | X6: 0.1062 | Y6: 2737596 | Z6: 42605 | AA6: 237 | AB6: 38 | AC6: 6721 | AD6: 14.6 | AE6: 202 | AF6: 0.3447 | AG6: 0.3347 | AH6: 2 | AI6: $1.39 - $2.22 | AJ6: B00S93EQUK | AK6: 0.1834 | AL6: 0.1894 | AM6: B0BQ782XNW | AN6: 0.0858 | AO6: 0.0718 | AP6: B09LSGPHT3 | AQ6: 0.0755 | AR6: 0.0735 | AS6: B00S93EQUK,B01IHHLB3W,B07Y51PCW7,B09LSGPHT3,B07XXSYLL8,B0D9QW8L6H,B0C37DLHWW,B017613C3C,B0DHKM51RK,B08RWPPD8J | AT6: 0.0431 | AU6: B07SRRQS5B,B0B8V6Y2X8,B0CL9SXSBD,B01DODMU9I,B07HY3S811,B082K8ZNQ1,B07W76MV4Y,B00LB7REMS,B0CFF2JG1N,B07S59BW5F
A7: =W7 -> 9829 | B7: =IF(A7="","",IF(A7<词盘!$B$2,"大词",IF(A7<词盘!$C$2,"中尾词","长尾词"))) -> 大词 | C7: =IF(S7/20>70%,1,IF(S7/20>40%,2,IF(S7/20>10%,3,0))) -> 2 | D7: =IF(M7="","",IF(OR(E7="/",E7=""),"无序",IF(COUNTIFS(E:E,E7)<4,"无序","有序"))) -> 无序 | F7: 品牌词 | H7: 了解或购买Anker品牌的电源产品 | I7: =P7/SUM(P:P) -> 0.026013007 | J7: =AC7 -> 6961 | K7: =IFERROR(Z7*AH7,"") -> 57224.7 | L7: V | M7: cooking thermometer | N7: 烹饪温度计 | P7: 0.026 | Q7: 自然搜索词 | R7: 165473 | S7: 14 | T7: B0C7D27GV8/B005KCG6CE/B00GRFHXVQ/B096K2L985/B0CRY9V6LL/B01F59K0KA/B0BBR2RL6X/B0BJK5W11R/B017613C3C/B0BQ782XNW/B01IHHLB3W/B07XXSYLL8/B09LSGPHT3/B00S93EQUK | U7: 19194 | V7: 72759 | W7: 9829 | X7: 0.1351 | Y7: 1708167 | Z7: 28470 | AA7: 224 | AB7: 12 | AC7: 6961 | AD7: 10.45 | AE7: 179 | AF7: 0.3317 | AG7: 0.3229 | AH7: 2.01 | AI7: $1.59 - $2.25 | AJ7: B00S93EQUK | AK7: 0.1733 | AL7: 0.1951 | AM7: B09C32DYV1 | AN7: 0.0849 | AO7: 0.0712 | AP7: B0BQ782XNW | AQ7: 0.0735 | AR7: 0.0566 | AS7: B00S93EQUK,B07XXSYLL8,B07Y51PCW7,B0DFH64CCP,B01IHHLB3W,B017613C3C,B09LSGPHT3,B0B71HFH9K,B0D6YQ8LV2,B0DC8776HK | AT7: 0.0252 | AU7: B08YZ633BY,B0CL9YMRD5,B07MYW7C3Z,B07Z13H4TP,B09MQWWP87,B07SRRQS5B,B07CZDXDG8,B00I5H5Z1O,B0BN9DD956,B0B7BFMHNF
A8: =W8 -> 9881 | B8: =IF(A8="","",IF(A8<词盘!$B$2,"大词",IF(A8<词盘!$C$2,"中尾词","长尾词"))) -> 大词 | C8: =IF(S8/20>70%,1,IF(S8/20>40%,2,IF(S8/20>10%,3,0))) -> 1 | D8: =IF(M8="","",IF(OR(E8="/",E8=""),"无序",IF(COUNTIFS(E:E,E8)<4,"无序","有序"))) -> 无序 | F8: 功能词 | G8: 包括太阳能面板 | H8: 寻找带太阳能面板的太阳能发电机 | I8: =P8/SUM(P:P) -> 0.022011006 | J8: =AC8 -> 2188 | K8: =IFERROR(Z8*AH8,"") -> 53492 | M8: instant read thermometer | N8: 速读温度计 | P8: 0.022 | Q8: 自然搜索词 | R8: 139639 | S8: 15 | T8: B0DDXWY41V/B0BJK5W11R/B005KCG6CE/B096K2L985/B00GRFHXVQ/B01F59K0KA/B0CRY9V6LL/B0BBR2RL6X/B0BQ782XNW/B017613C3C/B01IHHLB3W/B07XXSYLL8/B09LSGPHT3/B00S93EQUK/B0C7D27GV8 | U8: 23593 | V8: 64331 | W8: 9881 | X8: 0.1536 | Y8: 1633185 | Z8: 31100 | AA8: 225 | AB8: 12 | AC8: 2188 | AD8: 29.4 | AE8: 158 | AF8: 0.4861 | AG8: 0.457 | AH8: 1.72 | AI8: $1.28 - $2.15 | AJ8: B00S93EQUK | AK8: 0.2701 | AL8: 0.2681 | AM8: B07XXSYLL8 | AN8: 0.1379 | AO8: 0.1157 | AP8: B09LSGPHT3 | AQ8: 0.0781 | AR8: 0.0732 | AS8: B0DG2YC3BW,B00S93EQUK,B07XXSYLL8,B0DG6FVVFN,B01IHHLB3W,B07Y51PCW7,B0DJY2PWTY,B08X6KHFMX,B09LSGPHT3,B0BBR2RL6X | AT8: 0.066 | AU8: B00LB7REFK,B01MXSZOKS,B0CFV5LZ3R,B07QHDRCZ3,B09YJ34W96,B079X5FTZR,B0C7F7LS8Z,B09BF7N5MT,B0BC6G9Q35,B0CX53FBSR
A9: =W9 -> 27793 | B9: =IF(A9="","",IF(A9<词盘!$B$2,"大词",IF(A9<词盘!$C$2,"中尾词","长尾词"))) -> 中尾词 | C9: =IF(S9/20>70%,1,IF(S9/20>40%,2,IF(S9/20>10%,3,0))) -> 2 | D9: =IF(M9="","",IF(OR(E9="/",E9=""),"无序",IF(COUNTIFS(E:E,E9)<4,"无序","有序"))) -> 无序 | F9: 品牌词 | H9: 了解或购买EcoFlow品牌电源产品 | I9: =P9/SUM(P:P) -> 0.021710855 | J9: =AC9 -> 3307 | K9: =IFERROR(Z9*AH9,"") -> 114072.96 | M9: oven thermometer | N9: 烤箱温度计 | P9: 0.0217 | Q9: 自然搜索词 | R9: 137749 | S9: 14 | T9: B0BBR2RL6X/B0BJK5W11R/B017613C3C/B005KCG6CE/B00GRFHXVQ/B0CRY9V6LL/B00S93EQUK/B01IHHLB3W/B07XXSYLL8/B09LSGPHT3/B096K2L985/B01F59K0KA/B0BQ782XNW/B0C7D27GV8 | U9: 6999 | V9: 155443 | W9: 27793 | X9: 0.1788 | Y9: 4046535 | Z9: 64448 | AA9: 630 | AB9: 36 | AC9: 3307 | AD9: 47 | AE9: 200 | AF9: 0.6982 | AG9: 0.6352 | AH9: 1.77 | AI9: $1.34 - $2.23 | AJ9: B083BMMQV9 | AK9: 0.4441 | AL9: 0.4444 | AM9: B005KDEIZ0 | AN9: 0.1404 | AO9: 0.0954 | AP9: B0000DJUYR | AQ9: 0.1137 | AR9: 0.0954 | AS9: B083BMMQV9,B0000DJUYR,B07YP9G4Z7,B0D6YQ8LV2,B017613C3C,B0CX19TQH1,B000BQWMTK,B09JSBXJDV,B08GY3K7KD,B0D3XLVZCP | AT9: 0.0164 | AU9: B07SRRQS5B,B07HY3S811,B0982TPZTW,B01DODMU9I,B09NFRC4LM,B0B75JF6CM,B0CFF2JG1N,B0C42FRFHG,B0B8V6Y2X8,B0BN9DD956
A10: =W10 -> 5334 | B10: =IF(A10="","",IF(A10<词盘!$B$2,"大词",IF(A10<词盘!$C$2,"中尾词","长尾词"))) -> 大词 | C10: =IF(S10/20>70%,1,IF(S10/20>40%,2,IF(S10/20>10%,3,0))) -> 2 | D10: =IF(M10="","",IF(OR(E10="/",E10=""),"无序",IF(COUNTIFS(E:E,E10)<4,"无序","有序"))) -> 无序 | F10: 场景词 | G10: 户外活动场景 | H10: 寻找适合户外活动的电源或设备 | I10: =P10/SUM(P:P) -> 0.020610305 | J10: =AC10 -> 10631 | K10: =IFERROR(Z10*AH10,"") -> 99923.34 | L10: V | M10: digital thermometer | N10: 数字温度计 | P10: 0.0206 | Q10: 自然搜索词 | R10: 130893 | S10: 13 | T10: B0CRY9V6LL/B017613C3C/B0BQ782XNW/B01IHHLB3W/B07XXSYLL8/B09LSGPHT3/B01F59K0KA/B00S93EQUK/B0BBR2RL6X/B00GRFHXVQ/B096K2L985/B0BJK5W11R/B0C7D27GV8 | U10: 10392 | V10: 85076 | W10: 5334 | X10: 0.0627 | Y10: 1921067 | Z10: 32978 | AA10: 121 | AB10: 17 | AC10: 10631 | AD10: 8 | AE10: 172 | AF10: 0.3826 | AG10: 0.3653 | AH10: 3.03 | AI10: $2.27 - $3.79 | AJ10: B0824XNJSW | AK10: 0.2111 | AL10: 0.2012 | AM10: B08B8BDG42 | AN10: 0.0944 | AO10: 0.0979 | AP10: B08B7V2RG3 | AQ10: 0.0771 | AR10: 0.0662 | AS10: B0D6RHCSCJ,B0824XNJSW,B08B8BDG42,B00S93EQUK,B0D8HY1YQM,B0CGRB23YM,B0DFLQQ2K7,B08B7V2RG3,B0DFM3S7VR,B07XXSYLL8 | AT10: 0.0354 | AU10: B07SRRQS5B,B0B8V6Y2X8,B0CL9SXSBD,B0995B8K8V,B0982TPZTW,B0B75JF6CM,B01MQQTB51,B0BXCKKNN8,B0BC6G9Q35,B07MXJ93K8
A11: =W11 -> 8676 | B11: =IF(A11="","",IF(A11<词盘!$B$2,"大词",IF(A11<词盘!$C$2,"中尾词","长尾词"))) -> 大词 | C11: =IF(S11/20>70%,1,IF(S11/20>40%,2,IF(S11/20>10%,3,0))) -> 2 | D11: =IF(M11="","",IF(OR(E11="/",E11=""),"无序",IF(COUNTIFS(E:E,E11)<4,"无序","有序"))) -> 有序 | E11: food thermometer | F11: 场景词 | G11: 户外活动必备品 | H11: 了解户外活动必备电源设备或其他装备 | I11: =P11/SUM(P:P) -> 0.017008504 | J11: =AC11 -> 4847 | K11: =IFERROR(Z11*AH11,"") -> 49106 | L11: V | M11: food thermometer for cooking | N11: 烹饪用食物温度计 | P11: 0.017 | Q11: 自然搜索词 | R11: 108140 | S11: 14 | T11: B0C7D27GV8/B005KCG6CE/B096K2L985/B00GRFHXVQ/B0BBR2RL6X/B017613C3C/B0BQ782XNW/B01IHHLB3W/B0BJK5W11R/B07XXSYLL8/B09LSGPHT3/B01F59K0KA/B0CRY9V6LL/B00S93EQUK | U11: 29589 | V11: 56487 | W11: 8676 | X11: 0.1536 | Y11: 1521326 | Z11: 24553 | AA11: 197 | AB11: 5 | AC11: 4847 | AD11: 11.65 | AE11: 124 | AF11: 0.4575 | AG11: 0.4119 | AH11: 2 | AI11: $1.40 - $2.32 | AJ11: B00S93EQUK | AK11: 0.2009 | AL11: 0.1901 | AM11: B09LSGPHT3 | AN11: 0.1636 | AO11: 0.1331 | AP11: B0DQDB5DRR | AQ11: 0.093 | AR11: 0.0887 | AS11: B00S93EQUK,B01IHHLB3W,B09LSGPHT3,B07XXSYLL8,B07Y51PCW7,B0C37DLHWW,B017613C3C,B09MTX71VX,B0B71HFH9K,B0BQ782XNW | AT11: 0.0203 | AU11: B079X5FTZR,B0BY3RK5CC,B07G5KHQGH,B079JYP5DP,B084YPVTXB,B0C5N9YYTY,B079X5XWXP,B07SRRQS5B,B0BWNXJ9QR,B082K8ZNQ1
A12: =W12 -> 8075 | B12: =IF(A12="","",IF(A12<词盘!$B$2,"大词",IF(A12<词盘!$C$2,"中尾词","长尾词"))) -> 大词 | C12: =IF(S12/20>70%,1,IF(S12/20>40%,2,IF(S12/20>10%,3,0))) -> 1 | D12: =IF(M12="","",IF(OR(E12="/",E12=""),"无序",IF(COUNTIFS(E:E,E12)<4,"无序","有序"))) -> 有序 | E12: meat thermometer | F12: 场景词 | G12: 家庭使用场景 | H12: 寻找家庭用发电机 | I12: =P12/SUM(P:P) -> 0.016808404 | J12: =AC12 -> 2490 | K12: =IFERROR(Z12*AH12,"") -> 63407.37 | M12: digital meat thermometer | N12: 数字式肉类温度计 | P12: 0.0168 | Q12: 自然搜索词 | R12: 107187 | S12: 15 | T12: B096K2L985/B0C7D27GV8/B0CRY9V6LL/B0BBR2RL6X/B017613C3C/B0BJK5W11R/B0BQ782XNW/B01IHHLB3W/B07XXSYLL8/B09LSGPHT3/B01F59K0KA/B00S93EQUK/B005KCG6CE/B00GRFHXVQ/B0DDXWY41V | U12: 23252 | V12: 69680 | W12: 8075 | X12: 0.1159 | Y12: 1787141 | Z12: 31863 | AA12: 184 | AB12: 18 | AC12: 2490 | AD12: 27.98 | AE12: 175 | AF12: 0.4705 | AG12: 0.4274 | AH12: 1.99 | AI12: $1.59 - $2.64 | AJ12: B00S93EQUK | AK12: 0.2455 | AL12: 0.2327 | AM12: B09C32DYV1 | AN12: 0.1197 | AO12: 0.0944 | AP12: B09LSGPHT3 | AQ12: 0.1053 | AR12: 0.1003 | AS12: B00S93EQUK,B07XXSYLL8,B07Y51PCW7,B09LSGPHT3,B017613C3C,B01IHHLB3W,B0BQ782XNW,B0DJY2PWTY,B0C37DLHWW,B0DG5LP1VK | AT12: 0.0036 | AU12: B08YZ633BY,B0CJB2KBJX,B01LXFSJY7,B0CGX538DK,B08S8RZ32R,B0CPDYVKPX,B0B7S213SX,B09DYN6SYR,B007BF7BUY,B00I5H5Z1O
A13: =W13 -> 8556 | B13: =IF(A13="","",IF(A13<词盘!$B$2,"大词",IF(A13<词盘!$C$2,"中尾词","长尾词"))) -> 大词 | C13: =IF(S13/20>70%,1,IF(S13/20>40%,2,IF(S13/20>10%,3,0))) -> 1 | D13: =IF(M13="","",IF(OR(E13="/",E13=""),"无序",IF(COUNTIFS(E:E,E13)<4,"无序","有序"))) -> 无序 | F13: 功能词 | G13: 太阳能发电 | H13: 寻找太阳能发电机 | I13: =P13/SUM(P:P) -> 0.016808404 | J13: =AC13 -> 1312 | K13: =IFERROR(Z13*AH13,"") -> 71401.9 | M13: candy thermometer | N13: 糖果温度计 | P13: 0.0168 | Q13: 自然搜索词 | R13: 107080 | S13: 16 | T13: B0DDXWY41V/B017613C3C/B01IHHLB3W/B07XXSYLL8/B09LSGPHT3/B0BBR2RL6X/B00S93EQUK/B0BQ782XNW/B0BJK5W11R/B005KCG6CE/B00GRFHXVQ/B01F59K0KA/B0CRY9V6LL/B096K2L985/B0C7D27GV8/B0DGXKNV6Y | U13: 10343 | V13: 121371 | W13: 8556 | X13: 0.0705 | Y13: 3178848 | Z13: 53285 | AA13: 194 | AB13: 39 | AC13: 1312 | AD13: 92.51 | AE13: 225 | AF13: 0.4028 | AG13: 0.3438 | AH13: 1.34 | AI13: $1.00 - $1.67 | AJ13: B094NBSRT4 | AK13: 0.1496 | AL13: 0.1331 | AM13: B098DSQHY9 | AN13: 0.139 | AO13: 0.1267 | AP13: B0DMNQZTR3 | AQ13: 0.1142 | AR13: 0.084 | AS13: B0DC8MWQ8K,B00004XSC9,B01CI50FJU,B0D89YR1W2,B0BGX4RG9B,B001FB6IFY,B0DC8776HK,B07YP9GT1N,B09QJJSZM5,B01BICCN6M | AT13: 0.0267 | AU13: B0C1GQ54QD,B0CSN2CZQR,B09964WTF5,B0CM6L37XR,B0CT5GCT24,B0CXHY4R34,B08CXGDZXD,B0C6G43SGX,B0BVR8F5W3,B0CP27G91Z
A14: =W14 -> 5461 | B14: =IF(A14="","",IF(A14<词盘!$B$2,"大词",IF(A14<词盘!$C$2,"中尾词","长尾词"))) -> 大词 | C14: =IF(S14/20>70%,1,IF(S14/20>40%,2,IF(S14/20>10%,3,0))) -> 2 | D14: =IF(M14="","",IF(OR(E14="/",E14=""),"无序",IF(COUNTIFS(E:E,E14)<4,"无序","有序"))) -> 无序 | F14: 功能词 | G14: 便携式发电机 | H14: 寻找便携式发电机 | I14: =P14/SUM(P:P) -> 0.016108054 | J14: =AC14 -> 7012 | K14: =IFERROR(Z14*AH14,"") -> 58588 | L14: V | M14: thermometer for cooking | N14: 烹饪温度计 | P14: 0.0161 | Q14: 自然搜索词 | R14: 102107 | S14: 14 | T14: B005KCG6CE/B096K2L985/B01F59K0KA/B017613C3C/B0BQ782XNW/B01IHHLB3W/B0BJK5W11R/B00GRFHXVQ/B07XXSYLL8/B09LSGPHT3/B0CRY9V6LL/B0BBR2RL6X/B00S93EQUK/B0C7D27GV8 | U14: 26839 | V14: 61638 | W14: 5461 | X14: 0.0886 | Y14: 1707180 | Z14: 29294 | AA14: 125 | AB14: 16 | AC14: 7012 | AD14: 8.79 | AE14: 177 | AF14: 0.2989 | AG14: 0.3046 | AH14: 2 | AI14: $1.58 - $2.27 | AJ14: B00S93EQUK | AK14: 0.1447 | AL14: 0.1692 | AM14: B09C32DYV1 | AN14: 0.0779 | AO14: 0.0631 | AP14: B0DQDB5DRR | AQ14: 0.0763 | AR14: 0.0723 | AS14: B00S93EQUK,B07XXSYLL8,B07Y51PCW7,B01IHHLB3W,B017613C3C,B0B71HFH9K,B09LSGPHT3,B09MTX71VX,B0C37DLHWW,B0BQ782XNW | AT14: 0.012 | AU14: B07SRRQS5B,B07VHPFK5B,B0B8V6Y2X8,B0CFV5LZ3R,B07HY3S811,B0982TPZTW,B0C6X25XQ3,B01IEJHJWK,B0BC6G9Q35,B0CFF2JG1N
A15: =W15 -> 5951 | B15: =IF(A15="","",IF(A15<词盘!$B$2,"大词",IF(A15<词盘!$C$2,"中尾词","长尾词"))) -> 大词 | C15: =IF(S15/20>70%,1,IF(S15/20>40%,2,IF(S15/20>10%,3,0))) -> 1 | D15: =IF(M15="","",IF(OR(E15="/",E15=""),"无序",IF(COUNTIFS(E:E,E15)<4,"无序","有序"))) -> 无序 | F15: 品牌词 | H15: 了解或购买Bluetti品牌的电源产品 | I15: =P15/SUM(P:P) -> 0.012606303 | J15: =AC15 -> 2804 | K15: =IFERROR(Z15*AH15,"") -> 26836.59 | M15: digital thermometer for cooking | N15: 烹饪用数字温度计 | P15: 0.0126 | Q15: 自然搜索词 | R15: 80468 | S15: 15 | T15: B096K2L985/B0CRY9V6LL/B0BBR2RL6X/B017613C3C/B0BJK5W11R/B0BQ782XNW/B01IHHLB3W/B0C7D27GV8/B00GRFHXVQ/B07XXSYLL8/B09LSGPHT3/B005KCG6CE/B01F59K0KA/B00S93EQUK/B0DDXWY41V | U15: 36126 | V15: 46866 | W15: 5951 | X15: 0.127 | Y15: 1063853 | Z15: 22179 | AA15: 135 | AB15: 0 | AC15: 2804 | AD15: 16.71 | AE15: 180 | AF15: 0.3822 | AG15: 0.3798 | AH15: 1.21 | AI15: $0.67 - $2.43 | AJ15: B00S93EQUK | AK15: 0.2041 | AL15: 0.2433 | AM15: B09C32DYV1 | AN15: 0.1034 | AO15: 0.0816 | AP15: B0DQDB5DRR | AQ15: 0.0747 | AR15: 0.0549 | AS15: B00S93EQUK,B07XXSYLL8,B07Y51PCW7,B017613C3C,B01IHHLB3W,B09LSGPHT3,B0B71HFH9K,B0C37DLHWW,B09MTX71VX,B09988SD2B | AT15: 0.0514 | AU15: B0CZDB93YR,B0CYBVYNRL,B0CYBV9Q6M,B01DODMU9I,B07WLPBPKM,B01MQQTB51,B0CRQJ23DH,B09PGQD7LS,B0D17C4VNX,B082K8ZNQ1
A16: =W16 -> 3688 | B16: =IF(A16="","",IF(A16<词盘!$B$2,"大词",IF(A16<词盘!$C$2,"中尾词","长尾词"))) -> 大词 | C16: =IF(S16/20>70%,1,IF(S16/20>40%,2,IF(S16/20>10%,3,0))) -> 2 | D16: =IF(M16="","",IF(OR(E16="/",E16=""),"无序",IF(COUNTIFS(E:E,E16)<4,"无序","有序"))) -> 无序 | F16: 品牌词 | H16: 了解或购买Bluetti品牌的电源产品 | I16: =P16/SUM(P:P) -> 0.012006003 | J16: =AC16 -> 58126 | K16: =IFERROR(Z16*AH16,"") -> 116108.69 | L16: V | M16: kitchen gadgets | N16: 厨房小工具 | P16: 0.012 | Q16: 自然搜索词/SP广告词 | R16: 76468 | S16: 10 | T16: B09LSGPHT3/B00S93EQUK/B07XXSYLL8/B0C7D27GV8/B017613C3C/B01F59K0KA/B01IHHLB3W/B096K2L985/B0BBR2RL6X/B0CRY9V6LL | U16: 3814 | V16: 400944 | W16: 3688 | X16: 0.0092 | Y16: 9701425 | Z16: 159053 | AA16: 84 | AB16: 27 | AC16: 58126 | AD16: 6.9 | AE16: 481 | AF16: 0.1517 | AG16: 0.0624 | AH16: 0.73 | AI16: $0.55 - $0.91 | AJ16: B0CJF94M8J | AK16: 0.0687 | AL16: 0.0518 | AM16: B0764HS4SL | AN16: 0.0493 | AO16: 0.0106 | AP16: B0D7CZ9Y7D | AQ16: 0.0337 | AR16: 0 | AS16: B08N9Q24M9,B0764HS4SL,B0C9ZQ434J,B08573DQ39,B07D15V7T3,B0C3H9MJQV,B0CLS1D1SY,B0DCGG1FDT,B0CJ4WZXQF,B07GTC4NCV | AT16: 0.0763 | AU16: B0CXTBZR2H,B0D1KDXFZJ,B0D17DB7SX,B07WLPBPKM,B0CZRC9F86,B01MQQTB51,B0D17C4VNX,B0CZDB93YR,B0D1XL2B6P,B0CYBRQ7FC
A17: =W17 -> 3659 | B17: =IF(A17="","",IF(A17<词盘!$B$2,"大词",IF(A17<词盘!$C$2,"中尾词","长尾词"))) -> 大词 | C17: =IF(S17/20>70%,1,IF(S17/20>40%,2,IF(S17/20>10%,3,0))) -> 1 | D17: =IF(M17="","",IF(OR(E17="/",E17=""),"无序",IF(COUNTIFS(E:E,E17)<4,"无序","有序"))) -> 有序 | E17: meat thermometer | F17: 属性词 | G17: 太阳能面板 | H17: 寻找太阳能面板 | I17: =P17/SUM(P:P) -> 0.0086043022 | J17: =AC17 -> 1378 | K17: =IFERROR(Z17*AH17,"") -> 24948.69 | L17: V | M17: instant read meat thermometer | N17: 速读肉温计 | P17: 0.0086 | Q17: 自然搜索词/SP广告词 | R17: 54748 | S17: 15 | T17: B0BJK5W11R/B005KCG6CE/B096K2L985/B01F59K0KA/B0CRY9V6LL/B0BBR2RL6X/B017613C3C/B0BQ782XNW/B01IHHLB3W/B00GRFHXVQ/B07XXSYLL8/B09LSGPHT3/B00S93EQUK/B0C7D27GV8/B0DDXWY41V | U17: 71611 | V17: 26288 | W17: 3659 | X17: 0.1392 | Y17: 708335 | Z17: 11289 | AA17: 83 | AB17: 32 | AC17: 1378 | AD17: 19.08 | AE17: 137 | AF17: 0.5153 | AG17: 0.5177 | AH17: 2.21 | AI17: $1.61 - $2.76 | AJ17: B00S93EQUK | AK17: 0.2634 | AL17: 0.2752 | AM17: B09LSGPHT3 | AN17: 0.1355 | AO17: 0.1172 | AP17: B0DHZTCNR5 | AQ17: 0.1164 | AR17: 0.1253 | AS17: B00S93EQUK,B07XXSYLL8,B0DJY2PWTY,B07Y51PCW7,B01IHHLB3W,B0DG5LP1VK,B09LSGPHT3,B0DHZTCNR5,B0BBR2RL6X,B0DKHVXLHW | AT17: 0.012 | AU17: B07SRRQS5B,B0CL9SXSBD,B0B8V6Y2X8,B07HY3S811,B0982TPZTW,B082K8ZNQ1,B01DODMU9I,B0CFF2JG1N,B0C9N2GH43,B00DZKQLZ0
A18: =W18 -> 3964 | B18: =IF(A18="","",IF(A18<词盘!$B$2,"大词",IF(A18<词盘!$C$2,"中尾词","长尾词"))) -> 大词 | C18: =IF(S18/20>70%,1,IF(S18/20>40%,2,IF(S18/20>10%,3,0))) -> 0 | D18: =IF(M18="","",IF(OR(E18="/",E18=""),"无序",IF(COUNTIFS(E:E,E18)<4,"无序","有序"))) -> 无序 | F18: 品牌词 | H18: 了解或购买Anker品牌的电源产品 | I18: =P18/SUM(P:P) -> 0.0082041021 | J18: =AC18 -> 197742 | K18: =IFERROR(Z18*AH18,"") -> 150343.83 | L18: V | M18: gifts for men | N18: 男士礼物 | O18: Y | P18: 0.0082 | Q18: 自然搜索词/AC推荐词/SP广告词 | R18: 51984 | S18: 2 | T18: B00S93EQUK/B01F59K0KA | U18: 2044 | V18: 333120 | W18: 3964 | X18: 0.0119 | Y18: 7022443 | Z18: 128499 | AA18: 90 | AB18: 18 | AC18: 197742 | AD18: 1.68 | AE18: 630 | AF18: 0.1052 | AG18: 0.0707 | AH18: 1.17 | AI18: $0.88 - $1.48 | AJ18: 1450845800 | AK18: 0.0431 | AL18: 0.0402 | AM18: B0D4215HCX | AN18: 0.0334 | AO18: 0.0181 | AP18: B0CRR1XXC4 | AQ18: 0.0287 | AR18: 0.0124 | AS18: B0B4X5SLKC,B0BKYR53JB,B0CZ7RQRQD,B0CZ7S666D,B0D84GSMR5,B0D94SF2P6,B0DBH99KYR,B07G142F9Z,B07S1BNNYD,B0CP9YF9W7 | AT18: 0.0113 | AU18: B07SRRQS5B,B0BPNMT5DM,B07HY3S811,B07P8NXQF4,B0BXN2WJ3D,B0982TPZTW,B0B8V6Y2X8,B0BC6G9Q35,B01DODMU9I,B01IEJHJWK
A19: =W19 -> 2749 | B19: =IF(A19="","",IF(A19<词盘!$B$2,"大词",IF(A19<词盘!$C$2,"中尾词","长尾词"))) -> 大词 | C19: =IF(S19/20>70%,1,IF(S19/20>40%,2,IF(S19/20>10%,3,0))) -> 1 | D19: =IF(M19="","",IF(OR(E19="/",E19=""),"无序",IF(COUNTIFS(E:E,E19)<4,"无序","有序"))) -> 无序 | F19: 场景词 | G19: 户外发电机场景 | H19: 寻找适合户外活动的电源或设备 | I19: =P19/SUM(P:P) -> 0.007803902 | J19: =AC19 -> 7489 | K19: =IFERROR(Z19*AH19,"") -> 22090.8 | M19: kitchen thermometer | N19: 厨房温度计 | P19: 0.0078 | Q19: 自然搜索词/SP广告词 | R19: 49804 | S19: 15 | T19: B0BJK5W11R/B005KCG6CE/B096K2L985/B0C7D27GV8/B01F59K0KA/B0CRY9V6LL/B017613C3C/B0BQ782XNW/B01IHHLB3W/B07XXSYLL8/B00GRFHXVQ/B09LSGPHT3/B0BBR2RL6X/B00S93EQUK/B0DDXWY41V | U19: 73086 | V19: 27470 | W19: 2749 | X19: 0.1001 | Y19: 817943 | Z19: 10776 | AA19: 63 | AB19: 3 | AC19: 7489 | AD19: 3.67 | AE19: 202 | AF19: 0.3377 | AG19: 0.2983 | AH19: 2.05 | AI19: $1.54 - $2.57 | AJ19: B00S93EQUK | AK19: 0.1421 | AL19: 0.1559 | AM19: B0C37DLHWW | AN19: 0.1004 | AO19: 0.061 | AP19: B09C32DYV1 | AQ19: 0.0952 | AR19: 0.0814 | AS19: B0D9VYW2Q9,B0D9VZ1MWH,B0DG2YC3BW,B00S93EQUK,B07XXSYLL8,B0C37DLHWW,B09LSGPHT3,B0D174XGXH,B07Y51PCW7,B017613C3C | AT19: 0.0068 | AU19: B0BQZBMXD4,B08YZ633BY,B00I5H5Z1O,B0B7BFMHNF,B07QK9C9KT,B095C7H62X,B007BF7BUY,B0BN9DD956,B0C5R981CT,B07MYW7C3Z
A20: =W20 -> 5405 | B20: =IF(A20="","",IF(A20<词盘!$B$2,"大词",IF(A20<词盘!$C$2,"中尾词","长尾词"))) -> 大词 | C20: =IF(S20/20>70%,1,IF(S20/20>40%,2,IF(S20/20>10%,3,0))) -> 3 | D20: =IF(M20="","",IF(OR(E20="/",E20=""),"无序",IF(COUNTIFS(E:E,E20)<4,"无序","有序"))) -> 无序 | F20: 功能词 | G20: 太阳能电站 | H20: 寻找太阳能发电机 | I20: =P20/SUM(P:P) -> 0.007803902 | J20: =AC20 -> 18127 | K20: =IFERROR(Z20*AH20,"") -> 42299.2 | M20: lightning deals of today prime | N20: 今日黄金闪电交易 | P20: 0.0078 | Q20: SP广告词 | R20: 49386 | S20: 7 | T20: B09LSGPHT3/B0C7D27GV8/B0BBR2RL6X/B01IHHLB3W/B0BQ782XNW/B00S93EQUK/B07XXSYLL8 | U20: 2246 | V20: 217078 | W20: 5405 | X20: 0.0249 | Y20: 4953036 | Z20: 105748 | AA20: 123 | AB20: 1 | AC20: 18127 | AD20: 11.98 | AE20: 1029 | AF20: 0.1149 | AG20: 0.0796 | AH20: 0.4 | AI20: $0.31 - $0.49 | AJ20: B0CFGYFCYL | AK20: 0.06 | AL20: 0.0259 | AM20: B0C7CQFZYM | AN20: 0.0314 | AO20: 0.0134 | AP20: B0BZ7S8QJW | AQ20: 0.0235 | AR20: 0.0403 | AS20: B01D944MIO,B00W5D1MDE,B09QKBBNCX,B0CFGYFCYL,B0DPFXHXSC,B081T7N948,B0DS5BRTT7,B0DSVLD1MF,B08PNYPL28,B0DRVRZF4V | AT20: 0.008 | AU20: B0B8V6Y2X8,B07SRRQS5B,B0BZCMDZNS,B07HXWPBRT,B08CXGDZXD,B0B776Y6JQ,B0C1GQ54QD,B0982TPZTW,B00B2LBNKM,B0CFF2JG1N
A21: =W21 -> 3306 | B21: =IF(A21="","",IF(A21<词盘!$B$2,"大词",IF(A21<词盘!$C$2,"中尾词","长尾词"))) -> 大词 | C21: =IF(S21/20>70%,1,IF(S21/20>40%,2,IF(S21/20>10%,3,0))) -> 2 | D21: =IF(M21="","",IF(OR(E21="/",E21=""),"无序",IF(COUNTIFS(E:E,E21)<4,"无序","有序"))) -> 无序 | F21: 品牌词 | H21: 了解或购买Jackery品牌的电源产品 | I21: =P21/SUM(P:P) -> 0.0069034517 | J21: =AC21 -> 351 | K21: =IFERROR(Z21*AH21,"") -> 219517.48 | M21: meater thermometer wireless | N21: 肉食温度计无线 | P21: 0.0069 | Q21: HR推荐词 | R21: 43648 | S21: 14 | T21: B0C37ZWPZR/B0C7D27GV8/B0CRY9V6LL/B017613C3C/B0BBR2RL6X/B01IHHLB3W/B07XXSYLL8/B09LSGPHT3/B01F59K0KA/B00S93EQUK/B00GRFHXVQ/B096K2L985/B0BJK5W11R/B0BQ782XNW | U21: 29631 | V21: 68884 | W21: 3306 | X21: 0.048 | Y21: 1525007 | Z21: 32473 | AA21: 75 | AB21: 0 | AC21: 351 | AD21: 196.25 | AE21: 128 | AF21: 0.6851 | AG21: 0.5993 | AH21: 6.76 | AI21: $5.05 - $7.75 | AJ21: B07H8WTFHW | AK21: 0.4397 | AL21: 0.3502 | AM21: B0D2LQGJ2V | AN21: 0.127 | AO21: 0.1582 | AP21: B07TJ95CBM | AQ21: 0.1184 | AR21: 0.0909 | AS21: B07H8WTFHW,B0CP8BPXKR,B07TJ95CBM,B07DZB6XZ6,B0BMLDL5GM,B0D5ZRJM51,B0D1TMFTPN,B0CRY9V6LL,B0D5M9RW7C,B08K2G5Y78 | AT21: 0 | AU21: B00L4Z0T2Y,B08FCSLZBY,B08FCSNXQ6,B01IEJHJWK,B0C4G2BPJ2,B0BC6G9Q35,B08FCSZ14H,B01MQQTB51,B07HXWPBRT,B07SRRQS5B
A22: =W22 -> 783 | B22: =IF(A22="","",IF(A22<词盘!$B$2,"大词",IF(A22<词盘!$C$2,"中尾词","长尾词"))) -> 大词 | C22: =IF(S22/20>70%,1,IF(S22/20>40%,2,IF(S22/20>10%,3,0))) -> 3 | D22: =IF(M22="","",IF(OR(E22="/",E22=""),"无序",IF(COUNTIFS(E:E,E22)<4,"无序","有序"))) -> 无序 | F22: 场景词 | G22: 便携式房屋场景 | H22: 了解或购买便携式房屋及电源产品 | I22: =P22/SUM(P:P) -> 0.0068034017 | J22: =AC22 -> 139900 | K22: =IFERROR(Z22*AH22,"") -> 20864.8 | L22: V | M22: kitchen accessories | N22: 厨房配件 | P22: 0.0068 | Q22: 自然搜索词/HR推荐词/SP广告词 | R22: 43553 | S22: 7 | T22: B07XXSYLL8/B00S93EQUK/B01F59K0KA/B0CRY9V6LL/B01IHHLB3W/B096K2L985/B0BBR2RL6X | U22: 8978 | V22: 126356 | W22: 783 | X22: 0.0062 | Y22: 3559977 | Z22: 52162 | AA22: 18 | AB22: 1 | AC22: 139900 | AD22: 0.9 | AE22: 666 | AF22: 0.1456 | AG22: 0.0689 | AH22: 0.4 | AI22: $0.37 - $0.50 | AJ22: B0C3QZ7SNF | AK22: 0.0591 | AL22: 0.0345 | AM22: B0C2Y3T5LN | AN22: 0.0444 | AO22: 0.0172 | AP22: B0BKRVT66L | AQ22: 0.0421 | AR22: 0.0172 | AS22: B0BLSM37FJ,B0C3QZ7SNF,B0D93Y27ZR,B0D9H27SPR,B0C3H9MJQV,B0D6V87HQR,B0D95TCPLP,B09Z65MVY5,B0D832C56W,B0D83SZT1W | AT22: 0.0108 | AU22: B07PJG4FBM,B0B9VGMLZR,B082WJMM5H,B0C33V7QSW,B0C3D6D5VC,B07TRMF56R,B09H2CLPHT,B01DOE0DO6,B0CLRZ7L29,B0CJF9LBQL
A23: =W23 -> 1946 | B23: =IF(A23="","",IF(A23<词盘!$B$2,"大词",IF(A23<词盘!$C$2,"中尾词","长尾词"))) -> 大词 | C23: =IF(S23/20>70%,1,IF(S23/20>40%,2,IF(S23/20>10%,3,0))) -> 2 | D23: =IF(M23="","",IF(OR(E23="/",E23=""),"无序",IF(COUNTIFS(E:E,E23)<4,"无序","有序"))) -> 有序 | E23: meat thermometer | F23: 品牌词 | H23: 了解或购买EcoFlow品牌电源产品 | I23: =P23/SUM(P:P) -> 0.0066033017 | J23: =AC23 -> 915 | K23: =IFERROR(Z23*AH23,"") | M23: meat thermometer digital wireless | N23: 肉类温度计数字无线 | P23: 0.0066 | Q23: 自然搜索词 | R23: 41814 | S23: 14 | T23: B0CRY9V6LL/B017613C3C/B0BJK5W11R/B01IHHLB3W/B00GRFHXVQ/B07XXSYLL8/B09LSGPHT3/B01F59K0KA/B0BBR2RL6X/B00S93EQUK/B0C7D27GV8/B0BQ782XNW/B005KCG6CE/B096K2L985 | U23: 56667 | V23: 36929 | W23: 1946 | X23: 0.0527 | Y23: 800632 | Z23: 16577 | AA23: 45 | AB23: 5 | AC23: 915 | AD23: 40.36 | AE23: 150 | AF23: 0.3045 | AG23: 0.3179 | AI23: - | AJ23: B00S93EQUK | AK23: 0.1533 | AL23: 0.2393 | AM23: B0D5M9RW7C | AN23: 0.0854 | AO23: 0.0536 | AP23: B07H8WTFHW | AQ23: 0.0658 | AR23: 0.025 | AS23: B07H8WTFHW,B0DG5LP1VK,B0D5M9RW7C,B08K2G5Y78,B0B48NL6L8,B0BMLDL5GM,B0D2LQGJ2V,B0CRY9V6LL,B0DPCHVMNP,B0D9JBL8NG | AT23: 0.0079 | AU23: B07SRRQS5B,B07HY3S811,B0982TPZTW,B0B8V6Y2X8,B0BZCMDZNS,B0CFF2JG1N,B082K8ZNQ1,B0BXCKKNN8,B00DZKQLZ0,B0C6YGZ4B6
A24: =W24 -> 1018 | B24: =IF(A24="","",IF(A24<词盘!$B$2,"大词",IF(A24<词盘!$C$2,"中尾词","长尾词"))) -> 大词 | C24: =IF(S24/20>70%,1,IF(S24/20>40%,2,IF(S24/20>10%,3,0))) -> 2 | D24: =IF(M24="","",IF(OR(E24="/",E24=""),"无序",IF(COUNTIFS(E:E,E24)<4,"无序","有序"))) -> 无序 | F24: 功能词 | G24: 电池发电机 | H24: 寻找电池发电机 | I24: =P24/SUM(P:P) -> 0.0065032516 | J24: =AC24 -> 225 | K24: =IFERROR(Z24*AH24,"") -> 160340 | M24: thermapen | N24: 热敏笔 | P24: 0.0065 | Q24: 自然搜索词 | R24: 41511 | S24: 13 | T24: B0BJK5W11R/B00GRFHXVQ/B01F59K0KA/B0CRY9V6LL/B0BBR2RL6X/B01IHHLB3W/B0BQ782XNW/B07XXSYLL8/B00S93EQUK/B017613C3C/B096K2L985/B09LSGPHT3/B0DDXWY41V | U24: 70119 | V24: 34889 | W24: 1018 | X24: 0.0292 | Y24: 889363 | Z24: 16034 | AA24: 24 | AB24: 7 | AC24: 225 | AD24: 155.06 | AE24: 30 | AF24: 0.6541 | AG24: 0.3978 | AH24: 10 | AI24: $9.00 - $11.00 | AJ24: B0DC8MWQ8K | AK24: 0.4674 | AL24: 0.2513 | AM24: B0DC8776HK | AN24: 0.099 | AO24: 0.0366 | AP24: B07XXSYLL8 | AQ24: 0.0877 | AR24: 0.1099 | AS24: B0DC8FWCDT,B0DC8MWQ8K,B07XXSYLL8,B0BBR2RL6X,B0DC82YRDW,B00S93EQUK,B0DC8FD41B,B07R18W3W1,B0DJY2PWTY,B07Y51PCW7 | AT24: 0.0068 | AU24: B0B9V8KN72,B07PJG4FBM,B082WJMM5H,B0C33TRJ48,B01DOE0DO6,B09RWN11T5,B0928K23P6,B07TRMF56R,B0CWLV8TMK,B0BYV8MFNN
A25: =W25 -> 1798 | B25: =IF(A25="","",IF(A25<词盘!$B$2,"大词",IF(A25<词盘!$C$2,"中尾词","长尾词"))) -> 大词 | C25: =IF(S25/20>70%,1,IF(S25/20>40%,2,IF(S25/20>10%,3,0))) -> 2 | D25: =IF(M25="","",IF(OR(E25="/",E25=""),"无序",IF(COUNTIFS(E:E,E25)<4,"无序","有序"))) -> 无序 | F25: 功能词 | G25: 电动发电机 | H25: 寻找电动发电机 | I25: =P25/SUM(P:P) -> 0.0065032516 | J25: =AC25 -> 6743 | K25: =IFERROR(Z25*AH25,"") -> 38173.66 | L25: V | M25: termometro digital | N25: 数字温度计 | P25: 0.0065 | Q25: 自然搜索词 | R25: 41166 | S25: 12 | T25: B096K2L985/B017613C3C/B0BQ782XNW/B07XXSYLL8/B00S93EQUK/B01IHHLB3W/B09LSGPHT3/B01F59K0KA/B0BBR2RL6X/B0C7D27GV8/B00GRFHXVQ/B0CRY9V6LL | U25: 39573 | V25: 39434 | W25: 1798 | X25: 0.0456 | Y25: 895114 | Z25: 15029 | AA25: 41 | AB25: 0 | AC25: 6743 | AD25: 5.85 | AE25: 108 | AF25: 0.4124 | AG25: 0.3497 | AH25: 2.54 | AI25: $1.90 - $3.19 | AJ25: B0824XNJSW | AK25: 0.2125 | AL25: 0.2023 | AM25: B0CGRB23YM | AN25: 0.1174 | AO25: 0.0838 | AP25: B08B8BDG42 | AQ25: 0.0825 | AR25: 0.0636 | AS25: B0824XNJSW,B0CGRB23YM,B0CTCPQ6N9,B08B8BDG42,B087FR1272,B08B7V2RG3,B0C3B2VZLJ,B0DM5SKGL2,B08MT3D361,B00MUK6M82 | AT25: 0.0686 | AU25: B07SRRQS5B,B0B7Z2MRWY,B07VHPFK5B,B01DODMU9I,B0CGD6Q656,B082K8ZNQ1,B0CL6CXMGZ,B07MXJ93K8,B01IEJHJWK,B00LB7REFK
A26: =W26 -> 5187 | B26: =IF(A26="","",IF(A26<词盘!$B$2,"大词",IF(A26<词盘!$C$2,"中尾词","长尾词"))) -> 大词 | C26: =IF(S26/20>70%,1,IF(S26/20>40%,2,IF(S26/20>10%,3,0))) -> 0 | D26: =IF(M26="","",IF(OR(E26="/",E26=""),"无序",IF(COUNTIFS(E:E,E26)<4,"无序","有序"))) -> 无序 | F26: 品名词 | H26: 寻找电池包或购买电池包 | I26: =P26/SUM(P:P) -> 0.0055027514 | J26: =AC26 -> 154561 | K26: =IFERROR(Z26*AH26,"") -> 149905.93 | M26: birthday gifts for men | N26: 男士生日礼物 | P26: 0.0055 | Q26: 自然搜索词/SP广告词 | R26: 34807 | S26: 1 | T26: B00S93EQUK | U26: 3291 | V26: 296423 | W26: 5187 | X26: 0.0175 | Y26: 8476656 | Z26: 140099 | AA26: 120 | AB26: 13 | AC26: 154561 | AD26: 1.92 | AE26: 438 | AF26: 0.1479 | AG26: 0.1091 | AH26: 1.07 | AI26: $0.80 - $1.34 | AJ26: B0CPPSGC6H | AK26: 0.071 | AL26: 0.0499 | AM26: 1450845800 | AN26: 0.0436 | AO26: 0.035 | AP26: B0C1ZXGQRH | AQ26: 0.0333 | AR26: 0.0242 | AS26: B0BJXRWWHX,B06XZTZ7GB,B01HRCU3SW,1957590424,1648451217,B0CPPSGC6H,B06XFY5NZW,B0CLGHVWVQ,B07NPGMDW8,B0B1VM1C6L | AT26: 0.017 | AU26: B07SRRQS5B,B07VHPFK5B,B082K8ZNQ1,B01DODMU9I,B0CRQJ23DH,B09B4Y89F8,B00LB7REBE,B0B7Z2MRWY,B0CFF2JG1N,B0BC6JDHVR
A27: =W27 -> 2274 | B27: =IF(A27="","",IF(A27<词盘!$B$2,"大词",IF(A27<词盘!$C$2,"中尾词","长尾词"))) -> 大词 | C27: =IF(S27/20>70%,1,IF(S27/20>40%,2,IF(S27/20>10%,3,0))) -> 2 | D27: =IF(M27="","",IF(OR(E27="/",E27=""),"无序",IF(COUNTIFS(E:E,E27)<4,"无序","有序"))) -> 有序 | E27: food thermometer | F27: 品牌词 | H27: 了解或购买Jackery品牌的电源产品 | I27: =P27/SUM(P:P) -> 0.0055027514 | J27: =AC27 -> 2902 | K27: =IFERROR(Z27*AH27,"") -> 18550.62 | M27: digital food thermometer | N27: 数字式食品温度计 | P27: 0.0055 | Q27: 自然搜索词 | R27: 34697 | S27: 14 | T27: B005KCG6CE/B096K2L985/B01F59K0KA/B0C7D27GV8/B0BBR2RL6X/B017613C3C/B0BJK5W11R/B0BQ782XNW/B01IHHLB3W/B07XXSYLL8/B09LSGPHT3/B0CRY9V6LL/B00S93EQUK/B0DDXWY41V | U27: 99295 | V27: 18781 | W27: 2274 | X27: 0.1211 | Y27: 473846 | Z27: 9369 | AA27: 52 | AB27: 8 | AC27: 2902 | AD27: 6.47 | AE27: 54 | AF27: 0.349 | AG27: 0.3103 | AH27: 1.98 | AI27: $1.45 - $2.27 | AJ27: B00S93EQUK | AK27: 0.1806 | AL27: 0.1609 | AM27: B09C32DYV1 | AN27: 0.0885 | AO27: 0.0843 | AP27: B09LSGPHT3 | AQ27: 0.0799 | AR27: 0.0651 | AS27: B00S93EQUK,B07XXSYLL8,B09LSGPHT3,B01IHHLB3W,B07Y51PCW7,B0BQ782XNW,B0C37DLHWW,B017613C3C,B09MTX71VX,B0B71HFH9K | AT27: 0.0403 | AU27: B0BVR8F5W3,B0D2W5JK16,B09964WTF5,B0CSN2CZQR,B08CXGDZXD,B0C7QRSLD9,B0D25ZZ8DL,B09S5TZH5N,B0CHPB2719,B0C8587TZP
A28: =W28 -> 4327 | B28: =IF(A28="","",IF(A28<词盘!$B$2,"大词",IF(A28<词盘!$C$2,"中尾词","长尾词"))) -> 大词 | C28: =IF(S28/20>70%,1,IF(S28/20>40%,2,IF(S28/20>10%,3,0))) -> 2 | D28: =IF(M28="","",IF(OR(E28="/",E28=""),"无序",IF(COUNTIFS(E:E,E28)<4,"无序","有序"))) -> 无序 | F28: 品牌词 | H28: 了解或购买EcoFlow品牌电源产品 | I28: =P28/SUM(P:P) -> 0.0053026513 | J28: =AC28 -> 4005 | K28: =IFERROR(Z28*AH28,"") -> 14775 | L28: V | M28: cooking thermometer for meat | N28: 肉类烹饪温度计 | P28: 0.0053 | Q28: 自然搜索词 | R28: 33467 | S28: 14 | T28: B0C7D27GV8/B005KCG6CE/B00GRFHXVQ/B01F59K0KA/B0CRY9V6LL/B0BBR2RL6X/B017613C3C/B0BQ782XNW/B0BJK5W11R/B01IHHLB3W/B096K2L985/B07XXSYLL8/B09LSGPHT3/B00S93EQUK | U28: 121810 | V28: 16343 | W28: 4327 | X28: 0.2648 | Y28: 399317 | Z28: 7500 | AA28: 99 | AB28: 0 | AC28: 4005 | AD28: 4.08 | AE28: 60 | AF28: 0.4336 | AG28: 0.4554 | AH28: 1.97 | AI28: $1.35 - $2.36 | AJ28: B00S93EQUK | AK28: 0.2463 | AL28: 0.2681 | AM28: B09LSGPHT3 | AN28: 0.1326 | AO28: 0.1277 | AP28: B09C32DYV1 | AQ28: 0.0547 | AR28: 0.0596 | AS28: B00S93EQUK,B017613C3C,B07XXSYLL8,B07Y51PCW7,B09LSGPHT3,B0BQ782XNW,B0C37DLHWW,B01IHHLB3W,B01CI4ZYMO,B07477NMF4 | AT28: 0.1074 | AU28: B07CMFWXS6,B09KLVZ88T,B00NM9HO3W,B07VHPFK5B,B092DGF3FK,B088DQDFL1,B00B4S6SLW,B0BM9H6H62,B08N6Z4B75,B01DODMU9I
A29: =W29 -> 1838 | B29: =IF(A29="","",IF(A29<词盘!$B$2,"大词",IF(A29<词盘!$C$2,"中尾词","长尾词"))) -> 大词 | C29: =IF(S29/20>70%,1,IF(S29/20>40%,2,IF(S29/20>10%,3,0))) -> 1 | D29: =IF(M29="","",IF(OR(E29="/",E29=""),"无序",IF(COUNTIFS(E:E,E29)<4,"无序","有序"))) -> 有序 | E29: meat thermometer | F29: 场景词 | G29: 户外装备场景 | H29: 了解户外活动必备电源设备或其他装备 | I29: =P29/SUM(P:P) -> 0.0049024512 | J29: =AC29 -> 1041 | K29: =IFERROR(Z29*AH29,"") -> 205001.83 | L29: V | M29: wireless meat thermometer | N29: 无线肉类温度计 | P29: 0.0049 | Q29: 自然搜索词 | R29: 31290 | S29: 15 | T29: B0C37ZWPZR/B0CRY9V6LL/B0C7D27GV8/B017613C3C/B07XXSYLL8/B09LSGPHT3/B096K2L985/B005KCG6CE/B0BBR2RL6X/B0BJK5W11R/B00S93EQUK/B01F59K0KA/B01IHHLB3W/B0BQ782XNW/B00GRFHXVQ | U29: 27653 | V29: 63192 | W29: 1838 | X29: 0.0291 | Y29: 1743232 | Z29: 29161 | AA29: 42 | AB29: 56 | AC29: 1041 | AD29: 60.7 | AE29: 153 | AF29: 0.2635 | AG29: 0.2211 | AH29: 7.03 | AI29: $4.48 - $7.80 | AJ29: B0DWK2RMWY | AK29: 0.0909 | AL29: 0.103 | AM29: B0D5M9RW7C | AN29: 0.0882 | AO29: 0.0578 | AP29: B0DFNR55LB | AQ29: 0.0844 | AR29: 0.0603 | AS29: B07H8WTFHW,B0D5M9RW7C,B0BMLDL5GM,B0D2LQGJ2V,B0CRY9V6LL,B0B48NL6L8,B0D9QW8L6H,B08K2G5Y78,B0DCG67Z7Q,B0DK9BMDB1 | AT29: 0.0157 | AU29: B08YZ2K3PV,B0B7BP6CJN,B0CJB2KBJX,B0BN4Z47CK,B01LXFSJY7,B0BQ7PD5YW,B00I5H5Z1O,B07MVKJLHV,B0BX8NQBJS,B0B7X8CWZM
A30: =W30 -> 2018 | B30: =IF(A30="","",IF(A30<词盘!$B$2,"大词",IF(A30<词盘!$C$2,"中尾词","长尾词"))) -> 大词 | C30: =IF(S30/20>70%,1,IF(S30/20>40%,2,IF(S30/20>10%,3,0))) -> 2 | D30: =IF(M30="","",IF(OR(E30="/",E30=""),"无序",IF(COUNTIFS(E:E,E30)<4,"无序","有序"))) -> 有序 | E30: meat thermometer | F30: 品牌词 | H30: 了解或购买Anker品牌的电源产品 | I30: =P30/SUM(P:P) -> 0.0049024512 | J30: =AC30 -> 773 | K30: =IFERROR(Z30*AH30,"") -> 13530.88 | M30: thermopro digital meat thermometer | N30: Thermopro 数字肉类温度计 | P30: 0.0049 | Q30: 自然搜索词 | R30: 31188 | S30: 14 | T30: B0BJK5W11R/B096K2L985/B0CRY9V6LL/B0C7D27GV8/B0BBR2RL6X/B017613C3C/B01IHHLB3W/B07XXSYLL8/B09LSGPHT3/B01F59K0KA/B00S93EQUK/B0BQ782XNW/B005KCG6CE/B00GRFHXVQ | U30: 107677 | V30: 25166 | W30: 2018 | X30: 0.0802 | Y30: 553203 | Z30: 10912 | AA30: 46 | AB30: 0 | AC30: 773 | AD30: 32.56 | AE30: 106 | AF30: 0.4038 | AG30: 0.4061 | AH30: 1.24 | AI30: $0.79 - $2.49 | AJ30: B07XXSYLL8 | AK30: 0.2542 | AL30: 0.3152 | AM30: B0CJLNCYG6 | AN30: 0.0879 | AO30: 0.0364 | AP30: B01IHHLB3W | AQ30: 0.0617 | AR30: 0.0545 | AS30: B07XXSYLL8,B017613C3C,B0B48NL6L8,B0BMLDL5GM,B08K2G5Y78,B0CRY9V6LL,B08KZR4F23,B07Y51PCW7,B01IHHLB3W,B0BBR2RL6X | AT30: 0.027 | AU30: B0BPNMT5DM,B07P8NXQF4,B0BSTWKSDX,B0CC54BQVY,B09NV5M55S,B0B8V6Y2X8,B07C85S2PV,B0CHVWVK3C,B0BV6ZR4GL,B0BXN2WJ3D
A31: =W31 -> 2667 | B31: =IF(A31="","",IF(A31<词盘!$B$2,"大词",IF(A31<词盘!$C$2,"中尾词","长尾词"))) -> 大词 | C31: =IF(S31/20>70%,1,IF(S31/20>40%,2,IF(S31/20>10%,3,0))) -> 2 | D31: =IF(M31="","",IF(OR(E31="/",E31=""),"无序",IF(COUNTIFS(E:E,E31)<4,"无序","有序"))) -> 无序 | F31: 品牌词 | H31: 了解或购买EcoFlow品牌电源产品 | I31: =P31/SUM(P:P) -> 0.0048024012 | J31: =AC31 -> 503 | K31: =IFERROR(Z31*AH31,"") -> 16025.31 | L31: V | M31: oil thermometer for frying | N31: 油炸用油温计 | P31: 0.0048 | Q31: 自然搜索词 | R31: 30677 | S31: 14 | T31: B0BQ782XNW/B01IHHLB3W/B0BJK5W11R/B005KCG6CE/B07XXSYLL8/B09LSGPHT3/B0C7D27GV8/B01F59K0KA/B0CRY9V6LL/B0BBR2RL6X/B00S93EQUK/B017613C3C/B00GRFHXVQ/B096K2L985 | U31: 74249 | V31: 22764 | W31: 2667 | X31: 0.1172 | Y31: 591870 | Z31: 8757 | AA31: 61 | AB31: 3 | AC31: 503 | AD31: 45.26 | AE31: 129 | AF31: 0.5133 | AG31: 0.4285 | AH31: 1.83 | AI31: $1.37 - $2.28 | AJ31: B01N7KIDW0 | AK31: 0.2249 | AL31: 0.2381 | AM31: B0BGX4RG9B | AN31: 0.1508 | AO31: 0.1245 | AP31: B098DSQHY9 | AQ31: 0.1376 | AR31: 0.0659 | AS31: B01N7KIDW0,B0BGX4RG9B,B00004XSC9,B0B71HFH9K,B07H9RFNVC,B0C8254GJM,B094V3R7H8,B07YP9GT1N,B088DTK1QZ,B01CI50FJU | AT31: 0.0184 | AU31: B07SRRQS5B,B0B8V6Y2X8,B0982TPZTW,B0CFF2JG1N,B0B7Z2MRWY,B00DZKQLZ0,B0BC6G9Q35,B07MNW4VMY,B00B2KV5D8,B0995B8K8V
A32: =W32 -> 3788 | B32: =IF(A32="","",IF(A32<词盘!$B$2,"大词",IF(A32<词盘!$C$2,"中尾词","长尾词"))) -> 大词 | C32: =IF(S32/20>70%,1,IF(S32/20>40%,2,IF(S32/20>10%,3,0))) -> 2 | D32: =IF(M32="","",IF(OR(E32="/",E32=""),"无序",IF(COUNTIFS(E:E,E32)<4,"无序","有序"))) -> 无序 | F32: 品牌词 | H32: 了解或购买Anker品牌的电源产品 | I32: =P32/SUM(P:P) -> 0.0048024012 | J32: =AC32 -> 1328 | K32: =IFERROR(Z32*AH32,"") | M32: instant read thermometer for cooking | N32: 即时读取烹饪温度计 | P32: 0.0048 | Q32: 自然搜索词 | R32: 30229 | S32: 14 | T32: B005KCG6CE/B00GRFHXVQ/B096K2L985/B01F59K0KA/B0BBR2RL6X/B0BJK5W11R/B017613C3C/B0BQ782XNW/B01IHHLB3W/B09LSGPHT3/B07XXSYLL8/B0CRY9V6LL/B00S93EQUK/B0C7D27GV8 | U32: 121604 | V32: 18065 | W32: 3788 | X32: 0.2097 | Y32: 476243 | Z32: 7861 | AA32: 86 | AB32: 1 | AC32: 1328 | AD32: 13.6 | AE32: 20 | AF32: 0.4853 | AG32: 0.4545 | AI32: - | AJ32: B00S93EQUK | AK32: 0.2647 | AL32: 0.2314 | AM32: B09LSGPHT3 | AN32: 0.1408 | AO32: 0.157 | AP32: B07XXSYLL8 | AQ32: 0.0798 | AR32: 0.0661 | AS32: B00S93EQUK,B07XXSYLL8,B07Y51PCW7,B01IHHLB3W,B0DJY2PWTY,B09LSGPHT3,B0C37DLHWW,B0DG5LP1VK,B0DG5KDHS8,B0BQ782XNW | AT32: 0.082 | AU32: B07SRRQS5B,B082K8ZNQ1,B01DODMU9I,B0BC6G9Q35,B0C6YGZ4B6,B00LB7REFK,B0B7Z2MRWY,B0CXT9W574,B07W76MV4Y,B00L4Z0T2Y
A33: =W33 -> 814 | B33: =IF(A33="","",IF(A33<词盘!$B$2,"大词",IF(A33<词盘!$C$2,"中尾词","长尾词"))) -> 大词 | C33: =IF(S33/20>70%,1,IF(S33/20>40%,2,IF(S33/20>10%,3,0))) -> 2 | D33: =IF(M33="","",IF(OR(E33="/",E33=""),"无序",IF(COUNTIFS(E:E,E33)<4,"无序","有序"))) -> 无序 | F33: 品牌词 | H33: 了解或购买Jackery品牌的电源产品 | I33: =P33/SUM(P:P) -> 0.0046023012 | J33: =AC33 -> 532 | K33: =IFERROR(Z33*AH33,"") -> 17377.08 | L33: V | M33: thermopro | N33: 暖气片 | P33: 0.0046 | Q33: 自然搜索词/SP广告词 | R33: 29327 | S33: 10 | T33: B0BJK5W11R/B096K2L985/B0CRY9V6LL/B0BBR2RL6X/B017613C3C/B01IHHLB3W/B07XXSYLL8/B09LSGPHT3/B00S93EQUK/B01F59K0KA | U33: 80317 | V33: 28574 | W33: 814 | X33: 0.0285 | Y33: 712999 | Z33: 11508 | AA33: 19 | AB33: 72 | AC33: 532 | AD33: 53.71 | AE33: 51 | AF33: 0.3429 | AG33: 0.2917 | AH33: 1.51 | AI33: $1.13 - $1.89 | AJ33: B07XXSYLL8 | AK33: 0.1394 | AL33: 0.1875 | AM33: B0CJLNCYG6 | AN33: 0.111 | AO33: 0.0417 | AP33: B01H1R0K68 | AQ33: 0.0925 | AR33: 0.0625 | AS33: B07XXSYLL8,B08DKKZY19,B0BMLDL5GM,B0B48NL6L8,B0DHFN5HK8,B0CRY9V6LL,B0CJLNCYG6,B08K2G5Y78,B017613C3C,B01H1R0K68 | AT33: 0.066 | AU33: B0D17C4VNX,B0D1KDXFZJ,B0CXTBZR2H,B0D1XL2B6P,B0CZNXB4KN,B0CZRC9F86,B0CZDB93YR,B0CYBRQ7FC,B0CXXTZ45P,B0D17DB7SX
A34: =W34 -> 2202 | B34: =IF(A34="","",IF(A34<词盘!$B$2,"大词",IF(A34<词盘!$C$2,"中尾词","长尾词"))) -> 大词 | C34: =IF(S34/20>70%,1,IF(S34/20>40%,2,IF(S34/20>10%,3,0))) -> 2 | D34: =IF(M34="","",IF(OR(E34="/",E34=""),"无序",IF(COUNTIFS(E:E,E34)<4,"无序","有序"))) -> 无序 | F34: 品牌词 | H34: 了解或购买EcoFlow品牌电源产品 | I34: =P34/SUM(P:P) -> 0.0045022511 | J34: =AC34 -> 261 | K34: =IFERROR(Z34*AH34,"") -> 116030.25 | M34: meater | N34: 肉食者 | P34: 0.0045 | Q34: 品牌广告词 | R34: 28882 | S34: 12 | T34: B0CRY9V6LL/B0BBR2RL6X/B09LSGPHT3/B01F59K0KA/B00S93EQUK/B017613C3C/B096K2L985/B01IHHLB3W/B0BQ782XNW/B00GRFHXVQ/B0BJK5W11R/B0C7D27GV8 | U34: 48197 | V34: 44397 | W34: 2202 | X34: 0.0496 | Y34: 1161936 | Z34: 22101 | AA34: 50 | AB34: 21 | AC34: 261 | AD34: 170.1 | AE34: 72 | AF34: 0.6871 | AG34: 0.6705 | AH34: 5.25 | AI34: $3.94 - $6.55 | AJ34: B07H8WTFHW | AK34: 0.3564 | AL34: 0.2832 | AM34: B0D2LQGJ2V | AN34: 0.1711 | AO34: 0.1792 | AP34: B0CP8BPXKR | AQ34: 0.1596 | AR34: 0.2081 | AS34: B07H8WTFHW,B0CP8BPXKR,B0D2LQGJ2V,B07TJ95CBM,B0D5ZRJM51,B07DZB6XZ6,B0DG5GKJKB,B0BMLDL5GM,B08WWGRGVY,B0DGGMTYXV | AT34: 0.0147 | AU34: B07SRRQS5B,B07HY3S811,B0B75JF6CM,B09N71WGLF,B0982TPZTW,B082K8ZNQ1,B07VHPFK5B,B0BC6G9Q35,B07J63KGNN,B0CWP3757G
A35: =W35 -> 752 | B35: =IF(A35="","",IF(A35<词盘!$B$2,"大词",IF(A35<词盘!$C$2,"中尾词","长尾词"))) -> 大词 | C35: =IF(S35/20>70%,1,IF(S35/20>40%,2,IF(S35/20>10%,3,0))) -> 0 | D35: =IF(M35="","",IF(OR(E35="/",E35=""),"无序",IF(COUNTIFS(E:E,E35)<4,"无序","有序"))) -> 无序 | F35: 场景词 | G35: 户外配件场景 | H35: 了解户外活动必备电源设备或其他装备 | I35: =P35/SUM(P:P) -> 0.0043021511 | J35: =AC35 -> 112243 | K35: =IFERROR(Z35*AH35,"") -> 101239.6 | L35: V | M35: kitchen essentials | N35: 厨房必备品 | P35: 0.0043 | Q35: 自然搜索词/HR推荐词/SP广告词 | R35: 27149 | S35: 2 | T35: B00S93EQUK/B0BQ782XNW | U35: 4762 | V35: 139405 | W35: 752 | X35: 0.0054 | Y35: 3760756 | Z35: 66605 | AA35: 18 | AB35: 7 | AC35: 112243 | AD35: 1.24 | AE35: 390 | AF35: 0.1489 | AG35: 0.0814 | AH35: 1.52 | AI35: $1.14 - $1.90 | AJ35: B08573DQ39 | AK35: 0.0556 | AL35: 0.0366 | AM35: B0C3QZ7SNF | AN35: 0.0504 | AO35: 0.0285 | AP35: B0764HS4SL | AQ35: 0.0429 | AR35: 0.0163 | AS35: B08573DQ39,B0BKRVT66L,B09VZ11WHK,B0CW3SZCW6,B0CJ1B6D6S,B0CTD5PYS3,B0764HS4SL,B0C3H9MJQV,B08J8GZXKZ,B0BSKQW2T2 | AT35: 0.0142 | AU35: B08YZ633BY,B07CZDXDG8,B07KPYMMG6,B07GKVBQDG,B07MYW7C3Z,B007BF7BUY,B07SRRQS5B,B00I5H5Z1O,B0BFWD2VML,B0B7BFMHNF
A36: =W36 -> 2216 | B36: =IF(A36="","",IF(A36<词盘!$B$2,"大词",IF(A36<词盘!$C$2,"中尾词","长尾词"))) -> 大词 | C36: =IF(S36/20>70%,1,IF(S36/20>40%,2,IF(S36/20>10%,3,0))) -> 1 | D36: =IF(M36="","",IF(OR(E36="/",E36=""),"无序",IF(COUNTIFS(E:E,E36)<4,"无序","有序"))) -> 有序 | E36: meat thermometer | F36: 品牌词 | H36: 了解或购买EcoFlow品牌电源产品 | I36: =P36/SUM(P:P) -> 0.004102051 | J36: =AC36 -> 1279 | K36: =IFERROR(Z36*AH36,"") -> 6414.65 | M36: digital meat thermometer instant read | N36: 数字肉类温度计即时读取 | P36: 0.0041 | Q36: 自然搜索词 | R36: 26394 | S36: 15 | T36: B0BJK5W11R/B096K2L985/B01F59K0KA/B0BBR2RL6X/B017613C3C/B0BQ782XNW/B01IHHLB3W/B005KCG6CE/B00GRFHXVQ/B09LSGPHT3/B07XXSYLL8/B0CRY9V6LL/B00S93EQUK/B0C7D27GV8/B0DDXWY41V | U36: 137356 | V36: 13223 | W36: 2216 | X36: 0.1676 | Y36: 385456 | Z36: 5995 | AA36: 51 | AB36: 0 | AC36: 1279 | AD36: 10.34 | AE36: 38 | AF36: 0.5094 | AG36: 0.48 | AH36: 1.07 | AI36: $0.71 - $2.15 | AJ36: B00S93EQUK | AK36: 0.2594 | AL36: 0.2578 | AM36: B09LSGPHT3 | AN36: 0.1627 | AO36: 0.1422 | AP36: B09C32DYV1 | AQ36: 0.0873 | AR36: 0.08 | AS36: B00S93EQUK,B07XXSYLL8,B0DG5LP1VK,B0DJY2PWTY,B01IHHLB3W,B07Y51PCW7,B09LSGPHT3,B0DHZTCNR5,B0DG5KDHS8,B0BQ782XNW | AT36: 0.0199 | AU36: B0B9VGMLZR,B07FH8BCX5,B09RWN11T5,B09H2CLPHT,B0CQ7CQXTL,B0CJF9LBQL,B0C33V7QSW,B0928K23P6,B082WJMM5H,B0CLRZ7L29
A37: =W37 -> 1242 | B37: =IF(A37="","",IF(A37<词盘!$B$2,"大词",IF(A37<词盘!$C$2,"中尾词","长尾词"))) -> 大词 | C37: =IF(S37/20>70%,1,IF(S37/20>40%,2,IF(S37/20>10%,3,0))) -> 2 | D37: =IF(M37="","",IF(OR(E37="/",E37=""),"无序",IF(COUNTIFS(E:E,E37)<4,"无序","有序"))) -> 无序 | F37: 功能词 | G37: 配备太阳能面板的便携电站 | H37: 寻找带太阳能面板的便携电源站 | I37: =P37/SUM(P:P) -> 0.004002001 | J37: =AC37 -> 19897 | K37: =IFERROR(Z37*AH37,"") -> 22869.6 | M37: temperature thermometer | N37: 温度温度计 | P37: 0.004 | Q37: 自然搜索词 | R37: 25252 | S37: 12 | T37: B0BBR2RL6X/B0BQ782XNW/B01IHHLB3W/B07XXSYLL8/B09LSGPHT3/B00S93EQUK/B017613C3C/B0CRY9V6LL/B005KCG6CE/B00GRFHXVQ/B01F59K0KA/B0C7D27GV8 | U37: 74165 | V37: 22932 | W37: 1242 | X37: 0.0542 | Y37: 627532 | Z37: 9529 | AA37: 29 | AB37: 0 | AC37: 19897 | AD37: 1.15 | AE37: 50 | AF37: 0.4055 | AG37: 0.3874 | AH37: 2.4 | AI37: $1.79 - $3.00 | AJ37: B0824XNJSW | AK37: 0.2483 | AL37: 0.2252 | AM37: B08B8BDG42 | AN37: 0.0832 | AO37: 0.096 | AP37: B0CTCPQ6N9 | AQ37: 0.074 | AR37: 0.0662 | AS37: B0824XNJSW,B0CGRB23YM,B075QQ8VZW,B08B8BDG42,B08MT3D361,B0C3B2VZLJ,B07R3YC1BC,B00MUK6M82,B08B7V2RG3,B07WCR5Y4B | AT37: 0.0581 | AU37: B07NS8BF7X,B0BWHG8PMV,B0BNMVB18C,B0CNRFNRB7,B09YY9DLCF,B003Z22QNY,B0CJB7C4G7,B0BZTS57Y7,B0C5N9YYTY,B078NQLWRM
A38: =W38 -> 2310 | B38: =IF(A38="","",IF(A38<词盘!$B$2,"大词",IF(A38<词盘!$C$2,"中尾词","长尾词"))) -> 大词 | C38: =IF(S38/20>70%,1,IF(S38/20>40%,2,IF(S38/20>10%,3,0))) -> 2 | D38: =IF(M38="","",IF(OR(E38="/",E38=""),"无序",IF(COUNTIFS(E:E,E38)<4,"无序","有序"))) -> 有序 | E38: meat thermometer | F38: 功能词 | G38: 电力发电机 | H38: 寻找电力发电机 | I38: =P38/SUM(P:P) -> 0.0037018509 | J38: =AC38 -> 2415 | K38: =IFERROR(Z38*AH38,"") -> 10618.64 | M38: meat thermometer probe | N38: 肉类温度计探头 | O38: Y | P38: 0.0037 | Q38: 自然搜索词/AC推荐词 | R38: 23381 | S38: 14 | T38: B005KCG6CE/B0CRY9V6LL/B0BBR2RL6X/B017613C3C/B0BQ782XNW/B0BJK5W11R/B01IHHLB3W/B07XXSYLL8/B00GRFHXVQ/B096K2L985/B09LSGPHT3/B01F59K0KA/B00S93EQUK/B0C7D27GV8 | U38: 140541 | V38: 12375 | W38: 2310 | X38: 0.1867 | Y38: 249819 | Z38: 5336 | AA38: 53 | AB38: 1 | AC38: 2415 | AD38: 5.12 | AE38: 114 | AF38: 0.347 | AG38: 0.311 | AH38: 1.99 | AI38: $1.49 - $2.49 | AJ38: B00S93EQUK | AK38: 0.1639 | AL38: 0.2012 | AM38: B005KCG6CE | AN38: 0.1012 | AO38: 0.0732 | AP38: B017613C3C | AQ38: 0.0819 | AR38: 0.0366 | AS38: B017613C3C,B00S93EQUK,B07XXSYLL8,B0D6YQ8LV2,B0DBKYNY98,B01CI4ZYMO,B07477NMF4,B0DG5KDHS8,B07Y51PCW7,B0DDXY3V1V | AT38: 0.0312 | AU38: B07SRRQS5B,B01DODMU9I,B082K8ZNQ1,B0BC6G9Q35,B07VHPFK5B,B0CRQJSL1P,B0CFV5LZ3R,B07PDHHS3Y,B00LB7REFK,B07J63KGNN
A39: =W39 -> 981 | B39: =IF(A39="","",IF(A39<词盘!$B$2,"大词",IF(A39<词盘!$C$2,"中尾词","长尾词"))) -> 大词 | C39: =IF(S39/20>70%,1,IF(S39/20>40%,2,IF(S39/20>10%,3,0))) -> 2 | D39: =IF(M39="","",IF(OR(E39="/",E39=""),"无序",IF(COUNTIFS(E:E,E39)<4,"无序","有序"))) -> 无序 | F39: 功能词 | G39: 配有太阳能面板的电站 | H39: 寻找太阳能发电机 | I39: =P39/SUM(P:P) -> 0.0036018009 | J39: =AC39 -> 5483 | K39: =IFERROR(Z39*AH39,"") -> 8465.31 | M39: food temperature thermometer | N39: 食物温度温度计 | P39: 0.0036 | Q39: 自然搜索词/SP广告词 | R39: 22879 | S39: 13 | T39: B0C7D27GV8/B005KCG6CE/B0CRY9V6LL/B017613C3C/B0BQ782XNW/B01IHHLB3W/B0BJK5W11R/B096K2L985/B07XXSYLL8/B09LSGPHT3/B01F59K0KA/B0BBR2RL6X/B00S93EQUK | U39: 153755 | V39: 10023 | W39: 981 | X39: 0.0979 | Y39: 281812 | Z39: 4479 | AA39: 23 | AB39: 0 | AC39: 5483 | AD39: 1.83 | AE39: 50 | AF39: 0.4305 | AG39: 0.4472 | AH39: 1.89 | AI39: $1.37 - $2.20 | AJ39: B00S93EQUK | AK39: 0.2047 | AL39: 0.2484 | AM39: B09LSGPHT3 | AN39: 0.1549 | AO39: 0.1429 | AP39: B0C37DLHWW | AQ39: 0.0709 | AR39: 0.0559 | AS39: B00S93EQUK,B07XXSYLL8,B01IHHLB3W,B0B71HFH9K,B0BQ782XNW,B08RWPPD8J,B09LSGPHT3,B0C37DLHWW,B09MTX71VX,B017613C3C | AT39: 0.0528 | AU39: B0C1R964XD,B09BDZZQ4Y,B09LLYP2XL,B082M35PH3,B0BX5YKTWQ,B077Q382WD,B01IEJHJWK,B07SRRQS5B,B0BB378VKV,B072K59NYZ
A40: =W40 -> 5843 | B40: =IF(A40="","",IF(A40<词盘!$B$2,"大词",IF(A40<词盘!$C$2,"中尾词","长尾词"))) -> 大词 | C40: =IF(S40/20>70%,1,IF(S40/20>40%,2,IF(S40/20>10%,3,0))) -> 3 | D40: =IF(M40="","",IF(OR(E40="/",E40=""),"无序",IF(COUNTIFS(E:E,E40)<4,"无序","有序"))) -> 无序 | F40: 功能词 | G40: 太阳能发电机 | H40: 寻找太阳能发电机 | I40: =P40/SUM(P:P) -> 0.0034017009 | J40: =AC40 -> 8971 | K40: =IFERROR(Z40*AH40,"") -> 51572.22 | M40: outdoor thermometer | N40: 户外温度计 | P40: 0.0034 | Q40: SP广告词 | R40: 21684 | S40: 8 | T40: B0DGXKNV6Y/B09LSGPHT3/B00S93EQUK/B0BQ782XNW/B01IHHLB3W/B096K2L985/B00GRFHXVQ/B01F59K0KA | U40: 15494 | V40: 123284 | W40: 5843 | X40: 0.0474 | Y40: 2615367 | Z40: 55454 | AA40: 133 | AB40: 47 | AC40: 8971 | AD40: 13.74 | AE40: 174 | AF40: 0.3472 | AG40: 0.2948 | AH40: 0.93 | AI40: $0.80 - $1.12 | AJ40: B00004TBJP | AK40: 0.2008 | AL40: 0.1795 | AM40: B06XKH666P | AN40: 0.112 | AO40: 0.0897 | AP40: B000BZYBYU | AQ40: 0.0344 | AR40: 0.0256 | AS40: B06XKH666P,B00004TBJP,B0BYF6CTRK,B0D1VCSY1N,B0D8HY1YQM,B0D8J22Q45,B001A0K8KQ,B01ALO555E,B0BT9B25LP,B0D9B8DDQ9 | AT40: 0.0072 | AU40: B0B9V8KN72,B0C1RJHQ41,B07P8NXQF4,B09H2CLPHT,B082WJMM5H,B0CQ7CQXTL,B07SRRQS5B,B0C33V7QSW,B07TRMF56R,B07PJG4FBM
...

Sheet SOP
A1: 序号 | B1: 必做 | C1: 内容 | D1: 操作 | E1: 备注 | F1: 注意
A2: #1 | B2: v | C2: 【词库】对关键词打标按照流量大小、相关性、有无序性、词组、一级分类、二级分类、用户搜索意图，对重点追踪词进行打标“V” | D2: 1、将20个TOP相似的ASIN输入卖家精灵进行关键词“拓展流量词”，按照格式粘贴到【词库】 https://www.sellersprite.com/v3/traffic/extend 2、对加粗字段进行打标，其它都是公式。在这之前建议先做【词根】先把不相关词根找不出否定 https://chatgpt.com/g/g-RZEovC1BF-vikiguan-jian-ci-fen-xi-zhuan-jia/c/67362093-f224-8010-952b-e4f602764b30 | E2: =_xlfn.DISPIMG("ID_0AE6D8C63B884F3E9824A5EE3BDEBE06",1) -> =DISPIMG("ID_0AE6D8C63B884F3E9824A5EE3BDEBE06",1)
A3: #2 | B3: v | C3: 【词根】量化词根数据，对词根进行打标按照一级、二级、用户意图，将不相关词根找出来并标记“X” | D3: 1、将词库中的关键词做词频统计 2、对词根进行打标，其它都是公式 https://chatgpt.com/g/g-RZEovC1BF-vikiguan-jian-ci-fen-xi-zhuan-jia/c/67362093-f224-8010-952b-e4f602764b30 | E3: =_xlfn.DISPIMG("ID_564DC2EA9AEF4D649826B83151F6EAF3",1) -> =DISPIMG("ID_564DC2EA9AEF4D649826B83151F6EAF3",1)
A4: #3 | B4: v | C4: 【词盘】将关键词和词根按照各个维度进行量化，分析类目流量构成与竞争情况，是文案与广告结构预算分配依据 | D4: 1、按照ABA排名，自定义关键词大小，初始2w以内为大词，2-10w为中尾词，10w+为长尾词，划分大词建议在20个左右 2、刷新透视表（透视表如果报错，可能是刷新的数据被后边已有数据遮挡，可以将后边数据剪切到靠后行） | F4: 1、此表可以从多个维度看类目成熟期的流量结构，但不一定适合自己当前阶段。自己的流量结构一个是参考类目结构，另外一个是考虑自己所处阶段的投入产出如何利益最大化； 2、有序更适合做精准与词组，无序更适合做广泛与自动；强相关更适合做精准高竞价，较为相关与弱相关更适合做非精准低竞价； 3、关注用户意图
A11: 显示作者信息 | B11: =IF(A11="隐藏作者信息","",B42) -> 卖家精灵 | C11: =IF(A11="隐藏作者信息","",C42) -> Shulex | D11: =IF(A11="隐藏作者信息","",D42) -> 领星 | E11: =IF(A11="隐藏作者信息","",E42) -> SIF | F11: =IF(A11="隐藏作者信息","",F42) -> H10
