Workbook

Sheet 阶段实际盈亏
A1: 时间 | B1: 实际 | C1: 价格 | D1: 站内 coupon | E1: 站内 code | F1: 站外 折扣 | G1: 站外 订单 | H1: 站内 自然单 | I1: 站内 广告单 | J1: 阶段 销售 订单 | K1: 时间 /天 | L1: 阶段广告费 （出1单广告单预估） | M1: 阶段站外费用 （5美金/单） | N1: 阶段订单 盈亏 | O1: 阶段亏损 /美金 | P1: 六阶段 总亏损 | R1: 阶段日均 订单 | S1: 阶段日均 广告订单 | T1: 阶段日均 自然订单 | U1: 新品 排行榜 | V1: 小类目 排名
A2: 9月7-9月12 | B2: 第一阶段 | C2: 99.99 | D2: 0.05 | E2: 0.5 | F2: 0.68 | G2: =SUM(#REF!) -> #REF! | H2: 0 | I2: 0 | J2: =SUM(G2:I2) -> #REF! | K2: 6 | L2: 0 | M2: =SUM(#REF!) -> #REF! | N2: =SUM(#REF!) -> #REF! | O2: =SUM(L2:N2) -> #REF!
A3: 9月13-9月21 | B3: 第二阶段 | C3: 79.99 | D3: 0.3 | E3: 0.2 | F3: 0.3 | G3: 81 | H3: 14 | I3: 0 | J3: =SUM(G3:I3) -> 95 | K3: 9 | L3: =SUM(#REF!) -> #REF! | M3: =SUM(#REF!) -> #REF! | N3: =SUM(#REF!) -> #REF! | O3: =SUM(L3:N3) -> #REF!
A4: 9月22-10月1 | B4: 第三阶段 | C4: 69.99 | D4: 0.3 | E4: 0.2 | F4: 0.25 | G4: 45 | H4: 60 | I4: 3 | J4: =SUM(G4:I4) -> 108 | K4: 10 | L4: =SUM(#REF!) -> #REF! | M4: =SUM(#REF!) -> #REF! | N4: =SUM(#REF!) -> #REF! | O4: =SUM(L4:N4) -> #REF!
A5: 10月2-10月11 | B5: 第四阶段 | C5: 69.99 | D5: 0.3 | E5: 0 | F5: 0.25
A6: 10月12-10月21 | B6: 第五阶段 | C6: 69.99 | D6: 0.3 | E6: 0 | F6: 0.25
A7: 10月22-10月31 | B7: 第六阶段 | C7: 69.99 | D7: 0.3 | E7: 0 | F7: 0
A9: 11月1-11月30 | B9: 十一月份 | C9: 69.99 | D9: 0.2 | E9: 0 | F9: 0
A10: 12月1-12月31 | B10: 十二月份 | C10: 69.99 | D10: 0.2 | E10: 0 | F10: 0
A11: 1月1-1月31 | B11: 一月份 | C11: 69.99 | D11: 0.2 | E11: 0 | F11: 0

Sheet 价格策略模拟
B1: 价格策略模拟
A2: 阶段 | B2: 定价 | C2: coupon/ 秒杀 | D2: code | E2: 折后价 | F2: FBA 配送费 | G2: 亚马逊 佣金 | H2: 账号 回款 | I2: 仓储费+入库配置费 | J2: coupon 费用 | K2: 产品 成本 | L2: 物流费 | M2: 退货成本(公式后面加的是单套产品的移除费） | N2: 退货率 | O2: 每单平摊 退货成本 | P2: 每单 毛利 | Q2: 毛利率 | R2: 订单 数量 | S2: 阶段 订单 亏损 | T2: 阶段 订单 总盈亏
A3: 备注 | B3: 选择性调整 | C3: 选择性调整 | D3: / | E3: 公式 | F3: 3.参考机构或者在亚马逊后台查询 | G3: 公式 | H3: 公式 | I3: 公式 | J3: 未计算 | K3: 1.先填写采购价 | L3: 2.根据材积重推算头程运费 | M3: 4.[ 退货损失成本 = {(产品采购价 + 头程运费)}/{汇率} + 亚马逊配送费 + 佣金的20% + 移除/弃置费用 ] | N3: 5.亚马逊后台- 商机探测器 按关键词或 ASIN 搜索看细分类退货率 | O3: 6.按退货率计算退货成本，然后平摊到没有退货的95%产品里 | P3: 公式 | Q3: 公式 | S3: 公式 | T3: 公式 | U3: 备注：广告费用未计算
A4: 第一阶段 | B4: 17.99 | C4: 0.2 | D4: 0 | E4: =SUM(B4*(1-C4-D4)) -> 14.392 | F4: 6 | G4: =SUM(E4*15%) -> 2.1588 | H4: =SUM(E4-F4-G4) -> 6.2332 | I4: 0.22 | J4: 0.6 | K4: 3.7 | L4: 1.4 | M4: =SUM(20%*15%*E4+F4+I4+K4+L4+0.65) -> 12.40176 | N4: 0.02 | O4: =SUM(M4*N4/(1-N4)) -> 0.25309714 | P4: =SUM(H4-I4-J4-K4-L4-O4) -> 0.060102857 | Q4: =SUM(P4/B4) -> 0.0033409037 | R4: 1 | S4: =SUM(P4*R4) -> 0.060102857 | T4: =SUM(S4:S4) -> 0.060102857
A5: 第二阶段 | B5: 17.99 | C5: 0.15 | D5: 0 | E5: =SUM(B5*(1-C5-D5)) -> 15.2915 | F5: 6 | G5: =SUM(E5*15%) -> 2.293725 | H5: =SUM(E5-F5-G5) -> 6.997775 | I5: 0.22 | J5: 0.6 | K5: 3.7 | L5: 1.4 | M5: =SUM(20%*15%*E5+F5+I5+K5+L5+0.65) -> 12.428745 | N5: 0.02 | O5: =SUM(M5*N5/(1-N5)) -> 0.25364786 | P5: =SUM(H5-I5-J5-K5-L5-O5) -> 0.82412714 | Q5: =SUM(P5/B5) -> 0.045810291 | R5: 1 | S5: =SUM(P5*R5) -> 0.82412714 | T5: =SUM(S5:S5) -> 0.82412714
A6: 第三阶段 | B6: 17.99 | C6: 0.1 | D6: 0 | E6: =SUM(B6*(1-C6-D6)) -> 16.191 | F6: 6 | G6: =SUM(E6*15%) -> 2.42865 | H6: =SUM(E6-F6-G6) -> 7.76235 | I6: 0.22 | J6: 0.6 | K6: 3.7 | L6: 1.4 | M6: =SUM(20%*15%*E6+F6+I6+K6+L6+0.65) -> 12.45573 | N6: 0.02 | O6: =SUM(M6*N6/(1-N6)) -> 0.25419857 | P6: =SUM(H6-I6-J6-K6-L6-O6) -> 1.5881514 | Q6: =SUM(P6/B6) -> 0.088279679 | R6: 1 | S6: =SUM(P6*R6) -> 1.5881514 | T6: =SUM(S6:S6) -> 1.5881514
A7: 第四阶段 | B7: 17.99 | C7: 0.05 | D7: 0 | E7: =SUM(B7*(1-C7-D7)) -> 17.0905 | F7: 6 | G7: =SUM(E7*15%) -> 2.563575 | H7: =SUM(E7-F7-G7) -> 8.526925 | I7: 0.22 | J7: 0.6 | K7: 3.7 | L7: 1.4 | M7: =SUM(20%*15%*E7+F7+I7+K7+L7+0.65) -> 12.482715 | N7: 0.02 | O7: =SUM(M7*N7/(1-N7)) -> 0.25474929 | P7: =SUM(H7-I7-J7-K7-L7-O7) -> 2.3521757 | Q7: =SUM(P7/B7) -> 0.13074907 | R7: 1 | S7: =SUM(P7*R7) -> 2.3521757 | T7: =SUM(S7:S7) -> 2.3521757
A8: 第五阶段 | B8: 17.99 | C8: 0.05 | D8: 0 | E8: =SUM(B8*(1-C8-D8)) -> 17.0905 | F8: 6 | G8: =SUM(E8*15%) -> 2.563575 | H8: =SUM(E8-F8-G8) -> 8.526925 | I8: 0.22 | J8: 0.6 | K8: 3.7 | L8: 1.4 | M8: =SUM(20%*15%*E8+F8+I8+K8+L8+0.65) -> 12.482715 | N8: 0.02 | O8: =SUM(M8*N8/(1-N8)) -> 0.25474929 | P8: =SUM(H8-I8-J8-K8-L8-O8) -> 2.3521757 | Q8: =SUM(P8/B8) -> 0.13074907 | R8: 1 | S8: =SUM(P8*R8) -> 2.3521757 | T8: =SUM(S8:S8) -> 2.3521757
A9: 第六阶段 | B9: 17.99 | C9: 0 | D9: 0 | E9: =SUM(B9*(1-C9-D9)) -> 17.99 | F9: 6 | G9: =SUM(E9*15%) -> 2.6985 | H9: =SUM(E9-F9-G9) -> 9.2915 | I9: 0.22 | J9: 0 | K9: 3.7 | L9: 1.4 | M9: =SUM(20%*15%*E9+F9+I9+K9+L9+0.65) -> 12.5097 | N9: 0.02 | O9: =SUM(M9*N9/(1-N9)) -> 0.2553 | P9: =SUM(H9-I9-J9-K9-L9-O9) -> 3.7162 | Q9: =SUM(P9/B9) -> 0.20657032 | R9: 1 | S9: =SUM(P9*R9) -> 3.7162 | T9: =SUM(S9:S9) -> 3.7162
A11: 竞品日常价格 | B11: 34.99 | C11: 0.1 | D11: 0 | E11: =SUM(B11*(1-C11-D11)) -> 31.491 | F11: 6 | G11: =SUM(E11*15%) -> 4.72365 | H11: =SUM(E11-F11-G11) -> 20.76735 | I11: 0.22 | J11: 0 | K11: 8.5 | L11: 1.3 | M11: =SUM(20%*15%*E11+F11+I11+K11+L11+0.65) -> 17.61473 | N11: 0.05 | O11: =SUM(M11*N11/(1-N11)) -> 0.92709105 | P11: =SUM(H11-I11-J11-K11-L11-O11) -> 9.8202589 | Q11: =SUM(P11/B11) -> 0.28065902 | R11: 1 | S11: =SUM(P11*R11) -> 9.8202589 | T11: =SUM(S11:S11) -> 9.8202589
A12: 竞品日常价格 | B12: 32.99 | C12: 0 | D12: 0 | E12: =SUM(B12*(1-C12-D12)) -> 32.99 | F12: 6 | G12: =SUM(E12*15%) -> 4.9485 | H12: =SUM(E12-F12-G12) -> 22.0415 | I12: 0.22 | J12: 0 | K12: 8.5 | L12: 1.3 | M12: =SUM(20%*15%*E12+F12+I12+K12+L12+0.65) -> 17.6597 | N12: 0.05 | O12: =SUM(M12*N12/(1-N12)) -> 0.92945789 | P12: =SUM(H12-I12-J12-K12-L12-O12) -> 11.092042 | Q12: =SUM(P12/B12) -> 0.33622437 | R12: 1 | S12: =SUM(P12*R12) -> 11.092042 | T12: =SUM(S12:S12) -> 11.092042
A13: 竞品小类目 | B13: https://www.amazon.com/Best-Sellers-Beauty-Personal-Care-Personal-Makeup-Mirrors/zgbs/beauty/3785121/ref=zg_bs_nav_beauty_3_17738944011
A14: 前100名找竞品 | B14: https://www.amazon.com/20X-Magnifying-Adjustable-Brightness-Detachable/dp/B0CT37456F/ref=zg_bs_g_3785121_d_sccl_20/137-8764674-4814218?psc=1
A15: 前100名找竞品 | B15: https://www.amazon.com/20x-Magnifying-Rechargeable-Adjustable-Brightness/dp/B0D3HNWKWF/ref=zg_bs_g_3785121_d_sccl_39/137-8764674-4814218?psc=1
B16: 找到自己对标的竞品，为 新品做准备
K17: 820g
A18: 产品成本：1688询价60左右
A19: 物流费用：以海运为主，因此1.37美金运费足够
A21: 仓储费+配置费的路径 | C21: 后台目录-数据报告-库存与销售报告-月度仓储费 和 后台-帮助—查询-2024 年亚马逊物流入库配置服务费
A22: 产品移除费的路径 | C22: 后台目录-数据报告-库存与销售报告-移除订单详情
A23: 退货率的路径 | C23: 后台-商机探测器-查询框输入"makeup mirror with lights"
A24: 亚马逊退货成本主要包括以下几个方面： 1.亚马逊配送费：当产品被退回时，亚马逊会收取一次性的配送费用。 2.退款管理费：亚马逊在处理退货订单时，会扣除20%的佣金。无论买家是部分退款还是全部退款，这20%的佣金都称为退款管理费。 3.退货服务费：如果产品不可再售，需要支付额外的移除或弃置订单费用。 4.产品成本和头程运费：如果产品不可再售，除了上述费用外，还需要考虑产品的采购成本和头程运费。 具体计算方式如下： 1.可再次销售的情况：[ 退货损失成本 = 亚马逊配送费 + 佣金的20% ] 2.不可再次销售的情况：[ 退货损失成本 = {(产品采购价 + 头程运费)}/{汇率} + 亚马逊配送费 + 佣金的20% + 移除/弃置费用 ] | C24: [ 退货损失成本 = {(产品采购价 + 头程运费)}/{汇率} + 亚马逊配送费 + 佣金的20% + 移除/弃置费用 ]
A26: 美妆镜类目推广方法：
A27: 第一种：新品上架直接广告拉满
A28: 第二种：新品前期配合测款，提升自然排名，再开广告 | F28: 免评单为主，按照测评节奏递增
A29: 第三种：新品前期配合站外，提升自然排名，再开广告 | F29: 站外需要大折扣：50%code+（20%-30%coupon）
A30: 第四种：测评+广告+大coupon | F30: 10个左右高质量买家账户测评评论+100个以上的VINE
A31: 第五种：站外+广告
A32: 第六种：测评+站外+广告

Sheet 阶段总盈亏
A1: 阶段盈亏模拟数据
A2: 阶段 | B2: 周期 | C2: 定价 | D2: cou pon | E2: code | F2: 折后价 | G2: 站内 自然单 | H2: 站内 广告单 | I2: 阶段 销售 订单 | J2: 时间 /天 | K2: CPA | L2: 阶段 广告费 | M2: 毛利 盈亏 | N2: 阶段盈亏 /美金 | O2: 评论 数量 | P2: 阶段 日均 订单 | Q2: 阶段 日均 广告单 | R2: 自然单占比 | S2: 阶段 日均 自然单 | T2: 日均 广告费 | U2: 每周 销售额 | V2: Tacos | W2: 小类目 排名 | X2: 大类目 排名 | Y2: 备注 | Z2: 评论费/（开5个站点VINE，预计来100条评论）,视觉化费用 | AA2: 前期亏损/美金 | AB2: 总亏损（人民币） | AC2: 小类目 排名 | AD2: 对应 月销量 | AE2: 对应 日销量
C3: 与价格模拟表一样 | D3: 与价格模拟表一样 | E3: 与价格模拟表一样 | G3: 第6步 公式算出自然周出单 | H3: 第5步 公式算出广告周出单 | I3: 第4步，周销量等推测日销*7天，毛利模拟表缺的S3一栏就补齐了 | K3: 第8步 需先做CPC模拟表 | L3: 第9步 公式得出 | M3: 第7步 公式 数据来源于《毛利模拟盈亏》S3 | N3: 第10步，计算当周盈亏 | Q3: 第2步，根据订单占比推算广告订单；参考广告为主的竞品广告占比参考 | S3: 第3步，日销订单扣减广告单算出自然单 | AA3: 前期亏损+VINE | AC3: 第1步，根据目标销量倒推排名 | AD3: 根据推排名节奏推销量 | AE3: 分解到日销量
A4: 第一阶段 | B4: 第1周 | C4: =价格策略模拟!B4 -> 17.99 | D4: =价格策略模拟!C4 -> 0.2 | E4: =价格策略模拟!D4 -> 0 | F4: =SUM(C4*(1-D4-E4)) -> 14.392 | G4: =S4*J4 -> 1.4 | H4: =J4*Q4 -> 12.6 | I4: =SUM(G4:H4) -> 14 | J4: 7 | K4: =CPC模拟表格!V4 -> 15.789474 | L4: =SUM(H4*-K4) -> -198.94737 | M4: =毛利模拟盈亏!T4 -> 9.24144 | N4: =SUM(L4:M4) -> -189.70593 | O4: 10 | P4: =AE4 -> 2 | Q4: =P4*0.9 -> 1.8 | R4: =1-Q4/P4 -> 0.1 | S4: =SUM(P4-Q4) -> 0.2 | T4: =SUM(L4/J4) -> -28.421053 | U4: =毛利模拟盈亏!V4 -> 251.86 | V4: =-L4/U4 -> 0.78991252 | W4: =AC4 -> 0 | AA4: =SUM(N4:N22)+Z4 -> -10597.946 | AB4: =AA4*7 -> -74185.62 | AD4: 60 | AE4: =AD4/30 -> 2
B5: 第2周 | C5: =价格策略模拟!B4 -> 17.99 | D5: =价格策略模拟!C4 -> 0.2 | E5: =价格策略模拟!D4 -> 0 | F5: =SUM(C5*(1-D5-E5)) -> 14.392 | G5: =J5*S5 -> 2.1 | H5: =J5*Q5 -> 18.9 | I5: =SUM(G5:H5) -> 21 | J5: 7 | K5: =CPC模拟表格!V5 -> 15.263158 | L5: =SUM(H5*-K5) -> -288.47368 | M5: =毛利模拟盈亏!T5 -> 13.86216 | N5: =SUM(L5:M5) -> -274.61152 | P5: =AE5 -> 3 | Q5: =P5*0.9 -> 2.7 | R5: =1-Q5/P5 -> 0.1 | S5: =SUM(P5-Q5) -> 0.3 | T5: =SUM(L5/J5) -> -41.210526 | U5: =毛利模拟盈亏!V5 -> 377.79 | V5: =-L5/U5 -> 0.76358211 | W5: =AC5 -> 0 | Z5: 到货开售，开始销售时间填写到货时间 | AD5: 90 | AE5: =AD5/30 -> 3
B6: 第3周 | C6: =价格策略模拟!B4 -> 17.99 | D6: =价格策略模拟!C4 -> 0.2 | E6: =价格策略模拟!D4 -> 0 | F6: =SUM(C6*(1-D6-E6)) -> 14.392 | G6: =J6*S6 -> 7 | H6: =J6*Q6 -> 28 | I6: =SUM(G6:H6) -> 35 | J6: 7 | K6: =CPC模拟表格!V6 -> 14.736842 | L6: =SUM(H6*-K6) -> -412.63158 | M6: =毛利模拟盈亏!T6 -> 23.1036 | N6: =SUM(L6:M6) -> -389.52798 | P6: =AE6 -> 5 | Q6: =P6*0.8 -> 4 | R6: =1-Q6/P6 -> 0.2 | S6: =SUM(P6-Q6) -> 1 | T6: =SUM(L6/J6) -> -58.947368 | U6: =毛利模拟盈亏!V6 -> 629.65 | V6: =-L6/U6 -> 0.65533484 | W6: =AC6 -> 0 | Z6: 5个站点vine 送150个，成本$9+物流费$1.37+配送费$6美金一个 | AD6: 150 | AE6: =AD6/30 -> 5
B7: 第4周 | C7: =价格策略模拟!B4 -> 17.99 | D7: =价格策略模拟!C4 -> 0.2 | E7: =价格策略模拟!D4 -> 0 | F7: =SUM(C7*(1-D7-E7)) -> 14.392 | G7: =J7*S7 -> 9.8 | H7: =J7*Q7 -> 39.2 | I7: =SUM(G7:H7) -> 49 | J7: 7 | K7: =CPC模拟表格!V7 -> 14.210526 | L7: =SUM(H7*-K7) -> -557.05263 | M7: =毛利模拟盈亏!T7 -> 32.34504 | N7: =SUM(L7:M7) -> -524.70759 | P7: =AE7 -> 7 | Q7: =P7*0.8 -> 5.6 | R7: =1-Q7/P7 -> 0.2 | S7: =SUM(P7-Q7) -> 1.4 | T7: =SUM(L7/J7) -> -79.578947 | U7: =毛利模拟盈亏!V7 -> 881.51 | V7: =-L7/U7 -> 0.63193002 | W7: =AC7 -> 0 | Z7: vine成本200美金30个，5条vine就是1000美金 | AD7: 210 | AE7: =AD7/30 -> 7
A8: 第二阶段 | B8: 第5周 | C8: =价格策略模拟!B5 -> 17.99 | D8: =价格策略模拟!C5 -> 0.15 | E8: =价格策略模拟!D5 -> 0 | F8: =SUM(C8*(1-D8-E8)) -> 15.2915 | G8: =J8*S8 -> 12.6 | H8: =J8*Q8 -> 50.4 | I8: =SUM(G8:H8) -> 63 | J8: 7 | K8: =CPC模拟表格!V8 -> 13.5 | L8: =SUM(H8*-K8) -> -680.4 | M8: =毛利模拟盈亏!T8 -> 89.72001 | N8: =SUM(L8:M8) -> -590.67999 | O8: 100 | P8: =AE8 -> 9 | Q8: =P8*0.8 -> 7.2 | R8: =1-Q8/P8 -> 0.2 | S8: =SUM(P8-Q8) -> 1.8 | T8: =SUM(L8/J8) -> -97.2 | U8: =毛利模拟盈亏!V8 -> 1133.37 | V8: =-L8/U8 -> 0.60033352 | W8: =AC8 -> 0 | Z8: 图片和视频拍摄费用预估5000美金以内 | AD8: 270 | AE8: =AD8/30 -> 9
B9: 第6周 | C9: =价格策略模拟!B5 -> 17.99 | D9: =价格策略模拟!C5 -> 0.15 | E9: =价格策略模拟!D5 -> 0 | F9: =SUM(C9*(1-D9-E9)) -> 15.2915 | G9: =J9*S9 -> 16.333333 | H9: =J9*Q9 -> 65.333333 | I9: =SUM(G9:H9) -> 81.666667 | J9: 7 | K9: =CPC模拟表格!V9 -> 13.5 | L9: =SUM(H9*-K9) -> -882 | M9: =毛利模拟盈亏!T9 -> 116.30372 | N9: =SUM(L9:M9) -> -765.69628 | P9: =AE9 -> 11.666667 | Q9: =P9*0.8 -> 9.3333333 | R9: =1-Q9/P9 -> 0.2 | S9: =SUM(P9-Q9) -> 2.3333333 | T9: =SUM(L9/J9) -> -126 | U9: =毛利模拟盈亏!V9 -> 1469.1833 | V9: =-L9/U9 -> 0.60033352 | W9: =AC9 -> 0 | Z9: 评论测评费用+买家秀视频1000美金以内 | AD9: 350 | AE9: =AD9/30 -> 11.666667
B10: 第7周 | C10: =价格策略模拟!B5 -> 17.99 | D10: =价格策略模拟!C5 -> 0.15 | E10: =价格策略模拟!D5 -> 0 | F10: =SUM(C10*(1-D10-E10)) -> 15.2915 | G10: =J10*S10 -> 26.25 | H10: =J10*Q10 -> 78.75 | I10: =SUM(G10:H10) -> 105 | J10: 7 | K10: =CPC模拟表格!V10 -> 13.5 | L10: =SUM(H10*-K10) -> -1063.125 | M10: =毛利模拟盈亏!T10 -> 149.53335 | N10: =SUM(L10:M10) -> -913.59165 | P10: =AE10 -> 15 | Q10: =P10*0.75 -> 11.25 | R10: =1-Q10/P10 -> 0.25 | S10: =SUM(P10-Q10) -> 3.75 | T10: =SUM(L10/J10) -> -151.875 | U10: =毛利模拟盈亏!V10 -> 1888.95 | V10: =-L10/U10 -> 0.56281267 | W10: =AC10 -> 0 | Z10: 备注：可以新建子体测评做评论，再合并（测评10个） | AD10: 450 | AE10: =AD10/30 -> 15
B11: 第8周 | C11: =价格策略模拟!B5 -> 17.99 | D11: =价格策略模拟!C5 -> 0.15 | E11: =价格策略模拟!D5 -> 0 | F11: =SUM(C11*(1-D11-E11)) -> 15.2915 | G11: =J11*S11 -> 32.666667 | H11: =J11*Q11 -> 98 | I11: =SUM(G11:H11) -> 130.66667 | J11: 7 | K11: =CPC模拟表格!V11 -> 13.5 | L11: =SUM(H11*-K11) -> -1323 | M11: =毛利模拟盈亏!T11 -> 186.08595 | N11: =SUM(L11:M11) -> -1136.9141 | P11: =AE11 -> 18.666667 | Q11: =P11*0.75 -> 14 | R11: =1-Q11/P11 -> 0.25 | S11: =SUM(P11-Q11) -> 4.6666667 | T11: =SUM(L11/J11) -> -189 | U11: =毛利模拟盈亏!V11 -> 2350.6933 | V11: =-L11/U11 -> 0.56281267 | W11: =AC11 -> 0 | AD11: 560 | AE11: =AD11/30 -> 18.666667
A12: 第三阶段 | B12: 第9周 | C12: =价格策略模拟!B6 -> 17.99 | D12: =价格策略模拟!C6 -> 0.1 | E12: =价格策略模拟!D6 -> 0 | F12: =SUM(C12*(1-D12-E12)) -> 16.191 | G12: =J12*S12 -> 40.25 | H12: =J12*Q12 -> 120.75 | I12: =SUM(G12:H12) -> 161 | J12: 7 | K12: =CPC模拟表格!V12 -> 12.727273 | L12: =SUM(H12*-K12) -> -1536.8182 | M12: =毛利模拟盈亏!T12 -> 352.29238 | N12: =SUM(L12:M12) -> -1184.5258 | O12: 200 | P12: =AE12 -> 23 | Q12: =P12*0.75 -> 17.25 | R12: =1-Q12/P12 -> 0.25 | S12: =SUM(P12-Q12) -> 5.75 | T12: =SUM(L12/J12) -> -219.54545 | U12: =毛利模拟盈亏!V12 -> 2896.39 | V12: =-L12/U12 -> 0.53059781 | W12: =AC12 -> 0 | AD12: 690 | AE12: =AD12/30 -> 23
B13: 第10周 | C13: =价格策略模拟!B6 -> 17.99 | D13: =价格策略模拟!C6 -> 0.1 | E13: =价格策略模拟!D6 -> 0 | F13: =SUM(C13*(1-D13-E13)) -> 16.191 | G13: =J13*S13 -> 72.8 | H13: =J13*Q13 -> 109.2 | I13: =SUM(G13:H13) -> 182 | J13: 7 | K13: =CPC模拟表格!V13 -> 12.727273 | L13: =SUM(H13*-K13) -> -1389.8182 | M13: =毛利模拟盈亏!T13 -> 398.24356 | N13: =SUM(L13:M13) -> -991.57462 | P13: =AE13 -> 26 | Q13: =P13*0.6 -> 15.6 | R13: =1-Q13/P13 -> 0.4 | S13: =SUM(P13-Q13) -> 10.4 | T13: =SUM(L13/J13) -> -198.54545 | U13: =毛利模拟盈亏!V13 -> 3274.18 | V13: =-L13/U13 -> 0.42447825 | W13: =AC13 -> 0 | Z13: 1.链接细节 | AD13: 780 | AE13: =AD13/30 -> 26
B14: 第11周 | C14: =价格策略模拟!B6 -> 17.99 | D14: =价格策略模拟!C6 -> 0.1 | E14: =价格策略模拟!D6 -> 0 | F14: =SUM(C14*(1-D14-E14)) -> 16.191 | G14: =J14*S14 -> 99.166667 | H14: =J14*Q14 -> 99.166667 | I14: =SUM(G14:H14) -> 198.33333 | J14: 7 | K14: =CPC模拟表格!V14 -> 12.727273 | L14: =SUM(H14*-K14) -> -1262.1212 | M14: =毛利模拟盈亏!T14 -> 433.98337 | N14: =SUM(L14:M14) -> -828.13785 | P14: =AE14 -> 28.333333 | Q14: =P14*0.5 -> 14.166667 | R14: =1-Q14/P14 -> 0.5 | S14: =SUM(P14-Q14) -> 14.166667 | T14: =SUM(L14/J14) -> -180.30303 | U14: =毛利模拟盈亏!V14 -> 3568.0167 | V14: =-L14/U14 -> 0.35373187 | W14: =AC14 -> 0 | Z14: 2.产品开售，做关联视频，买家秀视频，最少做10个以上 | AD14: 850 | AE14: =AD14/30 -> 28.333333
B15: 第12周 | C15: =价格策略模拟!B6 -> 17.99 | D15: =价格策略模拟!C6 -> 0.1 | E15: =价格策略模拟!D6 -> 0 | F15: =SUM(C15*(1-D15-E15)) -> 16.191 | G15: =J15*S15 -> 105 | H15: =J15*Q15 -> 105 | I15: =SUM(G15:H15) -> 210 | J15: 7 | K15: =CPC模拟表格!V15 -> 12.272727 | L15: =SUM(H15*-K15) -> -1288.6364 | M15: =毛利模拟盈亏!T15 -> 459.5118 | N15: =SUM(L15:M15) -> -829.12456 | P15: =AE15 -> 30 | Q15: =P15*0.5 -> 15 | R15: =1-Q15/P15 -> 0.5 | S15: =SUM(P15-Q15) -> 15 | T15: =SUM(L15/J15) -> -184.09091 | U15: =毛利模拟盈亏!V15 -> 3777.9 | V15: =-L15/U15 -> 0.34109859 | W15: =AC15 -> 20 | Z15: 3.单独开售做vine，6个站点做VINE评价 | AC15: 20 | AD15: 900 | AE15: =AD15/30 -> 30
A16: 第四阶段 | B16: 第13周 | C16: =价格策略模拟!B7 -> 17.99 | D16: =价格策略模拟!C7 -> 0.05 | E16: =价格策略模拟!D7 -> 0 | F16: =SUM(C16*(1-D16-E16)) -> 17.0905 | G16: =J16*S16 -> 105 | H16: =J16*Q16 -> 105 | I16: =SUM(G16:H16) -> 210 | J16: 7 | K16: =CPC模拟表格!V16 -> 10.833333 | L16: =SUM(H16*-K16) -> -1137.5 | M16: =毛利模拟盈亏!T16 -> 619.9569 | N16: =SUM(L16:M16) -> -517.5431 | O16: 300 | P16: =AE16 -> 30 | Q16: =P16*0.5 -> 15 | R16: =1-Q16/P16 -> 0.5 | S16: =SUM(P16-Q16) -> 15 | T16: =SUM(L16/J16) -> -162.5 | U16: =毛利模拟盈亏!V16 -> 3777.9 | V16: =-L16/U16 -> 0.3010932 | W16: =AC16 -> 0 | Z16: 4.有评论再启动广告，10条优质图片视频评论 | AD16: 900 | AE16: =AD16/30 -> 30
B17: 第14周 | C17: =价格策略模拟!B7 -> 17.99 | D17: =价格策略模拟!C7 -> 0.05 | E17: =价格策略模拟!D7 -> 0 | F17: =SUM(C17*(1-D17-E17)) -> 17.0905 | G17: =J17*S17 -> 105 | H17: =J17*Q17 -> 105 | I17: =SUM(G17:H17) -> 210 | J17: 7 | K17: =CPC模拟表格!V17 -> 10.833333 | L17: =SUM(H17*-K17) -> -1137.5 | M17: =毛利模拟盈亏!T17 -> 619.9569 | N17: =SUM(L17:M17) -> -517.5431 | P17: =AE17 -> 30 | Q17: =P17*0.5 -> 15 | R17: =1-Q17/P17 -> 0.5 | S17: =SUM(P17-Q17) -> 15 | T17: =SUM(L17/J17) -> -162.5 | U17: =毛利模拟盈亏!V17 -> 3777.9 | V17: =-L17/U17 -> 0.3010932 | W17: =AC17 -> 0 | AD17: 900 | AE17: =AD17/30 -> 30
B18: 第15周 | C18: =价格策略模拟!B7 -> 17.99 | D18: =价格策略模拟!C7 -> 0.05 | E18: =价格策略模拟!D7 -> 0 | F18: =SUM(C18*(1-D18-E18)) -> 17.0905 | G18: =J18*S18 -> 126 | H18: =J18*Q18 -> 84 | I18: =SUM(G18:H18) -> 210 | J18: 7 | K18: =CPC模拟表格!V18 -> 10.416667 | L18: =SUM(H18*-K18) -> -875 | M18: =毛利模拟盈亏!T18 -> 619.9569 | N18: =SUM(L18:M18) -> -255.0431 | P18: =AE18 -> 30 | Q18: =P18*0.4 -> 12 | R18: =1-Q18/P18 -> 0.6 | S18: =SUM(P18-Q18) -> 18 | T18: =SUM(L18/J18) -> -125 | U18: =毛利模拟盈亏!V18 -> 3777.9 | V18: =-L18/U18 -> 0.23161015 | W18: =AC18 -> 0 | AD18: 900 | AE18: =AD18/30 -> 30
B19: 第16周 | C19: =价格策略模拟!B7 -> 17.99 | D19: =价格策略模拟!C7 -> 0.05 | E19: =价格策略模拟!D7 -> 0 | F19: =SUM(C19*(1-D19-E19)) -> 17.0905 | G19: =J19*S19 -> 126 | H19: =J19*Q19 -> 84 | I19: =SUM(G19:H19) -> 210 | J19: 7 | K19: =CPC模拟表格!V19 -> 10.416667 | L19: =SUM(H19*-K19) -> -875 | M19: =毛利模拟盈亏!T19 -> 619.9569 | N19: =SUM(L19:M19) -> -255.0431 | P19: =AE19 -> 30 | Q19: =P19*0.4 -> 12 | R19: =1-Q19/P19 -> 0.6 | S19: =SUM(P19-Q19) -> 18 | T19: =SUM(L19/J19) -> -125 | U19: =毛利模拟盈亏!V19 -> 3777.9 | V19: =-L19/U19 -> 0.23161015 | W19: =AC19 -> 0 | AD19: 900 | AE19: =AD19/30 -> 30
A20: 第五阶段 | B20: 第17周 | C20: =价格策略模拟!B8 -> 17.99 | D20: =价格策略模拟!C8 -> 0.05 | E20: =价格策略模拟!D8 -> 0 | F20: =SUM(C20*(1-D20-E20)) -> 17.0905 | G20: =J20*S20 -> 126 | H20: =J20*Q20 -> 84 | I20: =SUM(G20:H20) -> 210 | J20: 7 | K20: =CPC模拟表格!V20 -> 9.2307692 | L20: =SUM(H20*-K20) -> -775.38462 | M20: =毛利模拟盈亏!T20 -> 619.9569 | N20: =SUM(L20:M20) -> -155.42772 | O20: 400 | P20: =AE20 -> 30 | Q20: =P20*0.4 -> 12 | R20: =1-Q20/P20 -> 0.6 | S20: =SUM(P20-Q20) -> 18 | T20: =SUM(L20/J20) -> -110.76923 | U20: =毛利模拟盈亏!V20 -> 3777.9 | V20: =-L20/U20 -> 0.20524223 | W20: =AC20 -> 0 | AD20: 900 | AE20: =AD20/30 -> 30
B21: 第18周 | C21: =价格策略模拟!B8 -> 17.99 | D21: =价格策略模拟!C8 -> 0.05 | E21: =价格策略模拟!D8 -> 0 | F21: =SUM(C21*(1-D21-E21)) -> 17.0905 | G21: =J21*S21 -> 126 | H21: =J21*Q21 -> 84 | I21: =SUM(G21:H21) -> 210 | J21: 7 | K21: =CPC模拟表格!V21 -> 9.2307692 | L21: =SUM(H21*-K21) -> -775.38462 | M21: =毛利模拟盈亏!T21 -> 619.9569 | N21: =SUM(L21:M21) -> -155.42772 | P21: =AE21 -> 30 | Q21: =P21*0.4 -> 12 | R21: =1-Q21/P21 -> 0.6 | S21: =SUM(P21-Q21) -> 18 | T21: =SUM(L21/J21) -> -110.76923 | U21: =毛利模拟盈亏!V21 -> 3777.9 | V21: =-L21/U21 -> 0.20524223 | W21: =AC21 -> 0 | AD21: 900 | AE21: =AD21/30 -> 30
B22: 第19周 | C22: =价格策略模拟!B8 -> 17.99 | D22: =价格策略模拟!C8 -> 0.05 | E22: =价格策略模拟!D8 -> 0 | F22: =SUM(C22*(1-D22-E22)) -> 17.0905 | G22: =J22*S22 -> 126 | H22: =J22*Q22 -> 84 | I22: =SUM(G22:H22) -> 210 | J22: 7 | K22: =CPC模拟表格!V22 -> 8.8461538 | L22: =SUM(H22*-K22) -> -743.07692 | M22: =毛利模拟盈亏!T22 -> 619.9569 | N22: =SUM(L22:M22) -> -123.12002 | P22: =AE22 -> 30 | Q22: =P22*0.4 -> 12 | R22: =1-Q22/P22 -> 0.6 | S22: =SUM(P22-Q22) -> 18 | T22: =SUM(L22/J22) -> -106.15385 | U22: =毛利模拟盈亏!V22 -> 3777.9 | V22: =-L22/U22 -> 0.19669047 | W22: =AC22 -> 0 | AD22: 900 | AE22: =AD22/30 -> 30
B23: 第20周 | C23: =价格策略模拟!B8 -> 17.99 | D23: =价格策略模拟!C8 -> 0.05 | E23: =价格策略模拟!D8 -> 0 | F23: =SUM(C23*(1-D23-E23)) -> 17.0905 | G23: =J23*S23 -> 147 | H23: =J23*Q23 -> 63 | I23: =SUM(G23:H23) -> 210 | J23: 7 | K23: =CPC模拟表格!V23 -> 8.8461538 | L23: =SUM(H23*-K23) -> -557.30769 | M23: =毛利模拟盈亏!T23 -> 619.9569 | N23: =SUM(L23:M23) -> 62.649208 | P23: =AE23 -> 30 | Q23: =P23*0.3 -> 9 | R23: =1-Q23/P23 -> 0.7 | S23: =SUM(P23-Q23) -> 21 | T23: =SUM(L23/J23) -> -79.615385 | U23: =毛利模拟盈亏!V23 -> 3777.9 | V23: =-L23/U23 -> 0.14751785 | W23: =AC23 -> 0 | AD23: 900 | AE23: =AD23/30 -> 30
A24: 第六阶段 | B24: 第21周 | C24: =价格策略模拟!B9 -> 17.99 | D24: =价格策略模拟!C9 -> 0 | E24: =价格策略模拟!D9 -> 0 | F24: =SUM(C24*(1-D24-E24)) -> 17.99 | G24: =J24*S24 -> 147 | H24: =J24*Q24 -> 63 | I24: =SUM(G24:H24) -> 210 | J24: 7 | K24: =CPC模拟表格!V24 -> 7.8571429 | L24: =SUM(H24*-K24) -> -495 | M24: =毛利模拟盈亏!T24 -> 780.402 | N24: =SUM(L24:M24) -> 285.402 | O24: 500 | P24: =AE24 -> 30 | Q24: =P24*0.3 -> 9 | R24: =1-Q24/P24 -> 0.7 | S24: =SUM(P24-Q24) -> 21 | T24: =SUM(L24/J24) -> -70.714286 | U24: =毛利模拟盈亏!V24 -> 3777.9 | V24: =-L24/U24 -> 0.13102517 | W24: =AC24 -> 0 | AD24: 900 | AE24: =AD24/30 -> 30
B25: 第22周 | C25: =价格策略模拟!B9 -> 17.99 | D25: =价格策略模拟!C9 -> 0 | E25: =价格策略模拟!D9 -> 0 | F25: =SUM(C25*(1-D25-E25)) -> 17.99 | G25: =J25*S25 -> 147 | H25: =J25*Q25 -> 63 | I25: =SUM(G25:H25) -> 210 | J25: 7 | K25: =CPC模拟表格!V25 -> 7.8571429 | L25: =SUM(H25*-K25) -> -495 | M25: =毛利模拟盈亏!T25 -> 780.402 | N25: =SUM(L25:M25) -> 285.402 | P25: =AE25 -> 30 | Q25: =P25*0.3 -> 9 | R25: =1-Q25/P25 -> 0.7 | S25: =SUM(P25-Q25) -> 21 | T25: =SUM(L25/J25) -> -70.714286 | U25: =毛利模拟盈亏!V25 -> 3777.9 | V25: =-L25/U25 -> 0.13102517 | W25: =AC25 -> 0 | AD25: 900 | AE25: =AD25/30 -> 30
B26: 第23周 | C26: =价格策略模拟!B9 -> 17.99 | D26: =价格策略模拟!C9 -> 0 | E26: =价格策略模拟!D9 -> 0 | F26: =SUM(C26*(1-D26-E26)) -> 17.99 | G26: =J26*S26 -> 157.5 | H26: =J26*Q26 -> 52.5 | I26: =SUM(G26:H26) -> 210 | J26: 7 | K26: =CPC模拟表格!V26 -> 7.3333333 | L26: =SUM(H26*-K26) -> -385 | M26: =毛利模拟盈亏!T26 -> 780.402 | N26: =SUM(L26:M26) -> 395.402 | P26: =AE26 -> 30 | Q26: =P26*0.25 -> 7.5 | R26: =1-Q26/P26 -> 0.75 | S26: =SUM(P26-Q26) -> 22.5 | T26: =SUM(L26/J26) -> -55 | U26: =毛利模拟盈亏!V26 -> 3777.9 | V26: =-L26/U26 -> 0.10190847 | W26: =AC26 -> 0 | AD26: 900 | AE26: =AD26/30 -> 30
B27: 第24周 | C27: =价格策略模拟!B9 -> 17.99 | D27: =价格策略模拟!C9 -> 0 | E27: =价格策略模拟!D9 -> 0 | F27: =SUM(C27*(1-D27-E27)) -> 17.99 | G27: =J27*S27 -> 157.5 | H27: =J27*Q27 -> 52.5 | I27: =SUM(G27:H27) -> 210 | J27: 7 | K27: =CPC模拟表格!V27 -> 7.3333333 | L27: =SUM(H27*-K27) -> -385 | M27: =毛利模拟盈亏!T27 -> 780.402 | N27: =SUM(L27:M27) -> 395.402 | P27: =AE27 -> 30 | Q27: =P27*0.25 -> 7.5 | R27: =1-Q27/P27 -> 0.75 | S27: =SUM(P27-Q27) -> 22.5 | T27: =SUM(L27/J27) -> -55 | U27: =毛利模拟盈亏!V27 -> 3777.9 | V27: =-L27/U27 -> 0.10190847 | W27: =AC27 -> 0 | AD27: 900 | AE27: =AD27/30 -> 30
R28: =1-Q28/P28 -> #DIV/0! | W28: =AC28 -> 卖家精灵的【销量预测】查月销量 | AC28: 卖家精灵的【销量预测】查月销量
A29: 阶段盈亏真实数据 | R29: =1-Q29/P29 -> #DIV/0!
A30: 第一阶段 | B30: 第1周 | R30: =1-Q30/P30 -> #DIV/0! | W30: =AC30 -> 0
B31: 第2周 | R31: =1-Q31/P31 -> #DIV/0! | W31: =AC31 -> 0
B32: 第3周 | R32: =1-Q32/P32 -> #DIV/0! | W32: =AC32 -> 0
B33: 第4周 | R33: =1-Q33/P33 -> #DIV/0! | W33: =AC33 -> 0
A34: 第二阶段 | B34: 第5周 | R34: =1-Q34/P34 -> #DIV/0! | W34: =AC34 -> 0
B35: 第6周 | R35: =1-Q35/P35 -> #DIV/0! | W35: =AC35 -> 0
B36: 第7周 | R36: =1-Q36/P36 -> #DIV/0! | W36: =AC36 -> 0
B37: 第8周 | R37: =1-Q37/P37 -> #DIV/0! | W37: =AC37 -> 0
A38: 第三阶段 | B38: 第9周 | R38: =1-Q38/P38 -> #DIV/0! | W38: =AC38 -> 0
B39: 第10周 | R39: =1-Q39/P39 -> #DIV/0! | W39: =AC39 -> 0
B40: 第11周 | R40: =1-Q40/P40 -> #DIV/0! | W40: =AC40 -> 0
...

Sheet CPC模拟表格
A1: 常规数据 | N1: 广告数据 | AB1: 实时更新 | AC1: 操作备注
A2: 阶段 | B2: 周期 | C2: 价格 | D2: 站内 coupon | E2: 站内 code | F2: 折后价 | G2: 新品 榜单 | H2: 小类目 排名 | I2: 总 销量 | J2: 总访 问量 | K2: CVR | L2: 评论 数量 | M2: 评分 | N2: 曝光量 | O2: 广告 点击 | P2: CTR | Q2: 广告单 | R2: CVR | S2: 平均 CPC | T2: 花费 | U2: ACOS | V2: CPA | W2: 日均 广告费 | X2: 自然 访问 | Y2: 自然 订单 | Z2: 自然 单占比 | AA2: 最终 盈亏 | AB2: 质量分 | AC2: 运营调整 | AD2: 广告操作
C3: 与价格模拟表一样 | D3: 与价格模拟表一样 | E3: 与价格模拟表一样 | H3: 数据来源阶段总盈亏 | O3: 公式 | Q3: 数据来源阶段总盈亏 | R3: 转化率参考竞品 用极目可查 | S3: 极目/SIF/卖家精灵都可以 | T3: 1.花费=广告点击*cpc | U3: 2.acos=cpc/转化率/客单价 | V3: 如何得出CPA？ | W3: 公式
A4: 第一阶段 | B4: 第1周 | C4: =价格策略模拟!B4 -> 17.99 | D4: 0.3 | E4: =价格策略模拟!D4 -> 0 | F4: =SUM(C4*(1-D4-E4)) -> 12.593 | H4: =阶段总盈亏!AC4 -> 0 | O4: =SUM(Q4/R4) -> 132.63158 | Q4: =阶段总盈亏!H4 -> 12.6 | R4: 0.095 | S4: 1.5 | T4: =SUM(O4*S4) -> 198.94737 | U4: =SUM(S4/R4/C4) -> 0.87768058 | V4: =SUM(T4/Q4) -> 15.789474 | W4: =T4/7 -> 28.421053
B5: 第2周 | C5: =价格策略模拟!B4 -> 17.99 | D5: =价格策略模拟!C4 -> 0.2 | E5: =价格策略模拟!D4 -> 0 | F5: =SUM(C5*(1-D5-E5)) -> 14.392 | H5: =阶段总盈亏!AC5 -> 0 | O5: =SUM(Q5/R5) -> 198.94737 | Q5: =阶段总盈亏!H5 -> 18.9 | R5: 0.095 | S5: 1.45 | T5: =SUM(O5*S5) -> 288.47368 | U5: =SUM(S5/R5/C5) -> 0.84842456 | V5: =SUM(T5/Q5) -> 15.263158 | W5: =T5/7 -> 41.210526
B6: 第3周 | C6: =价格策略模拟!B4 -> 17.99 | D6: =价格策略模拟!C4 -> 0.2 | E6: =价格策略模拟!D4 -> 0 | F6: =SUM(C6*(1-D6-E6)) -> 14.392 | H6: =阶段总盈亏!AC6 -> 0 | O6: =SUM(Q6/R6) -> 294.73684 | Q6: =阶段总盈亏!H6 -> 28 | R6: 0.095 | S6: 1.4 | T6: =SUM(O6*S6) -> 412.63158 | U6: =SUM(S6/R6/C6) -> 0.81916854 | V6: =SUM(T6/Q6) -> 14.736842 | W6: =T6/7 -> 58.947368
B7: 第4周 | C7: =价格策略模拟!B4 -> 17.99 | D7: =价格策略模拟!C4 -> 0.2 | E7: =价格策略模拟!D4 -> 0 | F7: =SUM(C7*(1-D7-E7)) -> 14.392 | H7: =阶段总盈亏!AC7 -> 0 | O7: =SUM(Q7/R7) -> 412.63158 | Q7: =阶段总盈亏!H7 -> 39.2 | R7: 0.095 | S7: 1.35 | T7: =SUM(O7*S7) -> 557.05263 | U7: =SUM(S7/R7/C7) -> 0.78991252 | V7: =SUM(T7/Q7) -> 14.210526 | W7: =T7/7 -> 79.578947
A8: 第二阶段 | B8: 第5周 | C8: =价格策略模拟!B5 -> 17.99 | D8: =价格策略模拟!C5 -> 0.15 | E8: =价格策略模拟!D5 -> 0 | F8: =SUM(C8*(1-D8-E8)) -> 15.2915 | H8: =阶段总盈亏!AC8 -> 0 | O8: =SUM(Q8/R8) -> 504 | Q8: =阶段总盈亏!H8 -> 50.4 | R8: 0.1 | S8: 1.35 | T8: =SUM(O8*S8) -> 680.4 | U8: =SUM(S8/R8/C8) -> 0.7504169 | V8: =SUM(T8/Q8) -> 13.5 | W8: =T8/7 -> 97.2
B9: 第6周 | C9: =价格策略模拟!B5 -> 17.99 | D9: =价格策略模拟!C5 -> 0.15 | E9: =价格策略模拟!D5 -> 0 | F9: =SUM(C9*(1-D9-E9)) -> 15.2915 | H9: =阶段总盈亏!AC9 -> 0 | O9: =SUM(Q9/R9) -> 653.33333 | Q9: =阶段总盈亏!H9 -> 65.333333 | R9: 0.1 | S9: 1.35 | T9: =SUM(O9*S9) -> 882 | U9: =SUM(S9/R9/C9) -> 0.7504169 | V9: =SUM(T9/Q9) -> 13.5 | W9: =T9/7 -> 126
B10: 第7周 | C10: =价格策略模拟!B5 -> 17.99 | D10: =价格策略模拟!C5 -> 0.15 | E10: =价格策略模拟!D5 -> 0 | F10: =SUM(C10*(1-D10-E10)) -> 15.2915 | H10: =阶段总盈亏!AC10 -> 0 | O10: =SUM(Q10/R10) -> 787.5 | Q10: =阶段总盈亏!H10 -> 78.75 | R10: 0.1 | S10: 1.35 | T10: =SUM(O10*S10) -> 1063.125 | U10: =SUM(S10/R10/C10) -> 0.7504169 | V10: =SUM(T10/Q10) -> 13.5 | W10: =T10/7 -> 151.875
B11: 第8周 | C11: =价格策略模拟!B5 -> 17.99 | D11: =价格策略模拟!C5 -> 0.15 | E11: =价格策略模拟!D5 -> 0 | F11: =SUM(C11*(1-D11-E11)) -> 15.2915 | H11: =阶段总盈亏!AC11 -> 0 | O11: =SUM(Q11/R11) -> 980 | Q11: =阶段总盈亏!H11 -> 98 | R11: 0.1 | S11: 1.35 | T11: =SUM(O11*S11) -> 1323 | U11: =SUM(S11/R11/C11) -> 0.7504169 | V11: =SUM(T11/Q11) -> 13.5 | W11: =T11/7 -> 189
A12: 第三阶段 | B12: 第9周 | C12: =价格策略模拟!B6 -> 17.99 | D12: =价格策略模拟!C6 -> 0.1 | E12: =价格策略模拟!D6 -> 0 | F12: =SUM(C12*(1-D12-E12)) -> 16.191 | H12: =阶段总盈亏!AC12 -> 0 | O12: =SUM(Q12/R12) -> 1097.7273 | Q12: =阶段总盈亏!H12 -> 120.75 | R12: 0.11 | S12: 1.4 | T12: =SUM(O12*S12) -> 1536.8182 | U12: =SUM(S12/R12/C12) -> 0.70746374 | V12: =SUM(T12/Q12) -> 12.727273 | W12: =T12/7 -> 219.54545
B13: 第10周 | C13: =价格策略模拟!B6 -> 17.99 | D13: =价格策略模拟!C6 -> 0.1 | E13: =价格策略模拟!D6 -> 0 | F13: =SUM(C13*(1-D13-E13)) -> 16.191 | H13: =阶段总盈亏!AC13 -> 0 | O13: =SUM(Q13/R13) -> 992.72727 | Q13: =阶段总盈亏!H13 -> 109.2 | R13: 0.11 | S13: 1.4 | T13: =SUM(O13*S13) -> 1389.8182 | U13: =SUM(S13/R13/C13) -> 0.70746374 | V13: =SUM(T13/Q13) -> 12.727273 | W13: =T13/7 -> 198.54545
B14: 第11周 | C14: =价格策略模拟!B6 -> 17.99 | D14: =价格策略模拟!C6 -> 0.1 | E14: =价格策略模拟!D6 -> 0 | F14: =SUM(C14*(1-D14-E14)) -> 16.191 | H14: =阶段总盈亏!AC14 -> 0 | O14: =SUM(Q14/R14) -> 901.51515 | Q14: =阶段总盈亏!H14 -> 99.166667 | R14: 0.11 | S14: 1.4 | T14: =SUM(O14*S14) -> 1262.1212 | U14: =SUM(S14/R14/C14) -> 0.70746374 | V14: =SUM(T14/Q14) -> 12.727273 | W14: =T14/7 -> 180.30303
B15: 第12周 | C15: =价格策略模拟!B6 -> 17.99 | D15: =价格策略模拟!C6 -> 0.1 | E15: =价格策略模拟!D6 -> 0 | F15: =SUM(C15*(1-D15-E15)) -> 16.191 | H15: =阶段总盈亏!AC15 -> 20 | O15: =SUM(Q15/R15) -> 954.54545 | Q15: =阶段总盈亏!H15 -> 105 | R15: 0.11 | S15: 1.35 | T15: =SUM(O15*S15) -> 1288.6364 | U15: =SUM(S15/R15/C15) -> 0.68219718 | V15: =SUM(T15/Q15) -> 12.272727 | W15: =T15/7 -> 184.09091
A16: 第四阶段 | B16: 第13周 | C16: =价格策略模拟!B7 -> 17.99 | D16: =价格策略模拟!C7 -> 0.05 | E16: =价格策略模拟!D7 -> 0 | F16: =SUM(C16*(1-D16-E16)) -> 17.0905 | H16: =阶段总盈亏!AC16 -> 0 | O16: =SUM(Q16/R16) -> 875 | Q16: =阶段总盈亏!H16 -> 105 | R16: 0.12 | S16: 1.3 | T16: =SUM(O16*S16) -> 1137.5 | U16: =SUM(S16/R16/C16) -> 0.6021864 | V16: =SUM(T16/Q16) -> 10.833333 | W16: =T16/7 -> 162.5
B17: 第14周 | C17: =价格策略模拟!B7 -> 17.99 | D17: =价格策略模拟!C7 -> 0.05 | E17: =价格策略模拟!D7 -> 0 | F17: =SUM(C17*(1-D17-E17)) -> 17.0905 | H17: =阶段总盈亏!AC17 -> 0 | O17: =SUM(Q17/R17) -> 875 | Q17: =阶段总盈亏!H17 -> 105 | R17: 0.12 | S17: 1.3 | T17: =SUM(O17*S17) -> 1137.5 | U17: =SUM(S17/R17/C17) -> 0.6021864 | V17: =SUM(T17/Q17) -> 10.833333 | W17: =T17/7 -> 162.5
B18: 第15周 | C18: =价格策略模拟!B7 -> 17.99 | D18: =价格策略模拟!C7 -> 0.05 | E18: =价格策略模拟!D7 -> 0 | F18: =SUM(C18*(1-D18-E18)) -> 17.0905 | H18: =阶段总盈亏!AC18 -> 0 | O18: =SUM(Q18/R18) -> 700 | Q18: =阶段总盈亏!H18 -> 84 | R18: 0.12 | S18: 1.25 | T18: =SUM(O18*S18) -> 875 | U18: =SUM(S18/R18/C18) -> 0.57902538 | V18: =SUM(T18/Q18) -> 10.416667 | W18: =T18/7 -> 125
B19: 第16周 | C19: =价格策略模拟!B7 -> 17.99 | D19: =价格策略模拟!C7 -> 0.05 | E19: =价格策略模拟!D7 -> 0 | F19: =SUM(C19*(1-D19-E19)) -> 17.0905 | H19: =阶段总盈亏!AC19 -> 0 | O19: =SUM(Q19/R19) -> 700 | Q19: =阶段总盈亏!H19 -> 84 | R19: 0.12 | S19: 1.25 | T19: =SUM(O19*S19) -> 875 | U19: =SUM(S19/R19/C19) -> 0.57902538 | V19: =SUM(T19/Q19) -> 10.416667 | W19: =T19/7 -> 125
A20: 第五阶段 | B20: 第17周 | C20: =价格策略模拟!B8 -> 17.99 | D20: =价格策略模拟!C8 -> 0.05 | E20: =价格策略模拟!D8 -> 0 | F20: =SUM(C20*(1-D20-E20)) -> 17.0905 | H20: =阶段总盈亏!AC20 -> 0 | O20: =SUM(Q20/R20) -> 646.15385 | Q20: =阶段总盈亏!H20 -> 84 | R20: 0.13 | S20: 1.2 | T20: =SUM(O20*S20) -> 775.38462 | U20: =SUM(S20/R20/C20) -> 0.51310557 | V20: =SUM(T20/Q20) -> 9.2307692 | W20: =T20/7 -> 110.76923
B21: 第18周 | C21: =价格策略模拟!B8 -> 17.99 | D21: =价格策略模拟!C8 -> 0.05 | E21: =价格策略模拟!D8 -> 0 | F21: =SUM(C21*(1-D21-E21)) -> 17.0905 | H21: =阶段总盈亏!AC21 -> 0 | O21: =SUM(Q21/R21) -> 646.15385 | Q21: =阶段总盈亏!H21 -> 84 | R21: 0.13 | S21: 1.2 | T21: =SUM(O21*S21) -> 775.38462 | U21: =SUM(S21/R21/C21) -> 0.51310557 | V21: =SUM(T21/Q21) -> 9.2307692 | W21: =T21/7 -> 110.76923
B22: 第19周 | C22: =价格策略模拟!B8 -> 17.99 | D22: =价格策略模拟!C8 -> 0.05 | E22: =价格策略模拟!D8 -> 0 | F22: =SUM(C22*(1-D22-E22)) -> 17.0905 | H22: =阶段总盈亏!AC22 -> 0 | O22: =SUM(Q22/R22) -> 646.15385 | Q22: =阶段总盈亏!H22 -> 84 | R22: 0.13 | S22: 1.15 | T22: =SUM(O22*S22) -> 743.07692 | U22: =SUM(S22/R22/C22) -> 0.49172617 | V22: =SUM(T22/Q22) -> 8.8461538 | W22: =T22/7 -> 106.15385
B23: 第20周 | C23: =价格策略模拟!B8 -> 17.99 | D23: =价格策略模拟!C8 -> 0.05 | E23: =价格策略模拟!D8 -> 0 | F23: =SUM(C23*(1-D23-E23)) -> 17.0905 | H23: =阶段总盈亏!AC23 -> 0 | O23: =SUM(Q23/R23) -> 484.61538 | Q23: =阶段总盈亏!H23 -> 63 | R23: 0.13 | S23: 1.15 | T23: =SUM(O23*S23) -> 557.30769 | U23: =SUM(S23/R23/C23) -> 0.49172617 | V23: =SUM(T23/Q23) -> 8.8461538 | W23: =T23/7 -> 79.615385
A24: 第六阶段 | B24: 第21周 | C24: =价格策略模拟!B9 -> 17.99 | D24: =价格策略模拟!C9 -> 0 | E24: =价格策略模拟!D9 -> 0 | F24: =SUM(C24*(1-D24-E24)) -> 17.99 | H24: =阶段总盈亏!AC24 -> 0 | O24: =SUM(Q24/R24) -> 450 | Q24: =阶段总盈亏!H24 -> 63 | R24: 0.14 | S24: 1.1 | T24: =SUM(O24*S24) -> 495 | U24: =SUM(S24/R24/C24) -> 0.43675058 | V24: =SUM(T24/Q24) -> 7.8571429 | W24: =T24/7 -> 70.714286
B25: 第22周 | C25: =价格策略模拟!B9 -> 17.99 | D25: =价格策略模拟!C9 -> 0 | E25: =价格策略模拟!D9 -> 0 | F25: =SUM(C25*(1-D25-E25)) -> 17.99 | H25: =阶段总盈亏!AC25 -> 0 | O25: =SUM(Q25/R25) -> 450 | Q25: =阶段总盈亏!H25 -> 63 | R25: 0.14 | S25: 1.1 | T25: =SUM(O25*S25) -> 495 | U25: =SUM(S25/R25/C25) -> 0.43675058 | V25: =SUM(T25/Q25) -> 7.8571429 | W25: =T25/7 -> 70.714286
B26: 第23周 | C26: =价格策略模拟!B9 -> 17.99 | D26: =价格策略模拟!C9 -> 0 | E26: =价格策略模拟!D9 -> 0 | F26: =SUM(C26*(1-D26-E26)) -> 17.99 | H26: =阶段总盈亏!AC26 -> 0 | O26: =SUM(Q26/R26) -> 350 | Q26: =阶段总盈亏!H26 -> 52.5 | R26: 0.15 | S26: 1.1 | T26: =SUM(O26*S26) -> 385 | U26: =SUM(S26/R26/C26) -> 0.40763387 | V26: =SUM(T26/Q26) -> 7.3333333 | W26: =T26/7 -> 55
B27: 第24周 | C27: =价格策略模拟!B9 -> 17.99 | D27: =价格策略模拟!C9 -> 0 | E27: =价格策略模拟!D9 -> 0 | F27: =SUM(C27*(1-D27-E27)) -> 17.99 | H27: =阶段总盈亏!AC27 -> 0 | O27: =SUM(Q27/R27) -> 350 | Q27: =阶段总盈亏!H27 -> 52.5 | R27: 0.15 | S27: 1.1 | T27: =SUM(O27*S27) -> 385 | U27: =SUM(S27/R27/C27) -> 0.40763387 | V27: =SUM(T27/Q27) -> 7.3333333 | W27: =T27/7 -> 55
R28: 搜索词点击转化率 ABA数据里，ASIN视图里 需要数据加工
R29: 竞品的转化率，极目软件可查
R30: 类目平均转化率在增长建议里面-选品指南针-类目分析-输入关键词找品类-有转化率，有退货率
A31: 广告真实数据
A32: 常规数据 | N32: 广告数据 | AB32: 实时更新 | AC32: 操作备注
A33: 阶段 | B33: 周 | C33: 价格 | D33: 站内 coupon | E33: 站内 code | F33: 折后价 | G33: 新品 榜单 | H33: 小类目 排名 | I33: 总 销量 | J33: 总访 问量 | K33: CVR | L33: 评论 数量 | M33: 评分 | N33: 曝光量 | O33: 点击量 | P33: CTR | Q33: 广告单 | R33: CVR | S33: 平均 CPC | T33: 花费 | U33: ACOS | V33: CPA | W33: 日均 广告费 | X33: 自然 访问 | Y33: 自然 订单 | Z33: 自然 单占比 | AA33: 最终 盈亏 | AB33: 质量分 | AC33: 运营调整 | AD33: 广告操作
A34: 第一阶段 | B34: 第1周
B35: 第2周
B36: 第3周
B37: 第4周
A38: 第二阶段 | B38: 第5周
B39: 第6周
B40: 第7周
...

Sheet 毛利模拟盈亏
A1: 每日盈亏数据预估
A2: 阶段 | B2: 周期 | C2: 定价 | D2: coupon | E2: code | F2: 折后价 | G2: FBA 配送费 | H2: 亚马逊 佣金 | I2: 账号 回款 | J2: 仓储费+入库配置费 | K2: coupon 费用 | L2: 产品 成本 | M2: 物流费 | N2: 退货成本(公式后面加的是单套产品的移除费） | O2: 退货率 | P2: 每单平摊 退货成本 | Q2: 每单 毛利 | R2: 毛利率 | S2: 订单 数量 | T2: 阶段 订单 亏损 | U2: 阶段 订单 总盈亏 | V2: 每周 销售额 | W2: 实际回款
G3: 公式 来源《价格模拟表》 | L3: 公式 来源《价格模拟表》 | M3: 公式 来源《价格模拟表》 | N3: 公式 来源《价格模拟表》 | O3: 公式 来源《价格模拟表》 | S3: *来源 阶段总盈亏，需要拆解日销量*7天 | T3: 公式 | U3: 公式 | W3: 产品成本+头程运+毛利润）*订单量-广告费
A4: 第一阶段 | B4: 第1周 | C4: =价格策略模拟!B4 -> 17.99 | D4: =价格策略模拟!C4 -> 0.2 | E4: =价格策略模拟!D4 -> 0 | F4: =SUM(C4*(1-D4-E4)) -> 14.392 | G4: =价格策略模拟!F4 -> 6 | H4: =SUM(F4*15%) -> 2.1588 | I4: =SUM(F4-G4-H4) -> 6.2332 | J4: 0.22 | K4: 0 | L4: =价格策略模拟!K4 -> 3.7 | M4: =价格策略模拟!L4 -> 1.4 | N4: =SUM(20%*15%*F4+G4+J4+L4+M4+0.65) -> 12.40176 | O4: =价格策略模拟!N4 -> 0.02 | P4: =SUM(N4*O4/(1-O4)) -> 0.25309714 | Q4: =SUM(I4-J4-K4-L4-M4-P4) -> 0.66010286 | R4: =SUM(Q4/C4) -> 0.036692766 | S4: =阶段总盈亏!I4 -> 14 | T4: =SUM(Q4*S4) -> 9.24144 | U4: =SUM(T4:T4) -> 9.24144 | V4: =S4*C4 -> 251.86 | W4: =(L4+M4+Q4)*S4 -> 80.64144
B5: 第2周 | C5: =价格策略模拟!B4 -> 17.99 | D5: =价格策略模拟!C4 -> 0.2 | E5: =价格策略模拟!D4 -> 0 | F5: =SUM(C5*(1-D5-E5)) -> 14.392 | G5: =G4 -> 6 | H5: =SUM(F5*15%) -> 2.1588 | I5: =SUM(F5-G5-H5) -> 6.2332 | J5: 0.22 | K5: 0 | L5: =L4 -> 3.7 | M5: =M4 -> 1.4 | N5: =SUM(20%*15%*F5+G5+J5+L5+M5+0.65) -> 12.40176 | O5: =O4 -> 0.02 | P5: =SUM(N5*O5/(1-O5)) -> 0.25309714 | Q5: =SUM(I5-J5-K5-L5-M5-P5) -> 0.66010286 | R5: =SUM(Q5/C5) -> 0.036692766 | S5: =阶段总盈亏!I5 -> 21 | T5: =SUM(Q5*S5) -> 13.86216 | U5: =SUM(T5:T5) -> 13.86216 | V5: =S5*C5 -> 377.79 | W5: =(L5+M5+Q5)*S5 -> 120.96216
B6: 第3周 | C6: =价格策略模拟!B4 -> 17.99 | D6: =价格策略模拟!C4 -> 0.2 | E6: =价格策略模拟!D4 -> 0 | F6: =SUM(C6*(1-D6-E6)) -> 14.392 | G6: =G5 -> 6 | H6: =SUM(F6*15%) -> 2.1588 | I6: =SUM(F6-G6-H6) -> 6.2332 | J6: 0.22 | K6: 0 | L6: =L5 -> 3.7 | M6: =M5 -> 1.4 | N6: =SUM(20%*15%*F6+G6+J6+L6+M6+0.65) -> 12.40176 | O6: =O5 -> 0.02 | P6: =SUM(N6*O6/(1-O6)) -> 0.25309714 | Q6: =SUM(I6-J6-K6-L6-M6-P6) -> 0.66010286 | R6: =SUM(Q6/C6) -> 0.036692766 | S6: =阶段总盈亏!I6 -> 35 | T6: =SUM(Q6*S6) -> 23.1036 | U6: =SUM(T6:T6) -> 23.1036 | V6: =S6*C6 -> 629.65 | W6: =(L6+M6+Q6)*S6 -> 201.6036
B7: 第4周 | C7: =价格策略模拟!B4 -> 17.99 | D7: =价格策略模拟!C4 -> 0.2 | E7: =价格策略模拟!D4 -> 0 | F7: =SUM(C7*(1-D7-E7)) -> 14.392 | G7: =G6 -> 6 | H7: =SUM(F7*15%) -> 2.1588 | I7: =SUM(F7-G7-H7) -> 6.2332 | J7: 0.22 | K7: 0 | L7: =L6 -> 3.7 | M7: =M6 -> 1.4 | N7: =SUM(20%*15%*F7+G7+J7+L7+M7+0.65) -> 12.40176 | O7: =O6 -> 0.02 | P7: =SUM(N7*O7/(1-O7)) -> 0.25309714 | Q7: =SUM(I7-J7-K7-L7-M7-P7) -> 0.66010286 | R7: =SUM(Q7/C7) -> 0.036692766 | S7: =阶段总盈亏!I7 -> 49 | T7: =SUM(Q7*S7) -> 32.34504 | U7: =SUM(T7:T7) -> 32.34504 | V7: =S7*C7 -> 881.51 | W7: =(L7+M7+Q7)*S7 -> 282.24504
A8: 第二阶段 | B8: 第5周 | C8: =价格策略模拟!B5 -> 17.99 | D8: =价格策略模拟!C5 -> 0.15 | E8: =价格策略模拟!D5 -> 0 | F8: =SUM(C8*(1-D8-E8)) -> 15.2915 | G8: =G7 -> 6 | H8: =SUM(F8*15%) -> 2.293725 | I8: =SUM(F8-G8-H8) -> 6.997775 | J8: 0.22 | K8: 0 | L8: =L7 -> 3.7 | M8: =M7 -> 1.4 | N8: =SUM(20%*15%*F8+G8+J8+L8+M8+0.65) -> 12.428745 | O8: =O7 -> 0.02 | P8: =SUM(N8*O8/(1-O8)) -> 0.25364786 | Q8: =SUM(I8-J8-K8-L8-M8-P8) -> 1.4241271 | R8: =SUM(Q8/C8) -> 0.079162154 | S8: =阶段总盈亏!I8 -> 63 | T8: =SUM(Q8*S8) -> 89.72001 | U8: =SUM(T8:T8) -> 89.72001 | V8: =S8*C8 -> 1133.37 | W8: =(L8+M8+Q8)*S8 -> 411.02001
B9: 第6周 | C9: =价格策略模拟!B5 -> 17.99 | D9: =价格策略模拟!C5 -> 0.15 | E9: =价格策略模拟!D5 -> 0 | F9: =SUM(C9*(1-D9-E9)) -> 15.2915 | G9: =G8 -> 6 | H9: =SUM(F9*15%) -> 2.293725 | I9: =SUM(F9-G9-H9) -> 6.997775 | J9: 0.22 | K9: 0 | L9: =L8 -> 3.7 | M9: =M8 -> 1.4 | N9: =SUM(20%*15%*F9+G9+J9+L9+M9+0.65) -> 12.428745 | O9: =O8 -> 0.02 | P9: =SUM(N9*O9/(1-O9)) -> 0.25364786 | Q9: =SUM(I9-J9-K9-L9-M9-P9) -> 1.4241271 | R9: =SUM(Q9/C9) -> 0.079162154 | S9: =阶段总盈亏!I9 -> 81.666667 | T9: =SUM(Q9*S9) -> 116.30372 | U9: =SUM(T9:T9) -> 116.30372 | V9: =S9*C9 -> 1469.1833 | W9: =(L9+M9+Q9)*S9 -> 532.80372
B10: 第7周 | C10: =价格策略模拟!B5 -> 17.99 | D10: =价格策略模拟!C5 -> 0.15 | E10: =价格策略模拟!D5 -> 0 | F10: =SUM(C10*(1-D10-E10)) -> 15.2915 | G10: =G9 -> 6 | H10: =SUM(F10*15%) -> 2.293725 | I10: =SUM(F10-G10-H10) -> 6.997775 | J10: 0.22 | K10: 0 | L10: =L9 -> 3.7 | M10: =M9 -> 1.4 | N10: =SUM(20%*15%*F10+G10+J10+L10+M10+0.65) -> 12.428745 | O10: =O9 -> 0.02 | P10: =SUM(N10*O10/(1-O10)) -> 0.25364786 | Q10: =SUM(I10-J10-K10-L10-M10-P10) -> 1.4241271 | R10: =SUM(Q10/C10) -> 0.079162154 | S10: =阶段总盈亏!I10 -> 105 | T10: =SUM(Q10*S10) -> 149.53335 | U10: =SUM(T10:T10) -> 149.53335 | V10: =S10*C10 -> 1888.95 | W10: =(L10+M10+Q10)*S10 -> 685.03335
B11: 第8周 | C11: =价格策略模拟!B5 -> 17.99 | D11: =价格策略模拟!C5 -> 0.15 | E11: =价格策略模拟!D5 -> 0 | F11: =SUM(C11*(1-D11-E11)) -> 15.2915 | G11: =G10 -> 6 | H11: =SUM(F11*15%) -> 2.293725 | I11: =SUM(F11-G11-H11) -> 6.997775 | J11: 0.22 | K11: 0 | L11: =L10 -> 3.7 | M11: =M10 -> 1.4 | N11: =SUM(20%*15%*F11+G11+J11+L11+M11+0.65) -> 12.428745 | O11: =O10 -> 0.02 | P11: =SUM(N11*O11/(1-O11)) -> 0.25364786 | Q11: =SUM(I11-J11-K11-L11-M11-P11) -> 1.4241271 | R11: =SUM(Q11/C11) -> 0.079162154 | S11: =阶段总盈亏!I11 -> 130.66667 | T11: =SUM(Q11*S11) -> 186.08595 | U11: =SUM(T11:T11) -> 186.08595 | V11: =S11*C11 -> 2350.6933 | W11: =(L11+M11+Q11)*S11 -> 852.48595
A12: 第三阶段 | B12: 第9周 | C12: =价格策略模拟!B6 -> 17.99 | D12: =价格策略模拟!C6 -> 0.1 | E12: =价格策略模拟!D6 -> 0 | F12: =SUM(C12*(1-D12-E12)) -> 16.191 | G12: =G11 -> 6 | H12: =SUM(F12*15%) -> 2.42865 | I12: =SUM(F12-G12-H12) -> 7.76235 | J12: 0.22 | K12: 0 | L12: =L11 -> 3.7 | M12: =M11 -> 1.4 | N12: =SUM(20%*15%*F12+G12+J12+L12+M12+0.65) -> 12.45573 | O12: =O11 -> 0.02 | P12: =SUM(N12*O12/(1-O12)) -> 0.25419857 | Q12: =SUM(I12-J12-K12-L12-M12-P12) -> 2.1881514 | R12: =SUM(Q12/C12) -> 0.12163154 | S12: =阶段总盈亏!I12 -> 161 | T12: =SUM(Q12*S12) -> 352.29238 | U12: =SUM(T12:T12) -> 352.29238 | V12: =S12*C12 -> 2896.39 | W12: =(L12+M12+Q12)*S12 -> 1173.3924
B13: 第10周 | C13: =价格策略模拟!B6 -> 17.99 | D13: =价格策略模拟!C6 -> 0.1 | E13: =价格策略模拟!D6 -> 0 | F13: =SUM(C13*(1-D13-E13)) -> 16.191 | G13: =G12 -> 6 | H13: =SUM(F13*15%) -> 2.42865 | I13: =SUM(F13-G13-H13) -> 7.76235 | J13: 0.22 | K13: 0 | L13: =L12 -> 3.7 | M13: =M12 -> 1.4 | N13: =SUM(20%*15%*F13+G13+J13+L13+M13+0.65) -> 12.45573 | O13: =O12 -> 0.02 | P13: =SUM(N13*O13/(1-O13)) -> 0.25419857 | Q13: =SUM(I13-J13-K13-L13-M13-P13) -> 2.1881514 | R13: =SUM(Q13/C13) -> 0.12163154 | S13: =阶段总盈亏!I13 -> 182 | T13: =SUM(Q13*S13) -> 398.24356 | U13: =SUM(T13:T13) -> 398.24356 | V13: =S13*C13 -> 3274.18 | W13: =(L13+M13+Q13)*S13 -> 1326.4436
B14: 第11周 | C14: =价格策略模拟!B6 -> 17.99 | D14: =价格策略模拟!C6 -> 0.1 | E14: =价格策略模拟!D6 -> 0 | F14: =SUM(C14*(1-D14-E14)) -> 16.191 | G14: =G13 -> 6 | H14: =SUM(F14*15%) -> 2.42865 | I14: =SUM(F14-G14-H14) -> 7.76235 | J14: 0.22 | K14: 0 | L14: =L13 -> 3.7 | M14: =M13 -> 1.4 | N14: =SUM(20%*15%*F14+G14+J14+L14+M14+0.65) -> 12.45573 | O14: =O13 -> 0.02 | P14: =SUM(N14*O14/(1-O14)) -> 0.25419857 | Q14: =SUM(I14-J14-K14-L14-M14-P14) -> 2.1881514 | R14: =SUM(Q14/C14) -> 0.12163154 | S14: =阶段总盈亏!I14 -> 198.33333 | T14: =SUM(Q14*S14) -> 433.98337 | U14: =SUM(T14:T14) -> 433.98337 | V14: =S14*C14 -> 3568.0167 | W14: =(L14+M14+Q14)*S14 -> 1445.4834
B15: 第12周 | C15: =价格策略模拟!B6 -> 17.99 | D15: =价格策略模拟!C6 -> 0.1 | E15: =价格策略模拟!D6 -> 0 | F15: =SUM(C15*(1-D15-E15)) -> 16.191 | G15: =G14 -> 6 | H15: =SUM(F15*15%) -> 2.42865 | I15: =SUM(F15-G15-H15) -> 7.76235 | J15: 0.22 | K15: 0 | L15: =L14 -> 3.7 | M15: =M14 -> 1.4 | N15: =SUM(20%*15%*F15+G15+J15+L15+M15+0.65) -> 12.45573 | O15: =O14 -> 0.02 | P15: =SUM(N15*O15/(1-O15)) -> 0.25419857 | Q15: =SUM(I15-J15-K15-L15-M15-P15) -> 2.1881514 | R15: =SUM(Q15/C15) -> 0.12163154 | S15: =阶段总盈亏!I15 -> 210 | T15: =SUM(Q15*S15) -> 459.5118 | U15: =SUM(T15:T15) -> 459.5118 | V15: =S15*C15 -> 3777.9 | W15: =(L15+M15+Q15)*S15 -> 1530.5118
A16: 第四阶段 | B16: 第13周 | C16: =价格策略模拟!B7 -> 17.99 | D16: =价格策略模拟!C7 -> 0.05 | E16: =价格策略模拟!D7 -> 0 | F16: =SUM(C16*(1-D16-E16)) -> 17.0905 | G16: =G15 -> 6 | H16: =SUM(F16*15%) -> 2.563575 | I16: =SUM(F16-G16-H16) -> 8.526925 | J16: 0.22 | K16: 0 | L16: =L15 -> 3.7 | M16: =M15 -> 1.4 | N16: =SUM(20%*15%*F16+G16+J16+L16+M16+0.65) -> 12.482715 | O16: =O15 -> 0.02 | P16: =SUM(N16*O16/(1-O16)) -> 0.25474929 | Q16: =SUM(I16-J16-K16-L16-M16-P16) -> 2.9521757 | R16: =SUM(Q16/C16) -> 0.16410093 | S16: =阶段总盈亏!I16 -> 210 | T16: =SUM(Q16*S16) -> 619.9569 | U16: =SUM(T16:T16) -> 619.9569 | V16: =S16*C16 -> 3777.9 | W16: =(L16+M16+Q16)*S16 -> 1690.9569
B17: 第14周 | C17: =价格策略模拟!B7 -> 17.99 | D17: =价格策略模拟!C7 -> 0.05 | E17: =价格策略模拟!D7 -> 0 | F17: =SUM(C17*(1-D17-E17)) -> 17.0905 | G17: =G16 -> 6 | H17: =SUM(F17*15%) -> 2.563575 | I17: =SUM(F17-G17-H17) -> 8.526925 | J17: 0.22 | K17: 0 | L17: =L16 -> 3.7 | M17: =M16 -> 1.4 | N17: =SUM(20%*15%*F17+G17+J17+L17+M17+0.65) -> 12.482715 | O17: =O16 -> 0.02 | P17: =SUM(N17*O17/(1-O17)) -> 0.25474929 | Q17: =SUM(I17-J17-K17-L17-M17-P17) -> 2.9521757 | R17: =SUM(Q17/C17) -> 0.16410093 | S17: =阶段总盈亏!I17 -> 210 | T17: =SUM(Q17*S17) -> 619.9569 | U17: =SUM(T17:T17) -> 619.9569 | V17: =S17*C17 -> 3777.9 | W17: =(L17+M17+Q17)*S17 -> 1690.9569
B18: 第15周 | C18: =价格策略模拟!B7 -> 17.99 | D18: =价格策略模拟!C7 -> 0.05 | E18: =价格策略模拟!D7 -> 0 | F18: =SUM(C18*(1-D18-E18)) -> 17.0905 | G18: =G17 -> 6 | H18: =SUM(F18*15%) -> 2.563575 | I18: =SUM(F18-G18-H18) -> 8.526925 | J18: 0.22 | K18: 0 | L18: =L17 -> 3.7 | M18: =M17 -> 1.4 | N18: =SUM(20%*15%*F18+G18+J18+L18+M18+0.65) -> 12.482715 | O18: =O17 -> 0.02 | P18: =SUM(N18*O18/(1-O18)) -> 0.25474929 | Q18: =SUM(I18-J18-K18-L18-M18-P18) -> 2.9521757 | R18: =SUM(Q18/C18) -> 0.16410093 | S18: =阶段总盈亏!I18 -> 210 | T18: =SUM(Q18*S18) -> 619.9569 | U18: =SUM(T18:T18) -> 619.9569 | V18: =S18*C18 -> 3777.9 | W18: =(L18+M18+Q18)*S18 -> 1690.9569
B19: 第16周 | C19: =价格策略模拟!B7 -> 17.99 | D19: =价格策略模拟!C7 -> 0.05 | E19: =价格策略模拟!D7 -> 0 | F19: =SUM(C19*(1-D19-E19)) -> 17.0905 | G19: =G18 -> 6 | H19: =SUM(F19*15%) -> 2.563575 | I19: =SUM(F19-G19-H19) -> 8.526925 | J19: 0.22 | K19: 0 | L19: =L18 -> 3.7 | M19: =M18 -> 1.4 | N19: =SUM(20%*15%*F19+G19+J19+L19+M19+0.65) -> 12.482715 | O19: =O18 -> 0.02 | P19: =SUM(N19*O19/(1-O19)) -> 0.25474929 | Q19: =SUM(I19-J19-K19-L19-M19-P19) -> 2.9521757 | R19: =SUM(Q19/C19) -> 0.16410093 | S19: =阶段总盈亏!I19 -> 210 | T19: =SUM(Q19*S19) -> 619.9569 | U19: =SUM(T19:T19) -> 619.9569 | V19: =S19*C19 -> 3777.9 | W19: =(L19+M19+Q19)*S19 -> 1690.9569
A20: 第五阶段 | B20: 第17周 | C20: =价格策略模拟!B8 -> 17.99 | D20: =价格策略模拟!C8 -> 0.05 | E20: =价格策略模拟!D8 -> 0 | F20: =SUM(C20*(1-D20-E20)) -> 17.0905 | G20: =G19 -> 6 | H20: =SUM(F20*15%) -> 2.563575 | I20: =SUM(F20-G20-H20) -> 8.526925 | J20: 0.22 | K20: 0 | L20: =L19 -> 3.7 | M20: =M19 -> 1.4 | N20: =SUM(20%*15%*F20+G20+J20+L20+M20+0.65) -> 12.482715 | O20: =O19 -> 0.02 | P20: =SUM(N20*O20/(1-O20)) -> 0.25474929 | Q20: =SUM(I20-J20-K20-L20-M20-P20) -> 2.9521757 | R20: =SUM(Q20/C20) -> 0.16410093 | S20: =阶段总盈亏!I20 -> 210 | T20: =SUM(Q20*S20) -> 619.9569 | U20: =SUM(T20:T20) -> 619.9569 | V20: =S20*C20 -> 3777.9 | W20: =(L20+M20+Q20)*S20 -> 1690.9569
B21: 第18周 | C21: =价格策略模拟!B8 -> 17.99 | D21: =价格策略模拟!C8 -> 0.05 | E21: =价格策略模拟!D8 -> 0 | F21: =SUM(C21*(1-D21-E21)) -> 17.0905 | G21: =G20 -> 6 | H21: =SUM(F21*15%) -> 2.563575 | I21: =SUM(F21-G21-H21) -> 8.526925 | J21: 0.22 | K21: 0 | L21: =L20 -> 3.7 | M21: =M20 -> 1.4 | N21: =SUM(20%*15%*F21+G21+J21+L21+M21+0.65) -> 12.482715 | O21: =O20 -> 0.02 | P21: =SUM(N21*O21/(1-O21)) -> 0.25474929 | Q21: =SUM(I21-J21-K21-L21-M21-P21) -> 2.9521757 | R21: =SUM(Q21/C21) -> 0.16410093 | S21: =阶段总盈亏!I21 -> 210 | T21: =SUM(Q21*S21) -> 619.9569 | U21: =SUM(T21:T21) -> 619.9569 | V21: =S21*C21 -> 3777.9 | W21: =(L21+M21+Q21)*S21 -> 1690.9569
B22: 第19周 | C22: =价格策略模拟!B8 -> 17.99 | D22: =价格策略模拟!C8 -> 0.05 | E22: =价格策略模拟!D8 -> 0 | F22: =SUM(C22*(1-D22-E22)) -> 17.0905 | G22: =G21 -> 6 | H22: =SUM(F22*15%) -> 2.563575 | I22: =SUM(F22-G22-H22) -> 8.526925 | J22: 0.22 | K22: 0 | L22: =L21 -> 3.7 | M22: =M21 -> 1.4 | N22: =SUM(20%*15%*F22+G22+J22+L22+M22+0.65) -> 12.482715 | O22: =O21 -> 0.02 | P22: =SUM(N22*O22/(1-O22)) -> 0.25474929 | Q22: =SUM(I22-J22-K22-L22-M22-P22) -> 2.9521757 | R22: =SUM(Q22/C22) -> 0.16410093 | S22: =阶段总盈亏!I22 -> 210 | T22: =SUM(Q22*S22) -> 619.9569 | U22: =SUM(T22:T22) -> 619.9569 | V22: =S22*C22 -> 3777.9 | W22: =(L22+M22+Q22)*S22 -> 1690.9569
B23: 第20周 | C23: =价格策略模拟!B8 -> 17.99 | D23: =价格策略模拟!C8 -> 0.05 | E23: =价格策略模拟!D8 -> 0 | F23: =SUM(C23*(1-D23-E23)) -> 17.0905 | G23: =G22 -> 6 | H23: =SUM(F23*15%) -> 2.563575 | I23: =SUM(F23-G23-H23) -> 8.526925 | J23: 0.22 | K23: 0 | L23: =L22 -> 3.7 | M23: =M22 -> 1.4 | N23: =SUM(20%*15%*F23+G23+J23+L23+M23+0.65) -> 12.482715 | O23: =O22 -> 0.02 | P23: =SUM(N23*O23/(1-O23)) -> 0.25474929 | Q23: =SUM(I23-J23-K23-L23-M23-P23) -> 2.9521757 | R23: =SUM(Q23/C23) -> 0.16410093 | S23: =阶段总盈亏!I23 -> 210 | T23: =SUM(Q23*S23) -> 619.9569 | U23: =SUM(T23:T23) -> 619.9569 | V23: =S23*C23 -> 3777.9 | W23: =(L23+M23+Q23)*S23 -> 1690.9569
A24: 第六阶段 | B24: 第21周 | C24: =价格策略模拟!B9 -> 17.99 | D24: =价格策略模拟!C9 -> 0 | E24: =价格策略模拟!D9 -> 0 | F24: =SUM(C24*(1-D24-E24)) -> 17.99 | G24: =G23 -> 6 | H24: =SUM(F24*15%) -> 2.6985 | I24: =SUM(F24-G24-H24) -> 9.2915 | J24: 0.22 | K24: 0 | L24: =L23 -> 3.7 | M24: =M23 -> 1.4 | N24: =SUM(20%*15%*F24+G24+J24+L24+M24+0.65) -> 12.5097 | O24: =O23 -> 0.02 | P24: =SUM(N24*O24/(1-O24)) -> 0.2553 | Q24: =SUM(I24-J24-K24-L24-M24-P24) -> 3.7162 | R24: =SUM(Q24/C24) -> 0.20657032 | S24: =阶段总盈亏!I24 -> 210 | T24: =SUM(Q24*S24) -> 780.402 | U24: =SUM(T24:T24) -> 780.402 | V24: =S24*C24 -> 3777.9 | W24: =(L24+M24+Q24)*S24 -> 1851.402
B25: 第22周 | C25: =价格策略模拟!B9 -> 17.99 | D25: =价格策略模拟!C9 -> 0 | E25: =价格策略模拟!D9 -> 0 | F25: =SUM(C25*(1-D25-E25)) -> 17.99 | G25: =G24 -> 6 | H25: =SUM(F25*15%) -> 2.6985 | I25: =SUM(F25-G25-H25) -> 9.2915 | J25: 0.22 | K25: 0 | L25: =L24 -> 3.7 | M25: =M24 -> 1.4 | N25: =SUM(20%*15%*F25+G25+J25+L25+M25+0.65) -> 12.5097 | O25: =O24 -> 0.02 | P25: =SUM(N25*O25/(1-O25)) -> 0.2553 | Q25: =SUM(I25-J25-K25-L25-M25-P25) -> 3.7162 | R25: =SUM(Q25/C25) -> 0.20657032 | S25: =阶段总盈亏!I25 -> 210 | T25: =SUM(Q25*S25) -> 780.402 | U25: =SUM(T25:T25) -> 780.402 | V25: =S25*C25 -> 3777.9 | W25: =(L25+M25+Q25)*S25 -> 1851.402
B26: 第23周 | C26: =价格策略模拟!B9 -> 17.99 | D26: =价格策略模拟!C9 -> 0 | E26: =价格策略模拟!D9 -> 0 | F26: =SUM(C26*(1-D26-E26)) -> 17.99 | G26: =G25 -> 6 | H26: =SUM(F26*15%) -> 2.6985 | I26: =SUM(F26-G26-H26) -> 9.2915 | J26: 0.22 | K26: 0 | L26: =L25 -> 3.7 | M26: =M25 -> 1.4 | N26: =SUM(20%*15%*F26+G26+J26+L26+M26+0.65) -> 12.5097 | O26: =O25 -> 0.02 | P26: =SUM(N26*O26/(1-O26)) -> 0.2553 | Q26: =SUM(I26-J26-K26-L26-M26-P26) -> 3.7162 | R26: =SUM(Q26/C26) -> 0.20657032 | S26: =阶段总盈亏!I26 -> 210 | T26: =SUM(Q26*S26) -> 780.402 | U26: =SUM(T26:T26) -> 780.402 | V26: =S26*C26 -> 3777.9 | W26: =(L26+M26+Q26)*S26 -> 1851.402
B27: 第24周 | C27: =价格策略模拟!B9 -> 17.99 | D27: =价格策略模拟!C9 -> 0 | E27: =价格策略模拟!D9 -> 0 | F27: =SUM(C27*(1-D27-E27)) -> 17.99 | G27: =G26 -> 6 | H27: =SUM(F27*15%) -> 2.6985 | I27: =SUM(F27-G27-H27) -> 9.2915 | J27: 0.22 | K27: 0 | L27: =L26 -> 3.7 | M27: =M26 -> 1.4 | N27: =SUM(20%*15%*F27+G27+J27+L27+M27+0.65) -> 12.5097 | O27: =O26 -> 0.02 | P27: =SUM(N27*O27/(1-O27)) -> 0.2553 | Q27: =SUM(I27-J27-K27-L27-M27-P27) -> 3.7162 | R27: =SUM(Q27/C27) -> 0.20657032 | S27: =阶段总盈亏!I27 -> 210 | T27: =SUM(Q27*S27) -> 780.402 | U27: =SUM(T27:T27) -> 780.402 | V27: =S27*C27 -> 3777.9 | W27: =(L27+M27+Q27)*S27 -> 1851.402
A29: 每日盈亏真实数据
A30: 第一阶段 | B30: 第1周
B31: 第2周
B32: 第3周
B33: 第4周
A34: 第二阶段 | B34: 第5周
B35: 第6周
B36: 第7周
B37: 第8周
A38: 第三阶段 | B38: 第9周
B39: 第10周
B40: 第11周
B41: 第12周
...

Sheet 2
A1: amazon-order-id | B1: merchant-order-id | C1: purchase-date | D1: last-updated-date | E1: order-status | F1: fulfillment-channel | G1: sales-channel | H1: order-channel | I1: url | J1: ship-service-level | K1: product-name | L1: sku | M1: asin | N1: item-status | O1: quantity | P1: currency | Q1: item-price | R1: item-tax | S1: shipping-price | T1: shipping-tax | U1: gift-wrap-price | V1: gift-wrap-tax | W1: item-promotion-discount | X1: ship-promotion-discount | Y1: ship-city | Z1: ship-state | AA1: ship-postal-code | AB1: ship-country | AC1: promotion-ids | AD1: is-business-order | AE1: purchase-order-number | AF1: price-designation | AG1: default-ship-from-address-name | AH1: default-ship-from-address-field-1 | AI1: default-ship-from-address-field-2 | AJ1: default-ship-from-address-field-3 | AK1: default-ship-from-city | AL1: default-ship-from-state | AM1: default-ship-from-country | AN1: default-ship-from-postal-code | AO1: actual-ship-from-address-name | AP1: actual-ship-from-address-field-1 | AQ1: actual-ship-from-address-field-2 | AR1: actual-ship-from-address-field-3 | AS1: actual-ship-from-city | AT1: actual-ship-from-state | AU1: actual-ship-from-country | AV1: actual-ship-from-postal-code | AW1: is-buyer-requested-cancellation | AX1: buyer-requested-cancel-reason | AY1: serial-numbers | AZ1: signature-confirmation-recommended
A2: 111-9858618-2103444 | B2: 111-9858618-2103444 | C2: 2023-09-12T05:37:43+00:00 | D2: 2023-09-12T05:37:48+00:00 | E2: Pending | F2: Amazon | G2: Amazon.com | J2: Expedited | K2: Dash Cam Front with FHD 1080p, Wanlipo 2 Inch LCD Dashcam, Dashboard Camera for Cars with 24h Parking Monitor, G-Sensor, Loop Recording, Free 32GB SD | L2: J09-C1 | M2: B0BG6WPM3W | N2: Unshipped | O2: 1 | P2: USD | Q2: 79.99 | Y2: BELLMAWR | Z2: NJ | AA2: 08031-2115 | AB2: US | AC2: MPC-S Percentage Off 2023/09/10 11-52-12-900 | AD2: FALSE | AW2: FALSE | AZ2: FALSE
A3: 114-5667916-6324215 | B3: 114-5667916-6324215 | C3: 2023-09-12T03:37:05+00:00 | D3: 2023-09-12T09:02:46+00:00 | E3: Shipped | F3: Amazon | G3: Amazon.com | J3: Expedited | K3: 4K Dash Cam Front Built-in WiFi, WANLIPO Dash Camera for Cars with 64GB SD Card, Car Camera with 3" IPS Screen, 2160P Dashcam for Cars with App Contro | L3: Wanlipo M03-3 | M3: B0CC8CHTTJ | N3: Shipped | O3: 1 | P3: USD | Q3: 99.99 | R3: 1.89 | W3: 72.99 | Y3: MONROE | Z3: GA | AA3: 30656-4723 | AB3: US | AC3: MPC-S Percentage Off 2023/09/11 9-53-46-600 | AD3: FALSE | AW3: FALSE | AZ3: FALSE
A4: 111-1595396-9168227 | B4: 111-1595396-9168227 | C4: 2023-09-11T23:55:05+00:00 | D4: 2023-09-11T23:55:11+00:00 | E4: Pending | F4: Amazon | G4: Amazon.com | J4: Expedited | K4: Dash Cam Front with FHD 1080p, Wanlipo 2 Inch LCD Dashcam, Dashboard Camera for Cars with 24h Parking Monitor, G-Sensor, Loop Recording, Free 32GB SD | L4: J09-C1 | M4: B0BG6WPM3W | N4: Unshipped | O4: 1 | P4: USD | Q4: 79.99 | Y4: SILVER SPRING | Z4: MD | AA4: 20906-4527 | AB4: US | AC4: MPC-S Percentage Off 2023/09/10 11-52-3-698 | AD4: FALSE | AW4: FALSE | AZ4: FALSE
A5: 112-7810040-2837843 | B5: 112-7810040-2837843 | C5: 2023-09-11T19:41:13+00:00 | D5: 2023-09-12T01:35:23+00:00 | E5: Shipped | F5: Amazon | G5: Amazon.com | J5: Expedited | K5: Dash Cam Front with FHD 1080p, Wanlipo 2 Inch LCD Dashcam, Dashboard Camera for Cars with 24h Parking Monitor, G-Sensor, Loop Recording, Free 32GB SD | L5: J09-C1 | M5: B0BG6WPM3W | N5: Shipped | O5: 1 | P5: USD | Q5: 79.99 | R5: 1.85 | W5: 59.99 | Y5: Nashville | Z5: TN | AA5: 37208-1058 | AB5: US | AC5: MPC-S Percentage Off 2023/09/10 11-52-13-889 | AD5: FALSE | AW5: FALSE | AZ5: FALSE
A6: 111-4369826-2407442 | B6: 111-4369826-2407442 | C6: 2023-09-11T18:52:15+00:00 | D6: 2023-09-11T18:52:21+00:00 | E6: Pending | F6: Amazon | G6: Amazon.com | J6: Standard | K6: 4K Dash Cam Front with WiFi 2160P, VOFRTY Dash Camera for Cars with 3" IPS, Car Camera with App Control, Dashcam with G-Sensor, Loop Recording, 64GB S | L6: M03-3 | M6: B0C1C9T9KP | N6: Unshipped | O6: 1 | P6: USD | Q6: 79.99 | Y6: HUNTINGTON | Z6: WV | AA6: 25704-1119 | AB6: US | AC6: US Core Free Shipping Promotion A3JU1FCINF5SD0,Percentage Off 2023/08/28 6-17-47-400 | AD6: FALSE | AW6: FALSE | AZ6: FALSE
A7: 114-0862837-0430606 | B7: 114-0862837-0430606 | C7: 2023-09-11T17:17:31+00:00 | D7: 2023-09-11T17:17:37+00:00 | E7: Pending | F7: Amazon | G7: Amazon.com | J7: Expedited | K7: Dash Cam Front with FHD 1080p, Wanlipo 2 Inch LCD Dashcam, Dashboard Camera for Cars with 24h Parking Monitor, G-Sensor, Loop Recording, Free 32GB SD | L7: J09-C1 | M7: B0BG6WPM3W | N7: Unshipped | O7: 1 | P7: USD | Q7: 79.99 | Y7: LOS ANGELES | Z7: CA | AA7: 90016-2009 | AB7: US | AC7: MPC-S Percentage Off 2023/09/10 11-52-3-698 | AD7: FALSE | AW7: FALSE | AZ7: FALSE
A8: 114-2447819-7327466 | B8: 114-2447819-7327466 | C8: 2023-09-11T15:45:23+00:00 | D8: 2023-09-11T15:45:29+00:00 | E8: Pending | F8: Amazon | G8: Amazon.com | J8: Expedited | K8: 4K Dash Cam Front with WiFi 2160P, VOFRTY Dash Camera for Cars with 3" IPS, Car Camera with App Control, Dashcam with G-Sensor, Loop Recording, 64GB S | L8: M03-3 | M8: B0C1C9T9KP | N8: Unshipped | O8: 1 | P8: USD | Q8: 79.99 | Y8: DES MOINES | Z8: IA | AA8: 50317-6307 | AB8: US | AC8: MPC-S Percentage Off 2023/09/11 9-54-8-40 | AD8: FALSE | AW8: FALSE | AZ8: FALSE
A9: 114-3078544-2276207 | B9: 114-3078544-2276207 | C9: 2023-09-11T15:21:19+00:00 | D9: 2023-09-12T04:25:37+00:00 | E9: Shipped | F9: Amazon | G9: Amazon.com | J9: Expedited | K9: 4K Dash Cam Front with WiFi 2160P, VOFRTY Dash Camera for Cars with 3" IPS, Car Camera with App Control, Dashcam with G-Sensor, Loop Recording, 64GB S | L9: M03-3 | M9: B0C1C9T9KP | N9: Shipped | O9: 1 | P9: USD | Q9: 79.99 | R9: 3.12 | W9: 47.99 | Y9: LA VERGNE | Z9: TN | AA9: 37086-1439 | AB9: US | AC9: MPC-S Percentage Off 2023/09/11 9-54-8-40 | AD9: FALSE | AW9: FALSE | AZ9: FALSE
A10: 114-1356066-5534643 | B10: 114-1356066-5534643 | C10: 2023-09-11T13:58:53+00:00 | D10: 2023-09-12T07:08:25+00:00 | E10: Shipped | F10: Amazon | G10: Amazon.com | J10: Expedited | K10: Dash Cam Front with FHD 1080p, Wanlipo 2 Inch LCD Dashcam, Dashboard Camera for Cars with 24h Parking Monitor, G-Sensor, Loop Recording, Free 32GB SD | L10: J09-C1 | M10: B0BG6WPM3W | N10: Shipped | O10: 1 | P10: USD | Q10: 79.99 | R10: 1.25 | S10: 2.99 | W10: 59.99 | X10: 2.99 | Y10: BLACKSTONE | Z10: MA | AA10: 01504-1408 | AB10: US | AC10: MPC-S Percentage Off 2023/09/10 5-41-22-292 | AD10: FALSE | AW10: FALSE | AZ10: FALSE
A11: 112-9726611-4879461 | B11: 112-9726611-4879461 | C11: 2023-09-11T12:39:23+00:00 | D11: 2023-09-12T09:25:25+00:00 | E11: Shipped | F11: Amazon | G11: Amazon.com | J11: Standard | K11: 4K Dash Cam Front Built-in WiFi, WANLIPO Dash Camera for Cars with 64GB SD Card, Car Camera with 3" IPS Screen, 2160P Dashcam for Cars with App Contro | L11: Wanlipo M03-3 | M11: B0CC8CHTTJ | N11: Shipped | O11: 1 | P11: USD | Q11: 99.99 | R11: 2.84 | W11: 67.99 | Y11: Brooklyn | Z11: NY | AA11: 11235 | AB11: US | AC11: MPC-S Percentage Off 2023/09/07 1-34-35-547 | AD11: FALSE | AW11: FALSE | AZ11: FALSE
A12: 113-6400382-4997016 | B12: 113-6400382-4997016 | C12: 2023-09-11T11:06:47+00:00 | D12: 2023-09-11T11:06:52+00:00 | E12: Pending | F12: Amazon | G12: Amazon.com | J12: Expedited | K12: Dash Cam Front with FHD 1080p, Wanlipo 2 Inch LCD Dashcam, Dashboard Camera for Cars with 24h Parking Monitor, G-Sensor, Loop Recording, Free 32GB SD | L12: J09-C1 | M12: B0BG6WPM3W | N12: Unshipped | O12: 1 | P12: USD | Q12: 79.99 | Y12: BRONX | Z12: NY | AA12: 10461 | AB12: US | AC12: MPC-S Percentage Off 2023/09/10 11-52-12-900 | AD12: FALSE | AW12: FALSE | AZ12: FALSE
A13: 112-9947498-4884232 | B13: 112-9947498-4884232 | C13: 2023-09-11T07:15:23+00:00 | D13: 2023-09-11T18:12:08+00:00 | E13: Shipped | F13: Amazon | G13: Amazon.com | J13: Expedited | K13: 4K Dash Cam Front with WiFi 2160P, VOFRTY Dash Camera for Cars with 3" IPS, Car Camera with App Control, Dashcam with G-Sensor, Loop Recording, 64GB S | L13: M03-3 | M13: B0C1C9T9KP | N13: Shipped | O13: 1 | P13: USD | Q13: 79.99 | R13: 3.8 | W13: 40 | Y13: WEST COVINA | Z13: CA | AA13: 91792-1494 | AB13: US | AC13: Percentage Off 2023/08/28 6-17-47-400 | AD13: FALSE | AW13: FALSE | AZ13: FALSE

Sheet 逮虾户上贴费用详情
A1: 标题 | B1: 产品链接 | C1: ASIN | D1: 原价 | E1: 折后价 | F1: 折扣码 | G1: 折扣力度 | H1: 其他叠加优惠 | I1: 资源名称 | J1: 资源链接 | K1: 费用 | L1: 状态 | M1: 帖子链接 | N1: 上帖图片 | O1: 失败原因 | P1: 下单时间 | Q1: 接单时间 | R1: 上帖时间 | S1: 退款时间
A2: 4K Dash Cam Front Built-in WiFi, WANLIPO Dash Camera for Cars with 64GB SD Card App Control | B2: https://www.amazon.com/promocode/A1DX8GZASC5MLT | C2: B0CC8CHTTJ | D2: $99.99 | E2: $31.99 | F2: 68WHPID3 | G2: 68 | I2: INSANE CHRISTMAS DEALS, Forking Good Deals | J2: 查看链接 | K2: 37 | L2: 已完成 | M2: 查看帖子 | P2: 2023-09-07 15:24:49 | Q2: 2023-09-07 18:22:38 | R2: 2023-09-08 11:44:55
A3: 4K Dash Cam Front Built-in WiFi, WANLIPO Dash Camera for Cars with 64GB SD Card App Control | B3: https://www.amazon.com/promocode/A1DX8GZASC5MLT | C3: B0CC8CHTTJ | D3: $99.99 | E3: $31.99 | F3: 68WHPID3 | G3: 68 | I3: Saving With Joy- Online Deals and Giveaways | J3: 查看链接 | K3: 14 | L3: 已完成 | M3: 查看帖子 | P3: 2023-09-07 15:24:49 | Q3: 2023-09-07 16:49:59 | R3: 2023-09-08 13:42:22
A4: 4K Dash Cam Front Built-in WiFi, WANLIPO Dash Camera for Cars with 64GB SD Card App Control | B4: https://www.amazon.com/promocode/A1DX8GZASC5MLT | C4: B0CC8CHTTJ | D4: $99.99 | E4: $31.99 | F4: 68WHPID3 | G4: 68 | I4: The Frugal SAHM | Deals & Discounts for Moms + Babies | J4: 查看链接 | K4: 30 | L4: 已完成 | M4: 查看帖子 | P4: 2023-09-07 15:24:49 | Q4: 2023-09-07 18:10:10 | R4: 2023-09-09 03:49:38
A5: 4K Dash Cam Front Built-in WiFi, WANLIPO Dash Camera for Cars with 64GB SD Card App Control | B5: https://www.amazon.com/promocode/A1DX8GZASC5MLT | C5: B0CC8CHTTJ | D5: $99.99 | E5: $31.99 | F5: 68WHPID3 | G5: 68 | I5: Leave it on the Porch | J5: 查看链接 | K5: 63 | L5: 已完成 | M5: 查看帖子 | P5: 2023-09-07 15:24:49 | Q5: 2023-09-07 15:34:15 | R5: 2023-09-08 09:11:21
A6: 4K Dash Cam Front Built-in WiFi, WANLIPO Dash Camera for Cars with 64GB SD Card App Control | B6: https://www.amazon.com/promocode/A1DX8GZASC5MLT | C6: B0CC8CHTTJ | D6: $99.99 | E6: $31.99 | F6: 68WHPID3 | G6: 68 | I6: Nats daily deals and codes | J6: 查看链接 | K6: 32 | L6: 已取消/退款 | O6: 未入选 | P6: 2023-09-07 15:24:49 | Q6: 2023-09-07 18:13:47 | S6: 2023-09-13 15:39:13
A7: 4K Dash Cam Front Built-in WiFi, WANLIPO Dash Camera for Cars with 64GB SD Card App Control | B7: https://www.amazon.com/promocode/A1DX8GZASC5MLT | C7: B0CC8CHTTJ | D7: $99.99 | E7: $31.99 | F7: 68WHPID3 | G7: 68 | I7: Bomb Deals - Promo Codes - Coupons | J7: 查看链接 | K7: 32 | L7: 已完成 | M7: 查看帖子 | P7: 2023-09-07 15:24:49 | Q7: 2023-09-07 22:32:59 | R7: 2023-09-08 10:43:22
A8: 4K Dash Cam Front Built-in WiFi, WANLIPO Dash Camera for Cars with 64GB SD Card App Control | B8: https://www.amazon.com/promocode/A1DX8GZASC5MLT | C8: B0CC8CHTTJ | D8: $99.99 | E8: $31.99 | F8: 68WHPID3 | G8: 68 | I8: Oopsie Deals | J8: 查看链接 | K8: 49 | L8: 已完成 | N8: 查看图片 | P8: 2023-09-07 15:24:49 | Q8: 2023-09-07 15:27:44 | R8: 2023-09-08 09:53:51
A9: 4K Dash Cam Front Built-in WiFi, WANLIPO Dash Camera for Cars with 64GB SD Card App Control | B9: https://www.amazon.com/promocode/A1DX8GZASC5MLT | C9: B0CC8CHTTJ | D9: $99.99 | E9: $31.99 | F9: 68WHPID3 | G9: 68 | I9: Dysautomama Deals | J9: 查看链接 | K9: 24 | L9: 已完成 | M9: 查看帖子 | P9: 2023-09-07 15:24:49 | Q9: 2023-09-07 16:25:17 | R9: 2023-09-08 15:28:24
A10: 4K Dash Cam Front Built-in WiFi, WANLIPO Dash Camera for Cars with 64GB SD Card App Control | B10: https://www.amazon.com/promocode/A1DX8GZASC5MLT | C10: B0CC8CHTTJ | D10: $99.99 | E10: $31.99 | F10: 68WHPID3 | G10: 68 | I10: Gretchen's Adventures Deals | J10: 查看链接 | K10: 14 | L10: 已取消/退款 | O10: 未入选 | P10: 2023-09-07 15:24:49 | Q10: 2023-09-07 18:16:12 | S10: 2023-09-08 18:19:33
