Workbook

Sheet 推广目标
A1: SKU： ASIN：
A3: 上架销售时间： | B3: 45716
A4: 推广周期： | B4: 2月28日-5月31日
A5: 排名目标： | B5: Portable Power Banks #20
A6: 目标销量： | B6: 50pcs/天
A10: 目标管理 | B10: 目标 | C10: ASIN 1
A11: 对标竞品
A12: 目标排名
A13: 目标日销
A14: 价格
A15: rating
A16: 评分
A17: 主推词

Sheet 推广计划
A1: WEEK | B1: Date | C1: SKU | D1: 售价 | E1: COUPON | F1: Action | G1: 目标平均日销 | H1: 周销 | I1: 目标排名 | J1: Review星级/数量 | K1: REVIEW计划 | M1: 周消耗库存 | N1: 销售额 | O1: 日均流量 | P1: 转化率 | Q1: 主关键词自然搜索排名 | R1: 广告计划 | X1: 库存计划
K2: 送出数量 | L2: 措施 | R2: 广告日预算 | S2: 每日点击 | T2: CPC | U2: CVR | V2: 广告日订单 | W2: 广告订单占比 | Z2: LBS库存 | AA2: SZ | AB2: LBS在途 | AC2: LBS发货 | AD2: 采购计划
A3: WEEK1 | B3: 2.28-3.6 | D3: 54.99 | E3: 5 | F3: coupon+广告 | G3: 18 | H3: =G3*7 -> 126 | I3: 60 | J3: 4.6 | N3: =D3*H3 -> 6928.74 | O3: =G3/P3 -> 100 | P3: 0.18 | Q3: 主推关键词：power bank, portable charger 目标：第5页 | R3: =T3*S3 -> 80.181818 | S3: =V3/U3 -> 114.54545 | T3: 0.7 | U3: 0.11 | V3: =G3*W3 -> 12.6 | W3: 0.7 | X3: 1200 | Y3: 0 | Z3: 0 | AA3: 1310 | AB3: 2490海运
A4: WEEK2 | B4: 3.7-3.13 | D4: 54.99 | E4: 5 | F4: coupon+广告 | G4: 28 | H4: =G4*7 -> 196 | I4: 40 | J4: 4.6 | N4: =D4*H4 -> 10778.04 | O4: =G4/P4 -> 140 | P4: 0.2 | Q4: 主推关键词：power bank, portable charger 目标：第4页 | R4: =T4*S4 -> 98.583333 | S4: =V4/U4 -> 151.66667 | T4: 0.65 | U4: 0.12 | V4: =G4*W4 -> 18.2 | W4: 0.65 | X4: =X3-H3 -> 1074 | Y4: 0 | Z4: 0 | AA4: 1310 | AB4: 2490
A5: WEEK3 | B5: 3.14-3.20 | D5: 54.99 | E5: 3 | F5: coupon+广告 | G5: 33 | H5: =G5*7 -> 231 | I5: 30 | J5: 4.6 | N5: =D5*H5 -> 12702.69 | O5: =G5/P5 -> 150 | P5: 0.22 | Q5: 主推关键词：power bank, portable charger 目标：第3页 | R5: =T5*S5 -> 91.384615 | S5: =V5/U5 -> 152.30769 | T5: 0.6 | U5: 0.13 | V5: =G5*W5 -> 19.8 | W5: 0.6 | X5: =X4-H4 -> 878 | Y5: 0 | Z5: 2490 | AA5: 0 | AB5: 1310卡派 | AC5: 720至TT 600至RUI备用
A6: WEEK4 | B6: 3.21-3.27 | D6: 54.99 | F6: 7DD+加大广告投放 | G6: 52 | H6: =G6*7 -> 364 | I6: 20 | J6: 4.6 | N6: =D6*H6 -> 20016.36 | O6: =G6/P6 -> 185.71429 | P6: 0.28 | Q6: 主推关键词：power bank, portable charger 目标：第3页 | R6: =T6*S6 -> 95.333333 | S6: =V6/U6 -> 173.33333 | T6: 0.55 | U6: 0.15 | V6: =G6*W6 -> 26 | W6: 0.5 | X6: =X5-H5+720 -> 1367 | Y6: 600 | Z6: 1170 | AA6: 0 | AB6: 1310 | AD6: 1500
A7: WEEK5 | B7: 3.28-4.3 | D7: 54.99 | E7: 2 | F7: coupon+广告 | G7: 38 | H7: =G7*7 -> 266 | I7: 28 | J7: 4.6 | N7: =D7*H7 -> 14627.34 | O7: =G7/P7 -> 165.21739 | P7: 0.23 | Q7: 主推关键词：power bank, portable charger 目标：第2页 | R7: =T7*S7 -> 76.633333 | S7: =V7/U7 -> 139.33333 | T7: 0.55 | U7: 0.15 | V7: =G7*W7 -> 20.9 | W7: 0.55 | X7: =X6-H6 -> 1003 | Y7: 600 | Z7: 1170 | AA7: 0 | AB7: 1310
A8: WEEK6 | B8: 4.4-4.10 | D8: 54.99 | E8: 0.1 | F8: coupon+广告 | G8: 41 | H8: =G8*7 -> 287 | I8: 26 | J8: 4.6 | N8: =D8*H8 -> 15782.13 | O8: =G8/P8 -> 170.83333 | P8: 0.24 | Q8: 主推关键词：power bank, portable charger 目标：第2页 | R8: =T8*S8 -> 75.166667 | S8: =V8/U8 -> 136.66667 | T8: 0.55 | U8: 0.15 | V8: =G8*W8 -> 20.5 | W8: 0.5 | X8: =X7-H7 -> 737 | Y8: 600 | Z8: 1170 | AA8: 0 | AB8: 1310 | AC8: 900至TT
A9: WEEK7 | B9: 4.11-4.17 | D9: 54.99 | F9: 7DD+加大广告投放 | G9: 65 | H9: =G9*7 -> 455 | I9: 20 | J9: 4.6 | N9: =D9*H9 -> 25020.45 | O9: =G9/P9 -> 216.66667 | P9: 0.3 | Q9: 主推关键词：power bank, portable charger 目标：第2页 | R9: =T9*S9 -> 81.25 | S9: =V9/U9 -> 162.5 | T9: 0.5 | U9: 0.16 | V9: =G9*W9 -> 26 | W9: 0.4 | X9: =X8-H8+900 -> 1350 | Y9: 600 | Z9: =Z8-900 -> 270 | AA9: 0 | AB9: 1310 | AD9: 1980(PD)
A10: WEEK8 | B10: 4.18-4.24 | D10: 54.99 | E10: 0.1 | F10: coupon+广告 | G10: 44 | H10: =G10*7 -> 308 | I10: 25 | J10: 4.6 | N10: =D10*H10 -> 16936.92 | O10: =G10/P10 -> 176 | P10: 0.25 | Q10: 主推关键词：power bank, portable charger 目标：第1页 | R10: =T10*S10 -> 61.875 | S10: =V10/U10 -> 123.75 | T10: 0.5 | U10: 0.16 | V10: =G10*W10 -> 19.8 | W10: 0.45 | X10: =X9-H9 -> 895 | Y10: 600 | Z10: 1580 | AA10: 1500 | AB10: 0 | AC10: 900至TT
A11: WEEK9 | B11: 4.25-5.1 | D11: 54.99 | E11: 0.1 | F11: coupon+广告 | G11: 46 | H11: =G11*7 -> 322 | I11: 24 | J11: 4.6 | N11: =D11*H11 -> 17706.78 | O11: =G11/P11 -> 176.92308 | P11: 0.26 | Q11: 主推关键词：power bank, portable charger 目标：第1页 | R11: =T11*S11 -> 57.5 | S11: =V11/U11 -> 115 | T11: 0.5 | U11: 0.16 | V11: =G11*W11 -> 18.4 | W11: 0.4 | X11: =X10-H10+900 -> 1487 | Y11: 600 | Z11: 680 | AA11: 0 | AB11: 1500卡派 | AD11: 2100
A12: WEEK10 | B12: 5.2-5.8 | D12: 54.99 | F12: 7DD+加大广告投放 | G12: 70 | H12: =G12*7 -> 490 | I12: 20 | J12: 4.6 | N12: =D12*H12 -> 26945.1 | O12: =G12/P12 -> 225.80645 | P12: 0.31 | Q12: 主推关键词：power bank, portable charger 目标：第1页 | R12: =T12*S12 -> 76.5625 | S12: =V12/U12 -> 153.125 | T12: 0.5 | U12: 0.16 | V12: =G12*W12 -> 24.5 | W12: 0.35 | X12: =X11-H11 -> 1165 | Y12: 600 | Z12: 680 | AA12: 0 | AB12: 1500 | AC12: 680至TT
A13: WEEK11 | B13: 5.9-5.15 | D13: 54.99 | E13: 2 | F13: coupon+广告 | G13: 48 | H13: =G13*7 -> 336 | I13: 22 | J13: 4.6 | N13: =D13*H13 -> 18476.64 | O13: =G13/P13 -> 177.77778 | P13: 0.27 | Q13: 主推关键词：power bank, portable charger 目标：第1页 | R13: =T13*S13 -> 52.5 | S13: =V13/U13 -> 105 | T13: 0.5 | U13: 0.16 | V13: =G13*W13 -> 16.8 | W13: 0.35 | X13: =X12-H12+680 -> 1355 | Y13: 600 | Z13: 0 | AA13: 1980 | AB13: 1500
A14: WEEK12 | B14: 5.16-5.22 | D14: 54.99 | E14: 0.1 | F14: coupon+广告 | G14: 50 | H14: =G14*7 -> 350 | I14: 21 | J14: 4.6 | N14: =D14*H14 -> 19246.5 | O14: =G14/P14 -> 178.57143 | P14: 0.28 | Q14: 主推关键词：power bank, portable charger 目标：第1页 | R14: =T14*S14 -> 46.875 | S14: =V14/U14 -> 93.75 | T14: 0.5 | U14: 0.16 | V14: =G14*W14 -> 15 | W14: 0.3 | X14: 1355 | Y14: =Y13-H13 -> 264 | Z14: 1500 | AA14: 0 | AB14: 1980卡派 | AE14: 切换到RUI卖
A15: WEEK13 | B15: 5.23-5.29 | D15: 54.99 | E15: 0.1 | F15: 7DD+加大广告投放 | G15: 75 | H15: =G15*7 -> 525 | I15: 20 | J15: 4.6 | N15: =D15*H15 -> 28869.75 | O15: =G15/P15 -> 234.375 | P15: 0.32 | Q15: 主推关键词：power bank, portable charger 目标：第1页 | R15: =T15*S15 -> 66.176471 | S15: =V15/U15 -> 132.35294 | T15: 0.5 | U15: 0.17 | V15: =G15*W15 -> 22.5 | W15: 0.3 | X15: =X14-H14 -> 1005 | Y15: 264 | Z15: 1500 | AA15: 2100 | AB15: 1980

Sheet 广告计划
A1: 预估量说明： 平均cpc和转化率的值的预估方法： 1.市场调研得到同行平均cpc的基础上适当上调； 2.正在做的同品类商品的历史cpc基础上适当上调； 平均cpc和转化率计划制定的说明： 新品期间波动大，采用梯度预估 eg:当cpc为2.5$,转化率为5%的时候，完成日销目标对应的广告费为105$/天； 当cpc为2.3$.转化率为7%的时候，完成日销目标对应的广告费为69$/天
A10: WEEK | B10: Date | C10: 售价 | D10: 目标平均日销 | E10: 销售额 | F10: 转化率 | G10: 日均流量 | H10: 广告销量 | I10: 广告销售额 | J10: 广告订单占比 | K10: 广告费 | L10: 点击量 | M10: 预估量 | O10: 广告结构 | P10: 广告目标及关注指标 | Q10: 广告关键词 | R10: 不同广告类型预算分配
L11: 点击量 | M11: 平均cpc | N11: 广告转化率
A12: WEEK1 | B12: 2.28-3.6 | C12: =推广计划!D3 -> 54.99 | D12: =推广计划!G3 -> 18 | E12: =C12*D12*7 -> 6928.74 | F12: =推广计划!P3 -> 0.18 | G12: =D12/F12 -> 100 | H12: =D12*J12 -> 12.6 | I12: =H12*C12 -> 692.874 | J12: 0.7 | K12: =L12*M12 -> 80.181818 | L12: =$H$12/N12 -> 114.54545 | M12: =推广计划!T3 -> 0.7 | N12: =推广计划!U3 -> 0.11 | O12: campaign1：自动广告 campaign2：手动广告测试组B campaign3：SD-categories campaign4：PT campaign5：手动广告核心关键词E | P12: 有效流量引入 点击率；转化率；订单量 | Q12: power bank（主推） powerbank power bank fast charging phone charger power bank power bank iphone usb power bank phone power bank usb c power bank power bank fast charge portable power bank fast charge power bank power bank 10000mah phone battery power bank iphone battery power bank samsung power bank iphone power bank charger slim power bank power bank charger 10000 mah power bank portable battery power bank quick charge 3.0 power bank usb c pd power bank portable charger（主推） portable charger iphone portable phone charger iphone portable charger battery usb c portable charger mobile phone charger portable portable phone charger power bank portable charger usb c portable charger samsung long lasting portable charger portable charger 10000mah portable phone charger samsung battery bank usb battery pack iphone battery pack usb c battery pack phone charger pack battery pack phone charger iphone power pack
K13: =L13*M13 -> 80.181818 | L13: =$H$12/N13 -> 114.54545 | M13: =推广计划!T3 -> 0.7 | N13: =推广计划!U3 -> 0.11
K14: =L14*M14 -> 80.181818 | L14: =$H$12/N14 -> 114.54545 | M14: =推广计划!T3 -> 0.7 | N14: =推广计划!U3 -> 0.11
K15: =L15*M15 -> 80.181818 | L15: =$H$12/N15 -> 114.54545 | M15: =推广计划!T3 -> 0.7 | N15: =推广计划!U3 -> 0.11
A16: WEEK2 | B16: 3.7-3.13 | C16: =推广计划!D4 -> 54.99 | D16: =推广计划!G4 -> 28 | E16: =C16*D16*7 -> 10778.04 | F16: =推广计划!P4 -> 0.2 | G16: =D16/F16 -> 140 | H16: =D16*J16 -> 18.2 | I16: =H16*C16 -> 1000.818 | J16: 0.65 | K16: =L16*M16 -> 98.583333 | L16: =$H$16/N16 -> 151.66667 | M16: =推广计划!T4 -> 0.65 | N16: =推广计划!U4 -> 0.12 | O16: campaign1：自动广告 campaign2：手动广告测试组B campaign3：SD-categories campaign4：PT campaign5：手动广告核心关键词E campaign6：SBV-PT / SBV-KT | R16: SP:70% SD:15% SB:15%
K17: =L17*M17 -> 98.583333 | L17: =$H$16/N17 -> 151.66667 | M17: =推广计划!T4 -> 0.65 | N17: =推广计划!U4 -> 0.12
K18: =L18*M18 -> 98.583333 | L18: =$H$16/N18 -> 151.66667 | M18: =推广计划!T4 -> 0.65 | N18: =推广计划!U4 -> 0.12
K19: =L19*M19 -> 98.583333 | L19: =$H$16/N19 -> 151.66667 | M19: =推广计划!T4 -> 0.65 | N19: =推广计划!U4 -> 0.12
A20: WEEK3 | B20: 3.14-3.20 | C20: =推广计划!D5 -> 54.99 | D20: =推广计划!G5 -> 33 | E20: =C20*D20*7 -> 12702.69 | F20: =推广计划!P5 -> 0.22 | G20: =D20/F20 -> 150 | H20: =D20*J20 -> 19.8 | I20: =H20*C20 -> 1088.802 | J20: 0.6 | K20: =L20*M20 -> 91.384615 | L20: =$H$20/N20 -> 152.30769 | M20: =推广计划!T5 -> 0.6 | N20: =推广计划!U5 -> 0.13 | O20: campaign1：自动广告 campaign2：手动广告测试组B campaign3：SD-categories campaign4：PT campaign5：手动广告核心关键词E campaign6：SBV-PT / SBV-KT
K21: =L21*M21 -> 91.384615 | L21: =$H$20/N21 -> 152.30769 | M21: =推广计划!T5 -> 0.6 | N21: =推广计划!U5 -> 0.13
K22: =L22*M22 -> 91.384615 | L22: =$H$20/N22 -> 152.30769 | M22: =推广计划!T5 -> 0.6 | N22: =推广计划!U5 -> 0.13
K23: =L23*M23 -> 91.384615 | L23: =$H$20/N23 -> 152.30769 | M23: =推广计划!T5 -> 0.6 | N23: =推广计划!U5 -> 0.13
A24: WEEK4 | B24: 3.21-3.27 | C24: =推广计划!D6 -> 54.99 | D24: =推广计划!G6 -> 52 | E24: =C24*D24*7 -> 20016.36 | F24: =推广计划!P6 -> 0.28 | G24: =D24/F24 -> 185.71429 | H24: =D24*J24 -> 28.6 | I24: =H24*C24 -> 1572.714 | J24: 0.55 | K24: =L24*M24 -> 104.86667 | L24: =$H$24/N24 -> 190.66667 | M24: =推广计划!T6 -> 0.55 | N24: =推广计划!U6 -> 0.15 | O24: campaign1：自动广告 campaign2：手动广告测试组B campaign3：SD-categories campaign4：PT campaign5：手动广告核心关键词E campaign6：SBV-PT / SBV-KT | R24: SP:70% SD:15% SB:15%
K25: =L25*M25 -> 104.86667 | L25: =$H$24/N25 -> 190.66667 | M25: =推广计划!T6 -> 0.55 | N25: =推广计划!U6 -> 0.15
K26: =L26*M26 -> 104.86667 | L26: =$H$24/N26 -> 190.66667 | M26: =推广计划!T6 -> 0.55 | N26: =推广计划!U6 -> 0.15
K27: =L27*M27 -> 104.86667 | L27: =$H$24/N27 -> 190.66667 | M27: =推广计划!T6 -> 0.55 | N27: =推广计划!U6 -> 0.15
A28: WEEK5 | B28: 3.28-4.3 | C28: =推广计划!D7 -> 54.99 | D28: =推广计划!G7 -> 38 | E28: =C28*D28*7 -> 14627.34 | F28: =推广计划!P7 -> 0.23 | G28: =D28/F28 -> 165.21739 | H28: =D28*J28 -> 19 | I28: =H28*C28 -> 1044.81 | J28: 0.5 | K28: =L28*M28 -> 69.666667 | L28: =$H$28/N28 -> 126.66667 | M28: =推广计划!T7 -> 0.55 | N28: =推广计划!U7 -> 0.15 | O28: campaign1：自动广告 campaign2：手动广告主推词BP campaign3：SD-categories campaign4：PT campaign5：手动广告核心关键词E campaign6：SBV-PT / SBV-KT | P28: 推动销售 点击率；转化率；订单量；Acos
K29: =L29*M29 -> 69.666667 | L29: =$H$28/N29 -> 126.66667 | M29: =推广计划!T7 -> 0.55 | N29: =推广计划!U7 -> 0.15
K30: =L30*M30 -> 69.666667 | L30: =$H$28/N30 -> 126.66667 | M30: =推广计划!T7 -> 0.55 | N30: =推广计划!U7 -> 0.15
K31: =L31*M31 -> 69.666667 | L31: =$H$28/N31 -> 126.66667 | M31: =推广计划!T7 -> 0.55 | N31: =推广计划!U7 -> 0.15
A32: WEEK6 | B32: 4.4-4.10 | C32: =推广计划!D8 -> 54.99 | D32: =推广计划!G8 -> 41 | E32: =C32*D32*7 -> 15782.13 | F32: =推广计划!P8 -> 0.24 | G32: =D32/F32 -> 170.83333 | H32: =D32*J32 -> 20.5 | I32: =H32*C32 -> 1127.295 | J32: 0.5 | K32: =L32*M32 -> 75.166667 | L32: =$H$32/N32 -> 136.66667 | M32: =推广计划!T8 -> 0.55 | N32: =推广计划!U8 -> 0.15 | O32: campaign1：自动广告 campaign2：手动广告主推词BP campaign3：SD-categories campaign4：PT campaign5：手动广告核心关键词E campaign6：SBV-PT / SBV-KT | R32: SP:70% SD:15% SB:15%
K33: =L33*M33 -> 75.166667 | L33: =$H$32/N33 -> 136.66667 | M33: =推广计划!T8 -> 0.55 | N33: =推广计划!U8 -> 0.15
K34: =L34*M34 -> 75.166667 | L34: =$H$32/N34 -> 136.66667 | M34: =推广计划!T8 -> 0.55 | N34: =推广计划!U8 -> 0.15
K35: =L35*M35 -> 75.166667 | L35: =$H$32/N35 -> 136.66667 | M35: =推广计划!T8 -> 0.55 | N35: =推广计划!U8 -> 0.15
A36: WEEK7 | B36: 4.11-4.17 | C36: =推广计划!D9 -> 54.99 | D36: =推广计划!G9 -> 65 | E36: =C36*D36*7 -> 25020.45 | F36: =推广计划!P9 -> 0.3 | G36: =D36/F36 -> 216.66667 | H36: =D36*J36 -> 32.5 | I36: =H36*C36 -> 1787.175 | J36: 0.5 | K36: =L36*M36 -> 101.5625 | L36: =$H$36/N36 -> 203.125 | M36: =推广计划!T9 -> 0.5 | N36: =推广计划!U9 -> 0.16 | O36: campaign1：自动广告 campaign2：手动广告主推词BP campaign3：SD-categories campaign4：PT campaign5：手动广告核心关键词E campaign6：SBV-PT / SBV-KT
K37: =L37*M37 -> 101.5625 | L37: =$H$36/N37 -> 203.125 | M37: =推广计划!T9 -> 0.5 | N37: =推广计划!U9 -> 0.16
K38: =L38*M38 -> 101.5625 | L38: =$H$36/N38 -> 203.125 | M38: =推广计划!T9 -> 0.5 | N38: =推广计划!U9 -> 0.16
K39: =L39*M39 -> 101.5625 | L39: =$H$36/N39 -> 203.125 | M39: =推广计划!T9 -> 0.5 | N39: =推广计划!U9 -> 0.16
A40: WEEK8 | B40: 4.18-4.24 | C40: =推广计划!D10 -> 54.99 | D40: =推广计划!G10 -> 44 | E40: =C40*D40*7 -> 16936.92 | F40: =推广计划!P10 -> 0.25 | G40: =D40/F40 -> 176 | H40: =D40*J40 -> 19.8 | I40: =H40*C40 -> 1088.802 | J40: 0.45 | K40: =L40*M40 -> 61.875 | L40: =$H$40/N40 -> 123.75 | M40: =推广计划!T10 -> 0.5 | N40: =推广计划!U10 -> 0.16 | O40: campaign1：自动广告 campaign2：手动广告主推词BP campaign3：SD-categories campaign4：PT campaign5：手动广告核心关键词E campaign6：SBV-PT / SBV-KT | R40: SP:70% SD:15% SB:15%
K41: =L41*M41 -> 61.875 | L41: =$H$40/N41 -> 123.75 | M41: =推广计划!T10 -> 0.5 | N41: =推广计划!U10 -> 0.16
K42: =L42*M42 -> 61.875 | L42: =$H$40/N42 -> 123.75 | M42: =推广计划!T10 -> 0.5 | N42: =推广计划!U10 -> 0.16
K43: =L43*M43 -> 61.875 | L43: =$H$40/N43 -> 123.75 | M43: =推广计划!T10 -> 0.5 | N43: =推广计划!U10 -> 0.16
A44: WEEK9 | B44: 4.25-5.1 | C44: =推广计划!D11 -> 54.99 | D44: =推广计划!G11 -> 46 | E44: =C44*D44*7 -> 17706.78 | F44: =推广计划!P11 -> 0.26 | G44: =D44/F44 -> 176.92308 | H44: =D44*J44 -> 20.7 | I44: =H44*C44 -> 1138.293 | J44: 0.45 | K44: =L44*M44 -> 64.6875 | L44: =$H$44/N44 -> 129.375 | M44: =推广计划!T11 -> 0.5 | N44: =推广计划!U11 -> 0.16 | O44: campaign1：自动广告 campaign2：手动广告主推词BP campaign3：SD-categories campaign4：PT campaign5：手动广告核心关键词E campaign6：SBV-PT / SBV-KT
K45: =L45*M45 -> 64.6875 | L45: =$H$44/N45 -> 129.375 | M45: =推广计划!T11 -> 0.5 | N45: =推广计划!U11 -> 0.16
K46: =L46*M46 -> 64.6875 | L46: =$H$44/N46 -> 129.375 | M46: =推广计划!T11 -> 0.5 | N46: =推广计划!U11 -> 0.16
K47: =L47*M47 -> 64.6875 | L47: =$H$44/N47 -> 129.375 | M47: =推广计划!T11 -> 0.5 | N47: =推广计划!U11 -> 0.16
A48: WEEK10 | B48: 5.2-5.8 | C48: =推广计划!D12 -> 54.99 | D48: =推广计划!G12 -> 70 | E48: =C48*D48*7 -> 26945.1 | F48: =推广计划!P12 -> 0.31 | G48: =D48/F48 -> 225.80645 | H48: =D48*J48 -> 28 | I48: =H48*C48 -> 1539.72 | J48: 0.4 | K48: =L48*M48 -> 87.5 | L48: =$H$48/N48 -> 175 | M48: =推广计划!T12 -> 0.5 | N48: =推广计划!U12 -> 0.16 | O48: campaign1：自动广告 campaign2：手动广告主推词BP campaign3：SD-categories campaign4：PT campaign5：手动广告核心关键词E campaign6：SBV-PT / SBV-KT | R48: SP:70% SD:15% SB:15%
...

Sheet 利润&ROI测算
A1: 细分项 | L1: 1月 | AB1: 2月 | AR1: 3月 | BH1: 达标后每月销售
A2: 状态 | B2: Asin | C2: Model# | D2: 国家 | E2: 佣金比例 | F2: RMA比例 | G2: 广告费占比 | H2: MC/个 | I2: FBA配送费 | J2: 退换货分摊 /个 | K2: VAT | L2: 待办操作 | M2: 售价 | N2: 月销量 | O2: 销售总额 | P2: MC | Q2: 佣金 | R2: 配送费 | S2: RMA扣减 | T2: 广告费 | U2: 促销费 | V2: VAT | W2: 成本总计 | X2: 回款额 UK | Y2: 回款率 | Z2: 净毛利 US | AA2: 净毛利率 | AB2: 操作 | AC2: 售价 | AD2: 月销量 | AE2: 销售总额 | AF2: MC | AG2: 佣金 | AH2: 配送费 | AI2: RMA扣减 | AJ2: 广告费 | AK2: 促销费 | AL2: VAT | AM2: 成本总计 | AN2: 回款额 US | AO2: 回款率 | AP2: 净毛利 US | AQ2: 净毛利率 | AR2: 操作 | AS2: 售价 | AT2: 月销量 | AU2: 销售总额 | AV2: MC | AW2: 佣金 | AX2: 配送费 | AY2: RMA扣减 | AZ2: 广告费 | BA2: 促销费 | BB2: VAT | BC2: 成本总计 | BD2: 回款额 US | BE2: 回款率 | BF2: 净毛利 US | BG2: 净毛利率 | BH2: 操作 | BI2: 售价 | BJ2: 月销量 | BK2: 销售总额 | BL2: 产品成本 | BM2: 佣金 | BN2: 配送费 | BO2: RMA扣减 | BP2: 广告费 | BQ2: 促销费 | BR2: VAT | BS2: 成本总计 | BT2: 回款额 EU | BU2: 回款率 | BV2: 净毛利 EU | BW2: 净毛利率
D3: 欧洲 | E3: 0.15 | F3: 0.05 | G3: 0.15 | H3: =115.04/8 -> 14.38 | I3: 3.16 | J3: =(H3+I3)*F3 -> 0.877 | K3: 0.16666667 | M3: =推广计划!D3 -> 54.99 | N3: 300 | O3: =M3*N3 -> 16497 | P3: =$H3*N3 -> 4314 | Q3: =M3*$E3*N3 -> 2474.55 | R3: =I3*N3 -> 948 | S3: =$J3*N3 -> 263.1 | T3: =O3*18% -> 2969.46 | U3: =O3*15% -> 2474.55 | V3: =O3*K3 -> 2749.5 | W3: =P3+Q3+R3+S3+T3+U3+V3 -> 16193.16 | X3: =O3-Q3-R3-T3-U3-V3 -> 4880.94 | Y3: =X3/O3 -> 0.29586834 | Z3: =O3-W3 -> 303.84 | AA3: =Z3/O3 -> 0.018417894 | AC3: =推广计划!D3 -> 54.99 | AD3: 500 | AE3: =AC3*AD3 -> 27495 | AF3: =$H3*AD3 -> 7190 | AG3: =AC3*$E3*AD3 -> 4124.25 | AH3: =AD3*I3 -> 1580 | AI3: =$J3*AD3 -> 438.5 | AJ3: =AE3*10% -> 2749.5 | AK3: =AE3*15% -> 4124.25 | AL3: =AE3*K3 -> 4582.5 | AM3: =AF3+AG3+AH3+AI3+AJ3+AK3+AL3 -> 24789 | AN3: =AE3-AG3-AH3-AJ3-AL3 -> 14458.75 | AO3: =AN3/AE3 -> 0.52586834 | AP3: =AE3-AM3 -> 2706 | AQ3: =AP3/AE3 -> 0.098417894 | AS3: =推广计划!D3 -> 54.99 | AT3: 700 | AU3: =AS3*AT3 -> 38493 | AV3: =$H3*AT3 -> 10066 | AW3: =AS3*$E3*AT3 -> 5773.95 | AX3: =AT3*I3 -> 2212 | AY3: =$J3*AT3 -> 613.9 | AZ3: =AU3*7% -> 2694.51 | BA3: =AU3*15% -> 5773.95 | BB3: =K3*AU3 -> 6415.5 | BC3: =AV3+AW3+AX3+AY3+AZ3+BA3+BB3 -> 33549.81 | BD3: =AU3-AW3-AX3-AZ3-BB3 -> 21397.04 | BE3: =BD3/AU3 -> 0.55586834 | BF3: =AU3-BC3 -> 4943.19 | BG3: =BF3/AU3 -> 0.12841789 | BI3: =推广计划!D3 -> 54.99 | BJ3: 900 | BK3: =BI3*BJ3 -> 49491 | BL3: =$H3*BJ3 -> 12942 | BM3: =E3*BK3 -> 7423.65 | BN3: =I3*BJ3 -> 2844 | BO3: =$J3*BJ3 -> 789.3 | BP3: =BK3*13% -> 6433.83 | BQ3: =BK3*15% -> 7423.65 | BR3: =K3*BK3 -> 8248.5 | BS3: =BL3+BM3+BN3+BO3+BP3+BQ3+BR3 -> 46104.93 | BT3: =BK3-BM3-BN3-BP3-BR3 -> 24541.02 | BU3: =BT3/BK3 -> 0.49586834 | BV3: =BK3-BS3 -> 3386.07 | BW3: =BV3/BK3 -> 0.068417894
D4: 欧洲 | E4: 0.15 | F4: 0.05 | G4: 0.15 | H4: =115.04/8 -> 14.38 | I4: 3.16 | J4: =(H4+I4)*F4 -> 0.877 | K4: 0.16666667 | M4: =推广计划!D3 -> 54.99 | N4: 300 | O4: =M4*N4 -> 16497 | P4: =$H4*N4 -> 4314 | Q4: =M4*$E4*N4 -> 2474.55 | R4: =I4*N4 -> 948 | S4: =$J4*N4 -> 263.1 | T4: =O4*18% -> 2969.46 | U4: =O4*15% -> 2474.55 | V4: =O4*K4 -> 2749.5 | W4: =P4+Q4+R4+S4+T4+U4+V4 -> 16193.16 | X4: =O4-Q4-R4-T4-U4-V4 -> 4880.94 | Y4: =X4/O4 -> 0.29586834 | Z4: =O4-W4 -> 303.84 | AA4: =Z4/O4 -> 0.018417894 | AC4: =推广计划!D3 -> 54.99 | AD4: 500 | AE4: =AC4*AD4 -> 27495 | AF4: =$H4*AD4 -> 7190 | AG4: =AC4*$E4*AD4 -> 4124.25 | AH4: =AD4*I4 -> 1580 | AI4: =$J4*AD4 -> 438.5 | AJ4: =AE4*10% -> 2749.5 | AK4: =AE4*15% -> 4124.25 | AL4: =AE4*K4 -> 4582.5 | AM4: =AF4+AG4+AH4+AI4+AJ4+AK4+AL4 -> 24789 | AN4: =AE4-AG4-AH4-AJ4-AL4 -> 14458.75 | AO4: =AN4/AE4 -> 0.52586834 | AP4: =AE4-AM4 -> 2706 | AQ4: =AP4/AE4 -> 0.098417894 | AS4: =推广计划!D3 -> 54.99 | AT4: 700 | AU4: =AS4*AT4 -> 38493 | AV4: =$H4*AT4 -> 10066 | AW4: =AS4*$E4*AT4 -> 5773.95 | AX4: =AT4*I4 -> 2212 | AY4: =$J4*AT4 -> 613.9 | AZ4: =AU4*7% -> 2694.51 | BA4: =AU4*15% -> 5773.95 | BB4: =K4*AU4 -> 6415.5 | BC4: =AV4+AW4+AX4+AY4+AZ4+BA4+BB4 -> 33549.81 | BD4: =AU4-AW4-AX4-AZ4-BB4 -> 21397.04 | BE4: =BD4/AU4 -> 0.55586834 | BF4: =AU4-BC4 -> 4943.19 | BG4: =BF4/AU4 -> 0.12841789 | BI4: =推广计划!D3 -> 54.99 | BJ4: 900 | BK4: =BI4*BJ4 -> 49491 | BL4: =$H4*BJ4 -> 12942 | BM4: =E4*BK4 -> 7423.65 | BN4: =I4*BJ4 -> 2844 | BO4: =$J4*BJ4 -> 789.3 | BP4: =BK4*13% -> 6433.83 | BQ4: =BK4*15% -> 7423.65 | BR4: =K4*BK4 -> 8248.5 | BS4: =BL4+BM4+BN4+BO4+BP4+BQ4+BR4 -> 46104.93 | BT4: =BK4-BM4-BN4-BP4-BR4 -> 24541.02 | BU4: =BT4/BK4 -> 0.49586834 | BV4: =BK4-BS4 -> 3386.07 | BW4: =BV4/BK4 -> 0.068417894
D5: 欧洲 | E5: 0.15 | F5: 0.05 | G5: 0.15 | H5: =115.04/8 -> 14.38 | I5: 3.16 | J5: =(H5+I5)*F5 -> 0.877 | K5: 0.16666667 | M5: =推广计划!D4 -> 54.99 | N5: 300 | O5: =M5*N5 -> 16497 | P5: =$H5*N5 -> 4314 | Q5: =M5*$E5*N5 -> 2474.55 | R5: =I5*N5 -> 948 | S5: =$J5*N5 -> 263.1 | T5: =O5*18% -> 2969.46 | U5: =O5*15% -> 2474.55 | V5: =O5*K5 -> 2749.5 | W5: =P5+Q5+R5+S5+T5+U5+V5 -> 16193.16 | X5: =O5-Q5-R5-T5-U5-V5 -> 4880.94 | Y5: =X5/O5 -> 0.29586834 | Z5: =O5-W5 -> 303.84 | AA5: =Z5/O5 -> 0.018417894 | AC5: =推广计划!D3 -> 54.99 | AD5: 500 | AE5: =AC5*AD5 -> 27495 | AF5: =$H5*AD5 -> 7190 | AG5: =AC5*$E5*AD5 -> 4124.25 | AH5: =AD5*I5 -> 1580 | AI5: =$J5*AD5 -> 438.5 | AJ5: =AE5*10% -> 2749.5 | AK5: =AE5*15% -> 4124.25 | AL5: =AE5*K5 -> 4582.5 | AM5: =AF5+AG5+AH5+AI5+AJ5+AK5+AL5 -> 24789 | AN5: =AE5-AG5-AH5-AJ5-AL5 -> 14458.75 | AO5: =AN5/AE5 -> 0.52586834 | AP5: =AE5-AM5 -> 2706 | AQ5: =AP5/AE5 -> 0.098417894 | AS5: =推广计划!D3 -> 54.99 | AT5: 700 | AU5: =AS5*AT5 -> 38493 | AV5: =$H5*AT5 -> 10066 | AW5: =AS5*$E5*AT5 -> 5773.95 | AX5: =AT5*I5 -> 2212 | AY5: =$J5*AT5 -> 613.9 | AZ5: =AU5*7% -> 2694.51 | BA5: =AU5*15% -> 5773.95 | BB5: =K5*AU5 -> 6415.5 | BC5: =AV5+AW5+AX5+AY5+AZ5+BA5+BB5 -> 33549.81 | BD5: =AU5-AW5-AX5-AZ5-BB5 -> 21397.04 | BE5: =BD5/AU5 -> 0.55586834 | BF5: =AU5-BC5 -> 4943.19 | BG5: =BF5/AU5 -> 0.12841789 | BI5: =推广计划!D3 -> 54.99 | BJ5: 900 | BK5: =BI5*BJ5 -> 49491 | BL5: =$H5*BJ5 -> 12942 | BM5: =E5*BK5 -> 7423.65 | BN5: =I5*BJ5 -> 2844 | BO5: =$J5*BJ5 -> 789.3 | BP5: =BK5*13% -> 6433.83 | BQ5: =BK5*15% -> 7423.65 | BR5: =K5*BK5 -> 8248.5 | BS5: =BL5+BM5+BN5+BO5+BP5+BQ5+BR5 -> 46104.93 | BT5: =BK5-BM5-BN5-BP5-BR5 -> 24541.02 | BU5: =BT5/BK5 -> 0.49586834 | BV5: =BK5-BS5 -> 3386.07 | BW5: =BV5/BK5 -> 0.068417894
N8: =SUM(N3:N6) -> 900 | O8: =SUM(O3:O6) -> 49491 | P8: =SUM(P3:P6) -> 12942 | Q8: =SUM(Q3:Q6) -> 7423.65 | R8: =SUM(R3:R6) -> 2844 | S8: =SUM(S3:S6) -> 789.3 | T8: =SUM(T3:T6) -> 8908.38 | U8: =SUM(U3:U6) -> 7423.65 | ... X8: =SUM(X3:X6) -> 14642.82 | Y8: =X8/O8 -> 0.29586834 | Z8: =SUM(Z3:Z6) -> 911.52 | AA8: =Z8/O8 -> 0.018417894 | AD8: =SUM(AD3:AD6) -> 1500 | AE8: =SUM(AE3:AE6) -> 82485 | AF8: =SUM(AF3:AF6) -> 21570 | AG8: =SUM(AG3:AG6) -> 12372.75 | AH8: =SUM(AH3:AH6) -> 4740 | AI8: =SUM(AI3:AI6) -> 1315.5 | AJ8: =SUM(AJ3:AJ6) -> 8248.5 | AK8: =SUM(AK3:AK6) -> 12372.75 | ... AN8: =SUM(AN3:AN6) -> 43376.25 | AO8: =AN8/AE8 -> 0.52586834 | AP8: =SUM(AP3:AP6) -> 8118 | AQ8: =AP8/AE8 -> 0.098417894 | AT8: =SUM(AT3:AT6) -> 2100 | AU8: =SUM(AU3:AU6) -> 115479 | AV8: =SUM(AV3:AV6) -> 30198 | AW8: =SUM(AW3:AW6) -> 17321.85 | AX8: =SUM(AX3:AX6) -> 6636 | AY8: =SUM(AY3:AY6) -> 1841.7 | AZ8: =SUM(AZ3:AZ6) -> 8083.53 | BA8: =SUM(BA3:BA6) -> 17321.85 | ... BD8: =SUM(BD3:BD6) -> 64191.12 | BE8: =BD8/AU8 -> 0.55586834 | BF8: =SUM(BF3:BF6) -> 14829.57 | BG8: =BF8/AU8 -> 0.12841789 | BJ8: =SUM(BJ3:BJ6) -> 2700 | BK8: =SUM(BK3:BK6) -> 148473 | BL8: =SUM(BL3:BL6) -> 38826 | BM8: =SUM(BM3:BM6) -> 22270.95 | BN8: =SUM(BN3:BN6) -> 8532 | BO8: =SUM(BO3:BO6) -> 2367.9 | BP8: =SUM(BP3:BP6) -> 19301.49 | BQ8: =SUM(BQ3:BQ6) -> 22270.95 | ... BT8: =SUM(BT3:BT6) -> 73623.06 | BU8: =BT8/BK8 -> 0.49586834 | BV8: =SUM(BV3:BV6) -> 10158.21 | BW8: =BV8/BK8 -> 0.068417894
A10: 价格利润测算
A11: Asin | B11: Model | C11: Price | D11: All cost | E11: Profit | F11: Profit% | G11: MC | H11: 佣金 | I11: 配送费 | J11: 退货均摊 | K11: VAT税率 | L11: 佣金率 | M11: 退货率 | N11: 折扣% off | O11: 底价
A12: x | B12: xx | C12: =$M$3 -> 54.99 | D12: =G12+H12+I12+J12+K12*C12+C12*N12 -> 37.703 | E12: =C12-D12 -> 17.287 | F12: =E12/C12 -> 0.31436625 | G12: 14.38 | H12: =C12*L12 -> 8.2485 | I12: =$I$3 -> 3.16 | J12: =C12*M12 -> 2.7495 | K12: 0.16666667 | L12: =$E$3 -> 0.15 | M12: =$F$3 -> 0.05 | N12: 0 | O12: =(G12+I12)/(1-L12-M12-K12) -> 27.694737
A13: x | B13: xx | C13: =$M$3 -> 54.99 | D13: =G13+H13+I13+J13+K13*C13+C13*N13 -> 40.4525 | E13: =C13-D13 -> 14.5375 | F13: =E13/C13 -> 0.26436625 | G13: 14.38 | H13: =C13*L13 -> 8.2485 | I13: =$I$3 -> 3.16 | J13: =C13*M13 -> 2.7495 | K13: 0.16666667 | L13: =$E$3 -> 0.15 | M13: =$F$3 -> 0.05 | N13: 0.05 | O13: =(G13+I13)/(1-L13-M13-K13) -> 27.694737
A14: x | B14: xx | C14: =$M$3 -> 54.99 | D14: =G14+H14+I14+J14+K14*C14+C14*N14 -> 43.202 | E14: =C14-D14 -> 11.788 | F14: =E14/C14 -> 0.21436625 | G14: 14.38 | H14: =C14*L14 -> 8.2485 | I14: =$I$3 -> 3.16 | J14: =C14*M14 -> 2.7495 | K14: 0.16666667 | L14: =$E$3 -> 0.15 | M14: =$F$3 -> 0.05 | N14: 0.1 | O14: =(G14+I14)/(1-L14-M14-K14) -> 27.694737
A15: x | B15: xx | C15: =$M$3 -> 54.99 | D15: =G15+H15+I15+J15+K15*C15+C15*N15 -> 45.9515 | E15: =C15-D15 -> 9.0385 | F15: =E15/C15 -> 0.16436625 | G15: 14.38 | H15: =C15*L15 -> 8.2485 | I15: =$I$3 -> 3.16 | J15: =C15*M15 -> 2.7495 | K15: 0.16666667 | L15: =$E$3 -> 0.15 | M15: =$F$3 -> 0.05 | N15: 0.15 | O15: =(G15+I15)/(1-L15-M15-K15) -> 27.694737
A16: x | B16: xx | C16: =$M$3 -> 54.99 | D16: =G16+H16+I16+J16+K16*C16+C16*N16 -> 48.701 | E16: =C16-D16 -> 6.289 | F16: =E16/C16 -> 0.11436625 | G16: 14.38 | H16: =C16*L16 -> 8.2485 | I16: =$I$3 -> 3.16 | J16: =C16*M16 -> 2.7495 | K16: 0.16666667 | L16: =$E$3 -> 0.15 | M16: =$F$3 -> 0.05 | N16: 0.2 | O16: =(G16+I16)/(1-L16-M16-K16) -> 27.694737
A17: x | B17: xx | C17: =$M$3 -> 54.99 | D17: =G17+H17+I17+J17+K17*C17+C17*N17 -> 51.4505 | E17: =C17-D17 -> 3.5395 | F17: =E17/C17 -> 0.064366248 | G17: 14.38 | H17: =C17*L17 -> 8.2485 | I17: =$I$3 -> 3.16 | J17: =C17*M17 -> 2.7495 | K17: 0.16666667 | L17: =$E$3 -> 0.15 | M17: =$F$3 -> 0.05 | N17: 0.25 | O17: =(G17+I17)/(1-L17-M17-K17) -> 27.694737
A18: x | B18: xx | C18: =$M$3 -> 54.99 | D18: =G18+H18+I18+J18+K18*C18+C18*N18 -> 54.2 | E18: =C18-D18 -> 0.79 | F18: =E18/C18 -> 0.014366248 | G18: 14.38 | H18: =C18*L18 -> 8.2485 | I18: =$I$3 -> 3.16 | J18: =C18*M18 -> 2.7495 | K18: 0.16666667 | L18: =$E$3 -> 0.15 | M18: =$F$3 -> 0.05 | N18: 0.3 | O18: =(G18+I18)/(1-L18-M18-K18) -> 27.694737
A21: ROI测算
A22: 月份 | B22: 售价 | C22: 月销量 | D22: 总销售额 | E22: MC | F22: 佣金 | G22: 配送费 | H22: RMA扣减 | I22: 广告费 | J22: 促销费 | K22: VAT | L22: 成本总计 | M22: 回款额 US/EU | N22: 回款率 | O22: 净毛利 US | P22: 净毛利率 | Q22: 累计净毛利
A23: 1月 | B23: 46.74 | C23: =N5 -> 300 | D23: =O3 -> 16497 | E23: =P3 -> 4314 | F23: =Q3 -> 2474.55 | G23: =R3 -> 948 | H23: =S3 -> 263.1 | I23: =T3 -> 2969.46 | J23: =U3 -> 2474.55 | K23: =V3 -> 2749.5 | ... P23: =AA3 -> 0.018417894 | Q23: =O23 -> 303.84
A24: 2月 | B24: 46.74 | C24: =AD5 -> 500 | D24: =AE4 -> 27495 | E24: =AF4 -> 7190 | F24: =AG4 -> 4124.25 | G24: =AH4 -> 1580 | H24: =AI4 -> 438.5 | I24: =AJ4 -> 2749.5 | J24: =AK4 -> 4124.25 | K24: =AL4 -> 4582.5 | ... P24: =AQ4 -> 0.098417894 | Q24: =SUM(O23:O24) -> 3009.84
A25: 3月 | B25: 46.74 | C25: =AT5 -> 700 | D25: =AU4 -> 38493 | E25: =AV4 -> 10066 | F25: =AW4 -> 5773.95 | G25: =AX4 -> 2212 | H25: =AY4 -> 613.9 | I25: =AZ4 -> 2694.51 | J25: =BA4 -> 5773.95 | K25: =BB4 -> 6415.5 | ... P25: =BG4 -> 0.12841789 | Q25: =SUM(O23:O25) -> 7953.03
A26: 4月 | B26: 46.74 | C26: =BJ5 -> 900 | D26: =BK3 -> 49491 | E26: =BL3 -> 12942 | F26: =BM3 -> 7423.65 | G26: =BN3 -> 2844 | H26: =BO3 -> 789.3 | I26: =BP3 -> 6433.83 | J26: =BQ3 -> 7423.65 | K26: =BR3 -> 8248.5 | ... P26: =BW3 -> 0.068417894 | Q26: =SUM(O23:O26) -> 11339.1
A27: 5月 | B27: 46.74 | C27: =BJ5 -> 900 | D27: =BK4 -> 49491 | E27: =BL4 -> 12942 | F27: =BM4 -> 7423.65 | G27: =BN4 -> 2844 | H27: =BO4 -> 789.3 | I27: =BP4 -> 6433.83 | J27: =BQ4 -> 7423.65 | K27: =BR4 -> 8248.5 | ... P27: =BW4 -> 0.068417894 | Q27: =SUM(O23:O27) -> 14725.17
A28: 6月 | B28: 46.74 | C28: =BJ5 -> 900 | D28: =BK5 -> 49491 | E28: =BL5 -> 12942 | F28: =BM5 -> 7423.65 | G28: =BN5 -> 2844 | H28: =BO5 -> 789.3 | I28: =BP5 -> 6433.83 | J28: =BQ5 -> 7423.65 | ... P28: =BW5 -> 0.068417894 | Q28: =SUM(O23:O28) -> 18111.24
A29: 7月 | B29: 46.74 | C29: =BJ5 -> 900 | D29: =BK5 -> 49491 | E29: =BL5 -> 12942 | F29: =BM5 -> 7423.65 | G29: =BN5 -> 2844 | H29: =BO5 -> 789.3 | I29: =BP5 -> 6433.83 | J29: =BQ5 -> 7423.65 | ... P29: =BW5 -> 0.068417894 | Q29: =SUM(O23:O29) -> 21497.31
A30: 8月 | B30: 46.74 | C30: =BJ5 -> 900 | D30: =BK5 -> 49491 | E30: =BL5 -> 12942 | F30: =BM5 -> 7423.65 | G30: =BN5 -> 2844 | H30: =BO5 -> 789.3 | I30: =BP5 -> 6433.83 | J30: =BQ5 -> 7423.65 | ... P30: =BW5 -> 0.068417894 | Q30: =SUM(O27:O30) -> 13544.28
A31: 9月 | B31: 46.74 | C31: 900 | D31: 49491 | E31: 12942 | F31: 7423.65 | G31: 2844 | H31: 789.3 | I31: 6433.83 | J31: 7423.65 | K31: 8248.5 | L31: 46104.93 | M31: 24541.02 | N31: 0.49586834 | O31: 3386.07 | P31: 0.068417894 | Q31: =SUM(O23:O31) -> 28269.45
A32: 10月 | B32: 46.74 | C32: 900 | D32: 49491 | E32: 12942 | F32: 7423.65 | G32: 2844 | H32: 789.3 | I32: 6433.83 | J32: 7423.65 | K32: 8248.5 | L32: 46104.93 | M32: 24541.02 | N32: 0.49586834 | O32: 3386.07 | P32: 0.068417894 | Q32: =SUM(O23:O32) -> 31655.52
A33: 11月 | B33: 46.74 | C33: 900 | D33: 49491 | E33: 12942 | F33: 7423.65 | G33: 2844 | H33: 789.3 | I33: 6433.83 | J33: 7423.65 | K33: 8248.5 | L33: 46104.93 | M33: 24541.02 | N33: 0.49586834 | O33: 3386.07 | P33: 0.068417894 | Q33: =SUM(O23:O33) -> 35041.59
A34: 12月 | B34: 46.74 | C34: 900 | D34: 49491 | E34: 12942 | F34: 7423.65 | G34: 2844 | H34: 789.3 | I34: 6433.83 | J34: 7423.65 | K34: 8248.5 | L34: 46104.93 | M34: 24541.02 | N34: 0.49586834 | O34: 3386.07 | P34: 0.068417894 | Q34: =SUM(O23:O34) -> 38427.66

Sheet 账号&备货规划
A1: 采购单 | D1: 中仓 | H1: FBA调拨
A2: 采购单类型 | B2: 下采购购单日期 | C2: 采购数量 | D2: 入中仓时间 | E2: 入仓数量 | F2: 是否备安全库存 | G2: 安全库存数量 | H2: 调拨时间 | I2: 物流方式 | J2: 调拨数量 | K2: 调拨账号
A3: 首单 | B3: 2021.12.7 | C3: 5000 | D3: 2022.1.16 | E3: 4988 | F3: 是 | G3: 1000 | H3: 2022.1.19 | I3: 海运 | J3: 2490 | K3: LBS
H4: 2022.2.11 | I4: 空派 | J4: 1200 | K4: TT
H5: 2022.3.18 | I5: 卡派 | J5: 1310 | K5: LBS
A6: 翻单1 | B6: 2022.3.22 | C6: 1500 | D6: 2022.4.22 | E6: 1500 | F6: 否 | G6: 0 | H6: 2022.4.23 | I6: 卡派 | J6: 1500
A7: 翻单2 | B7: 2022.4.12 | C7: 1980 | D7: 2022.5.12 | E7: 1980 | F7: 否 | G7: 0 | H7: 2022.5.13 | I7: 卡派 | J7: 1980
A8: 翻单3 | B8: 2022.4.28 | C8: 2100 | D8: 2022.5.28 | E8: 2100 | F8: 否 | G8: 0 | H8: 2022.5.29 | I8: 海运 | J8: 2100 | K8: LBS
A9: 翻单4 | B9: 2022.5.19 | C9: 3000 | D9: 2022.7.1 | E9: 3000 | F9: 否 | G9: 0 | H9: 2022.7.2 | I9: 海运 | J9: 3000 | K9: LBS
A11: 采购交期45天，翻单1，2，3由于时间关系需要催单30天交付，若无法提前交付时间，则需提前下单或走部分空运
A12: FBA详细备货见推广计划
C13: 安全库存
C14: 1. 备货数量较保守，可能会有销量上涨，此部分库存用来避免断货
C15: 2. 防止主要销售账号出现异常时，其他账号无货可售的情况
C16: 3. 安全库存遵循先进先出原则
