Workbook

Sheet 1.0 竞品拓词法 （至少50个）
A1: 品拓词导出_相似竞品拓词&筛查 | N1: Administrator:B08BLTZQ7R,B0DQT1MKZ3,B0DDPXCK6L,B0CPJ76KXR,B0CKTKBSP8,B0D9BQHSWQ,B0D6YTJD1S,B0DDCVZWCY,B0CJ9FL94H,B0DNYVJ4PL,B0DLTVHN3B,B0CHMPZVZT,B0CJFR8YZ1,B0DLWJD9MV,B0DGJPJJD9,B0DKY6RQRC,B0DDXZNCKL,B0DL5J6MK4,B0DPDK6RLJ,B0D73F6HDZ,B0D3QGFGR8,B0DKPGVGT5,B0DHCXJRS9,B0D7HF8S2W,B0DBLK3543,B0DPDHSHGK,B0DQSF6MDL,B0DCS2M8XZ,B08XQF7NRH,B0DQSLNPSK,B0DPKNMGRZ,B0CTCP2S2W,B0DBLKGKFZ,B0CTCMLZSQ,B0D83SRY9V,B0D7HN9GKW,B0DCG3BSC5,B0DDPHBKLK,B0DFL7333M,B0CRKGHTNR,B0DBLL3P6C,B0DBHBPWXW,B0DJ35DCZD,B0DFL7333M拓词并筛查共44个目标产品(加入拓词竞品库)，按Listing拓展后总共58个变体，合并去重后总共反查出848个关键词848
A2: # | B2: 关键词 | C2: 相关性-自动百分比 | D2: 相关性-自动占比 | E2: 相关性-自动 | F2: 自然位前4占位率 | G2: 自然位前8占位率 | H2: 自然位前16占位率 | I2: 自然位前32占位率 | J2: 自然位前48占位率 | K2: 搜索量 | L2: 排名 | M2: 相关性-手动 | N2: 流量大小 | O2: 相关性 | P2: 修饰词类型 | Q2: 搜索转化率
A3: 1 | B3: hoover milbensauger | C3: hoover除螨吸尘器 | D3: 0.7451 | E3: 高相关 | F3: 0.9063 | G3: 0.6719 | H3: 0.6094 | I3: 0.3555 | J3: 0.2578 | K3: 374 | L3: 149958 | M3: =E3 -> 高相关 | O3: =E3 -> 高相关
A4: 2 | B4: milbenstaubsauger | C4: 除螨吸尘器 | D4: 0.509 | E4: 中相关 | F4: 0.5 | G4: 0.5 | H4: 0.5625 | I4: 0.5234 | J4: 0.4323 | K4: 334 | L4: 169036 | M4: =E4 -> 中相关 | O4: =E4 -> 中相关
A5: 3 | B5: milbensauger für matratzen testsieger | C5: 床垫用除螨吸尘器测试冠军 | D5: 0.4965 | E5: 中相关 | F5: 0.5 | G5: 0.4844 | H5: 0.5156 | I5: 0.4961 | J5: 0.4453 | K5: 389 | L5: 143911 | M5: =E5 -> 中相关 | O5: =E5 -> 中相关
A6: 4 | B6: milbensauger | C6: 除螨吸尘器 | D6: 0.4962 | E6: 中相关 | F6: 0.5 | G6: 0.4844 | H6: 0.5156 | I6: 0.4844 | J6: 0.4609 | K6: 9229 | L6: 3344 | M6: =E6 -> 中相关 | O6: =E6 -> 中相关
A7: 5 | B7: milbensauger mit uv licht | C7: 带紫外线的除螨吸尘器 | D7: 0.4877 | E7: 中相关 | F7: 0.5 | G7: 0.4844 | H7: 0.4453 | I7: 0.5195 | J7: 0.4479 | K7: 879 | L7: 59735 | M7: =E7 -> 中相关 | O7: =E7 -> 中相关
A8: 6 | B8: jimmy jv35 milbensauger | C8: 吉米 JV35 除螨吸尘器 | D8: 0.4669 | E8: 中相关 | F8: 0.5 | G8: 0.5 | H8: 0.4375 | I8: 0.2734 | J8: 0.237 | K8: 774 | L8: 68603 | M8: =E8 -> 中相关 | O8: =E8 -> 中相关
A9: 7 | B9: milbensauger für matratzen | C9: 床垫用除螨吸尘器 | D9: 0.4617 | E9: 中相关 | F9: 0.4375 | G9: 0.4844 | H9: 0.5 | I9: 0.4766 | J9: 0.4505 | K9: 5289 | L9: 7239 | M9: =E9 -> 中相关 | O9: =E9 -> 中相关
A10: 8 | B10: hoover | C10: hoover | D10: 0.337 | E10: 中相关 | F10: 0.5 | G10: 0.25 | H10: 0.125 | I10: 0.0625 | J10: 0.0443 | K10: 594 | L10: 91525 | M10: =E10 -> 中相关 | O10: =E10 -> 中相关
A11: 9 | B11: matratzenreiniger gerät | C11: 床垫清洁设备 | D11: 0.3198 | E11: 中相关 | F11: 0.2813 | G11: 0.3594 | H11: 0.3672 | I11: 0.3477 | J11: 0.3307 | K11: 309 | L11: 183070 | M11: =E11 -> 中相关 | O11: =E11 -> 中相关
A12: 10 | B12: matratzen reiniger | C12: 床垫清洁剂 | D12: 0.1847 | E12: 低相关 | F12: 0.25 | G12: 0.125 | H12: 0.0625 | I12: 0.1953 | J12: 0.1797 | K12: 359 | L12: 156629 | M12: =E12 -> 低相关 | O12: =E12 -> 低相关
A13: 11 | B13: milben | C13: 螨虫 | D13: 0.1843 | E13: 低相关 | F13: 0.25 | G13: 0.125 | H13: 0.1094 | I13: 0.1133 | J13: 0.1224 | K13: 539 | L13: 101622 | M13: =E13 -> 低相关 | O13: =E13 -> 低相关
A14: 12 | B14: hoover staubsauger | C14: hoover吸尘器 | D14: 0.1795 | E14: 低相关 | F14: 0.25 | G14: 0.125 | H14: 0.1172 | I14: 0.0625 | J14: 0.0443 | K14: 334 | L14: 169036 | M14: =E14 -> 低相关 | O14: =E14 -> 低相关
... A90: 88 | B90: uwant b200 | C90: uwant b200 | D90: 0.0022 | E90: 不相关 | F90: 0 | G90: 0 | H90: 0.0078 | I90: 0.0117 | J90: 0.0078 | K90: 234 | L90: 243917 | M90: =E90 -> 不相关 | O90: =E90 -> 不相关
A91: 89 | B91: shark detect clean & empty | D91: 0.0021 | E91: 不相关 | F91: 0 | G91: 0 | H91: 0 | I91: 0.0234 | J91: 0.0156 | K91: 449 | L91: 123476 | M91: =E91 -> 不相关 | O91: =E91 -> 不相关
A92: 90 | B92: sofa cleaner | C92: 沙发清洁剂 | D92: 0.002 | E92: 不相关 | F92: 0 | G92: 0 | H92: 0 | I92: 0.0156 | J92: 0.0313 | K92: 369 | L92: 152138 | M92: =E92 -> 不相关 | O92: =E92 -> 不相关
A93: 91 | B93: sofa | C93: 沙发 | D93: 0.0019 | E93: 不相关 | F93: 0 | G93: 0 | H93: 0 | I93: 0.0195 | J93: 0.0182 | K93: 30522 | L93: 499 | M93: =E93 -> 不相关 | O93: =E93 -> 不相关
A94: 92 | B94: couch reinigen | C94: 清洁沙发 | D94: 0.0019 | E94: 不相关 | F94: 0 | G94: 0 | H94: 0.0078 | I94: 0.0078 | J94: 0.0052 | K94: 0 | L94: 0 | M94: =E94 -> 不相关 | O94: =E94 -> 不相关
A95: 93 | B95: polsterreiniger gerät klein | D95: 0.0018 | E95: 不相关 | F95: 0 | G95: 0 | H95: 0.0078 | I95: 0.0039 | J95: 0.0104 | K95: 0 | L95: 0 | M95: =E95 -> 不相关 | O95: =E95 -> 不相关
A96: 94 | B96: pink vacuum cleaner | C96: 粉色吸尘器 | D96: 0.0018 | E96: 不相关 | F96: 0 | G96: 0 | H96: 0 | I96: 0.0195 | J96: 0.0156 | K96: 139 | L96: 405844 | M96: =E96 -> 不相关 | O96: =E96 -> 不相关
A97: 95 | B97: bissell spotclean c3 | C97: 必胜点状清洁c3 | D97: 0.0018 | E97: 不相关 | F97: 0 | G97: 0 | H97: 0 | I97: 0.0195 | J97: 0.013 | K97: 0 | L97: 0 | M97: =E97 -> 不相关 | O97: =E97 -> 不相关
A98: 96 | B98: haushof waschsauger | C98: Haushof 洗地机 | D98: 0.0017 | E98: 不相关 | F98: 0 | G98: 0 | H98: 0 | I98: 0.0039 | J98: 0.0469 | K98: 1344 | L98: 37411 | M98: =E98 -> 不相关 | O98: =E98 -> 不相关
A99: 97 | B99: staubsauger wasserfilter | C99: 水过滤吸尘器 | D99: 0.0017 | E99: 不相关 | F99: 0 | G99: 0 | H99: 0 | I99: 0.0156 | J99: 0.0208 | K99: 464 | L99: 119207 | M99: =E99 -> 不相关 | O99: =E99 -> 不相关
A100: 98 | B100: matratzen | C100: 床垫 | D100: 0.0017 | E100: 不相关 | F100: 0 | G100: 0 | H100: 0.0078 | I100: 0.0039 | J100: 0.0078 | K100: 3484 | L100: 12253 | M100: =E100 -> 不相关 | O100: =E100 -> 不相关
A101: 99 | B101: bissell fleckenreiniger | C101: bissell 去污剂 | D101: 0.0016 | E101: 不相关 | F101: 0 | G101: 0 | H101: 0 | I101: 0.0156 | J101: 0.0156 | K101: 459 | L101: 120596 | M101: =E101 -> 不相关 | O101: =E101 -> 不相关
A102: 100 | B102: doppelzyklon | C102: doppelzyklon | D102: 0.0015 | E102: 不相关 | F102: 0 | G102: 0 | H102: 0.0078 | I102: 0.0039 | J102: 0.0026 | K102: 124 | L102: 451926 | M102: =E102 -> 不相关 | O102: =E102 -> 不相关
A103: 101 | B103: mini henry hoover | C103: 迷你亨利吸尘器 | D103: 0.0015 | E103: 不相关 | F103: 0 | G103: 0 | H103: 0.0078 | I103: 0.0039 | J103: 0.0026 | K103: 0 | L103: 0 | M103: =E103 -> 不相关 | O103: =E103 -> 不相关
A104: 102 | B104: dampfreiniger couch | C104: 沙发蒸汽清洁器 | D104: 0.0015 | E104: 不相关 | F104: 0 | G104: 0 | H104: 0.0078 | I104: 0.0039 | J104: 0.0026 | K104: 139 | L104: 405844 | M104: =E104 -> 不相关 | O104: =E104 -> 不相关
A105: 103 | B105: allergiker | C105: 过敏者 | D105: 0.0015 | E105: 不相关 | F105: 0 | G105: 0 | H105: 0.0078 | I105: 0.0039 | J105: 0.0026 | K105: 154 | L105: 367674 | M105: =E105 -> 不相关 | O105: =E105 -> 不相关
A106: 104 | B106: powercleany handstaubsauger der stärkste | C106: PowerCleany最强手持吸尘器 | D106: 0.0015 | E106: 不相关 | F106: 0 | G106: 0 | H106: 0 | I106: 0.0117 | J106: 0.0234 | K106: 0 | L106: 0 | M106: =E106 -> 不相关 | O106: =E106 -> 不相关
A107: 105 | B107: kroqo | C107: kroqo | D107: 0.0015 | E107: 不相关 | F107: 0 | G107: 0 | H107: 0.0078 | I107: 0.0039 | J107: 0.0026 | K107: 0 | L107: 0 | M107: =E107 -> 不相关 | O107: =E107 -> 不相关
... A113: 111 | B113: dampfreiniger für polstermöbel | C113: 软垫家具用蒸汽清洁器 | D113: 0.0015 | E113: 不相关 | F113: 0 | G113: 0 | H113: 0.0078 | I113: 0.0039 | J113: 0.0026 | K113: 274 | L113: 207537 | M113: =E113 -> 不相关 | O113: =E113 -> 不相关
A114: 112 | B114: pureprotect mini 900 series | D114: 0.0015 | E114: 不相关 | F114: 0 | G114: 0 | H114: 0.0078 | I114: 0.0039 | J114: 0.0026 | K114: 144 | L114: 392148 | M114: =E114 -> 不相关 | O114: =E114 -> 不相关
A115: 113 | B115: shark wv200eu | C115: 鲨鱼 wv200eu | D115: 0.0015 | E115: 不相关 | F115: 0 | G115: 0 | H115: 0.0078 | I115: 0.0039 | J115: 0.0026 | K115: 159 | L115: 356754 | M115: =E115 -> 不相关 | O115: =E115 -> 不相关
A116: 114 | B116: hover air x1 drohne | C116: hover air x1 无人机 | D116: 0.0014 | E116: 不相关 | F116: 0 | G116: 0 | H116: 0 | I116: 0.0156 | J116: 0.0104 | K116: 334 | L116: 169036 | M116: =E116 -> 不相关 | O116: =E116 -> 不相关
A117: 115 | B117: neakasa magic 1 vacuum steamer | D117: 0.0014 | E117: 不相关 | F117: 0 | G117: 0 | H117: 0 | I117: 0.0156 | J117: 0.0104 | K117: 774 | L117: 68603 | M117: =E117 -> 不相关 | O117: =E117 -> 不相关
A118: 116 | B118: polstersauger nass | C118: 湿式软垫吸尘器 | D118: 0.0014 | E118: 不相关 | F118: 0 | G118: 0 | H118: 0 | I118: 0.0039 | J118: 0.0365 | K118: 394 | L118: 142001 | M118: =E118 -> 不相关 | O118: =E118 -> 不相关
A119: 117 | B119: dupray steam cleaner | C119: dupray 蒸汽清洁器 | D119: 0.0014 | E119: 不相关 | F119: 0 | G119: 0 | H119: 0 | I119: 0.0117 | J119: 0.0208 | K119: 319 | L119: 177104 | M119: =E119 -> 不相关 | O119: =E119 -> 不相关
A120: 118 | B120: ryer nasssauger reinigung teppich und kauqe reinigung | D120: 0.0012 | E120: 不相关 | F120: 0 | G120: 0 | H120: 0 | I120: 0 | J120: 0.0391 | K120: 1179 | L120: 43236 | M120: =E120 -> 不相关 | O120: =E120 -> 不相关
...

Sheet 1.1 竞品拓词法 （至少20个）
A1: milbensauger竞品拓词导出_相似竞品拓词&筛查 | N1: B0DQSMD5VW,B0DL5J6MK4,B08BLTZQ7R,B0DKPGVGT5,B0CKTKBSP8,B014SPNQV2,B0CJFR8YZ1,B0CHMPZVZT,B0DDPXCK6L,B0CJ9FL94H
A2: # | B2: 关键词 | C2: 相关性-自动百分比 | D2: 相关性-自动 | E2: 相关性-自动 | F2: 相关性-自动 | G2: 自然位前4占位率 | H2: 自然位前8占位率 | I2: 自然位前16占位率 | J2: 自然位前32占位率 | K2: 自然位前48占位率 | L2: 搜索量 | M2: 排名 | N2: 相关性-手动 | O2: 流量大小 | P2: 相关性 | Q2: 修饰词类型 | R2: 搜索转化率
A3: 1 | B3: hoover milbensauger | C3: 胡佛除螨吸尘器 | D3: 72.81% | E3: 高相关 | F3: 高相关 | G3: 93.75% | H3: 60.94% | I3: 54.69% | J3: 27.73% | K3: 18.49% | L3: 329 | M3: 177403
A4: 2 | B4: milbensauger für matratzen testsieger | C4: 床垫用除螨吸尘器测试冠军 | D4: 42.67% | E4: 中相关 | F4: 中相关 | G4: 46.88% | H4: 43.75% | I4: 36.72% | J4: 30.08% | K4: 22.66% | L4: 444 | M4: 129581
A5: 3 | B5: milbensauger | C5: 除螨吸尘器 | D5: 41.68% | E5: 中相关 | F5: 中相关 | G5: 46.88% | H5: 39.06% | I5: 39.06% | J5: 27.73% | K5: 22.66% | L5: 10049 | M5: 3142
A6: 4 | B6: milbenstaubsauger | C6: 除螨吸尘器 | D6: 40.3% | E6: 中相关 | F6: 中相关 | G6: 46.88% | H6: 37.5% | I6: 31.25% | J6: 30.86% | K6: 21.35% | L6: 434 | M6: 132720
A7: 5 | B7: milbensauger mit uv licht | C7: 带紫外线的除螨吸尘器 | D7: 40.04% | E7: 中相关 | F7: 中相关 | G7: 46.88% | H7: 37.5% | I7: 31.25% | J7: 26.95% | K7: 21.88% | L7: 899 | M7: 60795
A8: 6 | B8: milbensauger für matratzen | C8: 床垫用除螨吸尘器 | D8: 39.39% | E8: 中相关 | F8: 中相关 | G8: 43.75% | H8: 42.19% | I8: 29.69% | J8: 26.17% | K8: 22.66% | L8: 5589 | M8: 7084
A9: 7 | B9: hoover | C9: 胡佛 | D9: 33.69% | E9: 中相关 | F9: 中相关 | G9: 50% | H9: 25% | I9: 12.5% | J9: 6.25% | K9: 4.17% | L9: 549 | M9: 103370
A10: 8 | B10: matratzenreiniger gerät | C10: 床垫清洁设备 | D10: 24.97% | E10: 中相关 | F10: 中相关 | G10: 28.13% | H10: 21.88% | I10: 23.44% | J10: 19.92% | K10: 17.71% | L10: 364 | M10: 159716
A11: 9 | B11: jimmy jv35 milbensauger | C11: 吉米 JV35 除螨吸尘器 | D11: 23.63% | E11: 中相关 | F11: 中相关 | G11: 25% | H11: 25% | I11: 25% | J11: 12.5% | K11: 8.59% | L11: 689 | M11: 81160
A12: 10 | B12: milben | C12: 螨虫 | D12: 18.37% | E12: 低相关 | F12: 低相关 | G12: 25% | H12: 12.5% | I12: 11.72% | J12: 9.77% | K12: 10.16% | L12: 524 | M12: 108734
A13: 11 | B13: hoover staubsauger | C13: 胡佛吸尘器 | D13: 17.84% | E13: 低相关 | F13: 低相关 | G13: 25% | H13: 12.5% | I13: 10.94% | J13: 6.25% | K13: 4.43% | L13: 319 | M13: 183101
A14: 12 | B14: matratzen reiniger | C14: 床垫清洁剂 | D14: 17.81% | E14: 低相关 | F14: 低相关 | G14: 25% | H14: 12.5% | I14: 6.25% | J14: 13.28% | K14: 10.68% | L14: 509 | M14: 112137
A15: 13 | B15: bettwanzen | C15: 臭虫（复数） | D15: 16.84% | F15: 低相关 | G15: 25% | H15: 12.5% | I15: 6.25% | J15: 3.13% | K15: 2.08% | L15: 874 | M15: 62632
A16: 14 | B16: bettwanzen bekämpfung | C16: 臭虫防治 | D16: 16.84% | F16: 低相关 | G16: 25% | H16: 12.5% | I16: 6.25% | J16: 3.13% | K16: 2.08% | L16: 959 | M16: 56582
A17: 15 | B17: jigoo j300 milbensauger | C17: 吉戈J300除螨吸尘器 | D17: 9.42% | F17: 低相关 | G17: 12.5% | H17: 7.81% | I17: 6.25% | J17: 3.13% | K17: 2.08% | L17: 144 | M17: 405696
A18: 16 | B18: jigoo j300 | C18: 吉戈J300 | D18: 9.27% | F18: 低相关 | G18: 12.5% | H18: 7.81% | I18: 5.47% | J18: 2.73% | K18: 1.82% | L18: 144 | M18: 405696
A19: 17 | B19: matratzenreiniger | C19: 床垫清洁剂 | D19: 8.43% | F19: 低相关 | G19: 3.13% | H19: 12.5% | I19: 13.28% | J19: 18.36% | K19: 15.63% | L19: 804 | M19: 68595
A20: 18 | B20: jigoo t600 milbensauger | D20: 7.74% | F20: 低相关 | G20: 9.38% | H20: 7.81% | I20: 5.47% | J20: 3.13% | K20: 2.08% | L20: 294 | M20: 199357
A21: 19 | B21: milbensauger jigoo | D21: 7.71% | F21: 低相关 | G21: 9.38% | H21: 7.81% | I21: 5.47% | J21: 2.73% | K21: 1.82% | L21: 149 | M21: 392766
A22: 20 | B22: jigoo milbensauger | C22: 吉戈除螨吸尘器 | D22: 7.55% | F22: 低相关 | G22: 9.38% | H22: 7.81% | I22: 4.69% | J22: 2.34% | K22: 1.56% | L22: 159 | M22: 368973
A23: 21 | B23: hoover ultra vortex milbensauger | C23: hoover ultra vortex 除螨吸尘器 | D23: 7.32% | F23: 低相关 | G23: 9.38% | H23: 6.25% | I23: 5.47% | J23: 2.73% | K23: 1.82% | L23: 129 | M23: 450049
A24: 22 | B24: hyla staubsauger | C24: hyla 吸尘器 | D24: 6.81% | F24: 低相关 | G24: 3.13% | H24: 10.94% | I24: 10.94% | J24: 8.98% | K24: 8.07% | L24: 674 | M24: 83172
A25: 23 | B25: jimmy milbensauger | C25: 吉米 除螨吸尘器 | D25: 6.5% | F25: 低相关 | G25: 6.25% | H25: 6.25% | I25: 8.59% | J25: 5.86% | K25: 3.91% | L25: 274 | M25: 214312
A26: 24 | B26: polstersauger | C26: 软垫吸尘器 | D26: 6.25% | F26: 低相关 | G26: 3.13% | H26: 12.5% | I26: 6.25% | J26: 5.86% | K26: 7.03% | L26: 684 | M26: 81829
A27: 25 | B27: mattress vacuum cleaner | C27: 床垫吸尘器 | D27: 5.75% | F27: 低相关 | G27: 6.25% | H27: 6.25% | I27: 5.47% | J27: 2.73% | K27: 1.82% | L27: 239 | M27: 246305
A28: 26 | B28: bed vacuum cleaner | C28: 床用吸尘器 | D28: 5.21% | F28: 低相关 | G28: 6.25% | H28: 4.69% | I28: 4.69% | J28: 2.34% | K28: 1.56% | L28: 154 | M28: 380614
A29: 27 | B29: hausstaubmilben sauger | C29: 防尘螨吸尘器 | D29: 5.12% | F29: 低相关 | G29: 6.25% | H29: 4.69% | I29: 3.13% | J29: 3.91% | K29: 2.6% | L29: 149 | M29: 392766
A30: 28 | B30: dampfreiniger matratze | C30: 蒸汽清洁器 床垫 | D30: 5.06% | F30: 低相关 | G30: 6.25% | H30: 4.69% | I30: 3.91% | J30: 1.95% | K30: 1.3% | L30: 209 | M30: 282089
A31: 29 | B31: sofa staubsauger | C31: 沙发吸尘器 | D31: 4.95% | F31: 低相关 | G31: 6.25% | H31: 4.69% | I31: 3.13% | J31: 1.95% | K31: 1.56% | L31: 184 | M31: 320398
A32: 30 | B32: matratzensauger | C32: 床垫吸尘器 | D32: 4.82% | F32: 低相关 | G32: 6.25% | H32: 3.13% | I32: 4.69% | J32: 2.34% | K32: 1.56% | L32: 219 | M32: 269187
A33: 31 | B33: milben sauger | C33: 螨虫吸尘器 | D33: 4.78% | F33: 低相关 | G33: 6.25% | H33: 3.13% | I33: 3.91% | J33: 3.13% | K33: 2.34% | L33: 249 | M33: 236350
... A46: 44 | B46: hausstaubmilben | C46: 尘螨 | D46: 2.76% | F46: 低相关 | G46: 3.13% | H46: 3.13% | I46: 1.56% | J46: 1.56% | K46: 2.34% | L46: 264 | M46: 222710
A47: 45 | B47: jimmy bx8 | D47: 2.65% | F47: 低相关 | G47: 3.13% | H47: 3.13% | I47: 1.56% | J47: 0.78% | K47: 0.52% | L47: 129 | M47: 450049
A48: 46 | B48: hyla wasserstaubsauger | C48: hyla 水吸尘器 | D48: 2.31% | F48: 低相关 | G48: 0% | H48: 0% | I48: 10.16% | J48: 8.59% | K48: 6.25% | L48: 2579 | M48: 18511
A49: 47 | B49: jimmy | C49: 吉米 | D49: 2.29% | F49: 低相关 | G49: 3.13% | H49: 1.56% | I49: 1.56% | J49: 1.17% | K49: 0.78% | L49: 259 | M49: 227059
A50: 48 | B50: matratzen reiniger gerät | C50: 床垫清洁设备 | D50: 2.26% | F50: 低相关 | G50: 3.13% | H50: 1.56% | I50: 1.56% | J50: 0.78% | K50: 0.52% | L50: 209 | M50: 282089
A51: 49 | B51: anti milben | C51: 抗螨虫 | D51: 2.19% | F51: 低相关 | G51: 3.13% | H51: 1.56% | I51: 0.78% | J51: 1.17% | K51: 1.3% | L51: 129 | M51: 450049
A52: 50 | B52: power cleany | C52: 电动清洁 | D52: 1.82% | F52: 不相关 | G52: 0% | H52: 0% | I52: 6.25% | J52: 8.2% | K52: 10.16% | L52: 0 | M52: 0
...

Sheet 1.2 以词拓词（词根法）
A1: 以词拓词导出_2023-08-25 词根: milbensauger
A2: # | B2: 关键词 | C2: 中文名字 | D2: 匹配模式 | E2: 搜索量 | F2: 排名 | G2: 相关性-手动
A3: 1 | B3: milbensauger | C3: 除螨吸尘器 | D3: 精准匹配 | E3: 49183 | F3: 2230 | G3: 高相干性
A4: 2 | B4: milbensauger für matratzen | C4: 床垫用除螨吸尘器 | D4: 词组匹配,下拉框匹配 | E4: 24649 | F4: 6107 | G4: 高相干性
A5: 3 | B5: milbensauger mit uv licht | C5: 带紫外线的除螨吸尘器 | D5: 词组匹配,下拉框匹配 | E5: 4514 | F5: 48570 | G5: 高相干性
A6: 4 | B6: jimmy jv35 milbensauger | C6: 吉米 JV35 除螨吸尘器 | D6: 词组匹配 | E6: 2814 | F6: 81546 | G6: 高相干性
A7: 5 | B7: hoover milbensauger | C7: 胡佛除螨吸尘器 | D7: 词组匹配 | E7: 2664 | F7: 86495 | G7: 高相干性
A8: 6 | B8: milbensauger für matratzen testsieger | C8: 床垫用除螨吸尘器测试冠军 | D8: 词组匹配,下拉框匹配 | E8: 2144 | F8: 109170 | G8: 高相干性
A9: 7 | B9: hoover ultra vortex milbensauger | C9: hoover ultra vortex 除螨吸尘器 | D9: 词组匹配 | E9: 1489 | F9: 160697 | G9: 高相干性
A10: 8 | B10: milbensauger | C10: 品类词 除螨仪 | E10: 49183 | F10: 2230 | G10: 高相干性
A11: 9
A12: 10
A13: 11
A14: 12
A15: 13
A16: 14
A17: 15
A18: 16
A19: 17
A20: 18
A21: 19
A22: 20
... A2414: 2412

Sheet 1.3品类拓词法
A1: 品类拓词导出 | N1: milbensauger
A2: # | B2: 关键词 | C2: 搜索量 | D2: 排名 | E2: 相关性-手动 | L2: 排名 | M2: 相关性-手动
A3: 1 | B3: sofareiniger waschsauger | C3: 洗吸一体沙发清洁机 | D3: 1249 | E3: 192640
A4: 2 | B4: dampfreiniger sofa | C4: 蒸汽清洁器 沙发 | D4: 1249 | E4: 192640
A5: 3 | B5: textilreiniger sofa | C5: 沙发纺织清洁剂 | D5: 1249 | E5: 192640
A6: 4 | B6: wasserstaubsauger hyla alternative | C6: Hyla水过滤吸尘器替代品 | D6: 1264 | E6: 190291
A7: 5 | B7: matratzenreiniger gerät | C7: 床垫清洁设备 | D7: 1284 | E7: 187252 | M7: 弱相关
A8: 6 | B8: couchreiniger | C8: 沙发清洁剂 | D8: 1289 | E8: 186501
A9: 7 | B9: avuso luminex | C9: avuso luminex | D9: 1459 | E9: 164157 | M9: 弱相关
A10: 8 | B10: hoover ultra vortex milbensauger | C10: hoover ultra vortex 除螨吸尘器 | D10: 1489 | E10: 160697 | M10: 强
A11: 9 | B11: polster reinigung gerät | C11: 垫子清洁设备 | D11: 1639 | E11: 145285
A12: 10 | B12: matratzen reiniger | C12: 床垫清洁剂 | D12: 1664 | E12: 142994 | M12: 强
A13: 11 | B13: polstersauger nass | C13: 湿式软垫吸尘器 | D13: 1724 | E13: 137760 | M13: 不相关
A14: 12 | B14: tepichreinigungsmaschine | C14: 地毯清洁机 | D14: 1779 | E14: 133271
A15: 13 | B15: nassreiniger polstermöbel | C15: 软垫家具湿式清洁器 | D15: 1844 | E15: 128289 | M15: 不相关，品牌词
A16: 14 | B16: sofareiniger | C16: 沙发清洁剂 | D16: 1854 | E16: 127540 | M16: 不相关，品牌词
A17: 15 | B17: jimmy | C17: 吉米 | D17: 1874 | E17: 126067
A18: 16 | B18: waschsauger polster | C18: 软垫洗涤吸尘器 | D18: 2009 | E18: 116986
A19: 17 | B19: milben | C19: 螨虫 | D19: 2124 | E19: 110246
A20: 18 | B20: milbensauger für matratzen testsieger | C20: 床垫用除螨吸尘器测试冠军 | D20: 2144 | E20: 109170
A21: 19 | B21: polster dampfreiniger | C21: 软垫蒸汽清洁器 | D21: 2154 | E21: 108626 | M21: 不相关
A22: 20 | B22: akku polsterreiniger | C22: 电池软垫清洁机 | D22: 2229 | E22: 104666
A23: 21 | B23: ambiano polsterreinigungsgerät | C23: 0 | D23: 2534 | E23: 91179
A24: 22 | B24: vivenso wasserstaubsauger - luftreiniger | C24: vivenso 水吸尘器 - 空气净化器 | D24: 2569 | E24: 89844 | M24: 不相关
A25: 23 | B25: milbenstaubsauger | C25: 除螨吸尘器 | D25: 2604 | E25: 88569 | M25: 不相关
A26: 24 | B26: couch reiniger | C26: 沙发清洁剂 | D26: 2609 | E26: 88374
A27: 25 | B27: couch reiniger gerät | C27: 沙发清洁设备 | D27: 2649 | E27: 86985
A28: 26 | B28: hoover milbensauger | C28: 胡佛除螨吸尘器 | D28: 2664 | E28: 86495
A29: 27 | B29: jimmy jv35 milbensauger | C29: 吉米 JV35 除螨吸尘器 | D29: 2814 | E29: 81546
A30: 28 | B30: polster und teppichreiniger gerät | C30: 垫子和地毯清洁设备 | D30: 2829 | E30: 81073 | M30: 强
A31: 29 | B31: vivenso | C31: 维文索 | D31: 2924 | E31: 78204
A32: 30 | B32: polstersauger | C32: 软垫吸尘器 | D32: 3069 | E32: 74278
A33: 31 | B33: hoover | C33: 胡佛 | D33: 3159 | E33: 72025
A34: 32 | B34: ryer nasssauger reinigung teppich und kauqe reinigung | C34: 0 | D34: 3184 | E34: 71407 | M34: 强
A35: 33 | B35: hyla staubsauger | C35: hyla 吸尘器 | D35: 3819 | E35: 58420
A36: 34 | B36: matratzenreiniger | C36: 床垫清洁剂 | D36: 3889 | E36: 57237 | M36: 强
A37: 35 | B37: sofa reiniger | C37: 沙发清洁剂 | D37: 4234 | E37: 52119
A38: 36 | B38: milbensauger mit uv licht | C38: 带紫外线的除螨吸尘器 | D38: 4514 | E38: 48570
A39: 37 | B39: nass trockensauger polsterreiniger | C39: 软垫清洁湿干两用吸尘器 | D39: 4759 | E39: 45832
A40: 38 | B40: milbenspray für matratzen | C40: 床垫用除螨喷雾 | D40: 4884 | E40: 44574
...

Sheet 2. 竞品拓词结果表
A1: milbensauger 关键词库 | Q1: 竞品拓词导出_2025-08-07 ASIN:B0DXKCZD5Z,B0DXQ34XZN,B0FHPRKP7F,B0F8VQ2Q6H,B0DJ9CSK63,B0F3JGRDBP,B0F32MV4J3,B0DJFMT6LS,B0CXCQR22Z,B0FCM61WRD,B0C1C73WS9,B0F187FF99,B0CDP5V9W8,B0DJ2YVV6F,B0DXPSYS1N,B0F2H6YTVS,B0F9W71RQQ,B0F7RDTSDF,B0F1YKY242,B0DCTPQLK2,B0F917NVW9,B0F9XTZDGW,B0CKVFMYH4,B0FFSTYXML,B0FH1K5PGW,B0D9NGRD9M,B0D45V1YXT,B0F484XM47
A2: # | B2: 关键词 | C2: 中文品名 | D2: 相关性-自动百分比 | E2: 相关性-自动 | F2: 自然位前4占位率 | G2: 自然位前8占位率 | H2: 自然位前16占位率 | I2: 自然位前32占位率 | J2: 自然位前48占位率 | K2: 搜索量 | L2: 排名 | M2: 流量大小 | N2: 相关性手动 | O2: 修饰词类型 | P2: 搜索转化率 | Q2: 搜索转化率 | R2: 360商品搜索量大小
A3: 1 | B3: jml go vac | C3: JML Go Vac吸尘器 | D3: 0.6173 | E3: 高相关 | F3: 0.7188 | G3: 0.5938 | H3: 0.4766 | I3: 0.4102 | J3: 0.3099 | K3: 1025 | L3: 43518 | M3: =K3 -> 1025 | N3: =E3 -> 高相关 | O3: 场景词 | P3: =VLOOKUP(B3,'附表-搜索转化率'!A:F,6,FALSE) -> #N/A | Q3: =IFERROR(P3,"-") -> - | R3: =IFERROR(VLOOKUP(B3,'附表-搜索转化率'!A:B,2,FALSE),"-") -> -
A4: 2 | B4: mini car hoover | C4: 迷你车吸尘器 | D4: 0.6092 | E4: 高相关 | F4: 0.75 | G4: 0.6094 | H4: 0.3438 | I4: 0.3047 | J4: 0.2995 | K4: 380 | L4: 125464 | M4: =K4 -> 380 | N4: =E4 -> 高相关 | O4: 产品词 | P4: =VLOOKUP(B4,'附表-搜索转化率'!A:F,6,FALSE) -> #N/A | Q4: =IFERROR(P4,"-") -> - | R4: =IFERROR(VLOOKUP(B4,'附表-搜索转化率'!A:B,2,FALSE),"-") -> -
A5: 3 | B5: mini vacuum cleaner cordless | C5: 迷你无绳吸尘器 | D5: 0.5826 | E5: 高相关 | F5: 0.7188 | G5: 0.4688 | H5: 0.4844 | I5: 0.3477 | J5: 0.3021 | K5: 1225 | L5: 36062 | M5: =K5 -> 1225 | N5: =E5 -> 高相关 | O5: 受众词 | P5: =VLOOKUP(B5,'附表-搜索转化率'!A:F,6,FALSE) -> 0.0196 | Q5: =IFERROR(P5,"-") -> 0.0196 | R5: =IFERROR(VLOOKUP(B5,'附表-搜索转化率'!A:B,2,FALSE),"-") -> 35791
A6: 4 | B6: car hoover cordless | C6: 无线汽车吸尘器 | D6: 0.5416 | E6: 高相关 | F6: 0.625 | G6: 0.5 | H6: 0.4453 | I6: 0.375 | J6: 0.3698 | K6: 503 | L6: 93422 | M6: =K6 -> 503 | N6: =E6 -> 高相关 | O6: 配件词 | P6: =VLOOKUP(B6,'附表-搜索转化率'!A:F,6,FALSE) -> #N/A | Q6: =IFERROR(P6,"-") -> - | R6: =IFERROR(VLOOKUP(B6,'附表-搜索转化率'!A:B,2,FALSE),"-") -> -
A7: 5 | B7: car vacuum | C7: 汽车吸尘器 | D7: 0.5381 | E7: 高相关 | F7: 0.5938 | G7: 0.5469 | H7: 0.4844 | I7: 0.332 | J7: 0.2865 | K7: 1825 | L7: 23157 | M7: =K7 -> 1825 | N7: =E7 -> 高相关 | O7: 尺寸词 | P7: =VLOOKUP(B7,'附表-搜索转化率'!A:F,6,FALSE) -> 0.0148 | Q7: =IFERROR(P7,"-") -> 0.0148 | R7: =IFERROR(VLOOKUP(B7,'附表-搜索转化率'!A:B,2,FALSE),"-") -> 109696
A8: 6 | B8: mini vacuum | C8: 迷你吸尘器 | D8: 0.5219 | E8: 高相关 | F8: 0.5625 | G8: 0.5625 | H8: 0.4922 | I8: 0.2734 | J8: 0.2344 | K8: 903 | L8: 49946 | M8: =K8 -> 903 | N8: =E8 -> 高相关 | O8: 尺寸词 | P8: =VLOOKUP(B8,'附表-搜索转化率'!A:F,6,FALSE) -> #N/A | Q8: =IFERROR(P8,"-") -> - | R8: =IFERROR(VLOOKUP(B8,'附表-搜索转化率'!A:B,2,FALSE),"-") -> -
A9: 7 | B9: cordless car vacuum cleaner | C9: 无线汽车吸尘器 | D9: 0.5205 | E9: 高相关 | F9: 0.5 | G9: 0.6094 | H9: 0.5547 | I9: 0.3594 | J9: 0.3281 | K9: 890 | L9: 50748 | M9: =K9 -> 890 | N9: =E9 -> 高相关 | O9: 无关词 | P9: =VLOOKUP(B9,'附表-搜索转化率'!A:F,6,FALSE) -> #N/A | Q9: =IFERROR(P9,"-") -> - | R9: =IFERROR(VLOOKUP(B9,'附表-搜索转化率'!A:B,2,FALSE),"-") -> -
A10: 8 | B10: car hoover powerful | C10: 强力汽车吸尘器 | D10: 0.5184 | E10: 高相关 | F10: 0.5 | G10: 0.5313 | H10: 0.6172 | I10: 0.457 | J10: 0.3672 | K10: 354 | L10: 134806 | M10: =K10 -> 354 | N10: =E10 -> 高相关 | O10: 不相关词 | P10: =VLOOKUP(B10,'附表-搜索转化率'!A:F,6,FALSE) -> #N/A | Q10: =IFERROR(P10,"-") -> - | R10: =IFERROR(VLOOKUP(B10,'附表-搜索转化率'!A:B,2,FALSE),"-") -> -
A11: 9 | B11: car vacuum cleaner cordless powerful | C11: 无线强力汽车吸尘器 | D11: 0.5161 | E11: 高相关 | F11: 0.5313 | G11: 0.5313 | H11: 0.5234 | I11: 0.4102 | J11: 0.3464 | K11: 1935 | L11: 21618 | M11: =K11 -> 1935 | N11: =E11 -> 高相关 | O11: NA | P11: =VLOOKUP(B11,'附表-搜索转化率'!A:F,6,FALSE) -> 0.0162 | Q11: =IFERROR(P11,"-") -> 0.0162 | R11: =IFERROR(VLOOKUP(B11,'附表-搜索转化率'!A:B,2,FALSE),"-") -> 68512
A12: 10 | B12: car hoovers cordless powerful | C12: 无线强力汽车吸尘器 | D12: 0.5154 | E12: 高相关 | F12: 0.5313 | G12: 0.4844 | H12: 0.5703 | I12: 0.4609 | J12: 0.362 | K12: 3161 | L12: 12203 | M12: =K12 -> 3161 | N12: =E12 -> 高相关 | O12: 功能词 | P12: =VLOOKUP(B12,'附表-搜索转化率'!A:F,6,FALSE) -> 0.0275 | Q12: =IFERROR(P12,"-") -> 0.0275 | R12: =IFERROR(VLOOKUP(B12,'附表-搜索转化率'!A:B,2,FALSE),"-") -> 133015
A13: 11 | B13: mini vacuum cleaner | C13: 迷你吸尘器 | D13: 0.4978 | E13: 中相关 | F13: 0.5 | G13: 0.5469 | H13: 0.4922 | I13: 0.3828 | J13: 0.349 | K13: 683 | L13: 67422 | M13: =K13 -> 683 | N13: =E13 -> 中相关 | O13: 尺寸词 | P13: =VLOOKUP(B13,'附表-搜索转化率'!A:F,6,FALSE) -> #N/A | Q13: =IFERROR(P13,"-") -> - | R13: =IFERROR(VLOOKUP(B13,'附表-搜索转化率'!A:B,2,FALSE),"-") -> -
A14: 12 | B14: car vacuum cleaner | C14: 车用吸尘器 | D14: 0.4955 | E14: 中相关 | F14: 0.5313 | G14: 0.5 | H14: 0.4531 | I14: 0.3906 | J14: 0.3177 | K14: 9851 | L14: 2688 | M14: =K14 -> 9851 | N14: =E14 -> 中相关 | O14: 不相关词 | P14: =VLOOKUP(B14,'附表-搜索转化率'!A:F,6,FALSE) -> 0.0146 | Q14: =IFERROR(P14,"-") -> 0.0146 | R14: =IFERROR(VLOOKUP(B14,'附表-搜索转化率'!A:B,2,FALSE),"-") -> 455206
... A29: 27 | B29: small vacuum | C29: 小型吸尘器 | D29: 0.3012 | E29: 中相关 | F29: 0.3125 | G29: 0.3438 | H29: 0.2266 | I29: 0.2539 | J29: 0.2422 | K29: 393 | L29: 121159 | M29: =K29 -> 393 | N29: =E29 -> 中相关 | O29: 尺寸词 | P29: =VLOOKUP(B29,'附表-搜索转化率'!A:F,6,FALSE) -> #N/A | Q29: =IFERROR(P29,"-") -> - | R29: =IFERROR(VLOOKUP(B29,'附表-搜索转化率'!A:B,2,FALSE),"-") -> -
A30: 28 | B30: portable hoover | C30: 便携式吸尘器 | D30: 0.2994 | E30: 中相关 | F30: 0.25 | G30: 0.3438 | H30: 0.3828 | I30: 0.3242 | J30: 0.2786 | K30: 845 | L30: 53677 | M30: =K30 -> 845 | N30: =E30 -> 中相关 | P30: =VLOOKUP(B30,'附表-搜索转化率'!A:F,6,FALSE) -> #N/A | Q30: =IFERROR(P30,"-") -> - | R30: =IFERROR(VLOOKUP(B30,'附表-搜索转化率'!A:B,2,FALSE),"-") -> -
A31: 29 | B31: hand held hoovers cordless | C31: 无线手持吸尘器 | D31: 0.2888 | E31: 中相关 | F31: 0.25 | G31: 0.3594 | H31: 0.3203 | I31: 0.2656 | J31: 0.2448 | K31: 1045 | L31: 42673 | M31: =K31 -> 1045 | N31: =E31 -> 中相关 | P31: =VLOOKUP(B31,'附表-搜索转化率'!A:F,6,FALSE) -> #N/A | Q31: =IFERROR(P31,"-") -> - | R31: =IFERROR(VLOOKUP(B31,'附表-搜索转化率'!A:B,2,FALSE),"-") -> -
A32: 30 | B32: handheld hoover cordless | C32: 无线手持式吸尘器 | D32: 0.2573 | E32: 中相关 | F32: 0.2188 | G32: 0.3125 | H32: 0.3125 | I32: 0.2344 | J32: 0.2161 | K32: 683 | L32: 67422 | M32: =K32 -> 683 | N32: =E32 -> 中相关 | P32: =VLOOKUP(B32,'附表-搜索转化率'!A:F,6,FALSE) -> #N/A | Q32: =IFERROR(P32,"-") -> - | R32: =IFERROR(VLOOKUP(B32,'附表-搜索转化率'!A:B,2,FALSE),"-") -> -
A33: 31 | B33: hand held hoover | C33: 手持吸尘器 | D33: 0.2468 | E33: 中相关 | F33: 0.2188 | G33: 0.2813 | H33: 0.2891 | I33: 0.2461 | J33: 0.2187 | K33: 1922 | L33: 21781 | M33: =K33 -> 1922 | N33: =E33 -> 中相关 | O33: 尺寸词 | P33: =VLOOKUP(B33,'附表-搜索转化率'!A:F,6,FALSE) -> 0.0248 | Q33: =IFERROR(P33,"-") -> 0.0248 | R33: =IFERROR(VLOOKUP(B33,'附表-搜索转化率'!A:B,2,FALSE),"-") -> 75659
A34: 32 | B34: portable vacuum cleaner | C34: 便携式吸尘器 | D34: 0.2318 | E34: 中相关 | F34: 0.0938 | G34: 0.3438 | H34: 0.4219 | I34: 0.3594 | J34: 0.3516 | K34: 432 | L34: 109761 | M34: =K34 -> 432 | N34: =E34 -> 中相关 | P34: =VLOOKUP(B34,'附表-搜索转化率'!A:F,6,FALSE) -> #N/A | Q34: =IFERROR(P34,"-") -> - | R34: =IFERROR(VLOOKUP(B34,'附表-搜索转化率'!A:B,2,FALSE),"-") -> -
A35: 33 | B35: handheld hoover | C35: 手持式吸尘器 | D35: 0.2195 | E35: 中相关 | F35: 0.125 | G35: 0.3438 | H35: 0.2969 | I35: 0.2656 | J35: 0.263 | K35: 3148 | L35: 12264 | M35: =K35 -> 3148 | N35: =E35 -> 中相关 | O35: 尺寸词 | P35: =VLOOKUP(B35,'附表-搜索转化率'!A:F,6,FALSE) -> 0.0243 | Q35: =IFERROR(P35,"-") -> 0.0243 | R35: =IFERROR(VLOOKUP(B35,'附表-搜索转化率'!A:B,2,FALSE),"-") -> 109751
A36: 34 | B36: handheld vacuum | C36: 手持吸尘器 | D36: 0.217 | E36: 中相关 | F36: 0.2188 | G36: 0.25 | H36: 0.1797 | I36: 0.1797 | J36: 0.1875 | K36: 1561 | L36: 27634 | M36: =K36 -> 1561 | N36: =E36 -> 中相关 | P36: =VLOOKUP(B36,'附表-搜索转化率'!A:F,6,FALSE) -> 0.0143 | Q36: =IFERROR(P36,"-") -> 0.0143 | R36: =IFERROR(VLOOKUP(B36,'附表-搜索转化率'!A:B,2,FALSE),"-") -> 83977
A37: 35 | B37: handheld vacuums | C37: 手持吸尘器 | D37: 0.2126 | E37: 中相关 | F37: 0.1875 | G37: 0.2344 | H37: 0.2656 | I37: 0.1992 | J37: 0.2161 | K37: 1787 | L37: 23757 | M37: =K37 -> 1787 | N37: =E37 -> 中相关 | P37: =VLOOKUP(B37,'附表-搜索转化率'!A:F,6,FALSE) -> 0.0082 | Q37: =IFERROR(P37,"-") -> 0.0082 | R37: =IFERROR(VLOOKUP(B37,'附表-搜索转化率'!A:B,2,FALSE),"-") -> 100456
A38: 36 | B38: handheld vacuum cleaner cordless | C38: 手持吸尘器无线 | D38: 0.201 | E38: 中相关 | F38: 0.125 | G38: 0.25 | H38: 0.2969 | I38: 0.3164 | J38: 0.3099 | K38: 1277 | L38: 34452 | M38: =K38 -> 1277 | N38: =E38 -> 中相关 | P38: =VLOOKUP(B38,'附表-搜索转化率'!A:F,6,FALSE) -> 0.0172 | Q38: =IFERROR(P38,"-") -> 0.0172 | R38: =IFERROR(VLOOKUP(B38,'附表-搜索转化率'!A:B,2,FALSE),"-") -> 38290
A39: 37 | B39: handheld vacuum cleaner | C39: 手持吸尘器 | D39: 0.191 | E39: 低相关 | F39: 0.125 | G39: 0.2344 | H39: 0.2969 | I39: 0.2617 | J39: 0.2344 | K39: 9677 | L39: 2772 | M39: =K39 -> 9677 | N39: =E39 -> 低相关 | P39: =VLOOKUP(B39,'附表-搜索转化率'!A:F,6,FALSE) -> 0.0197 | Q39: =IFERROR(P39,"-") -> 0.0197 | R39: =IFERROR(VLOOKUP(B39,'附表-搜索转化率'!A:B,2,FALSE),"-") -> 717259
A40: 38 | B40: hand vacuum cleaner cordless | C40: 无线手持吸尘器 | D40: 0.1846 | E40: 低相关 | F40: 0.125 | G40: 0.2656 | H40: 0.2188 | I40: 0.2461 | J40: 0.1901 | K40: 1187 | L40: 37323 | M40: =K40 -> 1187 | N40: =E40 -> 低相关 | P40: =VLOOKUP(B40,'附表-搜索转化率'!A:F,6,FALSE) -> 0.0245 | Q40: =IFERROR(P40,"-") -> 0.0245 | R40: =IFERROR(VLOOKUP(B40,'附表-搜索转化率'!A:B,2,FALSE),"-") -> 53076
A41: 39 | B41: hand held vacuum cordless | C41: 无线手持吸尘器 | D41: 0.1748 | E41: 低相关 | F41: 0.1563 | G41: 0.1719 | H41: 0.2031 | I41: 0.2188 | J41: 0.2656 | K41: 6670 | L41: 4697 | M41: =K41 -> 6670 | N41: =E41 -> 低相关 | P41: =VLOOKUP(B41,'附表-搜索转化率'!A:F,6,FALSE) -> 0.022 | Q41: =IFERROR(P41,"-") -> 0.022 | R41: =IFERROR(VLOOKUP(B41,'附表-搜索转化率'!A:B,2,FALSE),"-") -> 410982
A42: 40 | B42: cordless handheld vacuum cleaner | C42: 无线手持吸尘器 | D42: 0.1744 | E42: 低相关 | F42: 0.0938 | G42: 0.2188 | H42: 0.2969 | I42: 0.293 | J42: 0.2604 | K42: 819 | L42: 55576 | M42: =K42 -> 819 | N42: =E42 -> 低相关 | P42: =VLOOKUP(B42,'附表-搜索转化率'!A:F,6,FALSE) -> #N/A | Q42: =IFERROR(P42,"-") -> - | R42: =IFERROR(VLOOKUP(B42,'附表-搜索转化率'!A:B,2,FALSE),"-") -> -
A43: 41 | B43: car gadget | C43: 汽车小工具 | D43: 0.1684 | E43: 低相关 | F43: 0.25 | G43: 0.125 | H43: 0.0625 | I43: 0.0313 | J43: 0.0208 | K43: 0 | L43: 0 | M43: =K43 -> 0 | N43: =E43 -> 低相关 | P43: =VLOOKUP(B43,'附表-搜索转化率'!A:F,6,FALSE) -> #N/A | Q43: =IFERROR(P43,"-") -> - | R43: =IFERROR(VLOOKUP(B43,'附表-搜索转化率'!A:B,2,FALSE),"-") -> -
A44: 42 | B44: cordless vacuum cleaner handheld | C44: 无线手持吸尘器 | D44: 0.163 | E44: 低相关 | F44: 0.0313 | G44: 0.2344 | H44: 0.4063 | I44: 0.2813 | J44: 0.2734 | K44: 458 | L44: 103225 | M44: =K44 -> 458 | N44: =E44 -> 低相关 | P44: =VLOOKUP(B44,'附表-搜索转化率'!A:F,6,FALSE) -> #N/A | Q44: =IFERROR(P44,"-") -> - | R44: =IFERROR(VLOOKUP(B44,'附表-搜索转化率'!A:B,2,FALSE),"-") -> -
A45: 43 | B45: handheld cordless vacuum cleaner | C45: 手持无线吸尘器 | D45: 0.1589 | E45: 低相关 | F45: 0.0938 | G45: 0.1875 | H45: 0.2813 | I45: 0.2383 | J45: 0.2083 | K45: 380 | L45: 125464 | M45: =K45 -> 380 | N45: =E45 -> 低相关 | P45: =VLOOKUP(B45,'附表-搜索转化率'!A:F,6,FALSE) -> #N/A | Q45: =IFERROR(P45,"-") -> - | R45: =IFERROR(VLOOKUP(B45,'附表-搜索转化率'!A:B,2,FALSE),"-") -> -
A46: 44 | B46: hand held vacuum | C46: 手持吸尘器 | D46: 0.1528 | E46: 低相关 | F46: 0.0625 | G46: 0.2656 | H46: 0.1875 | I46: 0.2813 | J46: 0.2448 | K46: 825 | L46: 55108 | M46: =K46 -> 825 | N46: =E46 -> 低相关 | P46: =VLOOKUP(B46,'附表-搜索转化率'!A:F,6,FALSE) -> 0.0172 | Q46: =IFERROR(P46,"-") -> 0.0172 | R46: =IFERROR(VLOOKUP(B46,'附表-搜索转化率'!A:B,2,FALSE),"-") -> 52249
A47: 45 | B47: cordless car vacuum cleaners | C47: 无线汽车吸尘器 | D47: 0.1366 | E47: 低相关 | F47: 0.1563 | G47: 0.125 | H47: 0.1172 | I47: 0.1016 | J47: 0.0833 | K47: 387 | L47: 123268 | M47: =K47 -> 387 | N47: =E47 -> 低相关 | P47: =VLOOKUP(B47,'附表-搜索转化率'!A:F,6,FALSE) -> #N/A | Q47: =IFERROR(P47,"-") -> - | R47: =IFERROR(VLOOKUP(B47,'附表-搜索转化率'!A:B,2,FALSE),"-") -> -
... A64: 62 | B64: powerful car vacuum cleaner | C64: 强大的车载吸尘器 | D64: 0.0684 | E64: 低相关 | F64: 0.0625 | G64: 0.0781 | H64: 0.0781 | I64: 0.0625 | J64: 0.0495 | K64: 212 | L64: 225855 | M64: =K64 -> 212 | N64: =E64 -> 低相关 | P64: =VLOOKUP(B64,'附表-搜索转化率'!A:F,6,FALSE) -> #N/A | Q64: =IFERROR(P64,"-") -> - | R64: =IFERROR(VLOOKUP(B64,'附表-搜索转化率'!A:B,2,FALSE),"-") -> -
A65: 63 | B65: d80 pro car vacuum cleaner | D65: 0.0666 | E65: 低相关 | F65: 0.0625 | G65: 0.0781 | H65: 0.0703 | I65: 0.0547 | J65: 0.0469 | K65: 335 | L65: 142827 | M65: =K65 -> 335 | N65: =E65 -> 低相关 | P65: =VLOOKUP(B65,'附表-搜索转化率'!A:F,6,FALSE) -> #N/A | Q65: =IFERROR(P65,"-") -> - | R65: =IFERROR(VLOOKUP(B65,'附表-搜索转化率'!A:B,2,FALSE),"-") -> -
A66: 64 | B66: cordless car hoover | C66: 无线汽车吸尘器 | D66: 0.0627 | E66: 低相关 | F66: 0.0625 | G66: 0.0625 | H66: 0.0703 | I66: 0.0547 | J66: 0.0495 | K66: 187 | L66: 255329 | M66: =K66 -> 187 | N66: =E66 -> 低相关 | P66: =VLOOKUP(B66,'附表-搜索转化率'!A:F,6,FALSE) -> #N/A | Q66: =IFERROR(P66,"-") -> - | R66: =IFERROR(VLOOKUP(B66,'附表-搜索转化率'!A:B,2,FALSE),"-") -> -
A67: 65 | B67: handheld hoover for car | C67: 车用手持式吸尘器 | D67: 0.0618 | E67: 低相关 | F67: 0.0625 | G67: 0.0625 | H67: 0.0625 | I67: 0.0547 | J67: 0.0573 | K67: 193 | L67: 247222 | M67: =K67 -> 193 | N67: =E67 -> 低相关 | P67: =VLOOKUP(B67,'附表-搜索转化率'!A:F,6,FALSE) -> #N/A | Q67: =IFERROR(P67,"-") -> - | R67: =IFERROR(VLOOKUP(B67,'附表-搜索转化率'!A:B,2,FALSE),"-") -> -
A68: 66 | B68: portable car hoover | C68: 便携式车用吸尘器 | D68: 0.0616 | E68: 低相关 | F68: 0.0625 | G68: 0.0625 | H68: 0.0625 | I68: 0.0547 | J68: 0.0495 | K68: 187 | L68: 255329 | M68: =K68 -> 187 | N68: =E68 -> 低相关 | P68: =VLOOKUP(B68,'附表-搜索转化率'!A:F,6,FALSE) -> #N/A | Q68: =IFERROR(P68,"-") -> - | R68: =IFERROR(VLOOKUP(B68,'附表-搜索转化率'!A:B,2,FALSE),"-") -> -
A69: 67 | B69: car hoovers | C69: 汽车吸尘器 | D69: 0.0613 | E69: 低相关 | F69: 0.0625 | G69: 0.0625 | H69: 0.0625 | I69: 0.0508 | J69: 0.0495 | K69: 212 | L69: 225855 | M69: =K69 -> 212 | N69: =E69 -> 低相关 | P69: =VLOOKUP(B69,'附表-搜索转化率'!A:F,6,FALSE) -> #N/A | Q69: =IFERROR(P69,"-") -> - | R69: =IFERROR(VLOOKUP(B69,'附表-搜索转化率'!A:B,2,FALSE),"-") -> -
A70: 68 | B70: car vacuum cleaner high power | C70: 高功率汽车吸尘器 | D70: 0.0604 | E70: 低相关 | F70: 0.0625 | G70: 0.0625 | H70: 0.0547 | I70: 0.0547 | J70: 0.0495 | K70: 180 | L70: 263780 | M70: =K70 -> 180 | N70: =E70 -> 低相关 | P70: =VLOOKUP(B70,'附表-搜索转化率'!A:F,6,FALSE) -> #N/A | Q70: =IFERROR(P70,"-") -> - | R70: =IFERROR(VLOOKUP(B70,'附表-搜索转化率'!A:B,2,FALSE),"-") -> -
...

Sheet 3.词频统计完成
B1: 3.词根统计表
A2: 1个单词词根 | G2: 2个单词词根 | M2: 3个单词词根
A3: # | B3: 单词 | C3: 单词翻译 | D3: 出现次数词频 | E3: 搜索量加权词频 (亚马逊官方方法) | G3: # | H3: 单词 | I3: 单词翻译 | J3: 出现次数词频 | K3: 搜索量加权词频(亚马逊官方方法) | M3: # | N3: 单词 | O3: 单词翻译 | P3: 出现次数词频 | Q3: 搜索量加权词频(亚马逊官方方法)
A4: 词语 | B4: 词频 | C4: 一级分类 | D4: 二级分类 | E4: 用户搜索意图标签 | F4: 否定
A5: vacuum | B5: 597 | C5: 功能词 | D5: 电力 | E5: 电力驱动
A6: cleaner | B6: 392 | C6: 属性词 | D6: 便携性 | E6: 便携
A7: car | B7: 255 | C7: 品名词 | D7: 电池包 | E7: 电池包
A8: handheld | B8: 186 | C8: 功能词 | D8: 充电器 | E8: 充电器
A9: cordless | B9: 183 | C9: 品名词 | D9: 电池 | E9: 电池
A10: hoover | B10: 123 | C10: 功能词 | D10: 太阳能 | E10: 太阳能
A11: blower | B11: 87 | C11: 品名词 | D11: 电源站 | E11: 电源站 | F11: X
A12: shark | B12: 71 | C12: 品名词 | D12: 发电机 | E12: 发电机 | F12: X
A13: hand | B13: 70 | C13: 品名词 | D13: 手机
A14: air | B14: 64 | C14: 品名词 | D14: 手机
A15: mini | B15: 60 | C15: 场景词 | D15: 露营 | E15: 户外
A16: held | B16: 53 | C16: 属性词 | D16: 包装
A17: dust | B17: 46 | C17: 品牌词
A18: portable | B18: 45 | C18: 场景词 | D18: 家庭 | E18: 家庭
A19: duster | B19: 39 | C19: 品牌词
A20: cleaners | B20: 31 | C20: 功能词 | D20: 充电 | E20: 充电 | F20: X
A21: powerful | B21: 29 | C21: 品名词 | D21: 发电机 | E21: 发电机
A22: accessories | B22: 27 | C22: 品牌词
A23: small | B23: 25 | C23: 功能词 | D23: 面板 | E23: 太阳能面板
A24: cleaning | B24: 24 | C24: 功能词 | D24: 备份 | E24: 备份
A25: pet | B25: 23 | C25: 功能词 | D25: USB接口 | F25: X
A26: vac | B26: 23 | C26: 功能词 | D26: 电源插座 | E26: 电源插座 | F26: X
A27: kit | B27: 21 | C27: 功能词 | D27: 电力驱动 | E27: 电力驱动
A28: power | B28: 19 | C28: 属性词 | D28: 快速
A29: vacuums | B29: 18 | C29: 品名词 | D29: 专业版 | E29: 专业版
A30: dyson | B30: 17 | C30: 功能词 | D30: 供电 | E30: 备份 | F30: X
A31: pro | B31: 17 | C31: 品牌词
A32: suction | B32: 16 | C32: 场景词 | D32: 用途
A33: high | B33: 15 | C33: 品牌词
A34: rechargeable | B34: 15 | C34: 品名词 | D34: 电池单元
A35: desk | B35: 14 | C35: 功能词 | D35: 交流电 | E35: 交流电
A36: home | B36: 14 | C36: 品牌词
A37: dryer | B37: 13 | C37: 场景词 | D37: 呼吸机
A38: wireless | B38: 13 | C38: 功能词 | D38: 逆变器 | E38: 电力驱动
A39: brush | B39: 12 | C39: 品名词 | D39: 充电器 | E39: 充电器 | F39: X
A40: compressed | B40: 12 | C40: 功能词 | D40: 功率单位
...

Sheet 4.标题怎么写
A1: 标题 | B1: asin | C1: 内容
A2: 标题1 | D2: 选出优秀竞品10个标题结合词频统计
A3: 标题2
A4: 标题3
A5: 标题4
A6: 标题5
A7: 标题6
A8: 标题7
A9: 标题8
A10: 标题9
A11: 标题10
A13: 标题OK | B13: 标题
AG16: 德语 | AL16: 中文 | AP16: 英语
AL17: 直译 | AP17: 直译
A18: 卖点1 | P18: Robust Suction: This mattress vacuum boasts a powerful 15Kpa suction capability, capable of reaching deep into the mattress to eliminate even the tiniest dust particles and mites. | AG18: Schauen wir uns einmal die Geräte speks an: | AL18: 让我们来看一下这些设备的规格： | AP18: Let's take a look at the device specifications:
A19: 卖点2 | P19: UV Disinfection: Fitted with 273nm UV light, it effectively eradicates bacteria and viruses that have seeped into your mattress, ensuring meticulous hygiene and a refreshing sleep environment. | AG19: 👍 15 Kpa starke Saugleistung für eine gründliche Tiegenreinigung | AL19: 👍 15 Kpa 强大的吸力，用于彻底的深度清洁 | AP19: 👍 15 Kpa strong suction for thorough deep cleaning
A20: 卖点3 | P20: Ultrasonic Cleaning: Utilizing a 55KHz frequency, the ultrasonic feature aids in destroying minuscule mites and grime, resulting in a comprehensive mattress cleaning. | AG20: 👍 400 Watt Leistungsaufnahme | AL20: 👍 400 瓦的功率消耗 | AP20: 👍 400 Watt power consumption
A21: 卖点4 | P21: HEPA Filtration for Optimal Air Quality: The built-in HEPA filter traps up to 99.92% of airborne particles, preventing harmful allergens from re-entering your space. | AG21: 👍 Motordrehzal von 3000 U/min | AL21: 👍 电动机转速为3000转/分钟 | AP21: 👍 Motor speed of 3000 U/min
A22: 卖点5 | P22: Wide Cleaning Reach: Equipped with a 214mm wide suction head, it allows for quick and efficient cleaning of extensive mattress areas, cutting down on cleaning time. | AG22: 👍 UV-C Licht (273,7 nm) für eine gründliche Desinfektion gegen Bakterien und Viren. | AL22: 👍 UV-C 光（273.7 nm），用于对细菌和病毒进行彻底消毒。 | AP22: 👍 UV-C light (273.7 nm) for thorough disinfection against bacteria and viruses.
A23: 卖点6 | P23: User-Friendly and Adaptable: The vacuum's 4m cord and mere 2.3 kg weight ensure easy maneuverability, making it suitable for cleaning various surfaces including mattresses, pillows, and upholstery. | AG23: 👍 Ultraschalltechnologie: Mit einer Frequenz von 50KHz. Zerstört Mikroskopisch kleine Milben und Schmutzpartikel für eine gute Tiefenreinigung. | AL23: 👍 超声波技术：频率为50KHz。破坏显微镜下可见的微小螨虫和污垢颗粒，实现良好的深度清洁。 | AP23: 👍 Ultrasound technology: With a frequency of 50KHz. Destroys microscopic small mites and dirt particles for good deep cleaning.
AG24: 👍 60° Heißlufttechnik entfernt Feuchtigkeit | AL24: 👍 60° 热空气技术去除湿度 | AP24: 👍 60° hot air technology removes moisture
A25: 标题 | AG25: 👍 HEPA Filter filtert 99.92 % der Staubpartikel aus der Luft | AL25: 👍 HEPA 过滤器过滤掉空气中99.92%的尘埃颗粒 | AP25: 👍 HEPA filter filters 99.92% of dust particles from the air
A26: 卖点1 | AG26: 👍 214 mm großer Saugkopf für eine schnelle Reinigung | AL26: 👍 214毫米宽的吸头，用于快速清洁 | AP26: 👍 214 mm large suction head for quick cleaning
A27: 卖点2 | AG27: 👍 4 Meter langes Kabel für eine flexible Reinigung | AL27: 👍 4米长的电缆，用于灵活的清洁 | AP27: 👍 4 meters long cable for flexible cleaning
A28: 卖点3 | AG28: 👍 Gewicht 2.3 Kg | AL28: 👍 重量为2.3公斤 | AP28: 👍 Weight 2.3 Kg
A29: 卖点4
A30: 卖点5
A31: 卖点6
A33: 评论内容：
A34: 评论1
A35: 评论1
A36: 评论1
A37: 评论1
A38: 评论1
A39: 评论1
A40: 评论1
A41: 评论1
... A67: 买家图

Sheet 5.ASIN表
CP1: 搜索词 | CQ1: 搜索量（过去 360 天） | CR1: 搜索量增长（过去 90 天） | CS1: 搜索量增长（过去 180 天） | CT1: 点击份额（过去 360 天） | CU1: 搜索转化率（过去 360 天） | CV1: 点击率最高的商品1（标题） | CW1: 点击率最高的商品1 (ASIN) | CX1: 点击率最高的商品2（标题） | CY1: 点击率最高的商品2 (ASIN) | CZ1: 点击率最高的商品3（标题） | DA1: 点击率最高的商品3 (ASIN) | DB1: ASIN | DC1: 前台售价 | DD1: 日销量 | DE1: BSR | DF1: 近30天销量（子体） | DG1: 近30天销量（父体） | DH1: 优惠券 | DI1: 备注 | DJ1: 大类BSR | DK1: 小类BSR | DL1: 月销量 | DM1: 子体销量 | DN1: 子体销售额(£) | DO1: 价格(£) | DP1: 商品标题
A2: 图片 | B2: 是否同类 | C2: ASIN | D2: 品牌 | E2: 类目路径 | F2: 大类目 | G2: 大类BSR | H2: 小类目 | I2: 小类BSR | J2: 近30天销量 | K2: 价格($) | L2: Prime价格($) | M2: FBA($) | N2: 评分 | O2: 评分数 | P2: 留评率 | Q2: 变体数 | R2: 图片 | S2: ASIN | T2: SKU | U2: 详细参数 | V2: 品牌 | W2: 品牌链接 | X2: 商品标题 | Y2: 标题(翻译) | Z2: 产品卖点 | AA2: 产品卖点(翻译) | AB2: 商品详情页链接 | AC2: 商品主图 | AD2: 父ASIN | AE2: 类目路径 | AF2: 大类目 | AG2: 大类BSR | AH2: 大类BSR增长数 | AI2: 大类BSR增长率 | AJ2: 小类目 | AK2: 小类BSR | AL2: 月销量 | AM2: 月销量增长率 | AN2: 月销售额(€) | AO2: 子体销量 | AP2: 子体销售额(€) | AQ2: 变体数 | AR2: 价格(€) | AS2: Prime价格(€) | AT2: Coupon | AU2: Q&A数 | AV2: 评分数 | AW2: 月新增 评分数 | AX2: 评分 | AY2: 留评率 | AZ2: FBA(€) | BA2: 毛利率 | BB2: 评级 | BC2: 上架时间 | BD2: 上架天数 | BE2: 配送方式 | BF2: LQS | BG2: 卖家数 | BH2: Buybox卖家 | BI2: BuyBox类型 | BJ2: 卖家所属地 | BK2: 卖家信息 | BL2: 卖家首页 | BM2: Best Seller标识 | BN2: Amazon's Choice | BO2: New Release标识 | BP2: A+页面 | BQ2: 视频介绍 | BR2: SP广告 | BS2: 品牌故事 | BT2: 品牌广告 | BU2: 7天促销 | BV2: AC关键词 | BW2: 重量 | BX2: 重量 | BY2: 体积 | BZ2: 体积 | CA2: 包装重量 | CB2: 包装体积 | CP2: handheld vacuum cleaner | CQ2: 717259 | CR2: -0.0715 | CS2: -0.1965 | CT2: 0.2138 | CU2: 0.0197 | CV2: Shark Handheld Cordless Vacuum Cleaner with Pet Tool Crevice Tool & Dusting Brush 80 W 0.45 liters 10 Minute Run-Time Washable Filter Black & Yellow CH950UKT | CW2: B08M9JQ1J1 | CX2: Handheld Vacuum Cleaner Powerful Suction Portable Lightweight Hand Held Vacuum Cordless with 25-30Mins Long Runtime Rechargeable Battery Quick Charge for Home Car Carpet Stairs Pet Hair Cleaning | CY2: B09VKPHJVF | CZ2: Higoom 4 in 1 Cordless Handheld Vacuum Cleaner Car Vacuum Cleaner 22000PA Strong Suction Mini Vacuum Dust Blower Can be Used for Home Car | DA2: B0DJFMT6LS | DB2: B0F3JGRDBP | DC2: 25.49 | DD2: 83.7 | DE2: 2 | DF2: 2000 | DG2: 2511 | DJ2: 523 | DK2: 2 | DL2: 2511 | DM2: 2000 | DN2: 50980 | DO2: 25.49 | DP2: Handheld Vacuum Cleaner, 22000Pa Cordless Car Vacuum Cleaner, 3 Speed Brushless Motor Mini Hoover with Multiple Brush HeadsHigh Power Hand Held Vacuum Cordless, for Office, Home Kitchen, Car,Pet Hair
B3: 否 | C3: B003TFE7ZM | D3: Flexzilla | E3: Patio, Lawn & Garden:Gardening & Lawn Care:Watering Equipment:Garden Hoses | F3: Patio, Lawn & Garden | G3: 10 | H3: Garden Hoses | I3: 1 | J3: 37379 | K3: 39.97 | M3: 8.77 | N3: 4.5 | O3: 75158 | P3: 0.0361 | Q3: 15 | CP3: car vacuum cleaner | CQ3: 455206 | CR3: 0.0195 | CS3: -0.1366 | CT3: 0.148 | CU3: 0.0146 | CV3: Ginarelo Handheld Cordless Car Vacuum Cleaner - 4000Pa Small Hand Held Vacuums Cleaners Strong Suction Powerful Portable Wireless Lightweight Mini Long Runtime Hand-held Vaccum USB Vacum Blower | CW3: B0DB5VMBTC | CX3: Higoom 4 in 1 Cordless Handheld Vacuum Cleaner Car Vacuum Cleaner 22000PA Strong Suction Mini Vacuum Dust Blower Can be Used for Home Car | CY3: B0DJFMT6LS | CZ3: Wirelume Handheld Car Vacuum Cleaner Cordless Powerful 22000Pa Strong Cyclonic Suction Blowing Brushless Motor Mini Hand Held Portable Rechargeable Lightweight for Pet Hair Vehicle Home Office Purple | DA3: B0D45V1YXT | DB3: B0DJ2YVV6F | DC3: 21.24 | DD3: 64.166667 | DE3: 12 | DF3: 1000 | DG3: 1925 | DJ3: 2315 | DK3: 12 | DL3: 1925 | DM3: 1000 | DN3: 25990 | DO3: 21.24 | DP3: Nctoberows Handheld Vacuum Cleaner Cordless, 22000Pa Powerful Car Mini Vacuum Cleaner, Rechargeable Portable Lightweight dust catcher for Home Car Carpet Stairs Pet Hair Deep Cleaning
CP4: hand held vacuum cordless | CQ4: 410982 | CR4: -0.1937 | CS4: -0.1952 | CT4: 0.1142 | CU4: 0.022 | CV4: Shark Handheld Cordless Vacuum Cleaner with Pet Tool Crevice Tool & Dusting Brush 80 W 0.45 liters 10 Minute Run-Time Washable Filter Black & Yellow CH950UKT | CW4: B08M9JQ1J1 | CX4: Vax Gator Cordless Handheld Vacuum Cleaner | Lightweight Quick Cleaning | Built-in Crevice Tool - H85-GA-B10 0.3 Litre White and Orange | CY4: B015QZH2EU | CZ4: Handheld Vacuum Cleaner Powerful Suction Portable Lightweight Hand Held Vacuum Cordless with 25-30Mins Long Runtime Rechargeable Battery Quick Charge for Home Car Carpet Stairs Pet Hair Cleaning | DA4: B09VKPHJVF | DB4: B0D45V1YXT | DC4: 25.49 | DD4: 42.233333 | DE4: 13 | DF4: 600 | DG4: 1267 | DJ4: 3218 | DK4: 13 | DL4: 1267 | DM4: 600 | DN4: 15294 | DO4: 25.49 | DP4: Wirelume Handheld Car Vacuum Cleaner Cordless Powerful 22000Pa Strong Cyclonic Suction Blowing Brushless Motor Mini Hand Held Portable Rechargeable Lightweight for Pet Hair Vehicle Home Office Purple
CP5: car hoover | CQ5: 320576 | CR5: -0.0656 | CS5: -0.1624 | CT5: 0.107 | CU5: 0.0233 | CV5: Handheld Vacuum Cleaner Powerful Suction Portable Lightweight Hand Held Vacuum Cordless with 25-30Mins Long Runtime Rechargeable Battery Quick Charge for Home Car Carpet Stairs Pet Hair Cleaning | CW5: B09VKPHJVF | CX5: Handheld Vacuum Cordless 9000Pa Powerful Car Vacuum Cleaner Rechargeable Portable Lightweight Mini Vacuum Cleaner USB Car Vacuum Cleaner Car Cleaner for Pet Hair Car Home Office Kitchen | CY5: B0CKVFMYH4 | CZ5: Nctoberows Handheld Vacuum Cleaner Cordless 22000Pa Powerful Car Mini Vacuum Cleaner Rechargeable Portable Lightweight dust catcher for Home Car Carpet Stairs Pet Hair Deep Cleaning | DA5: B0DJ2YVV6F | DB5: B0CKVFMYH4 | DC5: 22.55 | DD5: 37.066667 | DE5: 14 | DF5: 900 | DG5: 1112 | DJ5: 3508 | DK5: 14 | DL5: 1112 | DM5: 900 | DN5: 20295 | DO5: 22.55 | DP5: Handheld Vacuum Cordless, 9000Pa Powerful Car Vacuum Cleaner, Rechargeable Portable Lightweight Mini Vacuum Cleaner, USB Car Vacuum Cleaner Car Cleaner for Pet Hair, Car, Home, Office, Kitchen
CP6: car vacuum cleaner cordless | CQ6: 190272 | CR6: 0.1062 | CS6: -0.1319 | CT6: 0.0734 | CU6: 0.0194 | CV6: Ginarelo Handheld Cordless Car Vacuum Cleaner - 4000Pa Small Hand Held Vacuums Cleaners Strong Suction Powerful Portable Wireless Lightweight Mini Long Runtime Hand-held Vaccum USB Vacum Blower | CW6: B0DB5VMBTC | CX6: Handheld Vacuum Cleaner Powerful Suction Portable Lightweight Hand Held Vacuum Cordless with 25-30Mins Long Runtime Rechargeable Battery Quick Charge for Home Car Carpet Stairs Pet Hair Cleaning | CY6: B09VKPHJVF | CZ6: Wirelume Handheld Car Vacuum Cleaner Cordless Powerful 22000Pa Strong Cyclonic Suction Blowing Brushless Motor Mini Hand Held Portable Rechargeable Lightweight for Pet Hair Vehicle Home Office Purple | DA6: B0D45V1YXT | DB6: B0D9NGRD9M | DC6: 49.99 | DD6: 42.833333 | DE6: 15 | DF6: 800 | DG6: 1285 | DJ6: 3667 | DK6: 15 | DL6: 1285 | DM6: 800 | DN6: 39992 | DO6: 49.99 | DP6: Lyiazsoy Car Vacuum Cleaner,22000PA High Power Mini Vacuum Cleaner,Rechargeable Handheld Vacuum,Portable Cordless Compressed Air Duster Air Blower for Car Home (Gold black)
CP7: handheld hoover | CQ7: 109751 | CR7: 0.5662 | CS7: -0.1233 | CT7: 0.0473 | CU7: 0.0243 | CV7: Shark Handheld Cordless Vacuum Cleaner with Pet Tool Crevice Tool & Dusting Brush 80 W 0.45 liters 10 Minute Run-Time Washable Filter Black & Yellow CH950UKT | CW7: B08M9JQ1J1 | CX7: Handheld Vacuum Cleaner Powerful Suction Portable Lightweight Hand Held Vacuum Cordless with 25-30Mins Long Runtime Rechargeable Battery Quick Charge for Home Car Carpet Stairs Pet Hair Cleaning | CY7: B09VKPHJVF | CZ7: Powools Handheld Vacuum Cordless with 2 Filters Car Vacuum Cleaner High Power with Fast Cahrge Tech Portable Rechargeable Mini Vacuum with Large-Capacity Battery Orange 14.3X4.6X4.0 | DA7: B0D4M3MSG7 | DB7: B0DJFMT6LS | DC7: 24.99 | DD7: 44.433333 | DE7: 19 | DF7: 1000 | DG7: 1333 | DJ7: 4342 | DK7: 19 | DL7: 1333 | DM7: 1000 | DN7: 24990 | DO7: 24.99 | DP7: Higoom 4 in 1 Cordless Handheld Vacuum Cleaner,Car Vacuum Cleaner,22000PA Strong Suction Mini Vacuum,Dust Blower,Can be Used for Home,Car
CP8: car hoovers cordless powerful | CQ8: 133015 | CR8: -0.001 | CS8: -0.1131 | CT8: 0.0558 | CU8: 0.0275 | CV8: Handheld Vacuum Cleaner Powerful Suction Portable Lightweight Hand Held Vacuum Cordless with 25-30Mins Long Runtime Rechargeable Battery Quick Charge for Home Car Carpet Stairs Pet Hair Cleaning | CW8: B09VKPHJVF | CX8: Nctoberows Handheld Vacuum Cleaner Cordless 22000Pa Powerful Car Mini Vacuum Cleaner Rechargeable Portable Lightweight dust catcher for Home Car Carpet Stairs Pet Hair Deep Cleaning | CY8: B0DJ2YVV6F | CZ8: Semflagree Handheld Mini Vacuum 4 in 1 Cordless 23000PA Powerful Strong Cyclonic Suction USB Rechargeable Portable Car Vacuum Cleaner Car Cleaner for Pet Hair Car Home Office Kitchen | DA8: B0DXKCZD5Z | DB8: B0F7RDTSDF | DC8: 32.99 | DD8: 12.366667 | DE8: 20 | DF8: 300 | DG8: 371 | DJ8: 4356 | DK8: 20 | DL8: 371 | DM8: 300 | DN8: 6000 | DO8: 32.99 | DP8: Handheld Vacuum Cleaner, 22000Pa Brushless Motor Cordless Vacuum Cleaners, 3-Speed Car Vacuum Cleaner with Dual Filters and Multiple Brush Heads for Office, Home, Car, Kitchen and Pet Hair, Dark Grey
CP9: car vacuum | CQ9: 109696 | CR9: 0.0631 | CS9: -0.2452 | CT9: 0.0331 | CU9: 0.0148 | CV9: Wirelume Handheld Car Vacuum Cleaner Cordless Powerful 22000Pa Strong Cyclonic Suction Blowing Brushless Motor Mini Portable Rechargeable Lightweight Blower for Pet Hair Vehicle Home Office Dark Grey | CW9: B0D45VR94F | CX9: Handheld Vacuum Cleaner Powerful Suction Portable Lightweight Hand Held Vacuum Cordless with 25-30Mins Long Runtime Rechargeable Battery Quick Charge for Home Car Carpet Stairs Pet Hair Cleaning | CY9: B09VKPHJVF | CZ9: Higoom 4 in 1 Cordless Handheld Vacuum Cleaner Car Vacuum Cleaner 22000PA Strong Suction Mini Vacuum Dust Blower Can be Used for Home Car | DA9: B0DJFMT6LS | DB9: B0CXCQR22Z | DC9: 23.99 | DD9: 23.4 | DE9: 24 | DF9: 600 | DG9: 702 | DJ9: 5908 | DK9: 24 | DL9: 702 | DM9: 600 | DN9: 14394 | DO9: 23.99 | DP9: Handheld Car Vacuum Cleaner, 15000Pa Powerful Vacuum Cleaner Cordless, 3 in 1 Lightweight Vacuum & Blower Dust Buster, LED Display, USB Rechargeable Mini Cleaner for Car, Home and Pet Hair Cleaning
CP10: mini hoover | CQ10: 96946 | CR10: -0.0553 | CS10: -0.2516 | CT10: 0.0227 | CU10: 0.0199 | CV10: Handheld Vacuum Cleaner Powerful Suction Portable Lightweight Hand Held Vacuum Cordless with 25-30Mins Long Runtime Rechargeable Battery Quick Charge for Home Car Carpet Stairs Pet Hair Cleaning | CW10: B09VKPHJVF | CX10: Handheld Vacuum Cordless 9000Pa Powerful Car Vacuum Cleaner Rechargeable Portable Lightweight Mini Vacuum Cleaner USB Car Vacuum Cleaner Car Cleaner for Pet Hair Car Home Office Kitchen | CY10: B0CKVFMYH4 | CZ10: Nctoberows Handheld Vacuum Cleaner Cordless 22000Pa Powerful Car Mini Vacuum Cleaner Rechargeable Portable Lightweight dust catcher for Home Car Carpet Stairs Pet Hair Deep Cleaning | DA10: B0DJ2YVV6F | DB10: B0FFSTYXML | DC10: 29.99 | DD10: 14.066667 | DE10: 26 | DF10: 400 | DG10: 422 | DJ10: 5985 | DK10: 26 | DL10: 422 | DM10: 400 | DN10: 12000 | DO10: 29.99 | DP10: Grixz Handheld Vacuum Cleaner, 22000Pa Powerful Car Vacuum Cleaner Cordless, Lightweight Mini Vacuum & Air Duster, Rechargeable Portable Vacuum for Car, Home, Office, Kitchen
CP11: handheld vacuum | CQ11: 83977 | CR11: 0.2376 | CS11: -0.2902 | CT11: 0.0226 | CU11: 0.0143 | CV11: Shark Handheld Cordless Vacuum Cleaner with Pet Tool Crevice Tool & Dusting Brush 80 W 0.45 liters 10 Minute Run-Time Washable Filter Black & Yellow CH950UKT | CW11: B08M9JQ1J1 | CX11: Vax Gator Cordless Handheld Vacuum Cleaner | Lightweight Quick Cleaning | Built-in Crevice Tool - H85-GA-B10 0.3 Litre White and Orange | CY11: B015QZH2EU | CZ11: Handheld Vacuum Cleaner Powerful Suction Portable Lightweight Hand Held Vacuum Cordless with 25-30Mins Long Runtime Rechargeable Battery Quick Charge for Home Car Carpet Stairs Pet Hair Cleaning | DA11: B09VKPHJVF | DB11: B0DXKCZD5Z | DC11: 26.99 | DD11: 38.366667 | DE11: 28 | DF11: 600 | DG11: 1151 | DJ11: 6205 | DK11: 28 | DL11: 1151 | DM11: 600 | DN11: 16194 | DO11: 26.99 | DP11: Semflagree Handheld Mini Vacuum 4 in 1 Cordless, 23000PA Powerful Strong Cyclonic Suction USB Rechargeable Portable Car Vacuum Cleaner Car Cleaner for Pet Hair, Car, Home, Office, Kitchen
CP12: hand held hoover | CQ12: 75659 | CR12: 0.2587 | CS12: -0.167 | CT12: 0.0253 | CU12: 0.0248 | CV12: Shark Handheld Cordless Vacuum Cleaner with Pet Tool Crevice Tool & Dusting Brush 80 W 0.45 liters 10 Minute Run-Time Washable Filter Black & Yellow CH950UKT | CW12: B08M9JQ1J1 | CX12: Handheld Vacuum Cleaner Powerful Suction Portable Lightweight Hand Held Vacuum Cordless with 25-30Mins Long Runtime Rechargeable Battery Quick Charge for Home Car Carpet Stairs Pet Hair Cleaning | CY12: B09VKPHJVF | CZ12: Nctoberows Handheld Vacuum Cleaner Cordless 22000Pa Powerful Car Mini Vacuum Cleaner Rechargeable Portable Lightweight dust catcher for Home Car Carpet Stairs Pet Hair Deep Cleaning | DA12: B0DJ2YVV6F | DB12: B0F1YKY242 | DC12: 25.99 | DD12: 15.666667 | DE12: 30 | DF12: 500 | DG12: 470 | DJ12: 6935 | DK12: 30 | DL12: 470 | DM12: 500 | DN12: 12995 | DO12: 25.99 | DP12: ONEWEST Handheld Vacuum Cleaner,15000pa Car Vacuum Cleaner Cordless Powerful,4 IN 1 USB Rechargeable Portable Mini Vacuum,Lightweight Hand Vacuum for Car,Keyboard,Pet Hair,Home,Office - Black
CP13: car vacuum cleaner cordless powerful | CQ13: 68512 | CR13: 0.0573 | CS13: -0.1873 | CT13: 0.0225 | CU13: 0.0162 | CV13: Handheld Vacuum Cleaner Powerful Suction Portable Lightweight Hand Held Vacuum Cordless with 25-30Mins Long Runtime Rechargeable Battery Quick Charge for Home Car Carpet Stairs Pet Hair Cleaning | CW13: B09VKPHJVF | CX13: Wirelume Handheld Car Vacuum Cleaner Cordless Powerful 22000Pa Strong Cyclonic Suction Blowing Brushless Motor Mini Hand Held Portable Rechargeable Lightweight for Pet Hair Vehicle Home Office Purple | CY13: B0D45V1YXT | CZ13: Semflagree Handheld Mini Vacuum 4 in 1 Cordless 23000PA Powerful Strong Cyclonic Suction USB Rechargeable Portable Car Vacuum Cleaner Car Cleaner for Pet Hair Car Home Office Kitchen | DA13: B0DXKCZD5Z | DB13: B0F187FF99 | DC13: 19.49 | DD13: 14.8 | DE13: 36 | DF13: 400 | DG13: 444 | DJ13: 11184 | DK13: 36 | DL13: 444 | DM13: 400 | DN13: 7796 | DO13: 19.49 | DP13: Handheld Vacuum Cleaner, Small Portable Car Vacuum Cleaner Cordless Powerful 7000Pa, 3 in 1 Car Hoovers Cordless Powerful USB Rechargeable, Air Duster & Blower for Car, Home Office (Black-logo)
CP14: handheld vacuums | CQ14: 100456 | CR14: -0.1738 | CS14: -0.4709 | CT14: 0.0125 | CU14: 0.0082 | CV14: Shark Handheld Cordless Vacuum Cleaner with Pet Tool Crevice Tool & Dusting Brush 80 W 0.45 liters 10 Minute Run-Time Washable Filter Black & Yellow CH950UKT | CW14: B08M9JQ1J1 | CX14: Shark WandVac 1.0 Cordless Handheld Vacuum Cleaner Small & Lightweight Powerful Suction Handheld Vacuum with Duster/Crevice and Multi-Surface Tools Charging Base Grey WV200UK | CY14: B07H5XMVGD | CZ14: Handheld Vacuum Cleaner Powerful Suction Portable Lightweight Hand Held Vacuum Cordless with 25-30Mins Long Runtime Rechargeable Battery Quick Charge for Home Car Carpet Stairs Pet Hair Cleaning | DA14: B09VKPHJVF | DB14: B0DXPSYS1N | DC14: 39.98 | DD14: 8.3666667 | DE14: 40 | DF14: 200 | DG14: 251 | DJ14: 13255 | DK14: 40 | DL14: 251 | DM14: 200 | DN14: 7996 | DO14: 39.98 | DP14: Handheld Vacuum Cleaner, 22000Pa Car Vacuum Cleaner Powerful, with Brushless Motor Rechargeable High Power Handheld Vacuum & Air Duster, Cleaning for Kitchen, Car, Computer desktop, Pet, Home
CP15: small hoover | CQ15: 65578 | CR15: -0.0286 | CS15: -0.1825 | CT15: 0.0079 | CU15: 0.0075 | CV15: Amazon Basics 2-in-1 Corded Upright Vacuum Cleaner ECO Motor HEPA filtration Lightweight Stick Black | CW15: B07SH66PXX | CX15: VYTRONIX HSV3 Upright Vacuum Cleaner | Lightweight 3-in-1 Compact Powerful Multifunction Corded Stick & Handheld Vacuum | 600 Watt 5 Metre Power Cord | 2.5Kg | CY15: B09RMQ1XLL | CZ15: Handheld Vacuum Cleaner Powerful Suction Portable Lightweight Hand Held Vacuum Cordless with 25-30Mins Long Runtime Rechargeable Battery Quick Charge for Home Car Carpet Stairs Pet Hair Cleaning | DA15: B09VKPHJVF | DB15: B0DJ9CSK63 | DC15: 19.94 | DD15: 4.6666667 | DE15: 46 | DF15: 100 | DG15: 140 | DJ15: 18723 | DK15: 46 | DL15: 140 | DM15: 100 | DN15: 1994 | DO15: 19.94 | DP15: VOLTATECH 13000PA Handheld Vacuum Cleaner Cordless - Dual Gear, Powerful, Hand held Vacuum Cordless, car hoover, Mini, Wireless & Portable, Type-C – Black
... CP21: handheld vacuum cleaner cordless | CQ21: 38290 | CR21: 0.683 | CS21: -0.1409 | CT21: 0.0151 | CU21: 0.0172 | CV21: Shark Handheld Cordless Vacuum Cleaner with Pet Tool Crevice Tool & Dusting Brush 80 W 0.45 liters 10 Minute Run-Time Washable Filter Black & Yellow CH950UKT | CW21: B08M9JQ1J1 | CX21: Handheld Vacuum Cleaner Powerful Suction Portable Lightweight Hand Held Vacuum Cordless with 25-30Mins Long Runtime Rechargeable Battery Quick Charge for Home Car Carpet Stairs Pet Hair Cleaning | CY21: B09VKPHJVF | CZ21: Higoom 4 in 1 Cordless Handheld Vacuum Cleaner Car Vacuum Cleaner 22000PA Strong Suction Mini Vacuum Dust Blower Can be Used for Home Car | DA21: B0DJFMT6LS | DB21: B0F32MV4J3 | DC21: 29.99 | DD21: 8.4 | DE21: 60 | DF21: 200 | DG21: 252 | DJ21: 29196 | DK21: 60 | DL21: 252 | DM21: 200 | DN21: 5998 | DO21: 29.99 | DP21: DEUKNICE Handheld Vacuum Cleaner, 22000Pa Powerful Car Vacuum Cleaner Cordless, Portable Rechargeable Air Duster, Mini Lightweight Vacuum for Car, Home
DB22: B0FH1K5PGW | DC22: 27.99 | DD22: 0.36666667 | DE22: 71 | DF22: 50 | DG22: 11 | DJ22: 35465 | DK22: 71 | DL22: 11 | DM22: 50 | DN22: 500 | DO22: 27.99 | DP22: Bemkia Cordless Handheld Vacuum Cleaner, 21000Pa Powerful Suction, 4-in-1 Portable Car Hoovers with Washable HEPA Filter, Ideal for Pet Hair, Home, Office, Vehicle Cleaning (Black)
DB23: B0F9XTZDGW | DC23: 39.99 | DD23: 0.73333333 | DE23: 73 | DF23: 50 | DG23: 22 | DJ23: 36527 | DK23: 73 | DL23: 22 | DM23: 50 | DN23: 1100 | DO23: 39.99 | DP23: Handheld Vacuum Cleaner, 25000Pa/120W Powerful Mini Car Vacuum Cleaner, 9000mAh Rechargeable Battery, Portable Lightweight Car Hoover, Air Duster Air Blower for Car, Office and Home Deep Cleaning
DB24: B0F9W71RQQ | DC24: 55.99 | DD24: 1.0666667 | DE24: 75 | DF24: 50 | DG24: 32 | DJ24: 36837 | DK24: 75 | DL24: 32 | DM24: 50 | DN24: 1500 | DO24: 55.99 | DP24: Lyiazsoy Car Vacuum Cleaner Cordless,22000PA High Power Mini Vacuum Cleaner,Rechargeable Handheld Vacuum Cordless,car hoovers for Pet Hair, Home, Office, Kitchen(Gold Black)
DB25: B0F2H6YTVS | DC25: 22.79 | DD25: 11.266667 | DE25: 76 | DF25: 200 | DG25: 338 | DJ25: 37165 | DK25: 76 | DL25: 338 | DM25: 200 | DN25: 6837 | DO25: 22.79 | DP25: Portable Handheld Car Vacuum Cleaner 9000PA,4 in 1 Air Duster and Vacuum Cleaner with Multi-Nozzles,120W High Power Lightweight Mini Rechargeable Cordless Hoover for Car Home Office, Pet Hair
DB26: B0DXQ34XZN | DC26: 26.98 | DD26: 4.6666667 | DE26: 80 | DF26: 50 | DG26: 140 | DJ26: 38198 | DK26: 80 | DL26: 140 | DM26: 50 | DN26: 1349 | DO26: 26.98 | DP26: LUCUHM Handheld Vacuum Cleaner Cordless - 16000Pa Powerful Dust Buster Handheld Car Vacuum Cleaner - Portable Lightweight USB Rechargeable for Car, Pet Hair, Office, Home, Kitchen (Grey)
DB27: B0F484XM47 | DC27: 19.99 | DD27: 12.466667 | DE27: 82 | DF27: 200 | DG27: 374 | DJ27: 39916 | DK27: 82 | DL27: 374 | DM27: 200 | DN27: 3998 | DO27: 19.99 | DP27: Handheld Vacuum Cleaner Powerful Car Vacuum Cordless Cleaner 4 in 1 Mini Car Vacuum Rechargeable Air Blower Cleaner with Extension Brush and Nozzles for Car,Office,Home with Washable HEPA Filter Grey
DB28: B0C1C73WS9 | DC28: 18.96 | DD28: 4.0333333 | DE28: 92 | DF28: 50 | DG28: 121 | DJ28: 50285 | DK28: 92 | DL28: 121 | DM28: 50 | DN28: 948 | DO28: 18.96 | DP28: YWSS Cordless Mini Handheld Vacuum, Electric Air Duster & Vacuum Cleaner 2 in 1 Rechargeable, Portable for Home, Office and Car
DB29: B0CDP5V9W8 | DC29: 18.98 | DD29: 3.1 | DE29: 93 | DF29: 50 | DG29: 93 | DJ29: 50292 | DK29: 93 | DL29: 93 | DM29: 50 | DN29: 949 | DO29: 18.98 | DP29: Mini Car Vacuum Cleaner,Handheld Vacuum Cordless,2 in 1 Rechargeable Vacuum Cleaner & Blower,Small Wireless Car Vacuum with 6000Pa Suction Power,Dust Buster,Portable Hoover Vacuum for Car Home Office
DB31: 平均售价是 | DC31: 28.49
