Workbook

Sheet 阶段实际盈亏
A1: 时间 | B1: 实际 | C1: 价格 | D1: 站内 coupon | E1: 站内 code | F1: 站外 折扣 | G1: 站外 订单 | H1: 站内 自然单 | I1: 站内 广告单 | J1: 阶段 销售 订单 | K1: 时间 /天 | L1: 阶段广告费 （出1单广告单预估） | M1: 阶段站外费用 （5美金/单） | N1: 阶段订单 盈亏 | O1: 阶段亏损 /美金 | P1: 六阶段 总亏损 | R1: 阶段日均 订单 | S1: 阶段日均 广告订单 | T1: 阶段日均 自然订单 | U1: 新品 排行榜 | V1: 小类目 排名
A2: 9月7-9月12 | B2: 第一阶段 | C2: 99.99 | D2: 0.05 | E2: 0.5 | F2: 0.68 | G2: =SUM(#REF!) -> #REF! | H2: 0 | I2: 0 | J2: =SUM(G2:I2) -> #REF! | K2: 6 | L2: 0 | M2: =SUM(#REF!) -> #REF! | N2: =SUM(#REF!) -> #REF! | O2: =SUM(L2:N2) -> #REF!
A3: 9月13-9月21 | B3: 第二阶段 | C3: 79.99 | D3: 0.3 | E3: 0.2 | F3: 0.3 | G3: 81 | H3: 14 | I3: 0 | J3: =SUM(G3:I3) -> 95 | K3: 9 | L3: =SUM(#REF!) -> #REF! | M3: =SUM(#REF!) -> #REF! | N3: =SUM(#REF!) -> #REF! | O3: =SUM(L3:N3) -> #REF!
A4: 9月22-10月1 | B4: 第三阶段 | C4: 69.99 | D4: 0.3 | E4: 0.2 | F4: 0.25 | G4: 45 | H4: 60 | I4: 3 | J4: =SUM(G4:I4) -> 108 | K4: 10 | L4: =SUM(#REF!) -> #REF! | M4: =SUM(#REF!) -> #REF! | N4: =SUM(#REF!) -> #REF! | O4: =SUM(L4:N4) -> #REF!
A5: 10月2-10月11 | B5: 第四阶段 | C5: 69.99 | D5: 0.3 | E5: 0 | F5: 0.25
A6: 10月12-10月21 | B6: 第五阶段 | C6: 69.99 | D6: 0.3 | E6: 0 | F6: 0.25
A7: 10月22-10月31 | B7: 第六阶段 | C7: 69.99 | D7: 0.3 | E7: 0 | F7: 0
A9: 11月1-11月30 | B9: 十一月份 | C9: 69.99 | D9: 0.2 | E9: 0 | F9: 0
A10: 12月1-12月31 | B10: 十二月份 | C10: 69.99 | D10: 0.2 | E10: 0 | F10: 0
A11: 1月1-1月31 | B11: 一月份 | C11: 69.99 | D11: 0.2 | E11: 0 | F11: 0

Sheet 价格策略模拟
B1: 价格策略模拟
A2: 阶段 | B2: 定价 | C2: coupon | D2: code | E2: 折后价 | F2: FBA 配送费 | G2: 亚马逊 佣金 | H2: 账号 回款 | I2: 仓储费+入库配置费 | J2: coupon 费用 | K2: 产品 成本 | L2: 物流费 | M2: 退货成本(公式后面加的是单套产品的移除费） | N2: 退货率 | O2: 每单平摊 退货成本 | P2: 每单 毛利 | Q2: 毛利率 | R2: 订单 数量 | S2: 阶段 订单 亏损 | T2: 阶段 订单 总盈亏
A3: 第一阶段 | B3: 23.99 | C3: 0.25 | D3: 0 | E3: =SUM(B3*(1-C3-D3)) -> 17.9925 | F3: 5.5 | G3: =SUM(E3*15%) -> 2.698875 | H3: =SUM(E3-F3-G3) -> 9.793625 | I3: =0.13+0.21 -> 0.34 | J3: 0.6 | K3: 4.5 | L3: 1 | M3: =SUM(20%*15%*E3+F3+I3+K3+L3+1.04) -> 12.919775 | N3: 0.15 | O3: =SUM(M3*N3/(1-N3)) -> 2.2799603 | P3: =SUM(H3-I3-J3-K3-L3-O3) -> 1.0736647 | Q3: =SUM(P3/B3) -> 0.044754677 | R3: 1 | S3: =SUM(P3*R3) -> 1.0736647 | T3: =SUM(S3:S3) -> 1.0736647
A4: 第二阶段 | B4: 24.99 | C4: 0.2 | D4: 0 | E4: =SUM(B4*(1-C4-D4)) -> 19.992 | F4: 5.5 | G4: =SUM(E4*15%) -> 2.9988 | H4: =SUM(E4-F4-G4) -> 11.4932 | I4: =0.13+0.21 -> 0.34 | J4: 0.6 | K4: 4.5 | L4: 1 | M4: =SUM(20%*15%*E4+F4+I4+K4+L4+1.04) -> 12.97976 | N4: 0.15 | O4: =SUM(M4*N4/(1-N4)) -> 2.2905459 | P4: =SUM(H4-I4-J4-K4-L4-O4) -> 2.7626541 | Q4: =SUM(P4/B4) -> 0.11055038 | R4: 1 | S4: =SUM(P4*R4) -> 2.7626541 | T4: =SUM(S4:S4) -> 2.7626541
A5: 第三阶段 | B5: 25.99 | C5: 0.15 | D5: 0 | E5: =SUM(B5*(1-C5-D5)) -> 22.0915 | F5: 5.5 | G5: =SUM(E5*15%) -> 3.313725 | H5: =SUM(E5-F5-G5) -> 13.277775 | I5: =0.13+0.21 -> 0.34 | J5: 0.6 | K5: 4.5 | L5: 1 | M5: =SUM(20%*15%*E5+F5+I5+K5+L5+1.04) -> 13.042745 | N5: 0.15 | O5: =SUM(M5*N5/(1-N5)) -> 2.3016609 | P5: =SUM(H5-I5-J5-K5-L5-O5) -> 4.5361141 | Q5: =SUM(P5/B5) -> 0.17453306 | R5: 1 | S5: =SUM(P5*R5) -> 4.5361141 | T5: =SUM(S5:S5) -> 4.5361141
A6: 第四阶段 | B6: 26.99 | C6: 0.1 | D6: 0 | E6: =SUM(B6*(1-C6-D6)) -> 24.291 | F6: 5.5 | G6: =SUM(E6*15%) -> 3.64365 | H6: =SUM(E6-F6-G6) -> 15.14735 | I6: =0.13+0.21 -> 0.34 | J6: 0.6 | K6: 4.5 | L6: 1 | M6: =SUM(20%*15%*E6+F6+I6+K6+L6+1.04) -> 13.10873 | N6: 0.15 | O6: =SUM(M6*N6/(1-N6)) -> 2.3133053 | P6: =SUM(H6-I6-J6-K6-L6-O6) -> 6.3940447 | Q6: =SUM(P6/B6) -> 0.23690421 | R6: 1 | S6: =SUM(P6*R6) -> 6.3940447 | T6: =SUM(S6:S6) -> 6.3940447
A7: 第五阶段 | B7: 27.99 | C7: 0.1 | D7: 0 | E7: =SUM(B7*(1-C7-D7)) -> 25.191 | F7: 5.5 | G7: =SUM(E7*15%) -> 3.77865 | H7: =SUM(E7-F7-G7) -> 15.91235 | I7: =0.13+0.21 -> 0.34 | J7: 0.6 | K7: 4.5 | L7: 1 | M7: =SUM(20%*15%*E7+F7+I7+K7+L7+1.04) -> 13.13573 | N7: 0.15 | O7: =SUM(M7*N7/(1-N7)) -> 2.31807 | P7: =SUM(H7-I7-J7-K7-L7-O7) -> 7.15428 | Q7: =SUM(P7/B7) -> 0.25560129 | R7: 1 | S7: =SUM(P7*R7) -> 7.15428 | T7: =SUM(S7:S7) -> 7.15428
A8: 第六阶段 | B8: 27.99 | C8: 0.1 | D8: 0 | E8: =SUM(B8*(1-C8-D8)) -> 25.191 | F8: 5.5 | G8: =SUM(E8*15%) -> 3.77865 | H8: =SUM(E8-F8-G8) -> 15.91235 | I8: =0.13+0.21 -> 0.34 | J8: 0 | K8: 4.5 | L8: 1 | M8: =SUM(20%*15%*E8+F8+I8+K8+L8+1.04) -> 13.13573 | N8: 0.15 | O8: =SUM(M8*N8/(1-N8)) -> 2.31807 | P8: =SUM(H8-I8-J8-K8-L8-O8) -> 7.75428 | Q8: =SUM(P8/B8) -> 0.27703751 | R8: 1 | S8: =SUM(P8*R8) -> 7.75428 | T8: =SUM(S8:S8) -> 7.75428
A10: 竞品日常价格 | B10: 29.99 | C10: 0 | D10: 0 | E10: =SUM(B10*(1-C10-D10)) -> 29.99 | F10: 5.5 | G10: =SUM(E10*15%) -> 4.4985 | H10: =SUM(E10-F10-G10) -> 19.9915 | I10: =0.08+0.34 -> 0.42 | J10: 0 | K10: 4.5 | L10: 1 | M10: =SUM(20%*15%*E10+F10+I10+K10+L10+1.46) -> 13.7797 | N10: 0.15 | O10: =SUM(M10*N10/(1-N10)) -> 2.4317118 | P10: =SUM(H10-I10-J10-K10-L10-O10) -> 11.639788 | Q10: =SUM(P10/B10) -> 0.38812232 | R10: 1 | S10: =SUM(P10*R10) -> 11.639788 | T10: =SUM(S10:S10) -> 11.639788
A11: 竞品活动价格 | B11: 29.99 | C11: 0.2 | D11: 0 | E11: =SUM(B11*(1-C11-D11)) -> 23.992 | F11: 5.5 | G11: =SUM(E11*15%) -> 3.5988 | H11: =SUM(E11-F11-G11) -> 14.8932 | I11: =0.08+0.34 -> 0.42 | J11: 0.6 | K11: 4.5 | L11: 1 | M11: =SUM(20%*15%*E11+F11+I11+K11+L11+1.46) -> 13.59976 | N11: 0.15 | O11: =SUM(M11*N11/(1-N11)) -> 2.3999576 | P11: =SUM(H11-I11-J11-K11-L11-O11) -> 5.9732424 | Q11: =SUM(P11/B11) -> 0.19917447 | R11: 1 | S11: =SUM(P11*R11) -> 5.9732424 | T11: =SUM(S11:S11) -> 5.9732424
A12: 竞品链接 | B12: https://www.amazon.com/Back-Brace-Posture-Corrector-Women/dp/B099WTPXN5
A15: 最新爆款链接推广表格数据模拟（送10本杂志）
A16: https://mp.weixin.qq.com/s/qAN_F4X7sGrzxkUmNgb7TA

Sheet 阶段总盈亏
A1: 阶段盈亏模拟数据
A2: 阶段 | B2: 日期 | C2: 定价 | D2: cou pon | E2: code | F2: 折后价 | G2: 站内 自然单 | H2: 站内 广告单 | I2: 阶段 销售 订单 | J2: 时间 /天 | K2: CPA | L2: 阶段 广告费 | M2: 毛利 盈亏 | N2: 阶段盈亏 /美金 | O2: 评论 数量 | P2: 阶段 日均 订单 | Q2: 阶段 日均 广告单 | R2: 阶段 日均 自然单 | S2: 日均 广告费 | T2: 每周 销售额 | U2: Tacos | V2: 新品 排行榜 | W2: 小类目 排名 | X2: 备注 | Y2: 种子评论费/（开3条VINE，预计来70条评论）,视觉化费用预估3000美金 | Z2: 前期亏损/美金 | AA2: 人民币
A3: 第一阶段 | B3: 第1周 | C3: =价格策略模拟!B3 -> 23.99 | D3: =价格策略模拟!C3 -> 0.25 | E3: =价格策略模拟!D3 -> 0 | F3: =SUM(C3*(1-D3-E3)) -> 17.9925 | G3: =J3*R3 -> 0 | H3: =J3*Q3 -> 14 | I3: =SUM(G3:H3) -> 14 | J3: 7 | K3: =CPC模拟表格!V3 -> 30 | L3: =SUM(H3*-K3) -> -420 | M3: =毛利模拟盈亏!T3 -> 15.031306 | N3: =SUM(L3:M3) -> -404.96869 | O3: 20 | P3: 2 | Q3: 2 | R3: =SUM(P3-Q3) -> 0 | S3: =SUM(L3/J3) -> -60 | T3: =毛利模拟盈亏!V3 -> 335.86 | U3: =-L3/T3 -> 1.2505211 | W3: 前100名 | Y3: =-(90*11+600+1500) -> -3090 | Z3: =SUM(N3:N18)+Y3 -> -13477.381 | AA3: =Z3*7 -> -94341.67
B4: 第2周 | C4: =价格策略模拟!B3 -> 23.99 | D4: =价格策略模拟!C3 -> 0.25 | E4: =价格策略模拟!D3 -> 0 | F4: =SUM(C4*(1-D4-E4)) -> 17.9925 | G4: =J4*R4 -> 7 | H4: =J4*Q4 -> 21 | I4: =SUM(G4:H4) -> 28 | J4: 7 | K4: =CPC模拟表格!V4 -> 30 | L4: =SUM(H4*-K4) -> -630 | M4: =毛利模拟盈亏!T4 -> 30.062612 | N4: =SUM(L4:M4) -> -599.93739 | P4: 4 | Q4: 3 | R4: =SUM(P4-Q4) -> 1 | S4: =SUM(L4/J4) -> -90 | T4: =毛利模拟盈亏!V4 -> 671.72 | U4: =-L4/T4 -> 0.93789079 | W4: 前90名
B5: 第3周 | C5: =价格策略模拟!B3 -> 23.99 | D5: =价格策略模拟!C3 -> 0.25 | E5: =价格策略模拟!D3 -> 0 | F5: =SUM(C5*(1-D5-E5)) -> 17.9925 | G5: =J5*R5 -> 14 | H5: =J5*Q5 -> 28 | I5: =SUM(G5:H5) -> 42 | J5: 7 | K5: =CPC模拟表格!V5 -> 30 | L5: =SUM(H5*-K5) -> -840 | M5: =毛利模拟盈亏!T5 -> 45.093918 | N5: =SUM(L5:M5) -> -794.90608 | P5: 6 | Q5: 4 | R5: =SUM(P5-Q5) -> 2 | S5: =SUM(L5/J5) -> -120 | T5: =毛利模拟盈亏!V5 -> 1007.58 | U5: =-L5/T5 -> 0.8336807 | W5: 前80名
B6: 第4周 | C6: =价格策略模拟!B3 -> 23.99 | D6: =价格策略模拟!C3 -> 0.25 | E6: =价格策略模拟!D3 -> 0 | F6: =SUM(C6*(1-D6-E6)) -> 17.9925 | G6: =J6*R6 -> 21 | H6: =J6*Q6 -> 35 | I6: =SUM(G6:H6) -> 56 | J6: 7 | K6: =CPC模拟表格!V6 -> 30 | L6: =SUM(H6*-K6) -> -1050 | M6: =毛利模拟盈亏!T6 -> 60.125224 | N6: =SUM(L6:M6) -> -989.87478 | P6: 8 | Q6: 5 | R6: =SUM(P6-Q6) -> 3 | S6: =SUM(L6/J6) -> -150 | T6: =毛利模拟盈亏!V6 -> 1343.44 | U6: =-L6/T6 -> 0.78157566 | W6: 前70名
A7: 第二阶段 | B7: 第5周 | C7: =价格策略模拟!B4 -> 24.99 | D7: =价格策略模拟!C4 -> 0.2 | E7: =价格策略模拟!D4 -> 0 | F7: =SUM(C7*(1-D7-E7)) -> 19.992 | G7: =J7*R7 -> 28 | H7: =J7*Q7 -> 42 | I7: =SUM(G7:H7) -> 70 | J7: 7 | K7: =CPC模拟表格!V7 -> 23.333333 | L7: =SUM(H7*-K7) -> -980 | M7: =毛利模拟盈亏!T7 -> 193.38579 | N7: =SUM(L7:M7) -> -786.61421 | O7: 40 | P7: 10 | Q7: 6 | R7: =SUM(P7-Q7) -> 4 | S7: =SUM(L7/J7) -> -140 | T7: =毛利模拟盈亏!V7 -> 1749.3 | U7: =-L7/T7 -> 0.56022409 | W7: 前60名
B8: 第6周 | C8: =价格策略模拟!B4 -> 24.99 | D8: =价格策略模拟!C4 -> 0.2 | E8: =价格策略模拟!D4 -> 0 | F8: =SUM(C8*(1-D8-E8)) -> 19.992 | G8: =J8*R8 -> 35 | H8: =J8*Q8 -> 49 | I8: =SUM(G8:H8) -> 84 | J8: 7 | K8: =CPC模拟表格!V8 -> 23.333333 | L8: =SUM(H8*-K8) -> -1143.3333 | M8: =毛利模拟盈亏!T8 -> 232.06295 | N8: =SUM(L8:M8) -> -911.27039 | P8: 12 | Q8: 7 | R8: =SUM(P8-Q8) -> 5 | S8: =SUM(L8/J8) -> -163.33333 | T8: =毛利模拟盈亏!V8 -> 2099.16 | U8: =-L8/T8 -> 0.54466231 | W8: 前50名
B9: 第7周 | C9: =价格策略模拟!B4 -> 24.99 | D9: =价格策略模拟!C4 -> 0.2 | E9: =价格策略模拟!D4 -> 0 | F9: =SUM(C9*(1-D9-E9)) -> 19.992 | G9: =J9*R9 -> 42 | H9: =J9*Q9 -> 56 | I9: =SUM(G9:H9) -> 98 | J9: 7 | K9: =CPC模拟表格!V9 -> 23.333333 | L9: =SUM(H9*-K9) -> -1306.6667 | M9: =毛利模拟盈亏!T9 -> 270.7401 | N9: =SUM(L9:M9) -> -1035.9266 | P9: 14 | Q9: 8 | R9: =SUM(P9-Q9) -> 6 | S9: =SUM(L9/J9) -> -186.66667 | T9: =毛利模拟盈亏!V9 -> 2449.02 | U9: =-L9/T9 -> 0.53354675 | W9: 前45名
B10: 第8周 | C10: =价格策略模拟!B4 -> 24.99 | D10: =价格策略模拟!C4 -> 0.2 | E10: =价格策略模拟!D4 -> 0 | F10: =SUM(C10*(1-D10-E10)) -> 19.992 | G10: =J10*R10 -> 49 | H10: =J10*Q10 -> 63 | I10: =SUM(G10:H10) -> 112 | J10: 7 | K10: =CPC模拟表格!V10 -> 23.333333 | L10: =SUM(H10*-K10) -> -1470 | M10: =毛利模拟盈亏!T10 -> 309.41726 | N10: =SUM(L10:M10) -> -1160.5827 | P10: 16 | Q10: 9 | R10: =SUM(P10-Q10) -> 7 | S10: =SUM(L10/J10) -> -210 | T10: =毛利模拟盈亏!V10 -> 2798.88 | U10: =-L10/T10 -> 0.52521008 | W10: 前40名
A11: 第三阶段 | B11: 第9周 | C11: =价格策略模拟!B5 -> 25.99 | D11: =价格策略模拟!C5 -> 0.15 | E11: =价格策略模拟!D5 -> 0 | F11: =SUM(C11*(1-D11-E11)) -> 22.0915 | G11: =J11*R11 -> 56 | H11: =J11*Q11 -> 70 | I11: =SUM(G11:H11) -> 126 | J11: 7 | K11: =CPC模拟表格!V11 -> 18.571429 | L11: =SUM(H11*-K11) -> -1300 | M11: =毛利模拟盈亏!T11 -> 571.55038 | N11: =SUM(L11:M11) -> -728.44962 | O11: 80 | P11: 18 | Q11: 10 | R11: =SUM(P11-Q11) -> 8 | S11: =SUM(L11/J11) -> -185.71429 | T11: =毛利模拟盈亏!V11 -> 3274.74 | U11: =-L11/T11 -> 0.39697808 | W11: 前35名
B12: 第10周 | C12: =价格策略模拟!B5 -> 25.99 | D12: =价格策略模拟!C5 -> 0.15 | E12: =价格策略模拟!D5 -> 0 | F12: =SUM(C12*(1-D12-E12)) -> 22.0915 | G12: =J12*R12 -> 63 | H12: =J12*Q12 -> 77 | I12: =SUM(G12:H12) -> 140 | J12: 7 | K12: =CPC模拟表格!V12 -> 18.571429 | L12: =SUM(H12*-K12) -> -1430 | M12: =毛利模拟盈亏!T12 -> 635.05598 | N12: =SUM(L12:M12) -> -794.94402 | P12: 20 | Q12: 11 | R12: =SUM(P12-Q12) -> 9 | S12: =SUM(L12/J12) -> -204.28571 | T12: =毛利模拟盈亏!V12 -> 3638.6 | U12: =-L12/T12 -> 0.3930083 | W12: 前30名
B13: 第11周 | C13: =价格策略模拟!B5 -> 25.99 | D13: =价格策略模拟!C5 -> 0.15 | E13: =价格策略模拟!D5 -> 0 | F13: =SUM(C13*(1-D13-E13)) -> 22.0915 | G13: =J13*R13 -> 70 | H13: =J13*Q13 -> 84 | I13: =SUM(G13:H13) -> 154 | J13: 7 | K13: =CPC模拟表格!V13 -> 18.571429 | L13: =SUM(H13*-K13) -> -1560 | M13: =毛利模拟盈亏!T13 -> 698.56157 | N13: =SUM(L13:M13) -> -861.43843 | P13: 22 | Q13: 12 | R13: =SUM(P13-Q13) -> 10 | S13: =SUM(L13/J13) -> -222.85714 | T13: =毛利模拟盈亏!V13 -> 4002.46 | U13: =-L13/T13 -> 0.3897603 | W13: 前25名
B14: 第12周 | C14: =价格策略模拟!B5 -> 25.99 | D14: =价格策略模拟!C5 -> 0.15 | E14: =价格策略模拟!D5 -> 0 | F14: =SUM(C14*(1-D14-E14)) -> 22.0915 | G14: =J14*R14 -> 77 | H14: =J14*Q14 -> 91 | I14: =SUM(G14:H14) -> 168 | J14: 7 | K14: =CPC模拟表格!V14 -> 18.571429 | L14: =SUM(H14*-K14) -> -1690 | M14: =毛利模拟盈亏!T14 -> 762.06717 | N14: =SUM(L14:M14) -> -927.93283 | P14: 24 | Q14: 13 | R14: =SUM(P14-Q14) -> 11 | S14: =SUM(L14/J14) -> -241.42857 | T14: =毛利模拟盈亏!V14 -> 4366.32 | U14: =-L14/T14 -> 0.38705363 | W14: 前25名
A15: 第四阶段 | B15: 第13周 | C15: =价格策略模拟!B6 -> 26.99 | D15: =价格策略模拟!C6 -> 0.1 | E15: =价格策略模拟!D6 -> 0 | F15: =SUM(C15*(1-D15-E15)) -> 24.291 | G15: =J15*R15 -> 84 | H15: =J15*Q15 -> 98 | I15: =SUM(G15:H15) -> 182 | J15: 7 | K15: =CPC模拟表格!V15 -> 13.75 | L15: =SUM(H15*-K15) -> -1347.5 | M15: =毛利模拟盈亏!T15 -> 1163.7161 | N15: =SUM(L15:M15) -> -183.78386 | O15: 120 | P15: 26 | Q15: 14 | R15: =SUM(P15-Q15) -> 12 | S15: =SUM(L15/J15) -> -192.5 | T15: =毛利模拟盈亏!V15 -> 4912.18 | U15: =-L15/T15 -> 0.27431812 | W15: 前25名
B16: 第14周 | C16: =价格策略模拟!B6 -> 26.99 | D16: =价格策略模拟!C6 -> 0.1 | E16: =价格策略模拟!D6 -> 0 | F16: =SUM(C16*(1-D16-E16)) -> 24.291 | G16: =J16*R16 -> 98 | H16: =J16*Q16 -> 98 | I16: =SUM(G16:H16) -> 196 | J16: 7 | K16: =CPC模拟表格!V16 -> 13.75 | L16: =SUM(H16*-K16) -> -1347.5 | M16: =毛利模拟盈亏!T16 -> 1253.2328 | N16: =SUM(L16:M16) -> -94.267238 | P16: 28 | Q16: 14 | R16: =SUM(P16-Q16) -> 14 | S16: =SUM(L16/J16) -> -192.5 | T16: =毛利模拟盈亏!V16 -> 5290.04 | U16: =-L16/T16 -> 0.25472397 | W16: 前25名
B17: 第15周 | C17: =价格策略模拟!B6 -> 26.99 | D17: =价格策略模拟!C6 -> 0.1 | E17: =价格策略模拟!D6 -> 0 | F17: =SUM(C17*(1-D17-E17)) -> 24.291 | G17: =J17*R17 -> 105 | H17: =J17*Q17 -> 105 | I17: =SUM(G17:H17) -> 210 | J17: 7 | K17: =CPC模拟表格!V17 -> 13.75 | L17: =SUM(H17*-K17) -> -1443.75 | M17: =毛利模拟盈亏!T17 -> 1342.7494 | N17: =SUM(L17:M17) -> -101.00061 | P17: 30 | Q17: 15 | R17: =SUM(P17-Q17) -> 15 | S17: =SUM(L17/J17) -> -206.25 | T17: =毛利模拟盈亏!V17 -> 5667.9 | U17: =-L17/T17 -> 0.25472397 | W17: 前25名
B18: 第16周 | C18: =价格策略模拟!B6 -> 26.99 | D18: =价格策略模拟!C6 -> 0.1 | E18: =价格策略模拟!D6 -> 0 | F18: =SUM(C18*(1-D18-E18)) -> 24.291 | G18: =J18*R18 -> 119 | H18: =J18*Q18 -> 105 | I18: =SUM(G18:H18) -> 224 | J18: 7 | K18: =CPC模拟表格!V18 -> 13.75 | L18: =SUM(H18*-K18) -> -1443.75 | M18: =毛利模拟盈亏!T18 -> 1432.266 | N18: =SUM(L18:M18) -> -11.483986 | P18: 32 | Q18: 15 | R18: =SUM(P18-Q18) -> 17 | S18: =SUM(L18/J18) -> -206.25 | T18: =毛利模拟盈亏!V18 -> 6045.76 | U18: =-L18/T18 -> 0.23880372 | W18: 前25名
A19: 第五阶段 | B19: 第17周 | C19: =价格策略模拟!B7 -> 27.99 | D19: =价格策略模拟!C7 -> 0.1 | E19: =价格策略模拟!D7 -> 0 | F19: =SUM(C19*(1-D19-E19)) -> 25.191 | G19: =J19*R19 -> 126 | H19: =J19*Q19 -> 112 | I19: =SUM(G19:H19) -> 238 | J19: 7 | K19: =CPC模拟表格!V19 -> 11.111111 | L19: =SUM(H19*-K19) -> -1244.4444 | M19: =毛利模拟盈亏!T19 -> 1702.7186 | N19: =SUM(L19:M19) -> 458.2742 | O19: 180 | P19: 34 | Q19: 16 | R19: =SUM(P19-Q19) -> 18 | S19: =SUM(L19/J19) -> -177.77778 | T19: =毛利模拟盈亏!V19 -> 6661.62 | U19: =-L19/T19 -> 0.18680808 | W19: 前25名
B20: 第18周 | C20: =价格策略模拟!B7 -> 27.99 | D20: =价格策略模拟!C7 -> 0.1 | E20: =价格策略模拟!D7 -> 0 | F20: =SUM(C20*(1-D20-E20)) -> 25.191 | G20: =J20*R20 -> 140 | H20: =J20*Q20 -> 112 | I20: =SUM(G20:H20) -> 252 | J20: 7 | K20: =CPC模拟表格!V20 -> 11.111111 | L20: =SUM(H20*-K20) -> -1244.4444 | M20: =毛利模拟盈亏!T20 -> 1802.8786 | N20: =SUM(L20:M20) -> 558.43412 | P20: 36 | Q20: 16 | R20: =SUM(P20-Q20) -> 20 | S20: =SUM(L20/J20) -> -177.77778 | T20: =毛利模拟盈亏!V20 -> 7053.48 | U20: =-L20/T20 -> 0.17642985 | W20: 前25名
B21: 第19周 | C21: =价格策略模拟!B7 -> 27.99 | D21: =价格策略模拟!C7 -> 0.1 | E21: =价格策略模拟!D7 -> 0 | F21: =SUM(C21*(1-D21-E21)) -> 25.191 | G21: =J21*R21 -> 147 | H21: =J21*Q21 -> 119 | I21: =SUM(G21:H21) -> 266 | J21: 7 | K21: =CPC模拟表格!V21 -> 11.111111 | L21: =SUM(H21*-K21) -> -1322.2222 | M21: =毛利模拟盈亏!T21 -> 1903.0385 | N21: =SUM(L21:M21) -> 580.81626 | P21: 38 | Q21: 17 | R21: =SUM(P21-Q21) -> 21 | S21: =SUM(L21/J21) -> -188.88889 | T21: =毛利模拟盈亏!V21 -> 7445.34 | U21: =-L21/T21 -> 0.17759058 | W21: 前25名
B22: 第20周 | C22: =价格策略模拟!B7 -> 27.99 | D22: =价格策略模拟!C7 -> 0.1 | E22: =价格策略模拟!D7 -> 0 | F22: =SUM(C22*(1-D22-E22)) -> 25.191 | G22: =J22*R22 -> 161 | H22: =J22*Q22 -> 119 | I22: =SUM(G22:H22) -> 280 | J22: 7 | K22: =CPC模拟表格!V22 -> 11.111111 | L22: =SUM(H22*-K22) -> -1322.2222 | M22: =毛利模拟盈亏!T22 -> 2003.1984 | N22: =SUM(L22:M22) -> 680.97618 | P22: 40 | Q22: 17 | R22: =SUM(P22-Q22) -> 23 | S22: =SUM(L22/J22) -> -188.88889 | T22: =毛利模拟盈亏!V22 -> 7837.2 | U22: =-L22/T22 -> 0.16871105 | W22: 前25名
A23: 第六阶段 | B23: 第21周 | C23: =价格策略模拟!B8 -> 27.99 | D23: =价格策略模拟!C8 -> 0.1 | E23: =价格策略模拟!D8 -> 0 | F23: =SUM(C23*(1-D23-E23)) -> 25.191 | G23: =J23*R23 -> 168 | H23: =J23*Q23 -> 126 | I23: =SUM(G23:H23) -> 294 | J23: 7 | K23: =CPC模拟表格!V23 -> 9 | L23: =SUM(H23*-K23) -> -1134 | M23: =毛利模拟盈亏!T23 -> 2279.7583 | N23: =SUM(L23:M23) -> 1145.7583 | O23: 250 | P23: 42 | Q23: 18 | R23: =SUM(P23-Q23) -> 24 | S23: =SUM(L23/J23) -> -162 | T23: =毛利模拟盈亏!V23 -> 8229.06 | U23: =-L23/T23 -> 0.13780432 | W23: 前25名
B24: 第22周 | C24: =价格策略模拟!B8 -> 27.99 | D24: =价格策略模拟!C8 -> 0.1 | E24: =价格策略模拟!D8 -> 0 | F24: =SUM(C24*(1-D24-E24)) -> 25.191 | G24: =J24*R24 -> 182 | H24: =J24*Q24 -> 126 | I24: =SUM(G24:H24) -> 308 | J24: 7 | K24: =CPC模拟表格!V24 -> 9 | L24: =SUM(H24*-K24) -> -1134 | M24: =毛利模拟盈亏!T24 -> 2388.3182 | N24: =SUM(L24:M24) -> 1254.3182 | P24: 44 | Q24: 18 | R24: =SUM(P24-Q24) -> 26 | S24: =SUM(L24/J24) -> -162 | T24: =毛利模拟盈亏!V24 -> 8620.92 | U24: =-L24/T24 -> 0.13154049 | W24: 前25名
B25: 第23周 | C25: =价格策略模拟!B8 -> 27.99 | D25: =价格策略模拟!C8 -> 0.1 | E25: =价格策略模拟!D8 -> 0 | F25: =SUM(C25*(1-D25-E25)) -> 25.191 | G25: =J25*R25 -> 189 | H25: =J25*Q25 -> 133 | I25: =SUM(G25:H25) -> 322 | J25: 7 | K25: =CPC模拟表格!V25 -> 9 | L25: =SUM(H25*-K25) -> -1197 | M25: =毛利模拟盈亏!T25 -> 2496.8782 | N25: =SUM(L25:M25) -> 1299.8782 | P25: 46 | Q25: 19 | R25: =SUM(P25-Q25) -> 27 | S25: =SUM(L25/J25) -> -171 | T25: =毛利模拟盈亏!V25 -> 9012.78 | U25: =-L25/T25 -> 0.13281141 | W25: 前25名
B26: 第24周 | C26: =价格策略模拟!B8 -> 27.99 | D26: =价格策略模拟!C8 -> 0.1 | E26: =价格策略模拟!D8 -> 0 | F26: =SUM(C26*(1-D26-E26)) -> 25.191 | G26: =J26*R26 -> 203 | H26: =J26*Q26 -> 133 | I26: =SUM(G26:H26) -> 336 | J26: 7 | K26: =CPC模拟表格!V26 -> 9 | L26: =SUM(H26*-K26) -> -1197 | M26: =毛利模拟盈亏!T26 -> 2605.4381 | N26: =SUM(L26:M26) -> 1408.4381 | P26: 48 | Q26: 19 | R26: =SUM(P26-Q26) -> 29 | S26: =SUM(L26/J26) -> -171 | T26: =毛利模拟盈亏!V26 -> 9404.64 | U26: =-L26/T26 -> 0.1272776 | W26: 前25名
A28: 阶段盈亏真实数据
A29: 第一阶段 | B29: 第1周
B30: 第2周
B31: 第3周
B32: 第4周
A33: 第二阶段 | B33: 第5周
B34: 第6周
B35: 第7周
B36: 第8周
A37: 第三阶段 | B37: 第9周
B38: 第10周
B39: 第11周
B40: 第12周
A41: 第四阶段 | B41: 第13周
...

Sheet CPC模拟表格
A1: 常规数据 | N1: 广告数据 | AB1: 实时更新 | AC1: 操作备注
A2: 阶段 | B2: 周 | C2: 价格 | D2: 站内 coupon | E2: 站内 code | F2: 折后价 | G2: 新品 榜单 | H2: 小类目 排名 | I2: 总 销量 | J2: 总访 问量 | K2: CVR | L2: 评论 数量 | M2: 评分 | N2: 曝光量 | O2: 点击量 | P2: CTR | Q2: 广告单 | R2: CVR | S2: 平均 CPC | T2: 花费 | U2: ACOS | V2: CPA | W2: 日均 广告费 | X2: 自然 访问 | Y2: 自然 订单 | Z2: 自然 单占比 | AA2: 最终 盈亏 | AB2: 质量分 | AC2: 运营调整 | AD2: 广告操作
A3: 第一阶段 | B3: 第1周 | C3: =价格策略模拟!B3 -> 23.99 | D3: =价格策略模拟!C3 -> 0.25 | E3: =价格策略模拟!D3 -> 0 | F3: =SUM(C3*(1-D3-E3)) -> 17.9925 | O3: =SUM(Q3/R3) -> 280 | Q3: =阶段总盈亏!H3 -> 14 | R3: 0.05 | S3: 1.5 | T3: =SUM(O3*S3) -> 420 | U3: =SUM(S3/R3/C3) -> 1.2505211 | V3: =SUM(T3/Q3) -> 30 | W3: =T3/7 -> 60
B4: 第2周 | C4: =价格策略模拟!B3 -> 23.99 | D4: =价格策略模拟!C3 -> 0.25 | E4: =价格策略模拟!D3 -> 0 | F4: =SUM(C4*(1-D4-E4)) -> 17.9925 | O4: =SUM(Q4/R4) -> 420 | Q4: =阶段总盈亏!H4 -> 21 | R4: 0.05 | S4: 1.5 | T4: =SUM(O4*S4) -> 630 | U4: =SUM(S4/R4/C4) -> 1.2505211 | V4: =SUM(T4/Q4) -> 30 | W4: =T4/7 -> 90
B5: 第3周 | C5: =价格策略模拟!B3 -> 23.99 | D5: =价格策略模拟!C3 -> 0.25 | E5: =价格策略模拟!D3 -> 0 | F5: =SUM(C5*(1-D5-E5)) -> 17.9925 | O5: =SUM(Q5/R5) -> 560 | Q5: =阶段总盈亏!H5 -> 28 | R5: 0.05 | S5: 1.5 | T5: =SUM(O5*S5) -> 840 | U5: =SUM(S5/R5/C5) -> 1.2505211 | V5: =SUM(T5/Q5) -> 30 | W5: =T5/7 -> 120
B6: 第4周 | C6: =价格策略模拟!B3 -> 23.99 | D6: =价格策略模拟!C3 -> 0.25 | E6: =价格策略模拟!D3 -> 0 | F6: =SUM(C6*(1-D6-E6)) -> 17.9925 | O6: =SUM(Q6/R6) -> 700 | Q6: =阶段总盈亏!H6 -> 35 | R6: 0.05 | S6: 1.5 | T6: =SUM(O6*S6) -> 1050 | U6: =SUM(S6/R6/C6) -> 1.2505211 | V6: =SUM(T6/Q6) -> 30 | W6: =T6/7 -> 150
A7: 第二阶段 | B7: 第5周 | C7: =价格策略模拟!B4 -> 24.99 | D7: =价格策略模拟!C4 -> 0.2 | E7: =价格策略模拟!D4 -> 0 | F7: =SUM(C7*(1-D7-E7)) -> 19.992 | O7: =SUM(Q7/R7) -> 700 | Q7: =阶段总盈亏!H7 -> 42 | R7: 0.06 | S7: 1.4 | T7: =SUM(O7*S7) -> 980 | U7: =SUM(S7/R7/C7) -> 0.93370682 | V7: =SUM(T7/Q7) -> 23.333333 | W7: =T7/7 -> 140
B8: 第6周 | C8: =价格策略模拟!B4 -> 24.99 | D8: =价格策略模拟!C4 -> 0.2 | E8: =价格策略模拟!D4 -> 0 | F8: =SUM(C8*(1-D8-E8)) -> 19.992 | O8: =SUM(Q8/R8) -> 816.66667 | Q8: =阶段总盈亏!H8 -> 49 | R8: 0.06 | S8: 1.4 | T8: =SUM(O8*S8) -> 1143.3333 | U8: =SUM(S8/R8/C8) -> 0.93370682 | V8: =SUM(T8/Q8) -> 23.333333 | W8: =T8/7 -> 163.33333
B9: 第7周 | C9: =价格策略模拟!B4 -> 24.99 | D9: =价格策略模拟!C4 -> 0.2 | E9: =价格策略模拟!D4 -> 0 | F9: =SUM(C9*(1-D9-E9)) -> 19.992 | O9: =SUM(Q9/R9) -> 933.33333 | Q9: =阶段总盈亏!H9 -> 56 | R9: 0.06 | S9: 1.4 | T9: =SUM(O9*S9) -> 1306.6667 | U9: =SUM(S9/R9/C9) -> 0.93370682 | V9: =SUM(T9/Q9) -> 23.333333 | W9: =T9/7 -> 186.66667
B10: 第8周 | C10: =价格策略模拟!B4 -> 24.99 | D10: =价格策略模拟!C4 -> 0.2 | E10: =价格策略模拟!D4 -> 0 | F10: =SUM(C10*(1-D10-E10)) -> 19.992 | O10: =SUM(Q10/R10) -> 1050 | Q10: =阶段总盈亏!H10 -> 63 | R10: 0.06 | S10: 1.4 | T10: =SUM(O10*S10) -> 1470 | U10: =SUM(S10/R10/C10) -> 0.93370682 | V10: =SUM(T10/Q10) -> 23.333333 | W10: =T10/7 -> 210
A11: 第三阶段 | B11: 第9周 | C11: =价格策略模拟!B5 -> 25.99 | D11: =价格策略模拟!C5 -> 0.15 | E11: =价格策略模拟!D5 -> 0 | F11: =SUM(C11*(1-D11-E11)) -> 22.0915 | O11: =SUM(Q11/R11) -> 1000 | Q11: =阶段总盈亏!H11 -> 70 | R11: 0.07 | S11: 1.3 | T11: =SUM(O11*S11) -> 1300 | U11: =SUM(S11/R11/C11) -> 0.71456055 | V11: =SUM(T11/Q11) -> 18.571429 | W11: =T11/7 -> 185.71429
B12: 第10周 | C12: =价格策略模拟!B5 -> 25.99 | D12: =价格策略模拟!C5 -> 0.15 | E12: =价格策略模拟!D5 -> 0 | F12: =SUM(C12*(1-D12-E12)) -> 22.0915 | O12: =SUM(Q12/R12) -> 1100 | Q12: =阶段总盈亏!H12 -> 77 | R12: 0.07 | S12: 1.3 | T12: =SUM(O12*S12) -> 1430 | U12: =SUM(S12/R12/C12) -> 0.71456055 | V12: =SUM(T12/Q12) -> 18.571429 | W12: =T12/7 -> 204.28571
B13: 第11周 | C13: =价格策略模拟!B5 -> 25.99 | D13: =价格策略模拟!C5 -> 0.15 | E13: =价格策略模拟!D5 -> 0 | F13: =SUM(C13*(1-D13-E13)) -> 22.0915 | O13: =SUM(Q13/R13) -> 1200 | Q13: =阶段总盈亏!H13 -> 84 | R13: 0.07 | S13: 1.3 | T13: =SUM(O13*S13) -> 1560 | U13: =SUM(S13/R13/C13) -> 0.71456055 | V13: =SUM(T13/Q13) -> 18.571429 | W13: =T13/7 -> 222.85714
B14: 第12周 | C14: =价格策略模拟!B5 -> 25.99 | D14: =价格策略模拟!C5 -> 0.15 | E14: =价格策略模拟!D5 -> 0 | F14: =SUM(C14*(1-D14-E14)) -> 22.0915 | O14: =SUM(Q14/R14) -> 1300 | Q14: =阶段总盈亏!H14 -> 91 | R14: 0.07 | S14: 1.3 | T14: =SUM(O14*S14) -> 1690 | U14: =SUM(S14/R14/C14) -> 0.71456055 | V14: =SUM(T14/Q14) -> 18.571429 | W14: =T14/7 -> 241.42857
A15: 第四阶段 | B15: 第13周 | C15: =价格策略模拟!B6 -> 26.99 | D15: =价格策略模拟!C6 -> 0.1 | E15: =价格策略模拟!D6 -> 0 | F15: =SUM(C15*(1-D15-E15)) -> 24.291 | O15: =SUM(Q15/R15) -> 1225 | Q15: =阶段总盈亏!H15 -> 98 | R15: 0.08 | S15: 1.1 | T15: =SUM(O15*S15) -> 1347.5 | U15: =SUM(S15/R15/C15) -> 0.50944794 | V15: =SUM(T15/Q15) -> 13.75 | W15: =T15/7 -> 192.5
B16: 第14周 | C16: =价格策略模拟!B6 -> 26.99 | D16: =价格策略模拟!C6 -> 0.1 | E16: =价格策略模拟!D6 -> 0 | F16: =SUM(C16*(1-D16-E16)) -> 24.291 | O16: =SUM(Q16/R16) -> 1225 | Q16: =阶段总盈亏!H16 -> 98 | R16: 0.08 | S16: 1.1 | T16: =SUM(O16*S16) -> 1347.5 | U16: =SUM(S16/R16/C16) -> 0.50944794 | V16: =SUM(T16/Q16) -> 13.75 | W16: =T16/7 -> 192.5
B17: 第15周 | C17: =价格策略模拟!B6 -> 26.99 | D17: =价格策略模拟!C6 -> 0.1 | E17: =价格策略模拟!D6 -> 0 | F17: =SUM(C17*(1-D17-E17)) -> 24.291 | O17: =SUM(Q17/R17) -> 1312.5 | Q17: =阶段总盈亏!H17 -> 105 | R17: 0.08 | S17: 1.1 | T17: =SUM(O17*S17) -> 1443.75 | U17: =SUM(S17/R17/C17) -> 0.50944794 | V17: =SUM(T17/Q17) -> 13.75 | W17: =T17/7 -> 206.25
B18: 第16周 | C18: =价格策略模拟!B6 -> 26.99 | D18: =价格策略模拟!C6 -> 0.1 | E18: =价格策略模拟!D6 -> 0 | F18: =SUM(C18*(1-D18-E18)) -> 24.291 | O18: =SUM(Q18/R18) -> 1312.5 | Q18: =阶段总盈亏!H18 -> 105 | R18: 0.08 | S18: 1.1 | T18: =SUM(O18*S18) -> 1443.75 | U18: =SUM(S18/R18/C18) -> 0.50944794 | V18: =SUM(T18/Q18) -> 13.75 | W18: =T18/7 -> 206.25
A19: 第五阶段 | B19: 第17周 | C19: =价格策略模拟!B7 -> 27.99 | D19: =价格策略模拟!C7 -> 0.1 | E19: =价格策略模拟!D7 -> 0 | F19: =SUM(C19*(1-D19-E19)) -> 25.191 | O19: =SUM(Q19/R19) -> 1244.4444 | Q19: =阶段总盈亏!H19 -> 112 | R19: 0.09 | S19: 1 | T19: =SUM(O19*S19) -> 1244.4444 | U19: =SUM(S19/R19/C19) -> 0.39696717 | V19: =SUM(T19/Q19) -> 11.111111 | W19: =T19/7 -> 177.77778
B20: 第18周 | C20: =价格策略模拟!B7 -> 27.99 | D20: =价格策略模拟!C7 -> 0.1 | E20: =价格策略模拟!D7 -> 0 | F20: =SUM(C20*(1-D20-E20)) -> 25.191 | O20: =SUM(Q20/R20) -> 1244.4444 | Q20: =阶段总盈亏!H20 -> 112 | R20: 0.09 | S20: 1 | T20: =SUM(O20*S20) -> 1244.4444 | U20: =SUM(S20/R20/C20) -> 0.39696717 | V20: =SUM(T20/Q20) -> 11.111111 | W20: =T20/7 -> 177.77778
B21: 第19周 | C21: =价格策略模拟!B7 -> 27.99 | D21: =价格策略模拟!C7 -> 0.1 | E21: =价格策略模拟!D7 -> 0 | F21: =SUM(C21*(1-D21-E21)) -> 25.191 | O21: =SUM(Q21/R21) -> 1322.2222 | Q21: =阶段总盈亏!H21 -> 119 | R21: 0.09 | S21: 1 | T21: =SUM(O21*S21) -> 1322.2222 | U21: =SUM(S21/R21/C21) -> 0.39696717 | V21: =SUM(T21/Q21) -> 11.111111 | W21: =T21/7 -> 188.88889
B22: 第20周 | C22: =价格策略模拟!B7 -> 27.99 | D22: =价格策略模拟!C7 -> 0.1 | E22: =价格策略模拟!D7 -> 0 | F22: =SUM(C22*(1-D22-E22)) -> 25.191 | O22: =SUM(Q22/R22) -> 1322.2222 | Q22: =阶段总盈亏!H22 -> 119 | R22: 0.09 | S22: 1 | T22: =SUM(O22*S22) -> 1322.2222 | U22: =SUM(S22/R22/C22) -> 0.39696717 | V22: =SUM(T22/Q22) -> 11.111111 | W22: =T22/7 -> 188.88889
A23: 第六阶段 | B23: 第21周 | C23: =价格策略模拟!B8 -> 27.99 | D23: =价格策略模拟!C8 -> 0.1 | E23: =价格策略模拟!D8 -> 0 | F23: =SUM(C23*(1-D23-E23)) -> 25.191 | O23: =SUM(Q23/R23) -> 1260 | Q23: =阶段总盈亏!H23 -> 126 | R23: 0.1 | S23: 0.9 | T23: =SUM(O23*S23) -> 1134 | U23: =SUM(S23/R23/C23) -> 0.32154341 | V23: =SUM(T23/Q23) -> 9 | W23: =T23/7 -> 162
B24: 第22周 | C24: =价格策略模拟!B8 -> 27.99 | D24: =价格策略模拟!C8 -> 0.1 | E24: =价格策略模拟!D8 -> 0 | F24: =SUM(C24*(1-D24-E24)) -> 25.191 | O24: =SUM(Q24/R24) -> 1260 | Q24: =阶段总盈亏!H24 -> 126 | R24: 0.1 | S24: 0.9 | T24: =SUM(O24*S24) -> 1134 | U24: =SUM(S24/R24/C24) -> 0.32154341 | V24: =SUM(T24/Q24) -> 9 | W24: =T24/7 -> 162
B25: 第23周 | C25: =价格策略模拟!B8 -> 27.99 | D25: =价格策略模拟!C8 -> 0.1 | E25: =价格策略模拟!D8 -> 0 | F25: =SUM(C25*(1-D25-E25)) -> 25.191 | O25: =SUM(Q25/R25) -> 1330 | Q25: =阶段总盈亏!H25 -> 133 | R25: 0.1 | S25: 0.9 | T25: =SUM(O25*S25) -> 1197 | U25: =SUM(S25/R25/C25) -> 0.32154341 | V25: =SUM(T25/Q25) -> 9 | W25: =T25/7 -> 171
B26: 第24周 | C26: =价格策略模拟!B8 -> 27.99 | D26: =价格策略模拟!C8 -> 0.1 | E26: =价格策略模拟!D8 -> 0 | F26: =SUM(C26*(1-D26-E26)) -> 25.191 | O26: =SUM(Q26/R26) -> 1330 | Q26: =阶段总盈亏!H26 -> 133 | R26: 0.1 | S26: 0.9 | T26: =SUM(O26*S26) -> 1197 | U26: =SUM(S26/R26/C26) -> 0.32154341 | V26: =SUM(T26/Q26) -> 9 | W26: =T26/7 -> 171
A28: 广告真实数据
A29: 常规数据 | N29: 广告数据 | AB29: 实时更新 | AC29: 操作备注
A30: 阶段 | B30: 周 | C30: 价格 | D30: 站内 coupon | E30: 站内 code | F30: 折后价 | G30: 新品 榜单 | H30: 小类目 排名 | I30: 总 销量 | J30: 总访 问量 | K30: CVR | L30: 评论 数量 | M30: 评分 | N30: 曝光量 | O30: 点击量 | P30: CTR | Q30: 广告单 | R30: CVR | S30: 平均 CPC | T30: 花费 | U30: ACOS | V30: CPA | W30: 日均 广告费 | X30: 自然 访问 | Y30: 自然 订单 | Z30: 自然 单占比 | AA30: 最终 盈亏 | AB30: 质量分 | AC30: 运营调整 | AD30: 广告操作
A31: 第一阶段 | B31: 第1周
B32: 第2周
B33: 第3周
B34: 第4周
A35: 第二阶段 | B35: 第5周
B36: 第6周
B37: 第7周
B38: 第8周
A39: 第三阶段 | B39: 第9周
B40: 第10周
B41: 第11周
...

Sheet 毛利模拟盈亏
A1: 每日盈亏数据预估
A2: 阶段 | B2: 日期 | C2: 定价 | D2: coupon | E2: code | F2: 折后价 | G2: FBA 配送费 | H2: 亚马逊 佣金 | I2: 账号 回款 | J2: 仓储费+入库配置费 | K2: coupon 费用 | L2: 产品 成本 | M2: 物流费 | N2: 退货成本(公式后面加的是单套产品的移除费） | O2: 退货率 | P2: 每单平摊 退货成本 | Q2: 每单 毛利 | R2: 毛利率 | S2: 订单 数量 | T2: 阶段 订单 亏损 | U2: 阶段 订单 总盈亏 | V2: 每周 销售额
A3: 第一阶段 | B3: 第1周 | C3: =价格策略模拟!B3 -> 23.99 | D3: =价格策略模拟!C3 -> 0.25 | E3: =价格策略模拟!D3 -> 0 | F3: =SUM(C3*(1-D3-E3)) -> 17.9925 | G3: 5.5 | H3: =SUM(F3*15%) -> 2.698875 | I3: =SUM(F3-G3-H3) -> 9.793625 | J3: =0.13+0.21 -> 0.34 | K3: 0.6 | L3: 4.5 | M3: 1 | N3: =SUM(20%*15%*F3+G3+J3+L3+M3+1.04) -> 12.919775 | O3: 0.15 | P3: =SUM(N3*O3/(1-O3)) -> 2.2799603 | Q3: =SUM(I3-J3-K3-L3-M3-P3) -> 1.0736647 | R3: =SUM(Q3/C3) -> 0.044754677 | S3: =阶段总盈亏!I3 -> 14 | T3: =SUM(Q3*S3) -> 15.031306 | U3: =SUM(T3:T3) -> 15.031306 | V3: =S3*C3 -> 335.86
B4: 第2周 | C4: =价格策略模拟!B3 -> 23.99 | D4: =价格策略模拟!C3 -> 0.25 | E4: =价格策略模拟!D3 -> 0 | F4: =SUM(C4*(1-D4-E4)) -> 17.9925 | G4: 5.5 | H4: =SUM(F4*15%) -> 2.698875 | I4: =SUM(F4-G4-H4) -> 9.793625 | J4: =0.13+0.21 -> 0.34 | K4: 0.6 | L4: 4.5 | M4: 1 | N4: =SUM(20%*15%*F4+G4+J4+L4+M4+1.04) -> 12.919775 | O4: 0.15 | P4: =SUM(N4*O4/(1-O4)) -> 2.2799603 | Q4: =SUM(I4-J4-K4-L4-M4-P4) -> 1.0736647 | R4: =SUM(Q4/C4) -> 0.044754677 | S4: =阶段总盈亏!I4 -> 28 | T4: =SUM(Q4*S4) -> 30.062612 | U4: =SUM(T4:T4) -> 30.062612 | V4: =S4*C4 -> 671.72
B5: 第3周 | C5: =价格策略模拟!B3 -> 23.99 | D5: =价格策略模拟!C3 -> 0.25 | E5: =价格策略模拟!D3 -> 0 | F5: =SUM(C5*(1-D5-E5)) -> 17.9925 | G5: 5.5 | H5: =SUM(F5*15%) -> 2.698875 | I5: =SUM(F5-G5-H5) -> 9.793625 | J5: =0.13+0.21 -> 0.34 | K5: 0.6 | L5: 4.5 | M5: 1 | N5: =SUM(20%*15%*F5+G5+J5+L5+M5+1.04) -> 12.919775 | O5: 0.15 | P5: =SUM(N5*O5/(1-O5)) -> 2.2799603 | Q5: =SUM(I5-J5-K5-L5-M5-P5) -> 1.0736647 | R5: =SUM(Q5/C5) -> 0.044754677 | S5: =阶段总盈亏!I5 -> 42 | T5: =SUM(Q5*S5) -> 45.093918 | U5: =SUM(T5:T5) -> 45.093918 | V5: =S5*C5 -> 1007.58
B6: 第4周 | C6: =价格策略模拟!B3 -> 23.99 | D6: =价格策略模拟!C3 -> 0.25 | E6: =价格策略模拟!D3 -> 0 | F6: =SUM(C6*(1-D6-E6)) -> 17.9925 | G6: 5.5 | H6: =SUM(F6*15%) -> 2.698875 | I6: =SUM(F6-G6-H6) -> 9.793625 | J6: =0.13+0.21 -> 0.34 | K6: 0.6 | L6: 4.5 | M6: 1 | N6: =SUM(20%*15%*F6+G6+J6+L6+M6+1.04) -> 12.919775 | O6: 0.15 | P6: =SUM(N6*O6/(1-O6)) -> 2.2799603 | Q6: =SUM(I6-J6-K6-L6-M6-P6) -> 1.0736647 | R6: =SUM(Q6/C6) -> 0.044754677 | S6: =阶段总盈亏!I6 -> 56 | T6: =SUM(Q6*S6) -> 60.125224 | U6: =SUM(T6:T6) -> 60.125224 | V6: =S6*C6 -> 1343.44
A7: 第二阶段 | B7: 第5周 | C7: =价格策略模拟!B4 -> 24.99 | D7: =价格策略模拟!C4 -> 0.2 | E7: =价格策略模拟!D4 -> 0 | F7: =SUM(C7*(1-D7-E7)) -> 19.992 | G7: 5.5 | H7: =SUM(F7*15%) -> 2.9988 | I7: =SUM(F7-G7-H7) -> 11.4932 | J7: =0.13+0.21 -> 0.34 | K7: 0.6 | L7: 4.5 | M7: 1 | N7: =SUM(20%*15%*F7+G7+J7+L7+M7+1.04) -> 12.97976 | O7: 0.15 | P7: =SUM(N7*O7/(1-O7)) -> 2.2905459 | Q7: =SUM(I7-J7-K7-L7-M7-P7) -> 2.7626541 | R7: =SUM(Q7/C7) -> 0.11055038 | S7: =阶段总盈亏!I7 -> 70 | T7: =SUM(Q7*S7) -> 193.38579 | U7: =SUM(T7:T7) -> 193.38579 | V7: =S7*C7 -> 1749.3
B8: 第6周 | C8: =价格策略模拟!B4 -> 24.99 | D8: =价格策略模拟!C4 -> 0.2 | E8: =价格策略模拟!D4 -> 0 | F8: =SUM(C8*(1-D8-E8)) -> 19.992 | G8: 5.5 | H8: =SUM(F8*15%) -> 2.9988 | I8: =SUM(F8-G8-H8) -> 11.4932 | J8: =0.13+0.21 -> 0.34 | K8: 0.6 | L8: 4.5 | M8: 1 | N8: =SUM(20%*15%*F8+G8+J8+L8+M8+1.04) -> 12.97976 | O8: 0.15 | P8: =SUM(N8*O8/(1-O8)) -> 2.2905459 | Q8: =SUM(I8-J8-K8-L8-M8-P8) -> 2.7626541 | R8: =SUM(Q8/C8) -> 0.11055038 | S8: =阶段总盈亏!I8 -> 84 | T8: =SUM(Q8*S8) -> 232.06295 | U8: =SUM(T8:T8) -> 232.06295 | V8: =S8*C8 -> 2099.16
B9: 第7周 | C9: =价格策略模拟!B4 -> 24.99 | D9: =价格策略模拟!C4 -> 0.2 | E9: =价格策略模拟!D4 -> 0 | F9: =SUM(C9*(1-D9-E9)) -> 19.992 | G9: 5.5 | H9: =SUM(F9*15%) -> 2.9988 | I9: =SUM(F9-G9-H9) -> 11.4932 | J9: =0.13+0.21 -> 0.34 | K9: 0.6 | L9: 4.5 | M9: 1 | N9: =SUM(20%*15%*F9+G9+J9+L9+M9+1.04) -> 12.97976 | O9: 0.15 | P9: =SUM(N9*O9/(1-O9)) -> 2.2905459 | Q9: =SUM(I9-J9-K9-L9-M9-P9) -> 2.7626541 | R9: =SUM(Q9/C9) -> 0.11055038 | S9: =阶段总盈亏!I9 -> 98 | T9: =SUM(Q9*S9) -> 270.7401 | U9: =SUM(T9:T9) -> 270.7401 | V9: =S9*C9 -> 2449.02
B10: 第8周 | C10: =价格策略模拟!B4 -> 24.99 | D10: =价格策略模拟!C4 -> 0.2 | E10: =价格策略模拟!D4 -> 0 | F10: =SUM(C10*(1-D10-E10)) -> 19.992 | G10: 5.5 | H10: =SUM(F10*15%) -> 2.9988 | I10: =SUM(F10-G10-H10) -> 11.4932 | J10: =0.13+0.21 -> 0.34 | K10: 0.6 | L10: 4.5 | M10: 1 | N10: =SUM(20%*15%*F10+G10+J10+L10+M10+1.04) -> 12.97976 | O10: 0.15 | P10: =SUM(N10*O10/(1-O10)) -> 2.2905459 | Q10: =SUM(I10-J10-K10-L10-M10-P10) -> 2.7626541 | R10: =SUM(Q10/C10) -> 0.11055038 | S10: =阶段总盈亏!I10 -> 112 | T10: =SUM(Q10*S10) -> 309.41726 | U10: =SUM(T10:T10) -> 309.41726 | V10: =S10*C10 -> 2798.88
A11: 第三阶段 | B11: 第9周 | C11: =价格策略模拟!B5 -> 25.99 | D11: =价格策略模拟!C5 -> 0.15 | E11: =价格策略模拟!D5 -> 0 | F11: =SUM(C11*(1-D11-E11)) -> 22.0915 | G11: 5.5 | H11: =SUM(F11*15%) -> 3.313725 | I11: =SUM(F11-G11-H11) -> 13.277775 | J11: =0.13+0.21 -> 0.34 | K11: 0.6 | L11: 4.5 | M11: 1 | N11: =SUM(20%*15%*F11+G11+J11+L11+M11+1.04) -> 13.042745 | O11: 0.15 | P11: =SUM(N11*O11/(1-O11)) -> 2.3016609 | Q11: =SUM(I11-J11-K11-L11-M11-P11) -> 4.5361141 | R11: =SUM(Q11/C11) -> 0.17453306 | S11: =阶段总盈亏!I11 -> 126 | T11: =SUM(Q11*S11) -> 571.55038 | U11: =SUM(T11:T11) -> 571.55038 | V11: =S11*C11 -> 3274.74
B12: 第10周 | C12: =价格策略模拟!B5 -> 25.99 | D12: =价格策略模拟!C5 -> 0.15 | E12: =价格策略模拟!D5 -> 0 | F12: =SUM(C12*(1-D12-E12)) -> 22.0915 | G12: 5.5 | H12: =SUM(F12*15%) -> 3.313725 | I12: =SUM(F12-G12-H12) -> 13.277775 | J12: =0.13+0.21 -> 0.34 | K12: 0.6 | L12: 4.5 | M12: 1 | N12: =SUM(20%*15%*F12+G12+J12+L12+M12+1.04) -> 13.042745 | O12: 0.15 | P12: =SUM(N12*O12/(1-O12)) -> 2.3016609 | Q12: =SUM(I12-J12-K12-L12-M12-P12) -> 4.5361141 | R12: =SUM(Q12/C12) -> 0.17453306 | S12: =阶段总盈亏!I12 -> 140 | T12: =SUM(Q12*S12) -> 635.05598 | U12: =SUM(T12:T12) -> 635.05598 | V12: =S12*C12 -> 3638.6
B13: 第11周 | C13: =价格策略模拟!B5 -> 25.99 | D13: =价格策略模拟!C5 -> 0.15 | E13: =价格策略模拟!D5 -> 0 | F13: =SUM(C13*(1-D13-E13)) -> 22.0915 | G13: 5.5 | H13: =SUM(F13*15%) -> 3.313725 | I13: =SUM(F13-G13-H13) -> 13.277775 | J13: =0.13+0.21 -> 0.34 | K13: 0.6 | L13: 4.5 | M13: 1 | N13: =SUM(20%*15%*F13+G13+J13+L13+M13+1.04) -> 13.042745 | O13: 0.15 | P13: =SUM(N13*O13/(1-O13)) -> 2.3016609 | Q13: =SUM(I13-J13-K13-L13-M13-P13) -> 4.5361141 | R13: =SUM(Q13/C13) -> 0.17453306 | S13: =阶段总盈亏!I13 -> 154 | T13: =SUM(Q13*S13) -> 698.56157 | U13: =SUM(T13:T13) -> 698.56157 | V13: =S13*C13 -> 4002.46
B14: 第12周 | C14: =价格策略模拟!B5 -> 25.99 | D14: =价格策略模拟!C5 -> 0.15 | E14: =价格策略模拟!D5 -> 0 | F14: =SUM(C14*(1-D14-E14)) -> 22.0915 | G14: 5.5 | H14: =SUM(F14*15%) -> 3.313725 | I14: =SUM(F14-G14-H14) -> 13.277775 | J14: =0.13+0.21 -> 0.34 | K14: 0.6 | L14: 4.5 | M14: 1 | N14: =SUM(20%*15%*F14+G14+J14+L14+M14+1.04) -> 13.042745 | O14: 0.15 | P14: =SUM(N14*O14/(1-O14)) -> 2.3016609 | Q14: =SUM(I14-J14-K14-L14-M14-P14) -> 4.5361141 | R14: =SUM(Q14/C14) -> 0.17453306 | S14: =阶段总盈亏!I14 -> 168 | T14: =SUM(Q14*S14) -> 762.06717 | U14: =SUM(T14:T14) -> 762.06717 | V14: =S14*C14 -> 4366.32
A15: 第四阶段 | B15: 第13周 | C15: =价格策略模拟!B6 -> 26.99 | D15: =价格策略模拟!C6 -> 0.1 | E15: =价格策略模拟!D6 -> 0 | F15: =SUM(C15*(1-D15-E15)) -> 24.291 | G15: 5.5 | H15: =SUM(F15*15%) -> 3.64365 | I15: =SUM(F15-G15-H15) -> 15.14735 | J15: =0.13+0.21 -> 0.34 | K15: 0.6 | L15: 4.5 | M15: 1 | N15: =SUM(20%*15%*F15+G15+J15+L15+M15+1.04) -> 13.10873 | O15: 0.15 | P15: =SUM(N15*O15/(1-O15)) -> 2.3133053 | Q15: =SUM(I15-J15-K15-L15-M15-P15) -> 6.3940447 | R15: =SUM(Q15/C15) -> 0.23690421 | S15: =阶段总盈亏!I15 -> 182 | T15: =SUM(Q15*S15) -> 1163.7161 | U15: =SUM(T15:T15) -> 1163.7161 | V15: =S15*C15 -> 4912.18
B16: 第14周 | C16: =价格策略模拟!B6 -> 26.99 | D16: =价格策略模拟!C6 -> 0.1 | E16: =价格策略模拟!D6 -> 0 | F16: =SUM(C16*(1-D16-E16)) -> 24.291 | G16: 5.5 | H16: =SUM(F16*15%) -> 3.64365 | I16: =SUM(F16-G16-H16) -> 15.14735 | J16: =0.13+0.21 -> 0.34 | K16: 0.6 | L16: 4.5 | M16: 1 | N16: =SUM(20%*15%*F16+G16+J16+L16+M16+1.04) -> 13.10873 | O16: 0.15 | P16: =SUM(N16*O16/(1-O16)) -> 2.3133053 | Q16: =SUM(I16-J16-K16-L16-M16-P16) -> 6.3940447 | R16: =SUM(Q16/C16) -> 0.23690421 | S16: =阶段总盈亏!I16 -> 196 | T16: =SUM(Q16*S16) -> 1253.2328 | U16: =SUM(T16:T16) -> 1253.2328 | V16: =S16*C16 -> 5290.04
B17: 第15周 | C17: =价格策略模拟!B6 -> 26.99 | D17: =价格策略模拟!C6 -> 0.1 | E17: =价格策略模拟!D6 -> 0 | F17: =SUM(C17*(1-D17-E17)) -> 24.291 | G17: 5.5 | H17: =SUM(F17*15%) -> 3.64365 | I17: =SUM(F17-G17-H17) -> 15.14735 | J17: =0.13+0.21 -> 0.34 | K17: 0.6 | L17: 4.5 | M17: 1 | N17: =SUM(20%*15%*F17+G17+J17+L17+M17+1.04) -> 13.10873 | O17: 0.15 | P17: =SUM(N17*O17/(1-O17)) -> 2.3133053 | Q17: =SUM(I17-J17-K17-L17-M17-P17) -> 6.3940447 | R17: =SUM(Q17/C17) -> 0.23690421 | S17: =阶段总盈亏!I17 -> 210 | T17: =SUM(Q17*S17) -> 1342.7494 | U17: =SUM(T17:T17) -> 1342.7494 | V17: =S17*C17 -> 5667.9
B18: 第16周 | C18: =价格策略模拟!B6 -> 26.99 | D18: =价格策略模拟!C6 -> 0.1 | E18: =价格策略模拟!D6 -> 0 | F18: =SUM(C18*(1-D18-E18)) -> 24.291 | G18: 5.5 | H18: =SUM(F18*15%) -> 3.64365 | I18: =SUM(F18-G18-H18) -> 15.14735 | J18: =0.13+0.21 -> 0.34 | K18: 0.6 | L18: 4.5 | M18: 1 | N18: =SUM(20%*15%*F18+G18+J18+L18+M18+1.04) -> 13.10873 | O18: 0.15 | P18: =SUM(N18*O18/(1-O18)) -> 2.3133053 | Q18: =SUM(I18-J18-K18-L18-M18-P18) -> 6.3940447 | R18: =SUM(Q18/C18) -> 0.23690421 | S18: =阶段总盈亏!I18 -> 224 | T18: =SUM(Q18*S18) -> 1432.266 | U18: =SUM(T18:T18) -> 1432.266 | V18: =S18*C18 -> 6045.76
A19: 第五阶段 | B19: 第17周 | C19: =价格策略模拟!B7 -> 27.99 | D19: =价格策略模拟!C7 -> 0.1 | E19: =价格策略模拟!D7 -> 0 | F19: =SUM(C19*(1-D19-E19)) -> 25.191 | G19: 5.5 | H19: =SUM(F19*15%) -> 3.77865 | I19: =SUM(F19-G19-H19) -> 15.91235 | J19: =0.13+0.21 -> 0.34 | K19: 0.6 | L19: 4.5 | M19: 1 | N19: =SUM(20%*15%*F19+G19+J19+L19+M19+1.04) -> 13.13573 | O19: 0.15 | P19: =SUM(N19*O19/(1-O19)) -> 2.31807 | Q19: =SUM(I19-J19-K19-L19-M19-P19) -> 7.15428 | R19: =SUM(Q19/C19) -> 0.25560129 | S19: =阶段总盈亏!I19 -> 238 | T19: =SUM(Q19*S19) -> 1702.7186 | U19: =SUM(T19:T19) -> 1702.7186 | V19: =S19*C19 -> 6661.62
B20: 第18周 | C20: =价格策略模拟!B7 -> 27.99 | D20: =价格策略模拟!C7 -> 0.1 | E20: =价格策略模拟!D7 -> 0 | F20: =SUM(C20*(1-D20-E20)) -> 25.191 | G20: 5.5 | H20: =SUM(F20*15%) -> 3.77865 | I20: =SUM(F20-G20-H20) -> 15.91235 | J20: =0.13+0.21 -> 0.34 | K20: 0.6 | L20: 4.5 | M20: 1 | N20: =SUM(20%*15%*F20+G20+J20+L20+M20+1.04) -> 13.13573 | O20: 0.15 | P20: =SUM(N20*O20/(1-O20)) -> 2.31807 | Q20: =SUM(I20-J20-K20-L20-M20-P20) -> 7.15428 | R20: =SUM(Q20/C20) -> 0.25560129 | S20: =阶段总盈亏!I20 -> 252 | T20: =SUM(Q20*S20) -> 1802.8786 | U20: =SUM(T20:T20) -> 1802.8786 | V20: =S20*C20 -> 7053.48
B21: 第19周 | C21: =价格策略模拟!B7 -> 27.99 | D21: =价格策略模拟!C7 -> 0.1 | E21: =价格策略模拟!D7 -> 0 | F21: =SUM(C21*(1-D21-E21)) -> 25.191 | G21: 5.5 | H21: =SUM(F21*15%) -> 3.77865 | I21: =SUM(F21-G21-H21) -> 15.91235 | J21: =0.13+0.21 -> 0.34 | K21: 0.6 | L21: 4.5 | M21: 1 | N21: =SUM(20%*15%*F21+G21+J21+L21+M21+1.04) -> 13.13573 | O21: 0.15 | P21: =SUM(N21*O21/(1-O21)) -> 2.31807 | Q21: =SUM(I21-J21-K21-L21-M21-P21) -> 7.15428 | R21: =SUM(Q21/C21) -> 0.25560129 | S21: =阶段总盈亏!I21 -> 266 | T21: =SUM(Q21*S21) -> 1903.0385 | U21: =SUM(T21:T21) -> 1903.0385 | V21: =S21*C21 -> 7445.34
B22: 第20周 | C22: =价格策略模拟!B7 -> 27.99 | D22: =价格策略模拟!C7 -> 0.1 | E22: =价格策略模拟!D7 -> 0 | F22: =SUM(C22*(1-D22-E22)) -> 25.191 | G22: 5.5 | H22: =SUM(F22*15%) -> 3.77865 | I22: =SUM(F22-G22-H22) -> 15.91235 | J22: =0.13+0.21 -> 0.34 | K22: 0.6 | L22: 4.5 | M22: 1 | N22: =SUM(20%*15%*F22+G22+J22+L22+M22+1.04) -> 13.13573 | O22: 0.15 | P22: =SUM(N22*O22/(1-O22)) -> 2.31807 | Q22: =SUM(I22-J22-K22-L22-M22-P22) -> 7.15428 | R22: =SUM(Q22/C22) -> 0.25560129 | S22: =阶段总盈亏!I22 -> 280 | T22: =SUM(Q22*S22) -> 2003.1984 | U22: =SUM(T22:T22) -> 2003.1984 | V22: =S22*C22 -> 7837.2
A23: 第六阶段 | B23: 第21周 | C23: =价格策略模拟!B8 -> 27.99 | D23: =价格策略模拟!C8 -> 0.1 | E23: =价格策略模拟!D8 -> 0 | F23: =SUM(C23*(1-D23-E23)) -> 25.191 | G23: 5.5 | H23: =SUM(F23*15%) -> 3.77865 | I23: =SUM(F23-G23-H23) -> 15.91235 | J23: =0.13+0.21 -> 0.34 | K23: 0 | L23: 4.5 | M23: 1 | N23: =SUM(20%*15%*F23+G23+J23+L23+M23+1.04) -> 13.13573 | O23: 0.15 | P23: =SUM(N23*O23/(1-O23)) -> 2.31807 | Q23: =SUM(I23-J23-K23-L23-M23-P23) -> 7.75428 | R23: =SUM(Q23/C23) -> 0.27703751 | S23: =阶段总盈亏!I23 -> 294 | T23: =SUM(Q23*S23) -> 2279.7583 | U23: =SUM(T23:T23) -> 2279.7583 | V23: =S23*C23 -> 8229.06
B24: 第22周 | C24: =价格策略模拟!B8 -> 27.99 | D24: =价格策略模拟!C8 -> 0.1 | E24: =价格策略模拟!D8 -> 0 | F24: =SUM(C24*(1-D24-E24)) -> 25.191 | G24: 5.5 | H24: =SUM(F24*15%) -> 3.77865 | I24: =SUM(F24-G24-H24) -> 15.91235 | J24: =0.13+0.21 -> 0.34 | K24: 0 | L24: 4.5 | M24: 1 | N24: =SUM(20%*15%*F24+G24+J24+L24+M24+1.04) -> 13.13573 | O24: 0.15 | P24: =SUM(N24*O24/(1-O24)) -> 2.31807 | Q24: =SUM(I24-J24-K24-L24-M24-P24) -> 7.75428 | R24: =SUM(Q24/C24) -> 0.27703751 | S24: =阶段总盈亏!I24 -> 308 | T24: =SUM(Q24*S24) -> 2388.3182 | U24: =SUM(T24:T24) -> 2388.3182 | V24: =S24*C24 -> 8620.92
B25: 第23周 | C25: =价格策略模拟!B8 -> 27.99 | D25: =价格策略模拟!C8 -> 0.1 | E25: =价格策略模拟!D8 -> 0 | F25: =SUM(C25*(1-D25-E25)) -> 25.191 | G25: 5.5 | H25: =SUM(F25*15%) -> 3.77865 | I25: =SUM(F25-G25-H25) -> 15.91235 | J25: =0.13+0.21 -> 0.34 | K25: 0 | L25: 4.5 | M25: 1 | N25: =SUM(20%*15%*F25+G25+J25+L25+M25+1.04) -> 13.13573 | O25: 0.15 | P25: =SUM(N25*O25/(1-O25)) -> 2.31807 | Q25: =SUM(I25-J25-K25-L25-M25-P25) -> 7.75428 | R25: =SUM(Q25/C25) -> 0.27703751 | S25: =阶段总盈亏!I25 -> 322 | T25: =SUM(Q25*S25) -> 2496.8782 | U25: =SUM(T25:T25) -> 2496.8782 | V25: =S25*C25 -> 9012.78
B26: 第24周 | C26: =价格策略模拟!B8 -> 27.99 | D26: =价格策略模拟!C8 -> 0.1 | E26: =价格策略模拟!D8 -> 0 | F26: =SUM(C26*(1-D26-E26)) -> 25.191 | G26: 5.5 | H26: =SUM(F26*15%) -> 3.77865 | I26: =SUM(F26-G26-H26) -> 15.91235 | J26: =0.13+0.21 -> 0.34 | K26: 0 | L26: 4.5 | M26: 1 | N26: =SUM(20%*15%*F26+G26+J26+L26+M26+1.04) -> 13.13573 | O26: 0.15 | P26: =SUM(N26*O26/(1-O26)) -> 2.31807 | Q26: =SUM(I26-J26-K26-L26-M26-P26) -> 7.75428 | R26: =SUM(Q26/C26) -> 0.27703751 | S26: =阶段总盈亏!I26 -> 336 | T26: =SUM(Q26*S26) -> 2605.4381 | U26: =SUM(T26:T26) -> 2605.4381 | V26: =S26*C26 -> 9404.64
A28: 每日盈亏真实数据
A29: 第一阶段 | B29: 第1周
B30: 第2周
B31: 第3周
B32: 第4周
A33: 第二阶段 | B33: 第5周
B34: 第6周
B35: 第7周
B36: 第8周
A37: 第三阶段 | B37: 第9周
B38: 第10周
B39: 第11周
B40: 第12周
A41: 第四阶段 | B41: 第13周
...

Sheet 关键词词库
A1: # | B1: 关键词 | C1: 埋入单词根 | D1: 埋入关键词位置 | E1: 组合 | F1: 关键词归类 | G1: 翻译 | H1: 相关性 | I1: 周ABA 排名 | J1: 周搜索量 | K1: 关键词 词根归类 | L1: 关键词 大小归类 | M1: 点击 集中度 | N1: 前三ASIN 转化总占比 | O1: CPC （广告竞价） | P1: CVR (点击转化率) | Q1: 客单价 （平均值） | R1: ACOS
A2: 429 | B2: dash cam | C2: dash和cam | D2: 标题 | E2: 标题有序组合 | F2: 共性关键词 | G2: 行车记录仪 | H2: 中相关 | I2: 401 | J2: 160890 | K2: dash cam | L2: 大词 | M2: 0.3668 | N2: 0.2278 | O2: 3 | P2: 0.0447 | Q2: 68.89 | R2: 0.9746
A3: 156 | B3: dash camera for cars | C3: camera和cars | D3: 标题 | E3: 标题有序组合 | F3: 共性关键词 | G3: 汽车破折号摄像头 | H3: 中相关 | I3: 4603 | J3: 42727 | K3: dash cam | L3: 大词 | M3: 0.3783 | N3: 0.1987 | O3: 2.13 | P3: 0.0439 | Q3: 68.89 | R3: 0.7048
A4: 225 | B4: dashcam | C4: dashcam | D4: 标题 | E4: 标题有序组合 | F4: 共性关键词 | G4: 行车记录仪 | H4: 中相关 | I4: 9483 | J4: 23045 | L4: 大词 | M4: 0.3925 | N4: 0.265 | O4: 2.34 | P4: 0.0479 | Q4: 68.89 | R4: 0.7089
A5: 316 | B5: garmin dash cam | F5: 属性关键词 | G5: 佳明行车记录仪 | H5: 高相关 | I5: 14151 | J5: 16909 | K5: dash cam | M5: #N/A | N5: #N/A | O5: 2.06 | P5: 0.0289 | Q5: 68.89 | R5: 1.0361
A6: 167 | B6: car decals | G6: 汽车贴纸 | H6: 低相关 | I6: 17655 | J6: 14141
A7: 311 | B7: car camera | D7: 标题 | E7: 标题有序组合 | F7: 共性关键词 | G7: 汽车摄像头 | H7: 中相关 | I7: 17978 | J7: 13919 | K7: car camera | L7: 大词 | M7: #N/A | N7: #N/A | O7: 2.28 | P7: 0.0385 | Q7: 68.89 | R7: 0.86
A8: 46 | B8: dash camera | D8: 标题 | E8: 标题有序组合 | F8: 共性关键词 | G8: 行车记录仪 | H8: 中相关 | I8: 18214 | J8: 13747 | K8: dash cam | L8: 大词 | M8: 0.3975 | N8: 0.2633 | O8: 1.86 | P8: 0.043 | Q8: 68.89 | R8: 0.6284
A9: 387 | B9: car dash cam | D9: 五点 | E9: 标题无序组合出来 | F9: 共性关键词 | G9: 汽车行车记录仪 | H9: 中相关 | I9: 23785 | J9: 10949 | K9: dash cam | L9: 大词 | M9: 0.4541 | N9: 0.2681 | O9: 1.96 | P9: 0.0412 | Q9: 68.89 | R9: 0.69
A10: 15 | B10: viofo dash cam | F10: 属性关键词 | G10: Viofo行车记录仪 | H10: 中相关 | I10: 33426 | J10: 8131 | K10: dash cam | M10: #N/A | N10: #N/A | O10: 3.19 | P10: 0.0401 | Q10: 68.89 | R10: 1.155
A11: 33 | B11: wireless dash cam | F11: 属性关键词 | G11: 无线行车记录仪 | H11: 中相关 | I11: 40550 | J11: 6858 | K11: dash cam | L11: 大词 | M11: 0.3847 | N11: 0.2361 | O11: 1.66 | P11: 0.0181 | Q11: 68.89 | R11: 1.3322
A12: 110 | B12: vantrue dash cam | G12: Vantrue行车记录仪 | H12: 低相关 | I12: 45263 | J12: 6217
A13: 180 | B13: camara de seguridad para carro | G13: 卡马拉-德塞古里达帕拉卡罗 | H13: 低相关 | I13: 47618 | J13: 5949
A14: 362 | B14: garmin dash cam mini 2 | F14: 属性关键词 | G14: garmin迷你2行车记录仪 | H14: 中相关 | I14: 48402 | J14: 5863 | K14: dash cam | M14: #N/A | N14: #N/A | O14: 2.74 | P14: 0.0615 | Q14: 68.89 | R14: 0.647
A15: 386 | B15: dashcams for cars | D15: 标题 | E15: 标题无序组合出来 | F15: 共性关键词 | G15: 汽车行车记录仪 | H15: 中相关 | I15: 48493 | J15: 5853 | L15: 大词 | M15: 0.4686 | N15: 0.3373 | O15: 2.76 | P15: 0.045 | Q15: 68.89 | R15: 0.8897
A16: 37 | B16: camera for car | D16: 五点 | E16: 标题无序组合出来 | F16: 共性关键词 | G16: 汽车相机 | H16: 中相关 | I16: 50021 | J16: 5691 | L16: 大词 | M16: #N/A | N16: #N/A | O16: 2.17 | P16: 0.0328 | Q16: 68.89 | R16: 0.961
A17: 63 | B17: nexar dash cam | G17: Nexar行车记录仪 | H17: 低相关 | I17: 50309 | J17: 5661
A18: 104 | B18: rove r2-4k car dash cam | F18: 属性关键词 | G18: 罗夫R2-4K汽车行车记录仪 | H18: 中相关 | I18: 59257 | J18: 4878 | K18: dash cam | M18: #N/A | N18: #N/A | O18: 1.25 | P18: 0.0752 | Q18: 68.89 | R18: 0.2413
A19: 165 | B19: dash cam front | F19: 属性关键词 | G19: 前置行车记录仪 | H19: 中相关 | I19: 61556 | J19: 4717 | K19: dash cam | L19: 大词 | M19: 0.252 | N19: 0.1378 | O19: 1.57 | P19: 0.0544 | Q19: 68.89 | R19: 0.419
A20: 384 | B20: top rated dash camera | F20: 属性关键词 | G20: 顶级仪表板摄像机 | H20: 中相关 | I20: 69217 | J20: 4242 | K20: dash cam | L20: 大词 | M20: 0.4711 | N20: 0.3112 | O20: 1.99 | P20: 0.0415 | Q20: 68.89 | R20: 0.6958
A21: 64 | B21: 70mai dash cam | G21: 70迈行车记录仪 | H21: 低相关 | I21: 73077 | J21: 4040
A22: 151 | B22: garmin mini 2 dash cam | F22: 属性关键词 | G22: garmin mini 2 dash cam | H22: 中相关 | I22: 74688 | J22: 3959 | K22: dash cam | M22: #N/A | N22: #N/A | O22: 2.26 | P22: 0.0743 | Q22: 68.89 | R22: 0.4417
A23: 409 | B23: redtiger dash cam | G23: 红虎行车记录仪 | H23: 低相关 | I23: 82096 | J23: 3631
A24: 238 | B24: viofo | G24: viofo | H24: 低相关 | I24: 85472 | J24: 3499
A25: 437 | B25: dash cams | G25: 行车记录仪 | H25: 低相关 | I25: 87963 | J25: 3409
A26: 200 | B26: viofo a119 v3 | F26: 属性关键词 | G26: 维欧福A119 V3 | H26: 中相关 | I26: 89292 | J26: 3363 | M26: #N/A | N26: #N/A | O26: 2.5 | P26: 0.0415 | Q26: 68.89 | R26: 0.8741
A27: 91 | B27: 4k dash cam | F27: 属性关键词 | G27: 4k行车记录仪 | H27: 中相关 | I27: 103211 | J27: 2944 | K27: dash cam | L27: 中词 | M27: 0.2917 | N27: 0.1814 | O27: 2.49 | P27: 0.0257 | Q27: 68.89 | R27: 1.4052
A28: 198 | B28: dash cam 4k | F28: 属性关键词 | G28: 4K行车记录仪 | H28: 中相关 | I28: 103387 | J28: 2939 | K28: dash cam | L28: 中词 | M28: 0.2845 | N28: 0.175 | O28: 1.68 | P28: 0.0327 | Q28: 68.89 | R28: 0.7462
A29: 357 | B29: vantrue | G29: vantrue | H29: 低相关 | I29: 107832 | J29: 2828
A30: 275 | B30: thinkware dash cam | G30: Thinkware行车记录仪 | H30: 低相关 | I30: 110724 | J30: 2757
A31: 233 | B31: red tiger dashcam | G31: 红虎dashcam | H31: 低相关 | I31: 116816 | J31: 2621
A32: 320 | B32: car cameras for surveillance 360 24 hour recording | G32: 用于监控的车载摄像机360 24小时记录 | H32: 低相关 | I32: 119037 | J32: 2575
A33: 348 | B33: dash cams for cars | D33: 五点 | E33: 标题无序组合出来 | F33: 共性关键词 | G33: 汽车行车记录仪 | H33: 中相关 | I33: 119514 | J33: 2565 | K33: dash cam | L33: 中词 | M33: 0.4609 | N33: 0.2236 | O33: 1.75 | P33: 0.0415 | Q33: 68.89 | R33: 0.6119
A34: 112 | B34: car on-dash mounted cameras | F34: 属性关键词 | G34: 汽车仪表盘安装摄像头 | H34: 中相关 | I34: 140532 | J34: 2207 | L34: 中词 | M34: 0.3334 | N34: 0.1274 | O34: 2.27 | P34: 0.0247 | Q34: 68.89 | R34: 1.3358
A35: 403 | B35: absuyy dash cam | H35: 低相关 | I35: 153480 | J35: 2030
A36: 366 | B36: car security camera | F36: 属性关键词 | G36: 汽车安全摄像头 | H36: 中相关 | I36: 160164 | J36: 1949 | L36: 中词 | M36: #N/A | N36: #N/A | O36: 0.75 | P36: 0.0513 | Q36: 68.89 | R36: 0.2124
A37: 115 | B37: dashboard cameras for vehicles | F37: 属性关键词 | G37: 车辆仪表板摄像头 | H37: 中相关 | I37: 165118 | J37: 1893 | L37: 中词 | M37: 0.3632 | N37: 0.325 | O37: 1.51 | P37: 0.0415 | Q37: 68.89 | R37: 0.528
A38: 281 | B38: dashboard camera | D38: 五点 | E38: 不能组合出来 | F38: 共性关键词 | G38: 仪表盘摄像头 | H38: 中相关 | I38: 170318 | J38: 1838 | L38: 中词 | M38: 0.3704 | N38: 0.3493 | O38: 1.38 | P38: 0.0415 | Q38: 68.89 | R38: 0.4825
A39: 72 | B39: rove dash cam | F39: 属性关键词 | G39: 罗夫行车记录仪 | H39: 中相关 | I39: 170829 | J39: 1833 | K39: dash cam | M39: #N/A | N39: #N/A | O39: 2.09 | P39: 0.0629 | Q39: 68.89 | R39: 0.4825
A40: 75 | B40: cámara para carro | D40: 五点 | E40: 不能组合出来 | F40: 共性关键词 | G40: 汽车摄像头（西班牙语） | H40: 中相关 | I40: 179492 | J40: 1747 | L40: 中词 | M40: #N/A | N40: #N/A | O40: 2.41 | P40: 0.0415 | Q40: 68.89 | R40: 0.8427
...

Sheet 主攻关键词
A1: 关键词 | B1: 关键词归类 | C1: 周ABA 排名 | D1: 周搜索量 | E1: front前缀 | F1: front后缀 | G1: 4k前缀 | H1: 4k后缀 | I1: wifi/wireless | J1: gps
A2: dash cam | B2: 共性关键词 | C2: 401 | D2: 160890 | E2: ="front "&A2 -> front dash cam | F2: =A2&" front" -> dash cam front | G2: ="4k "&A2 -> 4k dash cam | H2: =A2&" 4k" -> dash cam 4k
A3: dash camera for cars | B3: 共性关键词 | C3: 4603 | D3: 42727 | E3: ="front "&A3 -> front dash camera for cars | F3: =A3&" front" -> dash camera for cars front | G3: ="4k "&A3 -> 4k dash camera for cars | H3: =A3&" 4k" -> dash camera for cars 4k
A4: dashcam | B4: 共性关键词 | C4: 9483 | D4: 23045 | E4: ="front "&A4 -> front dashcam | F4: =A4&" front" -> dashcam front | G4: ="4k "&A4 -> 4k dashcam | H4: =A4&" 4k" -> dashcam 4k
A5: car camera | B5: 共性关键词 | C5: 17978 | D5: 13919 | E5: ="front "&A5 -> front car camera | F5: =A5&" front" -> car camera front | G5: ="4k "&A5 -> 4k car camera | H5: =A5&" 4k" -> car camera 4k
A6: dash camera | B6: 共性关键词 | C6: 18214 | D6: 13747 | E6: ="front "&A6 -> front dash camera | F6: =A6&" front" -> dash camera front | G6: ="4k "&A6 -> 4k dash camera | H6: =A6&" 4k" -> dash camera 4k
A7: car dash cam | B7: 共性关键词 | C7: 23785 | D7: 10949 | E7: ="front "&A7 -> front car dash cam | F7: =A7&" front" -> car dash cam front | G7: ="4k "&A7 -> 4k car dash cam | H7: =A7&" 4k" -> car dash cam 4k
A8: dashcams for cars | B8: 共性关键词 | C8: 48493 | D8: 5853 | E8: ="front "&A8 -> front dashcams for cars | F8: =A8&" front" -> dashcams for cars front | G8: ="4k "&A8 -> 4k dashcams for cars | H8: =A8&" 4k" -> dashcams for cars 4k
A9: camera for car | B9: 共性关键词 | C9: 50021 | D9: 5691 | E9: ="front "&A9 -> front camera for car | F9: =A9&" front" -> camera for car front | G9: ="4k "&A9 -> 4k camera for car | H9: =A9&" 4k" -> camera for car 4k
A10: dash cams for cars | B10: 共性关键词 | C10: 119514 | D10: 2565 | E10: ="front "&A10 -> front dash cams for cars | F10: =A10&" front" -> dash cams for cars front | G10: ="4k "&A10 -> 4k dash cams for cars | H10: =A10&" 4k" -> dash cams for cars 4k
A11: dashboard camera | B11: 共性关键词 | C11: 170318 | D11: 1838 | E11: ="front "&A11 -> front dashboard camera | F11: =A11&" front" -> dashboard camera front | G11: ="4k "&A11 -> 4k dashboard camera | H11: =A11&" 4k" -> dashboard camera 4k
A12: cámara para carro | B12: 共性关键词 | C12: 179492 | D12: 1747 | E12: ="front "&A12 -> front cámara para carro | F12: =A12&" front" -> cámara para carro front | G12: ="4k "&A12 -> 4k cámara para carro | H12: =A12&" 4k" -> cámara para carro 4k
A13: car dash camera | B13: 共性关键词 | C13: 208325 | D13: 1515 | E13: ="front "&A13 -> front car dash camera | F13: =A13&" front" -> car dash camera front | G13: ="4k "&A13 -> 4k car dash camera | H13: =A13&" 4k" -> car dash camera 4k
... A36: drive cam | B36: 共性关键词 | C36: 1385855 | D36: 227 | E36: ="front "&A36 -> front drive cam | F36: =A36&" front" -> drive cam front | G36: ="4k "&A36 -> 4k drive cam | H36: =A36&" 4k" -> drive cam 4k

Sheet 广告布局

Sheet 每日订单真实数据
A1: 广告真实日数据
D2: 常规数据 | N2: 广告数据 | AB2: 实时更新 | AC2: 操作备注
A3: 周 | B3: 星期 | C3: 日期 | D3: 价格 | E3: 站内 coupon | F3: 站内 code | G3: 新品 榜单 | H3: 小类目 排名 | I3: 总 销量 | J3: 总访 问量 | K3: 总CVR | L3: 评论 数量 | M3: 评分 | N3: 曝光量 | O3: 点击量 | P3: CTR | Q3: 广告单 | R3: CVR | S3: 平均 CPC | T3: 花费 | U3: ACOS | V3: CPA | W3: 自然 访问 | X3: 自然 订单 | Y3: 自然 单占比 | Z3: 广告 单占比 | AA3: 最终 盈亏 | AB3: Sif 质量分 | AC3: 运营调整 | AD3: 广告操作
A4: 第1周 | B4: 星期一 | C4: 45397 | E4: 0 | F4: 0 | O4: =SUM(Q4/R4) -> 0 | R4: 0.05 | S4: 1.5 | T4: =SUM(O4*S4) -> 0 | U4: =SUM(S4/R4/D4) -> #DIV/0! | V4: =SUM(T4/Q4) -> #DIV/0!
A5: 第1周 | B5: 星期二 | C5: 45398 | E5: 0 | F5: 0 | O5: =SUM(Q5/R5) -> 0 | R5: 0.05 | S5: 1.5 | T5: =SUM(O5*S5) -> 0 | U5: =SUM(S5/R5/D5) -> #DIV/0! | V5: =SUM(T5/Q5) -> #DIV/0!
A6: 第1周 | B6: 星期三 | C6: 45399 | E6: 0 | F6: 0 | O6: =SUM(Q6/R6) -> 0 | R6: 0.05 | S6: 1.5 | T6: =SUM(O6*S6) -> 0 | U6: =SUM(S6/R6/D6) -> #DIV/0! | V6: =SUM(T6/Q6) -> #DIV/0!
A7: 第1周 | B7: 星期四 | C7: 45400 | E7: 0 | F7: 0 | O7: =SUM(Q7/R7) -> 0 | R7: 0.05 | S7: 1.5 | T7: =SUM(O7*S7) -> 0 | U7: =SUM(S7/R7/D7) -> #DIV/0! | V7: =SUM(T7/Q7) -> #DIV/0!
A8: 第1周 | B8: 星期五 | C8: 45401 | E8: 0 | F8: 0
A9: 第1周 | B9: 星期六 | C9: 45402 | E9: 0 | F9: 0
A10: 第1周 | B10: 星期日 | C10: 45403
A11: 第1周汇总
A12: 第2周 | B12: 星期一 | C12: 45404 | E12: 0 | F12: 0
A13: 第2周 | B13: 星期二 | C13: 45405 | E13: 0 | F13: 0
A14: 第2周 | B14: 星期三 | C14: 45406 | E14: 0 | F14: 0
A15: 第2周 | B15: 星期四 | C15: 45407 | E15: 0 | F15: 0
A16: 第2周 | B16: 星期五 | C16: 45408 | E16: 0 | F16: 0
A17: 第2周 | B17: 星期六 | C17: 45409 | E17: 0 | F17: 0
A18: 第2周 | B18: 星期日 | C18: 45410 | E18: 0 | F18: 0
A19: 第2周汇总
A20: 第3周 | B20: 星期一 | C20: 45411 | E20: 0 | F20: 0
A21: 第3周 | B21: 星期二 | C21: 45412 | E21: 0 | F21: 0
A22: 第3周 | B22: 星期三 | C22: 45413 | E22: 0 | F22: 0
A23: 第3周 | B23: 星期四 | C23: 45414 | E23: 0 | F23: 0
A24: 第3周 | B24: 星期五 | C24: 45415 | E24: 0 | F24: 0
A25: 第3周 | B25: 星期六 | C25: 45416 | E25: 0 | F25: 0
A26: 第3周 | B26: 星期日 | C26: 45417 | E26: 0 | F26: 0
A27: 第3周汇总
A28: 第4周 | B28: 星期一 | C28: 45418 | E28: 0 | F28: 0
A29: 第4周 | B29: 星期二 | C29: 45419 | E29: 0 | F29: 0
A30: 第4周 | B30: 星期三 | C30: 45420 | E30: 0 | F30: 0
A31: 第4周 | B31: 星期四 | C31: 45421 | E31: 0 | F31: 0
A32: 第4周 | B32: 星期五 | C32: 45422 | E32: 0 | F32: 0
A33: 第4周 | B33: 星期六 | C33: 45423 | E33: 0 | F33: 0
A34: 第4周 | B34: 星期日 | C34: 45424 | E34: 0 | F34: 0
A35: 第4周汇总
A36: 第5周 | B36: 星期一 | C36: 45425
A37: 第5周 | B37: 星期二 | C37: 45426
A38: 第5周 | B38: 星期三 | C38: 45427
A39: 第5周 | B39: 星期四 | C39: 45428
A40: 第5周 | B40: 星期五 | C40: 45429
...

Sheet 数据演示
A1: 价格策略模拟
A2: 阶段 | B2: 日期 | C2: 定价 | D2: coupon | E2: code | F2: 折后价 | G2: FBA 配送费 | H2: 亚马逊 佣金 | I2: 账号 回款 | J2: 仓储费+入库配置费 | K2: coupon 费用 | L2: 产品 成本 | M2: 物流费 | N2: 退货成本(公式后面加的是单套产品的移除费） | O2: 退货率 | P2: 每单平摊 退货成本 | Q2: 每单 毛利 | R2: 毛利率 | S2: 订单 数量 | T2: 阶段 订单 亏损 | U2: 阶段 订单 总盈亏
A3: 第一阶段 | B3: 第1周 | C3: 23.99 | D3: 0.25 | E3: 0 | F3: =SUM(C3*(1-D3-E3)) -> 17.9925 | G3: 5.5 | H3: =SUM(F3*15%) -> 2.698875 | I3: =SUM(F3-G3-H3) -> 9.793625 | J3: =0.13+0.21 -> 0.34 | K3: 0.6 | L3: 4.5 | M3: 1 | N3: =SUM(20%*15%*F3+G3+J3+L3+M3+1.04) -> 12.919775 | O3: 0.15 | P3: =SUM(N3*O3/(1-O3)) -> 2.2799603 | Q3: =SUM(I3-J3-K3-L3-M3-P3) -> 1.0736647 | R3: =SUM(Q3/C3) -> 0.044754677 | S3: 7 | T3: =SUM(Q3*S3) -> 7.5156529 | U3: =SUM(T3:T3) -> 7.5156529
C4: 23.99 | D4: 0 | E4: 0 | F4: =SUM(C4*(1-D4-E4)) -> 23.99 | G4: 5.5 | H4: =SUM(F4*15%) -> 3.5985 | I4: =SUM(F4-G4-H4) -> 14.8915 | J4: =0.13+0.21 -> 0.34 | K4: 0 | L4: 4.5 | M4: 1 | N4: =SUM(20%*15%*F4+G4+J4+L4+M4+1.04) -> 13.0997 | O4: 0.15 | P4: =SUM(N4*O4/(1-O4)) -> 2.3117118 | Q4: =SUM(I4-J4-K4-L4-M4-P4) -> 6.7397882 | R4: =SUM(Q4/C4) -> 0.28094157 | S4: 7 | T4: =SUM(Q4*S4) -> 47.178518 | U4: =SUM(T4:T4) -> 47.178518
B5: 第2周 | C5: 23.99 | D5: 0.25 | E5: 0 | F5: =SUM(C5*(1-D5-E5)) -> 17.9925 | G5: 5.5 | H5: =SUM(F5*15%) -> 2.698875 | I5: =SUM(F5-G5-H5) -> 9.793625 | J5: =0.13+0.21 -> 0.34 | K5: 0.6 | L5: 4.5 | M5: 1 | N5: =SUM(20%*15%*F5+G5+J5+L5+M5+1.04) -> 12.919775 | O5: 0.15 | P5: =SUM(N5*O5/(1-O5)) -> 2.2799603 | Q5: =SUM(I5-J5-K5-L5-M5-P5) -> 1.0736647 | R5: =SUM(Q5/C5) -> 0.044754677 | S5: 14 | T5: =SUM(Q5*S5) -> 15.031306 | U5: =SUM(T5:T5) -> 15.031306
C6: 23.99 | D6: 0 | E6: 0 | F6: =SUM(C6*(1-D6-E6)) -> 23.99 | G6: 5.5 | H6: =SUM(F6*15%) -> 3.5985 | I6: =SUM(F6-G6-H6) -> 14.8915 | J6: =0.13+0.21 -> 0.34 | K6: 0 | L6: 4.5 | M6: 1 | N6: =SUM(20%*15%*F6+G6+J6+L6+M6+1.04) -> 13.0997 | O6: 0.15 | P6: =SUM(N6*O6/(1-O6)) -> 2.3117118 | Q6: =SUM(I6-J6-K6-L6-M6-P6) -> 6.7397882 | R6: =SUM(Q6/C6) -> 0.28094157 | S6: 14 | T6: =SUM(Q6*S6) -> 94.357035 | U6: =SUM(T6:T6) -> 94.357035
B7: 第3周 | C7: 23.99 | D7: 0.25 | E7: 0 | F7: =SUM(C7*(1-D7-E7)) -> 17.9925 | G7: 5.5 | H7: =SUM(F7*15%) -> 2.698875 | I7: =SUM(F7-G7-H7) -> 9.793625 | J7: =0.13+0.21 -> 0.34 | K7: 0.6 | L7: 4.5 | M7: 1 | N7: =SUM(20%*15%*F7+G7+J7+L7+M7+1.04) -> 12.919775 | O7: 0.15 | P7: =SUM(N7*O7/(1-O7)) -> 2.2799603 | Q7: =SUM(I7-J7-K7-L7-M7-P7) -> 1.0736647 | R7: =SUM(Q7/C7) -> 0.044754677 | S7: 21 | T7: =SUM(Q7*S7) -> 22.546959 | U7: =SUM(T7:T7) -> 22.546959
C8: 23.99 | D8: 0 | E8: 0 | F8: =SUM(C8*(1-D8-E8)) -> 23.99 | G8: 5.5 | H8: =SUM(F8*15%) -> 3.5985 | I8: =SUM(F8-G8-H8) -> 14.8915 | J8: =0.13+0.21 -> 0.34 | K8: 0 | L8: 4.5 | M8: 1 | N8: =SUM(20%*15%*F8+G8+J8+L8+M8+1.04) -> 13.0997 | O8: 0.15 | P8: =SUM(N8*O8/(1-O8)) -> 2.3117118 | Q8: =SUM(I8-J8-K8-L8-M8-P8) -> 6.7397882 | R8: =SUM(Q8/C8) -> 0.28094157 | S8: 21 | T8: =SUM(Q8*S8) -> 141.53555 | U8: =SUM(T8:T8) -> 141.53555
B9: 第4周 | C9: 23.99 | D9: 0.25 | E9: 0 | F9: =SUM(C9*(1-D9-E9)) -> 17.9925 | G9: 5.5 | H9: =SUM(F9*15%) -> 2.698875 | I9: =SUM(F9-G9-H9) -> 9.793625 | J9: =0.13+0.21 -> 0.34 | K9: 0.6 | L9: 4.5 | M9: 1 | N9: =SUM(20%*15%*F9+G9+J9+L9+M9+1.04) -> 12.919775 | O9: 0.15 | P9: =SUM(N9*O9/(1-O9)) -> 2.2799603 | Q9: =SUM(I9-J9-K9-L9-M9-P9) -> 1.0736647 | R9: =SUM(Q9/C9) -> 0.044754677 | S9: 28 | T9: =SUM(Q9*S9) -> 30.062612 | U9: =SUM(T9:T9) -> 30.062612
C10: 23.99 | D10: 0 | E10: 0 | F10: =SUM(C10*(1-D10-E10)) -> 23.99 | G10: 5.5 | H10: =SUM(F10*15%) -> 3.5985 | I10: =SUM(F10-G10-H10) -> 14.8915 | J10: =0.13+0.21 -> 0.34 | K10: 0 | L10: 4.5 | M10: 1 | N10: =SUM(20%*15%*F10+G10+J10+L10+M10+1.04) -> 13.0997 | O10: 0.15 | P10: =SUM(N10*O10/(1-O10)) -> 2.3117118 | Q10: =SUM(I10-J10-K10-L10-M10-P10) -> 6.7397882 | R10: =SUM(Q10/C10) -> 0.28094157 | S10: 28 | T10: =SUM(Q10*S10) -> 188.71407 | U10: =SUM(T10:T10) -> 188.71407
A11: 第二阶段 | C11: 24.99 | D11: 0.2 | E11: 0 | F11: =SUM(C11*(1-D11-E11)) -> 19.992 | G11: 5.5 | H11: =SUM(F11*15%) -> 2.9988 | I11: =SUM(F11-G11-H11) -> 11.4932 | J11: =0.13+0.21 -> 0.34 | K11: 0.6 | L11: 4.5 | M11: 1 | N11: =SUM(20%*15%*F11+G11+J11+L11+M11+1.04) -> 12.97976 | O11: 0.15 | P11: =SUM(N11*O11/(1-O11)) -> 2.2905459 | Q11: =SUM(I11-J11-K11-L11-M11-P11) -> 2.7626541 | R11: =SUM(Q11/C11) -> 0.11055038 | S11: 1 | T11: =SUM(Q11*S11) -> 2.7626541 | U11: =SUM(T11:T11) -> 2.7626541
A12: 第三阶段 | C12: 25.99 | D12: 0.15 | E12: 0 | F12: =SUM(C12*(1-D12-E12)) -> 22.0915 | G12: 5.5 | H12: =SUM(F12*15%) -> 3.313725 | I12: =SUM(F12-G12-H12) -> 13.277775 | J12: =0.13+0.21 -> 0.34 | K12: 0.6 | L12: 4.5 | M12: 1 | N12: =SUM(20%*15%*F12+G12+J12+L12+M12+1.04) -> 13.042745 | O12: 0.15 | P12: =SUM(N12*O12/(1-O12)) -> 2.3016609 | Q12: =SUM(I12-J12-K12-L12-M12-P12) -> 4.5361141 | R12: =SUM(Q12/C12) -> 0.17453306 | S12: 1 | T12: =SUM(Q12*S12) -> 4.5361141 | U12: =SUM(T12:T12) -> 4.5361141
A13: 第四阶段 | C13: 26.99 | D13: 0.1 | E13: 0 | F13: =SUM(C13*(1-D13-E13)) -> 24.291 | G13: 5.5 | H13: =SUM(F13*15%) -> 3.64365 | I13: =SUM(F13-G13-H13) -> 15.14735 | J13: =0.13+0.21 -> 0.34 | K13: 0.6 | L13: 4.5 | M13: 1 | N13: =SUM(20%*15%*F13+G13+J13+L13+M13+1.04) -> 13.10873 | O13: 0.15 | P13: =SUM(N13*O13/(1-O13)) -> 2.3133053 | Q13: =SUM(I13-J13-K13-L13-M13-P13) -> 6.3940447 | R13: =SUM(Q13/C13) -> 0.23690421 | S13: 1 | T13: =SUM(Q13*S13) -> 6.3940447 | U13: =SUM(T13:T13) -> 6.3940447
A14: 第五阶段 | C14: 27.99 | D14: 0.1 | E14: 0 | F14: =SUM(C14*(1-D14-E14)) -> 25.191 | G14: 5.5 | H14: =SUM(F14*15%) -> 3.77865 | I14: =SUM(F14-G14-H14) -> 15.91235 | J14: =0.13+0.21 -> 0.34 | K14: 0.6 | L14: 4.5 | M14: 1 | N14: =SUM(20%*15%*F14+G14+J14+L14+M14+1.04) -> 13.13573 | O14: 0.15 | P14: =SUM(N14*O14/(1-O14)) -> 2.31807 | Q14: =SUM(I14-J14-K14-L14-M14-P14) -> 7.15428 | R14: =SUM(Q14/C14) -> 0.25560129 | S14: 1 | T14: =SUM(Q14*S14) -> 7.15428 | U14: =SUM(T14:T14) -> 7.15428
A15: 第六阶段 | C15: 27.99 | D15: 0.1 | E15: 0 | F15: =SUM(C15*(1-D15-E15)) -> 25.191 | G15: 5.5 | H15: =SUM(F15*15%) -> 3.77865 | I15: =SUM(F15-G15-H15) -> 15.91235 | J15: =0.13+0.21 -> 0.34 | K15: 0 | L15: 4.5 | M15: 1 | N15: =SUM(20%*15%*F15+G15+J15+L15+M15+1.04) -> 13.13573 | O15: 0.15 | P15: =SUM(N15*O15/(1-O15)) -> 2.31807 | Q15: =SUM(I15-J15-K15-L15-M15-P15) -> 7.75428 | R15: =SUM(Q15/C15) -> 0.27703751 | S15: 1 | T15: =SUM(Q15*S15) -> 7.75428 | U15: =SUM(T15:T15) -> 7.75428

Sheet 2
