Workbook

Sheet 市场分析
A1: 市场趋势及分析
M3: 品牌 | N3: 求和项:日销量 | O3: 求和项:月销量 | P3: 求和项:月销售额 | Q3: 计数项:ASIN | R3: 市场份额
M4: Amazon Renewed | N4: 31 | O4: 930 | P4: 151362.9 | Q4: 6 | R4: =GETPIVOTDATA("求和项:月销售额",$M$3,"品牌","Amazon Renewed")/GETPIVOTDATA("求和项:月销售额",$M$3) -> 0.022639138
M5: AVERY | N5: 17 | O5: 510 | P5: 6660.6 | Q5: 1 | R5: =GETPIVOTDATA("求和项:月销售额",$M$3,"品牌","AVERY")/GETPIVOTDATA("求和项:月销售额",$M$3) -> 0.00099621665
M6: BESTEASY | N6: 44 | O6: 1320 | P6: 192706.8 | Q6: 1 | R6: =GETPIVOTDATA("求和项:月销售额",$M$3,"品牌","BESTEASY")/GETPIVOTDATA("求和项:月销售额",$M$3) -> 0.028822887
M7: Brady | N7: 1 | O7: 30 | P7: 26058.9 | Q7: 1 | R7: =GETPIVOTDATA("求和项:月销售额",$M$3,"品牌","Brady")/GETPIVOTDATA("求和项:月销售额",$M$3) -> 0.0038975933
M8: Brother | N8: 141 | O8: 4230 | P8: 1043246.1 | Q8: 6 | R8: =GETPIVOTDATA("求和项:月销售额",$M$3,"品牌","Brother")/GETPIVOTDATA("求和项:月销售额",$M$3) -> 0.15603686
M9: Datamax-O'Neil | N9: 2 | O9: 60 | P9: 20719.8 | Q9: 1 | R9: =GETPIVOTDATA("求和项:月销售额",$M$3,"品牌","Datamax-O'Neil")/GETPIVOTDATA("求和项:月销售额",$M$3) -> 0.0030990316
M10: DT-Techno | N10: 2 | O10: 60 | P10: 18600 | Q10: 1 | R10: =GETPIVOTDATA("求和项:月销售额",$M$3,"品牌","DT-Techno")/GETPIVOTDATA("求和项:月销售额",$M$3) -> 0.002781976
M11: DYMO | N11: 630 | O11: 18900 | P11: 2281843.8 | Q11: 6 | R11: =GETPIVOTDATA("求和项:月销售额",$M$3,"品牌","DYMO")/GETPIVOTDATA("求和项:月销售额",$M$3) -> 0.34129219
M12: Immuson | N12: 14 | O12: 420 | P12: 41995.8 | Q12: 1 | R12: =GETPIVOTDATA("求和项:月销售额",$M$3,"品牌","Immuson")/GETPIVOTDATA("求和项:月销售额",$M$3) -> 0.0062812532
M13: LotFancy | N13: 2 | O13: 60 | P13: 8396.4 | Q13: 1 | R13: =GETPIVOTDATA("求和项:月销售额",$M$3,"品牌","LotFancy")/GETPIVOTDATA("求和项:月销售额",$M$3) -> 0.0012558378
M14: MFLABEL | N14: 25 | O14: 750 | P14: 116692.5 | Q14: 3 | R14: =GETPIVOTDATA("求和项:月销售额",$M$3,"品牌","MFLABEL")/GETPIVOTDATA("求和项:月销售额",$M$3) -> 0.017453534
M15: NANA | N15: 2 | O15: 60 | P15: 2339.4 | Q15: 1 | R15: =GETPIVOTDATA("求和项:月销售额",$M$3,"品牌","NANA")/GETPIVOTDATA("求和项:月销售额",$M$3) -> 0.00034990079
M16: NETUM | N16: 4 | O16: 120 | P16: 17005.5 | Q16: 2 | R16: =GETPIVOTDATA("求和项:月销售额",$M$3,"品牌","NETUM")/GETPIVOTDATA("求和项:月销售额",$M$3) -> 0.0025434889
M17: Phomemo | N17: 24 | O17: 720 | P17: 100432.8 | Q17: 2 | R17: =GETPIVOTDATA("求和项:月销售额",$M$3,"品牌","Phomemo")/GETPIVOTDATA("求和项:月销售额",$M$3) -> 0.015021594
M18: Rollo | N18: 335 | O18: 10050 | P18: 2009899.5 | Q18: 1 | R18: =GETPIVOTDATA("求和项:月销售额",$M$3,"品牌","Rollo")/GETPIVOTDATA("求和项:月销售额",$M$3) -> 0.30061786
M19: Seiko Instruments | N19: 2 | O19: 60 | P19: 3925.8 | Q19: 1 | R19: =GETPIVOTDATA("求和项:月销售额",$M$3,"品牌","Seiko Instruments")/GETPIVOTDATA("求和项:月销售额",$M$3) -> 0.00058717643
M20: ZEBRA | N20: 61 | O20: 1830 | P20: 644008.5 | Q20: 13 | R20: =GETPIVOTDATA("求和项:月销售额",$M$3,"品牌","ZEBRA")/GETPIVOTDATA("求和项:月销售额",$M$3) -> 0.096323453
M21: 总计 | N21: 1337 | O21: 40110 | P21: 6685895.1 | Q21: 48
M24: 价格 | N24: 求和项:日销量 | O24: 求和项:月销量 | P24: 求和项:月销售额 | Q24: 计数项:ASIN | R24: 市场份额
M25: <50 | N25: 19 | O25: 570 | P25: 9000 | Q25: 2 | R25: =GETPIVOTDATA("求和项:月销售额",$M$24,"价格","<50")/GETPIVOTDATA("求和项:月销售额",$M$24) -> 0.0013461174
M26: 50-100 | N26: 458 | O26: 13740 | P26: 1113635.7 | Q26: 7 | R26: =GETPIVOTDATA("求和项:月销售额",$M$24,"价格","50-100")/GETPIVOTDATA("求和项:月销售额",$M$24) -> 0.16656494
M27: 100-150 | N27: 184 | O27: 5520 | P27: 774462.6 | Q27: 8 | R27: =GETPIVOTDATA("求和项:月销售额",$M$24,"价格","100-150")/GETPIVOTDATA("求和项:月销售额",$M$24) -> 0.11583529
M28: 150-200 | N28: 400 | O28: 12000 | P28: 2337186.6 | Q28: 9 | R28: =GETPIVOTDATA("求和项:月销售额",$M$24,"价格","150-200")/GETPIVOTDATA("求和项:月销售额",$M$24) -> 0.34956974
M29: 200-250 | N29: 159 | O29: 4770 | P29: 999573 | Q29: 4 | R29: =GETPIVOTDATA("求和项:月销售额",$M$24,"价格","200-250")/GETPIVOTDATA("求和项:月销售额",$M$24) -> 0.14950474
M30: 250-300 | N30: 17 | O30: 510 | P30: 147894.9 | Q30: 1 | R30: =GETPIVOTDATA("求和项:月销售额",$M$24,"价格","250-300")/GETPIVOTDATA("求和项:月销售额",$M$24) -> 0.022120434
M31: 300-350 | N31: 31 | O31: 930 | P31: 306164.7 | Q31: 6 | R31: =GETPIVOTDATA("求和项:月销售额",$M$24,"价格","300-350")/GETPIVOTDATA("求和项:月销售额",$M$24) -> 0.045792627
M32: 350-400 | N32: 3 | O32: 90 | P32: 33449.4 | Q32: 2 | R32: =GETPIVOTDATA("求和项:月销售额",$M$24,"价格","350-400")/GETPIVOTDATA("求和项:月销售额",$M$24) -> 0.0050029801
M33: 400-450 | N33: 7 | O33: 210 | P33: 86500.8 | Q33: 2 | R33: =GETPIVOTDATA("求和项:月销售额",$M$24,"价格","400-450")/GETPIVOTDATA("求和项:月销售额",$M$24) -> 0.012937804
M34: 450-500 | N34: 56 | O34: 1680 | P34: 813898.5 | Q34: 4 | R34: =GETPIVOTDATA("求和项:月销售额",$M$24,"价格","450-500")/GETPIVOTDATA("求和项:月销售额",$M$24) -> 0.12173366
M35: >500 | N35: 3 | O35: 90 | P35: 64128.9 | Q35: 3 | R35: =GETPIVOTDATA("求和项:月销售额",$M$24,"价格",">500")/GETPIVOTDATA("求和项:月销售额",$M$24) -> 0.0095916701
M36: 总计 | N36: 1337 | O36: 40110 | P36: 6685895.1 | Q36: 48
M39: 评分 | N39: 求和项:日销量 | O39: 求和项:月销量 | P39: 求和项:月销售额 | Q39: 计数项:ASIN | R39: 市场份额
M40: <3.2 | N40: 9 | O40: 270 | P40: 126033.3 | Q40: 4 | R40: =GETPIVOTDATA("求和项:月销售额",$M$39,"评分","<3.2")/GETPIVOTDATA("求和项:月销售额",$M$39) -> 0.018850625
M41: 3.2-3.7 | N41: 7 | O41: 210 | P41: 61975.8 | Q41: 4 | R41: =GETPIVOTDATA("求和项:月销售额",$M$39,"评分","3.2-3.7")/GETPIVOTDATA("求和项:月销售额",$M$39) -> 0.0092696339
M42: 3.7-4.2 | N42: 99 | O42: 2970 | P42: 594137.4 | Q42: 17 | R42: =GETPIVOTDATA("求和项:月销售额",$M$39,"评分","3.7-4.2")/GETPIVOTDATA("求和项:月销售额",$M$39) -> 0.088864302
M43: 4.2-4.7 | N43: 1176 | O43: 35280 | P43: 5692441.8 | Q43: 21 | R43: =GETPIVOTDATA("求和项:月销售额",$M$39,"评分","4.2-4.7")/GETPIVOTDATA("求和项:月销售额",$M$39) -> 0.85141058
M44: >4.7 | N44: 46 | O44: 1380 | P44: 211306.8 | Q44: 2 | R44: =GETPIVOTDATA("求和项:月销售额",$M$39,"评分",">4.7")/GETPIVOTDATA("求和项:月销售额",$M$39) -> 0.031604863
M45: 总计 | N45: 1337 | O45: 40110 | P45: 6685895.1 | Q45: 48
...

Sheet 竞品分析
A1: 品牌基本信息 | F1: listing信息 | O1: 产品信息
A2: 品牌 | B2: ASIN | C2: 市场份额 | D2: Link | E2: 主图 | F2: 小类排名 | G2: 大类排名 | H2: review数量 | I2: review评分 | J2: 价格（$) | K2: 上线时长（天） | L2: 预估日销 | M2: 预估月销 | N2: 月销售额 | O2: 技术 | P2: 分辨率（DPI) | Q2: 是否有应用程序 | R2: 每分钟打印标签数量/每秒打印长度 | S2: 输出类型 | T2: 产品重量（磅） | U2: 外观 | V2: 兼容系统 | W2: 可打印标签范围 | X2: 卖点 | Y2: 客诉点 | Z2: 备注
A3: DYMO(市场份额：34.19%） | B3: B0027JBLV4 | C3: =N3/GETPIVOTDATA("求和项:月销售额",市场分析!$M$3) -> 0.13854304 | D3: https://www.amazon.com/DYMO-LabelWriter-Thermal-Printer-1752264/dp/B0027JBLV4/ref=sr_1_1?dchild=1&keywords=B0027JBLV4&qid=1600764014&sr=8-1 | F3: 1 | G3: #526 | H3: 3331 | I3: 4.5 | J3: 79.99 | K3: 3469 | L3: 386 | M3: 11580 | N3: =J3*M3 -> 926284.2 | O3: 热敏 | P3: 600*300 | Q3: 是 | R3: 51张 | S3: / | T3: 2.2 | U3: 银黑色 | V3: Windows 7或更高版本； Mac OS X v10.8或更高版本 | W3: 运输和邮寄标签，资产标识，条形码，文件，名称徽章和绑定器 | X3: 1. 打印精确的数量，不浪费； 2. 热敏打印技术无需墨水和碳粉； 3. 随附DYMO软件快速创建和打印； 4. 每分钟最多创建和打印51个标签； 5. 直接从Word，Excel，Outlook和Google联系人中文本创建标签； 6. 各种尺寸的标签； 7. 与Dymo邮票不兼容。 | Y3: 1. DYMO相关软件操做麻烦； 2. 不兼容MAC、PC等部分系统； 3. 打印标签颜色变淡； 4. 打印纸缠绕，顺序错乱； 5. 自动喷出大量空白标签。
B4: B07DXH5CCJ | C4: =N4/GETPIVOTDATA("求和项:月销售额",市场分析!$M$3) -> 0.14064908 | D4: https://www.amazon.com/DYMO-LabelWriter-Adhesive-Shipping-400-pound/dp/B07DXH5CCJ/ref=sr_1_1?dchild=1&keywords=B07DXH5CCJ&qid=1600764027&sr=8-1 | F4: 3 | G4: #1,630 | H4: 3039 | I4: 4.4 | J4: 208.97 | K4: 4050 | L4: 150 | M4: 4500 | N4: =J4*M4 -> 940365 | O4: 热敏 | P4: / | Q4: 是 | R4: 71张 | S4: / | T4: / | U4: 银黑色 | V4: Windows 7或更高版本； Mac OS X v10.9或更高版本 | W4: 运输和邮寄标签，资产标识，条形码，文件，名称徽章和绑定器 | X4: 1. 每分钟最多创建和打印71个标签； 2. 随附DYMO Stamps软件可直接打印USPS批准的邮资； 3. 使用软件无需支付费用； 4. 热敏打印技术无需墨水和碳粉； 5. 内置便携式电子秤； 6. 电子秤可拆卸LED屏，方便手持或壁挂观看。 | Y4: 1. 自动打印标签； 2. 产品太小，无法大量打印标签； 3. DYMO相关操作软件太难使用； 4. 打印错误标签，标签内容、字体错误； 5. 标签不完整，仅有部分内容；
B5: B0027J9KH6 | C5: =N5/GETPIVOTDATA("求和项:月销售额",市场分析!$M$3) -> 0.039573026 | D5: https://www.amazon.com/DYMO-Writer-printer-Labels-1752266/dp/B0027J9KH6/ref=sr_1_1?dchild=1&keywords=B0027J9KH6&qid=1600764044&sr=8-1 | F5: 4 | G5: #3,908 | H5: 1141 | I5: 4.3 | J5: 139.99 | K5: 4072 | L5: 63 | M5: 1890 | N5: =J5*M5 -> 264581.1 | O5: 热敏 | P5: 600*300 | Q5: 是 | R5: 72张 | S5: 单色 | T5: 1.5 | U5: 银黑色 | V5: Windows 7或更高版本； Mac OS V10.10或更高版本 | W5: 大批量运输和邮寄标签，资产标识，条形码，文件，名称徽章和绑定器 | X5: 1. 热敏打印技术无需墨水和碳粉； 2. 每分钟最多可打印71个标签； 3. 与Windows 7、Mac OS X v10.8或更高版本兼容； 4. DYMO软件从PC自定义打印； 5. 600 x 300 dpi分辨率打印更清晰； 6. 精确打印，不浪费纸张； 7. 使用软件无需支付费用； | Y5: 1. 无法与Wind 10兼容； 2. 自动疯狂喷出一堆空白标签； 3.卡顿； 4. 只有一边正常工作； 5. 标签缠绕在滚轴上； 6. 需额外购买标签纸。
B6: B07DXDSPFT | C6: =N6/GETPIVOTDATA("求和项:月销售额",市场分析!$M$3) -> 0.0080758072 | D6: https://www.amazon.com/DYMO-1801611-Industrial-Labels-LabelWriter/dp/B07DXDSPFT/ref=sr_1_1?dchild=1&keywords=B07DXDSPFT&qid=1600764129&sr=8-1 | F6: 11 | G6: #10,971 | H6: 705 | I6: 4.6 | J6: 89.99 | K6: 3231 | L6: 20 | M6: 600 | N6: =J6*M6 -> 53994 | O6: / | P6: / | Q6: 否 | R6: / | S6: / | T6: / | U6: / | V6: / | W6: / | X6: 1. 轻触“热键”，用于创建和格式化标签的快捷方式； 2. 使用计算机风格（AZERTY）键盘输入文本； 3. 打印各种材料和颜色的1/4“，3/8”，1/2“和3/4”宽工业标签； 4. 可直接在热缩管上打印； 5. 耐用防污，耐化学药品，溶剂，油脂，热，湿气和其他苛刻元素。 | Y6: /
B7: B01MEEI5WC | C7: =N7/GETPIVOTDATA("求和项:月销售额",市场分析!$M$3) -> 0.012604101 | D7: https://www.amazon.com/DYMO-LabelWriter-Thermal-Printer-1755120/dp/B01MEEI5WC/ref=sr_1_1?dchild=1&keywords=B01MEEI5WC&qid=1600764097&sr=8-1 | F7: 18 | G7: #19,618 | H7: 15 | I7: 4.7 | J7: 312.11 | K7: 3862 | L7: 9 | M7: 270 | N7: =J7*M7 -> 84269.7 | O7: 热敏 | P7: / | Q7: 是 | R7: / | S7: / | T7: / | U7: 银黑色 | V7: Windows 7或更高版本； Mac OS v10.11或更高版本 | W7: 大量邮寄，运输，专业，资产识别，条形码，文件和装订 | X7: 1. 宽幅标签打印机可打印大量标签； 2. 打印宽度最大为4.16英寸的标签； 3. 热敏打印技术无需墨水和碳粉； 4. 与平台兼容，直接从DYMO Stamps，eBay，Etsy和iabol打印运输标签； 5. 打印数量准确，无标签浪费； 6. 直接从Word，Excel或Outlook等进行打印; 7. 系统要求：Windows 7、Mac OS v10.11或更高版本。 | Y7: 1. 打印错误尺寸标签，浪费纸张；
B8: B002M1LG1M | C8: =N8/GETPIVOTDATA("求和项:月销售额",市场分析!$M$3) -> 0.0018471424 | D8: https://www.amazon.com/DYMO-1752267-LabelWriter-Thermal-Printer/dp/B002M1LG1M/ref=sr_1_1?dchild=1&keywords=B002M1LG1M&qid=1600764115&sr=8-1 | F8: 40 | G8: #46,051 | H8: 90 | I8: 3.8 | J8: 205.83 | K8: 4190 | L8: 2 | M8: 60 | N8: =J8*M8 -> 12349.8 | O8: 热敏 | P8: 600*300 | Q8: 是 | R8: 71张 | S8: / | T8: 5.25 | U8: 银黑色 | V8: Windows 7或更高版本； Mac OS X v10.8或更高版本 | W8: 运输和邮寄标签，专业，资产标识，条形码，文件和装订夹，家庭组织，名称徽章和工业 | X8: 1. 每分钟最多创建和打印71个标签； 2. DYMO Stamps软件直接从桌面打印USPS批准的邮资； 3. 使用软件无需支付费用； 4. 热敏打印技术无需墨水和碳粉； 5. 连接到PC或Mac，可直接从Word，Excel，Outlook，Quick Books和其他程序中打印标签。 | Y8: 1. 自动改变标签格式； 2. 产品使用寿命太短 ，质量差； 3. 频繁卡顿、拥堵； 4. 额外付费购买标签；
A9: Brother | B9: B01MTWGMRR | C9: =N9/GETPIVOTDATA("求和项:月销售额",市场分析!$M$3) -> 0.020414544 | D9: https://www.amazon.com/Brother-QL-810W-Ultra-Fast-Wireless-Networking/dp/B01MTWGMRR/ref=sr_1_1?dchild=1&keywords=B01MTWGMRR&qid=1600764790&sr=8-1 | F9: 7 | G9: #6,603 | H9: 317 | I9: 4.3 | J9: 129.99 | K9: 1346 | L9: 35 | M9: 1050 | N9: =J9*M9 -> 136489.5 | O9: 热敏 | P9: 600*300 | Q9: / | R9: 110张 | S9: 单色 | T9: 2.4 | U9: 白色 | V9: 电脑：Windows Mac； 移动设备兼容性：AirPrint，Brother iPrint$Label | W9: 包裹、信封、文件夹、姓名牌、邮件标签 | X9: 1. 连接WIFI，任何地方打印或网络共享； 2. 可打印黑色/红色标签； 3. 切纸机寿命：高达300,000（模切标签）150,000（连续标签）； 4. 兼容不同操作系统：Mac，Windows； AirPrint，Brother iPrint和Label； 5. 无需墨水和碳粉； 6. 每分钟多达110个标签； 7. 300dpi分辨率。 | Y9: 1. 不能兼容MAC、Wind10，连接网络故障； 2. 不能打印条形码； 3. 操作麻烦，难操作； 4. 标签质量差，颜色太浓，有斑点； 5. 机器突然死机，机器冒烟了。
B10: B01N49R9KP | C10: =N10/GETPIVOTDATA("求和项:月销售额",市场分析!$M$3) -> 0.011126513 | D10: https://www.amazon.com/Brother-High-Speed-Professional-Multi-System-Compatible/dp/B01N49R9KP/ref=sr_1_1?dchild=1&keywords=B01N49R9KP&qid=1600764801&sr=8-1 | F10: 8 | G10: #7,408 | H10: 749 | I10: 4.2 | J10: 79.99 | K10: 1389 | L10: 31 | M10: 930 | N10: =J10*M10 -> 74390.7 | O10: / | P10: 600*300 | Q10: / | R10: 93张 | S10: 单色 | T10: 2.5 | U10: 白色 | V10: Windows和Mac | W10: 包裹、信封、文件夹、姓名牌、邮件标签 | X10: 1. 打印黑色/红色标签； 2. 超快速，每分钟可打印93个标签； 3. 300dpi分辨率的黑色文本显示； 4. 自动切纸器可启用3英尺横幅和标牌； 5. 可以直接在办公桌上打印邮资； 6. 打印机输出：单色 7. 连接技术：无线。 | Y10: 1. 不予MAC兼容，操作麻烦，费时； 2. 产品寿命短，不工作； 3. 相关软件不识别打印机，无法打印； 4. 打印机容易处于脱机或未连接状态
B11: B079G51QTB | C11: =N11/GETPIVOTDATA("求和项:月销售额",市场分析!$M$3) -> 0.018575389 | D11: https://www.amazon.com/Brother-QL-1100-Postage-Barcode-Professional/dp/B079G51QTB/ref=sr_1_1?dchild=1&keywords=B079G51QTB&qid=1600764814&sr=8-1 | F11: 9 | G11: #9,612 | H11: 190 | I11: 4.2 | J11: 179.99 | K11: 4335 | L11: 23 | M11: 690 | N11: =J11*M11 -> 124193.1 | O11: / | P11: 300x300 | Q11: 是 | R11: 69张 | S11: 单色 | T11: 3.65 | U11: 白色 | V11: 无需Windows pc安装软件； iPrint&Label app移动打印 | W11: 包裹，文件夹，信封，邮资，航运 | X11: 1. 在最大4英寸宽的宽幅标签上打印； 2. 条形码裁剪功能； 3. USB主机接口：允许与外围设备一起使用； 4. 无需在PC上安装软件即可打印标签； 5. 免费SDK轻松集成打印； 6. 内存（MB）：7.8； 7. 最大标签长度：9.8英尺（USB）3英尺（串行）。 | Y11: 1. 打印标签尺寸错误； 2. 无法与MAC兼容； 3. 打印标签不完整，仅打印部分标签； 4. 步骤麻烦，很难操作； 5. 质量差，仅使用几次就坏了，不工作。 | Z11: 1. 印刷标签宽达4英寸； 2. 免费软件开发工具包(SDK)；
B12: B005TJMC0S | C12: =N12/GETPIVOTDATA("求和项:月销售额",市场分析!$M$3) -> 0.0030052072 | D12: https://www.amazon.com/Brother-QL-700-High-speed-Professional-Printer/dp/B005TJMC0S/ref=sr_1_1?dchild=1&keywords=B005TJMC0S&qid=1600764822&sr=8-1 | F12: 22 | G12: #27,580 | H12: 1182 | I12: 4.3 | J12: 133.95 | K12: 1154 | L12: 5 | M12: 150 | N12: =J12*M12 -> 20092.5 | O12: / | P12: 300*300 | Q12: 是 | R12: 93张 | S12: / | T12: 2.47 | U12: 白色 | V12: 仅Windows | W12: 包裹、信封、文件夹、光盘、横幅、邮件标签 | X12: 1. 超快速，每分钟可打印多达93个标签； 2. 打印尺寸预先设定，易剥离； 3. 可在连续长度的纸和膜胶带上打印； 4. 用于横幅和标牌，最长3英尺； 5. 直接在办公桌上打印包裹和信封的邮资 6. 无需墨水或碳粉； 7. 自动裁纸器提供精确裁切。 | Y12: 1. 不兼容Wind 10，MAC等系统； 2. 巨响后死机，有噪音； 3. 冒烟，有安全隐患； 4. 操作程序复杂； 5. 打印机卡顿； | Z12: 需要申请pbsmart邮费服务、互联网连接、USB连接和邮费标签卷
A13: Zebra | B13: B07HLVSHVZ | C13: =N13/GETPIVOTDATA("求和项:月销售额",市场分析!$M$3) -> 0.022120434 | D13: https://www.amazon.com/Zebra-Label-Thermal-Printer-ZP450-0501-0006A/dp/B07HLVSHVZ/ref=sr_1_1?dchild=1&keywords=B07HLVSHVZ&qid=1600764857&sr=8-1 | F13: 12 | G13: #12,034 | H13: 54 | I13: 4 | J13: 289.99 | K13: 727 | L13: 17 | M13: 510 | N13: =J13*M13 -> 147894.9 | O13: / | P13: 203*600 | Q13: / | R13: 127mm/s | S13: / | T13: 7.78 | U13: 灰色 | V13: / | W13: / | X13: 1. 连接性：并行（IEEE1284），串行（RS-232C），USB 1.0 / 1.1； 2. 黑色打印速度5英寸/秒； 3. 最大分辨率（Bw）203x600DPI； | Y13: 1. 标签质量差，看不清标签内容； 2. 只与UPS Worldship一起工作； 3. 连不上以太网； 4. 只与UPS Worldship一起工作； 5. 缺少电源适配器； 6. 质量差，不工作。
B14: B00EUN90SG | C14: =N14/GETPIVOTDATA("求和项:月销售额",市场分析!$M$3) -> 0.019832214 | D14: https://www.amazon.com/Zebra-Receipts-Barcodes-Parallel-Connectivity/dp/B00EUN90SG/ref=sr_1_1?dchild=1&keywords=B00EUN90SG&qid=1600764870&sr=8-1 | F14: 16 | G14: #14,700 | H14: 140 | I14: 4.2 | J14: 339.99 | K14: 679 | L14: 13 | M14: 390 | N14: =J14*M14 -> 132596.1 | O14: 热敏 | P14: 203 | Q14: / | R14: 127mm/s | S14: 单色 | T14: 5.95 | U14: 灰色 | V14: Windows 10及以上； MAC OS X 10.6 Snow Leopard及以上； 以及使用当前CUPS打印机驱动程序的Linux系统。 | W14: 地址、运输、邮寄、文件夹、条形码、活页夹标签以及姓名标签、腕带和收据 | X14: 1. 通过USB串行或并行端口连接，并与直接热敏标签卷兼容； 2. 热敏技术打印，无需墨水或碳粉； 3. 专为耐用性和频繁使用而设计； 4. 203 dpi，打印速度5英寸/秒； 5. 精准打印，不浪费； 6. 与Windows 10及更高版本兼容。 | Y14: 1. 不兼容Wind10系统； 2. 无法连接以太网，通信连接失败； 3. 操作复杂，难使用； 4. 电源适配器坏了； 5. 打印标签尺寸不准确。
A15: Phomemo | B15: B07TX9PX1K | C15: =N15/GETPIVOTDATA("求和项:月销售额",市场分析!$M$3) -> 0.013460277 | D15: https://www.amazon.com/Phomemo-Printer-Printing-Thermal-Compatible/dp/B07TX9PX1K/ref=sr_1_1?dchild=1&keywords=B07TX9PX1K&qid=1600764882&sr=8-1 | F15: 10 | G15: #10,698 | H15: 210 | I15: 4 | J15: 149.99 | K15: 442 | L15: 20 | M15: 600 | N15: =J15*M15 -> 89994 | O15: 热敏 | P15: 203 | Q15: / | R15: 150mm/s | S15: / | T15: 2 | U15: 白色 | V15: Windows, Mac OS | W15: 运输标签，仓库标签，条形码和ID标签，批量邮件标签 | X15: 1. 150mm / s的速度进行高速打印； 2. 打印宽度最大为4''，可连续工作12个小时以上； 3. 6英寸/秒打印速度打印4“x6“标签； 4. 与Windows，Mac OS兼容； 5. 无需购买任何墨水，碳粉或色带； 6. 与所有主要的运输平台兼容； 7. 内存：8MB SDRAM，2MB闪存； 8. 插入标签，打印机将自动捕获标签。 | Y15: 1. 打印标签尺寸不准确，只打印出部分内容； 2. 打印的标签颜色变淡； 3. 启动慢，卡顿，堵塞； 4. 打印空白或者相同的标签； 5. 无法与Wind10系统兼容。
B16: B07XXB2MXN | C16: =N16/GETPIVOTDATA("求和项:月销售额",市场分析!$M$3) -> 0.0015613167 | D16: https://www.amazon.com/Phomemo-M110-Label-Maker-Bluetooth-Compatible/dp/B07XXB2MXN/ref=sr_1_1?dchild=1&keywords=B07XXB2MXN&qid=1600764898&sr=8-1 | F16: 26 | G16: #34,950 | H16: 191 | I16: 4.1 | J16: 86.99 | K16: 324 | L16: 4 | M16: 120 | N16: =J16*M16 -> 10438.8 | O16: 热敏 | P16: / | Q16: 是 | R16: / | S16: / | T16: 1 | U16: 黑色 | V16: 蓝牙连接“打印大师”APP | W16: 衣服标签，价格标签，电缆标签，珠宝标签，地址标签，文件夹标签 | X16: 1. 迷你蓝牙无线热敏移动标签打印机； 2. 轻松连接手机，APP中有很多模板； 3. 宽度范围为20mm〜50mm，最大宽度为48mm。 4. 强大的功能-OCR-光学字符识别； 5. 热敏打印技术无需墨水或碳粉； 6. 方便携带，内置1500mAh可充电电池，可待机1周。 | Y16: 1. 程序故障，保存的标签内容自动消失； 2. 打印出的标签尺寸很小； 3. 可选择的字体太少； 4. 应用程序无法运行。
A17: Rollo | B17: B01MA3EYC5 | C17: =N17/GETPIVOTDATA("求和项:月销售额",市场分析!$M$3) -> 0.30061786 | D17: https://www.amazon.com/Rollo-Label-Printer-Commercial-Compatible/dp/B01MA3EYC5/ref=sr_1_1?dchild=1&keywords=B01MA3EYC5&qid=1600765002&sr=8-1 | F17: 2 | G17: #633 | H17: 4733 | I17: 4.7 | J17: 199.99 | K17: 1440 | L17: 335 | M17: 10050 | N17: =J17*M17 -> 2009899.5 | O17: 热敏 | P17: / | Q17: / | R17: 150mm/s | S17: / | T17: 2.2 | U17: 灰色 | V17: Windows, Mac； | W17: 适合所有快递标签，包括UPS, USPS | X17: 1. 与Thermal Direct Label一起使用； 2. 150mm / s的高速打印； 3. 热敏技术无需碳粉或墨水； 4. 与所有主要的运输平台兼容； 5. 与Windows和Mac兼容； 6. 可以打印宽度从1.57英寸到4.1英寸的标签。 | Y17: 1. 打印出空白的标签 2. 标签质量差，无法被识别出来 3. 标签有斑点，模糊看不清 4. 长期使用后会褪色，颜色变淡 5. 使用六个月后冒烟 6. 卡顿，每次只能打印出一个标签
O18: 热敏 | P18: 203 | R18: 150mm/s | T18: / | U18: 白色 | V18: Windows 2000,XP,Vista7,8,10 MAC, LINUX | X18: 1. 直热式，分辨率：203dpi（8dots / mm）; 2. 宽度最大108mm，最大长度300mm; 3. 高达6IPS的高速打印且噪音低； 4. 最高速度150mm / s; 5. 内存：2MB RAM：2MB闪存； 6. 设计紧凑，内置适配器，节省更多空间； 7. 打印机头增强了涂层，更加耐用； 8. 较大尺寸的橡胶辊防止标签粘着; 9. 自动标签检测 10. 错误重印技术
A21: 标签打印机SWOT分析 | B21: Strength | D21: Weakness
B22: 1. 品质相对稳定，比竞品更有保障； 2. 具有较高的分辨率，能够打印清楚的标签； 3. 设计紧凑，体积小，能节省很大的办公空间，并且方便携带； 4. 打印速度较快，能满足客户的紧急需求； 5. 目前有较大的空间和优势 6. 电子办公产品是汉印强项，且具有成品； 7. 具有配套产品、耗材可以增长大量销售额； 8. 产品容易做升级和优化。 | D22: 1. 客户拥有不同的设备，很难兼容每一个操作系统，对兼容性要求较高； 2. 标签打印机普遍存在较多的客诉问题，维护评分难度大； 3. 打印机更新迭代快，市场上不断出现功能多元化的打印机； 4. 打印机操作步骤繁多，操作麻烦； 5. 客户对打印机的打印质量和打印容量有较高的要求； 6. 品牌没有知名度，需要长期做品宣工作； 7. 亚马逊自营的大牌品牌效应大和链接稳定；
A23: Opportunity | B23: SO | D23: OW
A24: 打印机已经成为办公必备品之一，市场关注度逐年攀升； | B24: 1. 强大的售后体系（call center) 2. 强大的品宣力度（建立完整的品牌体系）； 3. 强大的研发力度； | D24: 1. 进入市场较晚，作为后入市场者，较难抢占市场份额； 2. 品牌/RV积累较少，前期品宣不易。 3. 说明书内容过于简单粗略
A25: Threat | B25: ST | D25: WT
A26: 1、Rollo、DYMO、Brother、ZEBRA占有市场较大； 2、众多新兴电商品牌显露头角； 3. 市场上产品价格跨度较大，汉印打印机有一定的成本，价格战不具有优势。 | B26: 1. 产品功能和配件齐全，便于配套销售增加销量； 2. 是汉印强项产品，有很强的实力； 3. 产品升级容易，能够不断迭代产品 | D26: 1. 大品牌市场占有率较高，知名度高，前期较难进入市场； 2. 品牌积累不足，市场份额小； 3. 成本较高，不利于定价； 4. 兼容性要求高，客诉问题多，评分维护困难。

Sheet 竞品品牌分析
A1: 对标品牌分析
B2: 竞品品牌 | C2: 细分市场 | D2: 市场份额 | F2: 指标 | G2: 情况
A3: 竞对 | B3: DYMO（美国 帝么股份有限公司） | C3: Office Products | D3: 0.3413 | E3: 产品 | F3: 星级 | G3: 主要ASIN星级：3.8- 4.7，星级相对维护较好
F4: RV数量 | G4: 主要ASIN：15-3400，平均2000
F5: 价格 | G5: $89.99-$312.99, 各价格段均有分布
F6: 产品线布局 | G6: 专注印刷类产品，分办公及工业类，主要品线有标签打印机，工业标签制作机，标签，标签带（标签打印机和工业标签制作机产品布局较为齐全）
F7: 上新速度 | G7: 标签打印机均为老品，多年前已上线
E8: 供应链 | F8: 资金投入 | G8: 该品牌属于诺威品牌股份有限公司旗下品牌，总部位于美国桑迪斯普林斯 (佐治亚州)，是一家全球市场营销各类产品，包括：派克、帝么、史派、纸美、屈伯德等著名品牌用品，已上市。帝么股份有限公司，是一家全球生产电子标贴、印刷标贴、以及其他印刷镭射影碟等公司。 其企业成立于1958年，现时为诺威屈伯德旗下公司，资金实力雄厚。
F9: 供货能力 | G9: 自身供货能力较强，核心listing偶有断货现象，断货两周能接上
F10: 库存周转 | G10: 亚马逊自营，供货能力强，少有断货情况
F11: 研发实力 | G11: 研发实力强劲，多种型号与外观，有外观专利
F12: 资源整合能力 | G12: 资源整合能力较强，各国家市场均有涉猎
E13: 运营 | F13: 市场洞察力 | G13: 市场洞察力一般，市场排名较为稳定，波动不大
F14: 流量/转化 | G14: 广告bid出价较高，长时间居于shipping label printer首页中间及下方位置。但是站内投入不大，在label print下无广告位，主要关键词首页有编辑推荐
F15: 站内活动 | G15: 站内deal较少参与
F16: 独立站/官网 | G16: 有独立官网及其他独立站，官网较为简单，产品分布齐全但不能在官网进行购买，会跳转至亚马逊，沃尔玛等渠道进行购买 官网：https://www.dymo.com/en-US
F17: 站外品宣 | G17: Youtube无官方频道，FB粉丝3.78W，互动较少。INS粉丝2.6W，发布内容大多为厨具储存类产品，本营业务指向性不强
F18: 售后体系 | G18: 官方售后服务热线+邮箱双重售后，售后系统比较完善，但是亚马逊上售后服务一般，差评基本无回复及处理
B19: Brother（日本 兄弟工业株式会社） | C19: Office Products | D19: 0.156 | E19: 产品 | F19: 星级 | G19: 主要ASIN星级：4.2 - 4.3，评分较危险
F20: RV数量 | G20: 主要ASIN：190-1200
F21: 价格 | G21: 79.99-488.39
F22: 产品线布局 | G22: 专注打印类类产品，核心产品为打印机、缝纫机、大型机床、标签打印机和打字机、传真机等。产品布局齐全。
F23: 上新速度 | G23: 标签打印机均为老品，多年前已上线
E24: 供应链 | F24: 资金投入 | G24: 兄弟工业株式会社是一家多元化经营的日本公司，生产各种各样的产品，包括打印机、缝纫机、大型机床、标签打印机和打字机、传真机、电脑和其他相关电子产品。资金实力雄厚，迅速从进口公司转为出口公司。资金实力雄厚。
F25: 供货能力 | G25: 部分产品自发货，部分产品亚马逊自营，未曾断货，库存掌控力强
F26: 库存周转 | G26: 周转迅速，无滞销品
F27: 研发实力 | G27: 研发实力强，涉及各国各大市场，产品种类丰富。
F28: 资源整合能力 | G28: 资源整合能力较强，集研发设计制造于一体
E29: 运营 | F29: 市场洞察力 | G29: 线上市场洞察力比较强，在打造品牌方面有一定的成果，采用性价比及产品多样化的运营策略
F30: 流量/转化 | G30: 亚马逊站内流量高，站外流量较低但正在铺开建设
F31: 站内活动 | G31: 站内活动参与度不高，deal较少参与
F32: 独立站/官网 | G32: 有自己的官网及独立站，官网设计有一定的品牌格调，简约大方 官网：https://www.cosori.com/
F33: 站外品宣 | G33: 站外品宣较弱，YouTube站外视频1300多个，更新频繁但播放量与互动较少，FB无官方页面，有少部分群组及公共主页。
F34: 售后体系 | G34: 官方售后服务热线+邮箱+美国本地公司，本地化较强，构建完整售后体系，亚马逊平台上2月份前会维护差评，2月份后基本不再维护。
B35: ZEBRA（美国 斑马技术公司） | C35: Office Products | D35: 0.0963 | E35: 产品 | F35: 星级 | G35: 主要ASIN星级：2.8 - 4.5，平均3.8，评分较差
F36: RV数量 | G36: 主要ASIN：2-140
F37: 价格 | G37: 集中价格段$198-$699，主打高端市场
F38: 产品线布局 | G38: 主打打印类型产品，主营产品有标签打印机，工业打印机和标签及散热带等
F39: 上新速度 | G39: 上新速度较慢，还是以老款为主，新品两年间上线一款
E40: 供应链 | F40: 资金投入 | G40: 斑马技术是一家位于美国伊利诺伊州在NASDAQ上市的计算机外设制造公司。主要从事票据、条码标签打印机、RFID智能标签打印机、固定或手持读码器。 全世界170多个国家或地区，世界500强企业超过90%都在使用斑马打印机。
...

Sheet 用户场景分析
A1: 客户使用关键词 | B1: 数量 | C1: 占比 | D1: 用户群体 | E1: 数量 | F1: 占比 | G1: 使用场景 | H1: 数量 | I1: 占比 | J1: 提到的功能/特点 | K1: 数量 | L1: 占比
A2: label maker | B2: 395 | C2: =B2/SUM($B$2:$B$7) -> 0.14041948 | D2: officer | E2: 347 | F2: =E2/SUM($E$2:$E$4) -> 0.72291667 | G2: office | H2: 447 | I2: =H2/SUM($E$2:$E$4) -> 0.93125 | J2: easy to use | K2: 650 | L2: =K2/SUM($K$2:$K$8) -> 0.71585903
A3: label printer | B3: 1382 | C3: =B3/SUM($B$2:$B$7) -> 0.49129044 | D3: seller | E3: 126 | F3: =E3/SUM($E$2:$E$4) -> 0.2625 | G3: company | H3: 227 | I3: =H3/SUM($E$2:$E$4) -> 0.47291667 | J3: print clear | K3: 107 | L3: =K3/SUM($K$2:$K$8) -> 0.11784141
A4: shipping label printer | B4: 448 | C4: =B4/SUM($B$2:$B$7) -> 0.15926058 | D4: doctor/nurse/teacher | E4: 7 | F4: =E4/SUM($E$2:$E$4) -> 0.014583333 | G4: shop/store | H4: 248 | I4: =H4/SUM($E$2:$E$4) -> 0.51666667 | J4: good label quality | K4: 38 | L4: =K4/SUM($K$2:$K$8) -> 0.04185022
A5: label maker machine | B5: 92 | C5: =B5/SUM($B$2:$B$7) -> 0.032705297 | D5: express/shipper | E5: 21 | F5: =E5/SUM($E$2:$E$4) -> 0.04375 | G5: logistics/express | H5: 13 | I5: =H5/SUM($E$2:$E$4) -> 0.027083333 | J5: fast print speed, don't jam | K5: 33 | L5: =K5/SUM($K$2:$K$8) -> 0.036343612
A6: thermal printer | B6: 381 | C6: =B6/SUM($B$2:$B$7) -> 0.13544259 | G6: family | H6: 11 | I6: =H6/SUM($E$2:$E$4) -> 0.022916667 | J6: easy to connect, good compatibility | K6: 43 | L6: =K6/SUM($K$2:$K$8) -> 0.047356828
A7: barcode printer | B7: 115 | C7: =B7/SUM($B$2:$B$7) -> 0.040881621 | G7: hospital | H7: 4 | I7: =H7/SUM($E$2:$E$4) -> 0.0083333333 | J7: print accurate | K7: 17 | L7: =K7/SUM($K$2:$K$8) -> 0.018722467
A8: usps label printer | B8: 93 | C8: =B8/SUM($B$2:$B$7) -> 0.033060789 | J8: saving paper | K8: 20 | L8: =K8/SUM($K$2:$K$8) -> 0.022026432
A9: label printer for shipping packages | B9: 57 | C9: =B9/SUM($B$2:$B$7) -> 0.020263064
A32: 汇总分析：
A33: 1. 关键词：label printer是客户提到最频繁的关键词，使用频率高达49%；此外客户在搜索时主要使用label maker、shipping label printer和thermal printer这三个关键词，以上关键词适合用于标题以及广告重点关注的词；除此之外，客户使用到的关键词流量排序是：barcode printer、label maker machine、usps label printer和label printer for shipping packages，可用来埋词测试。 2. 用户群：根据用户群体和用户场景的分析，企业办公室工作者对标签打印机的需求最大，是最主要的客户资源，占比70%以上；商品卖家，销售人员的需求也较高；此外，还有来自教育和医疗行业的客户需求；需要注意到的是物流快递行业从业者对标签打印机的需求应该是很大的，但是通过客诉分析很难看出客户的职业，因此可能会带来一定的误差。 3. 提到的功能： （1）科技快速发展带来标签打印机更新迭代较快，一些品牌不断推出新的功能导致打印机的操作越来越麻烦，因此超过70%的客户最关注的是打印机是否操作简便，在客诉调查中发现更多的客户希望拿到的一台“即插即用”的打印机，而不是程序复杂、功能繁琐、操作麻烦的打印机； （2）客户对打印出的标签质量关注度也很高，一些打印机打印出的条码不清晰，颜色太深或太浅，导致扫码枪识别不出来； （3）此外，打印机的高度兼容性也是客户十分关注的点，一些产品在电脑系统更新后就没办法兼容，导致产品无法使用； （4）客户对打印机的打印速度、是否卡顿、打印尺寸和内容是否精确也十分关注，一些产品因为打印不精确导致浪费纸张，增加客户的成本而带来客诉。

Sheet 用户需求分析
B1: Brand | E1: DYMO | G1: Brother | I1: Zebra | K1: Phomemo | L1: Rollo
B2: Asin | E2: B0027JBLV4 | F2: B0027J9KH6 | G2: B01MTWGMRR | H2: B005TJMC0S | I2: B07HLVSHVZ | J2: B00EUN90SG | K2: B07TX9PX1K | L2: B01MA3EYC5
B3: 首图
B4: 差评类型 | C4: 占比 | D4: 总计 | E4: =SUM(E5:E39) -> 82 | F4: =SUM(F5:F39) -> 67 | G4: =SUM(G5:G39) -> 49 | H4: =SUM(H5:H39) -> 57 | I4: =SUM(I5:I39) -> 12 | J4: =SUM(J5:J39) -> 15 | K4: =SUM(K5:K39) -> 28 | L4: =SUM(L5:L39) -> 71
A5: 功能性 | B5: 打印标签尺寸、内容、类型不准确，只印到一部分 | C5: =D5/SUM($D$5:$D$39) -> 0.065616798 | D5: =SUM(E5:L5) -> 25 | E5: 5 | F5: 3 | G5: 3 | H5: 3 | I5: 1 | J5: 1 | K5: 6 | L5: 3
B6: 标签质量差，颜色变淡/浓/脏/斑点，不清楚/模糊，无法识别 | C6: =D6/SUM($D$5:$D$39) -> 0.047244094 | D6: =SUM(E6:L6) -> 18 | E6: 2 | G6: 1 | I6: 1 | K6: 4 | L6: 10
B7: 打印空白标签/相同标签，浪费纸张 | C7: =D7/SUM($D$5:$D$39) -> 0.097112861 | D7: =SUM(E7:L7) -> 37 | E7: 10 | F7: 12 | G7: 1 | I7: 1 | J7: 1 | K7: 1 | L7: 11
B8: 不兼容MAC、PC、Wind10、stamps等 | C8: =D8/SUM($D$5:$D$39) -> 0.19160105 | D8: =SUM(E8:L8) -> 73 | E8: 12 | F8: 10 | G8: 6 | H8: 27 | I8: 2 | J8: 5 | K8: 7 | L8: 4
B9: 启动慢，响应速度很慢，浪费时间 | C9: =D9/SUM($D$5:$D$39) -> 0.010498688 | D9: =SUM(E9:L9) -> 4 | E9: 1 | G9: 1 | K9: 1 | L9: 1
B10: 堵塞/卡顿、不流畅、撕裂纸张，缠绕 | C10: =D10/SUM($D$5:$D$39) -> 0.062992126 | D10: =SUM(E10:L10) -> 24 | E10: 10 | F10: 6 | G10: 1 | H10: 2 | K10: 1 | L10: 4
B11: 标签粘在打印头和传感器上，打印时自动剥离标签 | C11: =D11/SUM($D$5:$D$39) -> 0.015748031 | D11: =SUM(E11:L11) -> 6 | E11: 5 | G11: 1
B12: 打印跳过，顺序乱/错误标签 | C12: =D12/SUM($D$5:$D$39) -> 0.028871391 | D12: =SUM(E12:L12) -> 11 | F12: 2 | K12: 1 | L12: 8
A13: 设计性 | B13: 使用麻烦，操作复杂，难使用，浪费时间 | C13: =D13/SUM($D$5:$D$39) -> 0.070866142 | D13: =SUM(E13:L13) -> 27 | E13: 3 | F13: 4 | G13: 8 | H13: 5 | J13: 1 | K13: 1 | L13: 5
B14: 无法大规模打印 | C14: =D14/SUM($D$5:$D$39) -> 0.0078740157 | D14: =SUM(E14:L14) -> 3 | H14: 1 | L14: 2
B15: 软件安装/操作麻烦，程序难操作无法使用 | C15: =D15/SUM($D$5:$D$39) -> 0.10498688 | D15: =SUM(E15:L15) -> 40 | E15: 15 | F15: 14 | G15: 5 | H15: 4 | J15: 1 | L15: 1
B16: 网络连接/通信连接故障 | C16: =D16/SUM($D$5:$D$39) -> 0.049868766 | D16: =SUM(E16:L16) -> 19 | G16: 13 | H16: 3 | J16: 3
B17: 打印程序指令错乱，打印一次后要重新设置，每次打印都需校准 | C17: =D17/SUM($D$5:$D$39) -> 0.018372703 | D17: =SUM(E17:L17) -> 7 | E17: 1 | F17: 1 | G17: 2 | L17: 3
B18: 有噪音/巨响 | C18: =D18/SUM($D$5:$D$39) -> 0.0052493438 | D18: =SUM(E18:L18) -> 2 | E18: 1 | F18: 1
B19: 只与UPS Worldship一起工作 | C19: =D19/SUM($D$5:$D$39) -> 0.0078740157 | D19: =SUM(E19:L19) -> 3 | I19: 3
B20: 自动打印大量标签 | C20: =D20/SUM($D$5:$D$39) -> 0.018372703 | D20: =SUM(E20:L20) -> 7 | E20: 2 | F20: 5
A21: 批次性 | B21: 质量差，使用寿命短，不工作 | C21: =D21/SUM($D$5:$D$39) -> 0.14435696 | D21: =SUM(E21:L21) -> 55 | E21: 14 | F21: 8 | G21: 3 | H21: 7 | I21: 2 | J21: 2 | K21: 3 | L21: 16
B22: 零件坏了，滚筒、电源适配器坏了 | C22: =D22/SUM($D$5:$D$39) -> 0.015748031 | D22: =SUM(E22:L22) -> 6 | G22: 2 | K22: 3 | L22: 1
B23: 防损做不好/次品，缺少配件 | C23: =D23/SUM($D$5:$D$39) -> 0.023622047 | D23: =SUM(E23:L23) -> 9 | F23: 1 | G23: 2 | H23: 2 | I23: 2 | J23: 1 | L23: 1
B24: 突然死机，机器冒烟了 | C24: =D24/SUM($D$5:$D$39) -> 0.01312336 | D24: =SUM(E24:L24) -> 5 | E24: 1 | H24: 3 | L24: 1
A26: 差评总结分析：
A27: 功能性： 1. 差评最多的点集中在产品的兼容性，在客户更新升级设备后无法连接打印机，产品不能满足广泛的连接需求导致了客诉，因此产品应具备高度的兼容性，以适应不同的操作系统；但也可能存在客户在购买前没有仔细阅读说明导致的客诉； 2. 其次是打印出的标签质量问题，一些打印机打印出大量空白标签或者相同的标签、标签不清楚、内容模糊，导致无法被扫码枪扫描出来，浪费了很多标签纸，增加了客户的成本； 3. 此外，打印机不能精准打印标签，只打印出部分内容、尺寸不准确也带来了较多客诉； 4. 打印机在打印过程中出现卡顿、不流畅、打印纸缠绕、打印顺序错乱也是导致客诉问题的主要原因之一。 设计性： （1）一些品牌为使产品的功能更加丰富、与市场上的产品区别开来而增加了更多复杂的程序和操作，例如设置自己品牌的程序和驱动软件，导致客户很难理解操作步骤增加客户的使用难度带来大量客诉问题，而客户需要的是能够“即插即用”产品； （2)一些产品存在打印程序指令错乱问题，有的打印机每一次打印都需要校对才能打印出标签，又有的打印机会自动打印大量标签， 在打印的过程中客户需要花大量时间去检查和监控，因此打印机在这方面的设计要注意； （3）很多客户需要一次性打印大量标签，打印机应该满足大量打印的需求； （4）有少量的打印机在工作时会发出噪音。 批次性： （1）产品的质量和使用寿命是客户最关注的方面，打印机应该满足一个长期的使用过程而不是仅使用几次后就坏了； （2）其次是产品的包装和运输方面，要做好防损工作，检查好包装内部零件； （3）有少量产品在使用过程中发热冒烟，给客户带来安全隐患。

Sheet 产品定位
A1: 产品定位表格
A2: ASIN | B2: 图片 | C2: 产品描述（产品属性、产品特征、基本信息） | D2: 用户画像 | E2: 使用场景 | F2: 产品卖点 | G2: 产品痛点与用户关心 | H2: 购买驱动因素 | I2: 退货分析 | J2: 产品创新 | K2: 礼品与季节性属性 | L2: review insight

Sheet 流量定位
A1: 流量定位
A2: ASIN | B2: 产品关键词（一级） | C2: 流量结构（H10工具总结） | D2: 流量类型（SIF工具总结） | E2: 拓展关键词 | F2: 类目流量 | G2: 同类竞品 | H2: 关联流量 | I2: 品牌流量 | J2: 站外流量
C3: 背部按摩相关流量 | D3: SP关键词 | E3: leg massager | F3: Manual Back Massagers | G3: B07FSCCX1P | H3: B019F42TBY | I3: Rollga | J3: youtube
C4: 瑜伽相关流量 | D4: 品牌关键词 | E4: Spine Supporters | F4: Manual Massage Balls | G4: B0B68CQJ7Z | H4: B00XM2MRGI | I4: Amazon Basic Care | J4: INS
C5: 背部支撑相关流量 | D5: SBV流量 | E5: Manual Back Massagers | F5: Pilates Spine Supporters | G5: B07TLP86CW | H5: B01BW2YYZQ | I5: LuxFit | J5: facebook
C6: 室内运动流量 | D6: 编辑推荐流量 | E6: foam roller | F6: Manual Massage Sticks | G6: B07FSCCX1P | H6: B06XSJGYLJ | I6: UpCircleSeven | J6: Pinterest
C7: foam roller相关流量 | D7: TR关键词 | E7: yoga wheel | F7: Foam Rollers | G7: B0B68CQJ7Z | H7: B003QCI4GG | I7: Innova Health and Fitness | J7: reddit

Sheet 产品测试报告
A1: 热敏标签打印机
A2: 产品示图 | C2: 测试汇总 | F2: 备注
C3: 优势： 1. 操作方便，下载驱动程序、插上电源后就可以使用，符合“即插即用”的需求； 2. 打印出的标签内容清晰，可清楚看到文字内容； 3. 打印速度快，能够满足大量且急需打印的需求； 4. 有记忆功能，中途暂停后会从上次中断处继续打印； 5. 可选择较多不同类型的运输标签，尺寸齐全； 6. 体积小，不占据空间； 劣势： 1. 有噪声，在安静的办公环境下会比较吵； 2. 无取消功能，如打印错了没办法立即取消，只能将原来的设置打印结束才可重新设置新的打印需求，会造成纸张和时间的浪费； 3. 打印几张标签后，出现亮绿灯不吸标签纸的情况，但机器并没有卡顿，找不出是何原因； 4. 出现不能完全复印标签内容的情况，边缘位置缺少内容，且横向的标签会变斜； 5. 说明书不齐全，没办法确定指示灯颜色变换代表机器处于什么状态，需要使用者自行摸索； 6. 白色外观及材质不耐脏。 | F3: 产品是否具有高度兼容性是客诉的重要原因之一，由于缺少设备，无法检测在MAC上是否工作流畅，需要商务或者客户自行测试。
B4: 1. 产品概述：汉印N41热敏标签打印机，出货标签打印机； 2. 体验时间：30分钟； 3. 体验目的：实测产品质量、操作方法及市场上客诉较多的内容； 4. 环境：办公环境； 5. 配件：打印机，电源线，USB端口线、说明指南。
B9: 客户或工厂自行常规测试项
B10: 特殊测试 | C10: 高温环境测试（40%以上） | D10: 建议客户自行摸底测试，主要是验证产品可靠性和寿命（老化）。
C11: 高湿环境测试(75%以上)
B12: 可靠性测试 | C12: 机械强度，如裸机跌落，振动，冲击测试 | D12: 需要根据大货出货包装进行验证。
B13: 安规测试 | C13: 外观结构安全性测试 | D13: 根据产品定义客户测试
C14: 高压，接地测试
C15: 耐火测试
C16: 内部结构安规测试
B17: 环保确认 | C17: 主要针对塑胶件或大件有塑料或缓冲包装产品的RoHS,Reach,加州65等 | D17: 根据产品定义客户测试
B18: 内部安装工艺及元器件检查 | D18: 此项检查包括电源线安装；电源插头极性检查；内部焊接，连接检查；内部关机元器件检查；内部工艺（如走线工艺，元器件打胶固定等等）；内部螺丝装配（螺丝柱尺寸，位置是否合理等等）
B19: 测试示图
B21: 1. 标签内容不能完全印在纸上，超出边缘，标签变斜 ； 2. 打印出的标签有斑点是市场上客诉的原因之一，在测试过程中仅打印了少量标签，却发现少量出现斑点的情况，可能会影响扫码，需要注意大量打印后是否仍然存在该问题； 3. 在测试过程中，仅打印几次后出现不吸纸的情况，当时指示灯变绿，纸张也没有折角和褶皱，需要打开掀开顶盖再关闭才会继续工作，这种情况出现了大概三次，没有找出原因。

Sheet 利润分析
A1: FBA利润核算表
B2: 运输方式 | C2: 国家 | D2: size | E2: 售价（当地币种） | F2: 汇率 （当地币种兑美金） | G2: 售价 （$） | H2: 产品成本 （$） | I2: 头程 （$） | J2: FBA发货费 | K2: 美国关税额 | L2: 平台佣金比例（%） | M2: 成交费 （$） | N2: 总成本 （$） | O2: 毛利 （$） | P2: 平台毛利率 | Q2: 全年推广费（预估） | R2: 退款比率（预估） | S2: 净利率【扣除12%佣金】 | T2: 备注说明
B3: 海运 | C3: US | D3: SP410 | E3: 109.99 | F3: 1 | G3: 109.99 | H3: 45 | I3: 1.1 | J3: 5.8 | K3: 0 | L3: 0.15 | M3: =L3*G3 -> 16.4985 | N3: =SUM(J3,M3,I3,H3,K3) -> 68.3985 | O3: =G3-N3 -> 41.5915 | P3: =O3/G3 -> 0.37813892 | Q3: 0.08 | R3: 0.08 | S3: =P3-Q3-R3-12% -> 0.098138922
B4: 快船 | C4: US | D4: SP410 | E4: 109.99 | F4: 1 | G4: 109.99 | H4: 45 | I4: 2.57 | J4: 5.8 | K4: 0 | L4: 0.15 | M4: =L4*G4 -> 16.4985 | N4: =SUM(J4,M4,I4,H4,K4) -> 69.8685 | O4: =G4-N4 -> 40.1215 | P4: =O4/G4 -> 0.36477407 | Q4: 0.08 | R4: 0.08 | S4: =P4-Q4-R4-12% -> 0.08477407
B6: 美国关税额 | C6: （采购价*数量）*关税
E7: RMB | F7: USD
B8: 海运头程 | C8: CBM*海运单价 | D8: SP410 | E8: =950*(0.56*0.34*0.34)/8 -> 7.6874 | F8: =E8/7 -> 1.0982
D9: SP410 | E9: =9*16/8 -> 18 | F9: =E9/7 -> 2.5714286
B77: FBA发货费对标款 | C77: GR20AA | D77: B07WLSQPM5
C78: GR33AA | D78: B077KDNCHG
B79: 空炸烤箱对标 | D79: B086K2N9GN

Sheet 投入产出表
A1: 标签打印机SP410 运营计划
A2: 产品： | C2: 阶段一 | E2: 阶段二
A3: 阶段目标 | B3: 阶段 | C3: 完成P1.1目标 | D3: 完成P1.2目标 | E3: P2.1 | F3: P2.2
B4: 目标 | C4: reviews>50 rate>=4.8 | D4: reviews>150 rate>=4.8 | E4: rank<5（筹备新款） reviews>300 rate>=4.5 | F4: rank<5（上线新款） reviews>500 rate>=4.5
A5: MILESTONE | B5: MILESTONE | C5: 完成P1.1目标 | D5: 完成P1.2目标 | E5: 完成P2.1目标 | F5: 完成P2.2目标
B6: 预计时间 | C6: 11月-12月 | D6: 12月-1月 | E6: 1月-2月 | F6: 2月-3月
A7: 营销费用 | B7: 站内 (账号扣款不需要打款) | C7: 8800 | D7: 9000 | E7: 8000 | F7: 11500
B8: 站外(需打款) (刷单/红人/礼品/删差评等) | C8: 站外费用：15000 品宣：$5000 | D8: 站外费用：15000 品宣：$10000 | E8: 站外费用：7000 品宣：$3500 | F8: 站外费用：10000 品宣：$5000
B9: 合计 | C9: 28800 | D9: 34000 | E9: 18500 | F9: 26500
A10: 动作 | B10: 动作 | C10: 1. 上新链接，预计11月上旬到货 2. 产品到货后C账号安排测评100个（带评+免评），累积评论，维持满星星级 3. 广告投放，主打关键词 shipping label printers 4.测试Coupon 5.旺季前抓紧站外品宣引流，联系YouTube红人及网站编辑宣传推广，提前造势，提升排名。 | D10: 1.判断市场情况上秒杀/旺季各项活动，加大广告投放，站内站外同步推广,主推关键词label printers 2.抓紧旺季进行部分红人折扣营销活动，推广品牌 3.通过测评和删差评进行评分维护，维持评分4.8 4.申报秒杀活动 | E10: 1. 根据链接表现情况，准备上新其他款式或颜色新品 2. 总结自己产品及市场上的标签打印机产品表现情况，综合退货报告和客诉报告，重新调研准备上新品 3. 继续申报秒杀活动 | F10: 1.旧品创建新链接进行推广 2. 准备新品上线 3.旧品上LD/7Day Deal, 可适当设置Coupon推广 4.新品旧品绑定变体 5.联系品宣，加强红人宣传和媒体宣传
A11: 销售预计 | B11: 销售量/日 | C11: ≥20 | D11: ≥40 | E11: ≥70 | F11: ≥100
B12: 销售量/月 | C12: ≥600 | D12: ≥1200 | E12: ≥2100 | F12: ≥3000
B13: 销售均价 | C13: ≥109.99 | D13: ≥109.99 | E13: ≥109.99 | F13: ≥109.99
B14: 销售额/日 | C14: ≥$2200 | D14: ≥$4400 | E14: ≥$7700 | F14: ≥$11000
B15: 销售额/月 | C15: ≥66000 | D15: ≥132000 | E15: ≥231000 | F15: ≥330000
C16: 1. 市场平均价格$167, 我们的产品相对于平均水平$115来说，成本有较大优势，且功能相对齐全（热敏技术，分辨率，兼容WINDOWS和MAC，高速打印）。 2. 该市场被DYMO，Brother,Zebra等品牌瓜分近九成市场容量，新品牌上线竞争环境较为被动。 3. 我们前期先对标Phomemo品牌，两款产品外观及功能较为相似，该款评分相对市场为弱势项，后期产品规划可参考品牌DYMO，主打中高端。 Phomemo为中国卖家，公司位于广东珠海，且为初创型企业，创立于2017年。 4. 按摩仪市场容量尚可，市场评分四星半占比高，但相对售后及品宣较为薄弱，上线需要测评费用支持+站外同步宣传+售后体系打造，打造品牌效应。 5. 前期需投入，第四个月后开始盈利。若产品质量过关，后面可有不错的盈利。
A23: 首批备货1500PCS

Sheet 数据源
A1: Label Printers
A2: 排名 | B2: 大类排名 | C2: ASIN | D2: 商品 | E2: 品牌 | F2: 分类 | G2: 月销量 | H2: 日销量 | I2: 价格 | J2: 月销售额 | K2: 评论数 | L2: 评分 | M2: 上架天数 | N2: 发货方式
A3: 1 | B3: #526 | C3: B0027JBLV4 | D3: DYMO Label Printer | LabelWriter 450 Direct Thermal Label Printer, Great for Labeling, Filing, Mailing, Barcodes and More, Home & Office Organization | E3: DYMO | F3: Office Products | G3: 11580 | H3: =G3/30 -> 386 | I3: 79.99 | J3: =I3*G3 -> 926284.2 | K3: 3331 | L3: 4.5 | M3: 3469 | N3: AMZ
A4: 2 | B4: #633 | C4: B01MA3EYC5 | D4: ROLLO Label Printer - Commercial Grade Direct Thermal High Speed Printer – Compatible with Etsy, eBay, Amazon - Barcode Printer - 4x6 Printer | E4: Rollo | F4: Office Products | G4: 10050 | H4: =G4/30 -> 335 | I4: 199.99 | J4: =I4*G4 -> 2009899.5 | K4: 4733 | L4: 4.7 | M4: 1440 | N4: FBA
A5: 3 | B5: #1,630 | C5: B07DXH5CCJ | D5: DYMO LabelWriter 450 Turbo Thermal Label Printer (1752265) with LabelWriter LW Adhesive White Mailing Address Labels Retail Box With 2 Rolls of 350 Labels per Roll & Digital Shipping Scale, 400-pound | E5: DYMO | F5: Office Products | G5: 4500 | H5: =G5/30 -> 150 | I5: 208.97 | J5: =I5*G5 -> 940365 | K5: 3039 | L5: 4.4 | M5: 4050 | N5: AMZ
A6: 4 | B6: #3,908 | C6: B0027J9KH6 | D6: DYMO Label Writer 450 Twin Turbo label printer, 71 Labels Per Minute, Black/Silver (1752266) | E6: DYMO | F6: Office Products | G6: 1890 | H6: =G6/30 -> 63 | I6: 139.99 | J6: =I6*G6 -> 264581.1 | K6: 1141 | L6: 4.3 | M6: 4072 | N6: AMZ
A7: 5 | B7: #5,379 | C7: B0081TZD54 | D7: Brother QL-720NW Professional, High-speed Label Printer with Built-in Ethernet and Wireless Networking (QL720NW) | E7: Brother | F7: Office Products | G7: 1350 | H7: =G7/30 -> 45 | I7: 488.39 | J7: =I7*G7 -> 659326.5 | K7: 363 | L7: 4.3 | M7: 3025 | N7: FBM
A8: 6 | B8: #5,457 | C8: B08DQRH5B3 | D8: BESTEASY Label Printer,USPS Label Printer,4x6 Direct Thermal Printer,Commercial Grade Label Printer,High Speed,Clear Printing,Compatible with USPS,FedEx,Amazon, Ebay,UPS,Etsy,Shopify,etc | E8: BESTEASY | F8: Office Products | G8: 1320 | H8: =G8/30 -> 44 | I8: 145.99 | J8: =I8*G8 -> 192706.8 | K8: 4 | L8: 5 | M8: 48 | N8: FBA
A9: 7 | B9: #6,603 | C9: B01MTWGMRR | D9: Brother QL-810W Ultra-Fast Label Printer with Wireless Networking | E9: Brother | F9: Office Products | G9: 1050 | H9: =G9/30 -> 35 | I9: 129.99 | J9: =I9*G9 -> 136489.5 | K9: 317 | L9: 4.3 | M9: 1346 | N9: AMZ
A10: 8 | B10: #7,408 | C10: B01N49R9KP | D10: Brother QL-800 High-Speed Professional Label Printer, Lightning Quick Printing, Plug & Label Feature, Brother Genuine DK Pre-Sized Labels, Multi-System Compatible – Black & Red Printing Available | E10: Brother | F10: Office Products | G10: 930 | H10: =G10/30 -> 31 | I10: 79.99 | J10: =I10*G10 -> 74390.7 | K10: 749 | L10: 4.2 | M10: 1389 | N10: AMZ
A11: 9 | B11: #9,612 | C11: B079G51QTB | D11: Brother QL-1100 Wide Format, Postage and Barcode Professional Thermal Label Printer, Black | E11: Brother | F11: Office Products | G11: 690 | H11: =G11/30 -> 23 | I11: 179.99 | J11: =I11*G11 -> 124193.1 | K11: 190 | L11: 4.2 | M11: 4335 | N11: AMZ
A12: 10 | B12: #10,698 | C12: B07TX9PX1K | D12: Phomemo Label Printer- 4''×6'' Label Printer- High Speed Printing at 150mm/s PM-246 Thermal Printer, Compatible with UPS, FedEx, Amazon, Ebay, Etsy, Shopify,etc | E12: Phomemo | F12: Office Products | G12: 600 | H12: =G12/30 -> 20 | I12: 149.99 | J12: =I12*G12 -> 89994 | K12: 210 | L12: 4 | M12: 442 | N12: FBA
A13: 11 | B13: #10,971 | C13: B07DXDSPFT | D13: DYMO RHINO 4200 Label Maker (1801611) with Industrial Labels for LabelWriter and Industrial Label Makers, Black on White, 3/4", 1 Roll | E13: DYMO | F13: Office Products | G13: 600 | H13: =G13/30 -> 20 | I13: 89.99 | J13: =I13*G13 -> 53994 | K13: 705 | L13: 4.6 | M13: 3231 | N13: AMZ
A14: 12 | B14: #12,034 | C14: B07HLVSHVZ | D14: Zebra ZP 450 Label Thermal Bar Code Printer ZP450-0501-0006A | E14: ZEBRA | F14: Office Products | G14: 510 | H14: =G14/30 -> 17 | I14: 289.99 | J14: =I14*G14 -> 147894.9 | K14: 54 | L14: 4 | M14: 727 | N14: FBM
... A50: 48 | B50: #57,391 | C50: B07RKX8JMX | D50: NETUM Label Maker - Portable Bluetooth Thermal Label Printer Apply to Clothing, Jewelry, Retail, Mailing, Barcode, Compatible for Android & iOS System | E50: NETUM | F50: Office Products | G50: 30 | H50: =G50/30 -> 1 | I50: 86.88 | J50: =I50*G50 -> 2606.4 | K50: 94 | L50: 3.7 | M50: 504 | N50: FBA
