Workbook

Sheet 决策总览
A2: 墨西哥美客多｜壁灯选品决策
A3: 范围：用户上传的TOP400商品链接；近30天销量与销售额为工具估算值。全站结果数3,586来自截图，不作为市场总量分母。
A5: 样本链接 | B5: =COUNTA('400链接明细'!B4:B403) -> 400 | C5: 样本30天销量 | D5: =SUM('400链接明细'!N4:N403) -> 69143 | E5: 样本销售额 MXN | F5: =SUM('400链接明细'!Q4:Q403) -> 15718189 | G5: 核心壁灯链接 | H5: =SUM(B11:B15) -> 319 | J5: 平均销售额MXN | K5: =15718189/69143 -> 227.32871
A6: 核心壁灯销量 | B6: =C16 -> 54348 | C6: 核心壁灯销售额 MXN | D6: =D16 -> 11940507 | E6: 相邻/待复核销量 | F6: =D5-B6 -> 14795 | G6: 原排序TOP30销量 | H6: =SUM('400链接明细'!N4:N33) -> 20551
A8: 细分结构：主用途互斥归类；只用“核心壁灯”五类计算壁灯机会
A10: 细分 | B10: 链接数 | C10: 30天销量 | D10: 30天销售额 MXN | E10: 平均标价 MXN | F10: 占核心销量 | G10: 判断
A11: 有线户外/通用壁灯 | B11: =COUNTIF('400链接明细'!$D$4:$D$403,A11) -> 189 | C11: =SUMIF('400链接明细'!$D$4:$D$403,A11,'400链接明细'!$N$4:$N$403) -> 33039 | D11: =SUMIF('400链接明细'!$D$4:$D$403,A11,'400链接明细'!$Q$4:$Q$403) -> 6436705.6 | E11: =IFERROR(AVERAGEIF('400链接明细'!$D$4:$D$403,A11,'400链接明细'!$J$4:$J$403),0) -> 201.61434 | F11: =IFERROR(C11/$C$16,0) -> 0.60791565 | G11: 高需求，高同质化
A12: 太阳能户外壁灯 | B12: =COUNTIF('400链接明细'!$D$4:$D$403,A12) -> 41 | C12: =SUMIF('400链接明细'!$D$4:$D$403,A12,'400链接明细'!$N$4:$N$403) -> 8111 | D12: =SUMIF('400链接明细'!$D$4:$D$403,A12,'400链接明细'!$Q$4:$Q$403) -> 1940810 | E12: =IFERROR(AVERAGEIF('400链接明细'!$D$4:$D$403,A12,'400链接明细'!$J$4:$J$403),0) -> 240.32585 | F12: =IFERROR(C12/$C$16,0) -> 0.14924192 | G12: 感应/续航可差异化
A13: 充电/感应壁灯 | B13: =COUNTIF('400链接明细'!$D$4:$D$403,A13) -> 39 | C13: =SUMIF('400链接明细'!$D$4:$D$403,A13,'400链接明细'!$N$4:$N$403) -> 5107 | D13: =SUMIF('400链接明细'!$D$4:$D$403,A13,'400链接明细'!$Q$4:$Q$403) -> 1196764.4 | E13: =IFERROR(AVERAGEIF('400链接明细'!$D$4:$D$403,A13,'400链接明细'!$J$4:$J$403),0) -> 265.99949 | F13: =IFERROR(C13/$C$16,0) -> 0.093968499 | G13: 先验证电池与退货
A14: 复古/灯笼壁灯 | B14: =COUNTIF('400链接明细'!$D$4:$D$403,A14) -> 24 | C14: =SUMIF('400链接明细'!$D$4:$D$403,A14,'400链接明细'!$N$4:$N$403) -> 4780 | D14: =SUMIF('400链接明细'!$D$4:$D$403,A14,'400链接明细'!$Q$4:$Q$403) -> 1594593.6 | E14: =IFERROR(AVERAGEIF('400链接明细'!$D$4:$D$403,A14,'400链接明细'!$J$4:$J$403),0) -> 351.52917 | F14: =IFERROR(C14/$C$16,0) -> 0.087951719 | G14: 套装与外观有价差
A15: 室内装饰壁灯 | B15: =COUNTIF('400链接明细'!$D$4:$D$403,A15) -> 26 | C15: =SUMIF('400链接明细'!$D$4:$D$403,A15,'400链接明细'!$N$4:$N$403) -> 3311 | D15: =SUMIF('400链接明细'!$D$4:$D$403,A15,'400链接明细'!$Q$4:$Q$403) -> 771633.19 | E15: =IFERROR(AVERAGEIF('400链接明细'!$D$4:$D$403,A15,'400链接明细'!$J$4:$J$403),0) -> 237.44962 | F15: =IFERROR(C15/$C$16,0) -> 0.060922205 | G15: 低规模，造型定向验证
A16: 核心壁灯合计 | B16: =SUM(B11:B15) -> 319 | C16: =SUM(C11:C15) -> 54348 | D16: =SUM(D11:D15) -> 11940507 | F16: =SUM(F11:F15) -> 1
A17: 邻近：橱柜/衣柜灯 | B17: =COUNTIF('400链接明细'!$D$4:$D$403,A17) -> 47 | C17: =SUMIF('400链接明细'!$D$4:$D$403,A17,'400链接明细'!$N$4:$N$403) -> 9588 | D17: =SUMIF('400链接明细'!$D$4:$D$403,A17,'400链接明细'!$Q$4:$Q$403) -> 1936310 | E17: =IFERROR(AVERAGEIF('400链接明细'!$D$4:$D$403,A17,'400链接明细'!$J$4:$J$403),0) -> 214.50681 | G17: 关键词污染：单独成类
A18: 邻近：路灯/投光灯 | B18: =COUNTIF('400链接明细'!$D$4:$D$403,A18) -> 7 | C18: =SUMIF('400链接明细'!$D$4:$D$403,A18,'400链接明细'!$N$4:$N$403) -> 2031 | D18: =SUMIF('400链接明细'!$D$4:$D$403,A18,'400链接明细'!$Q$4:$Q$403) -> 767323.67 | E18: =IFERROR(AVERAGEIF('400链接明细'!$D$4:$D$403,A18,'400链接明细'!$J$4:$J$403),0) -> 296.59286 | G18: 远离壁灯核心定义
A19: 邻近：镜前灯 | B19: =COUNTIF('400链接明细'!$D$4:$D$403,A19) -> 14 | C19: =SUMIF('400链接明细'!$D$4:$D$403,A19,'400链接明细'!$N$4:$N$403) -> 1365 | D19: =SUMIF('400链接明细'!$D$4:$D$403,A19,'400链接明细'!$Q$4:$Q$403) -> 426682.49 | E19: =IFERROR(AVERAGEIF('400链接明细'!$D$4:$D$403,A19,'400链接明细'!$J$4:$J$403),0) -> 294.565 | G19: 另作镜前灯赛道
A20: 邻近：楼梯/嵌入灯 | B20: =COUNTIF('400链接明细'!$D$4:$D$403,A20) -> 8 | C20: =SUMIF('400链接明细'!$D$4:$D$403,A20,'400链接明细'!$N$4:$N$403) -> 1123 | D20: =SUMIF('400链接明细'!$D$4:$D$403,A20,'400链接明细'!$Q$4:$Q$403) -> 342060.28 | E20: =IFERROR(AVERAGEIF('400链接明细'!$D$4:$D$403,A20,'400链接明细'!$J$4:$J$403),0) -> 307.185 | G20: 独立场景验证
A21: 邻近：顶灯/配件/地灯 | B21: =COUNTIF('400链接明细'!$D$4:$D$403,A21) -> 3 | C21: =SUMIF('400链接明细'!$D$4:$D$403,A21,'400链接明细'!$N$4:$N$403) -> 243 | D21: =SUMIF('400链接明细'!$D$4:$D$403,A21,'400链接明细'!$Q$4:$Q$403) -> 156691.36 | E21: =IFERROR(AVERAGEIF('400链接明细'!$D$4:$D$403,A21,'400链接明细'!$J$4:$J$403),0) -> 721.04 | G21: 非核心
A22: 待人工复核 | B22: =COUNTIF('400链接明细'!$D$4:$D$403,A22) -> 2 | C22: =SUMIF('400链接明细'!$D$4:$D$403,A22,'400链接明细'!$N$4:$N$403) -> 445 | D22: =SUMIF('400链接明细'!$D$4:$D$403,A22,'400链接明细'!$Q$4:$Q$403) -> 148614.74 | E22: =IFERROR(AVERAGEIF('400链接明细'!$D$4:$D$403,A22,'400链接明细'!$J$4:$J$403),0) -> 380.44 | G22: 链接用途需人工复核
A23: 相邻/待复核合计 | B23: =SUM(B17:B22) -> 81 | C23: =SUM(C17:C22) -> 14795 | D23: =SUM(D17:D22) -> 3777682.5
A24: 400链接校核 | B24: =B16+B23 -> 400 | C24: =C16+C23 -> 69143 | D24: =D16+D23 -> 15718189
A27: 核心壁灯价格带（链接标价；套装仍按单链接计销量）
A28: 标价 MXN | B28: 链接数 | C28: 30天销量 | D28: 30天销售额 MXN | E28: 销量占比
A29: <100 | B29: =COUNTIFS('400链接明细'!$J$4:$J$403,"<100",'400链接明细'!$AJ$4:$AJ$403,1) -> 21 | C29: =SUMIFS('400链接明细'!$N$4:$N$403,'400链接明细'!$J$4:$J$403,"<100",'400链接明细'!$AJ$4:$AJ$403,1) -> 3376 | D29: =SUMIFS('400链接明细'!$Q$4:$Q$403,'400链接明细'!$J$4:$J$403,"<100",'400链接明细'!$AJ$4:$AJ$403,1) -> 309852.26 | E29: =IFERROR(C29/$C$16,0) -> 0.062118201 | J29: 试验优先级 | K29: 切入与判断
A30: 100–149 | B30: =COUNTIFS('400链接明细'!$J$4:$J$403,">=100",'400链接明细'!$J$4:$J$403,"<150",'400链接明细'!$AJ$4:$AJ$403,1) -> 64 | C30: =SUMIFS('400链接明细'!$N$4:$N$403,'400链接明细'!$J$4:$J$403,">=100",'400链接明细'!$J$4:$J$403,"<150",'400链接明细'!$AJ$4:$AJ$403,1) -> 11604 | D30: =SUMIFS('400链接明细'!$Q$4:$Q$403,'400链接明细'!$J$4:$J$403,">=100",'400链接明细'!$J$4:$J$403,"<150",'400链接明细'!$AJ$4:$AJ$403,1) -> 1571267.2 | E30: =IFERROR(C30/$C$16,0) -> 0.21351292 | J30: 1 有线户外 | K30: 单支 150–199；双支套装 309–349：检验防水、色温、安装与净利。
A31: 150–199 | B31: =COUNTIFS('400链接明细'!$J$4:$J$403,">=150",'400链接明细'!$J$4:$J$403,"<200",'400链接明细'!$AJ$4:$AJ$403,1) -> 75 | C31: =SUMIFS('400链接明细'!$N$4:$N$403,'400链接明细'!$J$4:$J$403,">=150",'400链接明细'!$J$4:$J$403,"<200",'400链接明细'!$AJ$4:$AJ$403,1) -> 14111 | D31: =SUMIFS('400链接明细'!$Q$4:$Q$403,'400链接明细'!$J$4:$J$403,">=150",'400链接明细'!$J$4:$J$403,"<200",'400链接明细'!$AJ$4:$AJ$403,1) -> 2518535.9 | E31: =IFERROR(C31/$C$16,0) -> 0.25964157 | J31: 2 复古/灯笼 | K31: 单支/双支、黑色/铜色，明确是否含灯泡、底座安装方式。
A32: 200–299 | B32: =COUNTIFS('400链接明细'!$J$4:$J$403,">=200",'400链接明细'!$J$4:$J$403,"<300",'400链接明细'!$AJ$4:$AJ$403,1) -> 122 | C32: =SUMIFS('400链接明细'!$N$4:$N$403,'400链接明细'!$J$4:$J$403,">=200",'400链接明细'!$J$4:$J$403,"<300",'400链接明细'!$AJ$4:$AJ$403,1) -> 20025 | D32: =SUMIFS('400链接明细'!$Q$4:$Q$403,'400链接明细'!$J$4:$J$403,">=200",'400链接明细'!$J$4:$J$403,"<300",'400链接明细'!$AJ$4:$AJ$403,1) -> 5178411.5 | E32: =IFERROR(C32/$C$16,0) -> 0.36845882 | J32: 3 太阳能户外 | K32: 双支 229–299；实测续航、雨淋、感应距离，不夸大流明。
A33: 300–499 | B33: =COUNTIFS('400链接明细'!$J$4:$J$403,">=300",'400链接明细'!$J$4:$J$403,"<500",'400链接明细'!$AJ$4:$AJ$403,1) -> 28 | C33: =SUMIFS('400链接明细'!$N$4:$N$403,'400链接明细'!$J$4:$J$403,">=300",'400链接明细'!$J$4:$J$403,"<500",'400链接明细'!$AJ$4:$AJ$403,1) -> 4413 | D33: =SUMIFS('400链接明细'!$Q$4:$Q$403,'400链接明细'!$J$4:$J$403,">=300",'400链接明细'!$J$4:$J$403,"<500",'400链接明细'!$AJ$4:$AJ$403,1) -> 1618128.9 | E33: =IFERROR(C33/$C$16,0) -> 0.08119894 | J33: 4 充电感应 | K33: 先小样试点；验证电池寿命、磁吸跌落、传感误触与退货。
A34: ≥500 | B34: =COUNTIFS('400链接明细'!$J$4:$J$403,">=500",'400链接明细'!$AJ$4:$AJ$403,1) -> 9 | C34: =SUMIFS('400链接明细'!$N$4:$N$403,'400链接明细'!$J$4:$J$403,">=500",'400链接明细'!$AJ$4:$AJ$403,1) -> 819 | D34: =SUMIFS('400链接明细'!$Q$4:$Q$403,'400链接明细'!$J$4:$J$403,">=500",'400链接明细'!$AJ$4:$AJ$403,1) -> 744310.93 | E34: =IFERROR(C34/$C$16,0) -> 0.015069552 | J34: 决策门槛 | K34: 取得单SKU实际费率/运费/税/广告/退货成本后再计算边际利润。
A36: 店铺结构：核心壁灯样本
A37: 店铺类型 | B37: 链接数 | C37: 30天销量 | D37: 30天销售额 MXN | E37: 每链接30天销量
A38: 本土店 | B38: =COUNTIFS('400链接明细'!$I$4:$I$403,A38,'400链接明细'!$AJ$4:$AJ$403,1) -> 144 | C38: =SUMIFS('400链接明细'!$N$4:$N$403,'400链接明细'!$I$4:$I$403,A38,'400链接明细'!$AJ$4:$AJ$403,1) -> 27708 | D38: =SUMIFS('400链接明细'!$Q$4:$Q$403,'400链接明细'!$I$4:$I$403,A38,'400链接明细'!$AJ$4:$AJ$403,1) -> 5787498.7 | E38: =IFERROR(C38/B38,0) -> 192.41667
A39: 跨境店 | B39: =COUNTIFS('400链接明细'!$I$4:$I$403,A39,'400链接明细'!$AJ$4:$AJ$403,1) -> 175 | C39: =SUMIFS('400链接明细'!$N$4:$N$403,'400链接明细'!$I$4:$I$403,A39,'400链接明细'!$AJ$4:$AJ$403,1) -> 26640 | D39: =SUMIFS('400链接明细'!$Q$4:$Q$403,'400链接明细'!$I$4:$I$403,A39,'400链接明细'!$AJ$4:$AJ$403,1) -> 6153008 | E39: =IFERROR(C39/B39,0) -> 152.22857
A42: 核心壁灯品牌（按归一品牌汇总；“Genérica”是泛称）
A43: 品牌 | B43: 链接数 | C43: 30天销量 | D43: 30天销售额 MXN
A44: dehobo | B44: =COUNTIFS('400链接明细'!$G$4:$G$403,A44,'400链接明细'!$AJ$4:$AJ$403,1) -> 49 | C44: =SUMIFS('400链接明细'!$N$4:$N$403,'400链接明细'!$G$4:$G$403,A44,'400链接明细'!$AJ$4:$AJ$403,1) -> 6000 | D44: =SUMIFS('400链接明细'!$Q$4:$Q$403,'400链接明细'!$G$4:$G$403,A44,'400链接明细'!$AJ$4:$AJ$403,1) -> 912497.61
A45: vanance | B45: =COUNTIFS('400链接明细'!$G$4:$G$403,A45,'400链接明细'!$AJ$4:$AJ$403,1) -> 16 | C45: =SUMIFS('400链接明细'!$N$4:$N$403,'400链接明细'!$G$4:$G$403,A45,'400链接明细'!$AJ$4:$AJ$403,1) -> 4415 | D45: =SUMIFS('400链接明细'!$Q$4:$Q$403,'400链接明细'!$G$4:$G$403,A45,'400链接明细'!$AJ$4:$AJ$403,1) -> 684391.54
A46: judeng | B46: =COUNTIFS('400链接明细'!$G$4:$G$403,A46,'400链接明细'!$AJ$4:$AJ$403,1) -> 22 | C46: =SUMIFS('400链接明细'!$N$4:$N$403,'400链接明细'!$G$4:$G$403,A46,'400链接明细'!$AJ$4:$AJ$403,1) -> 3979 | D46: =SUMIFS('400链接明细'!$Q$4:$Q$403,'400链接明细'!$G$4:$G$403,A46,'400链接明细'!$AJ$4:$AJ$403,1) -> 806046.09
A47: generica | B47: =COUNTIFS('400链接明细'!$G$4:$G$403,A47,'400链接明细'!$AJ$4:$AJ$403,1) -> 21 | C47: =SUMIFS('400链接明细'!$N$4:$N$403,'400链接明细'!$G$4:$G$403,A47,'400链接明细'!$AJ$4:$AJ$403,1) -> 2942 | D47: =SUMIFS('400链接明细'!$Q$4:$Q$403,'400链接明细'!$G$4:$G$403,A47,'400链接明细'!$AJ$4:$AJ$403,1) -> 603740.78
A48: time4buy | B48: =COUNTIFS('400链接明细'!$G$4:$G$403,A48,'400链接明细'!$AJ$4:$AJ$403,1) -> 15 | C48: =SUMIFS('400链接明细'!$N$4:$N$403,'400链接明细'!$G$4:$G$403,A48,'400链接明细'!$AJ$4:$AJ$403,1) -> 2601 | D48: =SUMIFS('400链接明细'!$Q$4:$Q$403,'400链接明细'!$G$4:$G$403,A48,'400链接明细'!$AJ$4:$AJ$403,1) -> 693246.13
A49: hutiirich | B49: =COUNTIFS('400链接明细'!$G$4:$G$403,A49,'400链接明细'!$AJ$4:$AJ$403,1) -> 2 | C49: =SUMIFS('400链接明细'!$N$4:$N$403,'400链接明细'!$G$4:$G$403,A49,'400链接明细'!$AJ$4:$AJ$403,1) -> 2205 | D49: =SUMIFS('400链接明细'!$Q$4:$Q$403,'400链接明细'!$G$4:$G$403,A49,'400链接明细'!$AJ$4:$AJ$403,1) -> 295141.01
...

Sheet 重点竞品
A1: 重点竞品 | 来源于400条链接
A2: 按场景选择代表款，非全站热销排名。库存覆盖天数按静态库存÷近30天日均销量；标价和评论均为抓取时快照。
A3: 原排序 | B3: 商品ID | C3: 细分 | D3: 标价 MXN | E3: 套装件数* | F3: 估算每件标价 MXN* | G3: 30天销量 | H3: 30天销售额 MXN | I3: 库存覆盖天数* | J3: 品牌 | K3: 店铺类型 | L3: 评论数 | M3: 上架日期 | N3: 要观察什么 | O3: 商品链接
A4: 1 | B4: MLM3854627100 | C4: 有线户外/通用壁灯 | D4: 133.91 | E4: 1 | F4: 133.91 | G4: 1340 | H4: 183590.61 | I4: 7.1 | J4: HUTIIRICH | K4: 本土店 | L4: 931 | M4: 45860 | N4: 低价长销；核实20W实际功率、安装与售后 | O4: https://articulo.mercadolibre.com.mx/MLM-3854627100-hutiirich-lamparas-de-pared-exterior-y-interiores-color-negro-cuadrado-arbotante-20w-modernas-decorativas-3000k-luz-blanco-calido-impermeable-lamparas-para-jardin-sala-bano-rectangulo-negro-_JM
A5: 2 | B5: MLM5194406162 | C5: 有线户外/通用壁灯 | D5: 128.96 | E5: 1 | F5: 128.96 | G5: 1241 | H5: 160039.36 | I5: 26.4 | J5: Vanance | K5: 本土店 | L5: 1411 | M5: 46127 | N5: 低价长销；核实调光功能与实际电压 | O5: https://articulo.mercadolibre.com.mx/MLM-5194406162-vanance-lampara-pared-luces-luz-calida-interiores-exterior-muro-12w-lamparas-modernas-regulador-de-luz-lampara-arbotante-lampara-decorativas-color-negro-_JM
A6: 3 | B6: MLM4124322628 | C6: 复古/灯笼壁灯 | D6: 239 | E6: 2 | F6: 119.5 | G6: 1007 | H6: 240673 | I6: 32.1 | J6: Raganet | K6: 本土店 | L6: 35 | M6: 45924 | N6: 双支复古套装，高销量；查是否含灯泡 | O6: https://articulo.mercadolibre.com.mx/MLM-4124322628-kit-2-lamparas-decorativas-de-pared-intext-vintage-retro-negro-_JM
A7: 4 | B7: MLM5598303430 | C7: 充电/感应壁灯 | D7: 217.9 | E7: 6 | F7: 36.32 | G7: 987 | H7: 215067.3 | I7: 5.6 | J7: AGTCOBT | K7: 跨境店 | L7: 101 | M7: 46202 | N7: 六支充电感应灯；极低单件价与短库存 | O7: https://articulo.mercadolibre.com.mx/MLM-5598303430-6pcs-lampara-pared-recargable-sensor-movimiento-led-luces-_JM
A8: 5 | B8: MLM5542913308 | C8: 有线户外/通用壁灯 | D8: 184.19 | E8: 1 | F8: 184.19 | G8: 902 | H8: 166139.38 | I8: 18.2 | J8: EMOTINIA | K8: 本土店 | L8: 353 | M8: 46194 | N8: 多色温有线款；观察竞品同款分流 | O8: https://articulo.mercadolibre.com.mx/MLM-5542913308-lampara-pared-exterior-impermeable-arbotante-moderna-3-modos-negro-_JM
A9: 6 | B9: MLM3854640070 | C9: 有线户外/通用壁灯 | D9: 128.96 | E9: 1 | F9: 128.96 | G9: 865 | H9: 111550.4 | I9: 8.4 | J9: HUTIIRICH | K9: 本土店 | L9: 931 | M9: 45860 | N9: 同牌圆款；验证造型变体带来的销量 | O9: https://articulo.mercadolibre.com.mx/MLM-3854640070-hutiirich-lamparas-de-pared-exterior-y-interiores-color-negro-redondo-arbotante-20w-modernas-decorativas-3000k-luz-blanco-calido-impermeable-lamparas-para-jardin-sala-bano-redondo-negro-_JM
A10: 9 | B10: MLM2979688231 | C10: 有线户外/通用壁灯 | D10: 269.45 | E10: 1 | F10: 269.45 | G10: 817 | H10: 225529.65 | I10: 15.6 | J10: SONHEO | K10: 本土店 | L10: 617 | M10: 46176 | N10: 双灯头/三色温；留意与同质款的差别 | O10: https://articulo.mercadolibre.com.mx/MLM-2979688231-sonheo-lampara-de-pared-exterior-y-interior-moderna-decorativas-para-jardin-sala-con-2-focos-y-3-modos-de-luz-blancacalidaneutra-negro-_JM
A11: 10 | B11: MLM2326733309 | C11: 复古/灯笼壁灯 | D11: 314.1 | E11: 1 | F11: 314.1 | G11: 782 | H11: 253478.7 | I11: 84.7 | J11: Geopower | K11: 本土店 | L11: 992 | M11: 45806 | N11: 单支复古灯；与双支套装比价格 | O11: https://articulo.mercadolibre.com.mx/MLM-2326733309-lampara-de-pared-exterior-farol-decorativo-negro-espanol-100-w-geopower-_JM
A12: 11 | B12: MLM4243156976 | C12: 太阳能户外壁灯 | D12: 292.57 | E12: 1 | F12: 292.57 | G12: 743 | H12: 217379.51 | I12: 1.7 | J12: Vedd | K12: 跨境店 | L12: 780 | M12: 45951 | N12: 太阳能高客单；库存很薄，核实续航 | O12: https://articulo.mercadolibre.com.mx/MLM-4243156976-vedd-lampara-solar-de-paruz-192-led-estructura-negro-_JM
A13: 12 | B13: MLM2280811385 | C13: 有线户外/通用壁灯 | D13: 154.85 | E13: 1 | F13: 154.85 | G13: 705 | H13: 113505.05 | I13: 2.2 | J13: HSLING | K13: 本土店 | L13: 60 | M13: 45759 | N13: 3000K壁灯；7天速度比30天更快 | O13: https://articulo.mercadolibre.com.mx/MLM-2280811385-aplique-led-de-pared-ip65-negro-3000k-lampara-interior-y-exterior-_JM
A14: 13 | B14: MLM2517942983 | C14: 复古/灯笼壁灯 | D14: 273.47 | E14: 1 | F14: 273.47 | G14: 679 | H14: 185686.13 | I14: 6.5 | J14: Gosun | K14: 跨境店 | L14: 741 | M14: 45951 | N14: 灯笼造型；验证不含灯泡说明 | O14: https://articulo.mercadolibre.com.mx/MLM-2517942983-farol-hexagonal-pared-negro-e27-exterior-impermeable-aluminio-_JM
A15: 16 | B15: MLM4780094146 | C15: 太阳能户外壁灯 | D15: 190 | E15: 1 | F15: 190 | G15: 642 | H15: 127680 | I15: 26.7 | J15: Ambueco | K15: 本土店 | L15: 204 | M15: 46065 | N15: 太阳能三色温；本土供给 | O15: https://articulo.mercadolibre.com.mx/MLM-4780094146-lampara-pared-led-solar-exterior-moderna-impermeable-3-modosluz-blanca-calida-neutralmodernas-decorativa-para-jardin-arbotante-exterior-ambueco-negro-_JM
... A27: 96 | B27: MLM3140818875 | C27: 室内装饰壁灯 | D27: 192.75 | E27: 1 | F27: 192.75 | G27: 192 | H27: 37008 | I27: 10.3 | J27: Pcmos | K27: 跨境店 | L27: 15 | M27: 46219 | N27: 室内装饰；低评论高销量样本 | O27: https://articulo.mercadolibre.com.mx/MLM-3140818875-aplique-de-pared-led-moderno-para-interior-_JM

Sheet 400链接明细
A1: 墨西哥美客多壁灯 | 400条链接逐条明细
A2: 来源：用户上传「400_商品列表 (39).xlsx」；采集时间未写在源表；30天销售额、转化率、库存均为第三方工具口径。细分/套装件数按标题推断，请逐条复核。
A3: 原排序 | B3: 商品ID | C3: 商品名称 | D3: 细分（标题判断） | E3: 标价带 MXN | F3: 品牌（原表） | G3: 品牌（归一） | H3: 卖家 | I3: 店铺类型 | J3: 标价 MXN | K3: 套装件数* | L3: 估算每件标价 MXN* | M3: 7天销量 | N3: 30天销量 | O3: 90天销量 | P3: 累计销量 | Q3: 近30天销售额 MXN* | R3: 7天折算/30天 | S3: 库存数（快照） | T3: 库存覆盖天数* | U3: 库存类型 | V3: 评论数 | W3: 评分 | X3: 转化率* | Y3: 上架日期 | Z3: 上架龄 | AA3: BSR | AB3: 销量环比 | AC3: 长度 | AD3: 宽度 | AE3: 高度 | AF3: 重量 | AG3: 商品状态 | AH3: 商品链接 | AI3: 原类目 | AJ3: 核心壁灯标识
A4: 1 | B4: MLM3854627100 | C4: Hutiirich® Lámparas De Pared Exterior Y Interiores Color Negro Cuadrado Arbotante 20w Modernas Decorativas 3000k Luz Blanco Cálido Impermeable Lámparas Para Jardín Sala Baño Rectángulo Negro | D4: 有线户外/通用壁灯 | E4: 100–149 | F4: HUTIIRICH | G4: hutiirich | H4: GREEN08EVEREVEN | I4: 本土店 | J4: 133.91 | K4: 1 | L4: 133.91 | M4: 393 | N4: 1340 | O4: 3558 | P4: 12756 | Q4: 183590.61 | R4: =IFERROR(M4*30/(N4*7),0) -> 1.2569296 | S4: 316 | T4: =IFERROR(S4*30/N4,0) -> 7.0746269 | U4: FULL | V4: 931 | W4: 4.6 | X4: 0.1177 | Y4: 45860 | Z4: 更早 | AA4: 5 | AB4: 0.16928447 | AC4: 21.6 cm | AD4: 10.8 cm | AE4: 9.4 cm | AF4: 1.26 kg | AG4: 在售 | AH4: https://articulo.mercadolibre.com.mx/MLM-3854627100-hutiirich-lamparas-de-pared-exterior-y-interiores-color-negro-cuadrado-arbotante-20w-modernas-decorativas-3000k-luz-blanco-calido-impermeable-lamparas-para-jardin-sala-bano-rectangulo-negro-_JM | AI4: Hogar, Muebles y Jardín(家居、家具和花园) -> Iluminación para el Hogar(家居照明) -> Lámparas(灯具) -> Lámparas de Pared(壁灯) | AJ4: 1
A5: 2 | B5: MLM5194406162 | C5: Vanance® Lámpara Pared Luces Luz Cálida Interiores Exterior Muro 12w Lamparas Modernas Regulador De Luz Lampara Arbotante Lampara Decorativas Color Negro | D5: 有线户外/通用壁灯 | E5: 100–149 | F5: Vanance | G5: vanance | H5: VANANCE | I5: 本土店 | J5: 128.96 | K5: 1 | L5: 128.96 | M5: 321 | N5: 1241 | O5: 3834 | P5: 6295 | Q5: 160039.36 | R5: =IFERROR(M5*30/(N5*7),0) -> 1.108553 | S5: 1092 | T5: =IFERROR(S5*30/N5,0) -> 26.398066 | U5: FULL | V5: 1411 | W5: 4.5 | X5: 0.1363 | Y5: 46127 | Z5: 91–180天 | AA5: 14 | AB5: 0.053480475 | AC5: 21.4 cm | AD5: 10.8 cm | AE5: 9.4 cm | AF5: 0.3 kg | AG5: 在售 | AH5: https://articulo.mercadolibre.com.mx/MLM-5194406162-vanance-lampara-pared-luces-luz-calida-interiores-exterior-muro-12w-lamparas-modernas-regulador-de-luz-lampara-arbotante-lampara-decorativas-color-negro-_JM | AI5: Hogar, Muebles y Jardín(家居、家具和花园) -> Iluminación para el Hogar(家居照明) -> Lámparas(灯具) -> Lámparas de Pared(壁灯) | AJ5: 1
A6: 3 | B6: MLM4124322628 | C6: Kit 2 Lámparas Decorativas De Pared Int/ext. Vintage Retro Negro | D6: 复古/灯笼壁灯 | E6: 200–299 | F6: Raganet | G6: raganet | H6: JANSEK | I6: 本土店 | J6: 239 | K6: 2 | L6: 119.5 | M6: 244 | N6: 1007 | O6: 2226 | P6: 6970 | Q6: 240673 | R6: =IFERROR(M6*30/(N6*7),0) -> 1.0384452 | S6: 1079 | T6: =IFERROR(S6*30/N6,0) -> 32.144985 | U6: FULL | V6: 35 | W6: 5 | X6: 0.0625 | Y6: 45924 | Z6: 更早 | AB6: 0.077005348 | AC6: 48.8 cm | AD6: 24.8 cm | AE6: 11.6 cm | AF6: 1.18 kg | AG6: 在售 | AH6: https://articulo.mercadolibre.com.mx/MLM-4124322628-kit-2-lamparas-decorativas-de-pared-intext-vintage-retro-negro-_JM | AI6: Hogar, Muebles y Jardín(家居、家具和花园) -> Iluminación para el Hogar(家居照明) -> Lámparas(灯具) -> Lámparas de Pared(壁灯) | AJ6: 1
A7: 4 | B7: MLM5598303430 | C7: 6pcs Lampara Pared Recargable Sensor Movimiento Led Luces | D7: 充电/感应壁灯 | E7: 200–299 | F7: AGTCOBT | G7: agtcobt | H7: NIUDEYIBI | I7: 跨境店 | J7: 217.9 | K7: 6 | L7: 36.32 | M7: 142 | N7: 987 | O7: 1656 | P7: 1656 | Q7: 215067.3 | R7: =IFERROR(M7*30/(N7*7),0) -> 0.61658706 | S7: 184 | T7: =IFERROR(S7*30/N7,0) -> 5.5927052 | U7: FULL | V7: 101 | W7: 4.7 | X7: 0.0769 | Y7: 46202 | Z7: 近90天上架 | AA7: 2 | AB7: 0.41 | AC7: 38.3 cm | AD7: 16.2 cm | AE7: 3.1 cm | AF7: 0.9 kg | AG7: 在售 | AH7: https://articulo.mercadolibre.com.mx/MLM-5598303430-6pcs-lampara-pared-recargable-sensor-movimiento-led-luces-_JM | AI7: Hogar, Muebles y Jardín(家居、家具和花园) -> Iluminación para el Hogar(家居照明) -> Lámparas(灯具) -> Lámparas de Pared(壁灯) | AJ7: 1
A8: 5 | B8: MLM5542913308 | C8: Lámpara Pared Exterior Impermeable Arbotante Moderna 3 Modos Negro | D8: 有线户外/通用壁灯 | E8: 150–199 | F8: EMOTINIA | G8: emotinia | H8: FALOVIGNADOSHOP | I8: 本土店 | J8: 184.19 | K8: 1 | L8: 184.19 | M8: 134 | N8: 902 | O8: 1377 | P8: 1377 | Q8: 166139.38 | R8: =IFERROR(M8*30/(N8*7),0) -> 0.63668039 | S8: 547 | T8: =IFERROR(S8*30/N8,0) -> 18.192905 | U8: FULL | V8: 353 | W8: 4.8 | X8: 0.0959 | Y8: 46194 | Z8: 91–180天 | AA8: 15 | AB8: 1.4444444 | AC8: 36.6 cm | AD8: 21.8 cm | AE8: 9.6 cm | AF8: 0.44 kg | AG8: 在售 | AH8: https://articulo.mercadolibre.com.mx/MLM-5542913308-lampara-pared-exterior-impermeable-arbotante-moderna-3-modos-negro-_JM | AI8: Hogar, Muebles y Jardín(家居、家具和花园) -> Iluminación para el Hogar(家居照明) -> Lámparas(灯具) -> Lámparas de Pared(壁灯) | AJ8: 1
A9: 6 | B9: MLM3854640070 | C9: Hutiirich® Lámparas De Pared Exterior Y Interiores Color Negro Redondo Arbotante 20w Modernas Decorativas 3000k Luz Blanco Cálido Impermeable Lámparas Para Jardín Sala Baño Redondo Negro | D9: 有线户外/通用壁灯 | E9: 100–149 | F9: HUTIIRICH | G9: hutiirich | H9: GREEN08EVEREVEN | I9: 本土店 | J9: 128.96 | K9: 1 | L9: 128.96 | M9: 238 | N9: 865 | O9: 2940 | P9: 9975 | Q9: 111550.4 | R9: =IFERROR(M9*30/(N9*7),0) -> 1.1791908 | S9: 243 | T9: =IFERROR(S9*30/N9,0) -> 8.4277457 | U9: FULL | V9: 931 | W9: 4.6 | X9: 0.1059 | Y9: 45860 | Z9: 更早 | AA9: 4 | AB9: -0.22698838 | AC9: 22 cm | AD9: 11.4 cm | AE9: 9.6 cm | AF9: 0.26 kg | AG9: 在售 | AH9: https://articulo.mercadolibre.com.mx/MLM-3854640070-hutiirich-lamparas-de-pared-exterior-y-interiores-color-negro-redondo-arbotante-20w-modernas-decorativas-3000k-luz-blanco-calido-impermeable-lamparas-para-jardin-sala-bano-redondo-negro-_JM | AI9: Hogar, Muebles y Jardín(家居、家具和花园) -> Iluminación para el Hogar(家居照明) -> Lámparas(灯具) -> Lámparas de Pared(壁灯) | AJ9: 1
A10: 7 | B10: MLM2740945503 | C10: Bakeway Reflector Lámpara Led Solar Exterior Luminaria Suburbanas 2500w Led Solar Light Lámparas De Pared | D10: 邻近：路灯/投光灯 | E10: 200–299 | F10: BAKEWAY | G10: bakeway | H10: O C | I10: 本土店 | J10: 298 | K10: 1 | L10: 298 | M10: 223 | N10: 860 | O10: 1388 | P10: 2665 | Q10: 256280 | R10: =IFERROR(M10*30/(N10*7),0) -> 1.1112957 | S10: 110 | T10: =IFERROR(S10*30/N10,0) -> 3.8372093 | U10: FULL | V10: 340 | W10: 4.7 | X10: 0.0766 | Y10: 46065 | Z10: 更早 | AA10: 6 | AB10: 2.1386861 | AC10: 38.4 cm | AD10: 20.2 cm | AE10: 25.8 cm | AF10: 0.72 kg | AG10: 在售 | AH10: https://articulo.mercadolibre.com.mx/MLM-2740945503-lampara-solar-led-exterior-suburbana-alumbrado-publiclamparas-de-pared-focos-solares-led-exteriore-impermeable-_JM | AI10: Hogar, Muebles y Jardín(家居、家具和花园) -> Iluminación para el Hogar(家居照明) -> Lámparas(灯具) -> Lámparas de Pared(壁灯) | AJ10: 0
A11: 8 | B11: MLM4348721588 | C11: 6pzs Luz De Led Clóset Lámpara Armario Noche Recargable Usb Led Closet Light 6 Packs | D11: 邻近：橱柜/衣柜灯 | E11: 150–199 | F11: Zhimatiandi | G11: zhimatiandi | H11: ZHIMATIANDI | I11: 本土店 | J11: 199.99 | K11: 6 | L11: 33.33 | M11: 73 | N11: 841 | O11: 2653 | P11: 4340 | Q11: 168191.59 | R11: =IFERROR(M11*30/(N11*7),0) -> 0.37200612 | S11: 231 | T11: =IFERROR(S11*30/N11,0) -> 8.2401902 | U11: FULL | V11: 0 | W11: 0 | X11: 0.0599 | Y11: 45970 | Z11: 更早 | AB11: -0.18900675 | AC11: 15.8 cm | AD11: 8.8 cm | AE11: 9 cm | AF11: 0.9 kg | AG11: 在售 | AH11: https://articulo.mercadolibre.com.mx/MLM-4348721588-6pzs-luz-de-led-closet-lampara-armario-noche-recargable-usb-led-closet-light-6-packs-_JM | AI11: Hogar, Muebles y Jardín(家居、家具和花园) -> Iluminación para el Hogar(家居照明) -> Lámparas(灯具) -> Lámparas de Pared(壁灯) | AJ11: 0
A12: 9 | B12: MLM2979688231 | C12: Sonheo® Lampara De Pared Exterior Y Interior Moderna Decorativas Para Jardin Sala Con 2 Focos Y 3 Modos De Luz Blanca,cálida,neutra | D12: 有线户外/通用壁灯 | E12: 200–299 | F12: SONHEO | G12: sonheo | H12: FANOKI | I12: 本土店 | J12: 269.45 | K12: 1 | L12: 269.45 | M12: 244 | N12: 817 | O12: 1542 | P12: 1654 | Q12: 225529.65 | R12: =IFERROR(M12*30/(N12*7),0) -> 1.279944 | S12: 426 | T12: =IFERROR(S12*30/N12,0) -> 15.642595 | U12: FULL | V12: 617 | W12: 4.6 | X12: 0.0858 | Y12: 46176 | Z12: 91–180天 | AA12: 20 | AB12: 0.36166667 | AC12: 30 cm | AD12: 16.2 cm | AE12: 9.6 cm | AF12: 1.08 kg | AG12: 在售 | AH12: https://articulo.mercadolibre.com.mx/MLM-2979688231-sonheo-lampara-de-pared-exterior-y-interior-moderna-decorativas-para-jardin-sala-con-2-focos-y-3-modos-de-luz-blancacalidaneutra-negro-_JM | AI12: Hogar, Muebles y Jardín(家居、家具和花园) -> Iluminación para el Hogar(家居照明) -> Lámparas(灯具) -> Lámparas de Pared(壁灯) | AJ12: 1
A13: 10 | B13: MLM2326733309 | C13: Lámpara De Pared Exterior Farol Decorativo Negro Español 100 W Geopower | D13: 复古/灯笼壁灯 | E13: 300–499 | F13: Geopower | G13: geopower | H13: GEOPOWER | I13: 本土店 | J13: 314.1 | K13: 1 | L13: 314.1 | M13: 136 | N13: 782 | O13: 2089 | P13: 13686 | Q13: 253478.7 | R13: =IFERROR(M13*30/(N13*7),0) -> 0.74534161 | S13: 2208 | T13: =IFERROR(S13*30/N13,0) -> 84.705882 | U13: FULL | V13: 992 | W13: 4.8 | X13: 0.0933 | Y13: 45806 | Z13: 更早 | AA13: 19 | AB13: -0.32118056 | AC13: 20.6 cm | AD13: 16.5 cm | AE13: 14.3 cm | AF13: 1.09 kg | AG13: 在售 | AH13: https://articulo.mercadolibre.com.mx/MLM-2326733309-lampara-de-pared-exterior-farol-decorativo-negro-espanol-100-w-geopower-_JM | AI13: Hogar, Muebles y Jardín(家居、家具和花园) -> Iluminación para el Hogar(家居照明) -> Lámparas(灯具) -> Lámparas de Pared(壁灯) | AJ13: 1
A14: 11 | B14: MLM4243156976 | C14: Vedd® Lámpara Solar De Pared Exteriores Sensor Luz 192 Led Estructura Negro | D14: 太阳能户外壁灯 | E14: 200–299 | F14: Vedd | G14: vedd | H14: VEDD | I14: 跨境店 | J14: 292.57 | K14: 1 | L14: 292.57 | M14: 118 | N14: 743 | O14: 2186 | P14: 12767 | Q14: 217379.51 | R14: =IFERROR(M14*30/(N14*7),0) -> 0.68063834 | S14: 41 | T14: =IFERROR(S14*30/N14,0) -> 1.6554509 | U14: FULL | V14: 780 | W14: 4.6 | X14: 0.108 | Y14: 45951 | Z14: 更早 | AA14: 4 | AB14: -0.022368421 | AC14: 21 cm | AD14: 14 cm | AE14: 14.6 cm | AF14: 0.65 kg | AG14: 在售 | AH14: https://articulo.mercadolibre.com.mx/MLM-4243156976-vedd-lampara-solar-de-paruz-192-led-estructura-negro-_JM | AI14: Hogar, Muebles y Jardín(家居、家具和花园) -> Iluminación para el Hogar(家居照明) -> Lámparas(灯具) -> Lámparas de Pared(壁灯) | AJ14: 1
A15: 12 | B15: MLM2280811385 | C15: Lámpara De Pared Led De Foco Flotante Moderno 3000k Estructura Negro | D15: 有线户外/通用壁灯 | E15: 150–199 | F15: HSLING | G15: hsling | H15: QISHUIQISHUI | I15: 本土店 | J15: 154.85 | K15: 1 | L15: 154.85 | M15: 263 | N15: 705 | O15: 1526 | P15: 2762 | Q15: 113505.05 | R15: =IFERROR(M15*30/(N15*7),0) -> 1.5987842 | S15: 52 | T15: =IFERROR(S15*30/N15,0) -> 2.212766 | U15: FULL | V15: 60 | W15: 4.8 | X15: 0.1185 | Y15: 45759 | Z15: 更早 | AB15: 0.5326087 | AC15: 11 cm | AD15: 11.2 cm | AE15: 11.6 cm | AF15: 0.26 kg | AG15: 在售 | AH15: https://articulo.mercadolibre.com.mx/MLM-2280811385-aplique-led-de-pared-ip65-negro-3000k-lampara-interior-y-exterior-_JM | AI15: Hogar, Muebles y Jardín(家居、家具和花园) -> Iluminación para el Hogar(家居照明) -> Lámparas(灯具) -> Lámparas de Pared(壁灯) | AJ15: 1
A16: 13 | B16: MLM2517942983 | C16: Gosun® Hexágono Faroles Lámparas De Pared Casa Decoración No Focos Wei World Zt-302 Color De Negro | D16: 复古/灯笼壁灯 | E16: 200–299 | F16: Gosun | G16: gosun | H16: CNWEIWORLD-MXF | I16: 跨境店 | J16: 273.47 | K16: 1 | L16: 273.47 | M16: 184 | N16: 679 | O16: 2480 | P16: 18851 | Q16: 185686.13 | R16: =IFERROR(M16*30/(N16*7),0) -> 1.1613718 | S16: 147 | T16: =IFERROR(S16*30/N16,0) -> 6.4948454 | U16: FULL | V16: 741 | W16: 4.8 | X16: 0.3063 | Y16: 45951 | Z16: 更早 | AA16: 10 | AB16: -0.34332689 | AC16: 15.2 cm | AD16: 16.8 cm | AE16: 20.8 cm | AF16: 0.72 kg | AG16: 在售 | AH16: https://articulo.mercadolibre.com.mx/MLM-2517942983-farol-hexagonal-pared-negro-e27-exterior-impermeable-aluminio-_JM | AI16: Hogar, Muebles y Jardín(家居、家具和花园) -> Iluminación para el Hogar(家居照明) -> Lámparas(灯具) -> Lámparas de Pared(壁灯) | AJ16: 1
A17: 14 | B17: MLM3699273080 | C17: Lámpara Pared Exterior Impermeable Arbotante Moderna 3 Modos | D17: 有线户外/通用壁灯 | E17: 150–199 | F17: arbotante exterior,arbotante de pared,lampara arbotante exterior | G17: arbotante exterior,arbotante de pared,lampara arbotante exterior | H17: FALOVIGNADOSHOP | I17: 本土店 | J17: 184.19 | K17: 1 | L17: 184.19 | M17: 266 | N17: 674 | O17: 1661 | P17: 6370 | Q17: 124144.06 | R17: =IFERROR(M17*30/(N17*7),0) -> 1.6913947 | S17: 191 | T17: =IFERROR(S17*30/N17,0) -> 8.5014837 | U17: FULL | V17: 319 | W17: 4.8 | X17: 0.1102 | Y17: 45796 | Z17: 更早 | AB17: 0.085346216 | AC17: 21.4 cm | AD17: 11.2 cm | AE17: 8.6 cm | AF17: 0.26 kg | AG17: 在售 | AH17: https://articulo.mercadolibre.com.mx/MLM-3699273080-lampara-pared-exterior-impermeable-arbotante-moderna-3-modos-negro-_JM | AI17: Hogar, Muebles y Jardín(家居、家具和花园) -> Iluminación para el Hogar(家居照明) -> Lámparas(灯具) -> Lámparas de Pared(壁灯) | AJ17: 1
A18: 15 | B18: MLM3323814200 | C18: Sensor De Movimiento Led Inalámbrico My Bajo Luces Color Silver 40cm | D18: 充电/感应壁灯 | E18: <100 | F18: Genérica | G18: generica | H18: CNTORISE-MXF | I18: 跨境店 | J18: 84.33 | K18: 1 | L18: 84.33 | M18: 174 | N18: 644 | O18: 1703 | P18: 16817 | Q18: 55910.79 | R18: =IFERROR(M18*30/(N18*7),0) -> 1.1579414 | S18: 789 | T18: =IFERROR(S18*30/N18,0) -> 36.754658 | U18: FULL | V18: 1573 | W18: 4.5 | X18: 0.0736 | Y18: 45525 | Z18: 更早 | AA18: 16 | AB18: 0.24084778 | AC18: 41.2 cm | AD18: 4.6 cm | AE18: 2.2 cm | AF18: 0.16 kg | AG18: 在售 | AH18: https://articulo.mercadolibre.com.mx/MLM-3323814200-sensor-de-movimiento-led-inalambrico-my-bajo-luces-color-silver-40cm-_JM | AI18: Hogar, Muebles y Jardín(家居、家具和花园) -> Iluminación para el Hogar(家居照明) -> Lámparas(灯具) -> Lámparas de Pared(壁灯) | AJ18: 1
A19: 16 | B19: MLM4780094146 | C19: Lampara Pared Led Solar Exterior Moderna Impermeable 3 Modos,luz Blanca / Cálida / Neutral,modernas Decorativa Para Jardín Arbotante Exterior Ambueco® Negro | D19: 太阳能户外壁灯 | E19: 150–199 | F19: Ambueco | G19: ambueco | H19: ZENITHIA | I19: 本土店 | J19: 190 | K19: 1 | L19: 190 | M19: 143 | N19: 642 | O19: 2112 | P19: 3955 | Q19: 127680 | R19: =IFERROR(M19*30/(N19*7),0) -> 0.95460614 | S19: 572 | T19: =IFERROR(S19*30/N19,0) -> 26.728972 | U19: FULL | V19: 204 | W19: 4.5 | X19: 0.0522 | Y19: 46065 | Z19: 更早 | AA19: 8 | AB19: -0.064139942 | AC19: 18.8 cm | AD19: 8.4 cm | AE19: 6.6 cm | AF19: 0.35 kg | AG19: 在售 | AH19: https://articulo.mercadolibre.com.mx/MLM-4780094146-lampara-pared-led-solar-exterior-moderna-impermeable-3-modosluz-blanca-calida-neutralmodernas-decorativa-para-jardin-arbotante-exterior-ambueco-negro-_JM | AI19: Hogar, Muebles y Jardín(家居、家具和花园) -> Iluminación para el Hogar(家居照明) -> Lámparas(灯具) -> Lámparas de Pared(壁灯) | AJ19: 1
A20: 17 | B20: MLM2980774929 | C20: Lamparas Solares Exterior Lamparas Solares Lampara Led 2pcs | D20: 太阳能户外壁灯 | E20: 200–299 | F20: YETONE | G20: yetone | H20: CNYUEHT-MXF | I20: 跨境店 | J20: 237.5 | K20: 2 | L20: 118.75 | M20: 114 | N20: 589 | O20: 589 | P20: 589 | Q20: 139887.5 | R20: =IFERROR(M20*30/(N20*7),0) -> 0.82949309 | S20: 125 | T20: =IFERROR(S20*30/N20,0) -> 6.3667233 | U20: FULL | V20: 5 | W20: 4.6 | X20: 0.0549 | Y20: 46177 | Z20: 91–180天 | AB20: 64.444444 | AC20: 14 cm | AD20: 11.8 cm | AE20: 10 cm | AF20: 0.36 kg | AG20: 在售 | AH20: https://articulo.mercadolibre.com.mx/MLM-2980774929-lamparas-solares-exterior-lamparas-solares-lampara-led-2pcs-_JM | AI20: Hogar, Muebles y Jardín(家居、家具和花园) -> Iluminación para el Hogar(家居照明) -> Lámparas(灯具) -> Lámparas de Pared(壁灯) | AJ20: 1
A21: 18 | B21: MLM4478861044 | C21: Lámpara Solar Exterior De Pared De 120 Cob Con Sensor | D21: 太阳能户外壁灯 | E21: 100–149 | F21: Cyotman | G21: cyotman | H21: O C | I21: 本土店 | J21: 115 | K21: 1 | L21: 115 | M21: 264 | N21: 588 | O21: 1495 | P21: 3751 | Q21: 69460 | R21: =IFERROR(M21*30/(N21*7),0) -> 1.9241983 | S21: 238 | T21: =IFERROR(S21*30/N21,0) -> 12.142857 | U21: FULL | V21: 1668 | W21: 4.3 | X21: 0.0656 | Y21: 45998 | Z21: 更早 | AA21: 10 | AB21: 0.32432432 | AC21: 23.1 cm | AD21: 9.2 cm | AE21: 4.4 cm | AF21: 0.21 kg | AG21: 在售 | AH21: https://articulo.mercadolibre.com.mx/MLM-4478861044-lampara-solar-exterior-de-pared-de-120-cob-con-sensor-_JM | AI21: Hogar, Muebles y Jardín(家居、家具和花园) -> Iluminación para el Hogar(家居照明) -> Lámparas(灯具) -> Lámparas de Pared(壁灯) | AJ21: 1
A22: 19 | B22: MLM4289959428 | C22: 6800w Lámpara Led Solar Exterior Suburbana Alumbrado Públic | D22: 邻近：路灯/投光灯 | E22: ≥500 | F22: General | G22: general | H22: OUTLETMEX | I22: 本土店 | J22: 597.13 | K22: 1 | L22: 597.13 | M22: 139 | N22: 586 | O22: 2623 | P22: 6696 | Q22: 356486.61 | R22: =IFERROR(M22*30/(N22*7),0) -> 1.0165773 | S22: 413 | T22: =IFERROR(S22*30/N22,0) -> 21.143345 | U22: FULL | V22: 0 | W22: 0 | X22: 0.0877 | Y22: 45959 | Z22: 更早 | AB22: -0.45690454 | AC22: 46.8 cm | AD22: 27.8 cm | AE22: 5.6 cm | AF22: 1.62 kg | AG22: 在售 | AH22: https://articulo.mercadolibre.com.mx/MLM-4289959428-7800w-lampara-led-solar-exterior-suburbana-alumbrado-public-_JM | AI22: Hogar, Muebles y Jardín(家居、家具和花园) -> Iluminación para el Hogar(家居照明) -> Lámparas(灯具) -> Lámparas de Pared(壁灯) | AJ22: 0
A23: 20 | B23: MLM4121803576 | C23: 6 Pzs Luz Led Clóset Lámpara Armario Noche Recargable Usb | D23: 邻近：橱柜/衣柜灯 | E23: 150–199 | F23: Genérica | G23: generica | H23: RSHX | I23: 本土店 | J23: 177.73 | K23: 6 | L23: 29.62 | M23: 285 | N23: 525 | O23: 2252 | P23: 4841 | Q23: 93308.25 | R23: =IFERROR(M23*30/(N23*7),0) -> 2.3265306 | S23: 325 | T23: =IFERROR(S23*30/N23,0) -> 18.571429 | U23: FULL | V23: 58 | W23: 4.6 | X23: 0.0751 | Y23: 45924 | Z23: 更早 | AA23: 17 | AB23: -0.45932029 | AC23: 16 cm | AD23: 8.8 cm | AE23: 8.6 cm | AF23: 0.27 kg | AG23: 在售 | AH23: https://articulo.mercadolibre.com.mx/MLM-4121803576-6-pzs-luz-led-closet-lampara-armario-noche-recargable-usb-blanco-_JM | AI23: Hogar, Muebles y Jardín(家居、家具和花园) -> Iluminación para el Hogar(家居照明) -> Lámparas(灯具) -> Lámparas de Pared(壁灯) | AJ23: 0
A24: 21 | B24: MLM2551024807 | C24: 2pcs 50cm Luz De Led Clóset Usb Con Sensor Movimiento | D24: 邻近：橱柜/衣柜灯 | E24: 100–149 | F24: Tongze | G24: tongze | H24: TONGZE | I24: 跨境店 | J24: 148.01 | K24: 2 | L24: 74 | M24: 130 | N24: 522 | O24: 1180 | P24: 1948 | Q24: 80073.41 | R24: =IFERROR(M24*30/(N24*7),0) -> 1.0673235 | S24: 77 | T24: =IFERROR(S24*30/N24,0) -> 4.4252874 | U24: FULL | V24: 137 | W24: 4.8 | X24: 0.0915 | Y24: 45969 | Z24: 更早 | AA24: 12 | AB24: 0.37368421 | AC24: 51 cm | AD24: 4.8 cm | AE24: 4.6 cm | AF24: 0.38 kg | AG24: 在售 | AH24: https://articulo.mercadolibre.com.mx/MLM-2551024807-2pcs-50cm-luz-de-led-closet-usb-con-sensor-movimiento-_JM | AI24: Hogar, Muebles y Jardín(家居、家具和花园) -> Iluminación para el Hogar(家居照明) -> Lámparas(灯具) -> Lámparas de Pared(壁灯) | AJ24: 0
A25: 22 | B25: MLM4308432370 | C25: 30cmcon Sensor Movimiento Luz De Led Clóset Usb 5 Piezas | D25: 邻近：橱柜/衣柜灯 | E25: 100–149 | F25: Try Me | G25: try me | H25: OSASKUFHBED | I25: 本土店 | J25: 149 | K25: 5 | L25: 29.8 | M25: 121 | N25: 509 | O25: 851 | P25: 1425 | Q25: 77480 | R25: =IFERROR(M25*30/(N25*7),0) -> 1.0188044 | S25: 171 | T25: =IFERROR(S25*30/N25,0) -> 10.078585 | U25: FULL | V25: 138 | W25: 4.7 | X25: 0.1159 | Y25: 45961 | Z25: 更早 | AB25: 0.76736111 | AC25: 37.8 cm | AD25: 12.6 cm | AE25: 3 cm | AF25: 0.34 kg | AG25: 在售 | AH25: https://articulo.mercadolibre.com.mx/MLM-4308432370-30cmcon-sensor-movimiento-luz-de-led-closet-usb-5-piezas-_JM | AI25: Hogar, Muebles y Jardín(家居、家具和花园) -> Iluminación para el Hogar(家居照明) -> Lámparas(灯具) -> Lámparas de Pared(壁灯) | AJ25: 0
A26: 23 | B26: MLM3632053106 | C26: Gosun® Lámpara De Pared Led 12w Impermeable Foco Flotante Estructura Negro - Blanco Cálido | D26: 有线户外/通用壁灯 | E26: 150–199 | F26: Genérica | G26: generica | H26: CNWEIWORLD-MXF | I26: 跨境店 | J26: 176.23 | K26: 1 | L26: 176.23 | M26: 132 | N26: 484 | O26: 1293 | P26: 6960 | Q26: 88291.23 | R26: =IFERROR(M26*30/(N26*7),0) -> 1.1688312 | S26: 612 | T26: =IFERROR(S26*30/N26,0) -> 37.933884 | U26: FULL | V26: 301 | W26: 4.9 | X26: 0.1695 | Y26: 45757 | Z26: 更早 | AA26: 20 | AB26: 0.10502283 | AC26: 11.4 cm | AD26: 11 cm | AE26: 11.2 cm | AF26: 0.27 kg | AG26: 在售 | AH26: https://articulo.mercadolibre.com.mx/MLM-3632053106-gosun-lampara-de-pared-led-12w-impermeable-foco-flotante-estructura-negro-blanco-calido-_JM | AI26: Hogar, Muebles y Jardín(家居、家具和花园) -> Iluminación para el Hogar(家居照明) -> Lámparas(灯具) -> Lámparas de Pared(壁灯) | AJ26: 1
A27: 24 | B27: MLM2766217743 | C27: 2 Barras Led 50cm Lampara Inteligente Con Sensor Corporal | D27: 邻近：橱柜/衣柜灯 | E27: 150–199 | F27: Rindion | G27: rindion | H27: RINDION | I27: 跨境店 | J27: 158.81 | K27: 2 | L27: 79.41 | M27: 99 | N27: 473 | O27: 477 | P27: 557 | Q27: 75117.13 | R27: =IFERROR(M27*30/(N27*7),0) -> 0.89700997 | S27: 98 | T27: =IFERROR(S27*30/N27,0) -> 6.2156448 | U27: FULL | V27: 22 | W27: 4.9 | X27: 0.0649 | Y27: 46087 | Z27: 更早 | AA27: 12 | AB27: 117.25 | AC27: 52.2 cm | AD27: 5.2 cm | AE27: 5.6 cm | AF27: 0.44 kg | AG27: 在售 | AH27: https://articulo.mercadolibre.com.mx/MLM-2766217743-2-barras-led-50cm-lampara-inteligente-con-sensor-corporal-_JM | AI27: Hogar, Muebles y Jardín(家居、家具和花园) -> Iluminación para el Hogar(家居照明) -> Lámparas(灯具) -> Lámparas de Pared(壁灯) | AJ27: 0
A28: 25 | B28: MLM2910627089 | C28: Time4buy 3pzs Lámpara De Pared Led 12w Exteriores Interior Impermeable Exterior Para Jardín, Patio, Terraza, Inicio (luz Cálida ) | D28: 有线户外/通用壁灯 | E28: 200–299 | F28: Time4buy | G28: time4buy | H28: TIME4BUY | I28: 跨境店 | J28: 296.87 | K28: 3 | L28: 98.96 | M28: 132 | N28: 440 | O28: 1486 | P28: 2172 | Q28: 134185.24 | R28: =IFERROR(M28*30/(N28*7),0) -> 1.2857143 | S28: 214 | T28: =IFERROR(S28*30/N28,0) -> 14.590909 | U28: FULL | V28: 164 | W28: 4.8 | X28: 0.0956 | Y28: 46148 | Z28: 91–180天 | AA28: 16 | AB28: 0.11392405 | AC28: 35 cm | AD28: 11.6 cm | AE28: 11.6 cm | AF28: 0.79 kg | AG28: 在售 | AH28: https://articulo.mercadolibre.com.mx/MLM-2910627089-time4buy-3pzs-lampara-de-pared-led-6w-exteriores-interior-angulo-de-luz-ajustable-10x10x10cm-haz-superior-e-inferior-impermeable-exterior-para-jardin-patio-terraza-inicio-luz-calida--_JM | AI28: Hogar, Muebles y Jardín(家居、家具和花园) -> Iluminación para el Hogar(家居照明) -> Lámparas(灯具) -> Lámparas de Pared(壁灯) | AJ28: 1
A29: 26 | B29: MLM2609956161 | C29: Lámpara Solar Pared Exterior Con Sensor De Movimiento Jardin | D29: 太阳能户外壁灯 | E29: 300–499 | F29: NENSED | G29: nensed | H29: NENSED STORE | I29: 跨境店 | J29: 343.51 | K29: 1 | L29: 343.51 | M29: 97 | N29: 432 | O29: 1495 | P29: 2855 | Q29: 154923.01 | R29: =IFERROR(M29*30/(N29*7),0) -> 0.96230159 | S29: 750 | T29: =IFERROR(S29*30/N29,0) -> 52.083333 | U29: FULL | V29: 157 | W29: 4.8 | X29: 0.0348 | Y29: 45999 | Z29: 更早 | AA29: 16 | AB29: 0.6744186 | AC29: 20.4 cm | AD29: 19 cm | AE29: 13.6 cm | AF29: 0.61 kg | AG29: 在售 | AH29: https://articulo.mercadolibre.com.mx/MLM-2609956161-lampara-solar-pared-exterior-con-sensor-de-movimiento-jardin-_JM | AI29: Hogar, Muebles y Jardín(家居、家具和花园) -> Iluminación para el Hogar(家居照明) -> Lámparas(灯具) -> Lámparas de Pared(壁灯) | AJ29: 1
A30: 27 | B30: MLM2115041365 | C30: 2 Barra De Luz Led Inteligente Con Sensor De Cuerpo Humano | D30: 邻近：橱柜/衣柜灯 | E30: 100–149 | F30: TIANZHI | G30: tianzhi | H30: TIANZHI | I30: 跨境店 | J30: 145.52 | K30: 2 | L30: 72.76 | M30: 52 | N30: 425 | O30: 1298 | P30: 5984 | Q30: 61846 | R30: =IFERROR(M30*30/(N30*7),0) -> 0.52436975 | S30: 145 | T30: =IFERROR(S30*30/N30,0) -> 10.235294 | U30: FULL | V30: 594 | W30: 4.6 | X30: 0.1248 | Y30: 45511 | Z30: 更早 | AA30: 18 | AB30: 0.021634615 | AC30: 40.2 cm | AD30: 4.6 cm | AE30: 4 cm | AF30: 0.25 kg | AG30: 在售 | AH30: https://articulo.mercadolibre.com.mx/MLM-2115041365-2-barra-de-luz-led-inteligente-con-sensor-de-cuerpo-humano-_JM | AI30: Hogar, Muebles y Jardín(家居、家具和花园) -> Iluminación para el Hogar(家居照明) -> Lámparas(灯具) -> Lámparas de Pared(壁灯) | AJ30: 0
A31: 28 | B31: MLM2284562447 | C31: Judeng® Lámpara Led De Pared Impermeable Para Interior Y Exterior Lampara De Pared Exterior Y Interior Moderna Decorativas Para Jardin Sala Con 2 Focos Y 3 Modos De Luz Blanca,cálida,neutra Negro | D31: 有线户外/通用壁灯 | E31: 200–299 | F31: Judeng | G31: judeng | H31: CNJUDENG-MXF | I31: 跨境店 | J31: 259.87 | K31: 1 | L31: 259.87 | M31: 59 | N31: 425 | O31: 941 | P31: 6508 | Q31: 110444.75 | R31: =IFERROR(M31*30/(N31*7),0) -> 0.59495798 | S31: 977 | T31: =IFERROR(S31*30/N31,0) -> 68.964706 | U31: FULL | V31: 305 | W31: 4.7 | X31: 0.0893 | Y31: 45764 | Z31: 更早 | AA31: 20 | AB31: 1.0238095 | AC31: 16.8 cm | AD31: 30 cm | AE31: 9.6 cm | AF31: 0.68 kg | AG31: 在售 | AH31: https://articulo.mercadolibre.com.mx/MLM-2284562447-lampara-de-pared-judeng-led-cuadrada-negra-para-exterior-e-interior-negro-_JM | AI31: Hogar, Muebles y Jardín(家居、家具和花园) -> Iluminación para el Hogar(家居照明) -> Lámparas(灯具) -> Lámparas de Pared(壁灯) | AJ31: 1
A32: 29 | B32: MLM3897340848 | C32: Dehobo Lámparas Pared Exterior Focos Impermeable Ip65 8w, Led Moderna Y Decorativas Arbotante Iluminacion Hogar Lamparas Exteriores,iluminacion Led Pared Uso Exterior/interior Color Negro,luz Cálida | D32: 有线户外/通用壁灯 | E32: 100–149 | F32: DEHOBO | G32: dehobo | H32: CNHAIZHILIMYMXF | I32: 跨境店 | J32: 140.26 | K32: 1 | L32: 140.26 | M32: 45 | N32: 416 | O32: 816 | P32: 2306 | Q32: 60031.28 | R32: =IFERROR(M32*30/(N32*7),0) -> 0.4635989 | S32: 205 | T32: =IFERROR(S32*30/N32,0) -> 14.783654 | U32: FULL | V32: 79 | W32: 4.7 | X32: 0.1551 | Y32: 45875 | Z32: 更早 | AB32: 0.67068273 | AC32: 22.6 cm | AD32: 8.8 cm | AE32: 5.6 cm | AF32: 0.3 kg | AG32: 在售 | AH32: https://articulo.mercadolibre.com.mx/MLM-3897340848-dehobo-lamparas-pared-exterior-focos-impermeable-ip65-8w-led-moderna-y-decorativas-arbotante-iluminacion-hogar-lamparas-exterioresiluminacion-led-pared-uso-exteriorinterior-color-negroluz-calida-_JM | AI32: Hogar, Muebles y Jardín(家居、家具和花园) -> Iluminación para el Hogar(家居照明) -> Lámparas(灯具) -> Lámparas de Pared(壁灯) | AJ32: 1
A33: 30 | B33: MLM2852310939 | C33: Vanance® Lamparas De Pared Led Exterior Interiores Arbotante Decorativa Modernas Impermeable Luz Cálida Lámpara Led Pared De 24w Lámparas Para Jardín Sala Baño Negro | D33: 有线户外/通用壁灯 | E33: 150–199 | F33: Vanance | G33: vanance | H33: VANANCE | I33: 本土店 | J33: 159 | K33: 1 | L33: 159 | M33: 141 | N33: 408 | O33: 1265 | P33: 2056 | Q33: 64872 | R33: =IFERROR(M33*30/(N33*7),0) -> 1.4810924 | S33: 345 | T33: =IFERROR(S33*30/N33,0) -> 25.367647 | U33: FULL | V33: 97 | W33: 4.5 | X33: 0.09 | Y33: 46121 | Z33: 91–180天 | AB33: 0.068062827 | AC33: 25.8 cm | AD33: 12 cm | AE33: 9.4 cm | AF33: 0.37 kg | AG33: 在售 | AH33: https://articulo.mercadolibre.com.mx/MLM-2852310939-vanance-lamparas-de-pared-led-exterior-interiores-arbotante-decorativa-modernas-impermeable-luz-calida-lampara-led-pared-de-24w-lamparas-para-jardin-sala-bano-negro-_JM | AI33: Hogar, Muebles y Jardín(家居、家具和花园) -> Iluminación para el Hogar(家居照明) -> Lámparas(灯具) -> Lámparas de Pared(壁灯) | AJ33: 1
A34: 31 | B34: MLM2863105865 | C34: 6 Piezas Lampara Con Sensor Movimiento Luz De Led Clóset Usb | D34: 邻近：橱柜/衣柜灯 | E34: 150–199 | F34: Genérica | G34: generica | H34: RIFENGSHAN | I34: 本土店 | J34: 190.78 | K34: 6 | L34: 31.8 | M34: 86 | N34: 405 | O34: 877 | P34: 929 | Q34: 77265.9 | R34: =IFERROR(M34*30/(N34*7),0) -> 0.91005291 | S34: 229 | T34: =IFERROR(S34*30/N34,0) -> 16.962963 | U34: FULL | V34: 60 | W34: 4.5 | X34: 0.0769 | Y34: 46126 | Z34: 91–180天 | AB34: 2.4913793 | AC34: 26 cm | AD34: 9.5 cm | AE34: 5.7 cm | AF34: 0.4 kg | AG34: 在售 | AH34: https://articulo.mercadolibre.com.mx/MLM-2863105865-6-piezas-lampara-con-sensor-movimiento-luz-de-led-closet-usb-_JM | AI34: Hogar, Muebles y Jardín(家居、家具和花园) -> Iluminación para el Hogar(家居照明) -> Lámparas(灯具) -> Lámparas de Pared(壁灯) | AJ34: 0
A35: 32 | B35: MLM4308534336 | C35: 50cm Con Sensor Movimiento Luz De Led Clóset Usb 5 Piezas | D35: 邻近：橱柜/衣柜灯 | E35: 150–199 | F35: Try Me | G35: try me | H35: OSASKUFHBED | I35: 本土店 | J35: 169 | K35: 5 | L35: 33.8 | M35: 123 | N35: 401 | O35: 539 | P35: 800 | Q35: 70304 | R35: =IFERROR(M35*30/(N35*7),0) -> 1.3145707 | S35: 395 | T35: =IFERROR(S35*30/N35,0) -> 29.551122 | U35: FULL | V35: 62 | W35: 4.8 | X35: 0.0989 | Y35: 45961 | Z35: 更早 | AA35: 8 | AB35: 99.25 | AC35: 56 cm | AD35: 12.2 cm | AE35: 2.8 cm | AF35: 0.48 kg | AG35: 在售 | AH35: https://articulo.mercadolibre.com.mx/MLM-4308534336-50cm-con-sensor-movimiento-luz-de-led-closet-usb-5-piezas-_JM | AI35: Hogar, Muebles y Jardín(家居、家具和花园) -> Iluminación para el Hogar(家居照明) -> Lámparas(灯具) -> Lámparas de Pared(壁灯) | AJ35: 0
A36: 33 | B36: MLM2630649971 | C36: Judeng® Lámpara De Pared Negra Impermeable Para Lámpara De Pared Led Para Exteriores Lampara De Pared Exterior Y Interior Moderna Decorativas Para Jardin Sala 3 Modos De Luz Blanca,cálida,neutra Negro | D36: 有线户外/通用壁灯 | E36: 200–299 | F36: Judeng | G36: judeng | H36: JUDENG ONLINE | I36: 跨境店 | J36: 254.02 | K36: 1 | L36: 254.02 | M36: 57 | N36: 396 | O36: 1177 | P36: 3089 | Q36: 103386.14 | R36: =IFERROR(M36*30/(N36*7),0) -> 0.61688312 | S36: 1 | T36: =IFERROR(S36*30/N36,0) -> 0.075757576 | U36: FULL | V36: 98 | W36: 4.7 | X36: 0.0906 | Y36: 46009 | Z36: 更早 | AB36: 0.29836066 | AC36: 31.4 cm | AD36: 13.8 cm | AE36: 11.8 cm | AF36: 0.7 kg | AG36: 在售 | AH36: https://articulo.mercadolibre.com.mx/MLM-2630649971-lampara-de-pared-judeng-led-de-2-focos-para-exterior-e-interior-_JM | AI36: Hogar, Muebles y Jardín(家居、家具和花园) -> Iluminación para el Hogar(家居照明) -> Lámparas(灯具) -> Lámparas de Pared(壁灯) | AJ36: 1
A37: 34 | B37: MLM2658745862 | C37: Lámpara Plástica Esférica Tipo Pantalla Decorativa De 15cm De Diámetro Cubre Socket Y Cubre Foco En Techo Y Pared O' Farrill Lucefacil-lf02t Color Blanco Opalino | D37: 有线户外/通用壁灯 | E37: 150–199 | F37: O Farrill Refract | G37: o farrill refract | H37: LOFFA | I37: 本土店 | J37: 179.99 | K37: 1 | L37: 179.99 | M37: 79 | N37: 395 | O37: 1392 | P37: 26980 | Q37: 73075.94 | R37: =IFERROR(M37*30/(N37*7),0) -> 0.85714286 | S37: 1489 | T37: =IFERROR(S37*30/N37,0) -> 113.08861 | U37: FULL | V37: 4591 | W37: 4.5 | X37: 0.0956 | Y37: 45236 | Z37: 更早 | AA37: 1 | AB37: -0.27655678 | AC37: 16.6 cm | AD37: 15.2 cm | AE37: 20.2 cm | AF37: 0.16 kg | AG37: 在售 | AH37: https://articulo.mercadolibre.com.mx/MLM-2658745862-lampara-esferica-blanca-o-farrill-techo-y-pared-para-led-e26e27-interior-exterior-blanco-_JM | AI37: Hogar, Muebles y Jardín(家居、家具和花园) -> Iluminación para el Hogar(家居照明) -> Lámparas(灯具) -> Lámparas de Pared(壁灯) | AJ37: 1
A38: 35 | B38: MLM2231781627 | C38: 3pack 40cm Luz De Led Clóset Usb Con Sensor Movimiento | D38: 邻近：橱柜/衣柜灯 | E38: 150–199 | F38: OCEBEEC | G38: ocebeec | H38: JUOYTGXZ | I38: 本土店 | J38: 173 | K38: 3 | L38: 57.67 | M38: 35 | N38: 385 | O38: 1057 | P38: 3607 | Q38: 68681 | R38: =IFERROR(M38*30/(N38*7),0) -> 0.38961039 | S38: 123 | T38: =IFERROR(S38*30/N38,0) -> 9.5844156 | U38: FULL | V38: 122 | W38: 4.7 | X38: 0.0645 | Y38: 45694 | Z38: 更早 | AB38: 0.27906977 | AC38: 43 cm | AD38: 9.9 cm | AE38: 5.4 cm | AF38: 0.35 kg | AG38: 在售 | AH38: https://articulo.mercadolibre.com.mx/MLM-2231781627-3pack-40cm-luz-de-led-closet-usb-con-sensor-movimiento-blanco-_JM | AI38: Hogar, Muebles y Jardín(家居、家具和花园) -> Iluminación para el Hogar(家居照明) -> Lámparas(灯具) -> Lámparas de Pared(壁灯) | AJ38: 0
A39: 36 | B39: MLM2310510009 | C39: Yuju Lámpara De Pared Led Impermeable Sobreponer Para Exterior Lamparas De Pared Exterior Lampara Arbotante Lampara Arbotante Potencia 60 W Negro | D39: 有线户外/通用壁灯 | E39: 200–299 | F39: Yuju | G39: yuju | H39: YU JU STORE | I39: 跨境店 | J39: 263.31 | K39: 1 | L39: 263.31 | M39: 93 | N39: 383 | O39: 1064 | P39: 4825 | Q39: 105060.69 | R39: =IFERROR(M39*30/(N39*7),0) -> 1.0406565 | S39: 579 | T39: =IFERROR(S39*30/N39,0) -> 45.35248 | U39: FULL | V39: 462 | W39: 4.7 | X39: 0.1074 | Y39: 45791 | Z39: 更早 | AB39: 0.018617021 | AC39: 30.6 cm | AD39: 16.4 cm | AE39: 9.6 cm | AF39: 0.8 kg | AG39: 在售 | AH39: https://articulo.mercadolibre.com.mx/MLM-2310510009-lampara-de-pared-para-exterior-led-ip65-y-con-diseno-de-iluminacion-arriba-y-abajo-e27-negro-_JM | AI39: Hogar, Muebles y Jardín(家居、家具和花园) -> Iluminación para el Hogar(家居照明) -> Lámparas(灯具) -> Lámparas de Pared(壁灯) | AJ39: 1
A40: 37 | B40: MLM2220599481 | C40: 2 Piezas Lámparas De Pared Lampara Solar Jardin Impermeables | D40: 太阳能户外壁灯 | E40: 150–199 | F40: Wasume | G40: wasume | H40: WASUME | I40: 跨境店 | J40: 194.47 | K40: 2 | L40: 97.23 | M40: 61 | N40: 376 | O40: 596 | P40: 1474 | Q40: 73120.72 | R40: =IFERROR(M40*30/(N40*7),0) -> 0.69528875 | S40: 21 | T40: =IFERROR(S40*30/N40,0) -> 1.6755319 | U40: FULL | V40: 149 | W40: 4.5 | X40: 0.0946 | Y40: 45670 | Z40: 更早 | AB40: 0.82524272 | AC40: 25.6 cm | AD40: 17.7 cm | AE40: 6.8 cm | AF40: 0.61 kg | AG40: 在售 | AH40: https://articulo.mercadolibre.com.mx/MLM-2220599481-2-piezas-lamparas-de-pared-lampara-solar-jardin-impermeables-_JM | AI40: Hogar, Muebles y Jardín(家居、家具和花园) -> Iluminación para el Hogar(家居照明) -> Lámparas(灯具) -> Lámparas de Pared(壁灯) | AJ40: 1
...
