Workbook

Sheet 项目封面
J1: 德国切菜板实战市场调研
J4: 德文关键词 | L4: schneidebrett / schneidebrett holz | O4: 调研时间 | Q4: 2026-09-10 | T4: 类目编号 | V4: 3177921031
J9: 阅读说明
J12: 本次填入：竞争格局、CPC（每次点击竞价）预估、自然流量，以及砧板榜单100款明细。 类目：Hackbretter（砧板），节点3177921031。切菜板、木制切菜板关键词样本分别展示，不与类目榜单混算。 子体订单量“1,000+”保留原显示；自然流量是关键词样本内份额，不等于自然订单比例。 13张“模拟_”业务表全部保留原输入和公式，各套售价、佣金及推广目标分别保留。推广计划源表已有26处公式错误，尚未修改。 无关案例数据和图片已清除，未开展部分保留空白模板。

Sheet ①市场背景调查
A1: 德国站切菜板 Hackbretter｜市场背景调查
A2: 1.宏观分析 | V2: 【总结】 2026年1—8月销量43.11万件，同比增长35.47%；销售额€898.48万，同比增长40.82%。 2025年第四季度贡献全年32.91%的销量。 2026年8月第三方销量占68.69%，自营28.98%。 【趋势表明】 需求增长、年末放量明显。按日期核验的12款新品月销2,529件，前三款贡献60.02%；有新品成交机会，但集中于少数款。 | AA2: 2026年较2025年｜固定样本销量 | AI2: 2025年较2024年｜固定样本销量
AA4: 月份 | AB4: 2025 已知销量 | AC4: 2026 已知销量 | AD4: 2025 配对销量 | AE4: 2026 配对销量 | AF4: 配对父体数 | AG4: 配对同比 | AI4: 月份 | AJ4: 2024 已知销量 | AK4: 2025 已知销量 | AL4: 2024 配对销量 | AM4: 2025 配对销量 | AN4: 配对父体数 | AO4: 配对同比
AA5: 1 | AB5: =SUM(J772:J871) -> 19056 | AC5: =SUM(V772:V871) -> 44072 | AD5: =SUM(J772,J776,J777,J778,J779,J780,J781,J782,J784,J786,J790,J792,J793,J794,J798,J800,J801,J804,J810,J813,J814,J816,J818,J819,J820,J822,J823,J825,J827,J830,J833,J834,J837,J840,J841,J842,J848,J852,J853,J855,J856,J857,J859,J863,J868,J869,J871) -> 19056 | AE5: =SUM(V772,V776,V777,V778,V779,V780,V781,V782,V784,V786,V790,V792,V793,V794,V798,V800,V801,V804,V810,V813,V814,V816,V818,V819,V820,V822,V823,V825,V827,V830,V833,V834,V837,V840,V841,V842,V848,V852,V853,V855,V856,V857,V859,V863,V868,V869,V871) -> 30709 | AF5: 47 | AG5: =AE5/AD5-1 -> 0.61151343 | AI5: 1 | AJ5: 缺数据 | AK5: =SUM(J772:J871) -> 19056 | AL5: 缺数据 | AM5: 缺数据 | AN5: 缺数据 | AO5: 缺数据
AA6: 2 | AB6: =SUM(K772:K871) -> 18616 | AC6: =SUM(W772:W871) -> 40545 | AD6: =SUM(K772,K776,K777,K778,K779,K780,K781,K782,K784,K785,K786,K790,K792,K793,K794,K798,K800,K801,K807,K809,K810,K813,K814,K816,K817,K818,K819,K820,K822,K823,K824,K825,K827,K830,K833,K834,K837,K840,K841,K842,K848,K849,K852,K853,K855,K856,K857,K859,K862,K863,K866,K868,K869) -> 18616 | AE6: =SUM(W772,W776,W777,W778,W779,W780,W781,W782,W784,W785,W786,W790,W792,W793,W794,W798,W800,W801,W807,W809,W810,W813,W814,W816,W817,W818,W819,W820,W822,W823,W824,W825,W827,W830,W833,W834,W837,W840,W841,W842,W848,W849,W852,W853,W855,W856,W857,W859,W862,W863,W866,W868,W869) -> 31513 | AF6: 53 | AG6: =AE6/AD6-1 -> 0.69279115 | AI6: 2 | AJ6: 缺数据 | AK6: =SUM(K772:K871) -> 18616 | AL6: 缺数据 | AM6: 缺数据 | AN6: 缺数据 | AO6: 缺数据
AA7: 3 | AB7: =SUM(L772:L871) -> 21515 | AC7: =SUM(X772:X871) -> 40468 | AD7: =SUM(L772,L776,L777,L778,L779,L780,L782,L784,L785,L786,L789,L790,L792,L793,L794,L798,L800,L801,L807,L809,L810,L813,L814,L816,L817,L818,L819,L820,L822,L823,L824,L825,L827,L830,L833,L834,L837,L840,L841,L842,L848,L852,L853,L855,L856,L857,L859,L862,L863,L866,L868,L869,L871) -> 21515 | AE7: =SUM(X772,X776,X777,X778,X779,X780,X782,X784,X785,X786,X789,X790,X792,X793,X794,X798,X800,X801,X807,X809,X810,X813,X814,X816,X817,X818,X819,X820,X822,X823,X824,X825,X827,X830,X833,X834,X837,X840,X841,X842,X848,X852,X853,X855,X856,X857,X859,X862,X863,X866,X868,X869,X871) -> 30960 | AF7: 53 | AG7: =AE7/AD7-1 -> 0.43899605 | AI7: 3 | AJ7: 缺数据 | AK7: =SUM(L772:L871) -> 21515 | AL7: 缺数据 | AM7: 缺数据 | AN7: 缺数据 | AO7: 缺数据
AA8: 4 | AB8: =SUM(M772:M871) -> 20379 | AC8: =SUM(Y772:Y871) -> 39223 | AD8: =SUM(M776,M777,M778,M779,M780,M781,M782,M784,M785,M786,M789,M790,M792,M793,M794,M798,M800,M801,M807,M809,M810,M813,M814,M816,M817,M818,M819,M820,M822,M823,M824,M825,M827,M828,M830,M833,M834,M837,M840,M841,M842,M849,M852,M853,M855,M856,M857,M859,M860,M862,M863,M866,M868,M869,M871) -> 20379 | AE8: =SUM(Y776,Y777,Y778,Y779,Y780,Y781,Y782,Y784,Y785,Y786,Y789,Y790,Y792,Y793,Y794,Y798,Y800,Y801,Y807,Y809,Y810,Y813,Y814,Y816,Y817,Y818,Y819,Y820,Y822,Y823,Y824,Y825,Y827,Y828,Y830,Y833,Y834,Y837,Y840,Y841,Y842,Y849,Y852,Y853,Y855,Y856,Y857,Y859,Y860,Y862,Y863,Y866,Y868,Y869,Y871) -> 30493 | AF8: 55 | AG8: =AE8/AD8-1 -> 0.49629521 | AI8: 4 | AJ8: 缺数据 | AK8: =SUM(M772:M871) -> 20379 | AL8: 缺数据 | AM8: 缺数据 | AN8: 缺数据 | AO8: 缺数据
AA9: 5 | AB9: =SUM(N772:N871) -> 26972 | AC9: =SUM(Z772:Z871) -> 45879 | AD9: =SUM(N776,N777,N778,N779,N780,N781,N782,N784,N785,N786,N787,N789,N790,N792,N793,N794,N798,N800,N801,N802,N807,N809,N810,N811,N813,N814,N816,N817,N818,N819,N820,N822,N823,N824,N825,N827,N828,N830,N833,N834,N837,N840,N841,N842,N848,N849,N852,N853,N855,N856,N857,N859,N860,N862,N863,N866,N867,N868,N869,N871) -> 26972 | AE9: =SUM(Z776,Z777,Z778,Z779,Z780,Z781,Z782,Z784,Z785,Z786,Z787,Z789,Z790,Z792,Z793,Z794,Z798,Z800,Z801,Z802,Z807,Z809,Z810,Z811,Z813,Z814,Z816,Z817,Z818,Z819,Z820,Z822,Z823,Z824,Z825,Z827,Z828,Z830,Z833,Z834,Z837,Z840,Z841,Z842,Z848,Z849,Z852,Z853,Z855,Z856,Z857,Z859,Z860,Z862,Z863,Z866,Z867,Z868,Z869,Z871) -> 36503 | AF9: 60 | AG9: =AE9/AD9-1 -> 0.35336645 | AI9: 5 | AJ9: 缺数据 | AK9: =SUM(N772:N871) -> 26972 | AL9: 缺数据 | AM9: 缺数据 | AN9: 缺数据 | AO9: 缺数据
AA10: 6 | AB10: =SUM(O772:O871) -> 20510 | AC10: =SUM(AA772:AA871) -> 45455 | AD10: =SUM(O772,O776,O777,O778,O779,O780,O781,O782,O784,O785,O786,O787,O789,O790,O792,O793,O794,O798,O800,O801,O802,O804,O807,O809,O810,O811,O813,O814,O816,O817,O818,O819,O820,O822,O823,O824,O825,O827,O828,O829,O830,O832,O833,O834,O837,O840,O841,O842,O843,O848,O849,O852,O853,O855,O856,O857,O859,O860,O862,O863,O866,O867,O868,O869,O871) -> 20510 | AE10: =SUM(AA772,AA776,AA777,AA778,AA779,AA780,AA781,AA782,AA784,AA785,AA786,AA787,AA789,AA790,AA792,AA793,AA794,AA798,AA800,AA801,AA802,AA804,AA807,AA809,AA810,AA811,AA813,AA814,AA816,AA817,AA818,AA819,AA820,AA822,AA823,AA824,AA825,AA827,AA828,AA829,AA830,AA832,AA833,AA834,AA837,AA840,AA841,AA842,AA843,AA848,AA849,AA852,AA853,AA855,AA856,AA857,AA859,AA860,AA862,AA863,AA866,AA867,AA868,AA869,AA871) -> 36457 | AF10: 65 | AG10: =AE10/AD10-1 -> 0.77752316 | AI10: 6 | AJ10: =SUM(C772:C871) -> 10880 | AK10: =SUM(O772:O871) -> 20510 | AL10: =SUM(C772,C776,C777,C778,C779,C780,C782,C784,C786,C792,C793,C794,C798,C800,C801,C813,C814,C816,C819,C820,C822,C823,C825,C827,C828,C830,C834,C837,C840,C841,C842,C848,C849,C852,C853,C855,C856,C857,C859) -> 10880 | AM10: =SUM(O772,O776,O777,O778,O779,O780,O782,O784,O786,O792,O793,O794,O798,O800,O801,O813,O814,O816,O819,O820,O822,O823,O825,O827,O828,O830,O834,O837,O840,O841,O842,O848,O849,O852,O853,O855,O856,O857,O859) -> 15247 | AN10: 39 | AO10: =AM10/AL10-1 -> 0.40137868
AA11: 7 | AB11: =SUM(P772:P871) -> 28857 | AC11: =SUM(AB772:AB871) -> 40513 | AD11: =SUM(P772,P776,P777,P778,P779,P780,P781,P782,P784,P785,P786,P787,P789,P790,P792,P793,P794,P798,P800,P801,P802,P804,P807,P809,P810,P811,P813,P814,P816,P817,P818,P819,P820,P822,P823,P824,P825,P827,P828,P829,P830,P832,P833,P834,P837,P838,P840,P841,P842,P843,P848,P849,P852,P853,P855,P856,P857,P859,P860,P862,P863,P866,P867,P868,P869,P871) -> 28857 | AE11: =SUM(AB772,AB776,AB777,AB778,AB779,AB780,AB781,AB782,AB784,AB785,AB786,AB787,AB789,AB790,AB792,AB793,AB794,AB798,AB800,AB801,AB802,AB804,AB807,AB809,AB810,AB811,AB813,AB814,AB816,AB817,AB818,AB819,AB820,AB822,AB823,AB824,AB825,AB827,AB828,AB829,AB830,AB832,AB833,AB834,AB837,AB838,AB840,AB841,AB842,AB843,AB848,AB849,AB852,AB853,AB855,AB856,AB857,AB859,AB860,AB862,AB863,AB866,AB867,AB868,AB869,AB871) -> 33719 | AF11: 66 | AG11: =AE11/AD11-1 -> 0.16848598 | AI11: 7 | AJ11: =SUM(D772:D871) -> 16308 | AK11: =SUM(P772:P871) -> 28857 | AL11: =SUM(D772,D776,D777,D778,D779,D780,D782,D784,D786,D792,D793,D794,D798,D800,D801,D813,D814,D816,D819,D820,D822,D823,D825,D827,D828,D830,D833,D834,D837,D840,D841,D842,D848,D849,D852,D853,D855,D856,D857,D859,D868) -> 16308 | AM11: =SUM(P772,P776,P777,P778,P779,P780,P782,P784,P786,P792,P793,P794,P798,P800,P801,P813,P814,P816,P819,P820,P822,P823,P825,P827,P828,P830,P833,P834,P837,P840,P841,P842,P848,P849,P852,P853,P855,P856,P857,P859,P868) -> 23075 | AN11: 41 | AO11: =AM11/AL11-1 -> 0.41494972
AA12: 8 | AB12: =SUM(Q772:Q871) -> 25245 | AC12: =SUM(AC772:AC871) -> 55240 | AD12: =SUM(Q772,Q774,Q776,Q777,Q778,Q779,Q780,Q781,Q782,Q784,Q785,Q786,Q787,Q789,Q790,Q792,Q793,Q794,Q798,Q800,Q801,Q802,Q804,Q807,Q809,Q810,Q811,Q812,Q813,Q814,Q816,Q817,Q818,Q819,Q820,Q822,Q823,Q824,Q825,Q827,Q828,Q829,Q830,Q832,Q833,Q834,Q837,Q838,Q840,Q841,Q842,Q843,Q848,Q849,Q852,Q853,Q855,Q856,Q857,Q859,Q860,Q862,Q863,Q866,Q867,Q868,Q869,Q871) -> 25245 | AE12: =SUM(AC772,AC774,AC776,AC777,AC778,AC779,AC780,AC781,AC782,AC784,AC785,AC786,AC787,AC789,AC790,AC792,AC793,AC794,AC798,AC800,AC801,AC802,AC804,AC807,AC809,AC810,AC811,AC812,AC813,AC814,AC816,AC817,AC818,AC819,AC820,AC822,AC823,AC824,AC825,AC827,AC828,AC829,AC830,AC832,AC833,AC834,AC837,AC838,AC840,AC841,AC842,AC843,AC848,AC849,AC852,AC853,AC855,AC856,AC857,AC859,AC860,AC862,AC863,AC866,AC867,AC868,AC869,AC871) -> 43783 | AF12: 68 | AG12: =AE12/AD12-1 -> 0.73432363 | AI12: 8 | AJ12: =SUM(E772:E871) -> 16301 | AK12: =SUM(Q772:Q871) -> 25245 | AL12: =SUM(E772,E776,E777,E778,E779,E780,E782,E784,E786,E792,E793,E794,E798,E800,E801,E813,E814,E816,E819,E820,E822,E823,E825,E827,E828,E830,E834,E837,E840,E842,E848,E852,E853,E855,E856,E857,E859,E868) -> 16301 | AM12: =SUM(Q772,Q776,Q777,Q778,Q779,Q780,Q782,Q784,Q786,Q792,Q793,Q794,Q798,Q800,Q801,Q813,Q814,Q816,Q819,Q820,Q822,Q823,Q825,Q827,Q828,Q830,Q834,Q837,Q840,Q842,Q848,Q852,Q853,Q855,Q856,Q857,Q859,Q868) -> 17340 | AN12: 38 | AO12: =AM12/AL12-1 -> 0.063738421
AA13: 9 | AB13: =SUM(R772:R871) -> 24913 | AI13: 9 | AJ13: =SUM(F772:F871) -> 13575 | AK13: =SUM(R772:R871) -> 24913 | AL13: =SUM(F772,F776,F777,F778,F779,F780,F781,F782,F784,F786,F792,F793,F794,F798,F800,F801,F813,F814,F816,F819,F822,F823,F825,F827,F828,F830,F833,F834,F837,F840,F841,F842,F852,F853,F855,F856,F857,F859,F868,F869) -> 13575 | AM13: =SUM(R772,R776,R777,R778,R779,R780,R781,R782,R784,R786,R792,R793,R794,R798,R800,R801,R813,R814,R816,R819,R822,R823,R825,R827,R828,R830,R833,R834,R837,R840,R841,R842,R852,R853,R855,R856,R857,R859,R868,R869) -> 18122 | AN13: 40 | AO13: =AM13/AL13-1 -> 0.33495396
AA14: 10 | AB14: =SUM(S772:S871) -> 30380 | AI14: 10 | AJ14: =SUM(G772:G871) -> 18563 | AK14: =SUM(S772:S871) -> 30380 | AL14: =SUM(G772,G776,G777,G778,G779,G780,G781,G782,G784,G786,G792,G793,G794,G798,G800,G801,G813,G814,G816,G819,G820,G822,G823,G825,G827,G828,G830,G833,G834,G837,G840,G841,G842,G848,G852,G853,G855,G856,G857,G859,G868,G869) -> 18563 | AM14: =SUM(S772,S776,S777,S778,S779,S780,S781,S782,S784,S786,S792,S793,S794,S798,S800,S801,S813,S814,S816,S819,S820,S822,S823,S825,S827,S828,S830,S833,S834,S837,S840,S841,S842,S848,S852,S853,S855,S856,S857,S859,S868,S869) -> 21599 | AN14: 42 | AO14: =AM14/AL14-1 -> 0.16355115
AA15: 11 | AB15: =SUM(T772:T871) -> 44117 | AI15: 11 | AJ15: =SUM(H772:H871) -> 24356 | AK15: =SUM(T772:T871) -> 44117 | AL15: =SUM(H772,H776,H777,H778,H779,H780,H781,H782,H784,H786,H790,H792,H793,H794,H798,H800,H801,H804,H813,H814,H816,H819,H820,H822,H823,H825,H827,H828,H830,H833,H834,H837,H840,H841,H842,H848,H852,H853,H856,H857,H859,H868,H869) -> 24356 | AM15: =SUM(T772,T776,T777,T778,T779,T780,T781,T782,T784,T786,T790,T792,T793,T794,T798,T800,T801,T804,T813,T814,T816,T819,T820,T822,T823,T825,T827,T828,T830,T833,T834,T837,T840,T841,T842,T848,T852,T853,T856,T857,T859,T868,T869) -> 31781 | AN15: 43 | AO15: =AM15/AL15-1 -> 0.30485301
AA16: 12 | AB16: =SUM(U772:U871) -> 59834 | AI16: 12 | AJ16: =SUM(I772:I871) -> 27524 | AK16: =SUM(U772:U871) -> 59834 | AL16: =SUM(I772,I776,I777,I778,I779,I780,I781,I782,I784,I786,I790,I792,I793,I794,I798,I800,I801,I804,I810,I813,I814,I816,I818,I819,I820,I822,I823,I825,I827,I830,I833,I834,I837,I840,I841,I842,I848,I852,I853,I856,I857,I859,I868,I869,I871) -> 27524 | AM16: =SUM(U772,U776,U777,U778,U779,U780,U781,U782,U784,U786,U790,U792,U793,U794,U798,U800,U801,U804,U810,U813,U814,U816,U818,U819,U820,U822,U823,U825,U827,U830,U833,U834,U837,U840,U841,U842,U848,U852,U853,U856,U857,U859,U868,U869,U871) -> 42330 | AN16: 45 | AO16: =AM16/AL16-1 -> 0.53793053
AA18: 已知销量：该月100个固定父体中全部有值记录合计；两表2025同月数值一致。配对销量：仅两年同月都有值的父体，用于同比。2026仅列1—8月完整月。 | AI18: 已知销量：该月100个固定父体中全部有值记录合计；两表2025同月数值一致。配对销量：仅两年同月都有值的父体，用于同比。2024年1—5月缺失，不算全年同比。
A22: 2.行业分析&市场大盘分析 | V22: 【竞争结构】 9月10日已验证图保留：前三品牌销量占30.00%，前三卖家占46.89%，自营销量占34.55%。品牌集中度低于卖家，不能只看品牌分散就判断进入容易。 卖家地区销量份额：德国50.45%、中国30.23%、英国10.78%；这描述供给方，不是买家画像。 9月11日当前100款快照：前20销量占57.13%，尾部80款占42.87%；新品分析卡8款与日期明细12款不一致。按日期核验的12款月销2,529件，前三款贡献60.02%，不能用分析卡概括全部新品。 【历史口径】 卖家/配送与新品销量历史：自然月每天进入Top100的商品汇总，不是某日固定100款；与当前快照不交叉计算。 历史自营占比已确认是商品数量占比。12个月自营及第三方销量份额见A490，年龄销量份额见A512。前20历史系数的销量/金额口径仍待确认。 上架年龄分布为插件原分组；“3个月新品”不自行改称精确90天。 【产业链｜待补】 缺切菜板材料供给、产区及供应商证据。 右侧销售额补表使用9月11日独立100款数据，与左侧9月10日图分日期展示。
AB23: “目前我不会直接判断能做。大盘需求是增长的，今年1—8月销量同比增长35%左右，而且Q4有明显旺季，说明需求端没问题。但我比较关注新品表现，新品占8%，销量只占3%左右，说明增长不一定代表新品容易进入。另外TOP20已经拿走57%的销量，有一定头部效应。所以我下一步会重点看头部产品为什么卖得好、新品为什么占比低，以及我们的SKU在材质、场景、功能和差评痛点上有没有明确差异化。如果能找到可打的产品机会，再判断值得开发。”
A24: Hackbretter｜市场销售额历史 | J24: 第三方／自营销售结构｜销量历史
A38: 来源：9月11日Sorftime网页。2026年9月未结束；首月窗口完整性待确认。 | J38: 纵轴为件数；自然月每日上榜商品汇总。销售额结构仍待补。
A40: 第三方逐月销量趋势（件） | J40: Amazon自营逐月销量趋势（件）
AA51: 9月11日100款快照。预估销售额占比＝该组已知销售额÷样本已知销售额；3款金额缺失。左图为9月10日销量口径。
AA54: 品牌 | AB54: 商品数 | AC54: 月销量 | AD54: 月销售额€ | AE54: 预估销售额占比 | AG54: 卖家 | AH54: 商品数 | AI54: 月销量 | AJ54: 月销售额€ | AK54: 预估销售额占比
A55: 第三方固定样本74个父体。按9月3日卖家类型固定分组；非各月真实卖家身份。缺值不作零，9月未完整不展示。与上方Sorftime商品池不同，不能据此计算销售单价。 | J55: Amazon自营固定样本25个父体。按9月3日卖家类型固定分组；非各月真实卖家身份。缺值不作零，9月未完整不展示。与上方Sorftime商品池不同，不能据此计算销售单价。
A56: =_xlfn.DISPIMG("ID_DDBF4758CE894FF29B68EE54D39B2F47",1) -> =DISPIMG("ID_DDBF4758CE894FF29B68EE54D39B2F47",1) | AA56: Deer & Oak | AB56: =COUNTIF($B$234:$B$333,AA56) -> 3 | AC56: =SUMIF($B$234:$B$333,AA56,$E$234:$E$333) -> 3640 | AD56: =SUMIF($B$234:$B$333,AA56,$F$234:$F$333) -> 69796.08 | AE56: =AD56/$F$334 -> 0.070616096 | AG56: Amazon | AH56: =COUNTIF($C$234:$C$333,AG56) -> 21 | AI56: =SUMIF($C$234:$C$333,AG56,$E$234:$E$333) -> 15471 | AJ56: =SUMIF($C$234:$C$333,AG56,$F$234:$F$333) -> 231956.27 | AK56: =AJ56/$F$334 -> 0.23468146
AA57: WMF | AB57: =COUNTIF($B$234:$B$333,AA57) -> 2 | AC57: =SUMIF($B$234:$B$333,AA57,$E$234:$E$333) -> 2092 | AD57: =SUMIF($B$234:$B$333,AA57,$F$234:$F$333) -> 68158.58 | AE57: =AD57/$F$334 -> 0.068959357 | AG57: Great Ideas | AH57: =COUNTIF($C$234:$C$333,AG57) -> 3 | AI57: =SUMIF($C$234:$C$333,AG57,$E$234:$E$333) -> 3640 | AJ57: =SUMIF($C$234:$C$333,AG57,$F$234:$F$333) -> 69796.08 | AK57: =AJ57/$F$334 -> 0.070616096
AA58: MUVELL | AB58: =COUNTIF($B$234:$B$333,AA58) -> 1 | AC58: =SUMIF($B$234:$B$333,AA58,$E$234:$E$333) -> 1514 | AD58: =SUMIF($B$234:$B$333,AA58,$F$234:$F$333) -> 60484.3 | AE58: =AD58/$F$334 -> 0.061194914 | AG58: Gastro Service Profis | AH58: =COUNTIF($C$234:$C$333,AG58) -> 1 | AI58: =SUMIF($C$234:$C$333,AG58,$E$234:$E$333) -> 1514 | AJ58: =SUMIF($C$234:$C$333,AG58,$F$234:$F$333) -> 60484.3 | AK58: =AJ58/$F$334 -> 0.061194914
AA59: Culiex | AB59: =COUNTIF($B$234:$B$333,AA59) -> 2 | AC59: =SUMIF($B$234:$B$333,AA59,$E$234:$E$333) -> 1680 | AD59: =SUMIF($B$234:$B$333,AA59,$F$234:$F$333) -> 53211.13 | AE59: =AD59/$F$334 -> 0.053836294 | AG59: Culiex Direct | AH59: =COUNTIF($C$234:$C$333,AG59) -> 1 | AI59: =SUMIF($C$234:$C$333,AG59,$E$234:$E$333) -> 887 | AJ59: =SUMIF($C$234:$C$333,AG59,$F$234:$F$333) -> 53211.13 | AK59: =AJ59/$F$334 -> 0.053836294
AA60: Kesper | AB60: =COUNTIF($B$234:$B$333,AA60) -> 6 | AC60: =SUMIF($B$234:$B$333,AA60,$E$234:$E$333) -> 6992 | AD60: =SUMIF($B$234:$B$333,AA60,$F$234:$F$333) -> 47232.95 | AE60: =AD60/$F$334 -> 0.047787878 | AG60: Bestcook DE | AH60: =COUNTIF($C$234:$C$333,AG60) -> 5 | AI60: =SUMIF($C$234:$C$333,AG60,$E$234:$E$333) -> 1193 | AJ60: =SUMIF($C$234:$C$333,AG60,$F$234:$F$333) -> 46680.07 | AK60: =AJ60/$F$334 -> 0.047228502
AA61: BESTCOOK | AB61: =COUNTIF($B$234:$B$333,AA61) -> 5 | AC61: =SUMIF($B$234:$B$333,AA61,$E$234:$E$333) -> 1193 | AD61: =SUMIF($B$234:$B$333,AA61,$F$234:$F$333) -> 46680.07 | AE61: =AD61/$F$334 -> 0.047228502 | AG61: Everbrent | AH61: =COUNTIF($C$234:$C$333,AG61) -> 3 | AI61: =SUMIF($C$234:$C$333,AG61,$E$234:$E$333) -> 2618 | AJ61: =SUMIF($C$234:$C$333,AG61,$F$234:$F$333) -> 43758.82 | AK61: =AJ61/$F$334 -> 0.044272931
AA62: Blumtal | AB62: =COUNTIF($B$234:$B$333,AA62) -> 3 | AC62: =SUMIF($B$234:$B$333,AA62,$E$234:$E$333) -> 2618 | AD62: =SUMIF($B$234:$B$333,AA62,$F$234:$F$333) -> 43758.82 | AE62: =AD62/$F$334 -> 0.044272931 | AG62: ACESELF-EU | AH62: =COUNTIF($C$234:$C$333,AG62) -> 1 | AI62: =SUMIF($C$234:$C$333,AG62,$E$234:$E$333) -> 824 | AJ62: =SUMIF($C$234:$C$333,AG62,$F$234:$F$333) -> 37895.76 | AK62: =AJ62/$F$334 -> 0.038340987
AA63: Aceselfㅤㅤㅤㅤㅤ | AB63: =COUNTIF($B$234:$B$333,AA63) -> 1 | AC63: =SUMIF($B$234:$B$333,AA63,$E$234:$E$333) -> 824 | AD63: =SUMIF($B$234:$B$333,AA63,$F$234:$F$333) -> 37895.76 | AE63: =AD63/$F$334 -> 0.038340987 | AG63: MOQIULI | AH63: =COUNTIF($C$234:$C$333,AG63) -> 4 | AI63: =SUMIF($C$234:$C$333,AG63,$E$234:$E$333) -> 2178 | AJ63: =SUMIF($C$234:$C$333,AG63,$F$234:$F$333) -> 36448.77 | AK63: =AJ63/$F$334 -> 0.036876997
A64: =_xlfn.DISPIMG("ID_C610484858B34BD29F18685F9AF88DA2",1) -> =DISPIMG("ID_C610484858B34BD29F18685F9AF88DA2",1) | AA64: KIKIIKE | AB64: =COUNTIF($B$234:$B$333,AA64) -> 2 | AC64: =SUMIF($B$234:$B$333,AA64,$E$234:$E$333) -> 1054 | AD64: =SUMIF($B$234:$B$333,AA64,$F$234:$F$333) -> 29855.46 | AE64: =AD64/$F$334 -> 0.030206224 | AG64: KIKIIKE-INC | AH64: =COUNTIF($C$234:$C$333,AG64) -> 2 | AI64: =SUMIF($C$234:$C$333,AG64,$E$234:$E$333) -> 1054 | AJ64: =SUMIF($C$234:$C$333,AG64,$F$234:$F$333) -> 29855.46 | AK64: =AJ64/$F$334 -> 0.030206224
AA65: Giftasy | AB65: =COUNTIF($B$234:$B$333,AA65) -> 3 | AC65: =SUMIF($B$234:$B$333,AA65,$E$234:$E$333) -> 1896 | AD65: =SUMIF($B$234:$B$333,AA65,$F$234:$F$333) -> 29683.59 | AE65: =AD65/$F$334 -> 0.030032335 | AG65: Gintan DE | AH65: =COUNTIF($C$234:$C$333,AG65) -> 1 | AI65: =SUMIF($C$234:$C$333,AG65,$E$234:$E$333) -> 1032 | AJ65: =SUMIF($C$234:$C$333,AG65,$F$234:$F$333) -> 23674.08 | AK65: =AJ65/$F$334 -> 0.023952221
AA66: ROTTOGOON | AB66: =COUNTIF($B$234:$B$333,AA66) -> 1 | AC66: =SUMIF($B$234:$B$333,AA66,$E$234:$E$333) -> 1650 | AD66: =SUMIF($B$234:$B$333,AA66,$F$234:$F$333) -> 28033.5 | AE66: =AD66/$F$334 -> 0.028362858 | AG66: Kitchenville Home &amp; Kitchen | AH66: =COUNTIF($C$234:$C$333,AG66) -> 1 | AI66: =SUMIF($C$234:$C$333,AG66,$E$234:$E$333) -> 1211 | AJ66: =SUMIF($C$234:$C$333,AG66,$F$234:$F$333) -> 21785.89 | AK66: =AJ66/$F$334 -> 0.022041847
AA67: Joseph Joseph | AB67: =COUNTIF($B$234:$B$333,AA67) -> 2 | AC67: =SUMIF($B$234:$B$333,AA67,$E$234:$E$333) -> 585 | AD67: =SUMIF($B$234:$B$333,AA67,$F$234:$F$333) -> 24864.54 | AE67: =AD67/$F$334 -> 0.025156667 | AG67: EDELHAUS DE | AH67: =COUNTIF($C$234:$C$333,AG67) -> 2 | AI67: =SUMIF($C$234:$C$333,AG67,$E$234:$E$333) -> 459 | AJ67: =SUMIF($C$234:$C$333,AG67,$F$234:$F$333) -> 21497.05 | AK67: =AJ67/$F$334 -> 0.021749613
AA71: 国家/地区 | AB71: 商品数 | AC71: 月销量 | AD71: 月销售额€ | AE71: 预估销售额占比
A72: =_xlfn.DISPIMG("ID_AD02DE2458004063B2AB959888551888",1) -> =DISPIMG("ID_AD02DE2458004063B2AB959888551888",1)
AA73: 中国 | AB73: =COUNTIF($D$234:$D$333,AA73) -> 47 | AC73: =SUMIF($D$234:$D$333,AA73,$E$234:$E$333) -> 16885 | AD73: =SUMIF($D$234:$D$333,AA73,$F$234:$F$333) -> 408206.37 | AE73: =AD73/$F$334 -> 0.41300228
AA74: 未知 | AB74: =COUNTIF($D$234:$D$333,AA74) -> 27 | AC74: =SUMIF($D$234:$D$333,AA74,$E$234:$E$333) -> 16948 | AD74: =SUMIF($D$234:$D$333,AA74,$F$234:$F$333) -> 245932.13 | AE74: =AD74/$F$334 -> 0.24882152
...

Sheet ②谷歌趋势
A1: 德国切菜板｜产品生命周期与搜索趋势 | B1: 德国切菜板｜产品生命周期与搜索趋势 | C1: 德国切菜板｜产品生命周期与搜索趋势 | D1: 德国切菜板｜产品生命周期与搜索趋势 | E1: 德国切菜板｜产品生命周期与搜索趋势 | F1: 德国切菜板｜产品生命周期与搜索趋势 | G1: 德国切菜板｜产品生命周期与搜索趋势 | H1: 德国切菜板｜产品生命周期与搜索趋势 | I1: 德国切菜板｜产品生命周期与搜索趋势 | J1: 德国切菜板｜产品生命周期与搜索趋势 | K1: 德国切菜板｜产品生命周期与搜索趋势 | L1: 德国切菜板｜产品生命周期与搜索趋势 | M1: 德国切菜板｜产品生命周期与搜索趋势 | N1: 德国切菜板｜产品生命周期与搜索趋势 | O1: 德国切菜板｜产品生命周期与搜索趋势 | P1: 德国切菜板｜产品生命周期与搜索趋势 | Q1: 德国切菜板｜产品生命周期与搜索趋势 | R1: 德国切菜板｜产品生命周期与搜索趋势 | S1: 德国切菜板｜产品生命周期与搜索趋势 | T1: 德国切菜板｜产品生命周期与搜索趋势 | U1: 德国切菜板｜产品生命周期与搜索趋势 | V1: 德国切菜板｜产品生命周期与搜索趋势 | W1: 德国切菜板｜产品生命周期与搜索趋势 | X1: 德国切菜板｜产品生命周期与搜索趋势
A2: 1. 产品季节性｜德国·过去12个月 | B2: 1. 产品季节性｜德国·过去12个月 | C2: 1. 产品季节性｜德国·过去12个月 | D2: 1. 产品季节性｜德国·过去12个月 | E2: 1. 产品季节性｜德国·过去12个月 | F2: 1. 产品季节性｜德国·过去12个月 | G2: 1. 产品季节性｜德国·过去12个月 | H2: 1. 产品季节性｜德国·过去12个月 | I2: 1. 产品季节性｜德国·过去12个月 | J2: 1. 产品季节性｜德国·过去12个月 | K2: 1. 产品季节性｜德国·过去12个月 | L2: 1. 产品季节性｜德国·过去12个月 | M2: 3. 产品流行区域｜德国·过去12个月 | N2: 3. 产品流行区域｜德国·过去12个月 | O2: 3. 产品流行区域｜德国·过去12个月 | P2: 3. 产品流行区域｜德国·过去12个月 | Q2: 3. 产品流行区域｜德国·过去12个月 | R2: 3. 产品流行区域｜德国·过去12个月 | S2: 3. 产品流行区域｜德国·过去12个月 | T2: 3. 产品流行区域｜德国·过去12个月 | U2: 3. 产品流行区域｜德国·过去12个月 | V2: 3. 产品流行区域｜德国·过去12个月 | W2: 3. 产品流行区域｜德国·过去12个月 | X2: 3. 产品流行区域｜德国·过去12个月 | Y2: 数据源：Google Trends（谷歌趋势）官网 截图日期：2026-09-11 地区：德国；所有类别；网页搜索 关键词： schneidebrett（切菜板） schneidebrett holz（木切菜板） 0—100是相对搜索热度，不是搜索次数或销量。关键词范围不完全等于Amazon切菜板类目。 【地区数据】 卖家精灵接口本次没有返回地区分布。本表的德国地图、州排名来自谷歌官网，不能用接口趋势数据代替。
A3: 1. 产品季节性｜德国·过去12个月 | B3: 1. 产品季节性｜德国·过去12个月 | C3: 1. 产品季节性｜德国·过去12个月 | D3: 1. 产品季节性｜德国·过去12个月 | E3: 1. 产品季节性｜德国·过去12个月 | F3: 1. 产品季节性｜德国·过去12个月 | G3: 1. 产品季节性｜德国·过去12个月 | H3: 1. 产品季节性｜德国·过去12个月 | I3: 1. 产品季节性｜德国·过去12个月 | J3: 1. 产品季节性｜德国·过去12个月 | K3: 1. 产品季节性｜德国·过去12个月 | L3: 1. 产品季节性｜德国·过去12个月 | M3: 3. 产品流行区域｜德国·过去12个月 | N3: 3. 产品流行区域｜德国·过去12个月 | O3: 3. 产品流行区域｜德国·过去12个月 | P3: 3. 产品流行区域｜德国·过去12个月 | Q3: 3. 产品流行区域｜德国·过去12个月 | R3: 3. 产品流行区域｜德国·过去12个月 | S3: 3. 产品流行区域｜德国·过去12个月 | T3: 3. 产品流行区域｜德国·过去12个月 | U3: 3. 产品流行区域｜德国·过去12个月 | V3: 3. 产品流行区域｜德国·过去12个月 | W3: 3. 产品流行区域｜德国·过去12个月 | X3: 3. 产品流行区域｜德国·过去12个月
A16: 近一年两个词均在2025年11月下旬至12月走高。主词12月7日所在周达到100，木切菜板词12月14日所在周达到21（同图统一尺度）。2026年多数非年末周仍有持续搜索，呈全年需求叠加年末旺季。 | B16: 近一年两个词均在2025年11月下旬至12月走高。主词12月7日所在周达到100，木切菜板词12月14日所在周达到21（同图统一尺度）。2026年多数非年末周仍有持续搜索，呈全年需求叠加年末旺季。 | C16: 近一年两个词均在2025年11月下旬至12月走高。主词12月7日所在周达到100，木切菜板词12月14日所在周达到21（同图统一尺度）。2026年多数非年末周仍有持续搜索，呈全年需求叠加年末旺季。 | D16: 近一年两个词均在2025年11月下旬至12月走高。主词12月7日所在周达到100，木切菜板词12月14日所在周达到21（同图统一尺度）。2026年多数非年末周仍有持续搜索，呈全年需求叠加年末旺季。 | E16: 近一年两个词均在2025年11月下旬至12月走高。主词12月7日所在周达到100，木切菜板词12月14日所在周达到21（同图统一尺度）。2026年多数非年末周仍有持续搜索，呈全年需求叠加年末旺季。 | F16: 近一年两个词均在2025年11月下旬至12月走高。主词12月7日所在周达到100，木切菜板词12月14日所在周达到21（同图统一尺度）。2026年多数非年末周仍有持续搜索，呈全年需求叠加年末旺季。 | G16: 近一年两个词均在2025年11月下旬至12月走高。主词12月7日所在周达到100，木切菜板词12月14日所在周达到21（同图统一尺度）。2026年多数非年末周仍有持续搜索，呈全年需求叠加年末旺季。 | H16: 近一年两个词均在2025年11月下旬至12月走高。主词12月7日所在周达到100，木切菜板词12月14日所在周达到21（同图统一尺度）。2026年多数非年末周仍有持续搜索，呈全年需求叠加年末旺季。 | I16: 近一年两个词均在2025年11月下旬至12月走高。主词12月7日所在周达到100，木切菜板词12月14日所在周达到21（同图统一尺度）。2026年多数非年末周仍有持续搜索，呈全年需求叠加年末旺季。 | J16: 近一年两个词均在2025年11月下旬至12月走高。主词12月7日所在周达到100，木切菜板词12月14日所在周达到21（同图统一尺度）。2026年多数非年末周仍有持续搜索，呈全年需求叠加年末旺季。 | K16: 近一年两个词均在2025年11月下旬至12月走高。主词12月7日所在周达到100，木切菜板词12月14日所在周达到21（同图统一尺度）。2026年多数非年末周仍有持续搜索，呈全年需求叠加年末旺季。 | L16: 近一年两个词均在2025年11月下旬至12月走高。主词12月7日所在周达到100，木切菜板词12月14日所在周达到21（同图统一尺度）。2026年多数非年末周仍有持续搜索，呈全年需求叠加年末旺季。
A17: 近一年两个词均在2025年11月下旬至12月走高。主词12月7日所在周达到100，木切菜板词12月14日所在周达到21（同图统一尺度）。2026年多数非年末周仍有持续搜索，呈全年需求叠加年末旺季。 | B17: 近一年两个词均在2025年11月下旬至12月走高。主词12月7日所在周达到100，木切菜板词12月14日所在周达到21（同图统一尺度）。2026年多数非年末周仍有持续搜索，呈全年需求叠加年末旺季。 | C17: 近一年两个词均在2025年11月下旬至12月走高。主词12月7日所在周达到100，木切菜板词12月14日所在周达到21（同图统一尺度）。2026年多数非年末周仍有持续搜索，呈全年需求叠加年末旺季。 | D17: 近一年两个词均在2025年11月下旬至12月走高。主词12月7日所在周达到100，木切菜板词12月14日所在周达到21（同图统一尺度）。2026年多数非年末周仍有持续搜索，呈全年需求叠加年末旺季。 | E17: 近一年两个词均在2025年11月下旬至12月走高。主词12月7日所在周达到100，木切菜板词12月14日所在周达到21（同图统一尺度）。2026年多数非年末周仍有持续搜索，呈全年需求叠加年末旺季。 | F17: 近一年两个词均在2025年11月下旬至12月走高。主词12月7日所在周达到100，木切菜板词12月14日所在周达到21（同图统一尺度）。2026年多数非年末周仍有持续搜索，呈全年需求叠加年末旺季。 | G17: 近一年两个词均在2025年11月下旬至12月走高。主词12月7日所在周达到100，木切菜板词12月14日所在周达到21（同图统一尺度）。2026年多数非年末周仍有持续搜索，呈全年需求叠加年末旺季。 | H17: 近一年两个词均在2025年11月下旬至12月走高。主词12月7日所在周达到100，木切菜板词12月14日所在周达到21（同图统一尺度）。2026年多数非年末周仍有持续搜索，呈全年需求叠加年末旺季。 | I17: 近一年两个词均在2025年11月下旬至12月走高。主词12月7日所在周达到100，木切菜板词12月14日所在周达到21（同图统一尺度）。2026年多数非年末周仍有持续搜索，呈全年需求叠加年末旺季。 | J17: 近一年两个词均在2025年11月下旬至12月走高。主词12月7日所在周达到100，木切菜板词12月14日所在周达到21（同图统一尺度）。2026年多数非年末周仍有持续搜索，呈全年需求叠加年末旺季。 | K17: 近一年两个词均在2025年11月下旬至12月走高。主词12月7日所在周达到100，木切菜板词12月14日所在周达到21（同图统一尺度）。2026年多数非年末周仍有持续搜索，呈全年需求叠加年末旺季。 | L17: 近一年两个词均在2025年11月下旬至12月走高。主词12月7日所在周达到100，木切菜板词12月14日所在周达到21（同图统一尺度）。2026年多数非年末周仍有持续搜索，呈全年需求叠加年末旺季。
A18: 近一年两个词均在2025年11月下旬至12月走高。主词12月7日所在周达到100，木切菜板词12月14日所在周达到21（同图统一尺度）。2026年多数非年末周仍有持续搜索，呈全年需求叠加年末旺季。 | B18: 近一年两个词均在2025年11月下旬至12月走高。主词12月7日所在周达到100，木切菜板词12月14日所在周达到21（同图统一尺度）。2026年多数非年末周仍有持续搜索，呈全年需求叠加年末旺季。 | C18: 近一年两个词均在2025年11月下旬至12月走高。主词12月7日所在周达到100，木切菜板词12月14日所在周达到21（同图统一尺度）。2026年多数非年末周仍有持续搜索，呈全年需求叠加年末旺季。 | D18: 近一年两个词均在2025年11月下旬至12月走高。主词12月7日所在周达到100，木切菜板词12月14日所在周达到21（同图统一尺度）。2026年多数非年末周仍有持续搜索，呈全年需求叠加年末旺季。 | E18: 近一年两个词均在2025年11月下旬至12月走高。主词12月7日所在周达到100，木切菜板词12月14日所在周达到21（同图统一尺度）。2026年多数非年末周仍有持续搜索，呈全年需求叠加年末旺季。 | F18: 近一年两个词均在2025年11月下旬至12月走高。主词12月7日所在周达到100，木切菜板词12月14日所在周达到21（同图统一尺度）。2026年多数非年末周仍有持续搜索，呈全年需求叠加年末旺季。 | G18: 近一年两个词均在2025年11月下旬至12月走高。主词12月7日所在周达到100，木切菜板词12月14日所在周达到21（同图统一尺度）。2026年多数非年末周仍有持续搜索，呈全年需求叠加年末旺季。 | H18: 近一年两个词均在2025年11月下旬至12月走高。主词12月7日所在周达到100，木切菜板词12月14日所在周达到21（同图统一尺度）。2026年多数非年末周仍有持续搜索，呈全年需求叠加年末旺季。 | I18: 近一年两个词均在2025年11月下旬至12月走高。主词12月7日所在周达到100，木切菜板词12月14日所在周达到21（同图统一尺度）。2026年多数非年末周仍有持续搜索，呈全年需求叠加年末旺季。 | J18: 近一年两个词均在2025年11月下旬至12月走高。主词12月7日所在周达到100，木切菜板词12月14日所在周达到21（同图统一尺度）。2026年多数非年末周仍有持续搜索，呈全年需求叠加年末旺季。 | K18: 近一年两个词均在2025年11月下旬至12月走高。主词12月7日所在周达到100，木切菜板词12月14日所在周达到21（同图统一尺度）。2026年多数非年末周仍有持续搜索，呈全年需求叠加年末旺季。 | L18: 近一年两个词均在2025年11月下旬至12月走高。主词12月7日所在周达到100，木切菜板词12月14日所在周达到21（同图统一尺度）。2026年多数非年末周仍有持续搜索，呈全年需求叠加年末旺季。
A19: 近一年两个词均在2025年11月下旬至12月走高。主词12月7日所在周达到100，木切菜板词12月14日所在周达到21（同图统一尺度）。2026年多数非年末周仍有持续搜索，呈全年需求叠加年末旺季。 | B19: 近一年两个词均在2025年11月下旬至12月走高。主词12月7日所在周达到100，木切菜板词12月14日所在周达到21（同图统一尺度）。2026年多数非年末周仍有持续搜索，呈全年需求叠加年末旺季。 | C19: 近一年两个词均在2025年11月下旬至12月走高。主词12月7日所在周达到100，木切菜板词12月14日所在周达到21（同图统一尺度）。2026年多数非年末周仍有持续搜索，呈全年需求叠加年末旺季。 | D19: 近一年两个词均在2025年11月下旬至12月走高。主词12月7日所在周达到100，木切菜板词12月14日所在周达到21（同图统一尺度）。2026年多数非年末周仍有持续搜索，呈全年需求叠加年末旺季。 | E19: 近一年两个词均在2025年11月下旬至12月走高。主词12月7日所在周达到100，木切菜板词12月14日所在周达到21（同图统一尺度）。2026年多数非年末周仍有持续搜索，呈全年需求叠加年末旺季。 | F19: 近一年两个词均在2025年11月下旬至12月走高。主词12月7日所在周达到100，木切菜板词12月14日所在周达到21（同图统一尺度）。2026年多数非年末周仍有持续搜索，呈全年需求叠加年末旺季。 | G19: 近一年两个词均在2025年11月下旬至12月走高。主词12月7日所在周达到100，木切菜板词12月14日所在周达到21（同图统一尺度）。2026年多数非年末周仍有持续搜索，呈全年需求叠加年末旺季。 | H19: 近一年两个词均在2025年11月下旬至12月走高。主词12月7日所在周达到100，木切菜板词12月14日所在周达到21（同图统一尺度）。2026年多数非年末周仍有持续搜索，呈全年需求叠加年末旺季。 | I19: 近一年两个词均在2025年11月下旬至12月走高。主词12月7日所在周达到100，木切菜板词12月14日所在周达到21（同图统一尺度）。2026年多数非年末周仍有持续搜索，呈全年需求叠加年末旺季。 | J19: 近一年两个词均在2025年11月下旬至12月走高。主词12月7日所在周达到100，木切菜板词12月14日所在周达到21（同图统一尺度）。2026年多数非年末周仍有持续搜索，呈全年需求叠加年末旺季。 | K19: 近一年两个词均在2025年11月下旬至12月走高。主词12月7日所在周达到100，木切菜板词12月14日所在周达到21（同图统一尺度）。2026年多数非年末周仍有持续搜索，呈全年需求叠加年末旺季。 | L19: 近一年两个词均在2025年11月下旬至12月走高。主词12月7日所在周达到100，木切菜板词12月14日所在周达到21（同图统一尺度）。2026年多数非年末周仍有持续搜索，呈全年需求叠加年末旺季。
A20: 近一年两个词均在2025年11月下旬至12月走高。主词12月7日所在周达到100，木切菜板词12月14日所在周达到21（同图统一尺度）。2026年多数非年末周仍有持续搜索，呈全年需求叠加年末旺季。 | B20: 近一年两个词均在2025年11月下旬至12月走高。主词12月7日所在周达到100，木切菜板词12月14日所在周达到21（同图统一尺度）。2026年多数非年末周仍有持续搜索，呈全年需求叠加年末旺季。 | C20: 近一年两个词均在2025年11月下旬至12月走高。主词12月7日所在周达到100，木切菜板词12月14日所在周达到21（同图统一尺度）。2026年多数非年末周仍有持续搜索，呈全年需求叠加年末旺季。 | D20: 近一年两个词均在2025年11月下旬至12月走高。主词12月7日所在周达到100，木切菜板词12月14日所在周达到21（同图统一尺度）。2026年多数非年末周仍有持续搜索，呈全年需求叠加年末旺季。 | E20: 近一年两个词均在2025年11月下旬至12月走高。主词12月7日所在周达到100，木切菜板词12月14日所在周达到21（同图统一尺度）。2026年多数非年末周仍有持续搜索，呈全年需求叠加年末旺季。 | F20: 近一年两个词均在2025年11月下旬至12月走高。主词12月7日所在周达到100，木切菜板词12月14日所在周达到21（同图统一尺度）。2026年多数非年末周仍有持续搜索，呈全年需求叠加年末旺季。 | G20: 近一年两个词均在2025年11月下旬至12月走高。主词12月7日所在周达到100，木切菜板词12月14日所在周达到21（同图统一尺度）。2026年多数非年末周仍有持续搜索，呈全年需求叠加年末旺季。 | H20: 近一年两个词均在2025年11月下旬至12月走高。主词12月7日所在周达到100，木切菜板词12月14日所在周达到21（同图统一尺度）。2026年多数非年末周仍有持续搜索，呈全年需求叠加年末旺季。 | I20: 近一年两个词均在2025年11月下旬至12月走高。主词12月7日所在周达到100，木切菜板词12月14日所在周达到21（同图统一尺度）。2026年多数非年末周仍有持续搜索，呈全年需求叠加年末旺季。 | J20: 近一年两个词均在2025年11月下旬至12月走高。主词12月7日所在周达到100，木切菜板词12月14日所在周达到21（同图统一尺度）。2026年多数非年末周仍有持续搜索，呈全年需求叠加年末旺季。 | K20: 近一年两个词均在2025年11月下旬至12月走高。主词12月7日所在周达到100，木切菜板词12月14日所在周达到21（同图统一尺度）。2026年多数非年末周仍有持续搜索，呈全年需求叠加年末旺季。 | L20: 近一年两个词均在2025年11月下旬至12月走高。主词12月7日所在周达到100，木切菜板词12月14日所在周达到21（同图统一尺度）。2026年多数非年末周仍有持续搜索，呈全年需求叠加年末旺季。
A21: 近一年两个词均在2025年11月下旬至12月走高。主词12月7日所在周达到100，木切菜板词12月14日所在周达到21（同图统一尺度）。2026年多数非年末周仍有持续搜索，呈全年需求叠加年末旺季。 | B21: 近一年两个词均在2025年11月下旬至12月走高。主词12月7日所在周达到100，木切菜板词12月14日所在周达到21（同图统一尺度）。2026年多数非年末周仍有持续搜索，呈全年需求叠加年末旺季。 | C21: 近一年两个词均在2025年11月下旬至12月走高。主词12月7日所在周达到100，木切菜板词12月14日所在周达到21（同图统一尺度）。2026年多数非年末周仍有持续搜索，呈全年需求叠加年末旺季。 | D21: 近一年两个词均在2025年11月下旬至12月走高。主词12月7日所在周达到100，木切菜板词12月14日所在周达到21（同图统一尺度）。2026年多数非年末周仍有持续搜索，呈全年需求叠加年末旺季。 | E21: 近一年两个词均在2025年11月下旬至12月走高。主词12月7日所在周达到100，木切菜板词12月14日所在周达到21（同图统一尺度）。2026年多数非年末周仍有持续搜索，呈全年需求叠加年末旺季。 | F21: 近一年两个词均在2025年11月下旬至12月走高。主词12月7日所在周达到100，木切菜板词12月14日所在周达到21（同图统一尺度）。2026年多数非年末周仍有持续搜索，呈全年需求叠加年末旺季。 | G21: 近一年两个词均在2025年11月下旬至12月走高。主词12月7日所在周达到100，木切菜板词12月14日所在周达到21（同图统一尺度）。2026年多数非年末周仍有持续搜索，呈全年需求叠加年末旺季。 | H21: 近一年两个词均在2025年11月下旬至12月走高。主词12月7日所在周达到100，木切菜板词12月14日所在周达到21（同图统一尺度）。2026年多数非年末周仍有持续搜索，呈全年需求叠加年末旺季。 | I21: 近一年两个词均在2025年11月下旬至12月走高。主词12月7日所在周达到100，木切菜板词12月14日所在周达到21（同图统一尺度）。2026年多数非年末周仍有持续搜索，呈全年需求叠加年末旺季。 | J21: 近一年两个词均在2025年11月下旬至12月走高。主词12月7日所在周达到100，木切菜板词12月14日所在周达到21（同图统一尺度）。2026年多数非年末周仍有持续搜索，呈全年需求叠加年末旺季。 | K21: 近一年两个词均在2025年11月下旬至12月走高。主词12月7日所在周达到100，木切菜板词12月14日所在周达到21（同图统一尺度）。2026年多数非年末周仍有持续搜索，呈全年需求叠加年末旺季。 | L21: 近一年两个词均在2025年11月下旬至12月走高。主词12月7日所在周达到100，木切菜板词12月14日所在周达到21（同图统一尺度）。2026年多数非年末周仍有持续搜索，呈全年需求叠加年末旺季。
A22: 2. 产品生命周期｜德国·过去5年 | B22: 2. 产品生命周期｜德国·过去5年 | C22: 2. 产品生命周期｜德国·过去5年 | D22: 2. 产品生命周期｜德国·过去5年 | E22: 2. 产品生命周期｜德国·过去5年 | F22: 2. 产品生命周期｜德国·过去5年 | G22: 2. 产品生命周期｜德国·过去5年 | H22: 2. 产品生命周期｜德国·过去5年 | I22: 2. 产品生命周期｜德国·过去5年 | J22: 2. 产品生命周期｜德国·过去5年 | K22: 2. 产品生命周期｜德国·过去5年 | L22: 2. 产品生命周期｜德国·过去5年 | M22: 4. 总结 | N22: 4. 总结 | O22: 4. 总结 | P22: 4. 总结 | Q22: 4. 总结 | R22: 4. 总结 | S22: 4. 总结 | T22: 4. 总结 | U22: 4. 总结 | V22: 4. 总结 | W22: 4. 总结 | X22: 4. 总结 | Y22: 【接口实测｜2026-09-12】 两个词各返回262条周数据；主词另有61条月数据。 【与官网的区别】 ①本次接口截至8月9日，官网到9月6日，慢4周。 ②走势接近，数值略有差别。主词257个重叠周，平均差0.67点，最大差7点。 ③例：2025年12月7日两边都是100；2026年8月9日接口64、官网57。 ④每个词单独算0—100，不能跨词比较需求大小。 ⑤没有地区分布；月数据的完整性和汇总方式未说明。 【用法】 批量初筛用接口；近期变化、两词对比和地区分布看官网。
A23: 2. 产品生命周期｜德国·过去5年 | B23: 2. 产品生命周期｜德国·过去5年 | C23: 2. 产品生命周期｜德国·过去5年 | D23: 2. 产品生命周期｜德国·过去5年 | E23: 2. 产品生命周期｜德国·过去5年 | F23: 2. 产品生命周期｜德国·过去5年 | G23: 2. 产品生命周期｜德国·过去5年 | H23: 2. 产品生命周期｜德国·过去5年 | I23: 2. 产品生命周期｜德国·过去5年 | J23: 2. 产品生命周期｜德国·过去5年 | K23: 2. 产品生命周期｜德国·过去5年 | L23: 2. 产品生命周期｜德国·过去5年 | M23: 4. 总结 | N23: 4. 总结 | O23: 4. 总结 | P23: 4. 总结 | Q23: 4. 总结 | R23: 4. 总结 | S23: 4. 总结 | T23: 4. 总结 | U23: 4. 总结 | V23: 4. 总结 | W23: 4. 总结 | X23: 4. 总结
M24: 【总结】 1）季节性：两个词的年末高峰同步，备货与推广应提前于11—12月；不能把平时有需求写成“无季节性”。 2）五年走势：主词2021—2025年各年最高周均在12月；对应指数71、68、66、94、100。2024—2025年的峰值高于前三年，但不是五年逐年增长。 3）地区：主词相对热度前三为汉堡100、巴伐利亚（网页译“拜仁”）96、巴登-符腾堡94；木切菜板为汉堡100、巴登-符腾堡91、萨克森91。地区指数不代表订单或购买力。 【趋势表明】 切菜板属于持续有搜索需求、年末旺季明显的成熟需求。近两年主词旺季热度抬升，值得继续研究；是否能带来新品成交，仍应结合第一表的竞争与销量数据。 | N24: 【总结】 1）季节性：两个词的年末高峰同步，备货与推广应提前于11—12月；不能把平时有需求写成“无季节性”。 2）五年走势：主词2021—2025年各年最高周均在12月；对应指数71、68、66、94、100。2024—2025年的峰值高于前三年，但不是五年逐年增长。 3）地区：主词相对热度前三为汉堡100、巴伐利亚（网页译“拜仁”）96、巴登-符腾堡94；木切菜板为汉堡100、巴登-符腾堡91、萨克森91。地区指数不代表订单或购买力。 【趋势表明】 切菜板属于持续有搜索需求、年末旺季明显的成熟需求。近两年主词旺季热度抬升，值得继续研究；是否能带来新品成交，仍应结合第一表的竞争与销量数据。 | O24: 【总结】 1）季节性：两个词的年末高峰同步，备货与推广应提前于11—12月；不能把平时有需求写成“无季节性”。 2）五年走势：主词2021—2025年各年最高周均在12月；对应指数71、68、66、94、100。2024—2025年的峰值高于前三年，但不是五年逐年增长。 3）地区：主词相对热度前三为汉堡100、巴伐利亚（网页译“拜仁”）96、巴登-符腾堡94；木切菜板为汉堡100、巴登-符腾堡91、萨克森91。地区指数不代表订单或购买力。 【趋势表明】 切菜板属于持续有搜索需求、年末旺季明显的成熟需求。近两年主词旺季热度抬升，值得继续研究；是否能带来新品成交，仍应结合第一表的竞争与销量数据。 | P24: 【总结】 1）季节性：两个词的年末高峰同步，备货与推广应提前于11—12月；不能把平时有需求写成“无季节性”。 2）五年走势：主词2021—2025年各年最高周均在12月；对应指数71、68、66、94、100。2024—2025年的峰值高于前三年，但不是五年逐年增长。 3）地区：主词相对热度前三为汉堡100、巴伐利亚（网页译“拜仁”）96、巴登-符腾堡94；木切菜板为汉堡100、巴登-符腾堡91、萨克森91。地区指数不代表订单或购买力。 【趋势表明】 切菜板属于持续有搜索需求、年末旺季明显的成熟需求。近两年主词旺季热度抬升，值得继续研究；是否能带来新品成交，仍应结合第一表的竞争与销量数据。 | Q24: 【总结】 1）季节性：两个词的年末高峰同步，备货与推广应提前于11—12月；不能把平时有需求写成“无季节性”。 2）五年走势：主词2021—2025年各年最高周均在12月；对应指数71、68、66、94、100。2024—2025年的峰值高于前三年，但不是五年逐年增长。 3）地区：主词相对热度前三为汉堡100、巴伐利亚（网页译“拜仁”）96、巴登-符腾堡94；木切菜板为汉堡100、巴登-符腾堡91、萨克森91。地区指数不代表订单或购买力。 【趋势表明】 切菜板属于持续有搜索需求、年末旺季明显的成熟需求。近两年主词旺季热度抬升，值得继续研究；是否能带来新品成交，仍应结合第一表的竞争与销量数据。 | R24: 【总结】 1）季节性：两个词的年末高峰同步，备货与推广应提前于11—12月；不能把平时有需求写成“无季节性”。 2）五年走势：主词2021—2025年各年最高周均在12月；对应指数71、68、66、94、100。2024—2025年的峰值高于前三年，但不是五年逐年增长。 3）地区：主词相对热度前三为汉堡100、巴伐利亚（网页译“拜仁”）96、巴登-符腾堡94；木切菜板为汉堡100、巴登-符腾堡91、萨克森91。地区指数不代表订单或购买力。 【趋势表明】 切菜板属于持续有搜索需求、年末旺季明显的成熟需求。近两年主词旺季热度抬升，值得继续研究；是否能带来新品成交，仍应结合第一表的竞争与销量数据。 | S24: 【总结】 1）季节性：两个词的年末高峰同步，备货与推广应提前于11—12月；不能把平时有需求写成“无季节性”。 2）五年走势：主词2021—2025年各年最高周均在12月；对应指数71、68、66、94、100。2024—2025年的峰值高于前三年，但不是五年逐年增长。 3）地区：主词相对热度前三为汉堡100、巴伐利亚（网页译“拜仁”）96、巴登-符腾堡94；木切菜板为汉堡100、巴登-符腾堡91、萨克森91。地区指数不代表订单或购买力。 【趋势表明】 切菜板属于持续有搜索需求、年末旺季明显的成熟需求。近两年主词旺季热度抬升，值得继续研究；是否能带来新品成交，仍应结合第一表的竞争与销量数据。 | T24: 【总结】 1）季节性：两个词的年末高峰同步，备货与推广应提前于11—12月；不能把平时有需求写成“无季节性”。 2）五年走势：主词2021—2025年各年最高周均在12月；对应指数71、68、66、94、100。2024—2025年的峰值高于前三年，但不是五年逐年增长。 3）地区：主词相对热度前三为汉堡100、巴伐利亚（网页译“拜仁”）96、巴登-符腾堡94；木切菜板为汉堡100、巴登-符腾堡91、萨克森91。地区指数不代表订单或购买力。 【趋势表明】 切菜板属于持续有搜索需求、年末旺季明显的成熟需求。近两年主词旺季热度抬升，值得继续研究；是否能带来新品成交，仍应结合第一表的竞争与销量数据。 | U24: 【总结】 1）季节性：两个词的年末高峰同步，备货与推广应提前于11—12月；不能把平时有需求写成“无季节性”。 2）五年走势：主词2021—2025年各年最高周均在12月；对应指数71、68、66、94、100。2024—2025年的峰值高于前三年，但不是五年逐年增长。 3）地区：主词相对热度前三为汉堡100、巴伐利亚（网页译“拜仁”）96、巴登-符腾堡94；木切菜板为汉堡100、巴登-符腾堡91、萨克森91。地区指数不代表订单或购买力。 【趋势表明】 切菜板属于持续有搜索需求、年末旺季明显的成熟需求。近两年主词旺季热度抬升，值得继续研究；是否能带来新品成交，仍应结合第一表的竞争与销量数据。 | V24: 【总结】 1）季节性：两个词的年末高峰同步，备货与推广应提前于11—12月；不能把平时有需求写成“无季节性”。 2）五年走势：主词2021—2025年各年最高周均在12月；对应指数71、68、66、94、100。2024—2025年的峰值高于前三年，但不是五年逐年增长。 3）地区：主词相对热度前三为汉堡100、巴伐利亚（网页译“拜仁”）96、巴登-符腾堡94；木切菜板为汉堡100、巴登-符腾堡91、萨克森91。地区指数不代表订单或购买力。 【趋势表明】 切菜板属于持续有搜索需求、年末旺季明显的成熟需求。近两年主词旺季热度抬升，值得继续研究；是否能带来新品成交，仍应结合第一表的竞争与销量数据。 | W24: 【总结】 1）季节性：两个词的年末高峰同步，备货与推广应提前于11—12月；不能把平时有需求写成“无季节性”。 2）五年走势：主词2021—2025年各年最高周均在12月；对应指数71、68、66、94、100。2024—2025年的峰值高于前三年，但不是五年逐年增长。 3）地区：主词相对热度前三为汉堡100、巴伐利亚（网页译“拜仁”）96、巴登-符腾堡94；木切菜板为汉堡100、巴登-符腾堡91、萨克森91。地区指数不代表订单或购买力。 【趋势表明】 切菜板属于持续有搜索需求、年末旺季明显的成熟需求。近两年主词旺季热度抬升，值得继续研究；是否能带来新品成交，仍应结合第一表的竞争与销量数据。 | X24: 【总结】 1）季节性：两个词的年末高峰同步，备货与推广应提前于11—12月；不能把平时有需求写成“无季节性”。 2）五年走势：主词2021—2025年各年最高周均在12月；对应指数71、68、66、94、100。2024—2025年的峰值高于前三年，但不是五年逐年增长。 3）地区：主词相对热度前三为汉堡100、巴伐利亚（网页译“拜仁”）96、巴登-符腾堡94；木切菜板为汉堡100、巴登-符腾堡91、萨克森91。地区指数不代表订单或购买力。 【趋势表明】 切菜板属于持续有搜索需求、年末旺季明显的成熟需求。近两年主词旺季热度抬升，值得继续研究；是否能带来新品成交，仍应结合第一表的竞争与销量数据。
M25: 【总结】 1）季节性：两个词的年末高峰同步，备货与推广应提前于11—12月；不能把平时有需求写成“无季节性”。 2）五年走势：主词2021—2025年各年最高周均在12月；对应指数71、68、66、94、100。2024—2025年的峰值高于前三年，但不是五年逐年增长。 3）地区：主词相对热度前三为汉堡100、巴伐利亚（网页译“拜仁”）96、巴登-符腾堡94；木切菜板为汉堡100、巴登-符腾堡91、萨克森91。地区指数不代表订单或购买力。 【趋势表明】 切菜板属于持续有搜索需求、年末旺季明显的成熟需求。近两年主词旺季热度抬升，值得继续研究；是否能带来新品成交，仍应结合第一表的竞争与销量数据。 | N25: 【总结】 1）季节性：两个词的年末高峰同步，备货与推广应提前于11—12月；不能把平时有需求写成“无季节性”。 2）五年走势：主词2021—2025年各年最高周均在12月；对应指数71、68、66、94、100。2024—2025年的峰值高于前三年，但不是五年逐年增长。 3）地区：主词相对热度前三为汉堡100、巴伐利亚（网页译“拜仁”）96、巴登-符腾堡94；木切菜板为汉堡100、巴登-符腾堡91、萨克森91。地区指数不代表订单或购买力。 【趋势表明】 切菜板属于持续有搜索需求、年末旺季明显的成熟需求。近两年主词旺季热度抬升，值得继续研究；是否能带来新品成交，仍应结合第一表的竞争与销量数据。 | O25: 【总结】 1）季节性：两个词的年末高峰同步，备货与推广应提前于11—12月；不能把平时有需求写成“无季节性”。 2）五年走势：主词2021—2025年各年最高周均在12月；对应指数71、68、66、94、100。2024—2025年的峰值高于前三年，但不是五年逐年增长。 3）地区：主词相对热度前三为汉堡100、巴伐利亚（网页译“拜仁”）96、巴登-符腾堡94；木切菜板为汉堡100、巴登-符腾堡91、萨克森91。地区指数不代表订单或购买力。 【趋势表明】 切菜板属于持续有搜索需求、年末旺季明显的成熟需求。近两年主词旺季热度抬升，值得继续研究；是否能带来新品成交，仍应结合第一表的竞争与销量数据。 | P25: 【总结】 1）季节性：两个词的年末高峰同步，备货与推广应提前于11—12月；不能把平时有需求写成“无季节性”。 2）五年走势：主词2021—2025年各年最高周均在12月；对应指数71、68、66、94、100。2024—2025年的峰值高于前三年，但不是五年逐年增长。 3）地区：主词相对热度前三为汉堡100、巴伐利亚（网页译“拜仁”）96、巴登-符腾堡94；木切菜板为汉堡100、巴登-符腾堡91、萨克森91。地区指数不代表订单或购买力。 【趋势表明】 切菜板属于持续有搜索需求、年末旺季明显的成熟需求。近两年主词旺季热度抬升，值得继续研究；是否能带来新品成交，仍应结合第一表的竞争与销量数据。 | Q25: 【总结】 1）季节性：两个词的年末高峰同步，备货与推广应提前于11—12月；不能把平时有需求写成“无季节性”。 2）五年走势：主词2021—2025年各年最高周均在12月；对应指数71、68、66、94、100。2024—2025年的峰值高于前三年，但不是五年逐年增长。 3）地区：主词相对热度前三为汉堡100、巴伐利亚（网页译“拜仁”）96、巴登-符腾堡94；木切菜板为汉堡100、巴登-符腾堡91、萨克森91。地区指数不代表订单或购买力。 【趋势表明】 切菜板属于持续有搜索需求、年末旺季明显的成熟需求。近两年主词旺季热度抬升，值得继续研究；是否能带来新品成交，仍应结合第一表的竞争与销量数据。 | R25: 【总结】 1）季节性：两个词的年末高峰同步，备货与推广应提前于11—12月；不能把平时有需求写成“无季节性”。 2）五年走势：主词2021—2025年各年最高周均在12月；对应指数71、68、66、94、100。2024—2025年的峰值高于前三年，但不是五年逐年增长。 3）地区：主词相对热度前三为汉堡100、巴伐利亚（网页译“拜仁”）96、巴登-符腾堡94；木切菜板为汉堡100、巴登-符腾堡91、萨克森91。地区指数不代表订单或购买力。 【趋势表明】 切菜板属于持续有搜索需求、年末旺季明显的成熟需求。近两年主词旺季热度抬升，值得继续研究；是否能带来新品成交，仍应结合第一表的竞争与销量数据。 | S25: 【总结】 1）季节性：两个词的年末高峰同步，备货与推广应提前于11—12月；不能把平时有需求写成“无季节性”。 2）五年走势：主词2021—2025年各年最高周均在12月；对应指数71、68、66、94、100。2024—2025年的峰值高于前三年，但不是五年逐年增长。 3）地区：主词相对热度前三为汉堡100、巴伐利亚（网页译“拜仁”）96、巴登-符腾堡94；木切菜板为汉堡100、巴登-符腾堡91、萨克森91。地区指数不代表订单或购买力。 【趋势表明】 切菜板属于持续有搜索需求、年末旺季明显的成熟需求。近两年主词旺季热度抬升，值得继续研究；是否能带来新品成交，仍应结合第一表的竞争与销量数据。 | T25: 【总结】 1）季节性：两个词的年末高峰同步，备货与推广应提前于11—12月；不能把平时有需求写成“无季节性”。 2）五年走势：主词2021—2025年各年最高周均在12月；对应指数71、68、66、94、100。2024—2025年的峰值高于前三年，但不是五年逐年增长。 3）地区：主词相对热度前三为汉堡100、巴伐利亚（网页译“拜仁”）96、巴登-符腾堡94；木切菜板为汉堡100、巴登-符腾堡91、萨克森91。地区指数不代表订单或购买力。 【趋势表明】 切菜板属于持续有搜索需求、年末旺季明显的成熟需求。近两年主词旺季热度抬升，值得继续研究；是否能带来新品成交，仍应结合第一表的竞争与销量数据。 | U25: 【总结】 1）季节性：两个词的年末高峰同步，备货与推广应提前于11—12月；不能把平时有需求写成“无季节性”。 2）五年走势：主词2021—2025年各年最高周均在12月；对应指数71、68、66、94、100。2024—2025年的峰值高于前三年，但不是五年逐年增长。 3）地区：主词相对热度前三为汉堡100、巴伐利亚（网页译“拜仁”）96、巴登-符腾堡94；木切菜板为汉堡100、巴登-符腾堡91、萨克森91。地区指数不代表订单或购买力。 【趋势表明】 切菜板属于持续有搜索需求、年末旺季明显的成熟需求。近两年主词旺季热度抬升，值得继续研究；是否能带来新品成交，仍应结合第一表的竞争与销量数据。 | V25: 【总结】 1）季节性：两个词的年末高峰同步，备货与推广应提前于11—12月；不能把平时有需求写成“无季节性”。 2）五年走势：主词2021—2025年各年最高周均在12月；对应指数71、68、66、94、100。2024—2025年的峰值高于前三年，但不是五年逐年增长。 3）地区：主词相对热度前三为汉堡100、巴伐利亚（网页译“拜仁”）96、巴登-符腾堡94；木切菜板为汉堡100、巴登-符腾堡91、萨克森91。地区指数不代表订单或购买力。 【趋势表明】 切菜板属于持续有搜索需求、年末旺季明显的成熟需求。近两年主词旺季热度抬升，值得继续研究；是否能带来新品成交，仍应结合第一表的竞争与销量数据。 | W25: 【总结】 1）季节性：两个词的年末高峰同步，备货与推广应提前于11—12月；不能把平时有需求写成“无季节性”。 2）五年走势：主词2021—2025年各年最高周均在12月；对应指数71、68、66、94、100。2024—2025年的峰值高于前三年，但不是五年逐年增长。 3）地区：主词相对热度前三为汉堡100、巴伐利亚（网页译“拜仁”）96、巴登-符腾堡94；木切菜板为汉堡100、巴登-符腾堡91、萨克森91。地区指数不代表订单或购买力。 【趋势表明】 切菜板属于持续有搜索需求、年末旺季明显的成熟需求。近两年主词旺季热度抬升，值得继续研究；是否能带来新品成交，仍应结合第一表的竞争与销量数据。 | X25: 【总结】 1）季节性：两个词的年末高峰同步，备货与推广应提前于11—12月；不能把平时有需求写成“无季节性”。 2）五年走势：主词2021—2025年各年最高周均在12月；对应指数71、68、66、94、100。2024—2025年的峰值高于前三年，但不是五年逐年增长。 3）地区：主词相对热度前三为汉堡100、巴伐利亚（网页译“拜仁”）96、巴登-符腾堡94；木切菜板为汉堡100、巴登-符腾堡91、萨克森91。地区指数不代表订单或购买力。 【趋势表明】 切菜板属于持续有搜索需求、年末旺季明显的成熟需求。近两年主词旺季热度抬升，值得继续研究；是否能带来新品成交，仍应结合第一表的竞争与销量数据。
M26: 【总结】 1）季节性：两个词的年末高峰同步，备货与推广应提前于11—12月；不能把平时有需求写成“无季节性”。 2）五年走势：主词2021—2025年各年最高周均在12月；对应指数71、68、66、94、100。2024—2025年的峰值高于前三年，但不是五年逐年增长。 3）地区：主词相对热度前三为汉堡100、巴伐利亚（网页译“拜仁”）96、巴登-符腾堡94；木切菜板为汉堡100、巴登-符腾堡91、萨克森91。地区指数不代表订单或购买力。 【趋势表明】 切菜板属于持续有搜索需求、年末旺季明显的成熟需求。近两年主词旺季热度抬升，值得继续研究；是否能带来新品成交，仍应结合第一表的竞争与销量数据。 | N26: 【总结】 1）季节性：两个词的年末高峰同步，备货与推广应提前于11—12月；不能把平时有需求写成“无季节性”。 2）五年走势：主词2021—2025年各年最高周均在12月；对应指数71、68、66、94、100。2024—2025年的峰值高于前三年，但不是五年逐年增长。 3）地区：主词相对热度前三为汉堡100、巴伐利亚（网页译“拜仁”）96、巴登-符腾堡94；木切菜板为汉堡100、巴登-符腾堡91、萨克森91。地区指数不代表订单或购买力。 【趋势表明】 切菜板属于持续有搜索需求、年末旺季明显的成熟需求。近两年主词旺季热度抬升，值得继续研究；是否能带来新品成交，仍应结合第一表的竞争与销量数据。 | O26: 【总结】 1）季节性：两个词的年末高峰同步，备货与推广应提前于11—12月；不能把平时有需求写成“无季节性”。 2）五年走势：主词2021—2025年各年最高周均在12月；对应指数71、68、66、94、100。2024—2025年的峰值高于前三年，但不是五年逐年增长。 3）地区：主词相对热度前三为汉堡100、巴伐利亚（网页译“拜仁”）96、巴登-符腾堡94；木切菜板为汉堡100、巴登-符腾堡91、萨克森91。地区指数不代表订单或购买力。 【趋势表明】 切菜板属于持续有搜索需求、年末旺季明显的成熟需求。近两年主词旺季热度抬升，值得继续研究；是否能带来新品成交，仍应结合第一表的竞争与销量数据。 | P26: 【总结】 1）季节性：两个词的年末高峰同步，备货与推广应提前于11—12月；不能把平时有需求写成“无季节性”。 2）五年走势：主词2021—2025年各年最高周均在12月；对应指数71、68、66、94、100。2024—2025年的峰值高于前三年，但不是五年逐年增长。 3）地区：主词相对热度前三为汉堡100、巴伐利亚（网页译“拜仁”）96、巴登-符腾堡94；木切菜板为汉堡100、巴登-符腾堡91、萨克森91。地区指数不代表订单或购买力。 【趋势表明】 切菜板属于持续有搜索需求、年末旺季明显的成熟需求。近两年主词旺季热度抬升，值得继续研究；是否能带来新品成交，仍应结合第一表的竞争与销量数据。 | Q26: 【总结】 1）季节性：两个词的年末高峰同步，备货与推广应提前于11—12月；不能把平时有需求写成“无季节性”。 2）五年走势：主词2021—2025年各年最高周均在12月；对应指数71、68、66、94、100。2024—2025年的峰值高于前三年，但不是五年逐年增长。 3）地区：主词相对热度前三为汉堡100、巴伐利亚（网页译“拜仁”）96、巴登-符腾堡94；木切菜板为汉堡100、巴登-符腾堡91、萨克森91。地区指数不代表订单或购买力。 【趋势表明】 切菜板属于持续有搜索需求、年末旺季明显的成熟需求。近两年主词旺季热度抬升，值得继续研究；是否能带来新品成交，仍应结合第一表的竞争与销量数据。 | R26: 【总结】 1）季节性：两个词的年末高峰同步，备货与推广应提前于11—12月；不能把平时有需求写成“无季节性”。 2）五年走势：主词2021—2025年各年最高周均在12月；对应指数71、68、66、94、100。2024—2025年的峰值高于前三年，但不是五年逐年增长。 3）地区：主词相对热度前三为汉堡100、巴伐利亚（网页译“拜仁”）96、巴登-符腾堡94；木切菜板为汉堡100、巴登-符腾堡91、萨克森91。地区指数不代表订单或购买力。 【趋势表明】 切菜板属于持续有搜索需求、年末旺季明显的成熟需求。近两年主词旺季热度抬升，值得继续研究；是否能带来新品成交，仍应结合第一表的竞争与销量数据。 | S26: 【总结】 1）季节性：两个词的年末高峰同步，备货与推广应提前于11—12月；不能把平时有需求写成“无季节性”。 2）五年走势：主词2021—2025年各年最高周均在12月；对应指数71、68、66、94、100。2024—2025年的峰值高于前三年，但不是五年逐年增长。 3）地区：主词相对热度前三为汉堡100、巴伐利亚（网页译“拜仁”）96、巴登-符腾堡94；木切菜板为汉堡100、巴登-符腾堡91、萨克森91。地区指数不代表订单或购买力。 【趋势表明】 切菜板属于持续有搜索需求、年末旺季明显的成熟需求。近两年主词旺季热度抬升，值得继续研究；是否能带来新品成交，仍应结合第一表的竞争与销量数据。 | T26: 【总结】 1）季节性：两个词的年末高峰同步，备货与推广应提前于11—12月；不能把平时有需求写成“无季节性”。 2）五年走势：主词2021—2025年各年最高周均在12月；对应指数71、68、66、94、100。2024—2025年的峰值高于前三年，但不是五年逐年增长。 3）地区：主词相对热度前三为汉堡100、巴伐利亚（网页译“拜仁”）96、巴登-符腾堡94；木切菜板为汉堡100、巴登-符腾堡91、萨克森91。地区指数不代表订单或购买力。 【趋势表明】 切菜板属于持续有搜索需求、年末旺季明显的成熟需求。近两年主词旺季热度抬升，值得继续研究；是否能带来新品成交，仍应结合第一表的竞争与销量数据。 | U26: 【总结】 1）季节性：两个词的年末高峰同步，备货与推广应提前于11—12月；不能把平时有需求写成“无季节性”。 2）五年走势：主词2021—2025年各年最高周均在12月；对应指数71、68、66、94、100。2024—2025年的峰值高于前三年，但不是五年逐年增长。 3）地区：主词相对热度前三为汉堡100、巴伐利亚（网页译“拜仁”）96、巴登-符腾堡94；木切菜板为汉堡100、巴登-符腾堡91、萨克森91。地区指数不代表订单或购买力。 【趋势表明】 切菜板属于持续有搜索需求、年末旺季明显的成熟需求。近两年主词旺季热度抬升，值得继续研究；是否能带来新品成交，仍应结合第一表的竞争与销量数据。 | V26: 【总结】 1）季节性：两个词的年末高峰同步，备货与推广应提前于11—12月；不能把平时有需求写成“无季节性”。 2）五年走势：主词2021—2025年各年最高周均在12月；对应指数71、68、66、94、100。2024—2025年的峰值高于前三年，但不是五年逐年增长。 3）地区：主词相对热度前三为汉堡100、巴伐利亚（网页译“拜仁”）96、巴登-符腾堡94；木切菜板为汉堡100、巴登-符腾堡91、萨克森91。地区指数不代表订单或购买力。 【趋势表明】 切菜板属于持续有搜索需求、年末旺季明显的成熟需求。近两年主词旺季热度抬升，值得继续研究；是否能带来新品成交，仍应结合第一表的竞争与销量数据。 | W26: 【总结】 1）季节性：两个词的年末高峰同步，备货与推广应提前于11—12月；不能把平时有需求写成“无季节性”。 2）五年走势：主词2021—2025年各年最高周均在12月；对应指数71、68、66、94、100。2024—2025年的峰值高于前三年，但不是五年逐年增长。 3）地区：主词相对热度前三为汉堡100、巴伐利亚（网页译“拜仁”）96、巴登-符腾堡94；木切菜板为汉堡100、巴登-符腾堡91、萨克森91。地区指数不代表订单或购买力。 【趋势表明】 切菜板属于持续有搜索需求、年末旺季明显的成熟需求。近两年主词旺季热度抬升，值得继续研究；是否能带来新品成交，仍应结合第一表的竞争与销量数据。 | X26: 【总结】 1）季节性：两个词的年末高峰同步，备货与推广应提前于11—12月；不能把平时有需求写成“无季节性”。 2）五年走势：主词2021—2025年各年最高周均在12月；对应指数71、68、66、94、100。2024—2025年的峰值高于前三年，但不是五年逐年增长。 3）地区：主词相对热度前三为汉堡100、巴伐利亚（网页译“拜仁”）96、巴登-符腾堡94；木切菜板为汉堡100、巴登-符腾堡91、萨克森91。地区指数不代表订单或购买力。 【趋势表明】 切菜板属于持续有搜索需求、年末旺季明显的成熟需求。近两年主词旺季热度抬升，值得继续研究；是否能带来新品成交，仍应结合第一表的竞争与销量数据。
M27: 【总结】 1）季节性：两个词的年末高峰同步，备货与推广应提前于11—12月；不能把平时有需求写成“无季节性”。 2）五年走势：主词2021—2025年各年最高周均在12月；对应指数71、68、66、94、100。2024—2025年的峰值高于前三年，但不是五年逐年增长。 3）地区：主词相对热度前三为汉堡100、巴伐利亚（网页译“拜仁”）96、巴登-符腾堡94；木切菜板为汉堡100、巴登-符腾堡91、萨克森91。地区指数不代表订单或购买力。 【趋势表明】 切菜板属于持续有搜索需求、年末旺季明显的成熟需求。近两年主词旺季热度抬升，值得继续研究；是否能带来新品成交，仍应结合第一表的竞争与销量数据。 | N27: 【总结】 1）季节性：两个词的年末高峰同步，备货与推广应提前于11—12月；不能把平时有需求写成“无季节性”。 2）五年走势：主词2021—2025年各年最高周均在12月；对应指数71、68、66、94、100。2024—2025年的峰值高于前三年，但不是五年逐年增长。 3）地区：主词相对热度前三为汉堡100、巴伐利亚（网页译“拜仁”）96、巴登-符腾堡94；木切菜板为汉堡100、巴登-符腾堡91、萨克森91。地区指数不代表订单或购买力。 【趋势表明】 切菜板属于持续有搜索需求、年末旺季明显的成熟需求。近两年主词旺季热度抬升，值得继续研究；是否能带来新品成交，仍应结合第一表的竞争与销量数据。 | O27: 【总结】 1）季节性：两个词的年末高峰同步，备货与推广应提前于11—12月；不能把平时有需求写成“无季节性”。 2）五年走势：主词2021—2025年各年最高周均在12月；对应指数71、68、66、94、100。2024—2025年的峰值高于前三年，但不是五年逐年增长。 3）地区：主词相对热度前三为汉堡100、巴伐利亚（网页译“拜仁”）96、巴登-符腾堡94；木切菜板为汉堡100、巴登-符腾堡91、萨克森91。地区指数不代表订单或购买力。 【趋势表明】 切菜板属于持续有搜索需求、年末旺季明显的成熟需求。近两年主词旺季热度抬升，值得继续研究；是否能带来新品成交，仍应结合第一表的竞争与销量数据。 | P27: 【总结】 1）季节性：两个词的年末高峰同步，备货与推广应提前于11—12月；不能把平时有需求写成“无季节性”。 2）五年走势：主词2021—2025年各年最高周均在12月；对应指数71、68、66、94、100。2024—2025年的峰值高于前三年，但不是五年逐年增长。 3）地区：主词相对热度前三为汉堡100、巴伐利亚（网页译“拜仁”）96、巴登-符腾堡94；木切菜板为汉堡100、巴登-符腾堡91、萨克森91。地区指数不代表订单或购买力。 【趋势表明】 切菜板属于持续有搜索需求、年末旺季明显的成熟需求。近两年主词旺季热度抬升，值得继续研究；是否能带来新品成交，仍应结合第一表的竞争与销量数据。 | Q27: 【总结】 1）季节性：两个词的年末高峰同步，备货与推广应提前于11—12月；不能把平时有需求写成“无季节性”。 2）五年走势：主词2021—2025年各年最高周均在12月；对应指数71、68、66、94、100。2024—2025年的峰值高于前三年，但不是五年逐年增长。 3）地区：主词相对热度前三为汉堡100、巴伐利亚（网页译“拜仁”）96、巴登-符腾堡94；木切菜板为汉堡100、巴登-符腾堡91、萨克森91。地区指数不代表订单或购买力。 【趋势表明】 切菜板属于持续有搜索需求、年末旺季明显的成熟需求。近两年主词旺季热度抬升，值得继续研究；是否能带来新品成交，仍应结合第一表的竞争与销量数据。 | R27: 【总结】 1）季节性：两个词的年末高峰同步，备货与推广应提前于11—12月；不能把平时有需求写成“无季节性”。 2）五年走势：主词2021—2025年各年最高周均在12月；对应指数71、68、66、94、100。2024—2025年的峰值高于前三年，但不是五年逐年增长。 3）地区：主词相对热度前三为汉堡100、巴伐利亚（网页译“拜仁”）96、巴登-符腾堡94；木切菜板为汉堡100、巴登-符腾堡91、萨克森91。地区指数不代表订单或购买力。 【趋势表明】 切菜板属于持续有搜索需求、年末旺季明显的成熟需求。近两年主词旺季热度抬升，值得继续研究；是否能带来新品成交，仍应结合第一表的竞争与销量数据。 | S27: 【总结】 1）季节性：两个词的年末高峰同步，备货与推广应提前于11—12月；不能把平时有需求写成“无季节性”。 2）五年走势：主词2021—2025年各年最高周均在12月；对应指数71、68、66、94、100。2024—2025年的峰值高于前三年，但不是五年逐年增长。 3）地区：主词相对热度前三为汉堡100、巴伐利亚（网页译“拜仁”）96、巴登-符腾堡94；木切菜板为汉堡100、巴登-符腾堡91、萨克森91。地区指数不代表订单或购买力。 【趋势表明】 切菜板属于持续有搜索需求、年末旺季明显的成熟需求。近两年主词旺季热度抬升，值得继续研究；是否能带来新品成交，仍应结合第一表的竞争与销量数据。 | T27: 【总结】 1）季节性：两个词的年末高峰同步，备货与推广应提前于11—12月；不能把平时有需求写成“无季节性”。 2）五年走势：主词2021—2025年各年最高周均在12月；对应指数71、68、66、94、100。2024—2025年的峰值高于前三年，但不是五年逐年增长。 3）地区：主词相对热度前三为汉堡100、巴伐利亚（网页译“拜仁”）96、巴登-符腾堡94；木切菜板为汉堡100、巴登-符腾堡91、萨克森91。地区指数不代表订单或购买力。 【趋势表明】 切菜板属于持续有搜索需求、年末旺季明显的成熟需求。近两年主词旺季热度抬升，值得继续研究；是否能带来新品成交，仍应结合第一表的竞争与销量数据。 | U27: 【总结】 1）季节性：两个词的年末高峰同步，备货与推广应提前于11—12月；不能把平时有需求写成“无季节性”。 2）五年走势：主词2021—2025年各年最高周均在12月；对应指数71、68、66、94、100。2024—2025年的峰值高于前三年，但不是五年逐年增长。 3）地区：主词相对热度前三为汉堡100、巴伐利亚（网页译“拜仁”）96、巴登-符腾堡94；木切菜板为汉堡100、巴登-符腾堡91、萨克森91。地区指数不代表订单或购买力。 【趋势表明】 切菜板属于持续有搜索需求、年末旺季明显的成熟需求。近两年主词旺季热度抬升，值得继续研究；是否能带来新品成交，仍应结合第一表的竞争与销量数据。 | V27: 【总结】 1）季节性：两个词的年末高峰同步，备货与推广应提前于11—12月；不能把平时有需求写成“无季节性”。 2）五年走势：主词2021—2025年各年最高周均在12月；对应指数71、68、66、94、100。2024—2025年的峰值高于前三年，但不是五年逐年增长。 3）地区：主词相对热度前三为汉堡100、巴伐利亚（网页译“拜仁”）96、巴登-符腾堡94；木切菜板为汉堡100、巴登-符腾堡91、萨克森91。地区指数不代表订单或购买力。 【趋势表明】 切菜板属于持续有搜索需求、年末旺季明显的成熟需求。近两年主词旺季热度抬升，值得继续研究；是否能带来新品成交，仍应结合第一表的竞争与销量数据。 | W27: 【总结】 1）季节性：两个词的年末高峰同步，备货与推广应提前于11—12月；不能把平时有需求写成“无季节性”。 2）五年走势：主词2021—2025年各年最高周均在12月；对应指数71、68、66、94、100。2024—2025年的峰值高于前三年，但不是五年逐年增长。 3）地区：主词相对热度前三为汉堡100、巴伐利亚（网页译“拜仁”）96、巴登-符腾堡94；木切菜板为汉堡100、巴登-符腾堡91、萨克森91。地区指数不代表订单或购买力。 【趋势表明】 切菜板属于持续有搜索需求、年末旺季明显的成熟需求。近两年主词旺季热度抬升，值得继续研究；是否能带来新品成交，仍应结合第一表的竞争与销量数据。 | X27: 【总结】 1）季节性：两个词的年末高峰同步，备货与推广应提前于11—12月；不能把平时有需求写成“无季节性”。 2）五年走势：主词2021—2025年各年最高周均在12月；对应指数71、68、66、94、100。2024—2025年的峰值高于前三年，但不是五年逐年增长。 3）地区：主词相对热度前三为汉堡100、巴伐利亚（网页译“拜仁”）96、巴登-符腾堡94；木切菜板为汉堡100、巴登-符腾堡91、萨克森91。地区指数不代表订单或购买力。 【趋势表明】 切菜板属于持续有搜索需求、年末旺季明显的成熟需求。近两年主词旺季热度抬升，值得继续研究；是否能带来新品成交，仍应结合第一表的竞争与销量数据。
M28: 【总结】 1）季节性：两个词的年末高峰同步，备货与推广应提前于11—12月；不能把平时有需求写成“无季节性”。 2）五年走势：主词2021—2025年各年最高周均在12月；对应指数71、68、66、94、100。2024—2025年的峰值高于前三年，但不是五年逐年增长。 3）地区：主词相对热度前三为汉堡100、巴伐利亚（网页译“拜仁”）96、巴登-符腾堡94；木切菜板为汉堡100、巴登-符腾堡91、萨克森91。地区指数不代表订单或购买力。 【趋势表明】 切菜板属于持续有搜索需求、年末旺季明显的成熟需求。近两年主词旺季热度抬升，值得继续研究；是否能带来新品成交，仍应结合第一表的竞争与销量数据。 | N28: 【总结】 1）季节性：两个词的年末高峰同步，备货与推广应提前于11—12月；不能把平时有需求写成“无季节性”。 2）五年走势：主词2021—2025年各年最高周均在12月；对应指数71、68、66、94、100。2024—2025年的峰值高于前三年，但不是五年逐年增长。 3）地区：主词相对热度前三为汉堡100、巴伐利亚（网页译“拜仁”）96、巴登-符腾堡94；木切菜板为汉堡100、巴登-符腾堡91、萨克森91。地区指数不代表订单或购买力。 【趋势表明】 切菜板属于持续有搜索需求、年末旺季明显的成熟需求。近两年主词旺季热度抬升，值得继续研究；是否能带来新品成交，仍应结合第一表的竞争与销量数据。 | O28: 【总结】 1）季节性：两个词的年末高峰同步，备货与推广应提前于11—12月；不能把平时有需求写成“无季节性”。 2）五年走势：主词2021—2025年各年最高周均在12月；对应指数71、68、66、94、100。2024—2025年的峰值高于前三年，但不是五年逐年增长。 3）地区：主词相对热度前三为汉堡100、巴伐利亚（网页译“拜仁”）96、巴登-符腾堡94；木切菜板为汉堡100、巴登-符腾堡91、萨克森91。地区指数不代表订单或购买力。 【趋势表明】 切菜板属于持续有搜索需求、年末旺季明显的成熟需求。近两年主词旺季热度抬升，值得继续研究；是否能带来新品成交，仍应结合第一表的竞争与销量数据。 | P28: 【总结】 1）季节性：两个词的年末高峰同步，备货与推广应提前于11—12月；不能把平时有需求写成“无季节性”。 2）五年走势：主词2021—2025年各年最高周均在12月；对应指数71、68、66、94、100。2024—2025年的峰值高于前三年，但不是五年逐年增长。 3）地区：主词相对热度前三为汉堡100、巴伐利亚（网页译“拜仁”）96、巴登-符腾堡94；木切菜板为汉堡100、巴登-符腾堡91、萨克森91。地区指数不代表订单或购买力。 【趋势表明】 切菜板属于持续有搜索需求、年末旺季明显的成熟需求。近两年主词旺季热度抬升，值得继续研究；是否能带来新品成交，仍应结合第一表的竞争与销量数据。 | Q28: 【总结】 1）季节性：两个词的年末高峰同步，备货与推广应提前于11—12月；不能把平时有需求写成“无季节性”。 2）五年走势：主词2021—2025年各年最高周均在12月；对应指数71、68、66、94、100。2024—2025年的峰值高于前三年，但不是五年逐年增长。 3）地区：主词相对热度前三为汉堡100、巴伐利亚（网页译“拜仁”）96、巴登-符腾堡94；木切菜板为汉堡100、巴登-符腾堡91、萨克森91。地区指数不代表订单或购买力。 【趋势表明】 切菜板属于持续有搜索需求、年末旺季明显的成熟需求。近两年主词旺季热度抬升，值得继续研究；是否能带来新品成交，仍应结合第一表的竞争与销量数据。 | R28: 【总结】 1）季节性：两个词的年末高峰同步，备货与推广应提前于11—12月；不能把平时有需求写成“无季节性”。 2）五年走势：主词2021—2025年各年最高周均在12月；对应指数71、68、66、94、100。2024—2025年的峰值高于前三年，但不是五年逐年增长。 3）地区：主词相对热度前三为汉堡100、巴伐利亚（网页译“拜仁”）96、巴登-符腾堡94；木切菜板为汉堡100、巴登-符腾堡91、萨克森91。地区指数不代表订单或购买力。 【趋势表明】 切菜板属于持续有搜索需求、年末旺季明显的成熟需求。近两年主词旺季热度抬升，值得继续研究；是否能带来新品成交，仍应结合第一表的竞争与销量数据。 | S28: 【总结】 1）季节性：两个词的年末高峰同步，备货与推广应提前于11—12月；不能把平时有需求写成“无季节性”。 2）五年走势：主词2021—2025年各年最高周均在12月；对应指数71、68、66、94、100。2024—2025年的峰值高于前三年，但不是五年逐年增长。 3）地区：主词相对热度前三为汉堡100、巴伐利亚（网页译“拜仁”）96、巴登-符腾堡94；木切菜板为汉堡100、巴登-符腾堡91、萨克森91。地区指数不代表订单或购买力。 【趋势表明】 切菜板属于持续有搜索需求、年末旺季明显的成熟需求。近两年主词旺季热度抬升，值得继续研究；是否能带来新品成交，仍应结合第一表的竞争与销量数据。 | T28: 【总结】 1）季节性：两个词的年末高峰同步，备货与推广应提前于11—12月；不能把平时有需求写成“无季节性”。 2）五年走势：主词2021—2025年各年最高周均在12月；对应指数71、68、66、94、100。2024—2025年的峰值高于前三年，但不是五年逐年增长。 3）地区：主词相对热度前三为汉堡100、巴伐利亚（网页译“拜仁”）96、巴登-符腾堡94；木切菜板为汉堡100、巴登-符腾堡91、萨克森91。地区指数不代表订单或购买力。 【趋势表明】 切菜板属于持续有搜索需求、年末旺季明显的成熟需求。近两年主词旺季热度抬升，值得继续研究；是否能带来新品成交，仍应结合第一表的竞争与销量数据。 | U28: 【总结】 1）季节性：两个词的年末高峰同步，备货与推广应提前于11—12月；不能把平时有需求写成“无季节性”。 2）五年走势：主词2021—2025年各年最高周均在12月；对应指数71、68、66、94、100。2024—2025年的峰值高于前三年，但不是五年逐年增长。 3）地区：主词相对热度前三为汉堡100、巴伐利亚（网页译“拜仁”）96、巴登-符腾堡94；木切菜板为汉堡100、巴登-符腾堡91、萨克森91。地区指数不代表订单或购买力。 【趋势表明】 切菜板属于持续有搜索需求、年末旺季明显的成熟需求。近两年主词旺季热度抬升，值得继续研究；是否能带来新品成交，仍应结合第一表的竞争与销量数据。 | V28: 【总结】 1）季节性：两个词的年末高峰同步，备货与推广应提前于11—12月；不能把平时有需求写成“无季节性”。 2）五年走势：主词2021—2025年各年最高周均在12月；对应指数71、68、66、94、100。2024—2025年的峰值高于前三年，但不是五年逐年增长。 3）地区：主词相对热度前三为汉堡100、巴伐利亚（网页译“拜仁”）96、巴登-符腾堡94；木切菜板为汉堡100、巴登-符腾堡91、萨克森91。地区指数不代表订单或购买力。 【趋势表明】 切菜板属于持续有搜索需求、年末旺季明显的成熟需求。近两年主词旺季热度抬升，值得继续研究；是否能带来新品成交，仍应结合第一表的竞争与销量数据。 | W28: 【总结】 1）季节性：两个词的年末高峰同步，备货与推广应提前于11—12月；不能把平时有需求写成“无季节性”。 2）五年走势：主词2021—2025年各年最高周均在12月；对应指数71、68、66、94、100。2024—2025年的峰值高于前三年，但不是五年逐年增长。 3）地区：主词相对热度前三为汉堡100、巴伐利亚（网页译“拜仁”）96、巴登-符腾堡94；木切菜板为汉堡100、巴登-符腾堡91、萨克森91。地区指数不代表订单或购买力。 【趋势表明】 切菜板属于持续有搜索需求、年末旺季明显的成熟需求。近两年主词旺季热度抬升，值得继续研究；是否能带来新品成交，仍应结合第一表的竞争与销量数据。 | X28: 【总结】 1）季节性：两个词的年末高峰同步，备货与推广应提前于11—12月；不能把平时有需求写成“无季节性”。 2）五年走势：主词2021—2025年各年最高周均在12月；对应指数71、68、66、94、100。2024—2025年的峰值高于前三年，但不是五年逐年增长。 3）地区：主词相对热度前三为汉堡100、巴伐利亚（网页译“拜仁”）96、巴登-符腾堡94；木切菜板为汉堡100、巴登-符腾堡91、萨克森91。地区指数不代表订单或购买力。 【趋势表明】 切菜板属于持续有搜索需求、年末旺季明显的成熟需求。近两年主词旺季热度抬升，值得继续研究；是否能带来新品成交，仍应结合第一表的竞争与销量数据。
M29: 【总结】 1）季节性：两个词的年末高峰同步，备货与推广应提前于11—12月；不能把平时有需求写成“无季节性”。 2）五年走势：主词2021—2025年各年最高周均在12月；对应指数71、68、66、94、100。2024—2025年的峰值高于前三年，但不是五年逐年增长。 3）地区：主词相对热度前三为汉堡100、巴伐利亚（网页译“拜仁”）96、巴登-符腾堡94；木切菜板为汉堡100、巴登-符腾堡91、萨克森91。地区指数不代表订单或购买力。 【趋势表明】 切菜板属于持续有搜索需求、年末旺季明显的成熟需求。近两年主词旺季热度抬升，值得继续研究；是否能带来新品成交，仍应结合第一表的竞争与销量数据。 | N29: 【总结】 1）季节性：两个词的年末高峰同步，备货与推广应提前于11—12月；不能把平时有需求写成“无季节性”。 2）五年走势：主词2021—2025年各年最高周均在12月；对应指数71、68、66、94、100。2024—2025年的峰值高于前三年，但不是五年逐年增长。 3）地区：主词相对热度前三为汉堡100、巴伐利亚（网页译“拜仁”）96、巴登-符腾堡94；木切菜板为汉堡100、巴登-符腾堡91、萨克森91。地区指数不代表订单或购买力。 【趋势表明】 切菜板属于持续有搜索需求、年末旺季明显的成熟需求。近两年主词旺季热度抬升，值得继续研究；是否能带来新品成交，仍应结合第一表的竞争与销量数据。 | O29: 【总结】 1）季节性：两个词的年末高峰同步，备货与推广应提前于11—12月；不能把平时有需求写成“无季节性”。 2）五年走势：主词2021—2025年各年最高周均在12月；对应指数71、68、66、94、100。2024—2025年的峰值高于前三年，但不是五年逐年增长。 3）地区：主词相对热度前三为汉堡100、巴伐利亚（网页译“拜仁”）96、巴登-符腾堡94；木切菜板为汉堡100、巴登-符腾堡91、萨克森91。地区指数不代表订单或购买力。 【趋势表明】 切菜板属于持续有搜索需求、年末旺季明显的成熟需求。近两年主词旺季热度抬升，值得继续研究；是否能带来新品成交，仍应结合第一表的竞争与销量数据。 | P29: 【总结】 1）季节性：两个词的年末高峰同步，备货与推广应提前于11—12月；不能把平时有需求写成“无季节性”。 2）五年走势：主词2021—2025年各年最高周均在12月；对应指数71、68、66、94、100。2024—2025年的峰值高于前三年，但不是五年逐年增长。 3）地区：主词相对热度前三为汉堡100、巴伐利亚（网页译“拜仁”）96、巴登-符腾堡94；木切菜板为汉堡100、巴登-符腾堡91、萨克森91。地区指数不代表订单或购买力。 【趋势表明】 切菜板属于持续有搜索需求、年末旺季明显的成熟需求。近两年主词旺季热度抬升，值得继续研究；是否能带来新品成交，仍应结合第一表的竞争与销量数据。 | Q29: 【总结】 1）季节性：两个词的年末高峰同步，备货与推广应提前于11—12月；不能把平时有需求写成“无季节性”。 2）五年走势：主词2021—2025年各年最高周均在12月；对应指数71、68、66、94、100。2024—2025年的峰值高于前三年，但不是五年逐年增长。 3）地区：主词相对热度前三为汉堡100、巴伐利亚（网页译“拜仁”）96、巴登-符腾堡94；木切菜板为汉堡100、巴登-符腾堡91、萨克森91。地区指数不代表订单或购买力。 【趋势表明】 切菜板属于持续有搜索需求、年末旺季明显的成熟需求。近两年主词旺季热度抬升，值得继续研究；是否能带来新品成交，仍应结合第一表的竞争与销量数据。 | R29: 【总结】 1）季节性：两个词的年末高峰同步，备货与推广应提前于11—12月；不能把平时有需求写成“无季节性”。 2）五年走势：主词2021—2025年各年最高周均在12月；对应指数71、68、66、94、100。2024—2025年的峰值高于前三年，但不是五年逐年增长。 3）地区：主词相对热度前三为汉堡100、巴伐利亚（网页译“拜仁”）96、巴登-符腾堡94；木切菜板为汉堡100、巴登-符腾堡91、萨克森91。地区指数不代表订单或购买力。 【趋势表明】 切菜板属于持续有搜索需求、年末旺季明显的成熟需求。近两年主词旺季热度抬升，值得继续研究；是否能带来新品成交，仍应结合第一表的竞争与销量数据。 | S29: 【总结】 1）季节性：两个词的年末高峰同步，备货与推广应提前于11—12月；不能把平时有需求写成“无季节性”。 2）五年走势：主词2021—2025年各年最高周均在12月；对应指数71、68、66、94、100。2024—2025年的峰值高于前三年，但不是五年逐年增长。 3）地区：主词相对热度前三为汉堡100、巴伐利亚（网页译“拜仁”）96、巴登-符腾堡94；木切菜板为汉堡100、巴登-符腾堡91、萨克森91。地区指数不代表订单或购买力。 【趋势表明】 切菜板属于持续有搜索需求、年末旺季明显的成熟需求。近两年主词旺季热度抬升，值得继续研究；是否能带来新品成交，仍应结合第一表的竞争与销量数据。 | T29: 【总结】 1）季节性：两个词的年末高峰同步，备货与推广应提前于11—12月；不能把平时有需求写成“无季节性”。 2）五年走势：主词2021—2025年各年最高周均在12月；对应指数71、68、66、94、100。2024—2025年的峰值高于前三年，但不是五年逐年增长。 3）地区：主词相对热度前三为汉堡100、巴伐利亚（网页译“拜仁”）96、巴登-符腾堡94；木切菜板为汉堡100、巴登-符腾堡91、萨克森91。地区指数不代表订单或购买力。 【趋势表明】 切菜板属于持续有搜索需求、年末旺季明显的成熟需求。近两年主词旺季热度抬升，值得继续研究；是否能带来新品成交，仍应结合第一表的竞争与销量数据。 | U29: 【总结】 1）季节性：两个词的年末高峰同步，备货与推广应提前于11—12月；不能把平时有需求写成“无季节性”。 2）五年走势：主词2021—2025年各年最高周均在12月；对应指数71、68、66、94、100。2024—2025年的峰值高于前三年，但不是五年逐年增长。 3）地区：主词相对热度前三为汉堡100、巴伐利亚（网页译“拜仁”）96、巴登-符腾堡94；木切菜板为汉堡100、巴登-符腾堡91、萨克森91。地区指数不代表订单或购买力。 【趋势表明】 切菜板属于持续有搜索需求、年末旺季明显的成熟需求。近两年主词旺季热度抬升，值得继续研究；是否能带来新品成交，仍应结合第一表的竞争与销量数据。 | V29: 【总结】 1）季节性：两个词的年末高峰同步，备货与推广应提前于11—12月；不能把平时有需求写成“无季节性”。 2）五年走势：主词2021—2025年各年最高周均在12月；对应指数71、68、66、94、100。2024—2025年的峰值高于前三年，但不是五年逐年增长。 3）地区：主词相对热度前三为汉堡100、巴伐利亚（网页译“拜仁”）96、巴登-符腾堡94；木切菜板为汉堡100、巴登-符腾堡91、萨克森91。地区指数不代表订单或购买力。 【趋势表明】 切菜板属于持续有搜索需求、年末旺季明显的成熟需求。近两年主词旺季热度抬升，值得继续研究；是否能带来新品成交，仍应结合第一表的竞争与销量数据。 | W29: 【总结】 1）季节性：两个词的年末高峰同步，备货与推广应提前于11—12月；不能把平时有需求写成“无季节性”。 2）五年走势：主词2021—2025年各年最高周均在12月；对应指数71、68、66、94、100。2024—2025年的峰值高于前三年，但不是五年逐年增长。 3）地区：主词相对热度前三为汉堡100、巴伐利亚（网页译“拜仁”）96、巴登-符腾堡94；木切菜板为汉堡100、巴登-符腾堡91、萨克森91。地区指数不代表订单或购买力。 【趋势表明】 切菜板属于持续有搜索需求、年末旺季明显的成熟需求。近两年主词旺季热度抬升，值得继续研究；是否能带来新品成交，仍应结合第一表的竞争与销量数据。 | X29: 【总结】 1）季节性：两个词的年末高峰同步，备货与推广应提前于11—12月；不能把平时有需求写成“无季节性”。 2）五年走势：主词2021—2025年各年最高周均在12月；对应指数71、68、66、94、100。2024—2025年的峰值高于前三年，但不是五年逐年增长。 3）地区：主词相对热度前三为汉堡100、巴伐利亚（网页译“拜仁”）96、巴登-符腾堡94；木切菜板为汉堡100、巴登-符腾堡91、萨克森91。地区指数不代表订单或购买力。 【趋势表明】 切菜板属于持续有搜索需求、年末旺季明显的成熟需求。近两年主词旺季热度抬升，值得继续研究；是否能带来新品成交，仍应结合第一表的竞争与销量数据。
M30: 【总结】 1）季节性：两个词的年末高峰同步，备货与推广应提前于11—12月；不能把平时有需求写成“无季节性”。 2）五年走势：主词2021—2025年各年最高周均在12月；对应指数71、68、66、94、100。2024—2025年的峰值高于前三年，但不是五年逐年增长。 3）地区：主词相对热度前三为汉堡100、巴伐利亚（网页译“拜仁”）96、巴登-符腾堡94；木切菜板为汉堡100、巴登-符腾堡91、萨克森91。地区指数不代表订单或购买力。 【趋势表明】 切菜板属于持续有搜索需求、年末旺季明显的成熟需求。近两年主词旺季热度抬升，值得继续研究；是否能带来新品成交，仍应结合第一表的竞争与销量数据。 | N30: 【总结】 1）季节性：两个词的年末高峰同步，备货与推广应提前于11—12月；不能把平时有需求写成“无季节性”。 2）五年走势：主词2021—2025年各年最高周均在12月；对应指数71、68、66、94、100。2024—2025年的峰值高于前三年，但不是五年逐年增长。 3）地区：主词相对热度前三为汉堡100、巴伐利亚（网页译“拜仁”）96、巴登-符腾堡94；木切菜板为汉堡100、巴登-符腾堡91、萨克森91。地区指数不代表订单或购买力。 【趋势表明】 切菜板属于持续有搜索需求、年末旺季明显的成熟需求。近两年主词旺季热度抬升，值得继续研究；是否能带来新品成交，仍应结合第一表的竞争与销量数据。 | O30: 【总结】 1）季节性：两个词的年末高峰同步，备货与推广应提前于11—12月；不能把平时有需求写成“无季节性”。 2）五年走势：主词2021—2025年各年最高周均在12月；对应指数71、68、66、94、100。2024—2025年的峰值高于前三年，但不是五年逐年增长。 3）地区：主词相对热度前三为汉堡100、巴伐利亚（网页译“拜仁”）96、巴登-符腾堡94；木切菜板为汉堡100、巴登-符腾堡91、萨克森91。地区指数不代表订单或购买力。 【趋势表明】 切菜板属于持续有搜索需求、年末旺季明显的成熟需求。近两年主词旺季热度抬升，值得继续研究；是否能带来新品成交，仍应结合第一表的竞争与销量数据。 | P30: 【总结】 1）季节性：两个词的年末高峰同步，备货与推广应提前于11—12月；不能把平时有需求写成“无季节性”。 2）五年走势：主词2021—2025年各年最高周均在12月；对应指数71、68、66、94、100。2024—2025年的峰值高于前三年，但不是五年逐年增长。 3）地区：主词相对热度前三为汉堡100、巴伐利亚（网页译“拜仁”）96、巴登-符腾堡94；木切菜板为汉堡100、巴登-符腾堡91、萨克森91。地区指数不代表订单或购买力。 【趋势表明】 切菜板属于持续有搜索需求、年末旺季明显的成熟需求。近两年主词旺季热度抬升，值得继续研究；是否能带来新品成交，仍应结合第一表的竞争与销量数据。 | Q30: 【总结】 1）季节性：两个词的年末高峰同步，备货与推广应提前于11—12月；不能把平时有需求写成“无季节性”。 2）五年走势：主词2021—2025年各年最高周均在12月；对应指数71、68、66、94、100。2024—2025年的峰值高于前三年，但不是五年逐年增长。 3）地区：主词相对热度前三为汉堡100、巴伐利亚（网页译“拜仁”）96、巴登-符腾堡94；木切菜板为汉堡100、巴登-符腾堡91、萨克森91。地区指数不代表订单或购买力。 【趋势表明】 切菜板属于持续有搜索需求、年末旺季明显的成熟需求。近两年主词旺季热度抬升，值得继续研究；是否能带来新品成交，仍应结合第一表的竞争与销量数据。 | R30: 【总结】 1）季节性：两个词的年末高峰同步，备货与推广应提前于11—12月；不能把平时有需求写成“无季节性”。 2）五年走势：主词2021—2025年各年最高周均在12月；对应指数71、68、66、94、100。2024—2025年的峰值高于前三年，但不是五年逐年增长。 3）地区：主词相对热度前三为汉堡100、巴伐利亚（网页译“拜仁”）96、巴登-符腾堡94；木切菜板为汉堡100、巴登-符腾堡91、萨克森91。地区指数不代表订单或购买力。 【趋势表明】 切菜板属于持续有搜索需求、年末旺季明显的成熟需求。近两年主词旺季热度抬升，值得继续研究；是否能带来新品成交，仍应结合第一表的竞争与销量数据。 | S30: 【总结】 1）季节性：两个词的年末高峰同步，备货与推广应提前于11—12月；不能把平时有需求写成“无季节性”。 2）五年走势：主词2021—2025年各年最高周均在12月；对应指数71、68、66、94、100。2024—2025年的峰值高于前三年，但不是五年逐年增长。 3）地区：主词相对热度前三为汉堡100、巴伐利亚（网页译“拜仁”）96、巴登-符腾堡94；木切菜板为汉堡100、巴登-符腾堡91、萨克森91。地区指数不代表订单或购买力。 【趋势表明】 切菜板属于持续有搜索需求、年末旺季明显的成熟需求。近两年主词旺季热度抬升，值得继续研究；是否能带来新品成交，仍应结合第一表的竞争与销量数据。 | T30: 【总结】 1）季节性：两个词的年末高峰同步，备货与推广应提前于11—12月；不能把平时有需求写成“无季节性”。 2）五年走势：主词2021—2025年各年最高周均在12月；对应指数71、68、66、94、100。2024—2025年的峰值高于前三年，但不是五年逐年增长。 3）地区：主词相对热度前三为汉堡100、巴伐利亚（网页译“拜仁”）96、巴登-符腾堡94；木切菜板为汉堡100、巴登-符腾堡91、萨克森91。地区指数不代表订单或购买力。 【趋势表明】 切菜板属于持续有搜索需求、年末旺季明显的成熟需求。近两年主词旺季热度抬升，值得继续研究；是否能带来新品成交，仍应结合第一表的竞争与销量数据。 | U30: 【总结】 1）季节性：两个词的年末高峰同步，备货与推广应提前于11—12月；不能把平时有需求写成“无季节性”。 2）五年走势：主词2021—2025年各年最高周均在12月；对应指数71、68、66、94、100。2024—2025年的峰值高于前三年，但不是五年逐年增长。 3）地区：主词相对热度前三为汉堡100、巴伐利亚（网页译“拜仁”）96、巴登-符腾堡94；木切菜板为汉堡100、巴登-符腾堡91、萨克森91。地区指数不代表订单或购买力。 【趋势表明】 切菜板属于持续有搜索需求、年末旺季明显的成熟需求。近两年主词旺季热度抬升，值得继续研究；是否能带来新品成交，仍应结合第一表的竞争与销量数据。 | V30: 【总结】 1）季节性：两个词的年末高峰同步，备货与推广应提前于11—12月；不能把平时有需求写成“无季节性”。 2）五年走势：主词2021—2025年各年最高周均在12月；对应指数71、68、66、94、100。2024—2025年的峰值高于前三年，但不是五年逐年增长。 3）地区：主词相对热度前三为汉堡100、巴伐利亚（网页译“拜仁”）96、巴登-符腾堡94；木切菜板为汉堡100、巴登-符腾堡91、萨克森91。地区指数不代表订单或购买力。 【趋势表明】 切菜板属于持续有搜索需求、年末旺季明显的成熟需求。近两年主词旺季热度抬升，值得继续研究；是否能带来新品成交，仍应结合第一表的竞争与销量数据。 | W30: 【总结】 1）季节性：两个词的年末高峰同步，备货与推广应提前于11—12月；不能把平时有需求写成“无季节性”。 2）五年走势：主词2021—2025年各年最高周均在12月；对应指数71、68、66、94、100。2024—2025年的峰值高于前三年，但不是五年逐年增长。 3）地区：主词相对热度前三为汉堡100、巴伐利亚（网页译“拜仁”）96、巴登-符腾堡94；木切菜板为汉堡100、巴登-符腾堡91、萨克森91。地区指数不代表订单或购买力。 【趋势表明】 切菜板属于持续有搜索需求、年末旺季明显的成熟需求。近两年主词旺季热度抬升，值得继续研究；是否能带来新品成交，仍应结合第一表的竞争与销量数据。 | X30: 【总结】 1）季节性：两个词的年末高峰同步，备货与推广应提前于11—12月；不能把平时有需求写成“无季节性”。 2）五年走势：主词2021—2025年各年最高周均在12月；对应指数71、68、66、94、100。2024—2025年的峰值高于前三年，但不是五年逐年增长。 3）地区：主词相对热度前三为汉堡100、巴伐利亚（网页译“拜仁”）96、巴登-符腾堡94；木切菜板为汉堡100、巴登-符腾堡91、萨克森91。地区指数不代表订单或购买力。 【趋势表明】 切菜板属于持续有搜索需求、年末旺季明显的成熟需求。近两年主词旺季热度抬升，值得继续研究；是否能带来新品成交，仍应结合第一表的竞争与销量数据。
M31: 【总结】 1）季节性：两个词的年末高峰同步，备货与推广应提前于11—12月；不能把平时有需求写成“无季节性”。 2）五年走势：主词2021—2025年各年最高周均在12月；对应指数71、68、66、94、100。2024—2025年的峰值高于前三年，但不是五年逐年增长。 3）地区：主词相对热度前三为汉堡100、巴伐利亚（网页译“拜仁”）96、巴登-符腾堡94；木切菜板为汉堡100、巴登-符腾堡91、萨克森91。地区指数不代表订单或购买力。 【趋势表明】 切菜板属于持续有搜索需求、年末旺季明显的成熟需求。近两年主词旺季热度抬升，值得继续研究；是否能带来新品成交，仍应结合第一表的竞争与销量数据。 | N31: 【总结】 1）季节性：两个词的年末高峰同步，备货与推广应提前于11—12月；不能把平时有需求写成“无季节性”。 2）五年走势：主词2021—2025年各年最高周均在12月；对应指数71、68、66、94、100。2024—2025年的峰值高于前三年，但不是五年逐年增长。 3）地区：主词相对热度前三为汉堡100、巴伐利亚（网页译“拜仁”）96、巴登-符腾堡94；木切菜板为汉堡100、巴登-符腾堡91、萨克森91。地区指数不代表订单或购买力。 【趋势表明】 切菜板属于持续有搜索需求、年末旺季明显的成熟需求。近两年主词旺季热度抬升，值得继续研究；是否能带来新品成交，仍应结合第一表的竞争与销量数据。 | O31: 【总结】 1）季节性：两个词的年末高峰同步，备货与推广应提前于11—12月；不能把平时有需求写成“无季节性”。 2）五年走势：主词2021—2025年各年最高周均在12月；对应指数71、68、66、94、100。2024—2025年的峰值高于前三年，但不是五年逐年增长。 3）地区：主词相对热度前三为汉堡100、巴伐利亚（网页译“拜仁”）96、巴登-符腾堡94；木切菜板为汉堡100、巴登-符腾堡91、萨克森91。地区指数不代表订单或购买力。 【趋势表明】 切菜板属于持续有搜索需求、年末旺季明显的成熟需求。近两年主词旺季热度抬升，值得继续研究；是否能带来新品成交，仍应结合第一表的竞争与销量数据。 | P31: 【总结】 1）季节性：两个词的年末高峰同步，备货与推广应提前于11—12月；不能把平时有需求写成“无季节性”。 2）五年走势：主词2021—2025年各年最高周均在12月；对应指数71、68、66、94、100。2024—2025年的峰值高于前三年，但不是五年逐年增长。 3）地区：主词相对热度前三为汉堡100、巴伐利亚（网页译“拜仁”）96、巴登-符腾堡94；木切菜板为汉堡100、巴登-符腾堡91、萨克森91。地区指数不代表订单或购买力。 【趋势表明】 切菜板属于持续有搜索需求、年末旺季明显的成熟需求。近两年主词旺季热度抬升，值得继续研究；是否能带来新品成交，仍应结合第一表的竞争与销量数据。 | Q31: 【总结】 1）季节性：两个词的年末高峰同步，备货与推广应提前于11—12月；不能把平时有需求写成“无季节性”。 2）五年走势：主词2021—2025年各年最高周均在12月；对应指数71、68、66、94、100。2024—2025年的峰值高于前三年，但不是五年逐年增长。 3）地区：主词相对热度前三为汉堡100、巴伐利亚（网页译“拜仁”）96、巴登-符腾堡94；木切菜板为汉堡100、巴登-符腾堡91、萨克森91。地区指数不代表订单或购买力。 【趋势表明】 切菜板属于持续有搜索需求、年末旺季明显的成熟需求。近两年主词旺季热度抬升，值得继续研究；是否能带来新品成交，仍应结合第一表的竞争与销量数据。 | R31: 【总结】 1）季节性：两个词的年末高峰同步，备货与推广应提前于11—12月；不能把平时有需求写成“无季节性”。 2）五年走势：主词2021—2025年各年最高周均在12月；对应指数71、68、66、94、100。2024—2025年的峰值高于前三年，但不是五年逐年增长。 3）地区：主词相对热度前三为汉堡100、巴伐利亚（网页译“拜仁”）96、巴登-符腾堡94；木切菜板为汉堡100、巴登-符腾堡91、萨克森91。地区指数不代表订单或购买力。 【趋势表明】 切菜板属于持续有搜索需求、年末旺季明显的成熟需求。近两年主词旺季热度抬升，值得继续研究；是否能带来新品成交，仍应结合第一表的竞争与销量数据。 | S31: 【总结】 1）季节性：两个词的年末高峰同步，备货与推广应提前于11—12月；不能把平时有需求写成“无季节性”。 2）五年走势：主词2021—2025年各年最高周均在12月；对应指数71、68、66、94、100。2024—2025年的峰值高于前三年，但不是五年逐年增长。 3）地区：主词相对热度前三为汉堡100、巴伐利亚（网页译“拜仁”）96、巴登-符腾堡94；木切菜板为汉堡100、巴登-符腾堡91、萨克森91。地区指数不代表订单或购买力。 【趋势表明】 切菜板属于持续有搜索需求、年末旺季明显的成熟需求。近两年主词旺季热度抬升，值得继续研究；是否能带来新品成交，仍应结合第一表的竞争与销量数据。 | T31: 【总结】 1）季节性：两个词的年末高峰同步，备货与推广应提前于11—12月；不能把平时有需求写成“无季节性”。 2）五年走势：主词2021—2025年各年最高周均在12月；对应指数71、68、66、94、100。2024—2025年的峰值高于前三年，但不是五年逐年增长。 3）地区：主词相对热度前三为汉堡100、巴伐利亚（网页译“拜仁”）96、巴登-符腾堡94；木切菜板为汉堡100、巴登-符腾堡91、萨克森91。地区指数不代表订单或购买力。 【趋势表明】 切菜板属于持续有搜索需求、年末旺季明显的成熟需求。近两年主词旺季热度抬升，值得继续研究；是否能带来新品成交，仍应结合第一表的竞争与销量数据。 | U31: 【总结】 1）季节性：两个词的年末高峰同步，备货与推广应提前于11—12月；不能把平时有需求写成“无季节性”。 2）五年走势：主词2021—2025年各年最高周均在12月；对应指数71、68、66、94、100。2024—2025年的峰值高于前三年，但不是五年逐年增长。 3）地区：主词相对热度前三为汉堡100、巴伐利亚（网页译“拜仁”）96、巴登-符腾堡94；木切菜板为汉堡100、巴登-符腾堡91、萨克森91。地区指数不代表订单或购买力。 【趋势表明】 切菜板属于持续有搜索需求、年末旺季明显的成熟需求。近两年主词旺季热度抬升，值得继续研究；是否能带来新品成交，仍应结合第一表的竞争与销量数据。 | V31: 【总结】 1）季节性：两个词的年末高峰同步，备货与推广应提前于11—12月；不能把平时有需求写成“无季节性”。 2）五年走势：主词2021—2025年各年最高周均在12月；对应指数71、68、66、94、100。2024—2025年的峰值高于前三年，但不是五年逐年增长。 3）地区：主词相对热度前三为汉堡100、巴伐利亚（网页译“拜仁”）96、巴登-符腾堡94；木切菜板为汉堡100、巴登-符腾堡91、萨克森91。地区指数不代表订单或购买力。 【趋势表明】 切菜板属于持续有搜索需求、年末旺季明显的成熟需求。近两年主词旺季热度抬升，值得继续研究；是否能带来新品成交，仍应结合第一表的竞争与销量数据。 | W31: 【总结】 1）季节性：两个词的年末高峰同步，备货与推广应提前于11—12月；不能把平时有需求写成“无季节性”。 2）五年走势：主词2021—2025年各年最高周均在12月；对应指数71、68、66、94、100。2024—2025年的峰值高于前三年，但不是五年逐年增长。 3）地区：主词相对热度前三为汉堡100、巴伐利亚（网页译“拜仁”）96、巴登-符腾堡94；木切菜板为汉堡100、巴登-符腾堡91、萨克森91。地区指数不代表订单或购买力。 【趋势表明】 切菜板属于持续有搜索需求、年末旺季明显的成熟需求。近两年主词旺季热度抬升，值得继续研究；是否能带来新品成交，仍应结合第一表的竞争与销量数据。 | X31: 【总结】 1）季节性：两个词的年末高峰同步，备货与推广应提前于11—12月；不能把平时有需求写成“无季节性”。 2）五年走势：主词2021—2025年各年最高周均在12月；对应指数71、68、66、94、100。2024—2025年的峰值高于前三年，但不是五年逐年增长。 3）地区：主词相对热度前三为汉堡100、巴伐利亚（网页译“拜仁”）96、巴登-符腾堡94；木切菜板为汉堡100、巴登-符腾堡91、萨克森91。地区指数不代表订单或购买力。 【趋势表明】 切菜板属于持续有搜索需求、年末旺季明显的成熟需求。近两年主词旺季热度抬升，值得继续研究；是否能带来新品成交，仍应结合第一表的竞争与销量数据。
