Workbook

Sheet 卖家Sellers
A1: 卖家 | B1: 月销量 | C1: 月销售额($) | D1: 近1年销量 | E1: 近一年销售额($) | F1: 平均价格($) | G1: 市场份额
A2: WaterdropDirect | B2: 23882 | C2: 4810627.7 | D2: 266071 | E2: 53595533 | F2: 201.4332 | G2: 0.26542929
A3: Amazon.com | B3: 35208 | C3: 5008816.8 | D3: 438685 | E3: 62408907 | F3: 142.2636 | G3: 0.3913087
A4: Lifetech Filter | B4: 2742 | C4: 1354548 | D4: 31483 | E4: 15552602 | F4: 494 | G4: 0.030475132
A5: Bluevua Reverse Osmosis Drinking Water System | B5: 2731 | C5: 994084 | D5: 63454 | E5: 23097256 | F5: 364 | G5: 0.030352876
A6: ICEPURE Store | B6: 1497 | C6: 89805.03 | D6: 18771 | E6: 1126072.3 | F6: 59.99 | G6: 0.016637955
A7: SimPure Water | B7: 1453 | C7: 499090.97 | D7: 21977 | E7: 7548879.7 | F7: 343.49 | G7: 0.01614893
A8: OUBI | B8: 972 | C8: 105938.28 | D8: 13739 | E8: 1497413.6 | F8: 108.99 | G8: 0.010803001
A9: Frizzlife solutions | B9: 1313 | C9: 107324.62 | D9: 17126 | E9: 1399879.2 | F9: 81.74 | G9: 0.014592942
A10: SimPure Direct | B10: 3302 | C10: 404131.78 | D10: 46974 | E10: 5749147.9 | F10: 122.39 | G10: 0.036699083
A11: A. O. Smith Water Treatment | B11: 3164 | C11: 230940.36 | D11: 36177 | E11: 2640559.2 | F11: 72.99 | G11: 0.035165324
A12: Aquasana. | B12: 1743 | C12: 217857.57 | D12: 17981 | E12: 2247445.2 | F12: 124.99 | G12: 0.019372048
A13: PUREPLUS FILTERS | B13: 554 | C13: 32680.46 | D13: 7952 | E13: 469088.48 | F13: 58.99 | G13: 0.0061572659
... A37: haochen store | B37: 258 | C37: 6370.02 | D37: 932 | E37: 23011.08 | F37: 24.69 | G37: 0.0028674632

Sheet 品牌Brands
A1: 品牌 | B1: 月销量 | C1: 月销售额($) | D1: 近1年销量 | E1: 近一年销售额($) | F1: 平均价格($) | G1: 市场份额
A2: Waterdrop | B2: 26624 | C2: 5939942.6 | D2: 297554 | E2: 66385730 | F2: 223.10481 | G2: 0.29590442
A3: iSpring | B3: 12298 | C3: 2001450.3 | D3: 138818 | E3: 22592074 | F3: 162.746 | G3: 0.13668241
A4: APEC WATER | B4: 3093 | C4: 472834.64 | D4: 63654 | E4: 9730946.1 | F4: 152.8725 | G4: 0.034376216
A5: Culligan | B5: 2406 | C5: 111193.29 | D5: 19437 | E5: 898280.95 | F5: 46.215 | G5: 0.026740761
A6: CuZn | B6: 1810 | C6: 271409.5 | D6: 21584 | E6: 3236520.8 | F6: 149.95 | G6: 0.020116699
A7: Bluevua | B7: 2731 | C7: 994084 | D7: 63454 | E7: 23097256 | F7: 364 | G7: 0.030352876
A8: ICEPURE | B8: 1497 | C8: 89805.03 | D8: 18771 | E8: 1126072.3 | F8: 59.99 | G8: 0.016637955
A9: Brita | B9: 1105 | C9: 99438.95 | D9: 9482 | E9: 853285.18 | F9: 89.99 | G9: 0.012281189
A10: EXPRESS WATER | B10: 3697 | C10: 950101.27 | D10: 51685 | E10: 13282657 | F10: 256.9925 | G10: 0.041089191
A11: SimPure | B11: 4755 | C11: 932407.95 | D11: 68951 | E11: 13520602 | F11: 196.09 | G11: 0.052848013
A12: Aquasana | B12: 9374 | C12: 1640356.3 | D12: 116606 | E12: 20404884 | F12: 174.99 | G12: 0.1041845
A13: Purewell | B13: 1473 | C13: 167907.27 | D13: 20314 | E13: 2315592.9 | F13: 113.99 | G13: 0.016371214
... A41: PURENAT | B41: 258 | C41: 6370.02 | D41: 932 | E41: 23011.08 | F41: 24.69 | G41: 0.0028674632

Sheet 5.ASIN表完成 US (2)
A1: # | B1: 图片 | C1: ASIN | D1: SKU | E1: 详细参数 | F1: 品牌 | G1: 品牌链接 | H1: 商品标题 | I1: 标题(翻译) | J1: 产品卖点 | K1: 产品卖点(翻译) | L1: 商品详情页链接 | M1: 商品主图 | N1: 父ASIN | O1: 类目路径 | P1: 大类目 | Q1: 大类BSR | R1: 大类BSR增长数 | S1: 大类BSR增长率 | T1: 小类目 | U1: 小类BSR | V1: 月销量 | W1: 月销量增长率 | X1: 月销售额($) | Y1: 子体销量 | Z1: 子体销售额($) | AA1: 变体数 | AB1: 价格($) | AC1: Prime价格($) | AD1: Coupon | AE1: Q&A数 | AF1: 评分数 | AG1: 月新增 评分数 | AH1: 评分 | AI1: 留评率 | AJ1: FBA($) | AK1: 毛利率 | AL1: 评级 | AM1: 上架时间 | AN1: 上架天数 | AO1: 配送方式 | AP1: LQS | AQ1: 卖家数 | AR1: Buybox卖家 | AS1: BuyBox类型 | AT1: 卖家所属地 | AU1: 卖家信息 | AV1: 卖家首页 | AW1: Best Seller标识 | AX1: Amazon's Choice | AY1: CPF绿标 | AZ1: CPF绿标信息 | BA1: New Release标识 | BB1: A+页面 | BC1: 视频介绍 | BD1: SP广告 | BE1: 品牌故事 | BF1: 品牌广告 | BG1: 7天促销 | BH1: AC关键词 | BI1: 商品重量 | BJ1: 商品重量（单位换算） | BK1: 商品尺寸 | BL1: 商品尺寸（单位换算） | BM1: 包装重量 | BN1: 包装重量（单位换算） | BO1: 包装尺寸 | BP1: 包装尺寸（单位换算） | BQ1: 包装尺寸分段
A2: 1 | C2: B083NPW1DN | D2: Size: 1 Year | Color: Black | E2: Brand: Waterdrop | Special Feature: PFAS, PFOA/PFOS and Chlorine Reduction, 12 months, NSF/ANSI 42&372, Easy Installation, Replacement filter: WD-RF10 | Product Dimensions: 3.9"L x 3.6"W x 12.3"H | Package Information: Box | Installation Type: Under Sink | Power Source: Mechanical Water Pressure | Item Weight: 1.31 Kilograms | Model Name: WD-10UA | Maximum Flow Rate: 2.5 Gallons Per Minute | Upper Temperature Rating: 100 Degrees Fahrenheit | F2: Waterdrop | G2: https://www.amazon.com/stores/Waterdrop/page/7BDC626C-1A82-4F74-BCA0-D6ABE6FEDFD4?lp_asin=B083NPW1DN&ref_=ast_bln | H2: Waterdrop 10UA Under Sink Water Filter System, Reduces PFAS, PFOA/PFOS, Lead, Chlorine, Bad Taste & Odor, Under Counter Water Filter Direct Connect to Kitchen Faucet, NSF/ANSI 42 Certified, 1 Year | I2: Waterdrop 10UA 水槽下滤水器系统，减少 PFAS、PFOA/PFOS、铅、氯、不良味道和气味，台下滤水器直接连接到厨房水龙头，经 NSF/ANSI 42 认证，1 年 | J2: Compatibility: Suitable for faucets with 1/2" or 3/8" FEMALE NPT thread. If a female threaded connector is needed to connect to your faucet, please contact us BEFORE purchase. Less than ＄25.99 per replacement filter WD-RF10(Search " B085G66JTZ "on Amazon), save over 50% of cost on subsequent use. [After Sales Assistance] Waterdrop Backs the WD-10UA's high-end technical performance with a comprehensive prorated performance service; should a quality issue arise with the filter, you can contact us. [Innovative Design] Only a cold-water source should be used to power the filter. Its twist-and-lock construction and push-to-connect fittings enable installation in three minutes, three second replacement, and safety-assuring integration. This filter comes with a 3/8" line that connects directly to US sinks' standard 3/8" feed water valves. The system is connected to 1/2" and 3/8" cold water pipes and faucets with the use of the 3/8"-1/2" convertor fitting. [Solve Clogging Problem] By upgrading the filtration area, our filter now provides a 20X increase in dirt adhesion area, enhancing filtration capability while minimizing the risk of clogging. [Filter Replacement and Long Lifespan] This system may be upgraded with a UF or a MZ filter to meet your water needs. It is compatible with several filters with various functions. Each system has a maximum service life of 12 months when used with municipal water, which is sufficient to cover the needs of an entire household. Before going on vacation, please Put the filters in separate sealed plastic bags, and store the bags in your refrigerator (NOT the freezer) to keep it fresh in 30 days. [Wide Application] The filtration system was created for residential and commercial usage, and it can be installed in your kitchen, bathroom, RV, or office to satisfy your daily water demands. This under sink water filter is the finest option for a leased property due to its stunning design and compact size. It is suitable for faucets with a FEMALE thread of 1/2" or 3/8". Please get in touch with us prior to making a purchase if a female threaded connector is required to connect to your faucet. TDS is not a professional way to measure the water quality. Essential Minerals, Calcium, Potassium, Sodium, Magnesium...These essential minerals are dissolved solids, PPM will not be dropping if you test with a TDS meter. Waterdrop undersink water filtration system is keeping all those minerals, but removes elements that are harmful to your body. Note: The activated carbon is made from natural coconut shells. Please confirm whether you are allergic to it. | K2: 兼容性：适用于带 1/2&quot; 或 3/8&quot; NPT 内螺纹的水龙头。如果需要使用内螺纹连接器连接到您的水龙头，请在购买前联系我们。 每个替换过滤器 WD-RF10 的价格不到 25.99 美元（在亚马逊上搜索“B085G66JTZ”），后续使用可节省 50% 以上的成本。如果过滤器出现质量问题，您可以联系我们。 [创新设计]仅应使用冷水源为过滤器供电。其扭锁结构和推接式配件可在三分钟内完成安装，三秒内完成更换，并确保安全集成。该过滤器配有 3/8 英寸管线，可直接连接到美国水槽的标准 3/8 英寸给水阀。该系统使用 3/8&quot;-1/2&quot; 转换器配件连接到 1/2&quot; 和 3/8&quot; 冷水管和水龙头。.[解决堵塞问题]通过升级过滤面积，我们的过滤器现在的污垢粘附面积增加了 20 倍，增强了过滤能力，同时最大限度地降低了堵塞风险。[过滤器更换和长使用寿命]该系统可以升级为 UF 或 MZ 过滤器，以满足您的用水需求。它与多种具有各种功能的过滤器兼容。每个系统与市政用水一起使用时的最长使用寿命为 12 个月，足以满足整个家庭的需求。去度假之前，请将过滤器放入单独的密封塑料袋中，并将袋子存放在冰箱（而非冰柜）中，以在 30 天内保持新鲜。 [广泛应用]该过滤系统专为住宅和商业用途而设计，可以安装在您的厨房、浴室、房车或办公室中，以满足您的日常用水需求。由于其令人惊叹的设计和紧凑的尺寸，这款水槽下滤水器是租赁物业的最佳选择。它适用于带有 1/2&quot; 或 3/8&quot; 内螺纹的水龙头。如果需要将内螺纹连接器连接到您的水龙头，请在购买前与我们联系。TDS 不是测量水质的专业方法。必需矿物质，钙，钾，钠，镁......这些必需矿物质是溶解固体，如果用TDS计测试，PPM不会下降。 Waterdrop 水槽下水过滤系统保留了所有这些矿物质，但去除了对身体有害的元素。注：活性炭由天然椰子壳制成。请确认您是否对此过敏。 | L2: https://www.amazon.com/dp/B083NPW1DN?psc=1 | M2: https://images-na.ssl-images-amazon.com/images/I/41IQFif62EL._AC_US600_.jpg | N2: B0CXPN97KY | O2: Tools & Home Improvement:Kitchen & Bath Fixtures:Water Filtration & Softeners:Under-Sink & Countertop Filtration | P2: Tools & Home Improvement | Q2: 984 | R2: 1685 | S2: 0.6313 | T2: Under-Sink & Countertop Filtration | U2: 1 | V2: 3680 | W2: 0.1019 | X2: 153051.2 | Y2: 3,000 | Z2: 146759.98 | AA2: 4 | AB2: 41.59 | AC2: 41.59 | AE2: 283 | AF2: 12115 | AG2: 497 | AH2: 4.6 | AI2: 0.1351 | AJ2: 7.89 | AK2: 0.6603 | AM2: 2020-01-07 | AN2: 2142 | AO2: FBA | AP2: 10 | AQ2: 1 | AR2: WaterdropDirect | AS2: FBA | AT2: CN | AU2: 公司名称：Qingdao Ecopure Filter Co., Ltd 电话号码：1-888-352-3558 办公地址： 即墨市环保产业园壹胜佰路13号 青岛市 山东省 266200 CN | AV2: https://www.amazon.com/gp/help/seller/at-a-glance.html/ref=dp_merchant_link?seller=A1G97TP4EUQK6R | AW2: Y | AX2: Y | BB2: Y | BC2: Y | BE2: Y | BH2: Amazon's Choice | BI2: 1.31 Kilograms | BJ2: 1.31 kg | BK2: 3.9"L x 3.6"W x 12.3"H | BL2: 9.91 x 9.14 x 31.24 cm | BM2: 3 pounds | BN2: 1.36 kg | BO2: 13.2 x 7.4 x 5.4 inches | BP2: 33.53 x 18.80 x 13.72 cm | BQ2: 大号标准尺寸
A3: 2 | C3: B005LJ8EXU | D3: Style: 6-Stage, Alkaline | Color: Brushed Nickel Faucet | E3: Brand: iSpring | Special Feature: Reduce TDS | Product Dimensions: 15.5"L x 16"W x 18"H | Package Information: Tube | Installation Type: Under Sink | Power Source: No Power Needed | Item Weight: 20 Pounds | Model Name: Reverse Osmosis System | Lower Temperature Rating: 40 Degrees Fahrenheit | Maximum Flow Rate: 284 Liters Per Day | F3: iSpring | G3: https://www.amazon.com/stores/iSpring/page/1D54E265-E27C-47ED-8271-57FA4531484F?lp_asin=B005LJ8EXU&ref_=ast_bln&store_ref=bl_ast_dp_brandLogo_sto | H3: iSpring RCC7AK, NSF Certified, 75 GPD, Alkaline 6-Stage Reverse Osmosis System, pH+ Remineralization RO Water Filter System Under Sink, Patented Top-Mounted Faucet Design for Easy Installation | I3: iSpring RCC7AK，NSF 认证，75 GPD，碱性 6 级反渗透系统，pH+ 再矿化 RO 水过滤系统位于水槽下方，获得专利的顶部安装水龙头设计，易于安装 | J3: PATENTED DESIGN – The top-mounted fastener allows for easy countertop installation entirely from above, eliminating the hassle of tightening the nut from underneath the sink. MINERAL BOOST – The patent-pending natural mineral AK stage delivers spring water with a balanced, healthy pH and multiple essential minerals. SEE WHAT’S CAUGHT – The transparent first-stage filter housing makes it easy to monitor contaminant buildup, ensuring timely filter changes. NSF 58 CERTIFIED RO SYSTEM – Unlike other brands that lack NSF certification or full system certification, our RCC7AK is certified to NSF/ANSI 58 standards for the entire water filtration system. EFFECTIVE FILTRATION – Reduces TDS (93-98%), PFAS (96-99%), Chlorine (95-99%), Asbestos (>99.7%), Barium (>98.4%), Cadmium (>98.8%), Chromium (>99.2%), Copper (>97.8%), Fluoride (>97.4%), Lead (>98.9%), Selenium (>99.0%), and over 1,000 other contaminants. EASY INSTALLATION – The RO water system features a DIY-friendly design with quick-fitting connections, a clear manual, and step-by-step videos for a hassle-free setup. TRUSTWORTHY SUPPORT – America’s favorite RO brand, backed by lifetime technical support in Atlanta, GA, ensuring expert assistance whenever you need it. CONVENIENT REPLACEMENT FILTERS - Easy access to replacement filter sets: F4AK (6-Month), F9K (1-Year), F19K75 (2-Year), and F28K75 (3-Year). | K3: 专利设计 – 顶部安装的紧固件可以轻松地从上方完全安装在台面上，消除了从水槽下方拧紧螺母的麻烦。 矿物质提升 – 正在申请专利的天然矿物质 AK 级提供具有平衡、健康 pH 值和多种必需矿物质的泉水。 看看发现了什么 – 透明的第一级过滤器外壳可以轻松监控污染物堆积，确保及时更换过滤器。 NSF 58 认证 RO 系统 – 不同于其他缺乏 NSF 认证或完整系统认证的品牌，我们的 RCC7AK 整个水过滤系统已通过 NSF/ANSI 58 标准认证。 有效过滤 - 减少 TDS (93-98%)、PFAS (96-99%)、氯 (95-99%)、石棉 (&gt;99.7%)、钡 (&gt;98.4%)、镉 (&gt;98.8%)、铬 (&gt;99.2%)、铜 (&gt;97.8%)、氟化物 (&gt;97.4%)、铅 (&gt;98.9%)、硒 (&gt;99.0%) 和超过 1,000 种其他污染物。值得信赖的支持 – 美国最受欢迎的 RO 品牌，在佐治亚州亚特兰大提供终身技术支持，确保您在需要时随时获得专家帮助。 方便的更换过滤器 - 轻松更换过滤器套件：F4AK（6 个月）、F9K（1 年）、F19K75（2 年）和 F28K75（3 年）。 | L3: https://www.amazon.com/dp/B005LJ8EXU?psc=1 | M3: https://images-na.ssl-images-amazon.com/images/I/81Ius7bMHaL._AC_US600_.jpg | N3: B0FZT1JXGJ | O3: Tools & Home Improvement:Kitchen & Bath Fixtures:Water Filtration & Softeners:Under-Sink & Countertop Filtration | P3: Tools & Home Improvement | Q3: 2257 | R3: -489 | S3: -0.2658 | T3: Under-Sink & Countertop Filtration | U3: 2 | V3: 4249 | W3: 0.2515 | X3: 844701.2 | Y3: 2,000 | Z3: 451920 | AA3: 9 | AB3: 198.8 | AE3: 1000 | AF3: 19665 | AG3: 257 | AH3: 4.7 | AI3: 0.0605 | AJ3: 24.33 | AK3: 0.7276 | AM3: 2011-09-05 | AN3: 5188 | AO3: AMZ | AP3: 10 | AQ3: 1 | AR3: Amazon.com | AS3: AMZ | AW3: Y | AX3: Y | BB3: Y | BC3: Y | BE3: Y | BG3: Y | BH3: Amazon's Choice | BI3: 20 Pounds | BJ3: 9.07 kg | BK3: 15.5 x 16 x 18 inches | BL3: 39.37 x 40.64 x 45.72 cm | BM3: 28.36 pounds | BN3: 12.86 kg | BO3: 23.5 x 17.1 x 12.7 inches | BP3: 59.69 x 43.43 x 32.26 cm | BQ3: 大号大件
A4: 3 | C4: B07P1XFYJP | E4: Brand: Waterdrop | Special Feature: 8-stage Filtration, 600GPD high capacity, 2:1 low drain ratio, Smart display faucet | Product Dimensions: 18.12"L x 5.67"W x 17.72"H | Package Information: Cartridge | Installation Type: Under Sink | Power Source: Corded Electric | Item Weight: 32 Pounds | Model Name: WD-G3P600 | Lower Temperature Rating: 41 Degrees Fahrenheit | Maximum Flow Rate: 0.42 Gallons Per Minute | F4: Waterdrop | G4: https://www.amazon.com/stores/Waterdrop/page/7BDC626C-1A82-4F74-BCA0-D6ABE6FEDFD4?lp_asin=B07P1XFYJP&ref_=ast_bln | H4: Waterdrop G3P600 Reverse Osmosis System, 8 Stage Tankless Reverse Osmosis Water Filter, NSF/ANSI 42 & 53 & 58 & 372 Certified, Under Sink RO System, 2:1 Pure to Drain, Smart LED Faucet | I4: Waterdrop G3P600 反渗透系统，8 级无罐反渗透滤水器，NSF/ANSI 42 &amp; 53 &amp; 58 &amp; 372 认证，水槽下 RO 系统，2:1 纯净排水，智能 LED 水龙头 | J4: 𝐓𝐫𝐮𝐬𝐭𝐞𝐝 𝐜𝐞𝐫𝐭𝐢𝐟𝐢𝐜𝐚𝐭𝐢𝐨𝐧𝐬: Waterdrop G3P600 reverse osmosis system is certified against NSF/ANSI 58 for TDS reduction and NSF/ANSI 372 certified for lead-free material. Also it has been tested and certified against NSF 42 to reduce chlorine, bad taste and odor. The tankless reverse osmosis system is also certified by the Federal Communications Commission. Besides, it meets the EU Standards and UKCA Standards for safety. 𝟖-𝐬𝐭𝐚𝐠𝐞 𝐟𝐢𝐥𝐭𝐫𝐚𝐭𝐢𝐨𝐧: Tested by official third-party laboratory (SGS), the reverse osmosis system can effectively reduce TDS, chromium, PFAS, radium, fluoride, arsenic salt, iron, calcium, particles, chloride, chlorine and radioactive substances in your tap water. And our RO water filter system can reduce chemicals such as vinyl chloride, ethylhexyl acrylate, isobutylene, ethylene glycol, according to the reverse osmosis membrane technical manual. 𝐒𝐦𝐚𝐫𝐭 𝐝𝐢𝐬𝐩𝐥𝐚𝐲 𝐟𝐚𝐮𝐜𝐞𝐭: The tankless reverse osmosis system is built with a smart display faucet. For instance, the TDS monitor tells you the quality of your filtered water, while the filter life tracker shows how soon you need to replace your filter. 𝐇𝐢𝐠𝐡 𝐜𝐚𝐩𝐚𝐜𝐢𝐭𝐲, 𝟐:𝟏 𝐥𝐨𝐰 𝐝𝐫𝐚𝐢𝐧 𝐫𝐚𝐭𝐢𝐨: As an upgraded reverse osmosis system, this reverse osmosis water system produces 600 gallons of filtered water per day. By its low drain ratio, this system can produce only one cup of waste water for every two cups of pure water produced. Furthermore, with a fast and stable water flow rate, this RO system fills a 8 oz cup of water in 8 seconds, which is ideal for drinking and washing vegetables. 𝐓𝐚𝐧𝐤𝐥𝐞𝐬𝐬 𝐝𝐞𝐬𝐢𝐠𝐧: Waterdrop G3P600 reverse osmosis system has a stylish look. This tankless design saves 70% under sink space. You can change a filter in 3 seconds without moving the system or using any tools. Note: This reverse osmosis system requires under-sink electricity. Please measure your cabinet dimensions to ensure that the cabinet size is larger than the product size. The product size is 𝟏𝟖.𝟏𝟐"𝐋 𝐱 𝟓.𝟔𝟕"𝐖 𝐱 𝟏𝟕.𝟕𝟐"𝐇. | K4: Waterdrop G3P600 反渗透系统经过 NSF/ANSI 58 认证，可减少 TDS，经过 NSF/ANSI 372 无铅材料认证。它还经过 NSF 42 测试和认证，可减少氯、异味和异味。无罐反渗透系统还获得了联邦通信委员会的认证。此外，它还符合欧盟标准和UKCA安全标准。。自来水中的镭、氟化物、砷盐、铁、钙、颗粒、氯化物、氯和放射性物质。根据反渗透膜技术手册，我们的RO水过滤系统可以减少氯乙烯、丙烯酸乙基己酯、异丁烯、乙二醇等化学物质。 𝐟𝐚𝐮𝐜𝐞𝐭：无罐反渗透系统配有智能显示水龙头。例如，TDS 监测器会告诉您过滤水的质量，而过滤器寿命跟踪器会显示您需要多长时间更换过滤器。 𝐝𝐫𝐚𝐢𝐧 𝐫𝐚𝐭𝐢𝐨：作为升级的反渗透系统，该反渗透水系统每天产生 600 加仑的过滤水。由于排水比低，该系统每生产两杯纯净水仅产生一杯废水。此外，凭借快速稳定的水流量，该RO系统可在8秒内充满一杯8盎司的水，非常适合饮用和清洗蔬菜。这种无水箱设计可节省 70% 的水槽空间。您可以在 3 秒内更换过滤器，而无需移动系统或使用任何工具。注意：此反渗透系统需要水槽下的电力。请测量您的柜体尺寸，以确保柜体尺寸大于产品尺寸。产品尺寸为𝟏𝟖.𝟏𝟐&quot;𝐋 𝐱 𝟓.𝟔𝟕&quot;𝐖 𝐱 𝟏𝟕.𝟕𝟐&quot;𝐇。 | L4: https://www.amazon.com/dp/B07P1XFYJP?psc=1 | M4: https://images-na.ssl-images-amazon.com/images/I/61PV-FYQwVL._AC_US600_.jpg | N4: B07P1XFYJP | O4: Tools & Home Improvement:Kitchen & Bath Fixtures:Water Filtration & Softeners:Under-Sink & Countertop Filtration | P4: Tools & Home Improvement | Q4: 4271 | R4: 72 | S4: 0.0166 | T4: Under-Sink & Countertop Filtration | U4: 3 | V4: 2382 | W4: 0.4373 | X4: 1021878 | Y4: 2,000 | Z4: 873980 | AA4: 1 | AB4: 429 | AE4: 752 | AF4: 3543 | AG4: 62 | AH4: 4.5 | AI4: 0.026 | AJ4: 27.57 | AK4: 0.7857 | AM4: 2019-02-20 | AN4: 2463 | AO4: FBA | AP4: 9.9 | AQ4: 5 | AR4: Lifetech Filter | AS4: FBA | AT4: US | AU4: 公司名称：LifeTech Filter LLC 办公地址： 21609 PARKVIEW CT WALNUT CA 91789 US | AV4: https://www.amazon.com/gp/help/seller/at-a-glance.html/ref=dp_merchant_link?seller=A3ONK17DX2DX3D | AX4: Y | AY4: Y | AZ4: Carbon impact (ClimatePartner certified) | BB4: Y | BC4: Y | BE4: Y | BH4: Amazon's Choice | BI4: 32 Pounds | BJ4: 14.51 kg | BK4: 18.12"L x 5.67"W x 17.72"H | BL4: 46.02 x 14.40 x 45.01 cm | BM4: 34.25 pounds | BN4: 15.54 kg | BO4: 21.5 x 20.7 x 15.1 inches | BP4: 54.61 x 52.58 x 38.35 cm | BQ4: 大号大件
A5: 4 | C5: B083NR5DVY | D5: Color: Black-basic | E5: Brand: Waterdrop | Special Feature: PFAS, PFOA/PFOS and Chlorine Reduction, 24 months, NSF/ANSI 372&42, Easy Installation, Replacement filter: WD-RF15 | Product Dimensions: 3.9"L x 3.6"W x 16.7"H | Package Information: Cartridge | Installation Type: Under Sink | Power Source: Corded Electric | Model Name: WD-15UA | Maximum Flow Rate: 0.75 Gallons Per Minute | UPC: 840814170847 | Manufacturer: Waterdrop | F5: Waterdrop | G5: https://www.amazon.com/stores/Waterdrop/page/7BDC626C-1A82-4F74-BCA0-D6ABE6FEDFD4?lp_asin=B083NR5DVY&ref_=ast_bln | H5: Waterdrop 15UA Under Sink Water Filter System, 2 Years, Reduces Lead, Chlorine, Bad Taste & Odor, Under Counter Water Filter Direct Connect to Kitchen Faucet, NSF/ANSI 42 Certified, USA Tech | I5: Waterdrop 15UA 水槽下滤水器系统，2 年，减少铅、氯、异味和异味，台下滤水器直接连接到厨房水龙头，经 NSF/ANSI 42 认证，美国技术 | J5: Less than ＄35.99 per replacement filter WD-RF15(Search " B085G78F7R "on Amazon), save over 50% of cost on subsequent use. 𝐔𝐥𝐭𝐫𝐚-𝐋𝐨𝐧𝐠 𝐒𝐞𝐫𝐯𝐢𝐜𝐞 𝐋𝐢𝐟𝐞:When used with municipal water, each under sink water filtration system has a maximum service life of 24 months.[1] Before going on vacation, please Put the filters in separate sealed plastic bags, and store the bags in your refrigerator (NOT the freezer) to keep it fresh in 30 days. 𝐈𝐧𝐧𝐨𝐯𝐚𝐭𝐢𝐯𝐞 𝐌𝐮𝐥𝐭𝐢𝐬𝐭𝐚𝐠𝐞 𝐅𝐢𝐥𝐭𝐫𝐚𝐭𝐢𝐨𝐧:The Waterdrop Direct Connect Under Sink Water Filtration System uses innovative multistage filtration. And it can effectively reduces PFAS, PFOA/PFOS, lead, chlorine, heavy metals, chemical iṁpurity, sediment and other large particles.[2] Enjoy healthy and pure water straight from your tap – no need to buy bottled water anymore! 𝐒𝐨𝐥𝐯𝐞 𝐂𝐥𝐨𝐠𝐠𝐢𝐧𝐠 𝐏𝐫𝐨𝐛𝐥𝐞𝐦: By upgrading the filtration area, our filter now provides a 20X increase in dirt adhesion area, enhancing filtration capability while minimizing the risk of clogging. 𝐈𝐀𝐏𝐌𝐎 𝐂𝐞𝐫𝐭𝐢𝐟𝐢𝐞𝐝 𝐅𝐢𝐥𝐭𝐞𝐫: Made from premium BPA-free and lead-free materials, the under sink water filter is certified by IAPMO against NSF/ANSI 372 Standard, ensuring reliable use from inside to outside. Certified by IAPMO against NSF/ANSI 42 Standard, the water filter can effectively reduce chlorine, taste and odor. Tested by third party laboratory against NSF/ANSI 53 standard it can reduce lead. To look over the 42&372 certification, please search "WD-15UA" on IAPMO website. 𝐄𝐚𝐬𝐲 𝐈𝐧𝐬𝐭𝐚𝐥𝐥𝐚𝐭𝐢𝐨𝐧: The system should be connected only to a cold water supply. With innovative push-to-connect fittings, the entire installation process takes less than 3 minutes. The design ensures that you can replace the filter in 3 seconds. The system includes a 3/8” hose with a direct connection that adapts to standard 3/8’’ feed water valves under US sinks. The 3/8’’–1/2’’ convertor fitting helps you connect the system to both 1/2’’ and 3/8’’ cold water lines and faucets. 𝐅𝐚𝐬𝐭 𝐅𝐥𝐨𝐰 𝐑𝐚𝐭𝐞 & 𝐌𝐮𝐥𝐭𝐢𝐩𝐥𝐞 𝐔𝐬𝐞𝐬: The fast and stable water supply provides pure and fresh water that tastes like spring water. The tested full flow rate is 0.75 gpm at 60 psi. Developed for household and commercial use, the Under Sink Water Filter System can be installed in your kitchen, bathroom, RV, or office to meet your daily water needs. Ideal for drinking, cooking, skincare, and cleaning. 𝐓𝐃𝐒 is not a professional way to measure the water quality. Essential Minerals, Calcium, Potassium, Sodium, Magnesium...These essential minerals are dissolved solids, PPM will not be dropping if you test with a TDS meter. Waterdrop undersink water filtration system is keeping all those minerals, but removes elements that are harmful to your body. 𝐍𝐨𝐭𝐞: The activated carbon is made from natural coconut shells. Please confirm whether you are allergic to it. 𝐀𝐭𝐭𝐞𝐧𝐭𝐢𝐨𝐧: The extended filter life of this filter requires more filter materials, resulting in a larger product size. Please verify the dimensions of your undersink space before making a purchase. | K5: 每个替换过滤器 WD-RF15 不到 35.99 美元（在亚马逊上搜索“B085G78F7R”），后续使用可节省 50% 以上的成本。 𝐋𝐢𝐟𝐞：与市政用水一起使用时，每个水槽下的水过滤系统的最长使用寿命为24个月。[1]去度假之前，请将过滤器放入单独的密封塑料袋中，并将袋子存放在冰箱（而不是冷冻柜）中，以在 30 天内保持新鲜。 𝐌𝐮𝐥𝐭𝐢𝐬𝐭𝐚𝐠𝐞 𝐅𝐢𝐥𝐭𝐫𝐚𝐭𝐢𝐨𝐧：Waterdrop 直接连接水槽下水过滤系统采用创新的多级过滤。并能有效降低PFAS、PFOA/PFOS、铅、氯、重金属、化学杂质、沉积物等大颗粒物。[2]直接从水龙头享用健康纯净的水 - 不再需要购买瓶装水！污垢粘附面积增加 20 倍，增强过滤能力，同时最大限度地降低堵塞风险。水槽下滤水器经过 IAPMO 认证，符合 NSF/ANSI 372 标准，确保从内到外的可靠使用。该滤水器已通过 IAPMO 认证，符合 NSF/ANSI 42 标准，可有效减少氯、味道和气味。经第三方实验室根据 NSF/ANSI 53 标准进行测试，它可以减少铅。要查看 42 和 372 认证，请在 IAPMO 网站上搜索“WD-15UA”。凭借创新的推接式配件，整个安装过程只需不到 3 分钟。该设计确保您可以在 3 秒内更换过滤器。该系统包括一根直接连接的 3/8” 软管，适用于美国水槽下的标准 3/8&#39;&#39; 给水阀。3/8&#39;&#39;–1/2&#39;&#39; 转换器配件可帮助您将系统连接到 1/2&#39;&#39; 和 3/8&#39;&#39; 冷水管线和水龙头。 𝐑𝐚𝐭𝐞 &amp; 𝐌𝐮𝐥𝐭𝐢𝐩𝐥𝐞 𝐔𝐬𝐞𝐬：快速稳定的供水提供纯净新鲜的水，味道像泉水。经测试，在 60 psi 下，全流量为 0.75 gpm。水槽水过滤系统可以安装在您的厨房、浴室、房车或办公室，以满足您的日常用水需求。𝐓𝐃𝐒不是测量必需矿物质、钙、钾、钠、镁...这些必需矿物质是溶解固体的专业方法，如果您使用 TDS 水过滤系统进行测试，PPM 不会下降。 𝐍𝐨𝐭𝐞：活性炭由天然椰子壳制成，请确认您是否对其过敏。𝐀𝐭𝐭𝐞𝐧𝐭𝐢𝐨𝐧：延长过滤器的使用寿命需要更多的过滤材料，导致产品尺寸较大。在购买之前。 | L5: https://www.amazon.com/dp/B083NR5DVY?psc=1 | M5: https://images-na.ssl-images-amazon.com/images/I/61YfVXLGV8L._AC_US600_.jpg | N5: B0FX9M4CK7 | O5: Tools & Home Improvement:Kitchen & Bath Fixtures:Water Filtration & Softeners:Under-Sink & Countertop Filtration | P5: Tools & Home Improvement | Q5: 4810 | R5: -1699 | S5: -0.5465 | T5: Under-Sink & Countertop Filtration | U5: 4 | V5: 3215 | W5: 0.0174 | X5: 180007.86 | Y5: 2,000 | Z5: 130640 | AA5: 4 | AB5: 55.99 | AC5: 55.99 | AE5: 219 | AF5: 7511 | AG5: 137 | AH5: 4.5 | AI5: 0.0426 | AJ5: 8.18 | AK5: 0.7039 | AM5: 2020-01-07 | AN5: 2142 | AO5: FBA | AP5: 10 | AQ5: 1 | AR5: WaterdropDirect | AS5: FBA | AT5: CN | AU5: 公司名称：Qingdao Ecopure Filter Co., Ltd 电话号码：1-888-352-3558 办公地址： 即墨市环保产业园壹胜佰路13号 青岛市 山东省 266200 CN | AV5: https://www.amazon.com/gp/help/seller/at-a-glance.html/ref=dp_merchant_link?seller=A1G97TP4EUQK6R | AW5: Y | AX5: Y | BB5: Y | BC5: Y | BE5: Y | BH5: Amazon's Choice | BI5: 3.52 pounds | BJ5: 1.60 kg | BK5: 3.9"L x 3.6"W x 16.7"H | BL5: 9.91 x 9.14 x 42.42 cm | BM5: 3.53 pounds | BN5: 1.60 kg | BO5: 17.7 x 7.5 x 5.5 inches | BP5: 44.96 x 19.05 x 13.97 cm | BQ5: 大号标准尺寸
A6: 5 | C6: B08DXYL81C | D6: Style: 1 Mineral Filter | F6: Waterdrop | G6: https://www.amazon.com/stores/Waterdrop/page/7BDC626C-1A82-4F74-BCA0-D6ABE6FEDFD4?lp_asin=B08DXYL81C&ref_=ast_bln | H6: Waterdrop Remineralization Filter WD-MNR35, 1/4" Quick Connect Mineral Filter for Reverse Osmosis System, Restore Essential Minerals for RO System, RO Mineral, Under Sink Water Filtration | I6: 水滴再矿化过滤器 WD-MNR35，用于反渗透系统的 1/4&quot; 快速连接矿物质过滤器，恢复 RO 系统的必需矿物质，RO 矿物质，水槽下水过滤 | J6: 𝐓𝐡𝐢𝐬 𝐑𝐎 𝐫𝐞𝐦𝐢𝐧𝐞𝐫𝐚𝐥𝐢𝐳𝐚𝐭𝐢𝐨𝐧 𝐟𝐢𝐥𝐭𝐞𝐫 𝐢𝐬 𝐚𝐛𝐥𝐞 𝐭𝐨 𝐥𝐚𝐬𝐭 𝟗-𝟏𝟐 𝐦𝐨𝐧𝐭𝐡𝐬, for better filtration, suggest to replace after 9 month.【𝐏𝐥𝐞𝐚𝐬𝐞 𝐍𝐨𝐭𝐞】The WD-MNR35 filter is 𝐧𝐨𝐭 𝐜𝐨𝐦𝐩𝐚𝐭𝐢𝐛𝐥𝐞 𝐰𝐢𝐭𝐡 𝐭𝐡𝐞 𝐗 𝐬𝐞𝐫𝐢𝐞𝐬 𝐚𝐧𝐝 𝐆𝟓 𝐬𝐞𝐫𝐢𝐞𝐬 Reverse Osmosis System. 𝗦𝗽𝗿𝗶𝗻𝗴 𝘄𝗮𝘁𝗲𝗿 𝗳𝗿𝗼𝗺 𝘁𝗮𝗽: This RO remineralization filter as an independent water filter is designed to compatible with 1/4” quick connect tubing. It could connect with most reverse osmosis water systems on the market or under-sink water filtration system, which let you enjoy “spring water” coming from your tap. 𝗠𝗶𝗻𝗲𝗿𝗮𝗹𝗶𝘇𝗮𝘁𝗶𝗼𝗻: Waterdrop reverse osmosis remineralization system adopts PCC technology to activate the crystalline structure of minerals, simulates the formation mechanisms of mineral spring to activate every mineral and guarantees product’s quality. Now people can drink healthy water straight at home with a safe product. 𝗦𝗲𝗹𝗲𝗰𝘁𝗲𝗱 𝗻𝗮𝘁𝘂𝗿𝗮𝗹 𝗺𝗶𝗻𝗲𝗿𝗮𝗹𝘀: The RO remineralization filter selects natural materials to restore minerals like calcium, magnesium, sodium, potassium, etc. Drinking this RO mineral water will, in the long run, help avoid chronic diseases, slow down the aging process,and improve digestion and immunity. 𝗖𝗼𝘀𝘁 𝗲𝗳𝗳𝗰𝗶𝗲𝗻𝘁𝗹𝘆: This RO remineralization filter is able to last 9-12 months or 1,100 gallons, whichever comes first. Up to 8300 single-used bottles and $12600 spent on bottled mineral water can be saved. Please Note: The mineralized filter cannot be connected to the hot water pipe. 𝗘𝗮𝘀𝘆 𝗶𝗻𝘀𝘁𝗮𝗹𝗹𝗹𝗮𝘁𝗶𝗼𝗻: 1/4" quick-connect fittings, it can be easy connected and disconnected during filter change-outs. You can simply plug or unplug the tubing without any tools! You could use the remineralization filter in different ways. This filter can also be connected to refrigerators or RO water purifiers. You can also directly install it under your kitchen sink. | K6: 𝐓𝐡𝐢𝐬𝐑𝐎𝐫𝐞𝐦𝐢𝐧𝐞𝐫𝐚𝐥𝐢𝐳𝐚𝐭𝐢𝐨𝐧𝐟𝐢𝐥𝐭𝐞𝐫 𝐢𝐬 𝐚𝐛𝐥𝐞 𝐭𝐨 𝐥𝐚𝐬𝐭 𝟗-𝟏𝟐 𝐦𝐨𝐧𝐭𝐡𝐬，为了更好的过滤，建议9后更换【𝐏𝐥𝐞𝐚𝐬𝐞 𝐍𝐨𝐭𝐞】WD-MNR35 滤镜是𝐧𝐨𝐭 𝐜𝐨𝐦𝐩𝐚𝐭𝐢𝐛𝐥𝐞反渗透系统。𝗦𝗽𝗿𝗶𝗻𝗴𝘄𝗮𝘁𝗲𝗿𝗳𝗿𝗼𝗺𝘁𝗮𝗽：此RO再矿化过滤器作为独立的水过滤器设计与1/4“快速连接管兼容。它可以与大多数反渗透水系统连接市场或水槽下的水过滤系统，让您享受来自水龙头的“泉水”。 𝗠𝗶𝗻𝗲𝗿𝗮𝗹𝗶𝘇𝗮𝘁𝗶𝗼𝗻：水滴反渗透再矿化系统采用PCC技术激活矿物质的晶体结构，模拟矿泉的形成机制以激活每种矿物质并保证产品的质量。现在人们可以在家中使用安全的产品直接饮用健康的水。 RO再矿化过滤器选择天然材料来恢复钙、镁、钠、钾等矿物质。从长远来看，饮用这种RO矿泉水将有助于避免慢性疾病，减缓衰老过程，并改善消化和免疫力。再矿化过滤器可持续使用 9-12 个月或 1,100 加仑，以先到者为准。最多可节省 8300 个一次性瓶子和 12600 美元的瓶装矿泉水费用。请注意：矿化过滤器无法连接到热水管。 𝗶𝗻𝘀𝘁𝗮𝗹𝗹𝗹𝗮𝘁𝗶𝗼𝗻：1/4&quot; 快速连接配件，在更换过滤器时可以轻松连接和断开。您无需任何工具即可轻松插入或拔出管道！您可以通过不同的方式使用再矿化过滤器。该过滤器还可以连接到冰箱或RO净水器。您也可以直接将其安装在厨房水槽下方。 | L6: https://www.amazon.com/dp/B08DXYL81C?psc=1 | M6: https://images-na.ssl-images-amazon.com/images/I/61VtnSk2M9L._AC_US600_.jpg | N6: B0CVVLTLFB | O6: Tools & Home Improvement:Kitchen & Bath Fixtures:Water Filtration & Softeners:Under-Sink & Countertop Filtration | P6: Tools & Home Improvement | Q6: 5084 | R6: 266 | S6: 0.0498 | T6: Under-Sink & Countertop Filtration | U6: 5 | V6: 2001 | W6: 0.0618 | X6: 68013.99 | Y6: 1,000 | Z6: 30230 | AA6: 3 | AB6: 33.99 | AE6: 24 | AF6: 1565 | AG6: 32 | AH6: 4.5 | AI6: 0.016 | AJ6: 4.84 | AK6: 0.7076 | AM6: 2020-07-30 | AN6: 1937 | AO6: FBA | AP6: 10 | AQ6: 1 | AR6: WaterdropDirect | AS6: FBA | AT6: CN | AU6: 公司名称：Qingdao Ecopure Filter Co., Ltd 电话号码：1-888-352-3558 办公地址： 即墨市环保产业园壹胜佰路13号 青岛市 山东省 266200 CN | AV6: https://www.amazon.com/gp/help/seller/at-a-glance.html/ref=dp_merchant_link?seller=A1G97TP4EUQK6R | AX6: Y | BB6: Y | BC6: Y | BE6: Y | BH6: Under-Sink & Countertop Filtration by Waterdrop | BI6: 0.79 Pounds | BJ6: 358.34 g | BK6: 2.6"D x 2.6"W x 11"H | BL6: 6.60 x 6.60 x 27.94 cm | BM6: 0.79 pounds | BN6: 358.34 g | BO6: 10.7 x 2.3 x 2.2 inches | BP6: 27.18 x 5.84 x 5.59 cm | BQ6: 大号标准尺寸
A7: 6 | C7: B00I0ZGOZM | D7: Style: ROES-50 | Size: RO System | E7: Brand: APEC WATER | Special Feature: Reduce TDS | Product Dimensions: 16"L x 5.25"W x 17.5"H | Package Information: Dispenser | Installation Type: Under Sink | Power Source: Ac | Item Weight: 11.3 Kilograms | Model Name: ROES-50 | Lower Temperature Rating: 40 Degrees Fahrenheit | Maximum Flow Rate: 0.03 Gallons Per Minute | F7: APEC WATER | G7: https://www.amazon.com/stores/APECWaterSystems/page/50EE1BBF-F0EF-4395-90D6-6954CDEA105C?lp_asin=B00I0ZGOZM&ref_=ast_bln&store_ref=bl_ast_dp_brandLogo_sto | H7: APEC WATER - Reverse Osmosis Water Filter System (ROES-50) Essence Series - 5-Stage Filtration - 50 GPD - Removes 99.99% of Impurities - DIY Install - WQA Certified - Under Sink Reverse Osmosis System | I7: APEC WATER - 反渗透水过滤系统 (ROES-50) 精华系列 - 5 级过滤 - 50 GPD - 去除 99.99% 的杂质 - DIY 安装 - WQA 认证 - 水槽下反渗透系统 | J7: Only technology to remove up to 99% of impurities including arsenic, chlorine, lead, fluoride, heavy metals, and 1000+ impurities. Max Total Dissolved Solids - 2000 ppm. Feed Water Pressure 40-85 psi WQA Certified System. Premium long-lasting filters used to treat tap water, well water. Provide unlimited clean, refreshing crisp tasting water superior to bottled water America's No.1 rated water filter brand with 20 years of success guaranteeing trouble free, noise-free system for long lasting, dependable, pure drinking water. System comes with 100% lead-free designer faucet, plus Certified JG premium grade tubing and parts to provide safe, impurity-free pure water. Pipe Size:1/4 inches | K7: 唯一能够去除高达 99% 的杂质（包括砷、氯、铅、氟化物、重金属和 1000 多种杂质）的技术。最大总溶解固体 - 2000 ppm。给水压力 40-85 psi，WQA 认证系统。用于处理自来水、井水的优质持久过滤器。提供无限干净、清爽、口感优于瓶装水的水，美国排名第一的水过滤器品牌，拥有 20 年的成功经验，保证无故障、无噪音的系统，提供持久、可靠、纯净的饮用水。系统配有 100% 无铅设计师水龙头，加上经过 JG 认证的优质管道和零件，可提供安全、无杂质的纯净水。管道尺寸：1/4 英寸 | L7: https://www.amazon.com/dp/B00I0ZGOZM?psc=1 | M7: https://images-na.ssl-images-amazon.com/images/I/41bLUJPooWL._AC_US600_.jpg | N7: B0DTWLZ5CB | O7: Tools & Home Improvement:Kitchen & Bath Fixtures:Water Filtration & Softeners:Under-Sink & Countertop Filtration | P7: Tools & Home Improvement | Q7: 5259 | R7: -522 | S7: -0.1022 | T7: Under-Sink & Countertop Filtration | U7: 6 | V7: 2282 | W7: 0.0948 | X7: 527119.2 | Y7: 500 | Z7: 110990 | AA7: 7 | AB7: 230.99 | AE7: 1000 | AF7: 14519 | AG7: 5349 | AH7: 4.4 | AI7: 0 | AJ7: 25.09 | AK7: 0.7414 | AM7: 2014-02-13 | AN7: 4296 | AO7: AMZ | AP7: 9.6 | AQ7: 1 | AR7: Amazon.com | AS7: AMZ | AW7: Y | BB7: Y | BC7: Y | BE7: Y | BI7: 24.91 Pounds | BJ7: 11.30 kg | BK7: 16 x 5.25 x 17.5 inches | BL7: 40.64 x 13.34 x 44.45 cm | BM7: 24.95 pounds | BN7: 11.32 kg | BO7: 23 x 20 x 11.7 inches | BP7: 58.42 x 50.80 x 29.72 cm | BQ7: 大号大件
A8: 7 | C8: B01JIRLRXY | D8: Size: 1 Inch | Style: Clear | E8: Brand: Culligan | Special Feature: Heavy Duty, WQA certified, Rust Resistant | Product Dimensions: 8.26"L x 7.48"W x 16.33"H | Package Information: Cartridge,Cartridges | Installation Type: In Line | Power Source: Not Powered | Item Weight: 3 Pounds | Model Name: Whole House Sediment Water Filter | Maximum Flow Rate: 10 Gallons Per Minute | Supported Water TDS Level Maximum (PPM): 600 | F8: Culligan | G8: https://www.amazon.com/stores/CulliganWater/page/726C890E-E539-482E-BEFA-9BBA03F58D3F?lp_asin=B01JIRLRXY&ref_=ast_bln&store_ref=bl_ast_dp_brandLogo_sto | H8: Culligan WH-HD200-C Whole House Water Filter System 1” Inlet/Outlet – Improve Tap Water Taste, Remove Sediment, Protect Appliances | I8: Culligan WH-HD200-C 全屋滤水系统 1 英寸进水口/出水口 – 改善自来水味道，去除沉积物，保护电器 | J8: Whole‑House Heavy‑Duty Filtration: Built for high sediment loads, this point-of-entry system uses 1" stainless-reinforced inlet/outlet to capture dirt, sand, silt, rust, and scale—protecting your entire home’s plumbing and appliances. Compatible with Key Culligan Cartridges: Designed for Culligan heavy-duty replacement cartridges—R50‑BBSA, CW25‑BBS, CP5‑BBS, CW5‑BBS, RFC‑BBSA—offering flexibility to meet your specific filtration needs. High Flow, Large Capacity Performance: Engineered to handle heavy household use with strong water pressure and throughput—ideal for kitchens, laundry, outdoor faucets, and more. Easy Maintenance with Built-in Bypass: Integrated bypass shut-off valve allows for uninterrupted service during filter changes. Includes mounting bracket, housing wrench, and filter life monitor with battery for effortless maintenance. Reliable, Certified Construction: Certified by WQA/CSA for low-lead compliance and NSF/ANSI standards for structural integrity and material safety. Durable, clear housing enables visual filter checks without disassembly. | K8: 全屋重型过滤：这款入口点系统专为高沉积物负载而设计，使用 1 英寸不锈钢加固入口/出口来捕获污垢、沙子、淤泥、铁锈和水垢，从而保护您整个家庭的管道和电器。 与 Culligan 关键滤芯兼容：专为 Culligan 重型替换滤芯设计 - R50-BBSA、CW25-BBS、 CP5‑BBS、CW5‑BBS、RFC‑BBSA — 提供灵活性，满足您的特定过滤需求。 高流量、大容量性能：专为处理重型家庭使用而设计，具有强大的水压和吞吐量 — 非常适合厨房、洗衣房、室外水龙头等。 内置旁路易于维护：集成旁路截止阀可在更换过滤器期间实现不间断服务，包括安装支架、外壳扳手和带电池的过滤器寿命监测器，可轻松实现。可靠、经过认证的结构：经 WQA/CSA 认证，符合低铅要求，并通过 NSF/ANSI 标准的结构完整性和材料安全性认证。耐用、透明的外壳无需拆卸即可进行目视过滤器检查。 | L8: https://www.amazon.com/dp/B01JIRLRXY?psc=1 | M8: https://m.media-amazon.com/images/I/41TsLYGf8nL._SX600_SY600_CR,0,0,600,600_.jpg | N8: B0FM8PQ68G | O8: Tools & Home Improvement:Kitchen & Bath Fixtures:Water Filtration & Softeners:Under-Sink & Countertop Filtration | P8: Tools & Home Improvement | Q8: 5865 | R8: -632 | S8: -0.1196 | T8: Under-Sink & Countertop Filtration | U8: 7 | V8: 1821 | W8: 0.2703 | X8: 106492.08 | Y8: 800 | Z8: 46784 | AA8: 6 | AB8: 58.48 | AE8: 281 | AF8: 6330 | AG8: 30 | AH8: 4.5 | AI8: 0.0165 | AJ8: 9.26 | AK8: 0.6917 | AM8: 2016-08-01 | AN8: 3396 | AO8: AMZ | AP8: 9.9 | AQ8: 33 | AR8: Amazon.com | AS8: AMZ | BB8: Y | BC8: Y | BE8: Y | BG8: Y | BI8: 3 Pounds | BJ8: 1.36 kg | BK8: 8.26 x 7.48 x 16.33 inches | BL8: 20.98 x 19.00 x 41.48 cm | BM8: 8.97 pounds | BN8: 4.07 kg | BO8: 16.7 x 8.5 x 7.8 inches | BP8: 42.42 x 21.59 x 19.81 cm | BQ8: 大号标准尺寸
A9: 8 | C9: B000923524 | D9: Size: 5-Year | E9: Brand: CuZn | Special Feature: Change Filter Indicator, Heavy Duty, Tankless | Product Dimensions: 4.5"L x 4.5"W x 16"H | Package Information: Bottle | Installation Type: Under Sink | Power Source: Adapter | Item Weight: 8 Pounds | Model Name: 1 Gallon Countertop Water Distiller Stainless Steel Distiller L10010100615-1 | EU Spare Part Availability Duration: 5 Years | Supported Water TDS Level Maximum (PPM): 300 | F9: CuZn | G9: https://www.amazon.com/stores/CuZn/page/53C688B0-AB43-4871-B35F-83D54F5C0E8B?lp_asin=B000923524&ref_=ast_bln&store_ref=bl_ast_dp_brandLogo_sto | H9: Under Sink Water Filter for Sink Faucet by CuZn, 5 Year Filtration Life, Reduces PFAs, PFOS, Lead, Chlorine, Improves Taste of Tap Water with NSF/ANSI 42 & 372 Certified High Performance | I9: 用于水槽水龙头的水槽下水过滤器，由 CuZn 制成，过滤寿命为 5 年，减少 PFA、PFOS、铅、氯，改善自来水的味道，具有 NSF/ANSI 42 和 372 认证的高性能 | J9: UNBEATABLE FILTER VALUE: Dollar for dollar nothing compares to performance and value of the UC-200 with an unbeatable 5 year filtration life. Other Under the sink filters last just 6 months, making them exceedingly expensive in comparison to UC-200 3-STAGE FILTRATION: Using a precise blend of Micro Sediment Membranes, KDF-55 and Coconut Shell Carbon, delivering clean, crisp water. The UC-200 purifies without removing beneficial minerals from drinking water INLINE FILTER SIMPLE DIY: Designed for direct connect for kitchen or bathroom sink with minimal space. No drilling required, all installation parts included. How to Install Video Tutorial Instructions Available EFFECTIVE FILTRATION: Independently tested & approved to reduce harmful impurities like PFAs, PFOA/PFOS, Lead, and Chlorine from kitchen or bathroom faucet tap water. NSF/ANSI 42 certified components/material deliver noticably improved water quality AFTER-SALE COMMITMENT: CuZn's backs the UC-200 quality and high filtration performance. Should any issues arise, we advise you contact CuZn support for swift response. NOTE: does not reduce TDS, which can only be performed by reverse osmosis | K9: 无与伦比的过滤器价值： UC-200 具有无与伦比的 5 年过滤寿命，其性能和价值无可比拟。其他水槽下过滤器的使用寿命仅为 6 个月，与 UC-200 相比极其昂贵。三级过滤：使用微沉积膜、KDF-55 和椰壳碳的精确混合，提供干净、清新的水。 UC-200 净化时不会去除饮用水中的有益矿物质。 在线过滤器简单 DIY：专为直接连接厨房或浴室水槽而设计，空间最小。无需钻孔，包括所有安装部件。如何安装提供视频教程说明，有效过滤：经过独立测试和批准，可减少厨房或浴室水龙头自来水中的 PFA、PFOA/PFOS、铅和氯等有害杂质。 NSF/ANSI 42 认证的组件/材料可显着改善水质。 售后承诺：CuZn 支持 UC-200 质量和高过滤性能。如果出现任何问题，我们建议您联系 CuZn 支持部门以获得快速响应。注意：不会降低TDS，只能通过反渗透来实现 | L9: https://www.amazon.com/dp/B000923524?psc=1 | M9: https://images-na.ssl-images-amazon.com/images/I/51EHzzbLaSL._AC_US600_.jpg | N9: B0FHJ4J858 | O9: Tools & Home Improvement:Kitchen & Bath Fixtures:Water Filtration & Softeners:Under-Sink & Countertop Filtration | P9: Tools & Home Improvement | Q9: 6653 | R9: -715 | S9: -0.1205 | T9: Under-Sink & Countertop Filtration | U9: 8 | V9: 1810 | W9: 0.1741 | X9: 271409.5 | Y9: 1,000 | Z9: 147960.02 | AA9: 3 | AB9: 149.95 | AE9: 742 | AF9: 6721 | AG9: 21 | AH9: 4.6 | AI9: 0.0116 | AJ9: 8.91 | AK9: 0.7906 | AM9: 2011-04-08 | AN9: 5338 | AO9: AMZ | AP9: 9.9 | AQ9: 2 | AR9: Amazon.com | AS9: AMZ | AX9: Y | BB9: Y | BC9: Y | BE9: Y | BH9: Amazon's Choice | BI9: 8 Pounds | BJ9: 3.63 kg | BK9: 4.5"L x 4.5"W x 16"H | BL9: 11.43 x 11.43 x 40.64 cm | BM9: 8.25 pounds | BN9: 3.74 kg | BO9: 17.9 x 7.4 x 7 inches | BP9: 45.47 x 18.80 x 17.78 cm | BQ9: 大号标准尺寸
A10: 9 | C10: B0CNPMRFXS | D10: Style: ROPOT-UV | E10: Brand: Bluevua | Special Feature: Built In TDS Meter, Portable, Reduce TDS | Product Dimensions: 10.9"L x 15.4"W x 14.3"H | Package Information: Borosilicate Glass Carafe | Installation Type: Countertop | Power Source: Corded Electric | Item Weight: 23.15 Pounds | Model Name: ROPOT-UV | Lower Temperature Rating: 41 Degrees Fahrenheit | Maximum Flow Rate: 0.26 Liters Per Minute | F10: Bluevua | G10: https://www.amazon.com/stores/Bluevua/page/48B18569-12F8-4319-98F4-3AC86A8714CE?lp_asin=B0CNPMRFXS&ref_=ast_bln&store_ref=bl_ast_dp_brandLogo_sto | H10: Bluevua RO100ROPOT-UV Reverse Osmosis System Countertop Water Filter - 6 Stage Purification with UV and Remineralization, Counter RO Filtration, Portable Water Purifier | I10: Bluevua RO100ROPOT-UV 反渗透系统台面滤水器 - 带紫外线和再矿化的 6 级净化、反渗透过滤、便携式净水器 | J10: 6-STAGE ADVANCED FILTRATION WITH UV LIGHT: The Bluevua RO100ROPOT-UV boasts a superior 6-stage filtration system, featuring a 0.0001μm RO membrane, including UV light and an added remineralization filter. Certified by WQA against NSF/ANSI/CAN 372 for lead-free and tested by SGS, this combination effectively reduces TDS, PFOA, PFOS, Chlorine, Fluoride, Arsenic, Lead, and more, while also enriching water with essential minerals, balancing taste and health benefits. COUNTERTOP FILTRATION + PREMIUM-QUALITY CARAFE: No plumbing or installation is required for this RO system. Simply plug this portable piece of tech into any power source and you're ready to fill it up and go! Better yet, the water container is constructed of a high borosilicate glass carafe instead of the traditional plastic, reducing the risk of secondary pollution and making this one of the best countertop water filter systems. POWER SAVING + WATER SAVING: The water system automatically enters power-saving standby mode when not in use to reduce power consumption. Filters are also designed to help save water with an impressive 2:1 Pure to Drain ratio. Leftover water from a cycle isn't deemed wastewater so more water is saved to use for various household purposes. FILTER LIFE MONITOR: The countertop water filters last for a long time between 12-24 months to provide 1-2 years of clean drinking water before needing replacement. Monitor display shows the service life of filters and water quality so you can easily keep track of filter replacement and periodically switch out filter tubes. SUSTAINABLE HYDRATION: 1-year limited manufacturer warranty included upon registration. Designed with premium quality components for years of reliable use, our RO system delivers bottled-quality water at home, reducing plastic waste and supporting sustainability efforts with ClimatePartner Certification. | K10: 带紫外线的 6 级高级过滤：Bluevua RO100ROPOT-UV 拥有卓越的 6 级过滤系统，采用 0.0001μm RO 膜，包括紫外线和附加的再矿化过滤器。该组合已通过 WQA NSF/ANSI/CAN 372 无铅认证，并通过 SGS 测试，可有效降低 TDS、PFOA、PFOS、氯、氟化物、砷、铅等，同时还富含必需矿物质，平衡口味和健康益处。 台面过滤 + 优质水瓶：该 RO 系统无需管道或安装。只需将这款便携式技术插入任何电源，即可充满电并开始使用！更好的是，水容器由高硼硅玻璃水瓶而不是传统的塑料制成，减少了二次污染的风险，并使之成为最好的台面水过滤系统之一。 省电+节水：水系统在不使用时自动进入省电待机模式，以减少功耗。过滤器还具有令人印象深刻的 2:1 纯排水比，有助于节约用水。循环中剩余的水不被视为废水，因此可以节省更多的水用于各种家庭用途。 过滤器寿命监测器：台面水过滤器可持续使用 12-24 个月，在需要更换之前可提供 1-2 年的清洁饮用水。监视器显示屏显示过滤器的使用寿命和水质，因此您可以轻松跟踪过滤器更换情况并定期更换过滤管。 可持续水合：注册后包含 1 年有限制造商保修。我们的 RO 系统采用优质组件设计，可确保多年可靠使用，可在家中提供瓶装优质水，减少塑料浪费，并通过气候合作伙伴认证支持可持续发展工作。 | L10: https://www.amazon.com/dp/B0CNPMRFXS?psc=1 | M10: https://images-na.ssl-images-amazon.com/images/I/61K2aRVG5wL._AC_US600_.jpg | N10: B0CV7KDHKV | O10: Tools & Home Improvement:Kitchen & Bath Fixtures:Water Filtration & Softeners:Under-Sink & Countertop Filtration | P10: Tools & Home Improvement | Q10: 7505 | R10: -1898 | S10: -0.3387 | T10: Under-Sink & Countertop Filtration | U10: 9 | V10: 1860 | W10: 0.0781 | X10: 760740 | Y10: 1,000 | Z10: 409000 | AA10: 2 | AB10: 409 | AE10: 208 | AF10: 4455 | AG10: 72 | AH10: 4.5 | AI10: 0.0387 | AJ10: 21.11 | AK10: 0.7984 | AM10: 2023-11-16 | AN10: 733 | AO10: FBA | AP10: 10 | AQ10: 2 | AR10: Bluevua Reverse Osmosis Drinking Water System | AS10: FBA | AT10: CN(HK) | AU10: 公司名称：Kflow (HK) Limited 办公地址： FLAT/RM A 12/F ZJ 300, 300 LOCKHART ROAD WAN CHAI HONG KONG 999077 HK | AV10: https://www.amazon.com/gp/help/seller/at-a-glance.html/ref=dp_merchant_link?seller=A36TRWRD1GO68H | AW10: Y | AX10: Y | AY10: Y | AZ10: Carbon impact (ClimatePartner certified) | BB10: Y | BC10: Y | BE10: Y | BH10: Amazon's Choice | BI10: 23.15 Pounds | BJ10: 10.50 kg | BK10: 10.9"L x 15.4"W x 14.3"H | BL10: 27.69 x 39.12 x 36.32 cm | BM10: 23.65 pounds | BN10: 10.73 kg | BO10: 18.2 x 17.7 x 13.7 inches | BP10: 46.23 x 44.96 x 34.80 cm | BQ10: 大号大件
A11: 10 | C11: B08P58F9SG | D11: Color: No Extra Faucet-Chlorine and Fluoride Reduction | Size: 1 Count (Pack of 1) | F11: Waterdrop | G11: https://www.amazon.com/stores/Waterdrop/page/7BDC626C-1A82-4F74-BCA0-D6ABE6FEDFD4?lp_asin=B08P58F9SG&ref_=ast_bln | H11: Waterdrop TSA 8 Layer Under Sink Water Filter System, Under Sink Water Filtration System, Reduces PFAS, PFOA/PFOS, Fluoride, Chlorine, Bad Taste & Odor, NSF/ANSI 42 Certified Element, USA Tech | I11: Waterdrop TSA 8 层水槽下水过滤系统，水槽下水过滤系统，减少 PFAS、PFOA/PFOS、氟化物、氯、不良味道和气味，NSF/ANSI 42 认证元素，美国技术 | J11: 𝐈𝐦𝐩𝐨𝐫𝐭𝐚𝐧𝐭 𝐍𝐨𝐭𝐞: Please be advised that this under sink water filter system will NOT REDUCE TDS. It is specifically designed for municipal tap water and can only be used with cold water sources. It is not suitable for well water or hot water. Suitable for faucets with 1/2" or 3/8" FEMALE NPT thread. Should you need to connect to a quick-connect faucet, please feel free to contact us — we'll be happy to provide free connection fittings. If you need the replacement WD-10PP filter for WD-TSB or WD-TSA under sink water filtration system, please search for B0CM8MHWNT. ASIN of WD-10GC filter is B0CM8KV1M9 and ASIN of WD-10CT filter is B0CM8SDWWD 𝐌𝐨𝐫𝐞 𝐟𝐢𝐥𝐭𝐞𝐫𝐬, 𝐛𝐞𝐭𝐭𝐞𝐫 𝐭𝐚𝐬𝐭𝐞: This under sink water filter system comes with 3 filters and can realize 8-stage deep filtration to reduce PFAS, PFOA/PFOS, residual chlorine, fluorides, heavy metals, silt, rust, cyst, etc. Its KDF materials can effectively reduce heavy metals. Its resin reduces fluorides. The CT filter has passed IAPMO certification to reduce residual chlorine and improve taste, thereby ensuring every drop is pure and healthy 𝐍𝐚𝐭𝐢𝐨𝐧𝐚𝐥 𝐆𝐞𝐨𝐠𝐫𝐚𝐩𝐡𝐢𝐜 𝐑𝐞𝐜𝐨𝐦𝐦𝐞𝐧𝐝𝐞𝐝:The Waterdrop TSA is an under sink water filter recommended by National Geographic. It is compact and easy to install. The filter's space-saving design fits neatly under most sinks, leaving ample room for other plumbing and storage needs. Its quick-connect fittings allow for a straightforward setup that can be completed without hiring a professional 𝐍𝐨 𝐥𝐞𝐚𝐤𝐢𝐧𝐠 𝐨𝐫 𝐜𝐫𝐚𝐜𝐤𝐢𝐧𝐠 𝐰𝐢𝐭𝐡 𝐡𝐢𝐠𝐡𝐥𝐲 𝐩𝐫𝐞𝐜𝐢𝐬𝐞𝐝 𝐭𝐞𝐜𝐡𝐧𝐢𝐪𝐮𝐞: The under sink water filter adopts strong materials with an upgraded design. In addition, the age-resistant and freeze-resistant materials make the system twice thicker. The under counter water filter system for kitchen has also passed 400 psi burst pressure, 100,000+ pulse tests at 150 psi, and static tests at 300 psi. These tests prove that the durable integral design clears up worries about cracking cases and leaking issue 𝐒𝐨𝐥𝐯𝐞 𝐂𝐥𝐨𝐠𝐠𝐢𝐧𝐠 𝐏𝐫𝐨𝐛𝐥𝐞𝐦:By upgrading the filtration area, our filter now provides a 20X increase in dirt adhesion area, enhancing filtration capability while minimizing the risk of clogging 𝐋𝐢𝐟𝐞𝐬𝐩𝐚𝐧 𝐨𝐟 𝐮𝐩 𝐭𝐨 𝟏𝟖 𝐦𝐨𝐧𝐭𝐡𝐬: The three under sink water filters have lifespans of 6 months, 8-12 months, and 12-18 months, respectively. Before going on vacation, please Put the filters in separate sealed plastic bags, and store the bags in your refrigerator (NOT the freezer) to keep it fresh in 30 days. 𝟑𝐦𝐢𝐧 𝐢𝐧𝐬𝐭𝐚𝐥𝐥𝐚𝐭𝐢𝐨𝐧, 𝟑𝐬 𝐫𝐞𝐩𝐥𝐚𝐜𝐞𝐦𝐞𝐧𝐭: This under sink water filter system works perfectly with 3/8” and 1/2” cold water tubes. The under sink water filtration system is a simple DIY. With innovative push-to-connect fittings, the installation of the under sink water filter system takes less than 3 minutes. In addition, the twist-and-lock design lets you replace each filter in just 3 seconds 𝐂𝐚𝐧𝐧𝐨𝐭 𝐟𝐢𝐥𝐭𝐞𝐫 𝐰𝐞𝐥𝐥 𝐰𝐚𝐭𝐞𝐫 𝐨𝐫 𝐡𝐨𝐭 𝐰𝐚𝐭𝐞𝐫：Only a cold-water source should be used to power the filter. This system is designed for Municipal Tap Water. If using well water as the source, please make sure the feed water has been through a pre-filtration system. For the solution with a pre-filtration system, please search for WD-PFK. 𝐆𝐨𝐨𝐝 𝐬𝐞𝐫𝐯𝐢𝐜𝐞：With a stable water flow, this under sink water filter provides all-round protection for drinking or usage. The carbon block is made from natural coconut shells. Please confirm whether you are allergic to it. TDS is not a professional way to measure the water quality. Essential Minerals, Calcium, Potassium, Sodium, Magnesium... These essential minerals are dissolved solids, PPM will not be dropping if you test with a TDS meter. Waterdrop undersink water filtration system is keeping all those minerals, but removes elements that are harmful to your body. | K11: 𝐈𝐦𝐩𝐨𝐫𝐭𝐚𝐧𝐭 𝐍𝐨𝐭𝐞：请注意，该水槽下滤水系统不会降低 TDS。它是专为市政自来水设计的，只能与冷水源一起使用。不适用于井水或热水。适用于带 1/2&quot; 或 3/8&quot; NPT 内螺纹的水龙头。如果您需要连接到快速连接水龙头，请随时与我们联系 — 我们很乐意提供免费连接配件。 如果您需要水槽下水过滤系统的 WD-TSB 或 WD-TSA 的替换 WD-10PP 过滤器，请搜索 B0CM8MHWNT。 WD-10GC 过滤器的 ASIN 为 B0CM8KV1M9，WD-10CT 过滤器的 ASIN 为 B0CM8SDWWD,𝐌𝐨𝐫𝐞 𝐟𝐢𝐥𝐭𝐞𝐫𝐬, 𝐛𝐞𝐭𝐭𝐞𝐫 𝐭𝐚𝐬𝐭𝐞：这款水槽下滤水系统配有3个过滤器，可实现8级深层过滤，减少PFAS、PFOA/PFOS、余氯、氟化物、重金属、淤泥、铁锈、囊肿等。其KDF材料可有效减少重金属。其树脂可减少氟化物。 CT过滤器通过IAPMO认证，减少余氯，改善口感，确保每一滴纯净健康，𝐍𝐚𝐭𝐢𝐨𝐧𝐚𝐥 𝐆𝐞𝐨𝐠𝐫𝐚𝐩𝐡𝐢𝐜 𝐑𝐞𝐜𝐨𝐦𝐦𝐞𝐧𝐝𝐞𝐝：Waterdrop TSA 是国家地理推荐的水槽下滤水器。它结构紧凑且易于安装。该过滤器节省空间的设计可以整齐地安装在大多数水槽下方，为其他管道和存储需求留出充足的空间。其快速连接配件可实现简单的设置，无需雇用专业人员即可完成。 𝐡𝐢𝐠𝐡𝐥𝐲 𝐩𝐫𝐞𝐜𝐢𝐬𝐞𝐝 𝐭𝐞𝐜𝐡𝐧𝐢𝐪𝐮𝐞：水槽下滤水器采用坚固的材料和升级的设计。此外，耐老化和抗冻材料使系统厚度增加了一倍。厨房台下滤水系统还通过了 400 psi 爆破压力、150 psi 下 100,000 多次脉冲测试和 300 psi 静态测试。这些测试证明，耐用的整体设计消除了对外壳破裂和泄漏问题的担忧。污垢附着面积增加20倍，增强过滤能力，同时最大限度地降低堵塞风险，𝐋𝐢𝐟𝐞𝐬𝐩𝐚𝐧 𝐨𝐟 𝐮𝐩 𝐭𝐨 𝟏𝟖 𝐦𝐨𝐧𝐭𝐡𝐬：以下三者水槽滤水器的使用寿命分别为6个月、8-12个月和12-18个月。去度假之前，请将过滤器放入单独的密封塑料袋中，并将袋子存放在冰箱（而不是冰箱）中，以在 30 天内保持新鲜。 𝐫𝐞𝐩𝐥𝐚𝐜𝐞𝐦𝐞𝐧𝐭：这款水槽下水过滤系统与 3/8 英寸和 1/2 英寸冷水管完美配合。水槽下的水过滤系统是一个简单的DIY。凭借创新的推接式配件，水槽下滤水器系统的安装时间不到 3 分钟。此外，扭锁设计让您只需 3 秒即可更换每个过滤器。 𝐡𝐨𝐭 𝐰𝐚𝐭𝐞𝐫：只能使用冷水源为过滤器供电。该系统专为市政自来水而设计。如果使用井水作为水源，请确保给水已通过预过滤系统。对于带有预过滤系统的解决方案，请搜索WD-PFK。 𝐆𝐨𝐨𝐝 𝐬𝐞𝐫𝐯𝐢𝐜𝐞：这款水槽下滤水器具有稳定的水流，为饮用或使用提供全方位保护。碳块由天然椰子壳制成。请确认您是否对此过敏。 TDS 并不是专业的水质测量方法。必需矿物质，钙，钾，钠，镁...这些必需矿物质都是溶解固体，如果用TDS计测试，PPM不会下降。 Waterdrop 水槽下水过滤系统保留了所有这些矿物质，但去除了对身体有害的元素。 | L11: https://www.amazon.com/dp/B08P58F9SG?psc=1 | M11: https://images-na.ssl-images-amazon.com/images/I/71S+CjmPG+L._AC_US600_.jpg | N11: B0D8TR1PTH | O11: Tools & Home Improvement:Kitchen & Bath Fixtures:Water Filtration & Softeners:Under-Sink & Countertop Filtration | P11: Tools & Home Improvement | Q11: 8112 | R11: -2165 | S11: -0.3543 | T11: Under-Sink & Countertop Filtration | U11: 10 | V11: 1412 | W11: 0.1518 | X11: 141185.88 | Y11: 1,000 | Z11: 111520 | AA11: 4 | AB11: 99.99 | AC11: 99.99 | AE11: 245 | AF11: 2328 | AG11: 53 | AH11: 4.5 | AI11: 0.0375 | AJ11: 10.19 | AK11: 0.7481 | AM11: 2020-12-17 | AN11: 1797 | AO11: FBA | AP11: 10 | AQ11: 1 | AR11: WaterdropDirect | AS11: FBA | AT11: CN | AU11: 公司名称：Qingdao Ecopure Filter Co., Ltd 电话号码：1-888-352-3558 办公地址： 即墨市环保产业园壹胜佰路13号 青岛市 山东省 266200 CN | AV11: https://www.amazon.com/gp/help/seller/at-a-glance.html/ref=dp_merchant_link?seller=A1G97TP4EUQK6R | AX11: Y | BB11: Y | BC11: Y | BE11: Y | BH11: Amazon's Choice | BI11: 6.9 Pounds | BJ11: 3.13 kg | BK11: 14.88 x 6.65 x 16.93 inches | BL11: 37.80 x 16.89 x 43.00 cm | BM11: 7.08 pounds | BN11: 3.21 kg | BO11: 17.3 x 13.8 x 7.1 inches | BP11: 43.94 x 35.05 x 18.03 cm | BQ11: 大号标准尺寸
A12: 11 | C12: B097YC4VC2 | D12: Color: Pitch black-Includes new dedicated faucet | E12: Material: NSF/ANSI Approved Material Components | Product Dimensions: 4.3"D x 16.8"W x 12.9"H | Item Weight: 7.56 Pounds | External Testing Certification: ANSI, NSF, WQA | Product Benefits: Reduce iṁpurities, retain beneficial minerals | F12: Waterdrop | G12: https://www.amazon.com/stores/Waterdrop/page/7BDC626C-1A82-4F74-BCA0-D6ABE6FEDFD4?lp_asin=B097YC4VC2&ref_=ast_bln | H12: Waterdrop TSB 8 Layer Under Sink Water Filter, Reduces PFAS, PFOA/PFOS, Fluoride, Chlorine, Bad Taste & Odor, with Dedicated Faucet, NSF/ANSI 42 Certified Element, USA Tech Water Filtration System | I12: Waterdrop TSB 8 层水槽下滤水器，减少 PFAS、PFOA/PFOS、氟化物、氯、不良味道和气味，配有专用水龙头，NSF/ANSI 42 认证滤芯，USA Tech 水过滤系统 | J12: [Important Note] Please be advised that this under sink water filter system will NOT REDUCE TDS. It is specifically designed for municipal tap water and can only be used with cold water sources. It is not suitable for well water or hot water. If you need the replacement WD-10PP filter for WD-TSB or WD-TSA under sink water filtration system, please search for B0CM8MHWNT. ASIN of WD-10GC filter is B0CM8KV1M9 and ASIN of WD-10CT filter is B0CM8SDWWD [More filters, better taste] This under sink filter system comes with 3 filters and can realize 8-stage deep filtration to reduce PFAS, PFOA/PFOS, residual chlorine, fluorides, heavy metals, silt, rust, cyst, etc. Its KDF materials can effectively reduce heavy metals. Its fluoride reduction resin reduces 97% of fluorides. This filter has passed IAPMO certification to reduce residual chlorine and improve taste, thereby ensuring every drop is pure and healthy. It also can retain minerals, but cannot reduce TDS. [No leaking or cracking with highly precised technique] The under counter water filter adopts strong materials with an upgraded design. In addition, the age-resistant and freeze-resistant materials make the system twice thicker. The under sink water filter system has also passed 400 psi burst pressure, 100,000+ pulse tests at 150 psi, and static tests at 300 psi. These tests prove that the durable integral design clears up worries about cracking cases and leaking issue. [Solve Clogging Problem] By upgrading the filtration area, our filter now provides a 20X increase in dirt adhesion area, enhancing filtration capability while minimizing the risk of clogging. [Lifespan of up to 18 months] The three under sink water filters have lifespans of 6 months, 8-12 months, and 12-18 months, respectively. This under sink water filter system has a long lifespan. Before going on vacation, please Put the filters in separate sealed plastic bags, and store the bags in your refrigerator (NOT the freezer) to keep it fresh in 30 days. [3min installation, 3s replacement] This under counter water filter system for kitchen works perfectly with 3/8” and 1/2” cold water tubes. The overall installation process does not require the help of a plumber; This under sink water filter is a simple DIY. With innovative push-to-connect fittings, the installation takes less than 3 minutes, with no plumbing experience. In addition, the twist-and-lock design lets you replace each filter in just 3 seconds. [Separate water dispensers for different needs] The under sink water filer system comes with a lead-free brushed stainless faucet, where you can fill a 12 oz cup of water in 5s. In addition, you can use separate water dispensers for different purposes, especially when you don’t need purified water. For example, you can use your original faucet to wash fruits and vegetables. The under sink filter system meets your dual need for both purified water and source water. 𝐂𝐚𝐧𝐧𝐨𝐭 𝐟𝐢𝐥𝐭𝐞𝐫 𝐰𝐞𝐥𝐥 𝐰𝐚𝐭𝐞𝐫 𝐨𝐫 𝐡𝐨𝐭 𝐰𝐚𝐭𝐞𝐫：Only a cold-water source should be used to power the filter. This system is designed for Municipal Tap Water. If using well water as the source, please make sure the feed water has been through a pre-filtration system. For the solution with a pre-filtration system, please search for WD-PFK. [TDS & WATER QUALITY] Heads up — TDS meters aren’t the be-all and end-all of water quality. Why? ‘Cause essential minerals like calcium, potassium, sodium, and magnesium are dissolved solids too. That means your TDS reading might not budge, and that’s actually a good thing! Our Waterdrop under-sink system keeps these beneficial minerals in your water while filtering out the nasty stuff you don’t want. Quick note: Our activated carbon is made from natural coconut shells. So if coconuts aren’t your thing, double-check before you get filtering! | K12: [重要提示] 请注意，这款水槽下滤水系统不会降低 TDS。它是专为市政自来水设计的，只能与冷水源一起使用。不适用于井水或热水。 如果您需要水槽下水过滤系统的 WD-TSB 或 WD-TSA 的替换 WD-10PP 过滤器，请搜索 B0CM8MHWNT。 WD-10GC滤芯的ASIN是B0CM8KV1M9，WD-10CT滤芯的ASIN是B0CM8SDWWD，【更多滤芯，更好口感】这款水槽下过滤系统配有3个滤芯，可实现8级深层过滤，减少PFAS、PFOA/PFOS、余氯、氟化物、重金属、淤泥、铁锈、孢囊等。其KDF材料可有效减少重金属。其氟化物减少树脂可减少97%的氟化物。该滤芯已通过IAPMO认证，减少余氯，改善口感，确保每一滴纯净健康。它还可以保留矿物质，但不能降低 TDS。 [采用高精度技术，不会泄漏或破裂]台下滤水器采用坚固的材料和升级的设计。此外，耐老化和抗冻材料使系统厚度增加了一倍。水槽下水过滤系统还通过了 400 psi 爆破压力、150 psi 下 100,000 多次脉冲测试以及 300 psi 下静态测试。这些测试证明，耐用的整体设计消除了对破裂和泄漏问题的担忧。 [解决堵塞问题]通过升级过滤面积，我们的过滤器现在可将污垢粘附面积增加 20 倍，增强过滤能力，同时最大限度地降低堵塞风险。 [使用寿命长达 18 个月] 三个水槽下滤水器的使用寿命分别为 6 个月、8-12 个月和 12-18 个月。这种水槽下的水过滤系统具有很长的使用寿命。去度假之前，请将过滤器放入单独的密封塑料袋中，并将袋子存放在冰箱（而不是冰箱）中，以在 30 天内保持新鲜。 [3 分钟安装，3 秒更换]这款厨房台下滤水系统与 3/8 英寸和 1/2 英寸冷水管完美配合。整个安装过程不需要水管工的帮助；这款水槽下滤水器是一个简单的 DIY。凭借创新的推接式配件，安装时间不到 3 分钟，无需管道安装经验。此外，扭锁设计让您只需 3 秒即可更换每个过滤器。 [满足不同需求的单独饮水机] 水槽下水过滤器系统配有无铅拉丝不锈钢水龙头，您可以在 5 秒内注满一杯 12 盎司的水。此外，您可以将单独的饮水机用于不同的目的，特别是当您不需要纯净水时。例如，您可以使用原来的水龙头来清洗水果和蔬菜。水槽下过滤系统满足您对纯净水和源水的双重需求。 𝐡𝐨𝐭 𝐰𝐚𝐭𝐞𝐫：只能使用冷水源为过滤器供电。该系统专为市政自来水而设计。如果使用井水作为水源，请确保给水已通过预过滤系统。对于带有预过滤系统的解决方案，请搜索 WD-PFK。 [TDS 和水质] 请注意 — TDS 仪表并不是水质的全部。为什么？因为钙、钾、钠和镁等必需矿物质也是溶解固体。这意味着您的 TDS 读数可能不会改变，这实际上是一件好事！我们的 Waterdrop 水槽下系统将这些有益的矿物质保留在您的水中，同时过滤掉您不想要的有害物质。小提示：我们的活性炭是由天然椰子壳制成的。因此，如果您不喜欢椰子，请在过滤之前仔细检查！ | L12: https://www.amazon.com/dp/B097YC4VC2?psc=1 | M12: https://m.media-amazon.com/images/I/41lC9faRYPL._SX600_SY600_CR,0,0,600,600_.jpg | N12: B0DGGLMXBT | O12: Tools & Home Improvement:Kitchen & Bath Fixtures:Water Filtration & Softeners:Under-Sink & Countertop Filtration | P12: Tools & Home Improvement | Q12: 8279 | R12: 8221 | S12: 0.5025 | T12: Under-Sink & Countertop Filtration | U12: 11 | V12: 1020 | W12: 0.1338 | X12: 111669.6 | Y12: 400 | Z12: 43792 | AA12: 4 | AB12: 109.48 | AC12: 109.48 | AE12: 38 | AF12: 1738 | AG12: 70 | AH12: 4.6 | AI12: 0.0686 | AJ12: 10.19 | AK12: 0.7569 | AM12: 2020-10-29 | AN12: 1846 | AO12: FBA | AP12: 9.9 | AQ12: 1 | AR12: WaterdropDirect | AS12: FBA | AT12: CN | AU12: 公司名称：Qingdao Ecopure Filter Co., Ltd 电话号码：1-888-352-3558 办公地址： 即墨市环保产业园壹胜佰路13号 青岛市 山东省 266200 CN | AV12: https://www.amazon.com/gp/help/seller/at-a-glance.html/ref=dp_merchant_link?seller=A1G97TP4EUQK6R | AX12: Y | BB12: Y | BC12: Y | BE12: Y | BH12: Under-Sink & Countertop Filtration by Waterdrop | BI12: 7.56 Pounds | BJ12: 3.43 kg | BK12: 17.4 x 13.89 x 7.05 inches | BL12: 44.20 x 35.28 x 17.91 cm | BM12: 7.21 pounds | BN12: 3.27 kg | BO12: 17.4 x 14 x 7.1 inches | BP12: 44.20 x 35.56 x 18.03 cm | BQ12: 大号标准尺寸
A13: 12 | C13: B01M1197LW | D13: Style: Chlorine | Pattern Name: Water Filter | E13: Brand: iSpring | Special Feature: Chlorine Reduction, NSF certified | Product Dimensions: 5.98"L x 5.98"W x 22.01"H | Installation Type: Whole House Water Tank | Power Source: Ac | Item Weight: 2.36 Kilograms | Model Name: High Capacity 20” x 4.5” Water Filter | Maximum Flow Rate: 15 Gallons Per Minute | UPC: 662425080250 | Global Trade Identification Number: 00662425080250 | F13: iSpring | G13: https://www.amazon.com/stores/iSpring/page/1D54E265-E27C-47ED-8271-57FA4531484F?lp_asin=B01M1197LW&ref_=ast_bln&store_ref=bl_ast_dp_brandLogo_sto | H13: iSpring FC25B Whole House Water Filter, CTO Carbon Block, 20” x 4.5” for Sediment & Chlorine Removal | I13: iSpring FC25B 全屋滤水器，CTO 碳块，20 英寸 x 4.5 英寸，用于去除沉积物和氯 | J13: Protect Your Family and Household Appliance from Chlorine and More: Say goodbye to smelly, bad tasting water! The FC25B carbon block water filter is specially designed to remove up to 99% of chlorine from water as well as taste and odor compounds, cloudiness, and chemicals. Standard Size: Our FC25B whole house water filter fits standard housings that requires 20” x 4.5” water filter cartridges, including brand name models. The 20” x 4. 5” water filter cartridge has a minimum impact on water flow (up to 15 GPM) and require minimum maintenance Top-Notch Quality: Our FC25B CTO Carbon Block filters are made of high-quality coconut shell activated carbon for maximum filtration efficiency and filter life. Activated carbon is an effective adsorbent because it is a highly porous material and provides a large surface area to which contaminants may adsorb. This whole house water filter is tested by an independent third-party to meet NSF/ANSI standards. Peace of Mind Customer Service: Register online to activate your manufacturer and life-time free tech support from U. S. local support team. We stand behind our products and if you encounter any problems with any of our water filters please reach out to us immediately. We are happy to help! Please Note: The water filter cartridges are individually wrapped to ensure freshness. Please unwrap the cartridges before use. Unlike an RO membrane, the filters don’t reduce Total Dissolved Solids (TDS), and instead keeps healthy minerals in your water. If you are interested in a filter that removes TDS, consider our iSpring Reverse Osmosis (RO) systems. | K13: 保护您的家人和家用电器免受氯等的侵害：告别臭味难闻的水！ FC25B 碳块水过滤器专门设计用于去除水中高达 99% 的氯以及味道和气味化合物、浑浊物和化学物质。 标准尺寸：我们的 FC25B 全屋水过滤器适合需要 20” x 4.5” 水过滤器滤芯的标准外壳，包括品牌型号。 20” x 4. 5” 水过滤器滤芯对水流量的影响最小（高达 15 GPM），并且需要最少的维护。 一流的质量：我们的 FC25B CTO 碳块过滤器由优质椰壳活性炭制成，可实现最大的过滤效率和过滤器寿命。活性炭是一种有效的吸附剂，因为它是一种高度多孔的材料，并提供了可以吸附污染物的大表面积。这款全屋滤水器经过独立第三方测试，符合 NSF/ANSI 标准。 安心的客户服务：在线注册以激活您的制造商和美国当地支持团队的终身免费技术支持。我们为我们的产品提供支持，如果您在使用我们的任何滤水器时遇到任何问题，请立即与我们联系。我们很乐意为您提供帮助！请注意：滤水器滤芯单独包装，以确保新鲜。使用前请打开墨盒的包装。与 RO 膜不同，过滤器不会减少总溶解固体 (TDS)，而是保留水中的健康矿物质。如果您对去除 TDS 的过滤器感兴趣，请考虑我们的 iSpring 反渗透 (RO) 系统。 | L13: https://www.amazon.com/dp/B01M1197LW?psc=1 | M13: https://images-na.ssl-images-amazon.com/images/I/61y2R3tF6qL._AC_US600_.jpg | N13: B08HPGZTJ8 | O13: Tools & Home Improvement:Kitchen & Bath Fixtures:Water Filtration & Softeners:Under-Sink & Countertop Filtration | P13: Tools & Home Improvement | Q13: 8526 | R13: 21891 | S13: 0.7197 | T13: Under-Sink & Countertop Filtration | U13: 12 | V13: 1230 | W13: 0.1463 | X13: 63332.703 | Y13: 400 | Z13: 20596 | AA13: 18 | AB13: 51.49 | AE13: 321 | AF13: 3676 | AG13: 31 | AH13: 4.7 | AI13: 0.0252 | AJ13: 11.23 | AK13: 0.6319 | AM13: 2016-10-05 | AN13: 3331 | AO13: AMZ | AP13: 9.9 | AQ13: 2 | AR13: Amazon.com | AS13: AMZ | AX13: Y | BB13: Y | BC13: Y | BE13: Y | BH13: Amazon's Choice | BI13: 5.2 Pounds | BJ13: 2.36 kg | BK13: 4.5 x 4.5 x 20 inches | BL13: 11.43 x 11.43 x 50.80 cm | BM13: 5.55 pounds | BN13: 2.52 kg | BO13: 21.3 x 5.7 x 5.7 inches | BP13: 54.10 x 14.48 x 14.48 cm | BQ13: 大号大件
