Workbook

Sheet 阶段实际盈亏
A1: 时间 | B1: 实际 | C1: 价格 | D1: 站内 coupon | E1: 站内 code | F1: 站外 折扣 | G1: 站外 订单 | H1: 站内 自然单 | I1: 站内 广告单 | J1: 阶段 销售 订单 | K1: 时间 /天 | L1: 阶段广告费 （出1单广告单预估） | M1: 阶段站外费用 （5美金/单） | N1: 阶段订单 盈亏 | O1: 阶段亏损 /美金 | P1: 六阶段 总亏损 | Q1: 资金ROI | R1: 阶段日均 订单 | S1: 阶段日均 广告订单 | T1: 阶段日均 自然订单 | U1: 新品 排行榜 | V1: 小类目 排名
A2: 9月7-9月12 | B2: 第一阶段 | C2: 99.99 | D2: 0.05 | E2: 0.5 | F2: 0.68 | G2: 58 | H2: 10 | I2: 20 | J2: =SUM(G2:I2) | K2: 6 | L2: =5*I2 | M2: =5*G2 | N2: =SUM(J2) | O2: =SUM(L2:N2) | P2: =SUM(L2:O2) | R2: =J2/7 | S2: =I2/7 | T2: =H2/7
A3: 9月13-9月21 | B3: 第二阶段 | C3: 79.99 | D3: 0.3 | E3: 0.2 | F3: 0.3 | G3: 81 | H3: 14 | I3: 20 | J3: =SUM(G3:I3) | K3: 9 | L3: =5*I3 | M3: =5*G3 | N3: =SUM(J3) | O3: =SUM(L3:N3) | P3: =SUM(L3:O3) | R3: =J3/7 | S3: =I3/7 | T3: =H3/7
A4: 9月22-10月1 | B4: 第三阶段 | C4: 69.99 | D4: 0.3 | E4: 0.2 | F4: 0.25 | G4: 45 | H4: 60 | I4: 23 | J4: =SUM(G4:I4) | K4: 10 | L4: =5*I4 | M4: =5*G4 | N4: =SUM(J4) | O4: =SUM(L4:N4) | P4: =SUM(L4:O4) | R4: =J4/7 | S4: =I4/7 | T4: =H4/7
A5: 10月2-10月11 | B5: 第四阶段 | C5: 69.99 | D5: 0.3 | E5: 0 | F5: 0.25 | G5: 55 | H5: 65 | I5: 30 | J5: =SUM(G5:I5) | K5: 10 | L5: =5*I5 | M5: =5*G5 | N5: =SUM(J5) | O5: =SUM(L5:N5) | P5: =SUM(L5:O5) | R5: =J5/7 | S5: =I5/7 | T5: =H5/7
A6: 10月12-10月21 | B6: 第五阶段 | C6: 69.99 | D6: 0.3 | E6: 0 | F6: 0.25 | G6: 60 | H6: 70 | I6: 30 | J6: =SUM(G6:I6) | K6: 10 | L6: =5*I6 | M6: =5*G6 | N6: =SUM(J6) | O6: =SUM(L6:N6) | P6: =SUM(L6:O6) | R6: =J6/7 | S6: =I6/7 | T6: =H6/7
A7: 10月22-10月31 | B7: 第六阶段 | C7: 69.99 | D7: 0.3 | E7: 0 | F7: 0 | G7: 65 | H7: 80 | I7: 35 | J7: =SUM(G7:I7) | K7: 12 | L7: =5*I7 | M7: =5*G7 | N7: =SUM(J7) | O7: =SUM(L7:N7) | P7: =SUM(L7:O7) | R7: =J7/7 | S7: =I7/7 | T7: =H7/7
A9: 11月1-11月30 | B9: 十一月份 | C9: 69.99 | D9: 0.2 | E9: 0 | F9: 0
A10: 12月1-12月31 | B10: 十二月份 | C10: 69.99 | D10: 0.2 | E10: 0 | F10: 0
A11: 1月1-1月31 | B11: 一月份 | C11: 69.99 | D11: 0.2 | E11: 0 | F11: 0

Sheet 价格策略模拟
B1: 价格策略模拟
A2: 阶段 | B2: 定价 | C2: coupon | D2: code | E2: 折后价 | F2: FBA 配送费 | G2: 亚马逊 佣金 | H2: 账号 回款 | I2: 仓储费+入库配置费 | J2: coupon 费用 | K2: 产品成本 | L2: 物流费 | M2: 退货成本(公式后面加的是单套产品的移除费） | N2: 退货率 | O2: 每单平摊 退货成本 | P2: 每单 毛利 | Q2: 毛利率 | R2: 订单 数量 | S2: 阶段 订单 亏损 | T2: 阶段 订单 总盈亏
A3: 第一阶段 | B3: 79.99 | C3: 0.3 | D3: 0 | E3: =SUM(B3*(1-C3-D3)) | F3: 10.51 | G3: =SUM(E3*8%) | H3: =SUM(E3-F3-G3) | I3: 0.5 | J3: 0.6 | K3: =80/7 | L3: 3 | M3: =SUM(20%*15%*E3+F3+I3+K3+L3+1.04) | N3: 0.044 | O3: =SUM(M3*N3/(1-N3)) | P3: =SUM(H3-I3-J3-K3-L3-O3) | Q3: =SUM(P3/B3) | R3: 1 | S3: =SUM(P3*R3) | T3: =SUM(S3)
A4: 第二阶段 | B4: 85.99 | C4: 0.2 | D4: 0 | E4: =SUM(B4*(1-C4-D4)) | F4: 10.51 | G4: =SUM(E4*8%) | H4: =SUM(E4-F4-G4) | I4: 0.5 | J4: 0.6 | K4: =80/7 | L4: 3 | M4: =SUM(20%*15%*E4+F4+I4+K4+L4+1.04) | N4: 0.044 | O4: =SUM(M4*N4/(1-N4)) | P4: =SUM(H4-I4-J4-K4-L4-O4) | Q4: =SUM(P4/B4) | R4: 1 | S4: =SUM(P4*R4) | T4: =SUM(S4)
A5: 第三阶段 | B5: 89.99 | C5: 0.1 | D5: 0 | E5: =SUM(B5*(1-C5-D5)) | F5: 10.51 | G5: =SUM(E5*8%) | H5: =SUM(E5-F5-G5) | I5: 0.5 | J5: 0 | K5: =80/7 | L5: 3 | M5: =SUM(20%*15%*E5+F5+I5+K5+L5+1.04) | N5: 0.044 | O5: =SUM(M5*N5/(1-N5)) | P5: =SUM(H5-I5-J5-K5-L5-O5) | Q5: =SUM(P5/B5) | R5: 1 | S5: =SUM(P5*R5) | T5: =SUM(S5)
A6: 第四阶段 | B6: 89.99 | C6: 0.05 | D6: 0 | E6: =SUM(B6*(1-C6-D6)) | F6: 10.51 | G6: =SUM(E6*8%) | H6: =SUM(E6-F6-G6) | I6: 0.5 | J6: 0 | K6: =80/7 | L6: 3 | M6: =SUM(20%*15%*E6+F6+I6+K6+L6+1.04) | N6: 0.044 | O6: =SUM(M6*N6/(1-N6)) | P6: =SUM(H6-I6-J6-K6-L6-O6) | Q6: =SUM(P6/B6) | R6: 1 | S6: =SUM(P6*R6) | T6: =SUM(S6)
A7: 第五阶段 | B7: 89.59 | C7: 0.05 | D7: 0 | E7: =SUM(B7*(1-C7-D7)) | F7: 10.51 | G7: =SUM(E7*8%) | H7: =SUM(E7-F7-G7) | I7: 0.5 | J7: 0 | K7: =80/7 | L7: 3 | M7: =SUM(20%*15%*E7+F7+I7+K7+L7+1.04) | N7: 0.044 | O7: =SUM(M7*N7/(1-N7)) | P7: =SUM(H7-I7-J7-K7-L7-O7) | Q7: =SUM(P7/B7) | R7: 1 | S7: =SUM(P7*R7) | T7: =SUM(S7)
A8: 第六阶段 | B8: 89.99 | C8: 0.05 | D8: 0 | E8: =SUM(B8*(1-C8-D8)) | F8: 10.51 | G8: =SUM(E8*8%) | H8: =SUM(E8-F8-G8) | I8: 0.5 | J8: 0 | K8: =80/7 | L8: 3 | M8: =SUM(20%*15%*E8+F8+I8+K8+L8+1.04) | N8: 0.044 | O8: =SUM(M8*N8/(1-N8)) | P8: =SUM(H8-I8-J8-K8-L8-O8) | Q8: =SUM(P8/B8) | R8: 1 | S8: =SUM(P8*R8) | T8: =SUM(S8)
A9: 第七阶段 | B9: 89.99 | C9: 0.05 | D9: 0 | E9: =SUM(B9*(1-C9-D9)) | F9: 10.51 | G9: =SUM(E9*8%) | H9: =SUM(E9-F9-G9) | I9: 0.5 | J9: 0 | K9: =80/7 | L9: 3 | M9: =SUM(20%*15%*E9+F9+I9+K9+L9+1.04) | N9: 0.044 | O9: =SUM(M9*N9/(1-N9)) | P9: =SUM(H9-I9-J9-K9-L9-O9) | Q9: =SUM(P9/B9) | R9: 1 | S9: =SUM(P9*R9) | T9: =SUM(S9)
A10: 竞品日常价格 | B10: 79.99 | C10: 0 | D10: 0 | E10: =SUM(B10*(1-C10-D10)) | F10: 10.51 | G10: =SUM(E10*15%) | H10: =SUM(E10-F10-G10) | I10: 0.5 | J10: 0 | K10: =80/7 | L10: 3 | M10: =SUM(20%*15%*E10+F10+I10+K10+L10+1.46) | N10: 0.044 | O10: =SUM(M10*N10/(1-N10)) | P10: =SUM(H10-I10-J10-K10-L10-O10) | Q10: =SUM(P10/B10) | R10: 1 | S10: =SUM(P10*R10) | T10: =SUM(S10)
A11: 竞品活动价格 | B11: 99.99 | C11: 0.2 | D11: 0 | E11: =SUM(B11*(1-C11-D11)) | F11: 10.51 | G11: =SUM(E11*15%) | H11: =SUM(E11-F11-G11) | I11: 0.5 | J11: 0.6 | K11: =80/7 | L11: 3 | M11: =SUM(20%*15%*E11+F11+I11+K11+L11+1.46) | N11: 0.044 | O11: =SUM(M11*N11/(1-N11)) | P11: =SUM(H11-I11-J11-K11-L11-O11) | Q11: =SUM(P11/B11) | R11: 1 | S11: =SUM(P11*R11) | T11: =SUM(S11)
A12: 竞品链接 | B12: 85.99 | C12: 0.2 | D12: 0 | E12: =SUM(B12*(1-C12-D12)) | F12: 10.51 | G12: =SUM(E12*8%) | H12: =SUM(E12-F12-G12) | I12: 0.5 | J12: 0.6 | K12: =80/7 | L12: 3 | M12: =SUM(20%*15%*E12+F12+I12+K12+L12+1.04) | N12: 0.044 | O12: =SUM(M12*N12/(1-N12)) | P12: =SUM(H12-I12-J12-K12-L12-O12) | Q12: =SUM(P12/B12) | R12: 1 | S12: =SUM(P12*R12) | T12: =SUM(S12)
A13: 竞品链接所在类目 | B13: https://www.amazon.com/gp/bestsellers/pet-supplies/3024205011
A15: 阶段 | B15: 型号 | C15: 采购成本（手写） | D15: 头程 （手写） | E15: FBA费用 （手写） | F15: 平台佣金（8%） | G15: 退货（2%） | H15: 优惠卷兑（2.5%） | I15: 在库成本 | J15: 展示售价 （手写） | K15: 折扣券 （手写） | L15: 实际售价 （手写） | M15: 毛利（不含人工、测评、推广等） | N15: 毛利率 | O15: 毛利/人民币 | P15: 汇率
A16: 第一阶段 | B16: RD01 | C16: =80/7 | D16: 2 | E16: 10.51 | F16: =L16*8% | G16: =L16*2% | H16: =L16*2.5% | I16: =SUM(C16:H16) | J16: 79.99 | K16: 0.3 | L16: 55.59 | M16: =L16-I16 | N16: =M16/L16 | O16: =M16*P16 | P16: 7.1
A17: 第二阶段 | B17: RD02 | C17: =80/7 | D17: 2 | E17: 10.51 | F17: =L17*8% | G17: =L17*2% | H17: =L17*2.5% | I17: =SUM(C17:H17) | J17: 85.99 | K17: 0.2 | L17: 68.79 | M17: =L17-I17 | N17: =M17/L17 | O17: =M17*P17 | P17: 7.1
A18: 第三阶段 | B18: RD03 | C18: =80/7 | D18: 2 | E18: 10.51 | F18: =L18*8% | G18: =L18*2% | H18: =L18*2.5% | I18: =SUM(C18:H18) | J18: 89.99 | K18: 0.1 | L18: 80.99 | M18: =L18-I18 | N18: =M18/L18 | O18: =M18*P18 | P18: 7.1
A20: 竞品日常价格 | C20: 11.43 | D20: 2 | E20: 10.51 | F20: =L20*8% | G20: =L20*2% | H20: =L20*2.5% | I20: =SUM(C20:H20) | J20: 77.99 | K20: =J20/L20 | L20: 79.99 | M20: =L20-I20 | N20: =M20/L20 | O20: =M20*P20 | P20: 7.1
A21: 竞品活动价格 | C21: 11.43 | D21: 2 | E21: 10.51 | F21: =L21*8% | G21: =L21*2% | H21: =L21*2.5% | I21: =SUM(C21:H21) | J21: 79.99 | K21: =J21/L21 | L21: 89.99 | M21: =L21-I21 | N21: =M21/L21 | O21: =M21*P21 | P21: 7.1
A22: 竞品链接 | C22: 11.43 | D22: 2 | E22: 10.51 | F22: =L22*8% | G22: =L22*2% | H22: =L22*2.5% | I22: =SUM(C22:H22) | J22: 77.99 | K22: =J22/L22 | L22: 79.99 | M22: =L22-I22 | N22: =M22/L22 | O22: =M22*P22 | P22: 7.1

Sheet 总表（阶段盈亏）
A1: 阶段盈亏模拟数据
A2: 阶段 | B2: 日期 | C2: 定价 | D2: cou pon | E2: code | F2: 折后价 | G2: 站内 自然单 | H2: 站内 广告单 | I2: 阶段 销售 订单 | J2: 时间 /天 | K2: CPA | L2: 阶段 广告费 | M2: 毛利 盈亏 | N2: 阶段盈亏 /美金 | O2: 评论 数量 | P2: 阶段 日均 订单 | Q2: 阶段 日均 广告单 | R2: 阶段 日均 自然单 | S2: 日均 广告费 | T2: 新品 排行榜 | U2: 小类目 排名 | V2: 备注 | W2: 种子评论费/（开3条VINE，预计来70条评论）,视觉化费用预估3000美金 | X2: 前期亏损/美金 | Y2: 人民币
A3: 第一阶段 | B3: WEEK1 | C3: 89.99 | D3: 0.3 | E3: 0 | F3: =SUM(C3*(1-D3-E3)) | G3: =J3*R3 | H3: =J3*Q3 | I3: 21 | J3: 7 | K3: ='CPC表格'!V4 | L3: =SUM(H3*-K3) | M3: ='毛利盈亏'!T3 | N3: =SUM(L3:M3) | O3: 20 | P3: 3 | Q3: 3 | R3: =SUM(P3-Q3) | S3: =SUM(L3/J3) | T3: 150 | U3: 前300名 | V3: 一开售投放广告 | W3: 3000 | X3: =SUM(N3:N10)+W3 | Y3: =X3*7
B4: WEEK2 | C4: 89.99 | D4: 0.3 | E4: 0 | F4: =SUM(C4*(1-D4-E4)) | G4: =J4*R4 | H4: =J4*Q4 | I4: =SUM(G4:H4) | J4: 7 | K4: ='CPC表格'!V5 | L4: =SUM(H4*-K4) | M4: ='毛利盈亏'!T4 | N4: =SUM(L4:M4) | O4: 25 | P4: 7 | Q4: 5 | R4: =SUM(P4-Q4) | S4: =SUM(L4/J4) | T4: 120 | U4: 前300名 | V4: 一开售投放广告 | W4: 0 | X4: =SUM(N4:N11)+W4 | Y4: =X4*7
B5: WEEK3 | C5: 89.99 | D5: 0.3 | E5: 0 | F5: =SUM(C5*(1-D5-E5)) | G5: =J5*R5 | H5: =J5*Q5 | I5: =SUM(G5:H5) | J5: 7 | K5: ='CPC表格'!V6 | L5: =SUM(H5*-K5) | M5: ='毛利盈亏'!T5 | N5: =SUM(L5:M5) | O5: 30 | P5: 10 | Q5: 6 | R5: =SUM(P5-Q5) | S5: =SUM(L5/J5) | T5: 100 | U5: 前250名 | W5: 0 | X5: =SUM(N5:N12)+W5 | Y5: =X5*7
B6: WEEK4 | C6: 89.99 | D6: 0.3 | E6: 0 | F6: =SUM(C6*(1-D6-E6)) | G6: =J6*R6 | H6: =J6*Q6 | I6: =SUM(G6:H6) | J6: 7 | K6: ='CPC表格'!V7 | L6: =SUM(H6*-K6) | M6: ='毛利盈亏'!T6 | N6: =SUM(L6:M6) | O6: 35 | P6: 12 | Q6: 7 | R6: =SUM(P6-Q6) | S6: =SUM(L6/J6) | T6: 50 | U6: 前250名 | W6: 0 | X6: =SUM(N6:N13)+W6 | Y6: =X6*7
A7: 第二阶段 | B7: WEEK5 | C7: 85.99 | D7: 0.2 | E7: 0 | F7: =SUM(C7*(1-D7-E7)) | G7: =J7*R7 | H7: =J7*Q7 | I7: =SUM(G7:H7) | J7: 7 | K7: ='CPC表格'!V8 | L7: =SUM(H7*-K7) | M7: ='毛利盈亏'!T7 | N7: =SUM(L7:M7) | O7: 40 | P7: 15 | Q7: 9 | R7: =SUM(P7-Q7) | S7: =SUM(L7/J7) | T7: 40 | U7: 前200名 | W7: 0 | X7: =SUM(N7:N14)+W7 | Y7: =X7*7
B8: WEEK6 | C8: 85.99 | D8: 0.2 | E8: 0 | F8: =SUM(C8*(1-D8-E8)) | G8: =J8*R8 | H8: =J8*Q8 | I8: =SUM(G8:H8) | J8: 7 | K8: ='CPC表格'!V9 | L8: =SUM(H8*-K8) | M8: ='毛利盈亏'!T8 | N8: =SUM(L8:M8) | O8: 50 | P8: 18 | Q8: 10 | R8: =SUM(P8-Q8) | S8: =SUM(L8/J8) | T8: 30 | U8: 前200名 | W8: 0 | X8: =SUM(N8:N15)+W8 | Y8: =X8*7
B9: WEEK7 | C9: 85.99 | D9: 0.2 | E9: 0 | F9: =SUM(C9*(1-D9-E9)) | G9: =J9*R9 | H9: =J9*Q9 | I9: =SUM(G9:H9) | J9: 7 | K9: ='CPC表格'!V10 | L9: =SUM(H9*-K9) | M9: ='毛利盈亏'!T9 | N9: =SUM(L9:M9) | O9: 60 | P9: 20 | Q9: 12 | R9: =SUM(P9-Q9) | S9: =SUM(L9/J9) | T9: 20 | U9: 前150名 | W9: 0 | X9: =SUM(N9:N16)+W9 | Y9: =X9*7
B10: WEEK8 | C10: 85.99 | D10: 0.2 | E10: 0 | F10: =SUM(C10*(1-D10-E10)) | G10: =J10*R10 | H10: =J10*Q10 | I10: =SUM(G10:H10) | J10: 7 | K10: ='CPC表格'!V11 | L10: =SUM(H10*-K10) | M10: ='毛利盈亏'!T10 | N10: =SUM(L10:M10) | O10: 70 | P10: 24 | Q10: 12 | R10: =SUM(P10-Q10) | S10: =SUM(L10/J10) | T10: 10 | U10: 前150名 | W10: 0 | X10: =SUM(N10:N17)+W10 | Y10: =X10*7
A11: 第三阶段 | B11: WEEK9 | C11: 85.99 | D11: 0.1 | E11: 0 | F11: =SUM(C11*(1-D11-E11)) | G11: =J11*R11 | H11: =J11*Q11 | I11: =SUM(G11:H11) | J11: 7 | K11: ='CPC表格'!V12 | L11: =SUM(H11*-K11) | M11: ='毛利盈亏'!T11 | N11: =SUM(L11:M11) | O11: 80 | P11: 26 | Q11: 14 | R11: =SUM(P11-Q11) | S11: =SUM(L11/J11) | T11: 10 | U11: 前100名 | W11: 0 | X11: =SUM(N11:N34)+W11 | Y11: =X11*7
B12: WEEK10 | C12: 85.99 | D12: 0.1 | E12: 0 | F12: =SUM(C12*(1-D12-E12)) | G12: =J12*R12 | H12: =J12*Q12 | I12: =SUM(G12:H12) | J12: 7 | K12: ='CPC表格'!V13 | L12: =SUM(H12*-K12) | M12: ='毛利盈亏'!T12 | N12: =SUM(L12:M12) | O12: 90 | P12: 28 | Q12: 15 | R12: 22 | S12: =SUM(L12/J12) | T12: 5 | U12: 前100名 | W12: 0 | X12: =SUM(N12:N35)+W12 | Y12: =X12*7
B13: WEEK11 | C13: 85.99 | D13: 0.1 | E13: 0 | F13: =SUM(C13*(1-D13-E13)) | G13: =J13*R13 | H13: =J13*Q13 | I13: =SUM(G13:H13) | J13: 7 | K13: ='CPC表格'!V14 | L13: =SUM(H13*-K13) | M13: ='毛利盈亏'!T13 | N13: =SUM(L13:M13) | O13: 100 | P13: 30 | Q13: 15 | R13: =P13-Q13 | S13: =SUM(L13/J13) | T13: 5 | U13: 前80名 | W13: 0 | X13: =SUM(N13:N36)+W13 | Y13: =X13*7
B14: WEEK12 | C14: 85.99 | D14: 0.1 | E14: 0 | F14: =SUM(C14*(1-D14-E14)) | G14: =J14*R14 | H14: =J14*Q14 | I14: =SUM(G14:H14) | J14: 7 | K14: ='CPC表格'!V15 | L14: =SUM(H14*-K14) | M14: ='毛利盈亏'!T14 | N14: =SUM(L14:M14) | O14: 110 | P14: 35 | Q14: 16 | R14: 37 | S14: =SUM(L14/J14) | T14: 4 | U14: 前80名 | W14: 0 | X14: =SUM(N14:N37)+W14 | Y14: =X14*7
A15: 第四阶段 | B15: WEEK13 | C15: 79.99 | D15: 0 | E15: 0 | F15: =SUM(C15*(1-D15-E15)) | G15: =J15*R15 | H15: =J15*Q15 | I15: =SUM(G15:H15) | J15: 7 | K15: ='CPC表格'!V16 | L15: =SUM(H15*-K15) | M15: ='毛利盈亏'!T15 | N15: =SUM(L15:M15) | O15: 120 | P15: 40 | Q15: 18 | R15: =SUM(P15-Q15) | S15: =SUM(L15/J15) | T15: 4 | U15: 前50名 | W15: 0 | X15: =SUM(N15:N38)+W15 | Y15: =X15*7
B16: WEEK14 | C16: 79.99 | D16: 0 | E16: 0 | F16: =SUM(C16*(1-D16-E16)) | G16: =J16*R16 | H16: =J16*Q16 | I16: =SUM(G16:H16) | J16: 7 | K16: ='CPC表格'!V17 | L16: =SUM(H16*-K16) | M16: ='毛利盈亏'!T16 | N16: =SUM(L16:M16) | O16: 130 | P16: 45 | Q16: 20 | R16: =SUM(P16-Q16) | S16: =SUM(L16/J16) | T16: 3 | U16: 前50名 | W16: 0 | X16: =SUM(N16:N39)+W16 | Y16: =X16*7
B17: WEEK15 | C17: 79.99 | D17: 0 | E17: 0 | F17: =SUM(C17*(1-D17-E17)) | G17: =J17*R17 | H17: =J17*Q17 | I17: =SUM(G17:H17) | J17: 7 | K17: ='CPC表格'!V18 | L17: =SUM(H17*-K17) | M17: ='毛利盈亏'!T17 | N17: =SUM(L17:M17) | O17: 140 | P17: 50 | Q17: 22 | R17: =SUM(P17-Q17) | S17: =SUM(L17/J17) | T17: 3 | U17: 前20名 | W17: 0 | X17: =SUM(N17:N40)+W17 | Y17: =X17*7
B18: WEEK16 | C18: 79.99 | D18: 0 | E18: 0 | F18: =SUM(C18*(1-D18-E18)) | G18: =J18*R18 | H18: =J18*Q18 | I18: =SUM(G18:H18) | J18: 7 | K18: ='CPC表格'!V19 | L18: =SUM(H18*-K18) | M18: ='毛利盈亏'!T18 | N18: =SUM(L18:M18) | O18: 150 | P18: 70 | Q18: 25 | R18: =SUM(P18-Q18) | S18: =SUM(L18/J18) | T18: 2 | U18: 前20名 | W18: 0 | X18: =SUM(N18:N41)+W18 | Y18: =X18*7
A19: 第五阶段 | B19: WEEK17 | C19: 79.99 | D19: 0 | E19: 0 | F19: =SUM(C19*(1-D19-E19)) | G19: =J19*R19 | H19: =J19*Q19 | I19: =SUM(G19:H19) | J19: 7 | K19: ='CPC表格'!V20 | L19: =SUM(H19*-K19) | M19: ='毛利盈亏'!T19 | N19: =SUM(L19:M19) | O19: 160 | P19: 70 | Q19: 25 | R19: =SUM(P19-Q19) | S19: =SUM(L19/J19) | T19: 2 | U19: 前20名 | W19: 0 | X19: =SUM(N19:N42)+W19 | Y19: =X19*7
B20: WEEK18 | C20: 79.99 | D20: 0 | E20: 0 | F20: =SUM(C20*(1-D20-E20)) | G20: =J20*R20 | H20: =J20*Q20 | I20: =SUM(G20:H20) | J20: 7 | K20: ='CPC表格'!V21 | L20: =SUM(H20*-K20) | M20: ='毛利盈亏'!T20 | N20: =SUM(L20:M20) | O20: 170 | P20: 70 | Q20: 25 | R20: =SUM(P20-Q20) | S20: =SUM(L20/J20) | T20: 2 | U20: 前20名 | W20: 0 | X20: =SUM(N20:N43)+W20 | Y20: =X20*7
B21: WEEK19 | C21: 79.99 | D21: 0 | E21: 0 | F21: =SUM(C21*(1-D21-E21)) | G21: =J21*R21 | H21: =J21*Q21 | I21: =SUM(G21:H21) | J21: 7 | K21: ='CPC表格'!V22 | L21: =SUM(H21*-K21) | M21: ='毛利盈亏'!T21 | N21: =SUM(L21:M21) | O21: 180 | P21: 70 | Q21: 25 | R21: =SUM(P21-Q21) | S21: =SUM(L21/J21) | T21: 1 | U21: 前20名 | W21: 0 | X21: =SUM(N21:N44)+W21 | Y21: =X21*7
B22: WEEK20 | C22: 79.99 | D22: 0 | E22: 0 | F22: =SUM(C22*(1-D22-E22)) | G22: =J22*R22 | H22: =J22*Q22 | I22: =SUM(G22:H22) | J22: 7 | K22: ='CPC表格'!V23 | L22: =SUM(H22*-K22) | M22: ='毛利盈亏'!T22 | N22: =SUM(L22:M22) | O22: 190 | P22: 70 | Q22: 25 | R22: =SUM(P22-Q22) | S22: =SUM(L22/J22) | T22: 1 | U22: 前20名 | W22: 0 | X22: =SUM(N22:N45)+W22 | Y22: =X22*7
A23: 第六阶段 | B23: WEEK21 | C23: 79.99 | D23: 0 | E23: 0 | F23: =SUM(C23*(1-D23-E23)) | G23: =J23*R23 | H23: =J23*Q23 | I23: =SUM(G23:H23) | J23: 7 | K23: ='CPC表格'!V24 | L23: =SUM(H23*-K23) | M23: ='毛利盈亏'!T23 | N23: =SUM(L23:M23) | O23: 200 | P23: 70 | Q23: 25 | R23: =SUM(P23-Q23) | S23: =SUM(L23/J23) | T23: 1 | U23: 前10名 | W23: 0 | X23: =SUM(N23:N46)+W23 | Y23: =X23*7
B24: WEEK22 | C24: 79.99 | D24: 0 | E24: 0 | F24: =SUM(C24*(1-D24-E24)) | G24: =J24*R24 | H24: =J24*Q24 | I24: =SUM(G24:H24) | J24: 7 | K24: ='CPC表格'!V25 | L24: =SUM(H24*-K24) | M24: ='毛利盈亏'!T24 | N24: =SUM(L24:M24) | O24: 220 | P24: 70 | Q24: 25 | R24: =SUM(P24-Q24) | S24: =SUM(L24/J24) | T24: 1 | U24: 前10名 | W24: 0 | X24: =SUM(N24:N47)+W24 | Y24: =X24*7
B25: WEEK23 | C25: 79.99 | D25: 0 | E25: 0 | F25: =SUM(C25*(1-D25-E25)) | G25: =J25*R25 | H25: =J25*Q25 | I25: =SUM(G25:H25) | J25: 7 | K25: ='CPC表格'!V26 | L25: =SUM(H25*-K25) | M25: ='毛利盈亏'!T25 | N25: =SUM(L25:M25) | O25: 240 | P25: 70 | Q25: 25 | R25: =SUM(P25-Q25) | S25: =SUM(L25/J25) | T25: 1 | U25: 前10名 | W25: 0 | X25: =SUM(N25:N48)+W25 | Y25: =X25*7
B26: WEEK24 | C26: 79.99 | D26: 0 | E26: 0 | F26: =SUM(C26*(1-D26-E26)) | G26: =J26*R26 | H26: =J26*Q26 | I26: =SUM(G26:H26) | J26: 7 | K26: ='CPC表格'!V27 | L26: =SUM(H26*-K26) | M26: ='毛利盈亏'!T26 | N26: =SUM(L26:M26) | O26: 260 | P26: 70 | Q26: 25 | R26: =SUM(P26-Q26) | S26: =SUM(L26/J26) | T26: 1 | U26: 前5名 | W26: 0 | X26: =SUM(N26:N49)+W26 | Y26: =X26*7
A28: 阶段盈亏真实数据
A29: 第一阶段 | B29: 第1周
B30: 第2周
B31: 第3周
B32: 第4周
A33: 第二阶段 | B33: 第5周
B34: 第6周
B35: 第7周
B36: 第8周
A37: 第三阶段 | B37: 第9周
B38: 第10周
B39: 第11周
B40: 第12周
A41: 第四阶段 | B41: 第13周
...

Sheet 毛利盈亏
A1: 每日盈亏数据预估
A2: 阶段 | B2: 日期 | C2: 定价 | D2: coupon | E2: code | F2: 折后价 | G2: FBA 配送费 | H2: 亚马逊 佣金 | I2: 账号 回款 | J2: 仓储费+入库配置费 | K2: coupon 费用 | L2: 产品 成本 | M2: 物流费 | N2: 退货成本(公式后面加的是单套产品的移除费） | O2: 退货率 | P2: 每单平摊 退货成本 | Q2: 每单 毛利 | R2: 毛利率 | S2: 订单 数量 | T2: 阶段 订单 亏损 | U2: 阶段 订单 总盈亏
A3: 第一阶段 | B3: week01 | C3: 89.99 | D3: 0.3 | E3: 0 | F3: =SUM(C3*(1-D3-E3)) | G3: 10.51 | H3: =SUM(F3*8%) | I3: =SUM(F3-G3-H3) | J3: 0.5 | K3: 0.6 | L3: 40 | M3: 3 | N3: =SUM(20%*15%*F3+G3+J3+L3+M3+1.04) | O3: 0.044 | P3: =SUM(N3*O3/(1-O3)) | Q3: =SUM(I3-J3-K3-L3-M3-P3) | R3: =SUM(Q3/C3) | S3: ='总表（阶段盈亏）'!I3 | T3: =SUM(Q3*S3) | U3: =SUM(T3)
B4: week02 | C4: 89.99 | D4: 0.3 | E4: 0 | F4: =SUM(C4*(1-D4-E4)) | G4: 10.51 | H4: =SUM(F4*8%) | I4: =SUM(F4-G4-H4) | J4: 0.5 | K4: 0.6 | L4: 40 | M4: 3 | N4: =SUM(20%*15%*F4+G4+J4+L4+M4+1.04) | O4: 0.044 | P4: =SUM(N4*O4/(1-O4)) | Q4: =SUM(I4-J4-K4-L4-M4-P4) | R4: =SUM(Q4/C4) | S4: ='总表（阶段盈亏）'!I4 | T4: =SUM(Q4*S4) | U4: =SUM(T4)
B5: week03 | C5: 89.99 | D5: 0.3 | E5: 0 | F5: =SUM(C5*(1-D5-E5)) | G5: 10.51 | H5: =SUM(F5*8%) | I5: =SUM(F5-G5-H5) | J5: 0.5 | K5: 0.6 | L5: 40 | M5: 3 | N5: =SUM(20%*15%*F5+G5+J5+L5+M5+1.04) | O5: 0.044 | P5: =SUM(N5*O5/(1-O5)) | Q5: =SUM(I5-J5-K5-L5-M5-P5) | R5: =SUM(Q5/C5) | S5: ='总表（阶段盈亏）'!I5 | T5: =SUM(Q5*S5) | U5: =SUM(T5)
B6: week04 | C6: 89.99 | D6: 0.3 | E6: 0 | F6: =SUM(C6*(1-D6-E6)) | G6: 10.51 | H6: =SUM(F6*8%) | I6: =SUM(F6-G6-H6) | J6: 0.5 | K6: 0.6 | L6: 40 | M6: 3 | N6: =SUM(20%*15%*F6+G6+J6+L6+M6+1.04) | O6: 0.044 | P6: =SUM(N6*O6/(1-O6)) | Q6: =SUM(I6-J6-K6-L6-M6-P6) | R6: =SUM(Q6/C6) | S6: ='总表（阶段盈亏）'!I6 | T6: =SUM(Q6*S6) | U6: =SUM(T6)
A7: 第二阶段 | B7: week05 | C7: 89.99 | D7: 0.2 | E7: 0 | F7: =SUM(C7*(1-D7-E7)) | G7: 10.51 | H7: =SUM(F7*8%) | I7: =SUM(F7-G7-H7) | J7: 0.5 | K7: 0.6 | L7: 40 | M7: 3 | N7: =SUM(20%*15%*F7+G7+J7+L7+M7+1.04) | O7: 0.044 | P7: =SUM(N7*O7/(1-O7)) | Q7: =SUM(I7-J7-K7-L7-M7-P7) | R7: =SUM(Q7/C7) | S7: ='总表（阶段盈亏）'!I7 | T7: =SUM(Q7*S7) | U7: =SUM(T7)
B8: week06 | C8: 89.99 | D8: 0.2 | E8: 0 | F8: =SUM(C8*(1-D8-E8)) | G8: 10.51 | H8: =SUM(F8*8%) | I8: =SUM(F8-G8-H8) | J8: 0.5 | K8: 0.6 | L8: 40 | M8: 3 | N8: =SUM(20%*15%*F8+G8+J8+L8+M8+1.04) | O8: 0.044 | P8: =SUM(N8*O8/(1-O8)) | Q8: =SUM(I8-J8-K8-L8-M8-P8) | R8: =SUM(Q8/C8) | S8: ='总表（阶段盈亏）'!I8 | T8: =SUM(Q8*S8) | U8: =SUM(T8)
B9: week07 | C9: 89.99 | D9: 0.2 | E9: 0 | F9: =SUM(C9*(1-D9-E9)) | G9: 10.51 | H9: =SUM(F9*8%) | I9: =SUM(F9-G9-H9) | J9: 0.5 | K9: 0.6 | L9: 40 | M9: 3 | N9: =SUM(20%*15%*F9+G9+J9+L9+M9+1.04) | O9: 0.044 | P9: =SUM(N9*O9/(1-O9)) | Q9: =SUM(I9-J9-K9-L9-M9-P9) | R9: =SUM(Q9/C9) | S9: ='总表（阶段盈亏）'!I9 | T9: =SUM(Q9*S9) | U9: =SUM(T9)
B10: week08 | C10: 89.99 | D10: 0.2 | E10: 0 | F10: =SUM(C10*(1-D10-E10)) | G10: 10.51 | H10: =SUM(F10*8%) | I10: =SUM(F10-G10-H10) | J10: 0.5 | K10: 0.6 | L10: 40 | M10: 3 | N10: =SUM(20%*15%*F10+G10+J10+L10+M10+1.04) | O10: 0.044 | P10: =SUM(N10*O10/(1-O10)) | Q10: =SUM(I10-J10-K10-L10-M10-P10) | R10: =SUM(Q10/C10) | S10: ='总表（阶段盈亏）'!I10 | T10: =SUM(Q10*S10) | U10: =SUM(T10)
A11: 第三阶段 | B11: week09 | C11: 89.99 | D11: 0.1 | E11: 0 | F11: =SUM(C11*(1-D11-E11)) | G11: 10.51 | H11: =SUM(F11*8%) | I11: =SUM(F11-G11-H11) | J11: 0.5 | K11: 0.6 | L11: 40 | M11: 3 | N11: =SUM(20%*15%*F11+G11+J11+L11+M11+1.04) | O11: 0.044 | P11: =SUM(N11*O11/(1-O11)) | Q11: =SUM(I11-J11-K11-L11-M11-P11) | R11: =SUM(Q11/C11) | S11: ='总表（阶段盈亏）'!I11 | T11: =SUM(Q11*S11) | U11: =SUM(T11)
B12: week10 | C12: 89.99 | D12: 0.1 | E12: 0 | F12: =SUM(C12*(1-D12-E12)) | G12: 10.51 | H12: =SUM(F12*8%) | I12: =SUM(F12-G12-H12) | J12: 0.5 | K12: 0.6 | L12: 40 | M12: 3 | N12: =SUM(20%*15%*F12+G12+J12+L12+M12+1.04) | O12: 0.044 | P12: =SUM(N12*O12/(1-O12)) | Q12: =SUM(I12-J12-K12-L12-M12-P12) | R12: =SUM(Q12/C12) | S12: ='总表（阶段盈亏）'!I12 | T12: =SUM(Q12*S12) | U12: =SUM(T12)
B13: week11 | C13: 89.99 | D13: 0.1 | E13: 0 | F13: =SUM(C13*(1-D13-E13)) | G13: 10.51 | H13: =SUM(F13*8%) | I13: =SUM(F13-G13-H13) | J13: 0.5 | K13: 0.6 | L13: 40 | M13: 3 | N13: =SUM(20%*15%*F13+G13+J13+L13+M13+1.04) | O13: 0.044 | P13: =SUM(N13*O13/(1-O13)) | Q13: =SUM(I13-J13-K13-L13-M13-P13) | R13: =SUM(Q13/C13) | S13: ='总表（阶段盈亏）'!I13 | T13: =SUM(Q13*S13) | U13: =SUM(T13)
B14: week12 | C14: 89.99 | D14: 0.1 | E14: 0 | F14: =SUM(C14*(1-D14-E14)) | G14: 10.51 | H14: =SUM(F14*8%) | I14: =SUM(F14-G14-H14) | J14: 0.5 | K14: 0.6 | L14: 40 | M14: 3 | N14: =SUM(20%*15%*F14+G14+J14+L14+M14+1.04) | O14: 0.044 | P14: =SUM(N14*O14/(1-O14)) | Q14: =SUM(I14-J14-K14-L14-M14-P14) | R14: =SUM(Q14/C14) | S14: ='总表（阶段盈亏）'!I14 | T14: =SUM(Q14*S14) | U14: =SUM(T14)
A15: 第四阶段 | B15: week13 | C15: 79.99 | D15: 0 | E15: 0 | F15: =SUM(C15*(1-D15-E15)) | G15: 10.51 | H15: =SUM(F15*8%) | I15: =SUM(F15-G15-H15) | J15: 0.5 | K15: 0 | L15: 40 | M15: 3 | N15: =SUM(20%*15%*F15+G15+J15+L15+M15+1.04) | O15: 0.044 | P15: =SUM(N15*O15/(1-O15)) | Q15: =SUM(I15-J15-K15-L15-M15-P15) | R15: =SUM(Q15/C15) | S15: ='总表（阶段盈亏）'!I15 | T15: =SUM(Q15*S15) | U15: =SUM(T15)
B16: week14 | C16: 79.99 | D16: 0 | E16: 0 | F16: =SUM(C16*(1-D16-E16)) | G16: 10.51 | H16: =SUM(F16*8%) | I16: =SUM(F16-G16-H16) | J16: 0.5 | K16: 0 | L16: 40 | M16: 3 | N16: =SUM(20%*15%*F16+G16+J16+L16+M16+1.04) | O16: 0.044 | P16: =SUM(N16*O16/(1-O16)) | Q16: =SUM(I16-J16-K16-L16-M16-P16) | R16: =SUM(Q16/C16) | S16: ='总表（阶段盈亏）'!I16 | T16: =SUM(Q16*S16) | U16: =SUM(T16)
B17: week15 | C17: 79.99 | D17: 0 | E17: 0 | F17: =SUM(C17*(1-D17-E17)) | G17: 10.51 | H17: =SUM(F17*8%) | I17: =SUM(F17-G17-H17) | J17: 0.5 | K17: 0 | L17: 40 | M17: 3 | N17: =SUM(20%*15%*F17+G17+J17+L17+M17+1.04) | O17: 0.044 | P17: =SUM(N17*O17/(1-O17)) | Q17: =SUM(I17-J17-K17-L17-M17-P17) | R17: =SUM(Q17/C17) | S17: ='总表（阶段盈亏）'!I17 | T17: =SUM(Q17*S17) | U17: =SUM(T17)
B18: week16 | C18: 79.99 | D18: 0 | E18: 0 | F18: =SUM(C18*(1-D18-E18)) | G18: 10.51 | H18: =SUM(F18*8%) | I18: =SUM(F18-G18-H18) | J18: 0.5 | K18: 0 | L18: 40 | M18: 3 | N18: =SUM(20%*15%*F18+G18+J18+L18+M18+1.04) | O18: 0.044 | P18: =SUM(N18*O18/(1-O18)) | Q18: =SUM(I18-J18-K18-L18-M18-P18) | R18: =SUM(Q18/C18) | S18: ='总表（阶段盈亏）'!I18 | T18: =SUM(Q18*S18) | U18: =SUM(T18)
A19: 第五阶段 | B19: week17 | C19: 79.99 | D19: 0 | E19: 0 | F19: =SUM(C19*(1-D19-E19)) | G19: 10.51 | H19: =SUM(F19*8%) | I19: =SUM(F19-G19-H19) | J19: 0.5 | K19: 0 | L19: 40 | M19: 3 | N19: =SUM(20%*15%*F19+G19+J19+L19+M19+1.04) | O19: 0.044 | P19: =SUM(N19*O19/(1-O19)) | Q19: =SUM(I19-J19-K19-L19-M19-P19) | R19: =SUM(Q19/C19) | S19: ='总表（阶段盈亏）'!I19 | T19: =SUM(Q19*S19) | U19: =SUM(T19)
B20: week18 | C20: 79.99 | D20: 0 | E20: 0 | F20: =SUM(C20*(1-D20-E20)) | G20: 10.51 | H20: =SUM(F20*8%) | I20: =SUM(F20-G20-H20) | J20: 0.5 | K20: 0 | L20: 40 | M20: 3 | N20: =SUM(20%*15%*F20+G20+J20+L20+M20+1.04) | O20: 0.044 | P20: =SUM(N20*O20/(1-O20)) | Q20: =SUM(I20-J20-K20-L20-M20-P20) | R20: =SUM(Q20/C20) | S20: ='总表（阶段盈亏）'!I20 | T20: =SUM(Q20*S20) | U20: =SUM(T20)
B21: week19 | C21: 79.99 | D21: 0 | E21: 0 | F21: =SUM(C21*(1-D21-E21)) | G21: 10.51 | H21: =SUM(F21*8%) | I21: =SUM(F21-G21-H21) | J21: 0.5 | K21: 0 | L21: 40 | M21: 3 | N21: =SUM(20%*15%*F21+G21+J21+L21+M21+1.04) | O21: 0.044 | P21: =SUM(N21*O21/(1-O21)) | Q21: =SUM(I21-J21-K21-L21-M21-P21) | R21: =SUM(Q21/C21) | S21: ='总表（阶段盈亏）'!I21 | T21: =SUM(Q21*S21) | U21: =SUM(T21)
B22: week20 | C22: 79.99 | D22: 0 | E22: 0 | F22: =SUM(C22*(1-D22-E22)) | G22: 10.51 | H22: =SUM(F22*8%) | I22: =SUM(F22-G22-H22) | J22: 0.5 | K22: 0 | L22: 40 | M22: 3 | N22: =SUM(20%*15%*F22+G22+J22+L22+M22+1.04) | O22: 0.044 | P22: =SUM(N22*O22/(1-O22)) | Q22: =SUM(I22-J22-K22-L22-M22-P22) | R22: =SUM(Q22/C22) | S22: ='总表（阶段盈亏）'!I22 | T22: =SUM(Q22*S22) | U22: =SUM(T22)
A23: 第六阶段 | B23: week21 | C23: 79.99 | D23: 0 | E23: 0 | F23: =SUM(C23*(1-D23-E23)) | G23: 10.51 | H23: =SUM(F23*8%) | I23: =SUM(F23-G23-H23) | J23: 0.5 | K23: 0 | L23: 40 | M23: 3 | N23: =SUM(20%*15%*F23+G23+J23+L23+M23+1.04) | O23: 0.044 | P23: =SUM(N23*O23/(1-O23)) | Q23: =SUM(I23-J23-K23-L23-M23-P23) | R23: =SUM(Q23/C23) | S23: ='总表（阶段盈亏）'!I23 | T23: =SUM(Q23*S23) | U23: =SUM(T23)
B24: week22 | C24: 79.99 | D24: 0 | E24: 0 | F24: =SUM(C24*(1-D24-E24)) | G24: 10.51 | H24: =SUM(F24*8%) | I24: =SUM(F24-G24-H24) | J24: 0.5 | K24: 0 | L24: 40 | M24: 3 | N24: =SUM(20%*15%*F24+G24+J24+L24+M24+1.04) | O24: 0.044 | P24: =SUM(N24*O24/(1-O24)) | Q24: =SUM(I24-J24-K24-L24-M24-P24) | R24: =SUM(Q24/C24) | S24: ='总表（阶段盈亏）'!I24 | T24: =SUM(Q24*S24) | U24: =SUM(T24)
B25: week23 | C25: 79.99 | D25: 0 | E25: 0 | F25: =SUM(C25*(1-D25-E25)) | G25: 10.51 | H25: =SUM(F25*8%) | I25: =SUM(F25-G25-H25) | J25: 0.5 | K25: 0 | L25: 40 | M25: 3 | N25: =SUM(20%*15%*F25+G25+J25+L25+M25+1.04) | O25: 0.044 | P25: =SUM(N25*O25/(1-O25)) | Q25: =SUM(I25-J25-K25-L25-M25-P25) | R25: =SUM(Q25/C25) | S25: ='总表（阶段盈亏）'!I25 | T25: =SUM(Q25*S25) | U25: =SUM(T25)
B26: week24 | C26: 79.99 | D26: 0 | E26: 0 | F26: =SUM(C26*(1-D26-E26)) | G26: 10.51 | H26: =SUM(F26*8%) | I26: =SUM(F26-G26-H26) | J26: 0.5 | K26: 0 | L26: 40 | M26: 3 | N26: =SUM(20%*15%*F26+G26+J26+L26+M26+1.04) | O26: 0.044 | P26: =SUM(N26*O26/(1-O26)) | Q26: =SUM(I26-J26-K26-L26-M26-P26) | R26: =SUM(Q26/C26) | S26: ='总表（阶段盈亏）'!I26 | T26: =SUM(Q26*S26) | U26: =SUM(T26)
A28: 每日盈亏真实数据
A29: 第一阶段 | B29: 第1周
B30: 第2周
B31: 第3周
B32: 第4周
A33: 第二阶段 | B33: 第5周
B34: 第6周
B35: 第7周
B36: 第8周
A37: 第三阶段 | B37: 第9周
B38: 第10周
B39: 第11周
B40: 第12周
A41: 第四阶段 | B41: 第13周
...

Sheet 总表（阶段盈亏） (调整后)
A1: 按照每周/每日不同的数据表现情况进行调整： | AB1: https://mp.weixin.qq.com/s/hJXWLb-KpYE6J5aK37fUqA?poc_token=HER7cGijba2sEL_p1d8TCVeaPrsbMxX-Mtg-J8JD
A2: 周 | B2: 星期 | C2: 名称 | D2: 店铺SKU | E2: ASIN | F2: Rating数 | G2: 星级 | H2: QA数量 | I2: 操作 | J2: flashlihte | K2: 访问IP数 | L2: 自然流量 | M2: 浏览量 | N2: 转化率 | O2: 总订单 | P2: 总销售额 | Q2: 总销量 | R2: 曝光量 | S2: 点击 | T2: 广告订单 | U2: CTR | V2: CVR | W2: 总花费 | X2: CPC | Y2: 广告销售额 | Z2: ACOS | AA2: 广告订单占比 | AB2: 广告订单占比
A3: ①周 | B3: 星期一 | AB3: Q&A数 QA图片视频， 评论数，星级，评论的质量： 前台首页无差评 3星，以及点赞数量（前3个评论，首页）
B4: 星期二
B5: 星期三
B6: 星期四
B7: 星期五
B8: 星期六
B9: 星期日
A10: 第一周
A11: ②周 | B11: 星期一
B12: 星期二
B13: 星期三
B14: 星期四
B15: 星期五
B16: 星期六
B17: 星期日
A18: 第二周
A19: ③周 | B19: 星期一
B20: 星期二
B21: 星期三
B22: 星期四
B23: 星期五
B24: 星期六
B25: 星期日
A26: 第三周
A27: ④周 | B27: 星期一
B28: 星期二
B29: 星期三
B30: 星期四
B31: 星期五
B32: 星期六
B33: 星期日
A34: 第四周
A35: ⑤周 | B35: 星期一
B36: 星期二
B37: 星期三
B38: 星期四
B39: 星期五
B40: 星期六
...

Sheet CPC表格
A1: 广告数据模拟
A2: 常规数据 | N2: 广告数据 | AB2: 实时更新 | AC2: 操作备注
A3: 阶段 | B3: 周 | C3: 价格 | D3: 站内 coupon | E3: 站内 code | F3: 折后价 | G3: 新品 榜单 | H3: 小类目 排名 | I3: 总 销量 | J3: 总访 问量 | K3: CVR | L3: 评论 数量 | M3: 评分 | N3: 曝光量 | O3: 点击量 | P3: CTR | Q3: 广告单 | R3: CVR | S3: 平均 CPC | T3: 花费 | U3: ACOS | V3: CPA | W3: 日均 广告费 | X3: 自然 访问 | Y3: 自然 订单 | Z3: 自然 单占比 | AA3: 最终 盈亏 | AB3: Sif 质量分 | AC3: 运营调整 | AD3: 广告操作
A4: 第一阶段 | C4: 79.99 | D4: 0.3 | E4: 0 | F4: =SUM(C4*(1-D4-E4)) | O4: =SUM(Q4/R4) | Q4: ='总表（阶段盈亏）'!H3 | R4: 0.08 | S4: 1.91 | T4: =SUM(O4*S4) | U4: =SUM(S4/R4/C4) | V4: =SUM(T4/Q4) | W4: =T4/7
C5: 89.99 | D5: 0.3 | E5: 0 | F5: =SUM(C5*(1-D5-E5)) | O5: =SUM(Q5/R5) | Q5: ='总表（阶段盈亏）'!H4 | R5: 0.08 | S5: 1.91 | T5: =SUM(O5*S5) | U5: =SUM(S5/R5/C5) | V5: =SUM(T5/Q5) | W5: =T5/7
C6: 89.99 | D6: 0.3 | E6: 0 | F6: =SUM(C6*(1-D6-E6)) | O6: =SUM(Q6/R6) | Q6: ='总表（阶段盈亏）'!H5 | R6: 0.08 | S6: 1.91 | T6: =SUM(O6*S6) | U6: =SUM(S6/R6/C6) | V6: =SUM(T6/Q6) | W6: =T6/7
C7: 89.99 | D7: 0.3 | E7: 0 | F7: =SUM(C7*(1-D7-E7)) | O7: =SUM(Q7/R7) | Q7: ='总表（阶段盈亏）'!H6 | R7: 0.08 | S7: 1.91 | T7: =SUM(O7*S7) | U7: =SUM(S7/R7/C7) | V7: =SUM(T7/Q7) | W7: =T7/7
A8: 第二阶段 | C8: 85.99 | D8: 0.2 | E8: 0 | F8: =SUM(C8*(1-D8-E8)) | O8: =SUM(Q8/R8) | Q8: ='总表（阶段盈亏）'!H7 | R8: 0.085 | S8: 1.87 | T8: =SUM(O8*S8) | U8: =SUM(S8/R8/C8) | V8: =SUM(T8/Q8) | W8: =T8/7
C9: 85.99 | D9: 0.2 | E9: 0 | F9: =SUM(C9*(1-D9-E9)) | O9: =SUM(Q9/R9) | Q9: ='总表（阶段盈亏）'!H8 | R9: 0.085 | S9: 1.87 | T9: =SUM(O9*S9) | U9: =SUM(S9/R9/C9) | V9: =SUM(T9/Q9) | W9: =T9/7
C10: 85.99 | D10: 0.2 | E10: 0 | F10: =SUM(C10*(1-D10-E10)) | O10: =SUM(Q10/R10) | Q10: ='总表（阶段盈亏）'!H9 | R10: 0.085 | S10: 1.87 | T10: =SUM(O10*S10) | U10: =SUM(S10/R10/C10) | V10: =SUM(T10/Q10) | W10: =T10/7
C11: 85.99 | D11: 0.2 | E11: 0 | F11: =SUM(C11*(1-D11-E11)) | O11: =SUM(Q11/R11) | Q11: ='总表（阶段盈亏）'!H10 | R11: 0.085 | S11: 1.87 | T11: =SUM(O11*S11) | U11: =SUM(S11/R11/C11) | V11: =SUM(T11/Q11) | W11: =T11/7
A12: 第三阶段 | C12: 85.99 | D12: 0.1 | E12: 0 | F12: =SUM(C12*(1-D12-E12)) | O12: =SUM(Q12/R12) | Q12: ='总表（阶段盈亏）'!H11 | R12: 0.09 | S12: 1.84 | T12: =SUM(O12*S12) | U12: =SUM(S12/R12/C12) | V12: =SUM(T12/Q12) | W12: =T12/7
C13: 85.99 | D13: 0.1 | E13: 0 | F13: =SUM(C13*(1-D13-E13)) | O13: =SUM(Q13/R13) | Q13: ='总表（阶段盈亏）'!H12 | R13: 0.09 | S13: 1.84 | T13: =SUM(O13*S13) | U13: =SUM(S13/R13/C13) | V13: =SUM(T13/Q13) | W13: =T13/7
C14: 85.99 | D14: 0.1 | E14: 0 | F14: =SUM(C14*(1-D14-E14)) | O14: =SUM(Q14/R14) | Q14: ='总表（阶段盈亏）'!H13 | R14: 0.09 | S14: 1.84 | T14: =SUM(O14*S14) | U14: =SUM(S14/R14/C14) | V14: =SUM(T14/Q14) | W14: =T14/7
C15: 85.99 | D15: 0.1 | E15: 0 | F15: =SUM(C15*(1-D15-E15)) | O15: =SUM(Q15/R15) | Q15: ='总表（阶段盈亏）'!H14 | R15: 0.09 | S15: 1.84 | T15: =SUM(O15*S15) | U15: =SUM(S15/R15/C15) | V15: =SUM(T15/Q15) | W15: =T15/7
A16: 第四阶段 | C16: 79.99 | D16: 0 | E16: 0 | F16: =SUM(C16*(1-D16-E16)) | O16: =SUM(Q16/R16) | Q16: ='总表（阶段盈亏）'!H15 | R16: 0.085 | S16: 1.8 | T16: =SUM(O16*S16) | U16: =SUM(S16/R16/C16) | V16: =SUM(T16/Q16) | W16: =T16/7
C17: 79.99 | D17: 0 | E17: 0 | F17: =SUM(C17*(1-D17-E17)) | O17: =SUM(Q17/R17) | Q17: ='总表（阶段盈亏）'!H16 | R17: 0.085 | S17: 1.8 | T17: =SUM(O17*S17) | U17: =SUM(S17/R17/C17) | V17: =SUM(T17/Q17) | W17: =T17/7
C18: 79.99 | D18: 0 | E18: 0 | F18: =SUM(C18*(1-D18-E18)) | O18: =SUM(Q18/R18) | Q18: ='总表（阶段盈亏）'!H17 | R18: 0.085 | S18: 1.8 | T18: =SUM(O18*S18) | U18: =SUM(S18/R18/C18) | V18: =SUM(T18/Q18) | W18: =T18/7
C19: 79.99 | D19: 0 | E19: 0 | F19: =SUM(C19*(1-D19-E19)) | O19: =SUM(Q19/R19) | Q19: ='总表（阶段盈亏）'!H18 | R19: 0.085 | S19: 1.8 | T19: =SUM(O19*S19) | U19: =SUM(S19/R19/C19) | V19: =SUM(T19/Q19) | W19: =T19/7
A20: 第五阶段 | C20: 79.99 | D20: 0 | E20: 0 | F20: =SUM(C20*(1-D20-E20)) | O20: =SUM(Q20/R20) | Q20: ='总表（阶段盈亏）'!H19 | R20: 0.085 | S20: 1.8 | T20: =SUM(O20*S20) | U20: =SUM(S20/R20/C20) | V20: =SUM(T20/Q20) | W20: =T20/7
C21: 79.99 | D21: 0 | E21: 0 | F21: =SUM(C21*(1-D21-E21)) | O21: =SUM(Q21/R21) | Q21: ='总表（阶段盈亏）'!H20 | R21: 0.085 | S21: 1.8 | T21: =SUM(O21*S21) | U21: =SUM(S21/R21/C21) | V21: =SUM(T21/Q21) | W21: =T21/7
C22: 79.99 | D22: 0 | E22: 0 | F22: =SUM(C22*(1-D22-E22)) | O22: =SUM(Q22/R22) | Q22: ='总表（阶段盈亏）'!H21 | R22: 0.085 | S22: 1.8 | T22: =SUM(O22*S22) | U22: =SUM(S22/R22/C22) | V22: =SUM(T22/Q22) | W22: =T22/7
C23: 79.99 | D23: 0 | E23: 0 | F23: =SUM(C23*(1-D23-E23)) | O23: =SUM(Q23/R23) | Q23: ='总表（阶段盈亏）'!H22 | R23: 0.085 | S23: 1.8 | T23: =SUM(O23*S23) | U23: =SUM(S23/R23/C23) | V23: =SUM(T23/Q23) | W23: =T23/7
A24: 第六阶段 | C24: 79.99 | D24: 0 | E24: 0 | F24: =SUM(C24*(1-D24-E24)) | O24: =SUM(Q24/R24) | Q24: ='总表（阶段盈亏）'!H23 | R24: 0.085 | S24: 1.8 | T24: =SUM(O24*S24) | U24: =SUM(S24/R24/C24) | V24: =SUM(T24/Q24) | W24: =T24/7
C25: 79.99 | D25: 0 | E25: 0 | F25: =SUM(C25*(1-D25-E25)) | O25: =SUM(Q25/R25) | Q25: ='总表（阶段盈亏）'!H24 | R25: 0.085 | S25: 1.8 | T25: =SUM(O25*S25) | U25: =SUM(S25/R25/C25) | V25: =SUM(T25/Q25) | W25: =T25/7
C26: 79.99 | D26: 0 | E26: 0 | F26: =SUM(C26*(1-D26-E26)) | O26: =SUM(Q26/R26) | Q26: ='总表（阶段盈亏）'!H25 | R26: 0.085 | S26: 1.8 | T26: =SUM(O26*S26) | U26: =SUM(S26/R26/C26) | V26: =SUM(T26/Q26) | W26: =T26/7
C27: 79.99 | D27: 0 | E27: 0 | F27: =SUM(C27*(1-D27-E27)) | O27: =SUM(Q27/R27) | Q27: ='总表（阶段盈亏）'!H26 | R27: 0.085 | S27: 1.8 | T27: =SUM(O27*S27) | U27: =SUM(S27/R27/C27) | V27: =SUM(T27/Q27) | W27: =T27/7
A29: 广告真实数据
A30: 常规数据 | N30: 广告数据 | AB30: 实时更新 | AC30: 操作备注
A31: 阶段 | B31: 周 | C31: 价格 | D31: 站内 coupon | E31: 站内 code | F31: 折后价 | G31: 新品 榜单 | H31: 小类目 排名 | I31: 总 销量 | J31: 总访 问量 | K31: CVR | L31: 评论 数量 | M31: 评分 | N31: 曝光量 | O31: 点击量 | P31: CTR | Q31: 广告单 | R31: CVR | S31: 平均 CPC | T31: 花费 | U31: ACOS | V31: CPA | W31: 日均 广告费 | X31: 自然 访问 | Y31: 自然 订单 | Z31: 自然 单占比 | AA31: 最终 盈亏 | AB31: Sif 质量分 | AC31: 运营调整 | AD31: 广告操作
A32: 第一阶段 | B32: 第1周
B33: 第2周
B34: 第3周
B35: 第4周
A36: 第二阶段 | B36: 第5周
B37: 第6周
B38: 第7周
B39: 第8周
A40: 第三阶段 | B40: 第9周
B41: 第10周
...

Sheet 推广目标
A1: SKU：R0001EU ASIN：Bxxxxxxxx3 | I1: 关键词
A3: 上架销售时间： | B3: 45765 | C3: B0F1F7J8V3
A4: 推广周期： | B4: 4月20日-6月31日 | I4: 关键词 | J4: 关键词翻译 | K4: 流量占比 | L4: 预估周曝光量 | M4: 关键词类型 | N4: 转化效果自然流量占比
A5: 排名目标： | B5: Matratzensauger #50 | I5: milbensauger | J5: 吸螨虫 | K5: 0.497508 | L5: 13984 | M5: 主要流量词 | N5: 0.3471
A6: 目标销量： | B6: 15-20pcs/天 | I6: milbensauger für matratzen | J6: 用于床垫的吸尘器 | K6: 0.294441 | L6: 8276 | M6: 主要流量词 | N6: 0.41862
I7: sofa reiniger | J7: 沙发清洁剂 | K7: 0.059295 | L7: 1667 | N7: 0.61722
I8: matratzenreiniger | J8: 床垫清洁剂 | K8: 0.047246 | L8: 1328 | N8: 0.80955
I9: milbensauger für matratzen testsieger | J9: 用于床垫测试的螨虫吸尘器测试获胜者 | K9: 0.02472 | L9: 695 | N9: 0.46301
A10: 目标管理 | B10: 目标 | C10: ASIN 1 | I10: milbensauger mit uv licht | J10: 带紫外线灯的螨虫奶嘴 | K10: 0.019301 | L10: 543 | N10: 0.06106
A11: 对标竞品 | B11: B0DKPGKSYS | C11: B0DKPGKSYS | I11: hoover milbensauger | J11: 胡佛螨吸盘 | K11: 0.017954 | L11: 505 | M11: 精准长尾词 | N11: 0.50632
A12: 目标排名 | B12: 21-24 | I12: milbenstaubsauger | J12: 螨吸尘器 | K12: 0.008428 | L12: 237 | N12: 0.28778
A13: 目标日销 | B13: 10-15 日销 | I13: polsterreiniger | J13: 室内装饰品清洁剂 | K13: 0.007424 | L13: 209 | N13: 15
A14: 价格 | B14: 109-129.99 | I14: teppichreiniger gerät | J14: 地毯清洁装置 | K14: 0.002209 | L14: 62 | M14: 、 | N14: 16
A15: rating | B15: 136 | I15: polsterreinigungsgerät | J15: 室内装潢清洗机 | K15: 0.001316 | L15: 37 | M15: 、 | N15: 6
A16: 评分 | B16: 4.7
A17: 主推词 | B17: milbensauger
D20: 广泛 | E20: 词组 | F20: 精准
A21: 核心关键词 选取， | B21: milbensauger | C21: 除螨仪 | D21: 1.33 | E21: 1.2 | F21: 1.23
B22: milbenstaubsauger | C22: 除螨仪 | D22: 1.39 | E22: 1.24 | F22: 1.29
B23: milbensauger für matratzen | C23: 床垫除螨仪 | D23: 1.33 | E23: 1.2 | F23: 1.21
B24: milbensauger mit uv licht | C24: 带紫外除螨仪 | D24: 1.36 | E24: 1.22 | F24: 1.28
B25: milbensauger für matratzen testsieger | C25: 床垫除螨仪冠军 | D25: 1.29 | E25: 1.16 | F25: 1.21
B26: Milbensauger | C26: 除螨仪 | D26: 1.33 | E26: 1.2 | F26: 1.23
B27: jigoo milbensauger | C27: jigoo 除螨仪 | D27: 1.47 | E27: 1.3 | F27: 1.36
B28: Hoover milbensauger | C28: Hoover除螨仪 | D28: 1.65 | E28: 1.33 | F28: 2.01
A29: 长尾词 选取
B30: milbenstaubsauger | C30: 除螨仪 | D30: 1.39 | E30: 1.2 | F30: 1.23
B31: handstaubsauger | C31: 手持吸尘器 | D31: 0.64 | E31: 0.58 | F31: 0.63
B32: milbensauger für matratzen testsieger | C32: 床垫除螨仪冠军 | D32: 1.29 | E32: 1.16 | F32: 1.21
B33: matratzenreiniger gerät | C33: 除螨仪冠军 | D33: 1.08 | E33: 0.97 | F33: 1.01
A35: 蓝海词 | B35: polsterreiniger gerät | C35: “沙发清洁器”“软家具清洁设备” | D35: 1.01 | E35: 0.94 | F35: 0.89
B37: 其他品牌相关 品牌词词组
A79: 关键词 | B79: 关键词翻译 | C79: 流量占比 | D79: 预估周曝光量 | E79: 关键词类型 | F79: 转化效果自然流量占比 | G79: B0F1F7J8V3
A80: milbensauger | B80: 吸螨虫 | C80: 0.497508 | D80: 13984 | E80: 主要流量词 | F80: 0.3471
A81: milbensauger für matratzen | B81: 用于床垫的吸尘器 | C81: 0.294441 | D81: 8276 | E81: 主要流量词 | F81: 0.41862
A82: sofa reiniger | B82: 沙发清洁剂 | C82: 0.059295 | D82: 1667 | F82: 0.61722
A83: matratzenreiniger | B83: 床垫清洁剂 | C83: 0.047246 | D83: 1328 | F83: 0.80955
A84: milbensauger für matratzen testsieger | B84: 用于床垫测试的螨虫吸尘器测试获胜者 | C84: 0.02472 | D84: 695 | F84: 0.46301
A85: milbensauger mit uv licht | B85: 带紫外线灯的螨虫奶嘴 | C85: 0.019301 | D85: 543 | F85: 0.06106
A86: hoover milbensauger | B86: 胡佛螨吸盘 | C86: 0.017954 | D86: 505 | E86: 精准长尾词 | F86: 0.50632
...

Sheet 推广计划
A1: WEEK | B1: Date | C1: SKU | D1: 售价 | E1: COUPON | F1: Action | G1: 目标平均日销 | H1: 周销 | I1: 目标排名 | J1: Review星级/数量 | K1: REVIEW计划 | M1: 周消耗库存 | N1: 销售额 | O1: 日均流量 | P1: 转化率 | Q1: 主关键词自然搜索排名 | R1: 广告计划 | X1: 库存计划
K2: 送出数量 | L2: 措施 | R2: 广告日预算 | S2: 每日点击 | T2: CPC | U2: CVR | V2: 广告日订单 | W2: 广告订单占比 | Z2: LBS库存 | AA2: SZ | AB2: LBS在途 | AC2: LBS发货 | AD2: 采购计划
A3: WEEK1 | B3: 4.18-4.25 | C3: R0001EU | D3: 109.99 | E3: 20 | F3: 10 coupon+广告 | G3: =M3/7 | H3: =G3*7 | I3: 60 | J3: 4.7 | K3: 首单测评1单5星 | L3: 直评 10个 | M3: 44 | N3: =D3*H3 | O3: 66 | P3: =G3/O3 | Q3: 主推关键词：milbensauger,milbensauger für matratzen 目标：第5页 | R3: =T3*S3 | S3: =V3/U3 | T3: 1.2 | U3: 0.11 | V3: =G3*W3 | W3: 0.7 | X3: 1200 | Y3: 0 | Z3: 0 | AA3: 1310 | AB3: 2490海运
A4: WEEK2 | B4: 4.26-5.2 | C4: R0001EU | D4: 109.99 | E4: 20 | F4: coupon+广告 | G4: =M4/7 | H4: =G4*7 | I4: 40 | J4: 4.7 | K4: 绿标10个 | L4: 直评补 3-5个 | M4: 81 | N4: =D4*H4 | O4: 88 | P4: =G4/O4 | Q4: 主推关键词：milbensauger,milbensauger für matratzen 目标：第4页 | R4: =T4*S4 | S4: =V4/U4 | T4: 1.2 | U4: 0.12 | V4: =G4*W4 | W4: 0.65 | X4: =X3-H3 | Y4: 0 | Z4: 0 | AA4: 1310 | AB4: 2490
A5: WEEK3 | B5: 5.3-5.9 | C5: R0001EU | D5: 109.99 | E5: 20 | F5: coupon+广告 | G5: =M5/7 | H5: =G5*7 | I5: 30 | J5: 4.7 | K5: 1 | L5: 测评 | M5: 55 | N5: =D5*H5 | O5: 60 | P5: =G5/O5 | Q5: 主推关键词：milbensauger,milbensauger für matratzen 目标：第3页 | R5: =T5*S5 | S5: =V5/U5 | T5: 1.1 | U5: 0.13 | V5: =G5*W5 | W5: 0.6 | X5: =X4-H4 | Y5: 0 | Z5: 2490 | AA5: 0 | AB5: 1310卡派 | AC5: 720至TT 600至RUI备用
A6: WEEK4 | B6: 5.10-5.16 | C6: R0001EU | D6: 109.99 | E6: 20 | F6: 10 coupon+7DD+加大广告投放 | G6: =M6/7 | H6: =G6*7 | I6: 20 | J6: 4.6 | K6: 2 | L6: 测评 | M6: 48 | N6: =D6*H6 | O6: 50 | P6: =G6/O6 | Q6: 主推关键词：milbensauger,milbensauger für matratzen 目标：第3页 | R6: =T6*S6 | S6: =V6/U6 | T6: 1.1 | U6: 0.15 | V6: =G6*W6 | W6: 0.5 | X6: =X5-H5+720 | Y6: 600 | Z6: 1170 | AA6: 0 | AB6: 1310 | AD6: 1500
A7: WEEK5 | B7: 5.17-5.23 | C7: R0001EU | D7: 119.99 | E7: 10 | F7: coupon+广告 | G7: =M7/7 | H7: =G7*7 | I7: 28 | J7: 4.6 | K7: 2 | L7: 测评 | M7: 52 | N7: =D7*H7 | O7: 56 | P7: =G7/O7 | Q7: 主推关键词：milbensauger,milbensauger für matratzen 目标：第2页 | R7: =T7*S7 | S7: =V7/U7 | T7: 1 | U7: 0.15 | V7: =G7*W7 | W7: 0.55 | X7: =X6-H6 | Y7: 600 | Z7: 1170 | AA7: 0 | AB7: 1310
A8: WEEK6 | B8: 5.24-5.30 | C8: R0001EU | D8: 119.99 | E8: 10 | F8: coupon+广告 | G8: =M8/7 | H8: =G8*7 | I8: 26 | J8: 4.6 | K8: 2 | L8: 测评 | M8: 50 | N8: =D8*H8 | O8: 60 | P8: =G8/O8 | Q8: 主推关键词：milbensauger,milbensauger für matratzen 目标：第2页 | R8: =T8*S8 | S8: =V8/U8 | T8: 1 | U8: 0.15 | V8: =G8*W8 | W8: 0.5 | X8: =X7-H7 | Y8: 600 | Z8: 1170 | AA8: 0 | AB8: 1310 | AC8: 900至TT
A9: WEEK7 | B9: 5.31-6.6 | C9: R0001EU | D9: 119.99 | E9: 10 | F9: 7DD+加大广告投放 | G9: =M9/7 | H9: =G9*7 | I9: 20 | J9: 4.6 | K9: 2 | L9: 测评 | M9: 58 | N9: =D9*H9 | O9: 68 | P9: =G9/O9 | Q9: 主推关键词：milbensauger,milbensauger für matratzen 目标：第2页 | R9: =T9*S9 | S9: =V9/U9 | T9: 0.9 | U9: 0.16 | V9: =G9*W9 | W9: 0.4 | X9: =X8-H8+900 | Y9: 600 | Z9: =Z8-900 | AA9: 0 | AB9: 1310 | AD9: 1980(PD)
A10: WEEK8 | B10: 6.7-6.13 | C10: R0001EU | D10: 119.99 | E10: 10 | F10: coupon+广告 | G10: =M10/7 | H10: =G10*7 | I10: 25 | J10: 4.6 | K10: 2 | L10: 测评 | M10: 50 | N10: =D10*H10 | O10: 68 | P10: =G10/O10 | Q10: 主推关键词：milbensauger,milbensauger für matratzen 目标：第1页 | R10: =T10*S10 | S10: =V10/U10 | T10: 0.9 | U10: 0.16 | V10: =G10*W10 | W10: 0.45 | X10: =X9-H9 | Y10: 600 | Z10: 1580 | AA10: 1500 | AB10: 0 | AC10: 900至TT
A11: WEEK9 | B11: 6.14-6.20 | C11: R0001EU | D11: 119.99 | E11: 10 | F11: coupon+广告 | G11: =M11/7 | H11: =G11*7 | I11: 24 | J11: 4.6 | K11: 2 | L11: 测评 | M11: 55 | N11: =D11*H11 | O11: 70 | P11: =G11/O11 | Q11: 主推关键词：milbensauger,milbensauger für matratzen 目标：第1页 | R11: =T11*S11 | S11: =V11/U11 | T11: 0.9 | U11: 0.16 | V11: =G11*W11 | W11: 0.4 | X11: =X10-H10+900 | Y11: 600 | Z11: 680 | AA11: 0 | AB11: 1500卡派 | AD11: 2100
A12: WEEK10 | B12: 6.21-6.27 | C12: R0001EU | D12: 119.99 | E12: 10 | F12: 7DD+加大广告投放 | G12: =M12/7 | H12: =G12*7 | I12: 20 | J12: 4.6 | K12: 2 | L12: 测评 | M12: 65 | N12: =D12*H12 | O12: 75 | P12: =G12/O12 | Q12: 主推关键词：milbensauger,milbensauger für matratzen 目标：第1页 | R12: =T12*S12 | S12: =V12/U12 | T12: 0.9 | U12: 0.16 | V12: =G12*W12 | W12: 0.35 | X12: =X11-H11 | Y12: 600 | Z12: 680 | AA12: 0 | AB12: 1500 | AC12: 680至TT
A13: WEEK11 | B13: 6.28-7.4 | C13: R0001EU | D13: 119.99 | E13: 10 | F13: coupon+广告 | G13: =M13/7 | H13: =G13*7 | I13: 22 | J13: 4.6 | K13: 2 | L13: 测评 | M13: 72 | N13: =D13*H13 | O13: 75 | P13: =G13/O13 | Q13: 主推关键词：milbensauger,milbensauger für matratzen 目标：第1页 | R13: =T13*S13 | S13: =V13/U13 | T13: 0.9 | U13: 0.16 | V13: =G13*W13 | W13: 0.35 | X13: =X12-H12+680 | Y13: 600 | Z13: 0 | AA13: 1980 | AB13: 1500
A14: WEEK12 | B14: 7.5-7.11 | C14: R0001EU | D14: 119.99 | E14: 10 | F14: coupon+广告 | G14: =M14/7 | H14: =G14*7 | I14: 21 | J14: 4.6 | K14: 2 | L14: 测评 | M14: 75 | N14: =D14*H14 | O14: 75 | P14: =G14/O14 | Q14: 主推关键词：milbensauger,milbensauger für matratzen 目标：第1页 | R14: =T14*S14 | S14: =V14/U14 | T14: 0.9 | U14: 0.16 | V14: =G14*W14 | W14: 0.3 | X14: 1355 | Y14: =Y13-H13 | Z14: 1500 | AA14: 0 | AB14: 1980卡派 | AE14: 切换到RUI卖
A15: WEEK13 | B15: 7.12-7.18 | C15: R0001EU | D15: 119.99 | E15: 10 | F15: 7DD+加大广告投放 | G15: =M15/7 | H15: =G15*7 | I15: 20 | J15: 4.6 | K15: 2 | L15: 测评 | M15: 80 | N15: =D15*H15 | O15: 75 | P15: =G15/O15 | Q15: 主推关键词：milbensauger,milbensauger für matratzen 目标：第1页 | R15: =T15*S15 | S15: =V15/U15 | T15: 0.9 | U15: 0.17 | V15: =G15*W15 | W15: 0.3 | X15: =X14-H14 | Y15: 264 | Z15: 1500 | AA15: 2100 | AB15: 1980
A16: WEEK14 | B16: 7.19-7.25 | C16: R0001EU | D16: 119.99 | E16: 0.1 | F16: 7DD+加大广告投放 | G16: =M16/7 | H16: =G16*7 | I16: 20 | J16: 4.6 | K16: 2 | L16: 测评 | M16: 85 | N16: =D16*H16 | O16: 75 | P16: =G16/O16 | Q16: 主推关键词：milbensauger,milbensauger für matratzen 目标：第1页 | R16: =T16*S16 | S16: =V16/U16 | T16: 0.9 | U16: 0.17 | V16: =G16*W16 | W16: 0.3 | X16: =X15-H15 | Y16: 264 | Z16: 1500 | AA16: 2100 | AB16: 1980
A17: WEEK15 | B17: 7.26--8.2 | C17: R0001EU | D17: 119.99 | E17: 0.1 | F17: 7DD+加大广告投放 | G17: =M17/7 | H17: =G17*7 | I17: 20 | J17: 4.6 | K17: 2 | L17: 测评 | M17: 95 | N17: =D17*H17 | O17: 80 | P17: =G17/O17 | Q17: 主推关键词：milbensauger,milbensauger für matratzen 目标：第1页 | R17: =T17*S17 | S17: =V17/U17 | T17: 0.9 | U17: 0.17 | V17: =G17*W17 | W17: 0.3 | X17: =X16-H16 | Y17: 264 | Z17: 1500 | AA17: 2100 | AB17: 1980
A18: WEEK16 | B18: 8.3-8.9 | C18: R0001EU | D18: 119.99 | E18: 0.1 | F18: 7DD+加大广告投放 | G18: =M18/7 | H18: =G18*7 | I18: 20 | J18: 4.6 | K18: 2 | L18: 测评 | M18: 100 | N18: =D18*H18 | O18: 80 | P18: =G18/O18 | Q18: 主推关键词：milbensauger,milbensauger für matratzen 目标：第1页 | R18: =T18*S18 | S18: =V18/U18 | T18: 0.9 | U18: 0.17 | V18: =G18*W18 | W18: 0.3 | X18: =X17-H17 | Y18: 264 | Z18: 1500 | AA18: 2100 | AB18: 1980
A19: WEEK17 | B19: 8.10-8.16 | C19: R0001EU | D19: 119.99 | E19: 0.1 | F19: 7DD+加大广告投放 | G19: =M19/7 | H19: =G19*7 | I19: 20 | J19: 4.6 | K19: 2 | L19: 测评 | M19: 80 | N19: =D19*H19 | O19: 80 | P19: =G19/O19 | Q19: 主推关键词：milbensauger,milbensauger für matratzen 目标：第1页 | R19: =T19*S19 | S19: =V19/U19 | T19: 0.9 | U19: 0.17 | V19: =G19*W19 | W19: 0.3 | X19: =X18-H18 | Y19: 264 | Z19: 1500 | AA19: 2100 | AB19: 1980
A20: WEEK18 | B20: 8.17-8.23 | C20: R0001EU | D20: 119.99 | E20: 0.1 | F20: 7DD+加大广告投放 | G20: =M20/7 | H20: =G20*7 | I20: 20 | J20: 4.6 | K20: 2 | L20: 测评 | M20: 60 | N20: =D20*H20 | O20: 60 | P20: =G20/O20 | Q20: 主推关键词：milbensauger,milbensauger für matratzen 目标：第1页 | R20: =T20*S20 | S20: =V20/U20 | T20: 0.9 | U20: 0.17 | V20: =G20*W20 | W20: 0.3 | X20: =X19-H19 | Y20: 264 | Z20: 1500 | AA20: 2100 | AB20: 1980
A21: WEEK19 | B21: 8.24-8.30 | C21: R0001EU | D21: 119.99 | E21: 0.1 | F21: 7DD+加大广告投放 | G21: =M21/7 | H21: =G21*7 | I21: 20 | J21: 4.6 | K21: 2 | L21: 测评 | M21: 65 | N21: =D21*H21 | O21: 60 | P21: =G21/O21 | Q21: 主推关键词：milbensauger,milbensauger für matratzen 目标：第1页 | R21: =T21*S21 | S21: =V21/U21 | T21: 0.9 | U21: 0.17 | V21: =G21*W21 | W21: 0.3 | X21: =X20-H20 | Y21: 264 | Z21: 1500 | AA21: 2100 | AB21: 1980
A22: WEEK20 | B22: 8.24-8.30 | C22: R0001EU | D22: 119.99 | E22: 0.1 | F22: 7DD+加大广告投放 | G22: =M22/7 | H22: =G22*7 | I22: 20 | J22: 4.6 | K22: 2 | L22: 测评 | M22: 75 | N22: =D22*H22 | O22: 60 | P22: =G22/O22 | Q22: 主推关键词：milbensauger,milbensauger für matratzen 目标：第1页 | R22: =T22*S22 | S22: =V22/U22 | T22: 0.9
A23: WEEK21 | B23: 8.24-8.30 | C23: R0001EU | D23: 119.99 | E23: 0.1 | F23: 7DD+加大广告投放 | G23: =M23/7 | H23: =G23*7 | I23: 20 | J23: 4.6 | K23: 2 | L23: 测评 | M23: 80 | N23: =D23*H23 | O23: 60 | P23: =G23/O23 | Q23: 主推关键词：milbensauger,milbensauger für matratzen 目标：第1页 | R23: =T23*S23 | S23: =V23/U23 | T23: 0.9
A24: WEEK22 | B24: 8.24-8.30 | C24: R0001EU | D24: 119.99 | E24: 0.1 | F24: 7DD+加大广告投放 | G24: =M24/7 | H24: =G24*7 | I24: 20 | J24: 4.6 | K24: 2 | L24: 测评 | M24: 90 | N24: =D24*H24 | O24: 60 | P24: =G24/O24 | Q24: 主推关键词：milbensauger,milbensauger für matratzen 目标：第1页 | R24: =T24*S24 | S24: =V24/U24 | T24: 0.9
A25: WEEK23 | B25: 8.24-8.30 | C25: R0001EU | D25: 119.99 | E25: 0.1 | F25: 7DD+加大广告投放 | G25: =M25/7 | H25: =G25*7 | I25: 20 | J25: 4.6 | K25: 2 | L25: 测评 | M25: 95 | N25: =D25*H25 | O25: 60 | P25: =G25/O25 | Q25: 主推关键词：milbensauger,milbensauger für matratzen 目标：第1页 | R25: =T25*S25 | S25: =V25/U25 | T25: 0.9
A26: WEEK24 | B26: 8.24-8.30 | C26: R0001EU | D26: 119.99 | E26: 0.1 | F26: 7DD+加大广告投放 | G26: =M26/7 | H26: =G26*7 | I26: 20 | J26: 4.6 | K26: 2 | L26: 测评 | M26: 100 | N26: =D26*H26 | O26: 60 | P26: =G26/O26 | Q26: 主推关键词：milbensauger,milbensauger für matratzen 目标：第1页 | R26: =T26*S26 | S26: =V26/U26 | T26: 0.9
A27: WEEK25 | B27: 8.24-8.30 | C27: R0001EU | D27: 119.99 | E27: 0.1 | F27: 7DD+加大广告投放 | G27: =M27/7 | H27: =G27*7 | I27: 20 | J27: 4.6 | K27: 2 | L27: 测评 | M27: 120 | N27: =D27*H27 | O27: 60 | P27: =G27/O27 | Q27: 主推关键词：milbensauger,milbensauger für matratzen 目标：第1页 | R27: =T27*S27 | S27: =V27/U27 | T27: 0.9
A28: WEEK25 | B28: 8.24-8.30 | C28: R0001EU | D28: 119.99 | E28: 0.1 | F28: 7DD+加大广告投放 | G28: =M28/7 | H28: =G28*7 | I28: 20 | J28: 4.6 | K28: 2 | L28: 测评 | M28: 120 | N28: =D28*H28 | O28: 60 | P28: =G28/O28 | Q28: 主推关键词：milbensauger,milbensauger für matratzen 目标：第1页 | R28: =T28*S28 | S28: =V28/U28 | T28: 0.9
A29: WEEK25 | B29: 8.24-8.30 | C29: R0001EU | D29: 119.99 | E29: 0.1 | F29: 7DD+加大广告投放 | G29: =M29/7 | H29: =G29*7 | I29: 20 | J29: 4.6 | K29: 2 | L29: 测评 | M29: 120 | N29: =D29*H29 | O29: 60 | P29: =G29/O29 | Q29: 主推关键词：milbensauger,milbensauger für matratzen 目标：第1页 | R29: =T29*S29 | S29: =V29/U29 | T29: 0.9

Sheet 广告计划
A1: 预估量说明： 平均cpc和转化率的值的预估方法： 1.市场调研得到同行平均cpc的基础上适当上调； 2.正在做的同品类商品的历史cpc基础上适当上调； 平均cpc和转化率计划制定的说明： 新品期间波动大，采用梯度预估 eg:当cpc为2.5$,转化率为5%的时候，完成日销目标对应的广告费为105$/天； 当cpc为2.3$.转化率为7%的时候，完成日销目标对应的广告费为69$/天 B0F1F7J8V3
A10: WEEK | B10: Date | C10: 售价 | D10: 目标平均日销 | E10: 销售额 | F10: 转化率 | G10: 日均流量 | H10: 广告销量 | I10: 广告销售额 | J10: 广告订单占比 | K10: 广告费 | L10: 点击量 | M10: 预估量 | O10: 广告结构 | P10: 广告目标及关注指标 | Q10: 广告关键词 | R10: 不同广告类型预算分配
L11: 点击量 | M11: 平均cpc | N11: 广告转化率
A12: WEEK1 | B12: 4.28-5.6 | C12: 109.99 | D12: 6.2857143 | E12: =C12*D12*7 | F12: 0.095238095 | G12: =D12/F12 | H12: =D12*J12 | I12: =H12*C12 | J12: 0.7 | K12: =L12*M12 | L12: =$H$12/N12 | M12: 1.2 | N12: 0.11 | O12: campaign1：自动广告 campaign2：手动广告测试组B campaign3：SD-categories campaign4：PT campaign5：手动广告核心关键词E | P12: 有效流量引入 点击率；转化率；订单量 | Q12: milbensauger（主推） milbensauger für matratzen 核心词 milbensauger milbenstaubsauger milbensauger für matratzen milbensauger mit uv licht milbensauger für matratzen testsieger Milbensauger Hoover milbensauger 长尾词 milbenstaubsauger handstaubsauger milbensauger für matratzen testsieger matratzenreiniger gerät polsterreiniger gerät “沙发清洁器”“软家具清洁设备” milbensauger milbenstaubsauger milbensauger für matratzen testsieger 欧11531 jimmy jv35 12362 jigoo t600 milbensauger 44157 jigoo milbensauger 53568 hoover milbensauger 62790 milbensauger für matratzen testsieger 90467 jimmy jv35 milbensauger 125594 milbenstaubsauger 247901 milbensauger mit uv licht 2625420 milbensauger für matratzen 5657246 milbensauger 关键词分析 milbensauger， milbensauger für matratzen testsieger， Milbenstaubsauger milbensauger mit uv licht milbensauger für matratzen Milbensauger jigoo milbensauger Hoover milbensauger 核心关键词 选取，milbensauger， milbenstaubsauger milbensauger für matratzen， milbensauger mit uv licht 长尾词 milbenstaubsauger handstaubsauger手持吸尘器 milbensauger für matratzen testsieger matratzenreiniger gerät 关键词竞价分析：除螨仪milbensauger 竞价CPC 1-1.54欧 Milbenstaubsauger 除螨仪 1.5-2.3欧 关键词竞价分析：床垫除螨仪milbensauger für matratzen 竞价CPC 1-2.4欧 带紫外线除螨仪 milbensauger mit uv licht 1.8-2.9欧 milbensauger für matratzen testsieger 1- 2.2欧 hoover milbensauger 1.8-2.8欧 jimmy jv35 milbensauger 1.1-3欧 以词拓词 Milbensauger
K13: =L13*M13 | L13: =$H$12/N13 | M13: 1.2 | N13: 0.11
K14: =L14*M14 | L14: =$H$12/N14 | M14: 1.2 | N14: 0.11
K15: =L15*M15 | L15: =$H$12/N15 | M15: 1.2 | N15: 0.11
A16: WEEK2 | B16: 5.7-5.13 | C16: 109.99 | D16: 11.571429 | E16: =C16*D16*7 | F16: 0.13149351 | G16: =D16/F16 | H16: =D16*J16 | I16: =H16*C16 | J16: 0.65 | K16: =L16*M16 | L16: =$H$16/N16 | M16: 1.2 | N16: 0.12 | O16: campaign1：自动广告 campaign2：手动广告测试组B campaign3：SD-categories campaign4：PT campaign5：手动广告核心关键词E campaign6：SBV-PT / SBV-KT | R16: SP:70% SD:15% SB:15% | S16: 关键词 | T16: 关键词翻译 | U16: 流量占比 | V16: 预估周曝光量 | W16: 关键词类型 | X16: 转化效果自然流量占比
K17: =L17*M17 | L17: =$H$16/N17 | M17: 1.2 | N17: 0.12 | S17: milbensauger | T17: 吸螨虫 | U17: 0.497508 | V17: 13984 | W17: 主要流量词 | X17: 0.3471
K18: =L18*M18 | L18: =$H$16/N18 | M18: 1.2 | N18: 0.12 | S18: milbensauger für matratzen | T18: 用于床垫的吸尘器 | U18: 0.294441 | V18: 8276 | W18: 主要流量词 | X18: 0.41862
K19: =L19*M19 | L19: =$H$16/N19 | M19: 1.2 | N19: 0.12 | S19: sofa reiniger | T19: 沙发清洁剂 | U19: 0.059295 | V19: 1667 | X19: 0.61722
A20: WEEK3 | B20: 5.14-5.20 | C20: 109.99 | D20: 7.8571429 | E20: =C20*D20*7 | F20: 0.13095238 | G20: =D20/F20 | H20: =D20*J20 | I20: =H20*C20 | J20: 0.6 | K20: =L20*M20 | L20: =$H$20/N20 | M20: 1.1 | N20: 0.13 | O20: campaign1：自动广告 campaign2：手动广告测试组B campaign3：SD-categories campaign4：PT campaign5：手动广告核心关键词E campaign6：SBV-PT / SBV-KT | S20: matratzenreiniger | T20: 床垫清洁剂 | U20: 0.047246 | V20: 1328 | X20: 0.80955
K21: =L21*M21 | L21: =$H$20/N21 | M21: 1.1 | N21: 0.13 | S21: milbensauger für matratzen testsieger | T21: 用于床垫测试的螨虫吸尘器测试获胜者 | U21: 0.02472 | V21: 695 | X21: 0.46301
K22: =L22*M22 | L22: =$H$20/N22 | M22: 1.1 | N22: 0.13 | S22: milbensauger mit uv licht | T22: 带紫外线灯的螨虫奶嘴 | U22: 0.019301 | V22: 543 | X22: 0.06106
K23: =L23*M23 | L23: =$H$20/N23 | M23: 1.1 | N23: 0.13 | S23: hoover milbensauger | T23: 胡佛螨吸盘 | U23: 0.017954 | V23: 505 | W23: 精准长尾词 | X23: 0.50632
A24: WEEK4 | B24: 5.21-5.27 | C24: 109.99 | D24: 6.8571429 | E24: =C24*D24*7 | F24: 0.13714286 | G24: =D24/F24 | H24: =D24*J24 | I24: =H24*C24 | J24: 0.55 | K24: =L24*M24 | L24: =$H$24/N24 | M24: 1.1 | N24: 0.15 | O24: campaign1：自动广告 campaign2：手动广告测试组B campaign3：SD-categories campaign4：PT campaign5：手动广告核心关键词E campaign6：SBV-PT / SBV-KT | R24: SP:70% SD:15% SB:15% | S24: milbenstaubsauger | T24: 螨吸尘器 | U24: 0.008428 | V24: 237 | X24: 0.28778
K25: =L25*M25 | L25: =$H$24/N25 | M25: 1.1 | N25: 0.15 | S25: polsterreiniger | T25: 室内装饰品清洁剂 | U25: 0.007424 | V25: 209
K26: =L26*M26 | L26: =$H$24/N26 | M26: 1.1 | N26: 0.15 | S26: teppichreiniger gerät | T26: 地毯清洁装置 | U26: 0.002209 | V26: 62
K27: =L27*M27 | L27: =$H$24/N27 | M27: 1.1 | N27: 0.15 | S27: polsterreinigungsgerät | T27: 室内装潢清洗机 | U27: 0.001316 | V27: 37
A28: WEEK5 | B28: 5.28-6.3 | C28: 119.99 | D28: 7.4285714 | E28: =C28*D28*7 | F28: 0.13265306 | G28: =D28/F28 | H28: =D28*J28 | I28: =H28*C28 | J28: 0.5 | K28: =L28*M28 | L28: =$H$28/N28 | M28: 1 | N28: 0.15 | O28: campaign1：自动广告 campaign2：手动广告主推词BP campaign3：SD-categories campaign4：PT campaign5：手动广告核心关键词E campaign6：SBV-PT / SBV-KT | P28: 推动销售 点击率；转化率；订单量；Acos
K29: =L29*M29 | L29: =$H$28/N29 | M29: 1 | N29: 0.15
K30: =L30*M30 | L30: =$H$28/N30 | M30: 1 | N30: 0.15
K31: =L31*M31 | L31: =$H$28/N31 | M31: 1 | N31: 0.15
A32: WEEK6 | B32: 6.4-6.10 | C32: 119.99 | D32: 7.1428571 | E32: =C32*D32*7 | F32: 0.11904762 | G32: =D32/F32 | H32: =D32*J32 | I32: =H32*C32 | J32: 0.5 | K32: =L32*M32 | L32: =$H$32/N32 | M32: 1 | N32: 0.15 | O32: campaign1：自动广告 campaign2：手动广告主推词BP campaign3：SD-categories campaign4：PT campaign5：手动广告核心关键词E campaign6：SBV-PT / SBV-KT | R32: SP:70% SD:15% SB:15%
K33: =L33*M33 | L33: =$H$32/N33 | M33: 1 | N33: 0.15
K34: =L34*M34 | L34: =$H$32/N34 | M34: 1 | N34: 0.15
K35: =L35*M35 | L35: =$H$32/N35 | M35: 1 | N35: 0.15
A36: WEEK7 | B36: 6.11-6.17 | C36: 119.99 | D36: 8.2857143 | E36: =C36*D36*7 | F36: 0.12184874 | G36: =D36/F36 | H36: =D36*J36 | I36: =H36*C36 | J36: 0.5 | K36: =L36*M36 | L36: =$H$36/N36 | M36: 0.9 | N36: 0.16 | O36: campaign1：自动广告 campaign2：手动广告主推词BP campaign3：SD-categories campaign4：PT campaign5：手动广告核心关键词E campaign6：SBV-PT / SBV-KT
K37: =L37*M37 | L37: =$H$36/N37 | M37: 0.9 | N37: 0.16
K38: =L38*M38 | L38: =$H$36/N38 | M38: 0.9 | N38: 0.16
K39: =L39*M39 | L39: =$H$36/N39 | M39: 0.9 | N39: 0.16
A40: WEEK8 | B40: 6.18-6.24 | C40: 119.99 | D40: 7.1428571 | E40: =C40*D40*7 | F40: 0.10504202 | G40: =D40/F40 | H40: =D40*J40 | I40: =H40*C40 | J40: 0.45 | K40: =L40*M40 | L40: =$H$40/N40 | M40: 0.9 | N40: 0.16 | O40: campaign1：自动广告 campaign2：手动广告主推词BP campaign3：SD-categories campaign4：PT campaign5：手动广告核心关键词E campaign6：SBV-PT / SBV-KT | R40: SP:70% SD:15% SB:15%
K41: =L41*M41 | L41: =$H$40/N41 | M41: 0.9 | N41: 0.16
K42: =L42*M42 | L42: =$H$40/N42 | M42: 0.9 | N42: 0.16
K43: =L43*M43 | L43: =$H$40/N43 | M43: 0.9 | N43: 0.16
A44: WEEK9 | B44: 6.25-7.1 | C44: 119.99 | D44: 7.8571429 | E44: =C44*D44*7 | F44: 0.1122449 | G44: =D44/F44 | H44: =D44*J44 | I44: =H44*C44 | J44: 0.45 | K44: =L44*M44 | L44: =$H$44/N44 | M44: 0.9 | N44: 0.16 | O44: campaign1：自动广告 campaign2：手动广告主推词BP campaign3：SD-categories campaign4：PT campaign5：手动广告核心关键词E campaign6：SBV-PT / SBV-KT
K45: =L45*M45 | L45: =$H$44/N45 | M45: 0.9 | N45: 0.16
K46: =L46*M46 | L46: =$H$44/N46 | M46: 0.9 | N46: 0.16
K47: =L47*M47 | L47: =$H$44/N47 | M47: 0.9 | N47: 0.16
A48: WEEK10 | B48: 7.2-7.8 | C48: 119.99 | D48: 9.2857143 | E48: =C48*D48*7 | F48: 0.12380952 | G48: =D48/F48 | H48: =D48*J48 | I48: =H48*C48 | J48: 0.4 | K48: =L48*M48 | L48: =$H$48/N48 | M48: 0.9 | N48: 0.16 | O48: campaign1：自动广告 campaign2：手动广告主推词BP campaign3：SD-categories campaign4：PT campaign5：手动广告核心关键词E campaign6：SBV-PT / SBV-KT | R48: SP:70% SD:15% SB:15%
...

Sheet 利润&ROI测算
A1: 细分项 | L1: 4月 | AB1: 5月 | AR1: 6月 | BH1: 达标后每月销售
A2: 状态 | B2: Asin | C2: Model# | D2: 国家 | E2: 佣金比例 | F2: RMA比例 | G2: 广告费占比 | H2: MC/个 | I2: FBA配送费 | J2: 退换货分摊 /个 | K2: VAT | L2: 待办操作 | M2: 售价 | N2: 月销量 | O2: 销售总额 | P2: MC | Q2: 佣金 | R2: 配送费 | S2: RMA扣减 | T2: 广告费 | U2: 促销费 | V2: VAT | W2: 成本总计 | X2: 回款额 UK | Y2: 回款率 | Z2: 净毛利 US | AA2: 净毛利率 | AB2: 操作 | AC2: 售价 | AD2: 月销量 | AE2: 销售总额 | AF2: MC | AG2: 佣金 | AH2: 配送费 | AI2: RMA扣减 | AJ2: 广告费 | AK2: 促销费 | AL2: VAT | AM2: 成本总计 | AN2: 回款额 US | AO2: 回款率 | AP2: 净毛利 US | AQ2: 净毛利率 | AR2: 操作 | AS2: 售价 | AT2: 月销量 | AU2: 销售总额 | AV2: MC | AW2: 佣金 | AX2: 配送费 | AY2: RMA扣减 | AZ2: 广告费 | BA2: 促销费 | BB2: VAT | BC2: 成本总计 | BD2: 回款额 US | BE2: 回款率 | BF2: 净毛利 US | BG2: 净毛利率 | BH2: 操作 | BI2: 售价 | BJ2: 月销量 | BK2: 销售总额 | BL2: 产品成本 | BM2: 佣金 | BN2: 配送费 | BO2: RMA扣减 | BP2: 广告费 | BQ2: 促销费 | BR2: VAT | BS2: 成本总计 | BT2: 回款额 EU | BU2: 回款率 | BV2: 净毛利 EU | BW2: 净毛利率
A3: 卡航 | B3: B0XXXXXXV3 | C3: SK0001EU | D3: DE | E3: 0.15 | F3: 0.07 | G3: 0.15 | H3: =122.56/7.4 | I3: 5.69 | J3: =(H3+I3)*F3 | K3: 0.16 | L3: B0XXXXXXV3 | M3: 109.99 | N3: 450 | O3: =M3*N3 | P3: =$H3*N3 | Q3: =M3*$E3*N3 | R3: =I3*N3 | S3: =$J3*N3 | T3: =O3*18% | U3: =O3*12% | V3: =O3*K3 | W3: =P3+Q3+R3+S3+T3+U3+V3 | X3: =O3-Q3-R3-T3-U3-V3 | Y3: =X3/O3 | Z3: =O3-W3 | AA3: =Z3/O3 | AC3: 114.99 | AD3: 500 | AE3: =AC3*AD3 | AF3: =$H3*AD3 | AG3: =AC3*$E3*AD3 | AH3: =AD3*I3 | AI3: =$J3*AD3 | AJ3: =AE3*10% | AK3: =AE3*6% | AL3: =AE3*K3 | AM3: =AF3+AG3+AH3+AI3+AJ3+AK3+AL3 | AN3: =AE3-AG3-AH3-AJ3-AL3 | AO3: =AN3/AE3 | AP3: =AE3-AM3 | AQ3: =AP3/AE3 | AS3: 116.99 | AT3: 700 | AU3: =AS3*AT3 | AV3: =$H3*AT3 | AW3: =AS3*$E3*AT3 | AX3: =AT3*I3 | AY3: =$J3*AT3 | AZ3: =AU3*7% | BA3: =AU3*15% | BB3: =K3*AU3 | BC3: =AV3+AW3+AX3+AY3+AZ3+BA3+BB3 | BD3: =AU3-AW3-AX3-AZ3-BB3 | BE3: =BD3/AU3 | BF3: =AU3-BC3 | BG3: =BF3/AU3 | BI3: 119.99 | BJ3: 1500 | BK3: =BI3*BJ3 | BL3: =$H3*BJ3 | BM3: =E3*BK3 | BN3: =I3*BJ3 | BO3: =$J3*BJ3 | BP3: =BK3*5.5% | BQ3: =BK3*8% | BR3: =K3*BK3 | BS3: =BL3+BM3+BN3+BO3+BP3+BQ3+BR3 | BT3: =BK3-BM3-BN3-BP3-BR3 | BU3: =BT3/BK3 | BV3: =BK3-BS3 | BW3: =BV3/BK3
A4: 铁路 | B4: B0XXXXXXV3 | C4: SK0001EU | D4: DE | E4: 0.15 | F4: 0.07 | G4: 0.15 | H4: =122.56/7.4 | I4: 5.69 | J4: =(H4+I4)*F4 | K4: 0.16 | L4: B0XXXXXXV3 | M4: 109.99 | N4: 450 | O4: =M4*N4 | P4: =$H4*N4 | Q4: =M4*$E4*N4 | R4: =I4*N4 | S4: =$J4*N4 | T4: =O4*18% | U4: =O4*12% | V4: =O4*K4 | W4: =P4+Q4+R4+S4+T4+U4+V4 | X4: =O4-Q4-R4-T4-U4-V4 | Y4: =X4/O4 | Z4: =O4-W4 | AA4: =Z4/O4 | AC4: 114.99 | AD4: 500 | AE4: =AC4*AD4 | AF4: =$H4*AD4 | AG4: =AC4*$E4*AD4 | AH4: =AD4*I4 | AI4: =$J4*AD4 | AJ4: =AE4*10% | AK4: =AE4*6% | AL4: =AE4*K4 | AM4: =AF4+AG4+AH4+AI4+AJ4+AK4+AL4 | AN4: =AE4-AG4-AH4-AJ4-AL4 | AO4: =AN4/AE4 | AP4: =AE4-AM4 | AQ4: =AP4/AE4 | AS4: 116.99 | AT4: 700 | AU4: =AS4*AT4 | AV4: =$H4*AT4 | AW4: =AS4*$E4*AT4 | AX4: =AT4*I4 | AY4: =$J4*AT4 | AZ4: =AU4*7% | BA4: =AU4*15% | BB4: =K4*AU4 | BC4: =AV4+AW4+AX4+AY4+AZ4+BA4+BB4 | BD4: =AU4-AW4-AX4-AZ4-BB4 | BE4: =BD4/AU4 | BF4: =AU4-BC4 | BG4: =BF4/AU4 | BI4: 119.99 | BJ4: 1500 | BK4: =BI4*BJ4 | BL4: =$H4*BJ4 | BM4: =E4*BK4 | BN4: =I4*BJ4 | BO4: =$J4*BJ4 | BP4: =BK4*5.5% | BQ4: =BK4*8% | BR4: =K4*BK4 | BS4: =BL4+BM4+BN4+BO4+BP4+BQ4+BR4 | BT4: =BK4-BM4-BN4-BP4-BR4 | BU4: =BT4/BK4 | BV4: =BK4-BS4 | BW4: =BV4/BK4
A5: 海运 | B5: B0XXXXXXV3 | C5: SK0001EU | D5: DE | E5: 0.15 | F5: 0.07 | G5: 0.15 | H5: =122.56/7.4 | I5: 5.69 | J5: =(H5+I5)*F5 | K5: 0.16 | L5: B0XXXXXXV3 | M5: 109.99 | N5: 450 | O5: =M5*N5 | P5: =$H5*N5 | Q5: =M5*$E5*N5 | R5: =I5*N5 | S5: =$J5*N5 | T5: =O5*18% | U5: =O5*12% | V5: =O5*K5 | W5: =P5+Q5+R5+S5+T5+U5+V5 | X5: =O5-Q5-R5-T5-U5-V5 | Y5: =X5/O5 | Z5: =O5-W5 | AA5: =Z5/O5
A6: 空运 | B6: B0XXXXXXV3 | C6: SK0001EU | D6: DE | E6: 0.15 | F6: 0.07 | G6: 0.15 | H6: =122.56/7.4 | I6: 5.69 | J6: =(H6+I6)*F6 | K6: 0.16 | L6: B0XXXXXXV3 | M6: 109.99 | N6: 450 | O6: =M6*N6 | P6: =$H6*N6 | Q6: =M6*$E6*N6 | R6: =I6*N6 | S6: =$J6*N6 | T6: =O6*18% | U6: =O6*12% | V6: =O6*K6 | W6: =P6+Q6+R6+S6+T6+U6+V6 | X6: =O6-Q6-R6-T6-U6-V6 | Y6: =X6/O6 | Z6: =O6-W6 | AA6: =Z6/O6
N8: =SUM(N3:N6) | O8: =SUM(O3:O6) | P8: =SUM(P3:P6) | Q8: =SUM(Q3:Q6) | R8: =SUM(R3:R6) | S8: =SUM(S3:S6) | T8: =SUM(T3:T6) | U8: =SUM(U3:U6) | ... X8: =SUM(X3:X6) | Y8: =X8/O8 | Z8: =SUM(Z3:Z6) | AA8: =Z8/O8 | AD8: =SUM(AD3:AD6) | AE8: =SUM(AE3:AE6) | AF8: =SUM(AF3:AF6) | AG8: =SUM(AG3:AG6) | AH8: =SUM(AH3:AH6) | AI8: =SUM(AI3:AI6) | AJ8: =SUM(AJ3:AJ6) | AK8: =SUM(AK3:AK6) | ... AN8: =SUM(AN3:AN6) | AO8: =AN8/AE8 | AP8: =SUM(AP3:AP6) | AQ8: =AP8/AE8 | AT8: =SUM(AT3:AT6) | AU8: =SUM(AU3:AU6) | AV8: =SUM(AV3:AV6) | AW8: =SUM(AW3:AW6) | AX8: =SUM(AX3:AX6) | AY8: =SUM(AY3:AY6) | AZ8: =SUM(AZ3:AZ6) | BA8: =SUM(BA3:BA6) | ... BD8: =SUM(BD3:BD6) | BE8: =BD8/AU8 | BF8: =SUM(BF3:BF6) | BG8: =BF8/AU8 | BJ8: =SUM(BJ3:BJ6) | BK8: =SUM(BK3:BK6) | BL8: =SUM(BL3:BL6) | BM8: =SUM(BM3:BM6) | BN8: =SUM(BN3:BN6) | BO8: =SUM(BO3:BO6) | BP8: =SUM(BP3:BP6) | BQ8: =SUM(BQ3:BQ6) | ... BT8: =SUM(BT3:BT6) | BU8: =BT8/BK8 | BV8: =SUM(BV3:BV6) | BW8: =BV8/BK8
A11: 价格利润测算
A13: Asin | B13: Model | C13: Price | D13: All cost | E13: Profit | F13: Profit% | G13: MC | H13: 佣金 | I13: 配送费 | J13: 退货均摊 | K13: VAT税率 | L13: 佣金率 | M13: 退货率 | N13: 折扣% off | O13: 底价
A14: B0XXXXXXV3 | B14: SK0001EU | C14: =$M$3 | D14: =G14+H14+I14+J14+K14*C14+C14*N14 | E14: =C14-D14 | F14: =E14/C14 | G14: 6.27 | H14: =C14*L14 | I14: =$I$3 | J14: =C14*M14 | K14: 0.16 | L14: =$E$3 | M14: =$F$3 | N14: 0.1 | O14: =(G14+I14)/(1-L14-M14-K14)
A15: B0XXXXXXV3 | B15: SK0001EU | C15: =$M$3 | D15: =G15+H15+I15+J15+K15*C15+C15*N15 | E15: =C15-D15 | F15: =E15/C15 | G15: 6.27 | H15: =C15*L15 | I15: =$I$3 | J15: =C15*M15 | K15: 0.16 | L15: =$E$3 | M15: =$F$3 | N15: 0.05 | O15: =(G15+I15)/(1-L15-M15-K15)
A16: B0XXXXXXV3 | B16: SK0001EU | C16: =$M$3 | D16: =G16+H16+I16+J16+K16*C16+C16*N16 | E16: =C16-D16 | F16: =E16/C16 | G16: 6.27 | H16: =C16*L16 | I16: =$I$3 | J16: =C16*M16 | K16: 0.16 | L16: =$E$3 | M16: =$F$3 | N16: 0.05 | O16: =(G16+I16)/(1-L16-M16-K16)
