Workbook

Sheet 项目进度
A1: 项目进度计划表
A2: 一、项目基本情况
A3: 项目名称 | B3: 英国 扫地机 | G3: 项目编号 | M3: XXXX-111
A4: 负责人 | B4: 西悉尼下1 | G4: 执行人 | M4: 西悉尼下3
A5: 知情人 | B5: 西悉尼下2 | G5: 顾问 | M5: 西悉尼下4
A6: 二、关键节点图
A8: 三、项目进度表
B9: 周 | C9: 1 | I9: 休 | J9: 2 | O9: 休 | P9: 休 | Q9: 3 | V9: 年假 | AC9: 4 | AK9: 休 | AL9: 5 | AQ9: 休 | AR9: 休 | AS9: 6 | AY9: 休 | AZ9: 7 | BE9: 休 | BF9: 休 | BG9: 8 | BM9: 休 | BN9: 9 | BS9: 休 | BT9: 休 | BU9: 10
A10: 版块 | B10: 关键动作 | C10: 44571 | D10: 44572 | E10: 44573 | F10: 44574 | G10: 44575 | H10: 44576 | I10: 44577 | J10: 44578 | K10: 44579 | L10: 44580 | M10: 44581 | N10: 44582 | O10: 44583 | P10: 44584 | Q10: 44585 | R10: 44586 | S10: 44587 | T10: 44588 | U10: 44589 | V10: 44590 | W10: 44591 | X10: 44592 | Y10: 44593 | Z10: 44594 | AA10: 44595 | AB10: 44596 | AC10: 44597 | AD10: 44598 | AE10: 44599 | AF10: 44600 | AG10: 44601 | AH10: 44602 | AI10: 44603 | AJ10: 44604 | AK10: 44605 | AL10: 44606 | AM10: 44607 | AN10: 44608 | AO10: 44609 | AP10: 44610 | AQ10: 44611 | AR10: 44612 | AS10: 44613 | AT10: 44614 | AU10: 44615 | AV10: 44616 | AW10: 44617 | AX10: 44618 | AY10: 44619 | AZ10: 44620 | BA10: 44621 | BB10: 44622 | BC10: 44623 | BD10: 44624 | BE10: 44625 | BF10: 44626 | BG10: 44627 | BH10: 44628 | BI10: 44629 | BJ10: 44630 | BK10: 44631 | BL10: 44632 | BM10: 44633 | BN10: 44634 | BO10: 44635 | BP10: 44636 | BQ10: 44637 | BR10: 44638 | BS10: 44639 | BT10: 44640 | BU10: 44641 | BV10: 44642
A11: PMC XXX | B11: 立项开模12.10
B12: T0验证12.30
B13: 修模
B14: T1验证1.8
B15: 修模
B16: 签样量产
B17: 评议营销计划
B18: 首批原材料下单
B19: 原材料生产
B20: 提醒创建X00
B21: 完成BOM录入系统
B22: 提醒走Listing流程
B23: 交货 | AP23: 1 | AQ23: 1 | AR23: 1 | AS23: 1 | AT23: 1 | AU23: 1
B24: 发货 | AR24: 2 | AT24: 2 | AV24: 2
B25: 到货 | AZ25: US-1K | BB25: US-2K | BG25: DE-1K | BK25: DE-2K
B26: 上架 | BJ26: US-1K | BK26: DE-1K | BL26: US-2K | BO26: DE-1K
B27: 审核首单配送费用
A28: 市场调研 | B28: 了解墙头充电历史容量、同类型产品市场表现等
B29: 确定产品USP、基础卖点
A30: 营销计划（销量预估） 李子云 | B30: 初稿（60天计划）
B31: 内部会议、修改
B32: 第一次会议-AAA
B33: 营销计划修改
B34: 营销计划定稿
A35: 图片：主副图、A+ XXX | B35: 图片需求调研
B36: 运营头脑风暴确定图片需求
B37: 图片需求同频给设计
B38: 设计出草图方案
B39: 运营、设计一起进行草图评议
B40: 草图修改后最终确认
B41: 设计下渲染图
...

Sheet 设计进度安排
A1: 设计出图项目周期管理表
A2: 项目决策权：XXX 负责人：XX 参与人员 XX | H2: 1月 | AF2: 2月
A3: 项目 | C3: 任务内容 | D3: 负责人 | E3: 开始日期 | F3: 完成日期 | G3: 利益干系人 | H3: 准备期 | K3: 方案确定期 | Z3: 出图中期 | AW3: 调整期后期
H4: 8 | I4: 9 | J4: 10 | K4: 11 | L4: 12 | M4: 13 | N4: 14 | O4: 15 | P4: 16 | Q4: 17 | R4: 18 | S4: 19 | T4: 20 | U4: 21 | V4: 22 | W4: 23 | X4: 24 | Y4: 25 | Z4: 26 | AA4: 27 | AB4: 28 | AC4: 29 | AD4: 30 | AE4: 31 | AF4: 1 | AG4: 2 | AH4: 3 | AI4: 4 | AJ4: 5 | AK4: 6 | AL4: 7 | AM4: 8 | AN4: 9 | AO4: 10 | AP4: 11 | AQ4: 12 | AR4: 13 | AS4: 14 | AT4: 15 | AU4: 16 | AV4: 17 | AW4: 18 | AX4: 19 | AY4: 20 | AZ4: 21 | BA4: 22 | BB4: 23 | BC4: 24 | BD4: 25 | BE4: 26 | BF4: 27 | BG4: 28 | BH4: 29 | BI4: 30 | BJ4: 31 | BK4: 32
A5: XXX-111 | B5: 主图 | C5: 3D模型确定，拿样品 | D5: xxx | E5: 202/1/8 | F5: 46366 | G5: xxx
C6: 项目启动会议 | D6: xxx | E6: 202/1/10 | F6: 46032 | G6: xxx
C7: 运营输出需求PPT对接（USP/功能卖点） | D7: xxx | E7: 46034 | F7: 46040 | G7: xxx
C8: 设计出草图方案-第一版 | D8: xxx | E8: 46041 | F8: 46048 | G8: xxx
C9: 设计运营一起讨论确定草图方案-第二版 | D9: xxx | E9: 46048 | F9: 46050 | G9: xxx
C10: 设计下渲染图 | D10: xxx | E10: 46048 | F10: 46050 | G10: xxx
C11: 渲染出主图给设计，确定质感和角度（群沟通） | D11: xxx | E11: 46049 | F11: 46050 | G11: xxx
C12: 第一版稿设计输出(主图一张）给运营确定 | D12: xxx | E12: 46050 | F12: 46051 | G12: xxx
C13: 渲染输出成品给设计 | D13: xxx | E13: 46048 | F13: 46073 | G13: xxx
C14: 设计精修排版（一套） | D14: xxx | E14: 46051 | F14: 46075 | G14: xxx
C15: 输出一套给到运营-增加文案+调整 | D15: xxx | E15: 46075 | F15: 46076 | G15: 全员参与
C16: 最终交稿（主副） | D16: xxx | E16: 46076 | F16: 46077 | G16: xxx
B17: A+ | C17: 设计精修排版（一套） | D17: xxx | E17: 46077 | F17: 46080 | G17: xxx
C18: 输出一套给到运营-增加文案+调整 | D18: xxx | E18: 46079 | F18: 46080 | G18: xxx
C19: A+终稿 | D19: xxx | E19: 46081 | F19: 46081 | G19: xxx
C20: 开会确定 | D20: xxx | E20: 46081 | F20: 46081 | G20: xxx | H20: 蓝色为工作日，黄色为休息日，红色为评议日 全员参与：全员参与评议，由负责人组织，全员讨论，最终有项目决策人决策
C21: MEIG+SHEJI
C22: MEIG+SHEJI

Sheet 测评
A1: 链接 | D1: 周 | E1: 8 | K1: 休 | L1: 9 | Q1: 休 | R1: 休 | S1: 10 | Y1: 休
A2: 美国 | B2: 板块 | D2: 关键动作 | E2: 44627 | F2: 44628 | G2: 44629 | H2: 44630 | I2: 44631 | J2: 44632 | K2: 44633 | L2: 44634 | M2: 44635 | N2: 44636 | O2: 44637 | P2: 44638 | Q2: 44639 | R2: 44640 | S2: 44641 | T2: 44642 | U2: 44643 | V2: 44644 | W2: 44645 | X2: 44646 | Y2: 44647 | Z2: 44648 | AA2: 44649 | AB2: 44650
B3: 测评下单 | C3: 1 | D3: 优质评论：文字+7图 | G3: 1
C4: 1 | D4: TOP：文字+5图+1视频 | H4: 1
C5: 2 | D5: 2个优质评论（文字+7图*2） | I5: 2
C6: 2 | D6: 1个优质评论（文字+5图+1视频）+1个优质评论（文字+7图） | N6: 2
C7: 2 | D7: 1个优质评论（文字+5图）+1个优质评论（文字+7图） | O7: 2
C8: 2 | D8: 1个优质评论（文字+5图）+1个优质评论（文字+7图） | P8: 2
C9: 20 | D9: 普评（20个）推广14个，运营6个 | G9: 1 | H9: 1 | J9: 2 | K9: 2 | L9: 2 | M9: 2 | Q9: 2 | R9: 2 | S9: 2（运营） | T9: 2（运营） | U9: 2（运营）
B11: 显评 | C11: 1 | D11: 优质评论：文字+7图 | N11: 1
C12: 1 | D12: TOP：文字+5图+1视频 | O12: 1
C13: 2 | D13: 2个优质评论（文字+7图*2） | P13: 2
C14: 2 | D14: 1个优质评论（文字+5图+1视频）+1个优质评论（文字+7图） | U14: 2
C15: 2 | D15: 1个优质评论（文字+5图）+1个优质评论（文字+7图） | V15: 2
C16: 2 | D16: 1个优质评论（文字+5图）+1个优质评论（文字+7图） | W16: 2
C17: 20 | D17: 普评（14个） | N17: 1 | O17: 1 | Q17: 2 | R17: 2 | S17: 2 | T17: 2 | X17: 2 | Y17: 2 | Z17: 2 | AA17: 2 | AB17: 2
B21: 备注 | D21: 1. 推广：10（优质）+15（普评） 2. Profile要求 -10个优质：9（100w）+1TOP（10万以内） -Profile不可有XXX的产品 -15个普评：Profile不可超过2个XXX的产品 -所有测评人的Profile不可空白 3. 不可一测二 4. 普评说明 -运营需要确定15个普评的主题 -有10个普评的文案运营写，字数在300字以内，可以跟顾客提一下附上3-5张图片，但不强求。 -另外5个普评的文案只给顾客提供主题，让顾客自由发挥，图片同样是3-5图，但不强求。
B29: 说明

Sheet 站外营销
A1: XXX产品系列项目时间节点图(市场营销）
A12: 市场合作计划表
A13: 平台
A14: 产品USP | B14: XXX
A15: 真机 | B15: 机模4个
A16: 红人时长 | B16: 3-5分钟
A17: 合作方式 | B17: 健身、户外运动、开箱
A18: 视频类型 | B18: 每个人介绍2个型号S22/S22U
A19: 红人合作数量 | B19: 2个
A20: 红人级别 | B20: YT——xxxx粉+
A21: 红人预算 | B21: 200$
A22: 红人佣金 | B22: $1/单
A23: 链接放置位置： | B23: 视频下方
A24: 链接放置时间（以美国东部时间为准） | B24: 3月18上链接
A25: 链接落地页 | B25: 产品页(流量风险)
... A27: 折扣使用范围 | B27: 指定产品
A28: 目标单量
A30: 周 | AR30: 发货 | BI30: 上架
A31: 模块 | B31: 项目 | C31: 44572 | D31: 44573 | E31: 44574 | F31: 44575 | G31: 44576 | H31: 44577 | I31: 44578 | J31: 44579 | K31: 44580 | L31: 44581 | M31: 44582 | N31: 44583 | O31: 44584 | P31: 44585 | Q31: 44586 | R31: 44587 | S31: 44588 | T31: 44589 | U31: 44590 | V31: 44591 | W31: 44592 | X31: 44593 | Y31: 44594 | Z31: 44595 | AA31: 44596 | AB31: 44597 | AC31: 44598 | AD31: 44599 | AE31: 44600 | AF31: 44601 | AG31: 44602 | AH31: 44603 | AI31: 44604 | AJ31: 44605 | AK31: 44606 | AL31: 44607 | AM31: 44608 | AN31: 44609 | AO31: 44610 | AP31: 44611 | AQ31: 44612 | AR31: 44613 | AS31: 44614 | AT31: 44615 | AU31: 44616 | AV31: 44617 | AW31: 44618 | AX31: 44619 | AY31: 44620 | AZ31: 44621 | BA31: 44622 | BB31: 44623 | BC31: 44624 | BD31: 44625 | BE31: 44626 | BF31: 44627 | BG31: 44628 | BH31: 44629 | BI31: 44630 | BJ31: 44631 | BK31: 44632 | BL31: 44633 | BM31: 44634 | BN31: 44635 | BO31: 44636 | BP31: 44637 | BQ31: 44638 | BR31: 44639 | BS31: 44640 | BT31: 44641 | BU31: 44642 | BV31: 44643 | BW31: 44644 | BX31: 44645 | BY31: 44646 | BZ31: 44647
A32: 红人营销 | B32: 确定产品USP(并需要产品实物） | U32: 年假
B33: 寻找对标视频
B34: 视频评议（确定方向+核对合作表格）
B35: 寻找红人+寄送样品
B36: 确定收货
B37: 视频跟进
B38: 合作视频评议会
B39: 视频问题修正时间
B40: 视频发布（折扣有效期3.18-3.27)
B41: 监测数据至活动结束
A42: 社媒 | B42: ⭐站外营销图片和文案准备PPT
B43: 下单
B44: 所有社媒图片的定稿
B45: 社媒发布3月18-3月27

Sheet 1.1核心竞争对手调研
A1: 变体形式
A2: ASIN
A3: 品牌
A4: 图片
A5: 卖点提炼
A6: 销售价格
A7: 尺寸信息
A8: FBA配送费
A9: reviews星级
A10: reviews数量
A11: 类目
A12: review内容分析
... A14: 历史销售数据
A15: 产品总结 | B15: 1.尺寸对比-分析配送费，优化价格 2.对比五点，找出共同描述的点，找出自己产品的差异点 3.查看星级 -是否需要控评 4.review数量-预估上评数量 5.reviews布局- 图片review内容（室内or室外），文字review内容（尺寸，材质，颜色，款式，质量），是否中评卡位 6.对比售价，定位自家价格 7.对比排名情况，设定目标 8.关键词分析

Sheet 1.2 产品定价
A1: 产品采购信息
A2: 产品型号 | B2: 每箱毛重 | C2: 每箱体积 | D2: 每箱数量 | E2: 头程运费 | F2: 产品采购成本
A3: XXXX-111 | B3: 5 | C3: 1 | D3: 20 | E3: =C3*1500/D3 -> 75 | F3: 20
A4: XXXX-222 | B4: 5 | C4: 1 | D4: 20 | E4: =C4*1500/D4 -> 75 | F4: 20
A6: 产品信息 | E6: 亚马逊销售核算公式
A7: 货号/品名 | B7: 图片 | C7: 英文品名 | D7: 产品型号 Model No. | E7: 销售价格 | F7: 类目佣金 | G7: FBA配送费 | H7: 头程运费 | I7: 产品成本 | J7: 毛利润 | K7: 毛利润率
C8: XXXXX | D8: XXXX-111 | E8: 25 | F8: =E8*0.15 -> 3.75 | G8: 4.75 | H8: =E3/6.5 -> 11.538462 | I8: =F3/6.5 -> 3.0769231 | J8: =E8-F8-G8-H8-I8 -> 1.8846154 | K8: =J8/E8 -> 0.075384615
C9: XXXXX | D9: XXXX-222 | E9: 25 | F9: =E9*0.15 -> 3.75 | G9: 4.75 | H9: =E4/6.5 -> 11.538462 | I9: =F4/6.5 -> 3.0769231 | J9: =E9-F9-G9-H9-I9 -> 1.8846154 | K9: =J9/E9 -> 0.075384615

Sheet 2.1 销售和库存规划
A1: 图片 | B1: 产品型号 | H1: 退货 | I1: 0.05 | J1: 25 | K1: =J1*('1.2 产品定价'!I8+'1.2 产品定价'!H8+'1.2 产品定价'!G8*0.15) -> 383.19712
B2: XXXX-111 | H2: 广告 | I2: 30 | J2: 30天 | K2: 900
B3: 1000 | H3: 仓储成本 | I3: 30天 | J3: 500个 | K3: =(1000/'1.2 产品定价'!D4*'1.2 产品定价'!C4)*35*0.83 -> 1452.5
A4: 日期 | B4: 每日销量目标 | C4: 目标剩余库存 | D4: 实际每日销量 | E4: 实际剩余库存 | F4: 实际售价 | G4: 单个利润 | H4: 利润 | I4: 实际广告成本 | J4: 每日销量完成率 | K4: 实际利润
A5: 2026.8.23 | B5: 1 | C5: =B3-B5 -> 999 | D5: 2 | E5: =B3-D5 -> 998 | F5: 13.99 | G5: 3.528 | H5: =G5*D5 -> 7.056 | I5: 20.95 | J5: =D5/B5 -> 2 | K5: =H5-I5 -> -13.894
A6: 2026.8.24 | B6: 1 | C6: =C5-B6 -> 998 | D6: 1 | E6: =E5-D6 -> 997 | F6: 13.99 | G6: 3.528 | H6: =G6*D6 -> 3.528 | I6: 18.32 | J6: =D6/B6 -> 1 | K6: =H6-I6 -> -14.792
A7: 2026.8.25 | B7: 1 | C7: =C6-B7 -> 997 | D7: 0 | E7: =E6-D7 -> 997 | F7: 13.99 | G7: 3.528 | H7: =G7*D7 -> 0 | I7: 4.72 | J7: =D7/B7 -> 0 | K7: =H7-I7 -> -4.72
A8: 2026.8.26 | B8: 1 | C8: =C7-B8 -> 996 | D8: 1 | E8: =E7-D8 -> 996 | F8: 13.99 | G8: 3.528 | H8: =G8*D8 -> 3.528 | I8: 20.26 | J8: =D8/B8 -> 1 | K8: =H8-I8 -> -16.732
A9: 2026.8.27 | B9: 1 | C9: =C8-B9 -> 995 | D9: 3 | E9: =E8-D9 -> 993 | F9: 13.99 | G9: 3.528 | H9: =G9*D9 -> 10.584 | I9: 26 | J9: =D9/B9 -> 3 | K9: =H9-I9 -> -15.416
A10: 2026.8.28 | B10: 1 | C10: =C9-B10 -> 994 | D10: 3 | E10: =E9-D10 -> 990 | F10: 13.99 | G10: 3.528 | H10: =G10*D10 -> 10.584 | I10: 23.48 | J10: =D10/B10 -> 3 | K10: =H10-I10 -> -12.896
A11: 2026.8.29 | B11: 1 | C11: =C10-B11 -> 993 | D11: 9 | E11: =E10-D11 -> 981 | F11: 13.99 | G11: 3.528 | H11: =G11*D11 -> 31.752 | I11: 20.61 | J11: =D11/B11 -> 9 | K11: =H11-I11 -> 11.142
A12: 2026.8.30 | B12: 1 | C12: =C11-B12 -> 992 | D12: 5 | E12: =E11-D12 -> 976 | F12: 13.99 | G12: 3.528 | H12: =G12*D12 -> 17.64 | I12: 19.58 | J12: =D12/B12 -> 5 | K12: =H12-I12 -> -1.94
A13: 2026.8.31 | B13: 2 | C13: =C12-B13 -> 990 | D13: 9 | E13: =E12-D13 -> 967 | F13: 13.99 | G13: 3.528 | H13: =G13*D13 -> 31.752 | I13: 20.38 | J13: =D13/B13 -> 4.5 | K13: =H13-I13 -> 11.372
A14: 2026.9.1 | B14: 5 | C14: =C13-B14 -> 985 | D14: 4 | E14: =E13-D14 -> 963 | F14: 13.99 | G14: 3.528 | H14: =G14*D14 -> 14.112 | I14: 20.3 | J14: =D14/B14 -> 0.8 | K14: =H14-I14 -> -6.188
A15: 2026.9.2 | B15: 5 | C15: =C14-B15 -> 980 | D15: 9 | E15: =E14-D15 -> 954 | F15: 13.99 | G15: 3.528 | H15: =G15*D15 -> 31.752 | I15: 20.22 | J15: =D15/B15 -> 1.8 | K15: =H15-I15 -> 11.532
A16: 2026.9.3 | B16: 5 | C16: =C15-B16 -> 975 | D16: 9 | E16: =E15-D16 -> 945 | F16: 13.99 | G16: 3.528 | H16: =G16*D16 -> 31.752 | I16: 19.49 | J16: =D16/B16 -> 1.8 | K16: =H16-I16 -> 12.262
A17: 2026.9.4 | B17: 5 | C17: =C16-B17 -> 970 | D17: 8 | E17: =E16-D17 -> 937 | F17: 13.99 | G17: 3.528 | H17: =G17*D17 -> 28.224 | I17: 19.53 | J17: =D17/B17 -> 1.6 | K17: =H17-I17 -> 8.694
... A74: 2026.10.31 | B74: 5 | C74: =C73-B74 -> 0 | D74: 18 | E74: =E73-D74 -> -323 | F74: 21.99 | G74: 10.328 | H74: =G74*D74 -> 185.904 | I74: 0 | J74: =D74/B74 -> 3.6 | K74: =H74-I74 -> 185.904

Sheet 2.2 运营策略
A1: 变体合并策略 | C1: 执行细节及实际情况 | D1: 整体推广策略 | F1: 使用指南
A2: XXXX-111和XXXX-222合并 使用颜色进行合并 XXXXX等细节 | C2: 记录情况:8.18号 变体合并成功 | D2: 1、XXXX-111和XXXX-222 先开自动广告测款定主推款 3、推广节奏 第一阶段：Listing校验----自动广告 第二阶段：变体策略验证， 提升关键词排序---手动广告， 站外 第三阶段：提升订单量和关键词排序 | F2: 1、根据实际运营情况，每周对整体推广策略进行调整 2、基于上周运营表现，对下一周的核心目标、运营措施等进行更新调整并执行 3、记录运营数据到板块3
A3: 主推款运营框架 | C3: 执行细节及实际情况 | D3: 次推款运营框架 | F3: 执行细节及实际情况
A4: 【时间节点】 | B4: 第一阶段：9月第一周 | D4: 【时间节点】 | E4: 第一阶段：9月第一周
A5: 【核心目标】 | B5: 1.校正Listing的准确性， 完成LISTING基础收录，积累基础权重 2. 测词， 测款 | C5: 【执行细节】 1. 8.23号， 开自动广告， 预算$20， Bid $1.2 【核心指标情况】 1. 预算$20 能花完，展示量正常，整体点击率0.17%，偏低， 每日访客数在30-40，呈递增趋势，转化率7.88%正常 2. 广告展示量主要在商品页面， 预算花费在商品页面最多， 结合投放来看， 花费主要分布在紧密匹配和宽泛匹配， 说明目前市场上的竞品还不多 3. 从用户搜索词看， 目前主要也是跑的关键词，ASIN少。 关键词与我们Listing定位的关键词非常匹配， 主要是XXXXXXXXXXXX等相关词 ，与我们Listing的定位一致 4. 虽然看不到广告展示位， 但是关键词自然排序位置靠前， 可以继续按照现在的自动广告跑。 【遇到问题及后续计划】 问题： 1. 进一步提升关键词自然排序和订单量 2. 预算花费很分散， 现在没有特别热销的ASIN 计划： 1. 预算增加到$30 2. 自动广告中关掉同类商品和关联商品。 | D5: 【核心目标】 | E5: 1.校正Listing的准确性， 完成LISTING基础收录，积累基础权重 2. 测词， 测款 | F5: 【执行细节】 1. 8.23号， 开自动广告， 预算$20， Bid $1.2 【核心指标情况】 1. 预算$20能花完， 展示量偏低， 点击率正常， 转化率正常 2. 广告位来看， 广告主要展示在商品页面，预算主要花费在搜索结果其余位置， 从投放来看， 预算主要分配在紧密匹配和宽泛匹配， 说明现在竞品还不多。 3.看不到广告位 4. 用户搜索词： 主要是跑的一些跟xxxx相关的关键词，，与我们Listing的定位一致 5. 从关键词排序上看， XXXX-111主要在XXXXXX下有排序， 跟XXXX-222关键词排序形成互补， 所以目前XXXX-111和XXXX-222的自然广告都可以开。 【遇到问题及后续计划】 问题： 1. 进一步提升关键词自然排序和订单量 2. 预算花费很分散， 现在没有特别热销的ASIN，跑了很多长尾词 计划： 1. 预算增加到$30， Bid提高到$1.5 2. 自动广告中关掉同类商品和关联商品。
A6: 【本阶段运营措施】 | B6: 广告策略： 开自动广告 价格策略： 站外策略: | D6: 【本阶段运营措施】 | E6: 广告策略： 开自动广告 价格策略： 站外策略:
A7: 【重点跟进关注指标】 | B7: 1.Listing资料定位准确 2. 跑出的关键词与我们定位的关键词一致 3.广告曝光量正常 4. 关注核心关键词的排序， 广告位置展示 | D7: 【重点跟进关注指标】 | E7: 1.Listing资料定位准确 2. 跑出的关键词与我们定位的关键词一致 3.广告曝光量正常 4. 关注核心关键词的排序， 广告位置展示
A8: 【指标变动后的应对策略】 | B8: 1. 关键词排序提升， 订单量增长， 广告继续这也跑， 直到每日订单量20， 逐渐减少广告预算， 靠关键词自然位出单 2. 关键词排序和订单量没有增长， 那我们集中预算主要跑核心关键词，关闭同类商品和关联商品 | D8: 【指标变动后的应对策略】 | E8: 1. 关键词排序提升， 订单量增长， 广告继续这也跑， 直到每日订单量20， 逐渐减少广告预算， 靠关键词自然位出单 2. 关键词排序和订单量没有增长， 那我们集中预算主要跑核心关键词，关闭同类商品和关联商品
A9: 【时间节点】 | B9: 第二阶段：9月第二周 | D9: 【时间节点】 | E9: 第二阶段：9月第二周
A10: 【核心目标】 | B10: 提升关键词排序占据流量坑位 | C10: 【执行细节】 1. 9.7号 优化listing 【核心指标情况】 1. 订单量增长明显 2. 关键词XXXXXXXXXX P3， XXXXXXXX P1， 关键词位置提升明显 【遇到问题及后续计划】 问题： 1.出现了一个3星rating， 影响订单量 计划： 1. 与其他链接合并，解决评论的问题 | D10: 【核心目标】 | E10: 提升关键词排序占据流量坑位 | F10: 【执行细节】 1. 9.6号 关闭自动广告 2. 9.7号 优化listing 【核心指标情况】 1. 订单量增长明显， 关闭自动广告后 ， 订单量有下降 2. 关键词XXXXXXXX 排序在P3-P4， 变化不大 【遇到问题及后续计划】
A11: 【本阶段运营措施】 | B11: 1. 优化Listing标题， 资料文案， 让关键词跑出 XXXXXXXXXXXXX | D11: 【本阶段运营措施】 | E11: 1. 优化Listing标题， 资料文案， 让关键词跑出 XXXXXXXX 2. 关闭自动广告
A12: 【重点关注指标】 | B12: 1. 订单量的增长 2. 关键词排序的变化 | D12: 【重点关注指标】 | E12: 1. 订单量的增长 2. 关键词排序的变化
A13: 【指标变动后的应对策略】 | D13: 【指标变动后的应对策略】
A14: 【时间节点】 | B14: 第三阶段：9月第三周 | D14: 【时间节点】 | E14: 第三阶段：9月第三周
A15: 【核心目标】 | B15: 推动关键词排序进一步增长，抢占更靠前位置 | C15: 【执行细节】 9.13号 关闭自动广告 【核心指标情况】 1.订单量能够稳住， 并有增长 2. 关键词自然排序XXXXXXX 在P2， XXXXXXX在P1 能够稳住 3. 访客数也在增长 【遇到问题及后续计划】 计划： XXXX-111 涨价 | D15: 【核心目标】 | F15: 【执行细节】 【核心指标情况】 XXX 【遇到问题及后续计划】 XXX。
A16: 【本阶段运营措施】 | B16: 广告策略： 关闭自动广告， 靠自然出单 | D16: 【本阶段运营措施】
A17: 【重点关注指标】 | B17: 1. 订单量的变化 2. 关键词排序的变化 | D17: 【重点关注指标】
A18: 【指标变动后的应对策略】 | D18: 【指标变动后的应对策略】
A19: 【时间节点】 | B19: 第四阶段：9月第四周 | D19: 【时间节点】 | E19: 第四阶段：9月第四周
A20: 【核心目标】 | B20: 保证每日单量 整个链接40+， 提价做利润 | C20: 【执行细节】 9.17 号 XXXX-111 涨价 $13.99--$15.99 9.19号 XXXX-111 涨价 $15.99-$16.99 XXXX-222 涨价 $13.99-$14.99 【核心指标情况】 1.订单量能够稳住， 并有增长 2. 关键词自然排序XXXXXXXXX 在P2， XXXXXXXX在P1 能够稳住 3. 访客数也在增长 【遇到问题及后续计划】 | D20: 【核心目标】 | E20: 例：保持库存动销，避免库存积压 | F20: 【执行细节】 【核心指标情况】 XXX 【遇到问题及后续计划】 XXXX
A21: 【本阶段运营措施】 | B21: 价格策略：9.17 号 XXXX-111 涨价 $13.99--$15.99 9.19号 XXXX-111 涨价 $15.99-$16.99 XXXX-222 涨价 $13.99-$14.99 | D21: 【本阶段运营措施】
A22: 【重点关注指标】 | D22: 【重点关注指标】
A23: 【指标变动后的应对策略】 | D23: 【指标变动后的应对策略】
A25: 【时间节点】 | B25: 第五阶段：10月第一周 | D25: 【时间节点】 | E25: 第五阶段：10月第一周
A26: 【核心目标】 | B26: 例：保持每日XX销量，视情况提价释放利润 | C26: 【执行细节】 【核心指标情况】 【遇到问题及后续计划】 XXX | D26: 【核心目标】 | E26: 例：转化主推款流量，保持动销 | F26: 【执行细节】 【核心指标情况】 XXX 【遇到问题及后续计划】 XXX。
A27: 【本阶段运营措施】 | D27: 【本阶段运营措施】
A28: 【重点关注指标】 | D28: 【重点关注指标】
A29: 【指标变动后的应对策略】 | D29: 【指标变动后的应对策略】
A30: 【时间节点】 | B30: 第六阶段：10月第二周 | D30: 【时间节点】 | E30: 第六阶段：10月第二周
A31: 【核心目标】 | B31: 例：保持每日XX销量，视情况提价释放利润 | C31: 【执行细节】 【核心指标情况】 XXX 【遇到问题及后续计划】 XXX | D31: 【核心目标】 | E31: 例：保持库存动销，避免库存积压 | F31: 【执行细节】 【核心指标情况】 XXX 【遇到问题及后续计划】 XXXX
A32: 【本阶段运营措施】 | D32: 【本阶段运营措施】
A33: 【重点关注指标】 | D33: 【重点关注指标】
A34: 【指标变动后的应对策略】 | D34: 【指标变动后的应对策略】

Sheet  3.1 ASIN数据
A1: 分析指南 | B1: 1、关注数据重点：整个链接的整体数据规模到了什么程度？哪些指标需要重点分析？ 2、关注产品重点：主推款与次推款之间的数据占比如何？变体之间是否出现任何异常情况？ 3、关注工作重点：下阶段的工作重点是什么？如何帮助我们更好完成目标？后续需要重点关注哪些指标？
A2: 主推款SKU | B2: XXXX-111 | C2: ASIN | D2: ASIN1 | E2: 主图 | H2: 次推款SKU | I2: XXXX-222 | J2: ASIN | K2: ASIN2 | L2: 主图
A3: 日期 | B3: 销量 | C3: SESSION | D3: 销量转化率 | E3: 价格变动 | F3: 运营细节备注 | H3: 日期 | I3: 销量 | J3: 总SESSION | K3: 销量转化率 | L3: 运营细节备注
A4: 2022-08-23 | B4: =VLOOKUP($A4&$B$2,'4.2 产品详情原始数据'!$A:$BG,10,FALSE) -> #N/A | C4: =VLOOKUP($A4&$B$2,'4.2 产品详情原始数据'!$A:$BG,37,FALSE) -> #N/A | D4: =VLOOKUP($A4&$B$2,'4.2 产品详情原始数据'!$A:$BG,43,FALSE) -> #N/A | E4: =VLOOKUP($A4&$B$2,'4.2 产品详情原始数据'!$A:$BG,7,FALSE) -> #N/A | H4: 2022-08-23 | I4: =VLOOKUP(H4&$I$2,'4.2 产品详情原始数据'!$A:$BG,10,FALSE) -> #N/A | J4: =VLOOKUP($H4&$I$2,'4.2 产品详情原始数据'!$A:$BG,37,FALSE) -> #N/A | K4: =VLOOKUP($H4&$I$2,'4.2 产品详情原始数据'!$A:$BG,43,FALSE) -> #N/A
A5: 2022-08-24 | B5: =VLOOKUP($A5&$B$2,'4.2 产品详情原始数据'!$A:$BG,10,FALSE) -> #N/A | C5: =VLOOKUP($A5&$B$2,'4.2 产品详情原始数据'!$A:$BG,37,FALSE) -> #N/A | D5: =VLOOKUP($A5&$B$2,'4.2 产品详情原始数据'!$A:$BG,43,FALSE) -> #N/A | E5: =VLOOKUP($A5&$B$2,'4.2 产品详情原始数据'!$A:$BG,7,FALSE) -> #N/A | H5: 2022-08-24 | I5: =VLOOKUP(H5&$I$2,'4.2 产品详情原始数据'!$A:$BG,10,FALSE) -> #N/A | J5: =VLOOKUP($H5&$I$2,'4.2 产品详情原始数据'!$A:$BG,37,FALSE) -> #N/A | K5: =VLOOKUP($H5&$I$2,'4.2 产品详情原始数据'!$A:$BG,43,FALSE) -> #N/A
A6: 2022-08-25 | B6: =VLOOKUP($A6&$B$2,'4.2 产品详情原始数据'!$A:$BG,10,FALSE) -> #N/A | C6: =VLOOKUP($A6&$B$2,'4.2 产品详情原始数据'!$A:$BG,37,FALSE) -> #N/A | D6: =VLOOKUP($A6&$B$2,'4.2 产品详情原始数据'!$A:$BG,43,FALSE) -> #N/A | E6: =VLOOKUP($A6&$B$2,'4.2 产品详情原始数据'!$A:$BG,7,FALSE) -> #N/A | H6: 2022-08-25 | I6: =VLOOKUP(H6&$I$2,'4.2 产品详情原始数据'!$A:$BG,10,FALSE) -> #N/A | J6: =VLOOKUP($H6&$I$2,'4.2 产品详情原始数据'!$A:$BG,37,FALSE) -> #N/A | K6: =VLOOKUP($H6&$I$2,'4.2 产品详情原始数据'!$A:$BG,43,FALSE) -> #N/A
A7: 2022-08-26 | B7: =VLOOKUP($A7&$B$2,'4.2 产品详情原始数据'!$A:$BG,10,FALSE) -> #N/A | C7: =VLOOKUP($A7&$B$2,'4.2 产品详情原始数据'!$A:$BG,37,FALSE) -> #N/A | D7: =VLOOKUP($A7&$B$2,'4.2 产品详情原始数据'!$A:$BG,43,FALSE) -> #N/A | E7: =VLOOKUP($A7&$B$2,'4.2 产品详情原始数据'!$A:$BG,7,FALSE) -> #N/A | H7: 2022-08-26 | I7: =VLOOKUP(H7&$I$2,'4.2 产品详情原始数据'!$A:$BG,10,FALSE) -> #N/A | J7: =VLOOKUP($H7&$I$2,'4.2 产品详情原始数据'!$A:$BG,37,FALSE) -> #N/A | K7: =VLOOKUP($H7&$I$2,'4.2 产品详情原始数据'!$A:$BG,43,FALSE) -> #N/A
A8: 2022-08-27 | B8: =VLOOKUP($A8&$B$2,'4.2 产品详情原始数据'!$A:$BG,10,FALSE) -> #N/A | C8: =VLOOKUP($A8&$B$2,'4.2 产品详情原始数据'!$A:$BG,37,FALSE) -> #N/A | D8: =VLOOKUP($A8&$B$2,'4.2 产品详情原始数据'!$A:$BG,43,FALSE) -> #N/A | E8: =VLOOKUP($A8&$B$2,'4.2 产品详情原始数据'!$A:$BG,7,FALSE) -> #N/A | H8: 2022-08-27 | I8: =VLOOKUP(H8&$I$2,'4.2 产品详情原始数据'!$A:$BG,10,FALSE) -> #N/A | J8: =VLOOKUP($H8&$I$2,'4.2 产品详情原始数据'!$A:$BG,37,FALSE) -> #N/A | K8: =VLOOKUP($H8&$I$2,'4.2 产品详情原始数据'!$A:$BG,43,FALSE) -> #N/A
A9: 2022-08-28 | B9: =VLOOKUP($A9&$B$2,'4.2 产品详情原始数据'!$A:$BG,10,FALSE) -> #N/A | C9: =VLOOKUP($A9&$B$2,'4.2 产品详情原始数据'!$A:$BG,37,FALSE) -> #N/A | D9: =VLOOKUP($A9&$B$2,'4.2 产品详情原始数据'!$A:$BG,43,FALSE) -> #N/A | E9: =VLOOKUP($A9&$B$2,'4.2 产品详情原始数据'!$A:$BG,7,FALSE) -> #N/A | H9: 2022-08-28 | I9: =VLOOKUP(H9&$I$2,'4.2 产品详情原始数据'!$A:$BG,10,FALSE) -> #N/A | J9: =VLOOKUP($H9&$I$2,'4.2 产品详情原始数据'!$A:$BG,37,FALSE) -> #N/A | K9: =VLOOKUP($H9&$I$2,'4.2 产品详情原始数据'!$A:$BG,43,FALSE) -> #N/A
A10: 2022-08-29 | B10: =VLOOKUP($A10&$B$2,'4.2 产品详情原始数据'!$A:$BG,10,FALSE) -> #N/A | C10: =VLOOKUP($A10&$B$2,'4.2 产品详情原始数据'!$A:$BG,37,FALSE) -> #N/A | D10: =VLOOKUP($A10&$B$2,'4.2 产品详情原始数据'!$A:$BG,43,FALSE) -> #N/A | E10: =VLOOKUP($A10&$B$2,'4.2 产品详情原始数据'!$A:$BG,7,FALSE) -> #N/A | H10: 2022-08-29 | I10: =VLOOKUP(H10&$I$2,'4.2 产品详情原始数据'!$A:$BG,10,FALSE) -> #N/A | J10: =VLOOKUP($H10&$I$2,'4.2 产品详情原始数据'!$A:$BG,37,FALSE) -> #N/A | K10: =VLOOKUP($H10&$I$2,'4.2 产品详情原始数据'!$A:$BG,43,FALSE) -> #N/A
A11: 2022-08-30 | B11: =VLOOKUP($A11&$B$2,'4.2 产品详情原始数据'!$A:$BG,10,FALSE) -> #N/A | C11: =VLOOKUP($A11&$B$2,'4.2 产品详情原始数据'!$A:$BG,37,FALSE) -> #N/A | D11: =VLOOKUP($A11&$B$2,'4.2 产品详情原始数据'!$A:$BG,43,FALSE) -> #N/A | E11: =VLOOKUP($A11&$B$2,'4.2 产品详情原始数据'!$A:$BG,7,FALSE) -> #N/A | H11: 2022-08-30 | I11: =VLOOKUP(H11&$I$2,'4.2 产品详情原始数据'!$A:$BG,10,FALSE) -> #N/A | J11: =VLOOKUP($H11&$I$2,'4.2 产品详情原始数据'!$A:$BG,37,FALSE) -> #N/A | K11: =VLOOKUP($H11&$I$2,'4.2 产品详情原始数据'!$A:$BG,43,FALSE) -> #N/A
A12: 2022-08-31 | B12: =VLOOKUP($A12&$B$2,'4.2 产品详情原始数据'!$A:$BG,10,FALSE) -> #N/A | C12: =VLOOKUP($A12&$B$2,'4.2 产品详情原始数据'!$A:$BG,37,FALSE) -> #N/A | D12: =VLOOKUP($A12&$B$2,'4.2 产品详情原始数据'!$A:$BG,43,FALSE) -> #N/A | E12: =VLOOKUP($A12&$B$2,'4.2 产品详情原始数据'!$A:$BG,7,FALSE) -> #N/A | H12: 2022-08-31 | I12: =VLOOKUP(H12&$I$2,'4.2 产品详情原始数据'!$A:$BG,10,FALSE) -> #N/A | J12: =VLOOKUP($H12&$I$2,'4.2 产品详情原始数据'!$A:$BG,37,FALSE) -> #N/A | K12: =VLOOKUP($H12&$I$2,'4.2 产品详情原始数据'!$A:$BG,43,FALSE) -> #N/A
A13: 2022-09-01 | B13: =VLOOKUP($A13&$B$2,'4.2 产品详情原始数据'!$A:$BG,10,FALSE) -> #N/A | C13: =VLOOKUP($A13&$B$2,'4.2 产品详情原始数据'!$A:$BG,37,FALSE) -> #N/A | D13: =VLOOKUP($A13&$B$2,'4.2 产品详情原始数据'!$A:$BG,43,FALSE) -> #N/A | E13: =VLOOKUP($A13&$B$2,'4.2 产品详情原始数据'!$A:$BG,7,FALSE) -> #N/A | H13: 2022-09-01 | I13: =VLOOKUP(H13&$I$2,'4.2 产品详情原始数据'!$A:$BG,10,FALSE) -> #N/A | J13: =VLOOKUP($H13&$I$2,'4.2 产品详情原始数据'!$A:$BG,37,FALSE) -> #N/A | K13: =VLOOKUP($H13&$I$2,'4.2 产品详情原始数据'!$A:$BG,43,FALSE) -> #N/A
A14: 2022-09-02 | B14: =VLOOKUP($A14&$B$2,'4.2 产品详情原始数据'!$A:$BG,10,FALSE) -> #N/A | C14: =VLOOKUP($A14&$B$2,'4.2 产品详情原始数据'!$A:$BG,37,FALSE) -> #N/A | D14: =VLOOKUP($A14&$B$2,'4.2 产品详情原始数据'!$A:$BG,43,FALSE) -> #N/A | E14: =VLOOKUP($A14&$B$2,'4.2 产品详情原始数据'!$A:$BG,7,FALSE) -> #N/A | H14: 2022-09-02 | I14: =VLOOKUP(H14&$I$2,'4.2 产品详情原始数据'!$A:$BG,10,FALSE) -> #N/A | J14: =VLOOKUP($H14&$I$2,'4.2 产品详情原始数据'!$A:$BG,37,FALSE) -> #N/A | K14: =VLOOKUP($H14&$I$2,'4.2 产品详情原始数据'!$A:$BG,43,FALSE) -> #N/A
A15: 2022-09-03 | B15: =VLOOKUP($A15&$B$2,'4.2 产品详情原始数据'!$A:$BG,10,FALSE) -> #N/A | C15: =VLOOKUP($A15&$B$2,'4.2 产品详情原始数据'!$A:$BG,37,FALSE) -> #N/A | D15: =VLOOKUP($A15&$B$2,'4.2 产品详情原始数据'!$A:$BG,43,FALSE) -> #N/A | E15: =VLOOKUP($A15&$B$2,'4.2 产品详情原始数据'!$A:$BG,7,FALSE) -> #N/A | H15: 2022-09-03 | I15: =VLOOKUP(H15&$I$2,'4.2 产品详情原始数据'!$A:$BG,10,FALSE) -> #N/A | J15: =VLOOKUP($H15&$I$2,'4.2 产品详情原始数据'!$A:$BG,37,FALSE) -> #N/A | K15: =VLOOKUP($H15&$I$2,'4.2 产品详情原始数据'!$A:$BG,43,FALSE) -> #N/A
... A57: 2022-10-15 | B57: =VLOOKUP($A57&$B$2,'4.2 产品详情原始数据'!$A:$BG,10,FALSE) -> #N/A | C57: =VLOOKUP($A57&$B$2,'4.2 产品详情原始数据'!$A:$BG,37,FALSE) -> #N/A | D57: =VLOOKUP($A57&$B$2,'4.2 产品详情原始数据'!$A:$BG,43,FALSE) -> #N/A | E57: =VLOOKUP($A57&$B$2,'4.2 产品详情原始数据'!$A:$BG,7,FALSE) -> #N/A | H57: 2022-10-15 | I57: =VLOOKUP(H57&$I$2,'4.2 产品详情原始数据'!$A:$BG,10,FALSE) -> #N/A | J57: =VLOOKUP($H57&$I$2,'4.2 产品详情原始数据'!$A:$BG,37,FALSE) -> #N/A | K57: =VLOOKUP($H57&$I$2,'4.2 产品详情原始数据'!$A:$BG,43,FALSE) -> #N/A
AF69: 求和项:Sessions-Total | AG69: MSKU
AF70: 时间 | AG70: XXXX-111 | AH70: XXXX-222 | AI70: 总计
AF71: 2022-08-20 | AG71: 0 | AH71: 0 | AI71: 0
AF72: 2022-08-21 | AG72: 0 | AH72: 0 | AI72: 0
AF73: 2022-08-22 | AG73: 0 | AH73: 0 | AI73: 0
AF74: 2022-08-23 | AG74: 29 | AH74: 25 | AI74: 54
AF75: 2022-08-24 | AG75: 25 | AH75: 16 | AI75: 41
A76: 求和项:Sessions-Total | B76: MSKU | H76: 求和项:销量 | I76: MSKU | N76: 求和项:销量CVR | O76: MSKU | AF76: 2022-08-25 | AG76: 17 | AH76: 28 | AI76: 45
A77: 时间 | B77: XXXX-111 | C77: XXXX-222 | D77: 总计 | H77: 时间 | I77: XXXX-111 | J77: XXXX-222 | K77: 总计 | N77: 时间 | O77: XXXX-111 | P77: XXXX-222 | Q77: 总计 | AF77: 2022-08-26 | AG77: 32 | AH77: 37 | AI77: 69
A78: 2022-08-20 | B78: 0 | C78: 0 | D78: 0 | H78: 2022-08-20 | I78: 0 | J78: 0 | K78: 0 | N78: 2022-08-20 | O78: 0 | P78: 0 | Q78: 0 | AF78: 2022-08-27 | AG78: 40 | AH78: 47 | AI78: 87
A79: 2022-08-21 | B79: 0 | C79: 0 | D79: 0 | H79: 2022-08-21 | I79: 0 | J79: 0 | K79: 0 | N79: 2022-08-21 | O79: 0 | P79: 0 | Q79: 0 | AF79: 2022-08-28 | AG79: 54 | AH79: 50 | AI79: 104
A80: 2022-08-22 | B80: 0 | C80: 0 | D80: 0 | H80: 2022-08-22 | I80: 0 | J80: 0 | K80: 0 | N80: 2022-08-22 | O80: 0 | P80: 0 | Q80: 0 | AF80: 2022-08-29 | AG80: 46 | AH80: 34 | AI80: 80
A81: 2022-08-23 | B81: 29 | C81: 25 | D81: 54 | H81: 2022-08-23 | I81: 2 | J81: 1 | K81: 3 | N81: 2022-08-23 | O81: 0.069 | P81: 0.04 | Q81: 0.109 | AF81: 2022-08-30 | AG81: 78 | AH81: 48 | AI81: 126
A82: 2022-08-24 | B82: 25 | C82: 16 | D82: 41 | H82: 2022-08-24 | I82: 1 | J82: 0 | K82: 1 | N82: 2022-08-24 | O82: 0.04 | P82: 0 | Q82: 0.04 | AF82: 2022-08-31 | AG82: 71 | AH82: 62 | AI82: 133
A83: 2022-08-25 | B83: 17 | C83: 28 | D83: 45 | H83: 2022-08-25 | I83: 0 | J83: 1 | K83: 1 | N83: 2022-08-25 | O83: 0 | P83: 0.0357 | Q83: 0.0357 | AF83: 2022-09-01 | AG83: 85 | AH83: 52 | AI83: 137
A84: 2022-08-26 | B84: 32 | C84: 37 | D84: 69 | H84: 2022-08-26 | I84: 1 | J84: 5 | K84: 6 | N84: 2022-08-26 | O84: 0.0312 | P84: 0.1351 | Q84: 0.1663 | AF84: 2022-09-02 | AG84: 94 | AH84: 61 | AI84: 155
A85: 2022-08-27 | B85: 40 | C85: 47 | D85: 87 | H85: 2022-08-27 | I85: 3 | J85: 2 | K85: 5 | N85: 2022-08-27 | O85: 0.075 | P85: 0.0426 | Q85: 0.1176 | AF85: 2022-09-03 | AG85: 124 | AH85: 81 | AI85: 205
A86: 2022-08-28 | B86: 54 | C86: 50 | D86: 104 | H86: 2022-08-28 | I86: 3 | J86: 1 | K86: 4 | N86: 2022-08-28 | O86: 0.0556 | P86: 0.02 | Q86: 0.0756 | AF86: 2022-09-04 | AG86: 149 | AH86: 90 | AI86: 239
A87: 2022-08-29 | B87: 46 | C87: 34 | D87: 80 | H87: 2022-08-29 | I87: 9 | J87: 1 | K87: 10 | N87: 2022-08-29 | O87: 0.1957 | P87: 0.0294 | Q87: 0.2251 | AF87: 2022-09-05 | AG87: 203 | AH87: 129 | AI87: 332
A88: 2022-08-30 | B88: 78 | C88: 48 | D88: 126 | H88: 2022-08-30 | I88: 5 | J88: 5 | K88: 10 | N88: 2022-08-30 | O88: 0.0641 | P88: 0.1042 | Q88: 0.1683 | AF88: 2022-09-06 | AG88: 138 | AH88: 77 | AI88: 215
A89: 2022-08-31 | B89: 71 | C89: 62 | D89: 133 | H89: 2022-08-31 | I89: 9 | J89: 3 | K89: 12 | N89: 2022-08-31 | O89: 0.1268 | P89: 0.0484 | Q89: 0.1752 | AF89: 2022-09-07 | AG89: 142 | AH89: 62 | AI89: 204
... A93: 2022-09-04 | B93: 149 | C93: 90 | D93: 239 | H93: 2022-09-04 | I93: 8 | J93: 11 | K93: 19 | N93: 2022-09-04 | O93: 0.0537 | P93: 0.1222 | Q93: 0.1759 | AF93: 总计 | AG93: 1723 | AH93: 1085 | AI93: 2808
A94: 2022-09-05 | B94: 203 | C94: 129 | D94: 332 | H94: 2022-09-05 | I94: 23 | J94: 11 | K94: 34 | N94: 2022-09-05 | O94: 0.1133 | P94: 0.0853 | Q94: 0.1986
A95: 2022-09-06 | B95: 138 | C95: 77 | D95: 215 | H95: 2022-09-06 | I95: 17 | J95: 10 | K95: 27 | N95: 2022-09-06 | O95: 0.1232 | P95: 0.1299 | Q95: 0.2531
...

Sheet 3.2 关键词数据
B1: XXXX-111 | J1: XXXX-222 | S1: 辅助列
S2: 7 | T2: 8 | U2: 9 | V2: 10 | W2: 11 | X2: 12 | Y2: 13 | Z2: 14 | AA2: 15 | AB2: 16 | AC2: 17 | AD2: 18 | AE2: 19 | AF2: 20 | AG2: 21 | AH2: 22 | AI2: 23 | AJ2: 24 | AK2: 25 | AL2: 26 | AM2: 27 | AN2: 28 | AO2: 29 | AP2: 30 | AQ2: 31 | AR2: 32 | AS2: 33 | AT2: 34 | AU2: 35
B3: 关键词1 | D3: 关键词2 | F3: 关键词3 | H3: 关键词4 | J3: 关键词1 | L3: 关键词2 | N3: 关键词3 | P3: 关键词4
A4: 日期 | B4: 广告位 | C4: 自然位 | D4: 广告位 | E4: 自然位 | F4: 广告位 | G4: 自然位 | H4: 广告位 | I4: 自然位 | J4: 广告位 | K4: 自然位 | L4: 广告位 | M4: 自然位 | N4: 广告位 | O4: 自然位 | P4: 广告位 | Q4: 自然位
A5: 8月31日上午 | B5: =_xlfn.IFNA(IF(VLOOKUP($B$1&$A5,'4.1 关键词原始数据'!$A:$N,S$2,FALSE)=0," ",VLOOKUP($B$1&$A5,'4.1 关键词原始数据'!$A:$N,S$2,FALSE))," ") | C5: =_xlfn.IFNA(IF(VLOOKUP($B$1&$A5,'4.1 关键词原始数据'!$A:$N,T$2,FALSE)=0," ",VLOOKUP($B$1&$A5,'4.1 关键词原始数据'!$A:$N,T$2,FALSE))," ") -> 3-7-2 | D5: =_xlfn.IFNA(IF(VLOOKUP($B$1&$A5,'4.1 关键词原始数据'!$A:$N,U$2,FALSE)=0," ",VLOOKUP($B$1&$A5,'4.1 关键词原始数据'!$A:$N,U$2,FALSE))," ") | E5: =_xlfn.IFNA(IF(VLOOKUP($B$1&$A5,'4.1 关键词原始数据'!$A:$N,V$2,FALSE)=0," ",VLOOKUP($B$1&$A5,'4.1 关键词原始数据'!$A:$N,V$2,FALSE))," ") | F5: =_xlfn.IFNA(IF(VLOOKUP($B$1&$A5,'4.1 关键词原始数据'!$A:$N,W$2,FALSE)=0," ",VLOOKUP($B$1&$A5,'4.1 关键词原始数据'!$A:$N,W$2,FALSE))," ") | G5: =_xlfn.IFNA(IF(VLOOKUP($B$1&$A5,'4.1 关键词原始数据'!$A:$N,X$2,FALSE)=0," ",VLOOKUP($B$1&$A5,'4.1 关键词原始数据'!$A:$N,X$2,FALSE))," ") -> 1-17-1 | H5: =_xlfn.IFNA(IF(VLOOKUP($B$1&$A5,'4.1 关键词原始数据'!$A:$N,Y$2,FALSE)=0," ",VLOOKUP($B$1&$A5,'4.1 关键词原始数据'!$A:$N,Y$2,FALSE))," ") | I5: =_xlfn.IFNA(IF(VLOOKUP($B$1&$A5,'4.1 关键词原始数据'!$A:$N,Z$2,FALSE)=0," ",VLOOKUP($B$1&$A5,'4.1 关键词原始数据'!$A:$N,Z$2,FALSE))," ") | J5: =_xlfn.IFNA(IF(VLOOKUP($J$1&$A5,'4.1 关键词原始数据'!$A:$N,S$2,FALSE)=0," ",VLOOKUP($J$1&$A5,'4.1 关键词原始数据'!$A:$N,S$2,FALSE))," ") | K5: =_xlfn.IFNA(IF(VLOOKUP($J$1&$A5,'4.1 关键词原始数据'!$A:$N,T$2,FALSE)=0," ",VLOOKUP($J$1&$A5,'4.1 关键词原始数据'!$A:$N,T$2,FALSE))," ") | L5: =_xlfn.IFNA(IF(VLOOKUP($J$1&$A5,'4.1 关键词原始数据'!$A:$N,U$2,FALSE)=0," ",VLOOKUP($J$1&$A5,'4.1 关键词原始数据'!$A:$N,U$2,FALSE))," ") | M5: =_xlfn.IFNA(IF(VLOOKUP($J$1&$A5,'4.1 关键词原始数据'!$A:$N,V$2,FALSE)=0," ",VLOOKUP($J$1&$A5,'4.1 关键词原始数据'!$A:$N,V$2,FALSE))," ") | N5: =_xlfn.IFNA(IF(VLOOKUP($J$1&$A5,'4.1 关键词原始数据'!$A:$N,W$2,FALSE)=0," ",VLOOKUP($J$1&$A5,'4.1 关键词原始数据'!$A:$N,W$2,FALSE))," ") | O5: =_xlfn.IFNA(IF(VLOOKUP($J$1&$A5,'4.1 关键词原始数据'!$A:$N,X$2,FALSE)=0," ",VLOOKUP($J$1&$A5,'4.1 关键词原始数据'!$A:$N,X$2,FALSE))," ") | P5: =_xlfn.IFNA(IF(VLOOKUP($J$1&$A5,'4.1 关键词原始数据'!$A:$N,Y$2,FALSE)=0," ",VLOOKUP($J$1&$A5,'4.1 关键词原始数据'!$A:$N,Y$2,FALSE))," ") | Q5: =_xlfn.IFNA(IF(VLOOKUP($J$1&$A5,'4.1 关键词原始数据'!$A:$N,Z$2,FALSE)=0," ",VLOOKUP($J$1&$A5,'4.1 关键词原始数据'!$A:$N,Z$2,FALSE))," ")
A6: 8月31日晚上 | B6: =_xlfn.IFNA(IF(VLOOKUP($B$1&$A6,'4.1 关键词原始数据'!$A:$N,S$2,FALSE)=0," ",VLOOKUP($B$1&$A6,'4.1 关键词原始数据'!$A:$N,S$2,FALSE))," ") | C6: =_xlfn.IFNA(IF(VLOOKUP($B$1&$A6,'4.1 关键词原始数据'!$A:$N,T$2,FALSE)=0," ",VLOOKUP($B$1&$A6,'4.1 关键词原始数据'!$A:$N,T$2,FALSE))," ") | D6: =_xlfn.IFNA(IF(VLOOKUP($B$1&$A6,'4.1 关键词原始数据'!$A:$N,U$2,FALSE)=0," ",VLOOKUP($B$1&$A6,'4.1 关键词原始数据'!$A:$N,U$2,FALSE))," ") | E6: =_xlfn.IFNA(IF(VLOOKUP($B$1&$A6,'4.1 关键词原始数据'!$A:$N,V$2,FALSE)=0," ",VLOOKUP($B$1&$A6,'4.1 关键词原始数据'!$A:$N,V$2,FALSE))," ") | F6: =_xlfn.IFNA(IF(VLOOKUP($B$1&$A6,'4.1 关键词原始数据'!$A:$N,W$2,FALSE)=0," ",VLOOKUP($B$1&$A6,'4.1 关键词原始数据'!$A:$N,W$2,FALSE))," ") | G6: =_xlfn.IFNA(IF(VLOOKUP($B$1&$A6,'4.1 关键词原始数据'!$A:$N,X$2,FALSE)=0," ",VLOOKUP($B$1&$A6,'4.1 关键词原始数据'!$A:$N,X$2,FALSE))," ") | H6: =_xlfn.IFNA(IF(VLOOKUP($B$1&$A6,'4.1 关键词原始数据'!$A:$N,Y$2,FALSE)=0," ",VLOOKUP($B$1&$A6,'4.1 关键词原始数据'!$A:$N,Y$2,FALSE))," ") | I6: =_xlfn.IFNA(IF(VLOOKUP($B$1&$A6,'4.1 关键词原始数据'!$A:$N,Z$2,FALSE)=0," ",VLOOKUP($B$1&$A6,'4.1 关键词原始数据'!$A:$N,Z$2,FALSE))," ") | J6: =_xlfn.IFNA(IF(VLOOKUP($J$1&$A6,'4.1 关键词原始数据'!$A:$N,S$2,FALSE)=0," ",VLOOKUP($J$1&$A6,'4.1 关键词原始数据'!$A:$N,S$2,FALSE))," ") | K6: =_xlfn.IFNA(IF(VLOOKUP($J$1&$A6,'4.1 关键词原始数据'!$A:$N,T$2,FALSE)=0," ",VLOOKUP($J$1&$A6,'4.1 关键词原始数据'!$A:$N,T$2,FALSE))," ") | L6: =_xlfn.IFNA(IF(VLOOKUP($J$1&$A6,'4.1 关键词原始数据'!$A:$N,U$2,FALSE)=0," ",VLOOKUP($J$1&$A6,'4.1 关键词原始数据'!$A:$N,U$2,FALSE))," ") | M6: =_xlfn.IFNA(IF(VLOOKUP($J$1&$A6,'4.1 关键词原始数据'!$A:$N,V$2,FALSE)=0," ",VLOOKUP($J$1&$A6,'4.1 关键词原始数据'!$A:$N,V$2,FALSE))," ") | N6: =_xlfn.IFNA(IF(VLOOKUP($J$1&$A6,'4.1 关键词原始数据'!$A:$N,W$2,FALSE)=0," ",VLOOKUP($J$1&$A6,'4.1 关键词原始数据'!$A:$N,W$2,FALSE))," ") | O6: =_xlfn.IFNA(IF(VLOOKUP($J$1&$A6,'4.1 关键词原始数据'!$A:$N,X$2,FALSE)=0," ",VLOOKUP($J$1&$A6,'4.1 关键词原始数据'!$A:$N,X$2,FALSE))," ") | P6: =_xlfn.IFNA(IF(VLOOKUP($J$1&$A6,'4.1 关键词原始数据'!$A:$N,Y$2,FALSE)=0," ",VLOOKUP($J$1&$A6,'4.1 关键词原始数据'!$A:$N,Y$2,FALSE))," ") | Q6: =_xlfn.IFNA(IF(VLOOKUP($J$1&$A6,'4.1 关键词原始数据'!$A:$N,Z$2,FALSE)=0," ",VLOOKUP($J$1&$A6,'4.1 关键词原始数据'!$A:$N,Z$2,FALSE))," ")
A7: 9月1日上午 | B7: =_xlfn.IFNA(IF(VLOOKUP($B$1&$A7,'4.1 关键词原始数据'!$A:$N,S$2,FALSE)=0," ",VLOOKUP($B$1&$A7,'4.1 关键词原始数据'!$A:$N,S$2,FALSE))," ") | C7: =_xlfn.IFNA(IF(VLOOKUP($B$1&$A7,'4.1 关键词原始数据'!$A:$N,T$2,FALSE)=0," ",VLOOKUP($B$1&$A7,'4.1 关键词原始数据'!$A:$N,T$2,FALSE))," ") -> 2-12-4 | D7: =_xlfn.IFNA(IF(VLOOKUP($B$1&$A7,'4.1 关键词原始数据'!$A:$N,U$2,FALSE)=0," ",VLOOKUP($B$1&$A7,'4.1 关键词原始数据'!$A:$N,U$2,FALSE))," ") | E7: =_xlfn.IFNA(IF(VLOOKUP($B$1&$A7,'4.1 关键词原始数据'!$A:$N,V$2,FALSE)=0," ",VLOOKUP($B$1&$A7,'4.1 关键词原始数据'!$A:$N,V$2,FALSE))," ") -> 2-4-4 | F7: =_xlfn.IFNA(IF(VLOOKUP($B$1&$A7,'4.1 关键词原始数据'!$A:$N,W$2,FALSE)=0," ",VLOOKUP($B$1&$A7,'4.1 关键词原始数据'!$A:$N,W$2,FALSE))," ") | G7: =_xlfn.IFNA(IF(VLOOKUP($B$1&$A7,'4.1 关键词原始数据'!$A:$N,X$2,FALSE)=0," ",VLOOKUP($B$1&$A7,'4.1 关键词原始数据'!$A:$N,X$2,FALSE))," ") | H7: =_xlfn.IFNA(IF(VLOOKUP($B$1&$A7,'4.1 关键词原始数据'!$A:$N,Y$2,FALSE)=0," ",VLOOKUP($B$1&$A7,'4.1 关键词原始数据'!$A:$N,Y$2,FALSE))," ") | I7: =_xlfn.IFNA(IF(VLOOKUP($B$1&$A7,'4.1 关键词原始数据'!$A:$N,Z$2,FALSE)=0," ",VLOOKUP($B$1&$A7,'4.1 关键词原始数据'!$A:$N,Z$2,FALSE))," ") | J7: =_xlfn.IFNA(IF(VLOOKUP($J$1&$A7,'4.1 关键词原始数据'!$A:$N,S$2,FALSE)=0," ",VLOOKUP($J$1&$A7,'4.1 关键词原始数据'!$A:$N,S$2,FALSE))," ") | K7: =_xlfn.IFNA(IF(VLOOKUP($J$1&$A7,'4.1 关键词原始数据'!$A:$N,T$2,FALSE)=0," ",VLOOKUP($J$1&$A7,'4.1 关键词原始数据'!$A:$N,T$2,FALSE))," ") | L7: =_xlfn.IFNA(IF(VLOOKUP($J$1&$A7,'4.1 关键词原始数据'!$A:$N,U$2,FALSE)=0," ",VLOOKUP($J$1&$A7,'4.1 关键词原始数据'!$A:$N,U$2,FALSE))," ") | M7: =_xlfn.IFNA(IF(VLOOKUP($J$1&$A7,'4.1 关键词原始数据'!$A:$N,V$2,FALSE)=0," ",VLOOKUP($J$1&$A7,'4.1 关键词原始数据'!$A:$N,V$2,FALSE))," ") | N7: =_xlfn.IFNA(IF(VLOOKUP($J$1&$A7,'4.1 关键词原始数据'!$A:$N,W$2,FALSE)=0," ",VLOOKUP($J$1&$A7,'4.1 关键词原始数据'!$A:$N,W$2,FALSE))," ") | O7: =_xlfn.IFNA(IF(VLOOKUP($J$1&$A7,'4.1 关键词原始数据'!$A:$N,X$2,FALSE)=0," ",VLOOKUP($J$1&$A7,'4.1 关键词原始数据'!$A:$N,X$2,FALSE))," ") | P7: =_xlfn.IFNA(IF(VLOOKUP($J$1&$A7,'4.1 关键词原始数据'!$A:$N,Y$2,FALSE)=0," ",VLOOKUP($J$1&$A7,'4.1 关键词原始数据'!$A:$N,Y$2,FALSE))," ") | Q7: =_xlfn.IFNA(IF(VLOOKUP($J$1&$A7,'4.1 关键词原始数据'!$A:$N,Z$2,FALSE)=0," ",VLOOKUP($J$1&$A7,'4.1 关键词原始数据'!$A:$N,Z$2,FALSE))," ")
A8: 9月1日晚上 | B8: =_xlfn.IFNA(IF(VLOOKUP($B$1&$A8,'4.1 关键词原始数据'!$A:$N,S$2,FALSE)=0," ",VLOOKUP($B$1&$A8,'4.1 关键词原始数据'!$A:$N,S$2,FALSE))," ") | C8: =_xlfn.IFNA(IF(VLOOKUP($B$1&$A8,'4.1 关键词原始数据'!$A:$N,T$2,FALSE)=0," ",VLOOKUP($B$1&$A8,'4.1 关键词原始数据'!$A:$N,T$2,FALSE))," ") | D8: =_xlfn.IFNA(IF(VLOOKUP($B$1&$A8,'4.1 关键词原始数据'!$A:$N,U$2,FALSE)=0," ",VLOOKUP($B$1&$A8,'4.1 关键词原始数据'!$A:$N,U$2,FALSE))," ") | E8: =_xlfn.IFNA(IF(VLOOKUP($B$1&$A8,'4.1 关键词原始数据'!$A:$N,V$2,FALSE)=0," ",VLOOKUP($B$1&$A8,'4.1 关键词原始数据'!$A:$N,V$2,FALSE))," ") | F8: =_xlfn.IFNA(IF(VLOOKUP($B$1&$A8,'4.1 关键词原始数据'!$A:$N,W$2,FALSE)=0," ",VLOOKUP($B$1&$A8,'4.1 关键词原始数据'!$A:$N,W$2,FALSE))," ") | G8: =_xlfn.IFNA(IF(VLOOKUP($B$1&$A8,'4.1 关键词原始数据'!$A:$N,X$2,FALSE)=0," ",VLOOKUP($B$1&$A8,'4.1 关键词原始数据'!$A:$N,X$2,FALSE))," ") | H8: =_xlfn.IFNA(IF(VLOOKUP($B$1&$A8,'4.1 关键词原始数据'!$A:$N,Y$2,FALSE)=0," ",VLOOKUP($B$1&$A8,'4.1 关键词原始数据'!$A:$N,Y$2,FALSE))," ") | I8: =_xlfn.IFNA(IF(VLOOKUP($B$1&$A8,'4.1 关键词原始数据'!$A:$N,Z$2,FALSE)=0," ",VLOOKUP($B$1&$A8,'4.1 关键词原始数据'!$A:$N,Z$2,FALSE))," ") | J8: =_xlfn.IFNA(IF(VLOOKUP($J$1&$A8,'4.1 关键词原始数据'!$A:$N,S$2,FALSE)=0," ",VLOOKUP($J$1&$A8,'4.1 关键词原始数据'!$A:$N,S$2,FALSE))," ") | K8: =_xlfn.IFNA(IF(VLOOKUP($J$1&$A8,'4.1 关键词原始数据'!$A:$N,T$2,FALSE)=0," ",VLOOKUP($J$1&$A8,'4.1 关键词原始数据'!$A:$N,T$2,FALSE))," ") | L8: =_xlfn.IFNA(IF(VLOOKUP($J$1&$A8,'4.1 关键词原始数据'!$A:$N,U$2,FALSE)=0," ",VLOOKUP($J$1&$A8,'4.1 关键词原始数据'!$A:$N,U$2,FALSE))," ") | M8: =_xlfn.IFNA(IF(VLOOKUP($J$1&$A8,'4.1 关键词原始数据'!$A:$N,V$2,FALSE)=0," ",VLOOKUP($J$1&$A8,'4.1 关键词原始数据'!$A:$N,V$2,FALSE))," ") | N8: =_xlfn.IFNA(IF(VLOOKUP($J$1&$A8,'4.1 关键词原始数据'!$A:$N,W$2,FALSE)=0," ",VLOOKUP($J$1&$A8,'4.1 关键词原始数据'!$A:$N,W$2,FALSE))," ") | O8: =_xlfn.IFNA(IF(VLOOKUP($J$1&$A8,'4.1 关键词原始数据'!$A:$N,X$2,FALSE)=0," ",VLOOKUP($J$1&$A8,'4.1 关键词原始数据'!$A:$N,X$2,FALSE))," ") | P8: =_xlfn.IFNA(IF(VLOOKUP($J$1&$A8,'4.1 关键词原始数据'!$A:$N,Y$2,FALSE)=0," ",VLOOKUP($J$1&$A8,'4.1 关键词原始数据'!$A:$N,Y$2,FALSE))," ") | Q8: =_xlfn.IFNA(IF(VLOOKUP($J$1&$A8,'4.1 关键词原始数据'!$A:$N,Z$2,FALSE)=0," ",VLOOKUP($J$1&$A8,'4.1 关键词原始数据'!$A:$N,Z$2,FALSE))," ")
A9: 9月2日上午 | B9: =_xlfn.IFNA(IF(VLOOKUP($B$1&$A9,'4.1 关键词原始数据'!$A:$N,S$2,FALSE)=0," ",VLOOKUP($B$1&$A9,'4.1 关键词原始数据'!$A:$N,S$2,FALSE))," ") | C9: =_xlfn.IFNA(IF(VLOOKUP($B$1&$A9,'4.1 关键词原始数据'!$A:$N,T$2,FALSE)=0," ",VLOOKUP($B$1&$A9,'4.1 关键词原始数据'!$A:$N,T$2,FALSE))," ") -> 2-14-4 | D9: =_xlfn.IFNA(IF(VLOOKUP($B$1&$A9,'4.1 关键词原始数据'!$A:$N,U$2,FALSE)=0," ",VLOOKUP($B$1&$A9,'4.1 关键词原始数据'!$A:$N,U$2,FALSE))," ") | E9: =_xlfn.IFNA(IF(VLOOKUP($B$1&$A9,'4.1 关键词原始数据'!$A:$N,V$2,FALSE)=0," ",VLOOKUP($B$1&$A9,'4.1 关键词原始数据'!$A:$N,V$2,FALSE))," ") | F9: =_xlfn.IFNA(IF(VLOOKUP($B$1&$A9,'4.1 关键词原始数据'!$A:$N,W$2,FALSE)=0," ",VLOOKUP($B$1&$A9,'4.1 关键词原始数据'!$A:$N,W$2,FALSE))," ") | G9: =_xlfn.IFNA(IF(VLOOKUP($B$1&$A9,'4.1 关键词原始数据'!$A:$N,X$2,FALSE)=0," ",VLOOKUP($B$1&$A9,'4.1 关键词原始数据'!$A:$N,X$2,FALSE))," ") -> 2-7-4 | H9: =_xlfn.IFNA(IF(VLOOKUP($B$1&$A9,'4.1 关键词原始数据'!$A:$N,Y$2,FALSE)=0," ",VLOOKUP($B$1&$A9,'4.1 关键词原始数据'!$A:$N,Y$2,FALSE))," ") | I9: =_xlfn.IFNA(IF(VLOOKUP($B$1&$A9,'4.1 关键词原始数据'!$A:$N,Z$2,FALSE)=0," ",VLOOKUP($B$1&$A9,'4.1 关键词原始数据'!$A:$N,Z$2,FALSE))," ") | J9: =_xlfn.IFNA(IF(VLOOKUP($J$1&$A9,'4.1 关键词原始数据'!$A:$N,S$2,FALSE)=0," ",VLOOKUP($J$1&$A9,'4.1 关键词原始数据'!$A:$N,S$2,FALSE))," ") | K9: =_xlfn.IFNA(IF(VLOOKUP($J$1&$A9,'4.1 关键词原始数据'!$A:$N,T$2,FALSE)=0," ",VLOOKUP($J$1&$A9,'4.1 关键词原始数据'!$A:$N,T$2,FALSE))," ") | L9: =_xlfn.IFNA(IF(VLOOKUP($J$1&$A9,'4.1 关键词原始数据'!$A:$N,U$2,FALSE)=0," ",VLOOKUP($J$1&$A9,'4.1 关键词原始数据'!$A:$N,U$2,FALSE))," ") | M9: =_xlfn.IFNA(IF(VLOOKUP($J$1&$A9,'4.1 关键词原始数据'!$A:$N,V$2,FALSE)=0," ",VLOOKUP($J$1&$A9,'4.1 关键词原始数据'!$A:$N,V$2,FALSE))," ") -> 3-16-4 | N9: =_xlfn.IFNA(IF(VLOOKUP($J$1&$A9,'4.1 关键词原始数据'!$A:$N,W$2,FALSE)=0," ",VLOOKUP($J$1&$A9,'4.1 关键词原始数据'!$A:$N,W$2,FALSE))," ") | O9: =_xlfn.IFNA(IF(VLOOKUP($J$1&$A9,'4.1 关键词原始数据'!$A:$N,X$2,FALSE)=0," ",VLOOKUP($J$1&$A9,'4.1 关键词原始数据'!$A:$N,X$2,FALSE))," ") | P9: =_xlfn.IFNA(IF(VLOOKUP($J$1&$A9,'4.1 关键词原始数据'!$A:$N,Y$2,FALSE)=0," ",VLOOKUP($J$1&$A9,'4.1 关键词原始数据'!$A:$N,Y$2,FALSE))," ") | Q9: =_xlfn.IFNA(IF(VLOOKUP($J$1&$A9,'4.1 关键词原始数据'!$A:$N,Z$2,FALSE)=0," ",VLOOKUP($J$1&$A9,'4.1 关键词原始数据'!$A:$N,Z$2,FALSE))," ")
A10: 9月2日晚上 | B10: =_xlfn.IFNA(IF(VLOOKUP($B$1&$A10,'4.1 关键词原始数据'!$A:$N,S$2,FALSE)=0," ",VLOOKUP($B$1&$A10,'4.1 关键词原始数据'!$A:$N,S$2,FALSE))," ") | C10: =_xlfn.IFNA(IF(VLOOKUP($B$1&$A10,'4.1 关键词原始数据'!$A:$N,T$2,FALSE)=0," ",VLOOKUP($B$1&$A10,'4.1 关键词原始数据'!$A:$N,T$2,FALSE))," ") | D10: =_xlfn.IFNA(IF(VLOOKUP($B$1&$A10,'4.1 关键词原始数据'!$A:$N,U$2,FALSE)=0," ",VLOOKUP($B$1&$A10,'4.1 关键词原始数据'!$A:$N,U$2,FALSE))," ") | E10: =_xlfn.IFNA(IF(VLOOKUP($B$1&$A10,'4.1 关键词原始数据'!$A:$N,V$2,FALSE)=0," ",VLOOKUP($B$1&$A10,'4.1 关键词原始数据'!$A:$N,V$2,FALSE))," ") | F10: =_xlfn.IFNA(IF(VLOOKUP($B$1&$A10,'4.1 关键词原始数据'!$A:$N,W$2,FALSE)=0," ",VLOOKUP($B$1&$A10,'4.1 关键词原始数据'!$A:$N,W$2,FALSE))," ") | G10: =_xlfn.IFNA(IF(VLOOKUP($B$1&$A10,'4.1 关键词原始数据'!$A:$N,X$2,FALSE)=0," ",VLOOKUP($B$1&$A10,'4.1 关键词原始数据'!$A:$N,X$2,FALSE))," ") | H10: =_xlfn.IFNA(IF(VLOOKUP($B$1&$A10,'4.1 关键词原始数据'!$A:$N,Y$2,FALSE)=0," ",VLOOKUP($B$1&$A10,'4.1 关键词原始数据'!$A:$N,Y$2,FALSE))," ") | I10: =_xlfn.IFNA(IF(VLOOKUP($B$1&$A10,'4.1 关键词原始数据'!$A:$N,Z$2,FALSE)=0," ",VLOOKUP($B$1&$A10,'4.1 关键词原始数据'!$A:$N,Z$2,FALSE))," ") | J10: =_xlfn.IFNA(IF(VLOOKUP($J$1&$A10,'4.1 关键词原始数据'!$A:$N,S$2,FALSE)=0," ",VLOOKUP($J$1&$A10,'4.1 关键词原始数据'!$A:$N,S$2,FALSE))," ") | K10: =_xlfn.IFNA(IF(VLOOKUP($J$1&$A10,'4.1 关键词原始数据'!$A:$N,T$2,FALSE)=0," ",VLOOKUP($J$1&$A10,'4.1 关键词原始数据'!$A:$N,T$2,FALSE))," ") | L10: =_xlfn.IFNA(IF(VLOOKUP($J$1&$A10,'4.1 关键词原始数据'!$A:$N,U$2,FALSE)=0," ",VLOOKUP($J$1&$A10,'4.1 关键词原始数据'!$A:$N,U$2,FALSE))," ") | M10: =_xlfn.IFNA(IF(VLOOKUP($J$1&$A10,'4.1 关键词原始数据'!$A:$N,V$2,FALSE)=0," ",VLOOKUP($J$1&$A10,'4.1 关键词原始数据'!$A:$N,V$2,FALSE))," ") | N10: =_xlfn.IFNA(IF(VLOOKUP($J$1&$A10,'4.1 关键词原始数据'!$A:$N,W$2,FALSE)=0," ",VLOOKUP($J$1&$A10,'4.1 关键词原始数据'!$A:$N,W$2,FALSE))," ") | O10: =_xlfn.IFNA(IF(VLOOKUP($J$1&$A10,'4.1 关键词原始数据'!$A:$N,X$2,FALSE)=0," ",VLOOKUP($J$1&$A10,'4.1 关键词原始数据'!$A:$N,X$2,FALSE))," ") | P10: =_xlfn.IFNA(IF(VLOOKUP($J$1&$A10,'4.1 关键词原始数据'!$A:$N,Y$2,FALSE)=0," ",VLOOKUP($J$1&$A10,'4.1 关键词原始数据'!$A:$N,Y$2,FALSE))," ") | Q10: =_xlfn.IFNA(IF(VLOOKUP($J$1&$A10,'4.1 关键词原始数据'!$A:$N,Z$2,FALSE)=0," ",VLOOKUP($J$1&$A10,'4.1 关键词原始数据'!$A:$N,Z$2,FALSE))," ")
A11: 9月3日上午 | B11: =_xlfn.IFNA(IF(VLOOKUP($B$1&$A11,'4.1 关键词原始数据'!$A:$N,S$2,FALSE)=0," ",VLOOKUP($B$1&$A11,'4.1 关键词原始数据'!$A:$N,S$2,FALSE))," ") | C11: =_xlfn.IFNA(IF(VLOOKUP($B$1&$A11,'4.1 关键词原始数据'!$A:$N,T$2,FALSE)=0," ",VLOOKUP($B$1&$A11,'4.1 关键词原始数据'!$A:$N,T$2,FALSE))," ") -> 3-12-4 | D11: =_xlfn.IFNA(IF(VLOOKUP($B$1&$A11,'4.1 关键词原始数据'!$A:$N,U$2,FALSE)=0," ",VLOOKUP($B$1&$A11,'4.1 关键词原始数据'!$A:$N,U$2,FALSE))," ") | E11: =_xlfn.IFNA(IF(VLOOKUP($B$1&$A11,'4.1 关键词原始数据'!$A:$N,V$2,FALSE)=0," ",VLOOKUP($B$1&$A11,'4.1 关键词原始数据'!$A:$N,V$2,FALSE))," ") | F11: =_xlfn.IFNA(IF(VLOOKUP($B$1&$A11,'4.1 关键词原始数据'!$A:$N,W$2,FALSE)=0," ",VLOOKUP($B$1&$A11,'4.1 关键词原始数据'!$A:$N,W$2,FALSE))," ") | G11: =_xlfn.IFNA(IF(VLOOKUP($B$1&$A11,'4.1 关键词原始数据'!$A:$N,X$2,FALSE)=0," ",VLOOKUP($B$1&$A11,'4.1 关键词原始数据'!$A:$N,X$2,FALSE))," ") -> 1-16-4 | H11: =_xlfn.IFNA(IF(VLOOKUP($B$1&$A11,'4.1 关键词原始数据'!$A:$N,Y$2,FALSE)=0," ",VLOOKUP($B$1&$A11,'4.1 关键词原始数据'!$A:$N,Y$2,FALSE))," ") | I11: =_xlfn.IFNA(IF(VLOOKUP($B$1&$A11,'4.1 关键词原始数据'!$A:$N,Z$2,FALSE)=0," ",VLOOKUP($B$1&$A11,'4.1 关键词原始数据'!$A:$N,Z$2,FALSE))," ") | J11: =_xlfn.IFNA(IF(VLOOKUP($J$1&$A11,'4.1 关键词原始数据'!$A:$N,S$2,FALSE)=0," ",VLOOKUP($J$1&$A11,'4.1 关键词原始数据'!$A:$N,S$2,FALSE))," ") | K11: =_xlfn.IFNA(IF(VLOOKUP($J$1&$A11,'4.1 关键词原始数据'!$A:$N,T$2,FALSE)=0," ",VLOOKUP($J$1&$A11,'4.1 关键词原始数据'!$A:$N,T$2,FALSE))," ") | L11: =_xlfn.IFNA(IF(VLOOKUP($J$1&$A11,'4.1 关键词原始数据'!$A:$N,U$2,FALSE)=0," ",VLOOKUP($J$1&$A11,'4.1 关键词原始数据'!$A:$N,U$2,FALSE))," ") | M11: =_xlfn.IFNA(IF(VLOOKUP($J$1&$A11,'4.1 关键词原始数据'!$A:$N,V$2,FALSE)=0," ",VLOOKUP($J$1&$A11,'4.1 关键词原始数据'!$A:$N,V$2,FALSE))," ") -> 4-12-4 | N11: =_xlfn.IFNA(IF(VLOOKUP($J$1&$A11,'4.1 关键词原始数据'!$A:$N,W$2,FALSE)=0," ",VLOOKUP($J$1&$A11,'4.1 关键词原始数据'!$A:$N,W$2,FALSE))," ") | O11: =_xlfn.IFNA(IF(VLOOKUP($J$1&$A11,'4.1 关键词原始数据'!$A:$N,X$2,FALSE)=0," ",VLOOKUP($J$1&$A11,'4.1 关键词原始数据'!$A:$N,X$2,FALSE))," ") | P11: =_xlfn.IFNA(IF(VLOOKUP($J$1&$A11,'4.1 关键词原始数据'!$A:$N,Y$2,FALSE)=0," ",VLOOKUP($J$1&$A11,'4.1 关键词原始数据'!$A:$N,Y$2,FALSE))," ") | Q11: =_xlfn.IFNA(IF(VLOOKUP($J$1&$A11,'4.1 关键词原始数据'!$A:$N,Z$2,FALSE)=0," ",VLOOKUP($J$1&$A11,'4.1 关键词原始数据'!$A:$N,Z$2,FALSE))," ")
A12: 9月4日晚上 | B12: =_xlfn.IFNA(IF(VLOOKUP($B$1&$A12,'4.1 关键词原始数据'!$A:$N,S$2,FALSE)=0," ",VLOOKUP($B$1&$A12,'4.1 关键词原始数据'!$A:$N,S$2,FALSE))," ") | C12: =_xlfn.IFNA(IF(VLOOKUP($B$1&$A12,'4.1 关键词原始数据'!$A:$N,T$2,FALSE)=0," ",VLOOKUP($B$1&$A12,'4.1 关键词原始数据'!$A:$N,T$2,FALSE))," ") | D12: =_xlfn.IFNA(IF(VLOOKUP($B$1&$A12,'4.1 关键词原始数据'!$A:$N,U$2,FALSE)=0," ",VLOOKUP($B$1&$A12,'4.1 关键词原始数据'!$A:$N,U$2,FALSE))," ") | E12: =_xlfn.IFNA(IF(VLOOKUP($B$1&$A12,'4.1 关键词原始数据'!$A:$N,V$2,FALSE)=0," ",VLOOKUP($B$1&$A12,'4.1 关键词原始数据'!$A:$N,V$2,FALSE))," ") | F12: =_xlfn.IFNA(IF(VLOOKUP($B$1&$A12,'4.1 关键词原始数据'!$A:$N,W$2,FALSE)=0," ",VLOOKUP($B$1&$A12,'4.1 关键词原始数据'!$A:$N,W$2,FALSE))," ") | G12: =_xlfn.IFNA(IF(VLOOKUP($B$1&$A12,'4.1 关键词原始数据'!$A:$N,X$2,FALSE)=0," ",VLOOKUP($B$1&$A12,'4.1 关键词原始数据'!$A:$N,X$2,FALSE))," ") | H12: =_xlfn.IFNA(IF(VLOOKUP($B$1&$A12,'4.1 关键词原始数据'!$A:$N,Y$2,FALSE)=0," ",VLOOKUP($B$1&$A12,'4.1 关键词原始数据'!$A:$N,Y$2,FALSE))," ") | I12: =_xlfn.IFNA(IF(VLOOKUP($B$1&$A12,'4.1 关键词原始数据'!$A:$N,Z$2,FALSE)=0," ",VLOOKUP($B$1&$A12,'4.1 关键词原始数据'!$A:$N,Z$2,FALSE))," ") | J12: =_xlfn.IFNA(IF(VLOOKUP($J$1&$A12,'4.1 关键词原始数据'!$A:$N,S$2,FALSE)=0," ",VLOOKUP($J$1&$A12,'4.1 关键词原始数据'!$A:$N,S$2,FALSE))," ") | K12: =_xlfn.IFNA(IF(VLOOKUP($J$1&$A12,'4.1 关键词原始数据'!$A:$N,T$2,FALSE)=0," ",VLOOKUP($J$1&$A12,'4.1 关键词原始数据'!$A:$N,T$2,FALSE))," ") | L12: =_xlfn.IFNA(IF(VLOOKUP($J$1&$A12,'4.1 关键词原始数据'!$A:$N,U$2,FALSE)=0," ",VLOOKUP($J$1&$A12,'4.1 关键词原始数据'!$A:$N,U$2,FALSE))," ") | M12: =_xlfn.IFNA(IF(VLOOKUP($J$1&$A12,'4.1 关键词原始数据'!$A:$N,V$2,FALSE)=0," ",VLOOKUP($J$1&$A12,'4.1 关键词原始数据'!$A:$N,V$2,FALSE))," ") | N12: =_xlfn.IFNA(IF(VLOOKUP($J$1&$A12,'4.1 关键词原始数据'!$A:$N,W$2,FALSE)=0," ",VLOOKUP($J$1&$A12,'4.1 关键词原始数据'!$A:$N,W$2,FALSE))," ") | O12: =_xlfn.IFNA(IF(VLOOKUP($J$1&$A12,'4.1 关键词原始数据'!$A:$N,X$2,FALSE)=0," ",VLOOKUP($J$1&$A12,'4.1 关键词原始数据'!$A:$N,X$2,FALSE))," ") | P12: =_xlfn.IFNA(IF(VLOOKUP($J$1&$A12,'4.1 关键词原始数据'!$A:$N,Y$2,FALSE)=0," ",VLOOKUP($J$1&$A12,'4.1 关键词原始数据'!$A:$N,Y$2,FALSE))," ") | Q12: =_xlfn.IFNA(IF(VLOOKUP($J$1&$A12,'4.1 关键词原始数据'!$A:$N,Z$2,FALSE)=0," ",VLOOKUP($J$1&$A12,'4.1 关键词原始数据'!$A:$N,Z$2,FALSE))," ")
A13: 9月5日上午 | B13: =_xlfn.IFNA(IF(VLOOKUP($B$1&$A13,'4.1 关键词原始数据'!$A:$N,S$2,FALSE)=0," ",VLOOKUP($B$1&$A13,'4.1 关键词原始数据'!$A:$N,S$2,FALSE))," ") | C13: =_xlfn.IFNA(IF(VLOOKUP($B$1&$A13,'4.1 关键词原始数据'!$A:$N,T$2,FALSE)=0," ",VLOOKUP($B$1&$A13,'4.1 关键词原始数据'!$A:$N,T$2,FALSE))," ") -> 3-11-1 | D13: =_xlfn.IFNA(IF(VLOOKUP($B$1&$A13,'4.1 关键词原始数据'!$A:$N,U$2,FALSE)=0," ",VLOOKUP($B$1&$A13,'4.1 关键词原始数据'!$A:$N,U$2,FALSE))," ") | E13: =_xlfn.IFNA(IF(VLOOKUP($B$1&$A13,'4.1 关键词原始数据'!$A:$N,V$2,FALSE)=0," ",VLOOKUP($B$1&$A13,'4.1 关键词原始数据'!$A:$N,V$2,FALSE))," ") -> 5-11-2 | F13: =_xlfn.IFNA(IF(VLOOKUP($B$1&$A13,'4.1 关键词原始数据'!$A:$N,W$2,FALSE)=0," ",VLOOKUP($B$1&$A13,'4.1 关键词原始数据'!$A:$N,W$2,FALSE))," ") | G13: =_xlfn.IFNA(IF(VLOOKUP($B$1&$A13,'4.1 关键词原始数据'!$A:$N,X$2,FALSE)=0," ",VLOOKUP($B$1&$A13,'4.1 关键词原始数据'!$A:$N,X$2,FALSE))," ") -> 1-17-4 | H13: =_xlfn.IFNA(IF(VLOOKUP($B$1&$A13,'4.1 关键词原始数据'!$A:$N,Y$2,FALSE)=0," ",VLOOKUP($B$1&$A13,'4.1 关键词原始数据'!$A:$N,Y$2,FALSE))," ") | I13: =_xlfn.IFNA(IF(VLOOKUP($B$1&$A13,'4.1 关键词原始数据'!$A:$N,Z$2,FALSE)=0," ",VLOOKUP($B$1&$A13,'4.1 关键词原始数据'!$A:$N,Z$2,FALSE))," ") | J13: =_xlfn.IFNA(IF(VLOOKUP($J$1&$A13,'4.1 关键词原始数据'!$A:$N,S$2,FALSE)=0," ",VLOOKUP($J$1&$A13,'4.1 关键词原始数据'!$A:$N,S$2,FALSE))," ") | K13: =_xlfn.IFNA(IF(VLOOKUP($J$1&$A13,'4.1 关键词原始数据'!$A:$N,T$2,FALSE)=0," ",VLOOKUP($J$1&$A13,'4.1 关键词原始数据'!$A:$N,T$2,FALSE))," ") | L13: =_xlfn.IFNA(IF(VLOOKUP($J$1&$A13,'4.1 关键词原始数据'!$A:$N,U$2,FALSE)=0," ",VLOOKUP($J$1&$A13,'4.1 关键词原始数据'!$A:$N,U$2,FALSE))," ") | M13: =_xlfn.IFNA(IF(VLOOKUP($J$1&$A13,'4.1 关键词原始数据'!$A:$N,V$2,FALSE)=0," ",VLOOKUP($J$1&$A13,'4.1 关键词原始数据'!$A:$N,V$2,FALSE))," ") | N13: =_xlfn.IFNA(IF(VLOOKUP($J$1&$A13,'4.1 关键词原始数据'!$A:$N,W$2,FALSE)=0," ",VLOOKUP($J$1&$A13,'4.1 关键词原始数据'!$A:$N,W$2,FALSE))," ") | O13: =_xlfn.IFNA(IF(VLOOKUP($J$1&$A13,'4.1 关键词原始数据'!$A:$N,X$2,FALSE)=0," ",VLOOKUP($J$1&$A13,'4.1 关键词原始数据'!$A:$N,X$2,FALSE))," ") | P13: =_xlfn.IFNA(IF(VLOOKUP($J$1&$A13,'4.1 关键词原始数据'!$A:$N,Y$2,FALSE)=0," ",VLOOKUP($J$1&$A13,'4.1 关键词原始数据'!$A:$N,Y$2,FALSE))," ") | Q13: =_xlfn.IFNA(IF(VLOOKUP($J$1&$A13,'4.1 关键词原始数据'!$A:$N,Z$2,FALSE)=0," ",VLOOKUP($J$1&$A13,'4.1 关键词原始数据'!$A:$N,Z$2,FALSE))," ")
A14: 9月6日晚上 | B14: =_xlfn.IFNA(IF(VLOOKUP($B$1&$A14,'4.1 关键词原始数据'!$A:$N,S$2,FALSE)=0," ",VLOOKUP($B$1&$A14,'4.1 关键词原始数据'!$A:$N,S$2,FALSE))," ") | C14: =_xlfn.IFNA(IF(VLOOKUP($B$1&$A14,'4.1 关键词原始数据'!$A:$N,T$2,FALSE)=0," ",VLOOKUP($B$1&$A14,'4.1 关键词原始数据'!$A:$N,T$2,FALSE))," ") | D14: =_xlfn.IFNA(IF(VLOOKUP($B$1&$A14,'4.1 关键词原始数据'!$A:$N,U$2,FALSE)=0," ",VLOOKUP($B$1&$A14,'4.1 关键词原始数据'!$A:$N,U$2,FALSE))," ") | E14: =_xlfn.IFNA(IF(VLOOKUP($B$1&$A14,'4.1 关键词原始数据'!$A:$N,V$2,FALSE)=0," ",VLOOKUP($B$1&$A14,'4.1 关键词原始数据'!$A:$N,V$2,FALSE))," ") | F14: =_xlfn.IFNA(IF(VLOOKUP($B$1&$A14,'4.1 关键词原始数据'!$A:$N,W$2,FALSE)=0," ",VLOOKUP($B$1&$A14,'4.1 关键词原始数据'!$A:$N,W$2,FALSE))," ") | G14: =_xlfn.IFNA(IF(VLOOKUP($B$1&$A14,'4.1 关键词原始数据'!$A:$N,X$2,FALSE)=0," ",VLOOKUP($B$1&$A14,'4.1 关键词原始数据'!$A:$N,X$2,FALSE))," ") | H14: =_xlfn.IFNA(IF(VLOOKUP($B$1&$A14,'4.1 关键词原始数据'!$A:$N,Y$2,FALSE)=0," ",VLOOKUP($B$1&$A14,'4.1 关键词原始数据'!$A:$N,Y$2,FALSE))," ") | I14: =_xlfn.IFNA(IF(VLOOKUP($B$1&$A14,'4.1 关键词原始数据'!$A:$N,Z$2,FALSE)=0," ",VLOOKUP($B$1&$A14,'4.1 关键词原始数据'!$A:$N,Z$2,FALSE))," ") | J14: =_xlfn.IFNA(IF(VLOOKUP($J$1&$A14,'4.1 关键词原始数据'!$A:$N,S$2,FALSE)=0," ",VLOOKUP($J$1&$A14,'4.1 关键词原始数据'!$A:$N,S$2,FALSE))," ") | K14: =_xlfn.IFNA(IF(VLOOKUP($J$1&$A14,'4.1 关键词原始数据'!$A:$N,T$2,FALSE)=0," ",VLOOKUP($J$1&$A14,'4.1 关键词原始数据'!$A:$N,T$2,FALSE))," ") | L14: =_xlfn.IFNA(IF(VLOOKUP($J$1&$A14,'4.1 关键词原始数据'!$A:$N,U$2,FALSE)=0," ",VLOOKUP($J$1&$A14,'4.1 关键词原始数据'!$A:$N,U$2,FALSE))," ") | M14: =_xlfn.IFNA(IF(VLOOKUP($J$1&$A14,'4.1 关键词原始数据'!$A:$N,V$2,FALSE)=0," ",VLOOKUP($J$1&$A14,'4.1 关键词原始数据'!$A:$N,V$2,FALSE))," ") | N14: =_xlfn.IFNA(IF(VLOOKUP($J$1&$A14,'4.1 关键词原始数据'!$A:$N,W$2,FALSE)=0," ",VLOOKUP($J$1&$A14,'4.1 关键词原始数据'!$A:$N,W$2,FALSE))," ") | O14: =_xlfn.IFNA(IF(VLOOKUP($J$1&$A14,'4.1 关键词原始数据'!$A:$N,X$2,FALSE)=0," ",VLOOKUP($J$1&$A14,'4.1 关键词原始数据'!$A:$N,X$2,FALSE))," ") | P14: =_xlfn.IFNA(IF(VLOOKUP($J$1&$A14,'4.1 关键词原始数据'!$A:$N,Y$2,FALSE)=0," ",VLOOKUP($J$1&$A14,'4.1 关键词原始数据'!$A:$N,Y$2,FALSE))," ") | Q14: =_xlfn.IFNA(IF(VLOOKUP($J$1&$A14,'4.1 关键词原始数据'!$A:$N,Z$2,FALSE)=0," ",VLOOKUP($J$1&$A14,'4.1 关键词原始数据'!$A:$N,Z$2,FALSE))," ")
A15: 9月7日上午 | B15: =_xlfn.IFNA(IF(VLOOKUP($B$1&$A15,'4.1 关键词原始数据'!$A:$N,S$2,FALSE)=0," ",VLOOKUP($B$1&$A15,'4.1 关键词原始数据'!$A:$N,S$2,FALSE))," ") | C15: =_xlfn.IFNA(IF(VLOOKUP($B$1&$A15,'4.1 关键词原始数据'!$A:$N,T$2,FALSE)=0," ",VLOOKUP($B$1&$A15,'4.1 关键词原始数据'!$A:$N,T$2,FALSE))," ") -> 3-12-3 | D15: =_xlfn.IFNA(IF(VLOOKUP($B$1&$A15,'4.1 关键词原始数据'!$A:$N,U$2,FALSE)=0," ",VLOOKUP($B$1&$A15,'4.1 关键词原始数据'!$A:$N,U$2,FALSE))," ") | E15: =_xlfn.IFNA(IF(VLOOKUP($B$1&$A15,'4.1 关键词原始数据'!$A:$N,V$2,FALSE)=0," ",VLOOKUP($B$1&$A15,'4.1 关键词原始数据'!$A:$N,V$2,FALSE))," ") | F15: =_xlfn.IFNA(IF(VLOOKUP($B$1&$A15,'4.1 关键词原始数据'!$A:$N,W$2,FALSE)=0," ",VLOOKUP($B$1&$A15,'4.1 关键词原始数据'!$A:$N,W$2,FALSE))," ") | G15: =_xlfn.IFNA(IF(VLOOKUP($B$1&$A15,'4.1 关键词原始数据'!$A:$N,X$2,FALSE)=0," ",VLOOKUP($B$1&$A15,'4.1 关键词原始数据'!$A:$N,X$2,FALSE))," ") -> 2-3-1 | H15: =_xlfn.IFNA(IF(VLOOKUP($B$1&$A15,'4.1 关键词原始数据'!$A:$N,Y$2,FALSE)=0," ",VLOOKUP($B$1&$A15,'4.1 关键词原始数据'!$A:$N,Y$2,FALSE))," ") | I15: =_xlfn.IFNA(IF(VLOOKUP($B$1&$A15,'4.1 关键词原始数据'!$A:$N,Z$2,FALSE)=0," ",VLOOKUP($B$1&$A15,'4.1 关键词原始数据'!$A:$N,Z$2,FALSE))," ") | J15: =_xlfn.IFNA(IF(VLOOKUP($J$1&$A15,'4.1 关键词原始数据'!$A:$N,S$2,FALSE)=0," ",VLOOKUP($J$1&$A15,'4.1 关键词原始数据'!$A:$N,S$2,FALSE))," ") | K15: =_xlfn.IFNA(IF(VLOOKUP($J$1&$A15,'4.1 关键词原始数据'!$A:$N,T$2,FALSE)=0," ",VLOOKUP($J$1&$A15,'4.1 关键词原始数据'!$A:$N,T$2,FALSE))," ") | L15: =_xlfn.IFNA(IF(VLOOKUP($J$1&$A15,'4.1 关键词原始数据'!$A:$N,U$2,FALSE)=0," ",VLOOKUP($J$1&$A15,'4.1 关键词原始数据'!$A:$N,U$2,FALSE))," ") | M15: =_xlfn.IFNA(IF(VLOOKUP($J$1&$A15,'4.1 关键词原始数据'!$A:$N,V$2,FALSE)=0," ",VLOOKUP($J$1&$A15,'4.1 关键词原始数据'!$A:$N,V$2,FALSE))," ") -> 4-4-4 | N15: =_xlfn.IFNA(IF(VLOOKUP($J$1&$A15,'4.1 关键词原始数据'!$A:$N,W$2,FALSE)=0," ",VLOOKUP($J$1&$A15,'4.1 关键词原始数据'!$A:$N,W$2,FALSE))," ") | O15: =_xlfn.IFNA(IF(VLOOKUP($J$1&$A15,'4.1 关键词原始数据'!$A:$N,X$2,FALSE)=0," ",VLOOKUP($J$1&$A15,'4.1 关键词原始数据'!$A:$N,X$2,FALSE))," ") | P15: =_xlfn.IFNA(IF(VLOOKUP($J$1&$A15,'4.1 关键词原始数据'!$A:$N,Y$2,FALSE)=0," ",VLOOKUP($J$1&$A15,'4.1 关键词原始数据'!$A:$N,Y$2,FALSE))," ") | Q15: =_xlfn.IFNA(IF(VLOOKUP($J$1&$A15,'4.1 关键词原始数据'!$A:$N,Z$2,FALSE)=0," ",VLOOKUP($J$1&$A15,'4.1 关键词原始数据'!$A:$N,Z$2,FALSE))," ")
A16: 9月7日晚上 | B16: =_xlfn.IFNA(IF(VLOOKUP($B$1&$A16,'4.1 关键词原始数据'!$A:$N,S$2,FALSE)=0," ",VLOOKUP($B$1&$A16,'4.1 关键词原始数据'!$A:$N,S$2,FALSE))," ") | C16: =_xlfn.IFNA(IF(VLOOKUP($B$1&$A16,'4.1 关键词原始数据'!$A:$N,T$2,FALSE)=0," ",VLOOKUP($B$1&$A16,'4.1 关键词原始数据'!$A:$N,T$2,FALSE))," ") | D16: =_xlfn.IFNA(IF(VLOOKUP($B$1&$A16,'4.1 关键词原始数据'!$A:$N,U$2,FALSE)=0," ",VLOOKUP($B$1&$A16,'4.1 关键词原始数据'!$A:$N,U$2,FALSE))," ") | E16: =_xlfn.IFNA(IF(VLOOKUP($B$1&$A16,'4.1 关键词原始数据'!$A:$N,V$2,FALSE)=0," ",VLOOKUP($B$1&$A16,'4.1 关键词原始数据'!$A:$N,V$2,FALSE))," ") | F16: =_xlfn.IFNA(IF(VLOOKUP($B$1&$A16,'4.1 关键词原始数据'!$A:$N,W$2,FALSE)=0," ",VLOOKUP($B$1&$A16,'4.1 关键词原始数据'!$A:$N,W$2,FALSE))," ") | G16: =_xlfn.IFNA(IF(VLOOKUP($B$1&$A16,'4.1 关键词原始数据'!$A:$N,X$2,FALSE)=0," ",VLOOKUP($B$1&$A16,'4.1 关键词原始数据'!$A:$N,X$2,FALSE))," ") | H16: =_xlfn.IFNA(IF(VLOOKUP($B$1&$A16,'4.1 关键词原始数据'!$A:$N,Y$2,FALSE)=0," ",VLOOKUP($B$1&$A16,'4.1 关键词原始数据'!$A:$N,Y$2,FALSE))," ") | I16: =_xlfn.IFNA(IF(VLOOKUP($B$1&$A16,'4.1 关键词原始数据'!$A:$N,Z$2,FALSE)=0," ",VLOOKUP($B$1&$A16,'4.1 关键词原始数据'!$A:$N,Z$2,FALSE))," ") | J16: =_xlfn.IFNA(IF(VLOOKUP($J$1&$A16,'4.1 关键词原始数据'!$A:$N,S$2,FALSE)=0," ",VLOOKUP($J$1&$A16,'4.1 关键词原始数据'!$A:$N,S$2,FALSE))," ") | K16: =_xlfn.IFNA(IF(VLOOKUP($J$1&$A16,'4.1 关键词原始数据'!$A:$N,T$2,FALSE)=0," ",VLOOKUP($J$1&$A16,'4.1 关键词原始数据'!$A:$N,T$2,FALSE))," ") | L16: =_xlfn.IFNA(IF(VLOOKUP($J$1&$A16,'4.1 关键词原始数据'!$A:$N,U$2,FALSE)=0," ",VLOOKUP($J$1&$A16,'4.1 关键词原始数据'!$A:$N,U$2,FALSE))," ") | M16: =_xlfn.IFNA(IF(VLOOKUP($J$1&$A16,'4.1 关键词原始数据'!$A:$N,V$2,FALSE)=0," ",VLOOKUP($J$1&$A16,'4.1 关键词原始数据'!$A:$N,V$2,FALSE))," ") | N16: =_xlfn.IFNA(IF(VLOOKUP($J$1&$A16,'4.1 关键词原始数据'!$A:$N,W$2,FALSE)=0," ",VLOOKUP($J$1&$A16,'4.1 关键词原始数据'!$A:$N,W$2,FALSE))," ") | O16: =_xlfn.IFNA(IF(VLOOKUP($J$1&$A16,'4.1 关键词原始数据'!$A:$N,X$2,FALSE)=0," ",VLOOKUP($J$1&$A16,'4.1 关键词原始数据'!$A:$N,X$2,FALSE))," ") | P16: =_xlfn.IFNA(IF(VLOOKUP($J$1&$A16,'4.1 关键词原始数据'!$A:$N,Y$2,FALSE)=0," ",VLOOKUP($J$1&$A16,'4.1 关键词原始数据'!$A:$N,Y$2,FALSE))," ") | Q16: =_xlfn.IFNA(IF(VLOOKUP($J$1&$A16,'4.1 关键词原始数据'!$A:$N,Z$2,FALSE)=0," ",VLOOKUP($J$1&$A16,'4.1 关键词原始数据'!$A:$N,Z$2,FALSE))," ")
... A84: 10月15日上午 | B84: =_xlfn.IFNA(IF(VLOOKUP($B$1&$A84,'4.1 关键词原始数据'!$A:$N,S$2,FALSE)=0," ",VLOOKUP($B$1&$A84,'4.1 关键词原始数据'!$A:$N,S$2,FALSE))," ") | C84: =_xlfn.IFNA(IF(VLOOKUP($B$1&$A84,'4.1 关键词原始数据'!$A:$N,T$2,FALSE)=0," ",VLOOKUP($B$1&$A84,'4.1 关键词原始数据'!$A:$N,T$2,FALSE))," ") | D84: =_xlfn.IFNA(IF(VLOOKUP($B$1&$A84,'4.1 关键词原始数据'!$A:$N,U$2,FALSE)=0," ",VLOOKUP($B$1&$A84,'4.1 关键词原始数据'!$A:$N,U$2,FALSE))," ") | E84: =_xlfn.IFNA(IF(VLOOKUP($B$1&$A84,'4.1 关键词原始数据'!$A:$N,V$2,FALSE)=0," ",VLOOKUP($B$1&$A84,'4.1 关键词原始数据'!$A:$N,V$2,FALSE))," ") | F84: =_xlfn.IFNA(IF(VLOOKUP($B$1&$A84,'4.1 关键词原始数据'!$A:$N,W$2,FALSE)=0," ",VLOOKUP($B$1&$A84,'4.1 关键词原始数据'!$A:$N,W$2,FALSE))," ") | G84: =_xlfn.IFNA(IF(VLOOKUP($B$1&$A84,'4.1 关键词原始数据'!$A:$N,X$2,FALSE)=0," ",VLOOKUP($B$1&$A84,'4.1 关键词原始数据'!$A:$N,X$2,FALSE))," ") -> 5-3-1 | H84: =_xlfn.IFNA(IF(VLOOKUP($B$1&$A84,'4.1 关键词原始数据'!$A:$N,Y$2,FALSE)=0," ",VLOOKUP($B$1&$A84,'4.1 关键词原始数据'!$A:$N,Y$2,FALSE))," ") | I84: =_xlfn.IFNA(IF(VLOOKUP($B$1&$A84,'4.1 关键词原始数据'!$A:$N,Z$2,FALSE)=0," ",VLOOKUP($B$1&$A84,'4.1 关键词原始数据'!$A:$N,Z$2,FALSE))," ") | J84: =_xlfn.IFNA(IF(VLOOKUP($J$1&$A84,'4.1 关键词原始数据'!$A:$N,S$2,FALSE)=0," ",VLOOKUP($J$1&$A84,'4.1 关键词原始数据'!$A:$N,S$2,FALSE))," ") | K84: =_xlfn.IFNA(IF(VLOOKUP($J$1&$A84,'4.1 关键词原始数据'!$A:$N,T$2,FALSE)=0," ",VLOOKUP($J$1&$A84,'4.1 关键词原始数据'!$A:$N,T$2,FALSE))," ") | L84: =_xlfn.IFNA(IF(VLOOKUP($J$1&$A84,'4.1 关键词原始数据'!$A:$N,U$2,FALSE)=0," ",VLOOKUP($J$1&$A84,'4.1 关键词原始数据'!$A:$N,U$2,FALSE))," ") | M84: =_xlfn.IFNA(IF(VLOOKUP($J$1&$A84,'4.1 关键词原始数据'!$A:$N,V$2,FALSE)=0," ",VLOOKUP($J$1&$A84,'4.1 关键词原始数据'!$A:$N,V$2,FALSE))," ") -> 4-2-2 | N84: =_xlfn.IFNA(IF(VLOOKUP($J$1&$A84,'4.1 关键词原始数据'!$A:$N,W$2,FALSE)=0," ",VLOOKUP($J$1&$A84,'4.1 关键词原始数据'!$A:$N,W$2,FALSE))," ") -> 1-1-1 | O84: =_xlfn.IFNA(IF(VLOOKUP($J$1&$A84,'4.1 关键词原始数据'!$A:$N,X$2,FALSE)=0," ",VLOOKUP($J$1&$A84,'4.1 关键词原始数据'!$A:$N,X$2,FALSE))," ") | P84: =_xlfn.IFNA(IF(VLOOKUP($J$1&$A84,'4.1 关键词原始数据'!$A:$N,Y$2,FALSE)=0," ",VLOOKUP($J$1&$A84,'4.1 关键词原始数据'!$A:$N,Y$2,FALSE))," ") | Q84: =_xlfn.IFNA(IF(VLOOKUP($J$1&$A84,'4.1 关键词原始数据'!$A:$N,Z$2,FALSE)=0," ",VLOOKUP($J$1&$A84,'4.1 关键词原始数据'!$A:$N,Z$2,FALSE))," ")
A85: 10月15日晚上

Sheet 3.3 广告数据
A1: 分析指南 | B1: 1、发现问题：整体数据是否正常且符合预期，对主推SKU做重点分析，次推SKU做简要总结（花费、展示位置、搜索词、是否有特殊情况等） 2、业务优化：广告结构是否需要进行一定的优化？ 3、数据跟踪：后续应当关注哪些重点指标？（如关键词排序、曝光量、曝光位置等） 4、展示位、搜索词等辅助信息，在分析时如果需要再截取，不要每个SKU每个广告组都截
A2: 主推款SKU | B2: XXXX-111 | C2: ASIN | D2: ASIN1 | E2: 主图 | I2: 次推款SKU | J2: XXXX-222 | K2: ASIN | L2: ASIN2 | M2: 主图
A3: 日期 | B3: 广告总花费 | C3: 广告展示量 | D3: 广告点击量 | E3: 广告点击率 | F3: 广告订单量 | G3: 广告转化率 | I3: 日期 | J3: 广告总花费 | K3: 广告展示量 | L3: 广告点击量 | M3: 广告点击率 | N3: 广告订单量 | O3: 广告转化率
A4: 2026-08-23 | I4: 2026-08-23
A5: 2026-08-24 | I5: 2026-08-24
A6: 2026-08-25 | I6: 2026-08-25
A7: 2026-08-26 | I7: 2026-08-26
A8: 2026-08-27 | I8: 2026-08-27
A9: 2026-08-28 | I9: 2026-08-28
A10: 2026-08-29 | I10: 2026-08-29
A11: 2026-08-30 | I11: 2026-08-30
A12: 2026-08-31 | I12: 2026-08-31
A13: 2026-09-1 | I13: 2026-09-1
A14: 2026-09-2 | I14: 2026-09-2
A15: 2026-09-3 | I15: 2026-09-3
... A36: 2026-09-24 | I36: 2026-09-24
A222: MYTD-157

Sheet 4.1 关键词原始数据
B1: 品牌 | C1: 产品系列 | D1: 款式 | E1: SKU | G1: 关键词排序
G2: 关键词1 | I2: 关键词2 | K2: 关键词3 | M2: 关键词4
A3: 辅助标识 | F3: 日期 | G3: 广告位 | H3: 自然位 | I3: 广告位 | J3: 自然位 | K3: 广告位 | L3: 自然位 | M3: 广告位 | N3: 自然位
A4: =E4&F4 -> XXXX-1118月31日上午 | E4: XXXX-111 | F4: 8月31日上午 | H4: 3-7-2 | L4: 1-17-1
A5: =E5&F5 -> XXXX-2228月31日上午 | E5: XXXX-222 | F5: 8月31日上午
A6: =E6&F6 -> 8月31日上午 | F6: 8月31日上午
A7: =E7&F7 -> 8月31日上午 | F7: 8月31日上午 | J7: 6-12-3
A8: =E8&F8 -> 8月31日上午 | F8: 8月31日上午
A9: =E9&F9 -> 8月31日上午 | F9: 8月31日上午
A10: =E10&F10 -> 8月31日上午 | F10: 8月31日上午
A11: =E11&F11 | G11: 关键词排序
A12: =E12&F12 | G12: 关键词1 | I12: 关键词2 | K12: 关键词3 | M12: 关键词4
A13: =E13&F13 -> 日期 | F13: 日期 | G13: 广告位 | H13: 自然位 | I13: 广告位 | J13: 自然位 | K13: 广告位 | L13: 自然位 | M13: 广告位 | N13: 自然位
A14: =E14&F14 -> XXXX-1118月31日晚上 | E14: XXXX-111 | F14: 8月31日晚上
A15: =E15&F15 -> XXXX-2228月31日晚上 | E15: XXXX-222 | F15: 8月31日晚上
A16: =E16&F16 -> 8月31日晚上 | F16: 8月31日晚上
A17: =E17&F17 -> 8月31日晚上 | F17: 8月31日晚上
A18: =E18&F18 -> 8月31日晚上 | F18: 8月31日晚上
A19: =E19&F19 -> 8月31日晚上 | F19: 8月31日晚上
A20: =E20&F20 -> 8月31日晚上 | F20: 8月31日晚上
A22: =E22&F22
A23: =E23&F23
A24: =E24&F24 -> SKU | B24: 品牌 | C24: 产品系列 | D24: 款式 | E24: SKU | G24: 关键词排序
A25: =E25&F25 | G25: 关键词1 | I25: 关键词2 | K25: 关键词3 | M25: 关键词4
A26: =E26&F26 -> 日期 | F26: 日期 | G26: 广告位 | H26: 自然位 | I26: 广告位 | J26: 自然位 | K26: 广告位 | L26: 自然位 | M26: 广告位 | N26: 自然位
A27: =E27&F27 -> XXXX-1119月1日上午 | E27: XXXX-111 | F27: 9月1日上午 | H27: 2-12-4 | J27: 2-4-4
A28: =E28&F28 -> XXXX-2229月1日上午 | E28: XXXX-222 | F28: 9月1日上午
A29: =E29&F29 -> 9月1日上午 | F29: 9月1日上午 | J29: 6-5-1
A30: =E30&F30 -> 9月1日上午 | F30: 9月1日上午
A31: =E31&F31 -> 9月1日上午 | F31: 9月1日上午 | J31: 5-4-4
A32: =E32&F32 -> 9月1日上午 | F32: 9月1日上午
A33: =E33&F33 -> 9月1日上午 | F33: 9月1日上午
A34: =E34&F34 | G34: 关键词1 | I34: 关键词2 | K34: 关键词3 | M34: 关键词4
A35: =E35&F35 -> 日期 | F35: 日期 | G35: 广告位 | H35: 自然位 | I35: 广告位 | J35: 自然位 | K35: 广告位 | L35: 自然位 | M35: 广告位 | N35: 自然位
A36: =E36&F36 -> XXXX-1119月1日晚上 | E36: XXXX-111 | F36: 9月1日晚上
A37: =E37&F37 -> XXXX-2229月1日晚上 | E37: XXXX-222 | F37: 9月1日晚上
A38: =E38&F38 -> 9月1日晚上 | F38: 9月1日晚上
A39: =E39&F39 -> 9月1日晚上 | F39: 9月1日晚上
A40: =E40&F40 -> 9月1日晚上 | F40: 9月1日晚上
A41: =E41&F41 -> 9月1日晚上 | F41: 9月1日晚上
...

Sheet 4.2 产品详情原始数据
A1: 产品标识 | B1: 时间 | C1: ASIN | D1: 父ASIN | E1: MSKU | F1: 品名 | G1: 价格 | H1: FBA可售 | I1: FBM可售 | J1: 销量 | K1: 订单量 | L1: 销售额 | M1: 净销售额 | N1: B2B 销量 | O1: B2B 销售额 | P1: B2B 订单量 | Q1: 促销销量 | R1: 促销销售额 | S1: 促销订单量 | T1: 平均客单价 | U1: 平均销量 | V1: 大类排名 | W1: 小类排名 | X1: 退款量 | Y1: 退款率 | Z1: 评分 | AA1: 评论数 | AB1: 留评率 | AC1: 促销折扣 | AD1: 毛利润 | AE1: 毛利率 | AF1: ROI | AG1: 退货量 | AH1: 退货率 | AI1: Sessions-Browser | AJ1: Sessions-Mobile | AK1: Sessions-Total | AL1: PV-Browser | AM1: PV-Mobile | AN1: PV-Total | AO1: Buybox | AP1: CVR | AQ1: 销量CVR | AR1: CPC | AS1: CTR | AT1: 广告花费 | AU1: ROAS | AV1: ACOS | AW1: ACoAS | AX1: ASoAS | AY1: CPO | AZ1: CPM | BA1: 广告销售额 | BB1: 广告订单量 | BC1: 广告订单占比 | BD1: 广告CVR | BE1: 展示 | BF1: 点击 | BG1: 运营日志1
A2: =B2&E2 -> 46254XXXX-111 | B2: 46254 | C2: ASIN1 | E2: XXXX-111 | G2: 13.99 | H2: 199 | I2: 0 | J2: 0 | K2: 0 | L2: 0 | M2: 0 | N2: 0 | O2: 0 | P2: 0 | Q2: 0 | R2: 0 | S2: 0 | U2: 0 | X2: 0 | Y2: 0 | Z2: 0 | AA2: 0 | AB2: 0 | AC2: 0 | AD2: 0 | AE2: 0 | AF2: 0 | AG2: 0 | AH2: 0 | AI2: 0 | AJ2: 0 | AK2: 0 | AL2: 0 | AM2: 0 | AN2: 0 | AP2: 0 | AQ2: 0 | AS2: 0 | AT2: 0 | AU2: 0 | AV2: 0 | AW2: 0 | AX2: 0 | AZ2: 0 | BA2: 0 | BB2: 0 | BC2: 0 | BD2: 0 | BE2: 0 | BF2: 0
A3: =B3&E3 -> 46255XXXX-111 | B3: 46255 | C3: ASIN1 | E3: XXXX-111 | G3: 13.99 | H3: 259 | I3: 0 | J3: 0 | K3: 0 | L3: 0 | M3: 0 | N3: 0 | O3: 0 | P3: 0 | Q3: 0 | R3: 0 | S3: 0 | U3: 0 | X3: 0 | Y3: 0 | Z3: 0 | AA3: 0 | AB3: 0 | AC3: 0 | AD3: 0 | AE3: 0 | AF3: 0 | AG3: 0 | AH3: 0 | AI3: 0 | AJ3: 0 | AK3: 0 | AL3: 0 | AM3: 0 | AN3: 0 | AP3: 0 | AQ3: 0 | AS3: 0 | AT3: 0 | AU3: 0 | AV3: 0 | AW3: 0 | AX3: 0 | AZ3: 0 | BA3: 0 | BB3: 0 | BC3: 0 | BD3: 0 | BE3: 0 | BF3: 0
A4: =B4&E4 -> 46256XXXX-111 | B4: 46256 | C4: ASIN1 | E4: XXXX-111 | G4: 13.99 | H4: 319 | I4: 0 | J4: 0 | K4: 0 | L4: 0 | M4: 0 | N4: 0 | O4: 0 | P4: 0 | Q4: 0 | R4: 0 | S4: 0 | U4: 0 | X4: 0 | Y4: 0 | Z4: 0 | AA4: 0 | AB4: 0 | AC4: 0 | AD4: 0 | AE4: 0 | AF4: 0 | AG4: 0 | AH4: 0 | AI4: 0 | AJ4: 0 | AK4: 0 | AL4: 0 | AM4: 0 | AN4: 0 | AP4: 0 | AQ4: 0 | AS4: 0 | AT4: 0 | AU4: 0 | AV4: 0 | AW4: 0 | AX4: 0 | AZ4: 0 | BA4: 0 | BB4: 0 | BC4: 0 | BD4: 0 | BE4: 0 | BF4: 0
A5: =B5&E5 -> 46257XXXX-111 | B5: 46257 | C5: ASIN1 | E5: XXXX-111 | G5: 13.99 | H5: 340 | I5: 0 | J5: 2 | K5: 2 | L5: 27.98 | M5: 27.98 | N5: 0 | O5: 0 | P5: 0 | Q5: 0 | R5: 0 | S5: 0 | T5: 13.99 | U5: 0 | X5: 0 | Y5: 0 | Z5: 0 | AA5: 0 | AB5: 0 | AC5: 0 | AD5: -20.95 | AE5: 0 | AF5: 0.2452 | AG5: 0 | AH5: 0 | AI5: 9 | AJ5: 20 | AK5: 29 | AL5: 14 | AM5: 23 | AN5: 37 | AO5: 1 | AP5: 0.069 | AQ5: 0.069 | AR5: 0.91 | AS5: 0.002 | AT5: -20.95 | AU5: 2.67 | AV5: 0.3744 | AW5: 0.7487 | AX5: 2 | AY5: 5.24 | AZ5: 1.81 | BA5: 55.96 | BB5: 4 | BC5: 2 | BD5: 0.1739 | BE5: 11582 | BF5: 23
