Workbook

Sheet 阶段实际盈亏
A1: 时间 | B1: 实际 | C1: 价格 | D1: 站内 coupon | E1: 站内 code | F1: 站外 折扣 | G1: 站外 订单 | H1: 站内 自然单 | I1: 站内 广告单 | J1: 阶段 销售 订单 | K1: 时间 /天 | L1: 阶段广告费 （出1单广告单预估） | M1: 阶段站外费用 （5美金/单） | N1: 阶段订单 盈亏 | O1: 阶段亏损 /美金 | P1: 六阶段 总亏损 | Q1: 资金ROI | R1: 阶段日均 订单 | S1: 阶段日均 广告订单 | T1: 阶段日均 自然订单 | U1: 新品 排行榜 | V1: 小类目 排名
A2: 9月7-9月12 | B2: 第一阶段 | C2: 89.99 | D2: 0.05 | E2: 0.5 | F2: 0.68 | G2: 58 | H2: 10 | I2: 20 | J2: =SUM(G2:I2) -> 88 | K2: 6 | L2: =5*I2 -> 100 | M2: =5*G2 -> 290 | N2: =SUM(J2) -> 88 | O2: =SUM(L2:N2) -> 478 | P2: =SUM(L2:O2) -> 956 | R2: =J2/7 -> 12.571429 | S2: =I2/7 -> 2.8571429 | T2: =H2/7 -> 1.4285714 | V2: 25
A3: 9月13-9月21 | B3: 第二阶段 | C3: 79.99 | D3: 0.3 | E3: 0.2 | F3: 0.3 | G3: 81 | H3: 14 | I3: 20 | J3: =SUM(G3:I3) -> 115 | K3: 9 | L3: =5*I3 -> 100 | M3: =5*G3 -> 405 | N3: =SUM(J3) -> 115 | O3: =SUM(L3:N3) -> 620 | P3: =SUM(L3:O3) -> 1240 | R3: =J3/7 -> 16.428571 | S3: =I3/7 -> 2.8571429 | T3: =H3/7 -> 2 | V3: 22
A4: 9月22-10月1 | B4: 第三阶段 | C4: 69.99 | D4: 0.3 | E4: 0.2 | F4: 0.25 | G4: 45 | H4: 60 | I4: 23 | J4: =SUM(G4:I4) -> 128 | K4: 10 | L4: =5*I4 -> 115 | M4: =5*G4 -> 225 | N4: =SUM(J4) -> 128 | O4: =SUM(L4:N4) -> 468 | P4: =SUM(L4:O4) -> 936 | R4: =J4/7 -> 18.285714 | S4: =I4/7 -> 3.2857143 | T4: =H4/7 -> 8.5714286 | V4: 20
A5: 10月2-10月11 | B5: 第四阶段 | C5: 69.99 | D5: 0.3 | E5: 0 | F5: 0.25 | G5: 55 | H5: 65 | I5: 30 | J5: =SUM(G5:I5) -> 150 | K5: 10 | L5: =5*I5 -> 150 | M5: =5*G5 -> 275 | N5: =SUM(J5) -> 150 | O5: =SUM(L5:N5) -> 575 | P5: =SUM(L5:O5) -> 1150 | R5: =J5/7 -> 21.428571 | S5: =I5/7 -> 4.2857143 | T5: =H5/7 -> 9.2857143 | V5: 18
A6: 10月12-10月21 | B6: 第五阶段 | C6: 69.99 | D6: 0.3 | E6: 0 | F6: 0.25 | G6: 60 | H6: 70 | I6: 30 | J6: =SUM(G6:I6) -> 160 | K6: 10 | L6: =5*I6 -> 150 | M6: =5*G6 -> 300 | N6: =SUM(J6) -> 160 | O6: =SUM(L6:N6) -> 610 | P6: =SUM(L6:O6) -> 1220 | R6: =J6/7 -> 22.857143 | S6: =I6/7 -> 4.2857143 | T6: =H6/7 -> 10 | V6: 16
A7: 10月22-10月31 | B7: 第六阶段 | C7: 69.99 | D7: 0.3 | E7: 0 | F7: 0 | G7: 65 | H7: 80 | I7: 35 | J7: =SUM(G7:I7) -> 180 | K7: 12 | L7: =5*I7 -> 175 | M7: =5*G7 -> 325 | N7: =SUM(J7) -> 180 | O7: =SUM(L7:N7) -> 680 | P7: =SUM(L7:O7) -> 1360 | R7: =J7/7 -> 25.714286 | S7: =I7/7 -> 5 | T7: =H7/7 -> 11.428571 | V7: 10
A8: 稳定期
A9: 11月1-11月30 | B9: 十一月份 | C9: 69.99 | D9: 0.2 | E9: 0 | F9: 0 | G9: 70 | H9: 85 | I9: 30 | J9: =SUM(G9:I9) -> 185 | K9: 14 | L9: =5*I9 -> 150 | M9: =5*G9 -> 350 | N9: =SUM(J9) -> 185 | O9: =SUM(L9:N9) -> 685 | P9: =SUM(L9:O9) -> 1370 | R9: =J9/7 -> 26.428571 | S9: =I9/7 -> 4.2857143 | T9: =H9/7 -> 12.142857 | V9: 5
A10: 12月1-12月31 | B10: 十二月份 | C10: 69.99 | D10: 0.2 | E10: 0 | F10: 0 | G10: 75 | H10: 90 | I10: 30 | J10: =SUM(G10:I10) -> 195 | K10: 15 | L10: =5*I10 -> 150 | M10: =5*G10 -> 375 | N10: =SUM(J10) -> 195 | O10: =SUM(L10:N10) -> 720 | P10: =SUM(L10:O10) -> 1440 | R10: =J10/7 -> 27.857143 | S10: =I10/7 -> 4.2857143 | T10: =H10/7 -> 12.857143 | V10: 4
A11: 1月1-1月31 | B11: 一月份 | C11: 69.99 | D11: 0.2 | E11: 0 | F11: 0 | G11: 80 | H11: 100 | I11: 30 | J11: =SUM(G11:I11) -> 210 | K11: 16 | L11: =5*I11 -> 150 | M11: =5*G11 -> 400 | N11: =SUM(J11) -> 210 | O11: =SUM(L11:N11) -> 760 | P11: =SUM(L11:O11) -> 1520 | R11: =J11/7 -> 30 | S11: =I11/7 -> 4.2857143 | T11: =H11/7 -> 14.285714 | V11: 3
A12: 2月1-2月28 | B12: 二月份 | C12: 69.99 | D12: 0.2 | E12: 0 | F12: 0 | G12: 80 | H12: 100 | I12: 30 | J12: =SUM(G12:I12) -> 210 | K12: 16 | L12: =5*I12 -> 150 | M12: =5*G12 -> 400 | N12: =SUM(J12) -> 210 | O12: =SUM(L12:N12) -> 760 | P12: =SUM(L12:O12) -> 1520 | R12: =J12/7 -> 30 | S12: =I12/7 -> 4.2857143 | T12: =H12/7 -> 14.285714 | V12: 1
A14: 新品迭代期
A15: 3月1-3月28 | B15: 第一阶段 | C15: 99.99 | D15: 0.05 | E15: 0.5 | F15: 0.68 | G15: 58 | H15: 10 | I15: 20 | J15: =SUM(G15:I15) -> 88 | K15: 6 | L15: =5*I15 -> 100 | M15: =5*G15 -> 290 | N15: =SUM(J15) -> 88 | O15: =SUM(L15:N15) -> 478 | P15: =SUM(L15:O15) -> 956 | R15: =J15/7 -> 12.571429 | S15: =I15/7 -> 2.8571429 | T15: =H15/7 -> 1.4285714 | V15: 50
A16: 4月1-4月28 | B16: 第二阶段 | C16: 79.99 | D16: 0.3 | E16: 0.2 | F16: 0.3 | G16: 81 | H16: 14 | I16: 20 | J16: =SUM(G16:I16) -> 115 | K16: 9 | L16: =5*I16 -> 100 | M16: =5*G16 -> 405 | N16: =SUM(J16) -> 115 | O16: =SUM(L16:N16) -> 620 | P16: =SUM(L16:O16) -> 1240 | R16: =J16/7 -> 16.428571 | S16: =I16/7 -> 2.8571429 | T16: =H16/7 -> 2 | V16: 32
A17: 5月1-5月28 | B17: 第三阶段 | C17: 69.99 | D17: 0.3 | E17: 0.2 | F17: 0.25 | G17: 45 | H17: 60 | I17: 23 | J17: =SUM(G17:I17) -> 128 | K17: 10 | L17: =5*I17 -> 115 | M17: =5*G17 -> 225 | N17: =SUM(J17) -> 128 | O17: =SUM(L17:N17) -> 468 | P17: =SUM(L17:O17) -> 936 | R17: =J17/7 -> 18.285714 | S17: =I17/7 -> 3.2857143 | T17: =H17/7 -> 8.5714286 | V17: 20
A19: 新品迭代期

Sheet 价格策略模拟
A1: 字段 | B1: 价格策略模拟
A2: 阶段 | B2: 定价 | C2: coupon | D2: code | E2: 折后价 | F2: FBA 配送费 | G2: 亚马逊 佣金 | H2: 账号 回款 | I2: 仓储费+入库配置费 | J2: coupon 费用 | K2: 产品成本 | L2: 物流费 | M2: 退货成本(公式后面加的是单套产品的移除费） | N2: 退货率 | O2: 每单平摊 退货成本 | P2: 每单 毛利 | Q2: 毛利率 | R2: 订单 数量 | S2: 阶段 订单 亏损 | T2: 阶段 订单 总盈亏
A3: 第一阶段 | B3: 79.99 | C3: 0.3 | D3: 0 | E3: =SUM(B3*(1-C3-D3)) -> 55.993 | F3: 10.51 | G3: =SUM(E3*8%) -> 4.47944 | H3: =SUM(E3-F3-G3) -> 41.00356 | I3: 0.5 | J3: 0.6 | K3: =80/7 -> 11.428571 | L3: 3 | M3: =SUM(20%*15%*E3+F3+I3+K3+L3+1.04) -> 28.158361 | N3: 0.044 | O3: =SUM(M3*N3/(1-N3)) -> 1.2959915 | P3: =SUM(H3-I3-J3-K3-L3-O3) -> 24.178997 | Q3: =SUM(P3/B3) -> 0.30227525 | R3: 1 | S3: =SUM(P3*R3) -> 24.178997 | T3: =SUM(S3) -> 24.178997
A4: 第二阶段 | B4: 85.99 | C4: 0.2 | D4: 0 | E4: =SUM(B4*(1-C4-D4)) -> 68.792 | F4: 10.51 | G4: =SUM(E4*8%) -> 5.50336 | H4: =SUM(E4-F4-G4) -> 52.77864 | I4: 0.5 | J4: 0.6 | K4: =80/7 -> 11.428571 | L4: 3 | M4: =SUM(20%*15%*E4+F4+I4+K4+L4+1.04) -> 28.542331 | N4: 0.044 | O4: =SUM(M4*N4/(1-N4)) -> 1.3136638 | P4: =SUM(H4-I4-J4-K4-L4-O4) -> 35.936405 | Q4: =SUM(P4/B4) -> 0.41791377 | R4: 1 | S4: =SUM(P4*R4) -> 35.936405 | T4: =SUM(S4) -> 35.936405
A5: 第三阶段 | B5: 89.99 | C5: 0.1 | D5: 0 | E5: =SUM(B5*(1-C5-D5)) -> 80.991 | F5: 10.51 | G5: =SUM(E5*8%) -> 6.47928 | H5: =SUM(E5-F5-G5) -> 64.00172 | I5: 0.5 | J5: 0 | K5: =80/7 -> 11.428571 | L5: 3 | M5: =SUM(20%*15%*E5+F5+I5+K5+L5+1.04) -> 28.908301 | N5: 0.044 | O5: =SUM(M5*N5/(1-N5)) -> 1.3305076 | P5: =SUM(H5-I5-J5-K5-L5-O5) -> 47.742641 | Q5: =SUM(P5/B5) -> 0.53053274 | R5: 1 | S5: =SUM(P5*R5) -> 47.742641 | T5: =SUM(S5) -> 47.742641
A6: 第四阶段 | B6: 89.99 | C6: 0.05 | D6: 0 | E6: =SUM(B6*(1-C6-D6)) -> 85.4905 | F6: 10.51 | G6: =SUM(E6*8%) -> 6.83924 | H6: =SUM(E6-F6-G6) -> 68.14126 | I6: 0.5 | J6: 0 | K6: =80/7 -> 11.428571 | L6: 3 | M6: =SUM(20%*15%*E6+F6+I6+K6+L6+1.04) -> 29.043286 | N6: 0.044 | O6: =SUM(M6*N6/(1-N6)) -> 1.3367203 | P6: =SUM(H6-I6-J6-K6-L6-O6) -> 51.875968 | Q6: =SUM(P6/B6) -> 0.5764637 | R6: 1 | S6: =SUM(P6*R6) -> 51.875968 | T6: =SUM(S6) -> 51.875968
A7: 第五阶段 | B7: 89.59 | C7: 0.05 | D7: 0 | E7: =SUM(B7*(1-C7-D7)) -> 85.1105 | F7: 10.51 | G7: =SUM(E7*8%) -> 6.80884 | H7: =SUM(E7-F7-G7) -> 67.79166 | I7: 0.5 | J7: 0 | K7: =80/7 -> 11.428571 | L7: 3 | M7: =SUM(20%*15%*E7+F7+I7+K7+L7+1.04) -> 29.031886 | N7: 0.044 | O7: =SUM(M7*N7/(1-N7)) -> 1.3361956 | P7: =SUM(H7-I7-J7-K7-L7-O7) -> 51.526893 | Q7: =SUM(P7/B7) -> 0.57514112 | R7: 1 | S7: =SUM(P7*R7) -> 51.526893 | T7: =SUM(S7) -> 51.526893
A8: 第六阶段 | B8: 89.99 | C8: 0.05 | D8: 0 | E8: =SUM(B8*(1-C8-D8)) -> 85.4905 | F8: 10.51 | G8: =SUM(E8*8%) -> 6.83924 | H8: =SUM(E8-F8-G8) -> 68.14126 | I8: 0.5 | J8: 0 | K8: =80/7 -> 11.428571 | L8: 3 | M8: =SUM(20%*15%*E8+F8+I8+K8+L8+1.04) -> 29.043286 | N8: 0.044 | O8: =SUM(M8*N8/(1-N8)) -> 1.3367203 | P8: =SUM(H8-I8-J8-K8-L8-O8) -> 51.875968 | Q8: =SUM(P8/B8) -> 0.5764637 | R8: 1 | S8: =SUM(P8*R8) -> 51.875968 | T8: =SUM(S8) -> 51.875968
A9: 第七阶段 | B9: 89.99 | C9: 0.05 | D9: 0 | E9: =SUM(B9*(1-C9-D9)) -> 85.4905 | F9: 10.51 | G9: =SUM(E9*8%) -> 6.83924 | H9: =SUM(E9-F9-G9) -> 68.14126 | I9: 0.5 | J9: 0 | K9: =80/7 -> 11.428571 | L9: 3 | M9: =SUM(20%*15%*E9+F9+I9+K9+L9+1.04) -> 29.043286 | N9: 0.044 | O9: =SUM(M9*N9/(1-N9)) -> 1.3367203 | P9: =SUM(H9-I9-J9-K9-L9-O9) -> 51.875968 | Q9: =SUM(P9/B9) -> 0.5764637 | R9: 1 | S9: =SUM(P9*R9) -> 51.875968 | T9: =SUM(S9) -> 51.875968
A10: 竞品日常价格 | B10: 79.99 | C10: 0 | D10: 0 | E10: =SUM(B10*(1-C10-D10)) -> 79.99 | F10: 10.51 | G10: =SUM(E10*15%) -> 11.9985 | H10: =SUM(E10-F10-G10) -> 57.4815 | I10: 0.5 | J10: 0 | K10: =80/7 -> 11.428571 | L10: 3 | M10: =SUM(20%*15%*E10+F10+I10+K10+L10+1.46) -> 29.298271 | N10: 0.044 | O10: =SUM(M10*N10/(1-N10)) -> 1.348456 | P10: =SUM(H10-I10-J10-K10-L10-O10) -> 41.204473 | Q10: =SUM(P10/B10) -> 0.5151203 | R10: 1 | S10: =SUM(P10*R10) -> 41.204473 | T10: =SUM(S10) -> 41.204473
A11: 竞品活动价格 | B11: 99.99 | C11: 0.2 | D11: 0 | E11: =SUM(B11*(1-C11-D11)) -> 79.992 | F11: 10.51 | G11: =SUM(E11*15%) -> 11.9988 | H11: =SUM(E11-F11-G11) -> 57.4832 | I11: 0.5 | J11: 0.6 | K11: =80/7 -> 11.428571 | L11: 3 | M11: =SUM(20%*15%*E11+F11+I11+K11+L11+1.46) -> 29.298331 | N11: 0.044 | O11: =SUM(M11*N11/(1-N11)) -> 1.3484588 | P11: =SUM(H11-I11-J11-K11-L11-O11) -> 40.60617 | Q11: =SUM(P11/B11) -> 0.40610231 | R11: 1 | S11: =SUM(P11*R11) -> 40.60617 | T11: =SUM(S11) -> 40.60617
A12: 竞品链接 | B12: 85.99 | C12: 0.2 | D12: 0 | E12: =SUM(B12*(1-C12-D12)) -> 68.792 | F12: 10.51 | G12: =SUM(E12*8%) -> 5.50336 | H12: =SUM(E12-F12-G12) -> 52.77864 | I12: 0.5 | J12: 0.6 | K12: =80/7 -> 11.428571 | L12: 3 | M12: =SUM(20%*15%*E12+F12+I12+K12+L12+1.04) -> 28.542331 | N12: 0.044 | O12: =SUM(M12*N12/(1-N12)) -> 1.3136638 | P12: =SUM(H12-I12-J12-K12-L12-O12) -> 35.936405 | Q12: =SUM(P12/B12) -> 0.41791377 | R12: 1 | S12: =SUM(P12*R12) -> 35.936405 | T12: =SUM(S12) -> 35.936405
A13: 竞品链接所在类目 | B13: https://www.amazon.com/gp/bestsellers/pet-supplies/3024205011
A15: 阶段 | B15: 型号 | C15: 采购成本（手写） | D15: 头程 （手写） | E15: FBA费用 （手写） | F15: 平台佣金（8%） | G15: 退货（2%） | H15: 优惠卷兑（2.5%） | I15: 在库成本 | J15: 展示售价 （手写） | K15: 折扣券 （手写） | L15: 实际售价 （手写） | M15: 毛利（不含人工、测评、推广等） | N15: 毛利率 | O15: 毛利/人民币 | P15: 汇率 | Q15: 备注
A16: 第一阶段 | B16: RD01 | C16: =80/7 -> 11.428571 | D16: 2 | E16: 10.51 | F16: =L16*8% -> 4.4472 | G16: =L16*2% -> 1.1118 | H16: =L16*2.5% -> 1.38975 | I16: =SUM(C16:H16) -> 30.887321 | J16: 79.99 | K16: 0.3 | L16: 55.59 | M16: =L16-I16 -> 24.702679 | N16: =M16/L16 -> 0.4443727 | O16: =M16*P16 -> 175.38902 | P16: 7.1
A17: 第二阶段 | B17: RD02 | C17: =80/7 -> 11.428571 | D17: 2 | E17: 10.51 | F17: =L17*8% -> 5.5032 | G17: =L17*2% -> 1.3758 | H17: =L17*2.5% -> 1.71975 | I17: =SUM(C17:H17) -> 32.537321 | J17: 85.99 | K17: 0.2 | L17: 68.79 | M17: =L17-I17 -> 36.252679 | N17: =M17/L17 -> 0.52700507 | O17: =M17*P17 -> 257.39402 | P17: 7.1
A18: 第三阶段 | B18: RD03 | C18: =80/7 -> 11.428571 | D18: 2 | E18: 10.51 | F18: =L18*8% -> 6.4792 | G18: =L18*2% -> 1.6198 | H18: =L18*2.5% -> 2.02475 | I18: =SUM(C18:H18) -> 34.062321 | J18: 89.99 | K18: 0.1 | L18: 80.99 | M18: =L18-I18 -> 46.927679 | N18: =M18/L18 -> 0.57942559 | O18: =M18*P18 -> 333.18652 | P18: 7.1
A20: 竞品日常价格 | B20: JP01 | C20: 11.43 | D20: 2 | E20: 10.51 | F20: =L20*8% -> 6.3992 | G20: =L20*2% -> 1.5998 | H20: =L20*2.5% -> 1.99975 | I20: =SUM(C20:H20) -> 33.93875 | J20: 77.99 | K20: =J20/L20 -> 0.97499687 | L20: 79.99 | M20: =L20-I20 -> 46.05125 | N20: =M20/L20 -> 0.57571259 | O20: =M20*P20 -> 326.96387 | P20: 7.1
A21: 竞品活动价格 | B21: - | C21: 11.43 | D21: 2 | E21: 10.51 | F21: =L21*8% -> 7.1992 | G21: =L21*2% -> 1.7998 | H21: =L21*2.5% -> 2.24975 | I21: =SUM(C21:H21) -> 35.18875 | J21: 79.99 | K21: =J21/L21 -> 0.88887654 | L21: 89.99 | M21: =L21-I21 -> 54.80125 | N21: =M21/L21 -> 0.60897044 | O21: =M21*P21 -> 389.08887 | P21: 7.1
A22: 竞品链接 | B22: - | C22: 11.43 | D22: 2 | E22: 10.51 | F22: =L22*8% -> 6.3992 | G22: =L22*2% -> 1.5998 | H22: =L22*2.5% -> 1.99975 | I22: =SUM(C22:H22) -> 33.93875 | J22: 77.99 | K22: =J22/L22 -> 0.97499687 | L22: 79.99 | M22: =L22-I22 -> 46.05125 | N22: =M22/L22 -> 0.57571259 | O22: =M22*P22 -> 326.96387 | P22: 7.1

Sheet 总表（阶段盈亏）
A1: 阶段盈亏模拟数据
A2: 阶段 | B2: 日期 | C2: 定价 | D2: cou pon | E2: code | F2: 折后价 | G2: 站内 自然单 | H2: 站内 广告单 | I2: 阶段 销售 订单 | J2: 时间 /天 | K2: CPA | L2: 阶段 广告费 | M2: 毛利 盈亏 | N2: 阶段盈亏 /美金 | O2: 评论 数量 | P2: 阶段 日均 订单 | Q2: 阶段 日均 广告单 | R2: 阶段 日均 自然单 | S2: 日均 广告费 | T2: 新品 排行榜 | U2: 小类目 排名 | V2: 备注 | W2: 种子评论费/（开3条VINE，预计来70条评论）,视觉化费用预估3000美金 | X2: 前期亏损/美金 | Y2: 人民币
A3: 第一阶段 | B3: WEEK1 | C3: 89.99 | D3: 0.3 | E3: 0 | F3: =SUM(C3*(1-D3-E3)) -> 62.993 | G3: =J3*R3 -> 0 | H3: =J3*Q3 -> 21 | I3: 21 | J3: 7 | K3: =CPC表格!V4 -> 23.875 | L3: =SUM(H3*-K3) -> -501.375 | M3: =毛利盈亏!T3 -> 15.180904 | N3: =SUM(L3:M3) -> -486.1941 | O3: 20 | P3: 3 | Q3: 3 | R3: =SUM(P3-Q3) -> 0 | S3: =SUM(L3/J3) -> -71.625 | T3: 150 | U3: 前300名 | V3: 一开售投放广告 | W3: 3000 | X3: =SUM(N3:N10)+W3 -> -2124.3253 | Y3: =X3*7 -> -14870.277
B4: WEEK2 | C4: 89.99 | D4: 0.3 | E4: 0 | F4: =SUM(C4*(1-D4-E4)) -> 62.993 | G4: =J4*R4 -> 14 | H4: =J4*Q4 -> 35 | I4: =SUM(G4:H4) -> 49 | J4: 7 | K4: =CPC表格!V5 -> 23.875 | L4: =SUM(H4*-K4) -> -835.625 | M4: =毛利盈亏!T4 -> 35.42211 | N4: =SUM(L4:M4) -> -800.20289 | O4: 25 | P4: 7 | Q4: 5 | R4: =SUM(P4-Q4) -> 2 | S4: =SUM(L4/J4) -> -119.375 | T4: 120 | U4: 前300名 | V4: 一开售投放广告 | W4: 0 | X4: =SUM(N4:N11)+W4 -> -3501.0567 | Y4: =X4*7 -> -24507.397
B5: WEEK3 | C5: 89.99 | D5: 0.3 | E5: 0 | F5: =SUM(C5*(1-D5-E5)) -> 62.993 | G5: =J5*R5 -> 28 | H5: =J5*Q5 -> 42 | I5: =SUM(G5:H5) -> 70 | J5: 7 | K5: =CPC表格!V6 -> 23.875 | L5: =SUM(H5*-K5) -> -1002.75 | M5: =毛利盈亏!T5 -> 50.603015 | N5: =SUM(L5:M5) -> -952.14699 | O5: 30 | P5: 10 | Q5: 6 | R5: =SUM(P5-Q5) -> 4 | S5: =SUM(L5/J5) -> -143.25 | T5: 100 | U5: 前250名 | W5: 0 | X5: =SUM(N5:N12)+W5 -> -378.16219 | Y5: =X5*7 -> -2647.1354
B6: WEEK4 | C6: 89.99 | D6: 0.3 | E6: 0 | F6: =SUM(C6*(1-D6-E6)) -> 62.993 | G6: =J6*R6 -> 35 | H6: =J6*Q6 -> 49 | I6: =SUM(G6:H6) -> 84 | J6: 7 | K6: =CPC表格!V7 -> 23.875 | L6: =SUM(H6*-K6) -> -1169.875 | M6: =毛利盈亏!T6 -> 60.723618 | N6: =SUM(L6:M6) -> -1109.1514 | O6: 35 | P6: 12 | Q6: 7 | R6: =SUM(P6-Q6) -> 5 | S6: =SUM(L6/J6) -> -167.125 | T6: 50 | U6: 前250名 | W6: 0 | X6: =SUM(N6:N13)+W6 -> 2051.1221 | Y6: =X6*7 -> 14357.855
A7: 第二阶段 | B7: WEEK5 | C7: 85.99 | D7: 0.2 | E7: 0 | F7: =SUM(C7*(1-D7-E7)) -> 68.792 | G7: =J7*R7 -> 42 | H7: =J7*Q7 -> 63 | I7: =SUM(G7:H7) -> 105 | J7: 7 | K7: =CPC表格!V8 -> 22 | L7: =SUM(H7*-K7) -> -1386 | M7: =毛利盈亏!T7 -> 943.90326 | N7: =SUM(L7:M7) -> -442.09674 | O7: 40 | P7: 15 | Q7: 9 | R7: =SUM(P7-Q7) -> 6 | S7: =SUM(L7/J7) -> -198 | T7: 40 | U7: 前200名 | W7: 0 | X7: =SUM(N7:N14)+W7 -> 7272.5494 | Y7: =X7*7 -> 50907.846
B8: WEEK6 | C8: 85.99 | D8: 0.2 | E8: 0 | F8: =SUM(C8*(1-D8-E8)) -> 68.792 | G8: =J8*R8 -> 56 | H8: =J8*Q8 -> 70 | I8: =SUM(G8:H8) -> 126 | J8: 7 | K8: =CPC表格!V9 -> 22 | L8: =SUM(H8*-K8) -> -1540 | M8: =毛利盈亏!T8 -> 1132.6839 | N8: =SUM(L8:M8) -> -407.31609 | O8: 50 | P8: 18 | Q8: 10 | R8: =SUM(P8-Q8) -> 8 | S8: =SUM(L8/J8) -> -220 | T8: 30 | U8: 前200名 | W8: 0 | X8: =SUM(N8:N15)+W8 -> 9788.6789 | Y8: =X8*7 -> 68520.752
B9: WEEK7 | C9: 85.99 | D9: 0.2 | E9: 0 | F9: =SUM(C9*(1-D9-E9)) -> 68.792 | G9: =J9*R9 -> 56 | H9: =J9*Q9 -> 84 | I9: =SUM(G9:H9) -> 140 | J9: 7 | K9: =CPC表格!V10 -> 22 | L9: =SUM(H9*-K9) -> -1848 | M9: =毛利盈亏!T9 -> 1258.5377 | N9: =SUM(L9:M9) -> -589.46233 | O9: 60 | P9: 20 | Q9: 12 | R9: =SUM(P9-Q9) -> 8 | S9: =SUM(L9/J9) -> -264 | T9: 20 | U9: 前150名 | W9: 0 | X9: =SUM(N9:N16)+W9 -> 12566.341 | Y9: =X9*7 -> 87964.384
B10: WEEK8 | C10: 85.99 | D10: 0.2 | E10: 0 | F10: =SUM(C10*(1-D10-E10)) -> 68.792 | G10: =J10*R10 -> 84 | H10: =J10*Q10 -> 84 | I10: =SUM(G10:H10) -> 168 | J10: 7 | K10: =CPC表格!V11 -> 22 | L10: =SUM(H10*-K10) -> -1848 | M10: =毛利盈亏!T10 -> 1510.2452 | N10: =SUM(L10:M10) -> -337.75479 | O10: 70 | P10: 24 | Q10: 12 | R10: =SUM(P10-Q10) -> 12 | S10: =SUM(L10/J10) -> -264 | T10: 10 | U10: 前150名 | W10: 0 | X10: =SUM(N10:N17)+W10 -> 15822.462 | Y10: =X10*7 -> 110757.23
A11: 第三阶段 | B11: WEEK9 | C11: 85.99 | D11: 0.1 | E11: 0 | F11: =SUM(C11*(1-D11-E11)) -> 77.391 | G11: =J11*R11 -> 84 | H11: =J11*Q11 -> 98 | I11: =SUM(G11:H11) -> 182 | J11: 7 | K11: =CPC表格!V12 -> 20.444444 | L11: =SUM(H11*-K11) -> -2003.5556 | M11: =毛利盈亏!T11 -> 3140.6301 | N11: =SUM(L11:M11) -> 1137.0746 | O11: 80 | P11: 26 | Q11: 14 | R11: =SUM(P11-Q11) -> 12 | S11: =SUM(L11/J11) -> -286.22222 | T11: 10 | U11: 前100名 | W11: 0 | X11: =SUM(N11:N34)+W11 -> 53300.888 | Y11: =X11*7 -> 373106.22
B12: WEEK10 | C12: 85.99 | D12: 0.1 | E12: 0 | F12: =SUM(C12*(1-D12-E12)) -> 77.391 | G12: =J12*R12 -> 154 | H12: =J12*Q12 -> 105 | I12: =SUM(G12:H12) -> 259 | J12: 7 | K12: =CPC表格!V13 -> 20.444444 | L12: =SUM(H12*-K12) -> -2146.6667 | M12: =毛利盈亏!T12 -> 4469.3582 | N12: =SUM(L12:M12) -> 2322.6916 | O12: 90 | P12: 28 | Q12: 15 | R12: 22 | S12: =SUM(L12/J12) -> -306.66667 | T12: 5 | U12: 前100名 | W12: 0 | X12: =SUM(N12:N35)+W12 -> 51574.352 | Y12: =X12*7 -> 361020.46
B13: WEEK11 | C13: 85.99 | D13: 0.1 | E13: 0 | F13: =SUM(C13*(1-D13-E13)) -> 77.391 | G13: =J13*R13 -> 105 | H13: =J13*Q13 -> 105 | I13: =SUM(G13:H13) -> 210 | J13: 7 | K13: =CPC表格!V14 -> 20.444444 | L13: =SUM(H13*-K13) -> -2146.6667 | M13: =毛利盈亏!T13 -> 3623.804 | N13: =SUM(L13:M13) -> 1477.1373 | O13: 100 | P13: 30 | Q13: 15 | R13: =P13-Q13 -> 15 | S13: =SUM(L13/J13) -> -306.66667 | T13: 5 | U13: 前80名 | W13: 0 | X13: =SUM(N13:N36)+W13 -> 48913.905 | Y13: =X13*7 -> 342397.34
B14: WEEK12 | C14: 85.99 | D14: 0.1 | E14: 0 | F14: =SUM(C14*(1-D14-E14)) -> 77.391 | G14: =J14*R14 -> 259 | H14: =J14*Q14 -> 112 | I14: =SUM(G14:H14) -> 371 | J14: 7 | K14: =CPC表格!V15 -> 20.444444 | L14: =SUM(H14*-K14) -> -2289.7778 | M14: =毛利盈亏!T14 -> 6402.0537 | N14: =SUM(L14:M14) -> 4112.2759 | O14: 110 | P14: 35 | Q14: 16 | R14: 37 | S14: =SUM(L14/J14) -> -327.11111 | T14: 4 | U14: 前80名 | W14: 0 | X14: =SUM(N14:N37)+W14 -> 48573.842 | Y14: =X14*7 -> 340016.9
A15: 第四阶段 | B15: WEEK13 | C15: 79.99 | D15: 0 | E15: 0 | F15: =SUM(C15*(1-D15-E15)) -> 79.99 | G15: =J15*R15 -> 154 | H15: =J15*Q15 -> 126 | I15: =SUM(G15:H15) -> 280 | J15: 7 | K15: =CPC表格!V16 -> 21.176471 | L15: =SUM(H15*-K15) -> -2668.2353 | M15: =毛利盈亏!T15 -> 4742.268 | N15: =SUM(L15:M15) -> 2074.0327 | O15: 120 | P15: 40 | Q15: 18 | R15: =SUM(P15-Q15) -> 22 | S15: =SUM(L15/J15) -> -381.17647 | T15: 4 | U15: 前50名 | W15: 0 | X15: =SUM(N15:N38)+W15 -> 46784.258 | Y15: =X15*7 -> 327489.81
B16: WEEK14 | C16: 79.99 | D16: 0 | E16: 0 | F16: =SUM(C16*(1-D16-E16)) -> 79.99 | G16: =J16*R16 -> 175 | H16: =J16*Q16 -> 140 | I16: =SUM(G16:H16) -> 315 | J16: 7 | K16: =CPC表格!V17 -> 21.176471 | L16: =SUM(H16*-K16) -> -2964.7059 | M16: =毛利盈亏!T16 -> 5335.0515 | N16: =SUM(L16:M16) -> 2370.3457 | O16: 130 | P16: 45 | Q16: 20 | R16: =SUM(P16-Q16) -> 25 | S16: =SUM(L16/J16) -> -423.52941 | T16: 3 | U16: 前50名 | W16: 0 | X16: =SUM(N16:N39)+W16 -> 46187.363 | Y16: =X16*7 -> 323311.54
B17: WEEK15 | C17: 79.99 | D17: 0 | E17: 0 | F17: =SUM(C17*(1-D17-E17)) -> 79.99 | G17: =J17*R17 -> 196 | H17: =J17*Q17 -> 154 | I17: =SUM(G17:H17) -> 350 | J17: 7 | K17: =CPC表格!V18 -> 21.176471 | L17: =SUM(H17*-K17) -> -3261.1765 | M17: =毛利盈亏!T17 -> 5927.835 | N17: =SUM(L17:M17) -> 2666.6586 | O17: 140 | P17: 50 | Q17: 22 | R17: =SUM(P17-Q17) -> 28 | S17: =SUM(L17/J17) -> -465.88235 | T17: 3 | U17: 前20名 | W17: 0 | X17: =SUM(N17:N40)+W17 -> 47929.293 | Y17: =X17*7 -> 335505.05
B18: WEEK16 | C18: 79.99 | D18: 0 | E18: 0 | F18: =SUM(C18*(1-D18-E18)) -> 79.99 | G18: =J18*R18 -> 315 | H18: =J18*Q18 -> 175 | I18: =SUM(G18:H18) -> 490 | J18: 7 | K18: =CPC表格!V19 -> 21.176471 | L18: =SUM(H18*-K18) -> -3705.8824 | M18: =毛利盈亏!T18 -> 8298.9691 | N18: =SUM(L18:M18) -> 4593.0867 | O18: 150 | P18: 70 | Q18: 25 | R18: =SUM(P18-Q18) -> 45 | S18: =SUM(L18/J18) -> -529.41176 | T18: 2 | U18: 前20名 | W18: 0 | X18: =SUM(N18:N41)+W18 -> 47336.667 | Y18: =X18*7 -> 331356.67
A19: 第五阶段 | B19: WEEK17 | C19: 79.99 | D19: 0 | E19: 0 | F19: =SUM(C19*(1-D19-E19)) -> 79.99 | G19: =J19*R19 -> 315 | H19: =J19*Q19 -> 175 | I19: =SUM(G19:H19) -> 490 | J19: 7 | K19: =CPC表格!V20 -> 21.176471 | L19: =SUM(H19*-K19) -> -3705.8824 | M19: =毛利盈亏!T19 -> 8298.9691 | N19: =SUM(L19:M19) -> 4593.0867 | O19: 160 | P19: 70 | Q19: 25 | R19: =SUM(P19-Q19) -> 45 | S19: =SUM(L19/J19) -> -529.41176 | T19: 2 | U19: 前20名 | W19: 0 | X19: =SUM(N19:N42)+W19 -> 45113.926 | Y19: =X19*7 -> 315797.48
B20: WEEK18 | C20: 79.99 | D20: 0 | E20: 0 | F20: =SUM(C20*(1-D20-E20)) -> 79.99 | G20: =J20*R20 -> 315 | H20: =J20*Q20 -> 175 | I20: =SUM(G20:H20) -> 490 | J20: 7 | K20: =CPC表格!V21 -> 21.176471 | L20: =SUM(H20*-K20) -> -3705.8824 | M20: =毛利盈亏!T20 -> 8298.9691 | N20: =SUM(L20:M20) -> 4593.0867 | O20: 170 | P20: 70 | Q20: 25 | R20: =SUM(P20-Q20) -> 45 | S20: =SUM(L20/J20) -> -529.41176 | T20: 2 | U20: 前20名 | W20: 0 | X20: =SUM(N20:N43)+W20 -> 43187.498 | Y20: =X20*7 -> 302312.49
B21: WEEK19 | C21: 79.99 | D21: 0 | E21: 0 | F21: =SUM(C21*(1-D21-E21)) -> 79.99 | G21: =J21*R21 -> 315 | H21: =J21*Q21 -> 175 | I21: =SUM(G21:H21) -> 490 | J21: 7 | K21: =CPC表格!V22 -> 21.176471 | L21: =SUM(H21*-K21) -> -3705.8824 | M21: =毛利盈亏!T21 -> 8298.9691 | N21: =SUM(L21:M21) -> 4593.0867 | O21: 180 | P21: 70 | Q21: 25 | R21: =SUM(P21-Q21) -> 45 | S21: =SUM(L21/J21) -> -529.41176 | T21: 1 | U21: 前20名 | W21: 0 | X21: =SUM(N21:N44)+W21 -> 43187.498 | Y21: =X21*7 -> 302312.49
B22: WEEK20 | C22: 79.99 | D22: 0 | E22: 0 | F22: =SUM(C22*(1-D22-E22)) -> 79.99 | G22: =J22*R22 -> 315 | H22: =J22*Q22 -> 175 | I22: =SUM(G22:H22) -> 490 | J22: 7 | K22: =CPC表格!V23 -> 21.176471 | L22: =SUM(H22*-K22) -> -3705.8824 | M22: =毛利盈亏!T22 -> 8298.9691 | N22: =SUM(L22:M22) -> 4593.0867 | O22: 190 | P22: 70 | Q22: 25 | R22: =SUM(P22-Q22) -> 45 | S22: =SUM(L22/J22) -> -529.41176 | T22: 1 | U22: 前20名 | W22: 0 | X22: =SUM(N22:N45)+W22 -> 43187.498 | Y22: =X22*7 -> 302312.49
A23: 第六阶段 | B23: WEEK21 | C23: 79.99 | D23: 0 | E23: 0 | F23: =SUM(C23*(1-D23-E23)) -> 79.99 | G23: =J23*R23 -> 315 | H23: =J23*Q23 -> 175 | I23: =SUM(G23:H23) -> 490 | J23: 7 | K23: =CPC表格!V24 -> 21.176471 | L23: =SUM(H23*-K23) -> -3705.8824 | M23: =毛利盈亏!T23 -> 8298.9691 | N23: =SUM(L23:M23) -> 4593.0867 | O23: 200 | P23: 70 | Q23: 25 | R23: =SUM(P23-Q23) -> 45 | S23: =SUM(L23/J23) -> -529.41176 | T23: 1 | U23: 前10名 | W23: 0 | X23: =SUM(N23:N46)+W23 -> 43187.498 | Y23: =X23*7 -> 302312.49
B24: WEEK22 | C24: 79.99 | D24: 0 | E24: 0 | F24: =SUM(C24*(1-D24-E24)) -> 79.99 | G24: =J24*R24 -> 315 | H24: =J24*Q24 -> 175 | I24: =SUM(G24:H24) -> 490 | J24: 7 | K24: =CPC表格!V25 -> 21.176471 | L24: =SUM(H24*-K24) -> -3705.8824 | M24: =毛利盈亏!T24 -> 8298.9691 | N24: =SUM(L24:M24) -> 4593.0867 | O24: 220 | P24: 70 | Q24: 25 | R24: =SUM(P24-Q24) -> 45 | S24: =SUM(L24/J24) -> -529.41176 | T24: 1 | U24: 前10名 | W24: 0 | X24: =SUM(N24:N47)+W24 -> 43187.498 | Y24: =X24*7 -> 302312.49
B25: WEEK23 | C25: 79.99 | D25: 0 | E25: 0 | F25: =SUM(C25*(1-D25-E25)) -> 79.99 | G25: =J25*R25 -> 315 | H25: =J25*Q25 -> 175 | I25: =SUM(G25:H25) -> 490 | J25: 7 | K25: =CPC表格!V26 -> 21.176471 | L25: =SUM(H25*-K25) -> -3705.8824 | M25: =毛利盈亏!T25 -> 8298.9691 | N25: =SUM(L25:M25) -> 4593.0867 | O25: 240 | P25: 70 | Q25: 25 | R25: =SUM(P25-Q25) -> 45 | S25: =SUM(L25/J25) -> -529.41176 | T25: 1 | U25: 前10名 | W25: 0 | X25: =SUM(N25:N48)+W25 -> 43187.498 | Y25: =X25*7 -> 302312.49
B26: WEEK24 | C26: 79.99 | D26: 0 | E26: 0 | F26: =SUM(C26*(1-D26-E26)) -> 79.99 | G26: =J26*R26 -> 315 | H26: =J26*Q26 -> 175 | I26: =SUM(G26:H26) -> 490 | J26: 7 | K26: =CPC表格!V27 -> 21.176471 | L26: =SUM(H26*-K26) -> -3705.8824 | M26: =毛利盈亏!T26 -> 8298.9691 | N26: =SUM(L26:M26) -> 4593.0867 | O26: 260 | P26: 70 | Q26: 25 | R26: =SUM(P26-Q26) -> 45 | S26: =SUM(L26/J26) -> -529.41176 | T26: 1 | U26: 前5名 | W26: 0 | X26: =SUM(N26:N49)+W26 -> 43187.498 | Y26: =X26*7 -> 302312.49
A28: 阶段盈亏真实数据
A29: 第一阶段 | B29: 第1周 | C29: 89.99 | D29: 0.3 | E29: 0 | F29: 62.993 | G29: 0 | H29: 21 | I29: 21 | J29: 7 | K29: 23.875 | L29: -501.375 | M29: 15.180904 | N29: -486.1941 | O29: 20 | P29: 3 | Q29: 3 | R29: 0 | S29: -71.625 | T29: 150 | U29: 前300名 | V29: 一开售投放广告 | W29: 3000 | X29: -2124.3253 | Y29: -14870.277
B30: 第2周 | C30: 89.99 | D30: 0.3 | E30: 0 | F30: 62.993 | G30: 14 | H30: 35 | I30: 49 | J30: 7 | K30: 23.875 | L30: -835.625 | M30: 35.42211 | N30: -800.20289 | O30: 25 | P30: 7 | Q30: 5 | R30: 2 | S30: -119.375 | T30: 120 | U30: 前300名 | V30: 一开售投放广告 | W30: 0 | X30: -3501.0567 | Y30: -24507.397
B31: 第3周 | C31: 89.99 | D31: 0.3 | E31: 0 | F31: 62.993 | G31: 28 | H31: 42 | I31: 70 | J31: 7 | K31: 23.875 | L31: -1002.75 | M31: 50.603015 | N31: -952.14699 | O31: 30 | P31: 10 | Q31: 6 | R31: 4 | S31: -143.25 | T31: 100 | U31: 前250名 | W31: 0 | X31: -378.16219 | Y31: -2647.1354
B32: 第4周 | C32: 89.99 | D32: 0.3 | E32: 0 | F32: 62.993 | G32: 35 | H32: 49 | I32: 84 | J32: 7 | K32: 23.875 | L32: -1169.875 | M32: 60.723618 | N32: -1109.1514 | O32: 35 | P32: 12 | Q32: 7 | R32: 5 | S32: -167.125 | T32: 50 | U32: 前250名 | W32: 0 | X32: 2051.1221 | Y32: 14357.855
A33: 第二阶段 | B33: 第5周 | C33: 85.99 | D33: 0.2 | E33: 0 | F33: 68.792 | G33: 42 | H33: 63 | I33: 105 | J33: 7 | K33: 22 | L33: -1386 | M33: 943.90326 | N33: -442.09674 | O33: 40 | P33: 15 | Q33: 9 | R33: 6 | S33: -198 | T33: 40 | U33: 前200名 | W33: 0 | X33: 7272.5494 | Y33: 50907.846
B34: 第6周 | C34: 85.99 | D34: 0.2 | E34: 0 | F34: 68.792 | G34: 56 | H34: 70 | I34: 126 | J34: 7 | K34: 22 | L34: -1540 | M34: 1132.6839 | N34: -407.31609 | O34: 50 | P34: 18 | Q34: 10 | R34: 8 | S34: -220 | T34: 30 | U34: 前200名 | W34: 0 | X34: 9788.6789 | Y34: 68520.752
B35: 第7周 | C35: 85.99 | D35: 0.2 | E35: 0 | F35: 68.792 | G35: 56 | H35: 84 | I35: 140 | J35: 7 | K35: 22 | L35: -1848 | M35: 1258.5377 | N35: -589.46233 | O35: 60 | P35: 20 | Q35: 12 | R35: 8 | S35: -264 | T35: 20 | U35: 前150名 | W35: 0 | X35: 12566.341 | Y35: 87964.384
B36: 第8周 | C36: 85.99 | D36: 0.2 | E36: 0 | F36: 68.792 | G36: 84 | H36: 84 | I36: 168 | J36: 7 | K36: 22 | L36: -1848 | M36: 1510.2452 | N36: -337.75479 | O36: 70 | P36: 24 | Q36: 12 | R36: 12 | S36: -264 | T36: 10 | U36: 前150名 | W36: 0 | X36: 15822.462 | Y36: 110757.23
A37: 第三阶段 | B37: 第9周 | C37: 85.99 | D37: 0.1 | E37: 0 | F37: 77.391 | G37: 84 | H37: 98 | I37: 182 | J37: 7 | K37: 20.444444 | L37: -2003.5556 | M37: 3140.6301 | N37: 1137.0746 | O37: 80 | P37: 26 | Q37: 14 | R37: 12 | S37: -286.22222 | T37: 10 | U37: 前100名 | W37: 0 | X37: 57497.997 | Y37: 402485.98
B38: 第10周 | C38: 85.99 | D38: 0.1 | E38: 0 | F38: 77.391 | G38: 154 | H38: 105 | I38: 259 | J38: 7 | K38: 20.444444 | L38: -2146.6667 | M38: 4469.3582 | N38: 2322.6916 | O38: 90 | P38: 28 | Q38: 15 | R38: 22 | S38: -306.66667 | T38: 5 | U38: 前100名 | W38: 0 | X38: 56360.922 | Y38: 394526.45
B39: 第11周 | C39: 85.99 | D39: 0.1 | E39: 0 | F39: 77.391 | G39: 105 | H39: 105 | I39: 210 | J39: 7 | K39: 20.444444 | L39: -2146.6667 | M39: 3623.804 | N39: 1477.1373 | O39: 100 | P39: 30 | Q39: 15 | R39: 15 | S39: -306.66667 | T39: 5 | U39: 前80名 | W39: 0 | X39: 54038.231 | Y39: 378267.61
B40: 第12周 | C40: 85.99 | D40: 0.1 | E40: 0 | F40: 77.391 | G40: 259 | H40: 112 | I40: 371 | J40: 7 | K40: 20.444444 | L40: -2289.7778 | M40: 6402.0537 | N40: 4112.2759 | O40: 110 | P40: 35 | Q40: 16 | R40: 37 | S40: -327.11111 | T40: 4 | U40: 前80名 | W40: 0 | X40: 52561.093 | Y40: 367927.65
A41: 第四阶段 | B41: 第13周 | C41: 79.99 | D41: 0 | E41: 0 | F41: 79.99 | G41: 154 | H41: 126 | I41: 280 | J41: 7 | K41: 21.176471 | L41: -2668.2353 | M41: 4742.268 | N41: 2074.0327 | O41: 120 | P41: 40 | Q41: 18 | R41: 22 | S41: -381.17647 | T41: 4 | U41: 前50名 | W41: 0 | X41: 48448.817 | Y41: 339141.72
...

Sheet 毛利盈亏
A1: 每日盈亏数据预估
A2: 阶段 | B2: 日期 | C2: 定价 | D2: coupon | E2: code | F2: 折后价 | G2: FBA 配送费 | H2: 亚马逊 佣金 | I2: 账号 回款 | J2: 仓储费+入库配置费 | K2: coupon 费用 | L2: 产品 成本 | M2: 物流费 | N2: 退货成本(公式后面加的是单套产品的移除费） | O2: 退货率 | P2: 每单平摊 退货成本 | Q2: 每单 毛利 | R2: 毛利率 | S2: 订单 数量 | T2: 阶段 订单 亏损 | U2: 阶段 订单 总盈亏
A3: 第一阶段 | B3: week01 | C3: 89.99 | D3: 0.3 | E3: 0 | F3: =SUM(C3*(1-D3-E3)) -> 62.993 | G3: 10.51 | H3: =SUM(F3*8%) -> 5.03944 | I3: =SUM(F3-G3-H3) -> 47.44356 | J3: 0.5 | K3: 0.6 | L3: 40 | M3: 3 | N3: =SUM(20%*15%*F3+G3+J3+L3+M3+1.04) -> 56.93979 | O3: 0.044 | P3: =SUM(N3*O3/(1-O3)) -> 2.6206598 | Q3: =SUM(I3-J3-K3-L3-M3-P3) -> 0.72290021 | R3: =SUM(Q3/C3) -> 0.0080331171 | S3: ='总表（阶段盈亏）'!I3 -> 21 | T3: =SUM(Q3*S3) -> 15.180904 | U3: =SUM(T3) -> 15.180904
B4: week02 | C4: 89.99 | D4: 0.3 | E4: 0 | F4: =SUM(C4*(1-D4-E4)) -> 62.993 | G4: 10.51 | H4: =SUM(F4*8%) -> 5.03944 | I4: =SUM(F4-G4-H4) -> 47.44356 | J4: 0.5 | K4: 0.6 | L4: 40 | M4: 3 | N4: =SUM(20%*15%*F4+G4+J4+L4+M4+1.04) -> 56.93979 | O4: 0.044 | P4: =SUM(N4*O4/(1-O4)) -> 2.6206598 | Q4: =SUM(I4-J4-K4-L4-M4-P4) -> 0.72290021 | R4: =SUM(Q4/C4) -> 0.0080331171 | S4: ='总表（阶段盈亏）'!I4 -> 49 | T4: =SUM(Q4*S4) -> 35.42211 | U4: =SUM(T4) -> 35.42211
B5: week03 | C5: 89.99 | D5: 0.3 | E5: 0 | F5: =SUM(C5*(1-D5-E5)) -> 62.993 | G5: 10.51 | H5: =SUM(F5*8%) -> 5.03944 | I5: =SUM(F5-G5-H5) -> 47.44356 | J5: 0.5 | K5: 0.6 | L5: 40 | M5: 3 | N5: =SUM(20%*15%*F5+G5+J5+L5+M5+1.04) -> 56.93979 | O5: 0.044 | P5: =SUM(N5*O5/(1-O5)) -> 2.6206598 | Q5: =SUM(I5-J5-K5-L5-M5-P5) -> 0.72290021 | R5: =SUM(Q5/C5) -> 0.0080331171 | S5: ='总表（阶段盈亏）'!I5 -> 70 | T5: =SUM(Q5*S5) -> 50.603015 | U5: =SUM(T5) -> 50.603015
B6: week04 | C6: 89.99 | D6: 0.3 | E6: 0 | F6: =SUM(C6*(1-D6-E6)) -> 62.993 | G6: 10.51 | H6: =SUM(F6*8%) -> 5.03944 | I6: =SUM(F6-G6-H6) -> 47.44356 | J6: 0.5 | K6: 0.6 | L6: 40 | M6: 3 | N6: =SUM(20%*15%*F6+G6+J6+L6+M6+1.04) -> 56.93979 | O6: 0.044 | P6: =SUM(N6*O6/(1-O6)) -> 2.6206598 | Q6: =SUM(I6-J6-K6-L6-M6-P6) -> 0.72290021 | R6: =SUM(Q6/C6) -> 0.0080331171 | S6: ='总表（阶段盈亏）'!I6 -> 84 | T6: =SUM(Q6*S6) -> 60.723618 | U6: =SUM(T6) -> 60.723618
A7: 第二阶段 | B7: week05 | C7: 89.99 | D7: 0.2 | E7: 0 | F7: =SUM(C7*(1-D7-E7)) -> 71.992 | G7: 10.51 | H7: =SUM(F7*8%) -> 5.75936 | I7: =SUM(F7-G7-H7) -> 55.72264 | J7: 0.5 | K7: 0.6 | L7: 40 | M7: 3 | N7: =SUM(20%*15%*F7+G7+J7+L7+M7+1.04) -> 57.20976 | O7: 0.044 | P7: =SUM(N7*O7/(1-O7)) -> 2.6330852 | Q7: =SUM(I7-J7-K7-L7-M7-P7) -> 8.9895548 | R7: =SUM(Q7/C7) -> 0.099895042 | S7: ='总表（阶段盈亏）'!I7 -> 105 | T7: =SUM(Q7*S7) -> 943.90326 | U7: =SUM(T7) -> 943.90326
B8: week06 | C8: 89.99 | D8: 0.2 | E8: 0 | F8: =SUM(C8*(1-D8-E8)) -> 71.992 | G8: 10.51 | H8: =SUM(F8*8%) -> 5.75936 | I8: =SUM(F8-G8-H8) -> 55.72264 | J8: 0.5 | K8: 0.6 | L8: 40 | M8: 3 | N8: =SUM(20%*15%*F8+G8+J8+L8+M8+1.04) -> 57.20976 | O8: 0.044 | P8: =SUM(N8*O8/(1-O8)) -> 2.6330852 | Q8: =SUM(I8-J8-K8-L8-M8-P8) -> 8.9895548 | R8: =SUM(Q8/C8) -> 0.099895042 | S8: ='总表（阶段盈亏）'!I8 -> 126 | T8: =SUM(Q8*S8) -> 1132.6839 | U8: =SUM(T8) -> 1132.6839
B9: week07 | C9: 89.99 | D9: 0.2 | E9: 0 | F9: =SUM(C9*(1-D9-E9)) -> 71.992 | G9: 10.51 | H9: =SUM(F9*8%) -> 5.75936 | I9: =SUM(F9-G9-H9) -> 55.72264 | J9: 0.5 | K9: 0.6 | L9: 40 | M9: 3 | N9: =SUM(20%*15%*F9+G9+J9+L9+M9+1.04) -> 57.20976 | O9: 0.044 | P9: =SUM(N9*O9/(1-O9)) -> 2.6330852 | Q9: =SUM(I9-J9-K9-L9-M9-P9) -> 8.9895548 | R9: =SUM(Q9/C9) -> 0.099895042 | S9: ='总表（阶段盈亏）'!I9 -> 140 | T9: =SUM(Q9*S9) -> 1258.5377 | U9: =SUM(T9) -> 1258.5377
B10: week08 | C10: 89.99 | D10: 0.2 | E10: 0 | F10: =SUM(C10*(1-D10-E10)) -> 71.992 | G10: 10.51 | H10: =SUM(F10*8%) -> 5.75936 | I10: =SUM(F10-G10-H10) -> 55.72264 | J10: 0.5 | K10: 0.6 | L10: 40 | M10: 3 | N10: =SUM(20%*15%*F10+G10+J10+L10+M10+1.04) -> 57.20976 | O10: 0.044 | P10: =SUM(N10*O10/(1-O10)) -> 2.6330852 | Q10: =SUM(I10-J10-K10-L10-M10-P10) -> 8.9895548 | R10: =SUM(Q10/C10) -> 0.099895042 | S10: ='总表（阶段盈亏）'!I10 -> 168 | T10: =SUM(Q10*S10) -> 1510.2452 | U10: =SUM(T10) -> 1510.2452
A11: 第三阶段 | B11: week09 | C11: 89.99 | D11: 0.1 | E11: 0 | F11: =SUM(C11*(1-D11-E11)) -> 80.991 | G11: 10.51 | H11: =SUM(F11*8%) -> 6.47928 | I11: =SUM(F11-G11-H11) -> 64.00172 | J11: 0.5 | K11: 0.6 | L11: 40 | M11: 3 | N11: =SUM(20%*15%*F11+G11+J11+L11+M11+1.04) -> 57.47973 | O11: 0.044 | P11: =SUM(N11*O11/(1-O11)) -> 2.6455106 | Q11: =SUM(I11-J11-K11-L11-M11-P11) -> 17.256209 | R11: =SUM(Q11/C11) -> 0.19175697 | S11: ='总表（阶段盈亏）'!I11 -> 182 | T11: =SUM(Q11*S11) -> 3140.6301 | U11: =SUM(T11) -> 3140.6301
B12: week10 | C12: 89.99 | D12: 0.1 | E12: 0 | F12: =SUM(C12*(1-D12-E12)) -> 80.991 | G12: 10.51 | H12: =SUM(F12*8%) -> 6.47928 | I12: =SUM(F12-G12-H12) -> 64.00172 | J12: 0.5 | K12: 0.6 | L12: 40 | M12: 3 | N12: =SUM(20%*15%*F12+G12+J12+L12+M12+1.04) -> 57.47973 | O12: 0.044 | P12: =SUM(N12*O12/(1-O12)) -> 2.6455106 | Q12: =SUM(I12-J12-K12-L12-M12-P12) -> 17.256209 | R12: =SUM(Q12/C12) -> 0.19175697 | S12: ='总表（阶段盈亏）'!I12 -> 259 | T12: =SUM(Q12*S12) -> 4469.3582 | U12: =SUM(T12) -> 4469.3582
B13: week11 | C13: 89.99 | D13: 0.1 | E13: 0 | F13: =SUM(C13*(1-D13-E13)) -> 80.991 | G13: 10.51 | H13: =SUM(F13*8%) -> 6.47928 | I13: =SUM(F13-G13-H13) -> 64.00172 | J13: 0.5 | K13: 0.6 | L13: 40 | M13: 3 | N13: =SUM(20%*15%*F13+G13+J13+L13+M13+1.04) -> 57.47973 | O13: 0.044 | P13: =SUM(N13*O13/(1-O13)) -> 2.6455106 | Q13: =SUM(I13-J13-K13-L13-M13-P13) -> 17.256209 | R13: =SUM(Q13/C13) -> 0.19175697 | S13: ='总表（阶段盈亏）'!I13 -> 210 | T13: =SUM(Q13*S13) -> 3623.804 | U13: =SUM(T13) -> 3623.804
B14: week12 | C14: 89.99 | D14: 0.1 | E14: 0 | F14: =SUM(C14*(1-D14-E14)) -> 80.991 | G14: 10.51 | H14: =SUM(F14*8%) -> 6.47928 | I14: =SUM(F14-G14-H14) -> 64.00172 | J14: 0.5 | K14: 0.6 | L14: 40 | M14: 3 | N14: =SUM(20%*15%*F14+G14+J14+L14+M14+1.04) -> 57.47973 | O14: 0.044 | P14: =SUM(N14*O14/(1-O14)) -> 2.6455106 | Q14: =SUM(I14-J14-K14-L14-M14-P14) -> 17.256209 | R14: =SUM(Q14/C14) -> 0.19175697 | S14: ='总表（阶段盈亏）'!I14 -> 371 | T14: =SUM(Q14*S14) -> 6402.0537 | U14: =SUM(T14) -> 6402.0537
A15: 第四阶段 | B15: week13 | C15: 79.99 | D15: 0 | E15: 0 | F15: =SUM(C15*(1-D15-E15)) -> 79.99 | G15: 10.51 | H15: =SUM(F15*8%) -> 6.3992 | I15: =SUM(F15-G15-H15) -> 63.0808 | J15: 0.5 | K15: 0 | L15: 40 | M15: 3 | N15: =SUM(20%*15%*F15+G15+J15+L15+M15+1.04) -> 57.4497 | O15: 0.044 | P15: =SUM(N15*O15/(1-O15)) -> 2.6441285 | Q15: =SUM(I15-J15-K15-L15-M15-P15) -> 16.936672 | R15: =SUM(Q15/C15) -> 0.21173486 | S15: ='总表（阶段盈亏）'!I15 -> 280 | T15: =SUM(Q15*S15) -> 4742.268 | U15: =SUM(T15) -> 4742.268
B16: week14 | C16: 79.99 | D16: 0 | E16: 0 | F16: =SUM(C16*(1-D16-E16)) -> 79.99 | G16: 10.51 | H16: =SUM(F16*8%) -> 6.3992 | I16: =SUM(F16-G16-H16) -> 63.0808 | J16: 0.5 | K16: 0 | L16: 40 | M16: 3 | N16: =SUM(20%*15%*F16+G16+J16+L16+M16+1.04) -> 57.4497 | O16: 0.044 | P16: =SUM(N16*O16/(1-O16)) -> 2.6441285 | Q16: =SUM(I16-J16-K16-L16-M16-P16) -> 16.936672 | R16: =SUM(Q16/C16) -> 0.21173486 | S16: ='总表（阶段盈亏）'!I16 -> 315 | T16: =SUM(Q16*S16) -> 5335.0515 | U16: =SUM(T16) -> 5335.0515
B17: week15 | C17: 79.99 | D17: 0 | E17: 0 | F17: =SUM(C17*(1-D17-E17)) -> 79.99 | G17: 10.51 | H17: =SUM(F17*8%) -> 6.3992 | I17: =SUM(F17-G17-H17) -> 63.0808 | J17: 0.5 | K17: 0 | L17: 40 | M17: 3 | N17: =SUM(20%*15%*F17+G17+J17+L17+M17+1.04) -> 57.4497 | O17: 0.044 | P17: =SUM(N17*O17/(1-O17)) -> 2.6441285 | Q17: =SUM(I17-J17-K17-L17-M17-P17) -> 16.936672 | R17: =SUM(Q17/C17) -> 0.21173486 | S17: ='总表（阶段盈亏）'!I17 -> 350 | T17: =SUM(Q17*S17) -> 5927.835 | U17: =SUM(T17) -> 5927.835
B18: week16 | C18: 79.99 | D18: 0 | E18: 0 | F18: =SUM(C18*(1-D18-E18)) -> 79.99 | G18: 10.51 | H18: =SUM(F18*8%) -> 6.3992 | I18: =SUM(F18-G18-H18) -> 63.0808 | J18: 0.5 | K18: 0 | L18: 40 | M18: 3 | N18: =SUM(20%*15%*F18+G18+J18+L18+M18+1.04) -> 57.4497 | O18: 0.044 | P18: =SUM(N18*O18/(1-O18)) -> 2.6441285 | Q18: =SUM(I18-J18-K18-L18-M18-P18) -> 16.936672 | R18: =SUM(Q18/C18) -> 0.21173486 | S18: ='总表（阶段盈亏）'!I18 -> 490 | T18: =SUM(Q18*S18) -> 8298.9691 | U18: =SUM(T18) -> 8298.9691
A19: 第五阶段 | B19: week17 | C19: 79.99 | D19: 0 | E19: 0 | F19: =SUM(C19*(1-D19-E19)) -> 79.99 | G19: 10.51 | H19: =SUM(F19*8%) -> 6.3992 | I19: =SUM(F19-G19-H19) -> 63.0808 | J19: 0.5 | K19: 0 | L19: 40 | M19: 3 | N19: =SUM(20%*15%*F19+G19+J19+L19+M19+1.04) -> 57.4497 | O19: 0.044 | P19: =SUM(N19*O19/(1-O19)) -> 2.6441285 | Q19: =SUM(I19-J19-K19-L19-M19-P19) -> 16.936672 | R19: =SUM(Q19/C19) -> 0.21173486 | S19: ='总表（阶段盈亏）'!I19 -> 490 | T19: =SUM(Q19*S19) -> 8298.9691 | U19: =SUM(T19) -> 8298.9691
B20: week18 | C20: 79.99 | D20: 0 | E20: 0 | F20: =SUM(C20*(1-D20-E20)) -> 79.99 | G20: 10.51 | H20: =SUM(F20*8%) -> 6.3992 | I20: =SUM(F20-G20-H20) -> 63.0808 | J20: 0.5 | K20: 0 | L20: 40 | M20: 3 | N20: =SUM(20%*15%*F20+G20+J20+L20+M20+1.04) -> 57.4497 | O20: 0.044 | P20: =SUM(N20*O20/(1-O20)) -> 2.6441285 | Q20: =SUM(I20-J20-K20-L20-M20-P20) -> 16.936672 | R20: =SUM(Q20/C20) -> 0.21173486 | S20: ='总表（阶段盈亏）'!I20 -> 490 | T20: =SUM(Q20*S20) -> 8298.9691 | U20: =SUM(T20) -> 8298.9691
B21: week19 | C21: 79.99 | D21: 0 | E21: 0 | F21: =SUM(C21*(1-D21-E21)) -> 79.99 | G21: 10.51 | H21: =SUM(F21*8%) -> 6.3992 | I21: =SUM(F21-G21-H21) -> 63.0808 | J21: 0.5 | K21: 0 | L21: 40 | M21: 3 | N21: =SUM(20%*15%*F21+G21+J21+L21+M21+1.04) -> 57.4497 | O21: 0.044 | P21: =SUM(N21*O21/(1-O21)) -> 2.6441285 | Q21: =SUM(I21-J21-K21-L21-M21-P21) -> 16.936672 | R21: =SUM(Q21/C21) -> 0.21173486 | S21: ='总表（阶段盈亏）'!I21 -> 490 | T21: =SUM(Q21*S21) -> 8298.9691 | U21: =SUM(T21) -> 8298.9691
B22: week20 | C22: 79.99 | D22: 0 | E22: 0 | F22: =SUM(C22*(1-D22-E22)) -> 79.99 | G22: 10.51 | H22: =SUM(F22*8%) -> 6.3992 | I22: =SUM(F22-G22-H22) -> 63.0808 | J22: 0.5 | K22: 0 | L22: 40 | M22: 3 | N22: =SUM(20%*15%*F22+G22+J22+L22+M22+1.04) -> 57.4497 | O22: 0.044 | P22: =SUM(N22*O22/(1-O22)) -> 2.6441285 | Q22: =SUM(I22-J22-K22-L22-M22-P22) -> 16.936672 | R22: =SUM(Q22/C22) -> 0.21173486 | S22: ='总表（阶段盈亏）'!I22 -> 490 | T22: =SUM(Q22*S22) -> 8298.9691 | U22: =SUM(T22) -> 8298.9691
A23: 第六阶段 | B23: week21 | C23: 79.99 | D23: 0 | E23: 0 | F23: =SUM(C23*(1-D23-E23)) -> 79.99 | G23: 10.51 | H23: =SUM(F23*8%) -> 6.3992 | I23: =SUM(F23-G23-H23) -> 63.0808 | J23: 0.5 | K23: 0 | L23: 40 | M23: 3 | N23: =SUM(20%*15%*F23+G23+J23+L23+M23+1.04) -> 57.4497 | O23: 0.044 | P23: =SUM(N23*O23/(1-O23)) -> 2.6441285 | Q23: =SUM(I23-J23-K23-L23-M23-P23) -> 16.936672 | R23: =SUM(Q23/C23) -> 0.21173486 | S23: ='总表（阶段盈亏）'!I23 -> 490 | T23: =SUM(Q23*S23) -> 8298.9691 | U23: =SUM(T23) -> 8298.9691
B24: week22 | C24: 79.99 | D24: 0 | E24: 0 | F24: =SUM(C24*(1-D24-E24)) -> 79.99 | G24: 10.51 | H24: =SUM(F24*8%) -> 6.3992 | I24: =SUM(F24-G24-H24) -> 63.0808 | J24: 0.5 | K24: 0 | L24: 40 | M24: 3 | N24: =SUM(20%*15%*F24+G24+J24+L24+M24+1.04) -> 57.4497 | O24: 0.044 | P24: =SUM(N24*O24/(1-O24)) -> 2.6441285 | Q24: =SUM(I24-J24-K24-L24-M24-P24) -> 16.936672 | R24: =SUM(Q24/C24) -> 0.21173486 | S24: ='总表（阶段盈亏）'!I24 -> 490 | T24: =SUM(Q24*S24) -> 8298.9691 | U24: =SUM(T24) -> 8298.9691
B25: week23 | C25: 79.99 | D25: 0 | E25: 0 | F25: =SUM(C25*(1-D25-E25)) -> 79.99 | G25: 10.51 | H25: =SUM(F25*8%) -> 6.3992 | I25: =SUM(F25-G25-H25) -> 63.0808 | J25: 0.5 | K25: 0 | L25: 40 | M25: 3 | N25: =SUM(20%*15%*F25+G25+J25+L25+M25+1.04) -> 57.4497 | O25: 0.044 | P25: =SUM(N25*O25/(1-O25)) -> 2.6441285 | Q25: =SUM(I25-J25-K25-L25-M25-P25) -> 16.936672 | R25: =SUM(Q25/C25) -> 0.21173486 | S25: ='总表（阶段盈亏）'!I25 -> 490 | T25: =SUM(Q25*S25) -> 8298.9691 | U25: =SUM(T25) -> 8298.9691
B26: week24 | C26: 79.99 | D26: 0 | E26: 0 | F26: =SUM(C26*(1-D26-E26)) -> 79.99 | G26: 10.51 | H26: =SUM(F26*8%) -> 6.3992 | I26: =SUM(F26-G26-H26) -> 63.0808 | J26: 0.5 | K26: 0 | L26: 40 | M26: 3 | N26: =SUM(20%*15%*F26+G26+J26+L26+M26+1.04) -> 57.4497 | O26: 0.044 | P26: =SUM(N26*O26/(1-O26)) -> 2.6441285 | Q26: =SUM(I26-J26-K26-L26-M26-P26) -> 16.936672 | R26: =SUM(Q26/C26) -> 0.21173486 | S26: ='总表（阶段盈亏）'!I26 -> 490 | T26: =SUM(Q26*S26) -> 8298.9691 | U26: =SUM(T26) -> 8298.9691
A28: 每日盈亏真实数据
A29: 第一阶段 | B29: 第1周 | C29: 89.99 | D29: 0.3 | E29: 0 | F29: 62.993 | G29: 10.51 | H29: 5.03944 | I29: 47.44356 | J29: 0.5 | K29: 0.6 | L29: 40 | M29: 3 | N29: 56.93979 | O29: 0.044 | P29: 2.6206598 | Q29: 0.72290021 | R29: 0.0080331171 | S29: 21 | T29: 15.180904 | U29: 15.180904
B30: 第2周 | C30: 89.99 | D30: 0.3 | E30: 0 | F30: 62.993 | G30: 10.51 | H30: 5.03944 | I30: 47.44356 | J30: 0.5 | K30: 0.6 | L30: 40 | M30: 3 | N30: 56.93979 | O30: 0.044 | P30: 2.6206598 | Q30: 0.72290021 | R30: 0.0080331171 | S30: 49 | T30: 35.42211 | U30: 35.42211
B31: 第3周 | C31: 89.99 | D31: 0.3 | E31: 0 | F31: 62.993 | G31: 10.51 | H31: 5.03944 | I31: 47.44356 | J31: 0.5 | K31: 0.6 | L31: 40 | M31: 3 | N31: 56.93979 | O31: 0.044 | P31: 2.6206598 | Q31: 0.72290021 | R31: 0.0080331171 | S31: 70 | T31: 50.603015 | U31: 50.603015
B32: 第4周 | C32: 89.99 | D32: 0.3 | E32: 0 | F32: 62.993 | G32: 10.51 | H32: 5.03944 | I32: 47.44356 | J32: 0.5 | K32: 0.6 | L32: 40 | M32: 3 | N32: 56.93979 | O32: 0.044 | P32: 2.6206598 | Q32: 0.72290021 | R32: 0.0080331171 | S32: 84 | T32: 60.723618 | U32: 60.723618
A33: 第二阶段 | B33: 第5周 | C33: 89.99 | D33: 0.2 | E33: 0 | F33: 71.992 | G33: 10.51 | H33: 5.75936 | I33: 55.72264 | J33: 0.5 | K33: 0.6 | L33: 40 | M33: 3 | N33: 57.20976 | O33: 0.044 | P33: 2.6330852 | Q33: 8.9895548 | R33: 0.099895042 | S33: 105 | T33: 943.90326 | U33: 943.90326
B34: 第6周 | C34: 89.99 | D34: 0.2 | E34: 0 | F34: 71.992 | G34: 10.51 | H34: 5.75936 | I34: 55.72264 | J34: 0.5 | K34: 0.6 | L34: 40 | M34: 3 | N34: 57.20976 | O34: 0.044 | P34: 2.6330852 | Q34: 8.9895548 | R34: 0.099895042 | S34: 126 | T34: 1132.6839 | U34: 1132.6839
B35: 第7周 | C35: 89.99 | D35: 0.2 | E35: 0 | F35: 71.992 | G35: 10.51 | H35: 5.75936 | I35: 55.72264 | J35: 0.5 | K35: 0.6 | L35: 40 | M35: 3 | N35: 57.20976 | O35: 0.044 | P35: 2.6330852 | Q35: 8.9895548 | R35: 0.099895042 | S35: 140 | T35: 1258.5377 | U35: 1258.5377
B36: 第8周 | C36: 89.99 | D36: 0.2 | E36: 0 | F36: 71.992 | G36: 10.51 | H36: 5.75936 | I36: 55.72264 | J36: 0.5 | K36: 0.6 | L36: 40 | M36: 3 | N36: 57.20976 | O36: 0.044 | P36: 2.6330852 | Q36: 8.9895548 | R36: 0.099895042 | S36: 168 | T36: 1510.2452 | U36: 1510.2452
A37: 第三阶段 | B37: 第9周 | C37: 89.99 | D37: 0.1 | E37: 0 | F37: 80.991 | G37: 10.51 | H37: 6.47928 | I37: 64.00172 | J37: 0.5 | K37: 0.6 | L37: 40 | M37: 3 | N37: 57.47973 | O37: 0.044 | P37: 2.6455106 | Q37: 17.256209 | R37: 0.19175697 | S37: 182 | T37: 3140.6301 | U37: 3140.6301
B38: 第10周 | C38: 89.99 | D38: 0.1 | E38: 0 | F38: 80.991 | G38: 10.51 | H38: 6.47928 | I38: 64.00172 | J38: 0.5 | K38: 0.6 | L38: 40 | M38: 3 | N38: 57.47973 | O38: 0.044 | P38: 2.6455106 | Q38: 17.256209 | R38: 0.19175697 | S38: 259 | T38: 4469.3582 | U38: 4469.3582
B39: 第11周 | C39: 89.99 | D39: 0.1 | E39: 0 | F39: 80.991 | G39: 10.51 | H39: 6.47928 | I39: 64.00172 | J39: 0.5 | K39: 0.6 | L39: 40 | M39: 3 | N39: 57.47973 | O39: 0.044 | P39: 2.6455106 | Q39: 17.256209 | R39: 0.19175697 | S39: 210 | T39: 3623.804 | U39: 3623.804
B40: 第12周 | C40: 89.99 | D40: 0.1 | E40: 0 | F40: 80.991 | G40: 10.51 | H40: 6.47928 | I40: 64.00172 | J40: 0.5 | K40: 0.6 | L40: 40 | M40: 3 | N40: 57.47973 | O40: 0.044 | P40: 2.6455106 | Q40: 17.256209 | R40: 0.19175697 | S40: 371 | T40: 6402.0537 | U40: 6402.0537
A41: 第四阶段 | B41: 第13周 | C41: 79.99 | D41: 0 | E41: 0 | F41: 79.99 | G41: 10.51 | H41: 6.3992 | I41: 63.0808 | J41: 0.5 | K41: 0 | L41: 40 | M41: 3 | N41: 57.4497 | O41: 0.044 | P41: 2.6441285 | Q41: 16.936672 | R41: 0.21173486 | S41: 280 | T41: 4742.268 | U41: 4742.268
...

Sheet 总表（阶段盈亏） (调整后)
A1: 按照每周/每日不同的数据表现情况进行调整： | AB1: https://mp.weixin.qq.com/s/hJXWLb-KpYE6J5aK37fUqA?poc_token=HER7cGijba2sEL_p1d8TCVeaPrsbMxX-Mtg-J8JD
A2: 周 | B2: 星期 | C2: 名称 | D2: 店铺SKU | E2: ASIN | F2: Rating数 | G2: 星级 | H2: QA数量 | I2: 操作 | J2: flashlihte | K2: 访问IP数 | L2: 自然流量 | M2: 浏览量 | N2: 转化率 | O2: 总订单 | P2: 总销售额 | Q2: 总销量 | R2: 曝光量 | S2: 点击 | T2: 广告订单 | U2: CTR | V2: CVR | W2: 总花费 | X2: CPC | Y2: 广告销售额 | Z2: ACOS | AA2: 广告订单占比 | AB2: 广告订单占比
A3: ①周 | B3: 星期一 | AB3: Q&A数 QA图片视频， 评论数，星级，评论的质量： 前台首页无差评 3星，以及点赞数量（前3个评论，首页）
B4: 星期二
B5: 星期三
B6: 星期四
B7: 星期五
B8: 星期六
B9: 星期日
A10: 第一周
A11: ②周 | B11: 星期一
B12: 星期二
B13: 星期三
B14: 星期四
B15: 星期五
B16: 星期六
B17: 星期日
A18: 第二周
A19: ③周 | B19: 星期一
B20: 星期二
B21: 星期三
B22: 星期四
B23: 星期五
B24: 星期六
B25: 星期日
A26: 第三周
A27: ④周 | B27: 星期一
B28: 星期二
B29: 星期三
B30: 星期四
B31: 星期五
B32: 星期六
B33: 星期日
A34: 第四周
A35: ⑤周 | B35: 星期一
B36: 星期二
B37: 星期三
B38: 星期四
B39: 星期五
B40: 星期六
...

Sheet CPC表格
A1: 广告数据模拟
A2: 常规数据 | N2: 广告数据 | AB2: 实时更新 | AC2: 操作备注
A3: 阶段 | B3: 周 | C3: 价格 | D3: 站内 coupon | E3: 站内 code | F3: 折后价 | G3: 新品 榜单 | H3: 小类目 排名 | I3: 总 销量 | J3: 总访 问量 | K3: CVR | L3: 评论 数量 | M3: 评分 | N3: 曝光量 | O3: 点击量 | P3: CTR | Q3: 广告单 | R3: CVR | S3: 平均 CPC | T3: 花费 | U3: ACOS | V3: CPA | W3: 日均 广告费 | X3: 自然 访问 | Y3: 自然 订单 | Z3: 自然 单占比 | AA3: 最终 盈亏 | AB3: Sif 质量分 | AC3: 运营调整 | AD3: 广告操作
A4: 第一阶段 | C4: 79.99 | D4: 0.3 | E4: 0 | F4: =SUM(C4*(1-D4-E4)) -> 55.993 | O4: =SUM(Q4/R4) -> 262.5 | Q4: ='总表（阶段盈亏）'!H3 -> 21 | R4: 0.08 | S4: 1.91 | T4: =SUM(O4*S4) -> 501.375 | U4: =SUM(S4/R4/C4) -> 0.29847481 | V4: =SUM(T4/Q4) -> 23.875 | W4: =T4/7 -> 71.625
C5: 89.99 | D5: 0.3 | E5: 0 | F5: =SUM(C5*(1-D5-E5)) -> 62.993 | O5: =SUM(Q5/R5) -> 437.5 | Q5: ='总表（阶段盈亏）'!H4 -> 35 | R5: 0.08 | S5: 1.91 | T5: =SUM(O5*S5) -> 835.625 | U5: =SUM(S5/R5/C5) -> 0.26530726 | V5: =SUM(T5/Q5) -> 23.875 | W5: =T5/7 -> 119.375
C6: 89.99 | D6: 0.3 | E6: 0 | F6: =SUM(C6*(1-D6-E6)) -> 62.993 | O6: =SUM(Q6/R6) -> 525 | Q6: ='总表（阶段盈亏）'!H5 -> 42 | R6: 0.08 | S6: 1.91 | T6: =SUM(O6*S6) -> 1002.75 | U6: =SUM(S6/R6/C6) -> 0.26530726 | V6: =SUM(T6/Q6) -> 23.875 | W6: =T6/7 -> 143.25
C7: 89.99 | D7: 0.3 | E7: 0 | F7: =SUM(C7*(1-D7-E7)) -> 62.993 | O7: =SUM(Q7/R7) -> 612.5 | Q7: ='总表（阶段盈亏）'!H6 -> 49 | R7: 0.08 | S7: 1.91 | T7: =SUM(O7*S7) -> 1169.875 | U7: =SUM(S7/R7/C7) -> 0.26530726 | V7: =SUM(T7/Q7) -> 23.875 | W7: =T7/7 -> 167.125
A8: 第二阶段 | C8: 85.99 | D8: 0.2 | E8: 0 | F8: =SUM(C8*(1-D8-E8)) -> 68.792 | O8: =SUM(Q8/R8) -> 741.17647 | Q8: ='总表（阶段盈亏）'!H7 -> 63 | R8: 0.085 | S8: 1.87 | T8: =SUM(O8*S8) -> 1386 | U8: =SUM(S8/R8/C8) -> 0.2558437 | V8: =SUM(T8/Q8) -> 22 | W8: =T8/7 -> 198
C9: 85.99 | D9: 0.2 | E9: 0 | F9: =SUM(C9*(1-D9-E9)) -> 68.792 | O9: =SUM(Q9/R9) -> 823.52941 | Q9: ='总表（阶段盈亏）'!H8 -> 70 | R9: 0.085 | S9: 1.87 | T9: =SUM(O9*S9) -> 1540 | U9: =SUM(S9/R9/C9) -> 0.2558437 | V9: =SUM(T9/Q9) -> 22 | W9: =T9/7 -> 220
C10: 85.99 | D10: 0.2 | E10: 0 | F10: =SUM(C10*(1-D10-E10)) -> 68.792 | O10: =SUM(Q10/R10) -> 988.23529 | Q10: ='总表（阶段盈亏）'!H9 -> 84 | R10: 0.085 | S10: 1.87 | T10: =SUM(O10*S10) -> 1848 | U10: =SUM(S10/R10/C10) -> 0.2558437 | V10: =SUM(T10/Q10) -> 22 | W10: =T10/7 -> 264
C11: 85.99 | D11: 0.2 | E11: 0 | F11: =SUM(C11*(1-D11-E11)) -> 68.792 | O11: =SUM(Q11/R11) -> 988.23529 | Q11: ='总表（阶段盈亏）'!H10 -> 84 | R11: 0.085 | S11: 1.87 | T11: =SUM(O11*S11) -> 1848 | U11: =SUM(S11/R11/C11) -> 0.2558437 | V11: =SUM(T11/Q11) -> 22 | W11: =T11/7 -> 264
A12: 第三阶段 | C12: 85.99 | D12: 0.1 | E12: 0 | F12: =SUM(C12*(1-D12-E12)) -> 77.391 | O12: =SUM(Q12/R12) -> 1088.8889 | Q12: ='总表（阶段盈亏）'!H11 -> 98 | R12: 0.09 | S12: 1.84 | T12: =SUM(O12*S12) -> 2003.5556 | U12: =SUM(S12/R12/C12) -> 0.23775374 | V12: =SUM(T12/Q12) -> 20.444444 | W12: =T12/7 -> 286.22222
C13: 85.99 | D13: 0.1 | E13: 0 | F13: =SUM(C13*(1-D13-E13)) -> 77.391 | O13: =SUM(Q13/R13) -> 1166.6667 | Q13: ='总表（阶段盈亏）'!H12 -> 105 | R13: 0.09 | S13: 1.84 | T13: =SUM(O13*S13) -> 2146.6667 | U13: =SUM(S13/R13/C13) -> 0.23775374 | V13: =SUM(T13/Q13) -> 20.444444 | W13: =T13/7 -> 306.66667
C14: 85.99 | D14: 0.1 | E14: 0 | F14: =SUM(C14*(1-D14-E14)) -> 77.391 | O14: =SUM(Q14/R14) -> 1166.6667 | Q14: ='总表（阶段盈亏）'!H13 -> 105 | R14: 0.09 | S14: 1.84 | T14: =SUM(O14*S14) -> 2146.6667 | U14: =SUM(S14/R14/C14) -> 0.23775374 | V14: =SUM(T14/Q14) -> 20.444444 | W14: =T14/7 -> 306.66667
C15: 85.99 | D15: 0.1 | E15: 0 | F15: =SUM(C15*(1-D15-E15)) -> 77.391 | O15: =SUM(Q15/R15) -> 1244.4444 | Q15: ='总表（阶段盈亏）'!H14 -> 112 | R15: 0.09 | S15: 1.84 | T15: =SUM(O15*S15) -> 2289.7778 | U15: =SUM(S15/R15/C15) -> 0.23775374 | V15: =SUM(T15/Q15) -> 20.444444 | W15: =T15/7 -> 327.11111
A16: 第四阶段 | C16: 79.99 | D16: 0 | E16: 0 | F16: =SUM(C16*(1-D16-E16)) -> 79.99 | O16: =SUM(Q16/R16) -> 1482.3529 | Q16: ='总表（阶段盈亏）'!H15 -> 126 | R16: 0.085 | S16: 1.8 | T16: =SUM(O16*S16) -> 2668.2353 | U16: =SUM(S16/R16/C16) -> 0.26473897 | V16: =SUM(T16/Q16) -> 21.176471 | W16: =T16/7 -> 381.17647
C17: 79.99 | D17: 0 | E17: 0 | F17: =SUM(C17*(1-D17-E17)) -> 79.99 | O17: =SUM(Q17/R17) -> 1647.0588 | Q17: ='总表（阶段盈亏）'!H16 -> 140 | R17: 0.085 | S17: 1.8 | T17: =SUM(O17*S17) -> 2964.7059 | U17: =SUM(S17/R17/C17) -> 0.26473897 | V17: =SUM(T17/Q17) -> 21.176471 | W17: =T17/7 -> 423.52941
C18: 79.99 | D18: 0 | E18: 0 | F18: =SUM(C18*(1-D18-E18)) -> 79.99 | O18: =SUM(Q18/R18) -> 1811.7647 | Q18: ='总表（阶段盈亏）'!H17 -> 154 | R18: 0.085 | S18: 1.8 | T18: =SUM(O18*S18) -> 3261.1765 | U18: =SUM(S18/R18/C18) -> 0.26473897 | V18: =SUM(T18/Q18) -> 21.176471 | W18: =T18/7 -> 465.88235
C19: 79.99 | D19: 0 | E19: 0 | F19: =SUM(C19*(1-D19-E19)) -> 79.99 | O19: =SUM(Q19/R19) -> 2058.8235 | Q19: ='总表（阶段盈亏）'!H18 -> 175 | R19: 0.085 | S19: 1.8 | T19: =SUM(O19*S19) -> 3705.8824 | U19: =SUM(S19/R19/C19) -> 0.26473897 | V19: =SUM(T19/Q19) -> 21.176471 | W19: =T19/7 -> 529.41176
A20: 第五阶段 | C20: 79.99 | D20: 0 | E20: 0 | F20: =SUM(C20*(1-D20-E20)) -> 79.99 | O20: =SUM(Q20/R20) -> 2058.8235 | Q20: ='总表（阶段盈亏）'!H19 -> 175 | R20: 0.085 | S20: 1.8 | T20: =SUM(O20*S20) -> 3705.8824 | U20: =SUM(S20/R20/C20) -> 0.26473897 | V20: =SUM(T20/Q20) -> 21.176471 | W20: =T20/7 -> 529.41176
C21: 79.99 | D21: 0 | E21: 0 | F21: =SUM(C21*(1-D21-E21)) -> 79.99 | O21: =SUM(Q21/R21) -> 2058.8235 | Q21: ='总表（阶段盈亏）'!H20 -> 175 | R21: 0.085 | S21: 1.8 | T21: =SUM(O21*S21) -> 3705.8824 | U21: =SUM(S21/R21/C21) -> 0.26473897 | V21: =SUM(T21/Q21) -> 21.176471 | W21: =T21/7 -> 529.41176
C22: 79.99 | D22: 0 | E22: 0 | F22: =SUM(C22*(1-D22-E22)) -> 79.99 | O22: =SUM(Q22/R22) -> 2058.8235 | Q22: ='总表（阶段盈亏）'!H21 -> 175 | R22: 0.085 | S22: 1.8 | T22: =SUM(O22*S22) -> 3705.8824 | U22: =SUM(S22/R22/C22) -> 0.26473897 | V22: =SUM(T22/Q22) -> 21.176471 | W22: =T22/7 -> 529.41176
C23: 79.99 | D23: 0 | E23: 0 | F23: =SUM(C23*(1-D23-E23)) -> 79.99 | O23: =SUM(Q23/R23) -> 2058.8235 | Q23: ='总表（阶段盈亏）'!H22 -> 175 | R23: 0.085 | S23: 1.8 | T23: =SUM(O23*S23) -> 3705.8824 | U23: =SUM(S23/R23/C23) -> 0.26473897 | V23: =SUM(T23/Q23) -> 21.176471 | W23: =T23/7 -> 529.41176
A24: 第六阶段 | C24: 79.99 | D24: 0 | E24: 0 | F24: =SUM(C24*(1-D24-E24)) -> 79.99 | O24: =SUM(Q24/R24) -> 2058.8235 | Q24: ='总表（阶段盈亏）'!H23 -> 175 | R24: 0.085 | S24: 1.8 | T24: =SUM(O24*S24) -> 3705.8824 | U24: =SUM(S24/R24/C24) -> 0.26473897 | V24: =SUM(T24/Q24) -> 21.176471 | W24: =T24/7 -> 529.41176
C25: 79.99 | D25: 0 | E25: 0 | F25: =SUM(C25*(1-D25-E25)) -> 79.99 | O25: =SUM(Q25/R25) -> 2058.8235 | Q25: ='总表（阶段盈亏）'!H24 -> 175 | R25: 0.085 | S25: 1.8 | T25: =SUM(O25*S25) -> 3705.8824 | U25: =SUM(S25/R25/C25) -> 0.26473897 | V25: =SUM(T25/Q25) -> 21.176471 | W25: =T25/7 -> 529.41176
C26: 79.99 | D26: 0 | E26: 0 | F26: =SUM(C26*(1-D26-E26)) -> 79.99 | O26: =SUM(Q26/R26) -> 2058.8235 | Q26: ='总表（阶段盈亏）'!H25 -> 175 | R26: 0.085 | S26: 1.8 | T26: =SUM(O26*S26) -> 3705.8824 | U26: =SUM(S26/R26/C26) -> 0.26473897 | V26: =SUM(T26/Q26) -> 21.176471 | W26: =T26/7 -> 529.41176
C27: 79.99 | D27: 0 | E27: 0 | F27: =SUM(C27*(1-D27-E27)) -> 79.99 | O27: =SUM(Q27/R27) -> 2058.8235 | Q27: ='总表（阶段盈亏）'!H26 -> 175 | R27: 0.085 | S27: 1.8 | T27: =SUM(O27*S27) -> 3705.8824 | U27: =SUM(S27/R27/C27) -> 0.26473897 | V27: =SUM(T27/Q27) -> 21.176471 | W27: =T27/7 -> 529.41176
A29: 广告真实数据
A30: 常规数据 | N30: 广告数据 | AB30: 实时更新 | AC30: 操作备注
A31: 阶段 | B31: 周 | C31: 价格 | D31: 站内 coupon | E31: 站内 code | F31: 折后价 | G31: 新品 榜单 | H31: 小类目 排名 | I31: 总 销量 | J31: 总访 问量 | K31: CVR | L31: 评论 数量 | M31: 评分 | N31: 曝光量 | O31: 点击量 | P31: CTR | Q31: 广告单 | R31: CVR | S31: 平均 CPC | T31: 花费 | U31: ACOS | V31: CPA | W31: 日均 广告费 | X31: 自然 访问 | Y31: 自然 订单 | Z31: 自然 单占比 | AA31: 最终 盈亏 | AB31: Sif 质量分 | AC31: 运营调整 | AD31: 广告操作
A32: 第一阶段 | B32: 第1周 | C32: 79.99 | D32: 0.3 | E32: 0 | F32: 55.993 | O32: 262.5 | Q32: 21 | R32: 0.08 | S32: 1.91 | T32: 501.375 | U32: 0.29847481 | V32: 23.875 | W32: 71.625
B33: 第2周 | C33: 89.99 | D33: 0.3 | E33: 0 | F33: 62.993 | O33: 437.5 | Q33: 35 | R33: 0.08 | S33: 1.91 | T33: 835.625 | U33: 0.26530726 | V33: 23.875 | W33: 119.375
B34: 第3周 | C34: 89.99 | D34: 0.3 | E34: 0 | F34: 62.993 | O34: 525 | Q34: 42 | R34: 0.08 | S34: 1.91 | T34: 1002.75 | U34: 0.26530726 | V34: 23.875 | W34: 143.25
B35: 第4周 | C35: 89.99 | D35: 0.3 | E35: 0 | F35: 62.993 | O35: 612.5 | Q35: 49 | R35: 0.08 | S35: 1.91 | T35: 1169.875 | U35: 0.26530726 | V35: 23.875 | W35: 167.125
A36: 第二阶段 | B36: 第5周 | C36: 85.99 | D36: 0.2 | E36: 0 | F36: 68.792 | O36: 741.17647 | Q36: 63 | R36: 0.085 | S36: 1.87 | T36: 1386 | U36: 0.2558437 | V36: 22 | W36: 198
B37: 第6周 | C37: 85.99 | D37: 0.2 | E37: 0 | F37: 68.792 | O37: 823.52941 | Q37: 70 | R37: 0.085 | S37: 1.87 | T37: 1540 | U37: 0.2558437 | V37: 22 | W37: 220
B38: 第7周 | C38: 85.99 | D38: 0.2 | E38: 0 | F38: 68.792 | O38: 988.23529 | Q38: 84 | R38: 0.085 | S38: 1.87 | T38: 1848 | U38: 0.2558437 | V38: 22 | W38: 264
B39: 第8周 | C39: 85.99 | D39: 0.2 | E39: 0 | F39: 68.792 | O39: 988.23529 | Q39: 84 | R39: 0.085 | S39: 1.87 | T39: 1848 | U39: 0.2558437 | V39: 22 | W39: 264
A40: 第三阶段 | B40: 第9周 | C40: 85.99 | D40: 0.1 | E40: 0 | F40: 77.391 | O40: 1088.8889 | Q40: 98 | R40: 0.09 | S40: 1.84 | T40: 2003.5556 | U40: 0.23775374 | V40: 20.444444 | W40: 286.22222
B41: 第10周 | C41: 85.99 | D41: 0.1 | E41: 0 | F41: 77.391 | O41: 1166.6667 | Q41: 105 | R41: 0.09 | S41: 1.84 | T41: 2146.6667 | U41: 0.23775374 | V41: 20.444444 | W41: 306.66667
...

Sheet 推广目标
A1: SKU：skuR0001EU ASIN：Bxxxxxxxx3 | I1: 关键词
A3: 上架销售时间： | B3: 45765
A4: 推广周期： | B4: 4月20日-6月31日 | I4: 关键词 | J4: 关键词翻译 | K4: 流量占比 | L4: 预估周曝光量 | M4: 关键词类型 | N4: 转化效果自然流量占比
A5: 排名目标： | B5: Matratzensauger #50 | I5: milbensauger | J5: 吸螨虫 | K5: 0.497508 | L5: 13984 | M5: 主要流量词 | N5: 0.3471
A6: 目标销量： | B6: 20-25pcs/天 | I6: milbensauger für matratzen | J6: 用于床垫的吸尘器 | K6: 0.294441 | L6: 8276 | M6: 主要流量词 | N6: 0.41862
I7: sofa reiniger | J7: 沙发清洁剂 | K7: 0.059295 | L7: 1667 | N7: 0.61722
I8: matratzenreiniger | J8: 床垫清洁剂 | K8: 0.047246 | L8: 1328 | N8: 0.80955
I9: milbensauger für matratzen testsieger | J9: 用于床垫测试的螨虫吸尘器测试获胜者 | K9: 0.02472 | L9: 695 | N9: 0.46301
A10: 目标管理 | B10: 目标 | C10: ASIN 1 | I10: milbensauger mit uv licht | J10: 带紫外线灯的螨虫奶嘴 | K10: 0.019301 | L10: 543 | N10: 0.06106
A11: 对标竞品 | B11: B0DKPGKSYS | C11: B0DKPGKSYS | I11: hoover milbensauger | J11: 胡佛螨吸盘 | K11: 0.017954 | L11: 505 | M11: 精准长尾词 | N11: 0.50632
A12: 目标排名 | B12: 21-24 | C12: B0DKPGKSYS | I12: milbenstaubsauger | J12: 螨吸尘器 | K12: 0.008428 | L12: 237 | N12: 0.28778
A13: 目标日销 | B13: 20-25 日销 | C13: B0DKPGKSYS | I13: polsterreiniger | J13: 室内装饰品清洁剂 | K13: 0.007424 | L13: 209 | N13: 15
A14: 价格 | B14: 109-129.99 | C14: B0DKPGKSYS | I14: teppichreiniger gerät | J14: 地毯清洁装置 | K14: 0.002209 | L14: 62 | M14: 、 | N14: 16
A15: rating | B15: 136 | C15: B0DKPGKSYS | I15: polsterreinigungsgerät | J15: 室内装潢清洗机 | K15: 0.001316 | L15: 37 | M15: 、 | N15: 6
A16: 评分 | B16: 4.7 | C16: B0DKPGKSYS
A17: 主推词 | B17: milbensauger | C17: B0DKPGKSYS
D20: 广泛 | E20: 词组 | F20: 精准
A21: 核心关键词 选取， | B21: milbensauger | C21: 除螨仪 | D21: 1.33 | E21: 1.2 | F21: 1.23
B22: milbenstaubsauger | C22: 除螨仪 | D22: 1.39 | E22: 1.24 | F22: 1.29
B23: milbensauger für matratzen | C23: 床垫除螨仪 | D23: 1.33 | E23: 1.2 | F23: 1.21
B24: milbensauger mit uv licht | C24: 带紫外除螨仪 | D24: 1.36 | E24: 1.22 | F24: 1.28
B25: milbensauger für matratzen testsieger | C25: 床垫除螨仪冠军 | D25: 1.29 | E25: 1.16 | F25: 1.21
B26: Milbensauger | C26: 除螨仪 | D26: 1.33 | E26: 1.2 | F26: 1.23
B27: jigoo milbensauger | C27: jigoo 除螨仪 | D27: 1.47 | E27: 1.3 | F27: 1.36
B28: Hoover milbensauger | C28: Hoover除螨仪 | D28: 1.65 | E28: 1.33 | F28: 2.01
A29: 长尾词 选取
B30: milbenstaubsauger | C30: 除螨仪 | D30: 1.39 | E30: 1.2 | F30: 1.23
B31: handstaubsauger | C31: 手持吸尘器 | D31: 0.64 | E31: 0.58 | F31: 0.63
B32: milbensauger für matratzen testsieger | C32: 床垫除螨仪冠军 | D32: 1.29 | E32: 1.16 | F32: 1.21
B33: matratzenreiniger gerät | C33: 除螨仪冠军 | D33: 1.08 | E33: 0.97 | F33: 1.01
A35: 蓝海词 | B35: polsterreiniger gerät | C35: “沙发清洁器”“软家具清洁设备” | D35: 1.01 | E35: 0.94 | F35: 0.89
B37: 其他品牌相关 品牌词词组 | C37: brand name+keywords
A79: 关键词 | B79: 关键词翻译 | C79: 流量占比 | D79: 预估周曝光量 | E79: 关键词类型 | F79: 转化效果自然流量占比 | G79: B0F1F7J8V3
A80: milbensauger | B80: 吸螨虫 | C80: 0.497508 | D80: 13984 | E80: 主要流量词 | F80: 0.3471
A81: milbensauger für matratzen | B81: 用于床垫的吸尘器 | C81: 0.294441 | D81: 8276 | E81: 主要流量词 | F81: 0.41862
A82: sofa reiniger | B82: 沙发清洁剂 | C82: 0.059295 | D82: 1667 | F82: 0.61722
A83: matratzenreiniger | B83: 床垫清洁剂 | C83: 0.047246 | D83: 1328 | F83: 0.80955
A84: milbensauger für matratzen testsieger | B84: 用于床垫测试的螨虫吸尘器测试获胜者 | C84: 0.02472 | D84: 695 | F84: 0.46301
A85: milbensauger mit uv licht | B85: 带紫外线灯的螨虫奶嘴 | C85: 0.019301 | D85: 543 | F85: 0.06106
A86: hoover milbensauger | B86: 胡佛螨吸盘 | C86: 0.017954 | D86: 505 | E86: 精准长尾词 | F86: 0.50632
...

Sheet 推广计划
A1: WEEK | B1: Date | C1: SKU | D1: 售价 | E1: COUPON | F1: Action | G1: 目标平均日销 | H1: 周销 | I1: 目标排名 | J1: Review星级/数量 | K1: REVIEW计划 | M1: 周消耗库存 | N1: 销售额 | O1: 日均流量 | P1: 转化率 | Q1: 主关键词自然搜索排名 | R1: 广告计划 | X1: 库存计划
K2: 送出数量 | L2: 措施 | R2: 广告日预算 | S2: 每日点击 | T2: CPC | U2: CVR | V2: 广告日订单 | W2: 广告订单占比 | Z2: LBS库存 | AA2: SZ | AB2: LBS在途 | AC2: LBS发货 | AD2: 采购计划
A3: WEEK1 | B3: 4.18-4.25 | C3: R0001EU | D3: 109.99 | E3: 20 | F3: 10 coupon+广告 | G3: =M3/7 -> 6.2857143 | H3: =G3*7 -> 44 | I3: 60 | J3: 4.7 | K3: 首单测评1单5星 | L3: 直评 10个 | M3: 44 | N3: =D3*H3 -> 4839.56 | O3: 66 | P3: =G3/O3 -> 0.095238095 | Q3: 主推关键词：milbensauger,milbensauger für matratzen 目标：第5页 | R3: =T3*S3 -> 48 | S3: =V3/U3 -> 40 | T3: 1.2 | U3: 0.11 | V3: =G3*W3 -> 4.4 | W3: 0.7 | X3: 1200 | Y3: 0 | Z3: 0 | AA3: 1310 | AB3: 2490海运
A4: WEEK2 | B4: 4.26-5.2 | C4: R0001EU | D4: 109.99 | E4: 20 | F4: coupon+广告 | G4: =M4/7 -> 11.571429 | H4: =G4*7 -> 81 | I4: 40 | J4: 4.7 | K4: 绿标10个 | L4: 直评补 3-5个 | M4: 81 | N4: =D4*H4 -> 8909.19 | O4: 88 | P4: =G4/O4 -> 0.13149351 | Q4: 主推关键词：milbensauger,milbensauger für matratzen 目标：第4页 | R4: =T4*S4 -> 75.214286 | S4: =V4/U4 -> 62.678571 | T4: 1.2 | U4: 0.12 | V4: =G4*W4 -> 7.5214286 | W4: 0.65 | X4: =X3-H3 -> 1156 | Y4: 0 | Z4: 0 | AA4: 1310 | AB4: 2490
A5: WEEK3 | B5: 5.3-5.9 | C5: R0001EU | D5: 109.99 | E5: 20 | F5: coupon+广告 | G5: =M5/7 -> 7.8571429 | H5: =G5*7 -> 55 | I5: 30 | J5: 4.7 | K5: 1 | L5: 测评 | M5: 55 | N5: =D5*H5 -> 6049.45 | O5: 60 | P5: =G5/O5 -> 0.13095238 | Q5: 主推关键词：milbensauger,milbensauger für matratzen 目标：第3页 | R5: =T5*S5 -> 39.89011 | S5: =V5/U5 -> 36.263736 | T5: 1.1 | U5: 0.13 | V5: =G5*W5 -> 4.7142857 | W5: 0.6 | X5: =X4-H4 -> 1075 | Y5: 0 | Z5: 2490 | AA5: 0 | AB5: 1310卡派 | AC5: 720至TT 600至RUI备用
A6: WEEK4 | B6: 5.10-5.16 | C6: R0001EU | D6: 109.99 | E6: 20 | F6: 10 coupon+7DD+加大广告投放 | G6: =M6/7 -> 6.8571429 | H6: =G6*7 -> 48 | I6: 20 | J6: 4.6 | K6: 2 | L6: 测评 | M6: 48 | N6: =D6*H6 -> 5279.52 | O6: 50 | P6: =G6/O6 -> 0.13714286 | Q6: 主推关键词：milbensauger,milbensauger für matratzen 目标：第3页 | R6: =T6*S6 -> 25.142857 | S6: =V6/U6 -> 22.857143 | T6: 1.1 | U6: 0.15 | V6: =G6*W6 -> 3.4285714 | W6: 0.5 | X6: =X5-H5+720 -> 1740 | Y6: 600 | Z6: 1170 | AA6: 0 | AB6: 1310 | AD6: 1500
A7: WEEK5 | B7: 5.17-5.23 | C7: R0001EU | D7: 119.99 | E7: 10 | F7: coupon+广告 | G7: =M7/7 -> 7.4285714 | H7: =G7*7 -> 52 | I7: 28 | J7: 4.6 | K7: 2 | L7: 测评 | M7: 52 | N7: =D7*H7 -> 6239.48 | O7: 56 | P7: =G7/O7 -> 0.13265306 | Q7: 主推关键词：milbensauger,milbensauger für matratzen 目标：第2页 | R7: =T7*S7 -> 27.238095 | S7: =V7/U7 -> 27.238095 | T7: 1 | U7: 0.15 | V7: =G7*W7 -> 4.0857143 | W7: 0.55 | X7: =X6-H6 -> 1692 | Y7: 600 | Z7: 1170 | AA7: 0 | AB7: 1310
A8: WEEK6 | B8: 5.24-5.30 | C8: R0001EU | D8: 119.99 | E8: 10 | F8: coupon+广告 | G8: =M8/7 -> 7.1428571 | H8: =G8*7 -> 50 | I8: 26 | J8: 4.6 | K8: 2 | L8: 测评 | M8: 50 | N8: =D8*H8 -> 5999.5 | O8: 60 | P8: =G8/O8 -> 0.11904762 | Q8: 主推关键词：milbensauger,milbensauger für matratzen 目标：第2页 | R8: =T8*S8 -> 23.809524 | S8: =V8/U8 -> 23.809524 | T8: 1 | U8: 0.15 | V8: =G8*W8 -> 3.5714286 | W8: 0.5 | X8: =X7-H7 -> 1640 | Y8: 600 | Z8: 1170 | AA8: 0 | AB8: 1310 | AC8: 900至TT
A9: WEEK7 | B9: 5.31-6.6 | C9: R0001EU | D9: 119.99 | E9: 10 | F9: 7DD+加大广告投放 | G9: =M9/7 -> 8.2857143 | H9: =G9*7 -> 58 | I9: 20 | J9: 4.6 | K9: 2 | L9: 测评 | M9: 58 | N9: =D9*H9 -> 6959.42 | O9: 68 | P9: =G9/O9 -> 0.12184874 | Q9: 主推关键词：milbensauger,milbensauger für matratzen 目标：第2页 | R9: =T9*S9 -> 18.642857 | S9: =V9/U9 -> 20.714286 | T9: 0.9 | U9: 0.16 | V9: =G9*W9 -> 3.3142857 | W9: 0.4 | X9: =X8-H8+900 -> 2490 | Y9: 600 | Z9: =Z8-900 -> 270 | AA9: 0 | AB9: 1310 | AD9: 1980(PD)
