Workbook

Sheet ①使用说明与对标总览
A1: 产品选品决策模板 · 对标亚马逊官方「选品模拟器」做一个天机OS新品验证
A2: 依据: 亚马逊 Seller Central「选品模拟器 / 验证产品创意」(Validate Product Ideas) 官方文档与页面。
A4: 一、六大使用步骤
A5: 序号 | B5: 步骤 | C5: 做什么 | D5: 产物/位置
A6: 1 | B6: 输入产品概念 | C6: 填「②产品概念输入卡」: 站点/语言/标题/类目/目标售价/描述/3个以上要点(与官方模拟器输入口径一致) | D6: ② 产品概念输入卡
A7: 2 | B7: 看市场与对手 | C7: 「③市场细分与竞争格局」→「④相似产品分析」: 官方模式=把你与类目表现优异的产品做竞争定位与逐项功能对比 | D7: ③④
A8: 3 | B8: 听客户声音 ,VOC，产品差评分析 | C8: 「⑤VOC评论洞察」: 官方模式=买家满意度/评论洞察, 提炼好评卖点与差评痛点 | D8: ⑤
A9: 4 | B9: 算经济账 | C9: 「⑥季节性→⑦广告投入产出→⑧利润率(含FBA)→⑨供应商成本→⑩情景建模→⑪跨市场潜力」六张表逐项核算 | D9: ⑥-⑪
A10: 5 | B10: 画买家画像 | C10: 「⑫买家画像与购买路径」: 用 ABA 人口统计 + 商机探测器行为数据填写 | D10: ⑫
A11: 6 | B11: 汇总评分决策 | C11: 「⑬数据源矩阵」记录证据→「⑭概念概要+优化建议」→「⑮审核与评分」→「⑯总结与决策」输出 通过/待确认/否决 | D11: ⑬-⑯
A13: 二、对标: 官方「选品模拟器」输出模块 → 模板对应表
A14: 官方模拟器输出模块 | B14: 模板对应表 | C14: 官方模块做什么 | D14: 模板补充说明
A15: 研究结果总结(参考天机OS) | B15: ⑯总结与决策 | C15: 竞争定位/功能完善度/买家满意度 卡片 + AI 优化建议 | D15: 模板把官方3卡扩展为10项状态卡并接入评分
A16: 竞争定位 | B16: ③市场细分与竞争格局 | C16: 主要竞品售价/评分/评论数/上线时间, 头部品牌份额环图 | D16: ③+④合看, 分卖家/品牌/商品三层看集中度
A17: 功能对比(逐项) | B17: ④相似产品与功能对比 | C17: 与类目热销品平均逐项比, 标绿优红劣 | D17: ④功能矩阵即官方逐项对比的工作底稿
A18: 买家满意度/评论洞察 | B18: ⑤VOC客户反馈·评论洞察差评分析 | C18: 评论高频优点、刚需功能、竞品差评痛点 | D18: ⑤含原话引用与“能否设计规避”判断
A19: 季节性 | B19: ⑥季节性需求，淡旺季预测 | C19: 全年流量走势、需求模式、点击份额 | D19: ⑥叠加 Google Trends + SIF 历史销量双口径
A20: 买家画像 | B20: ⑫买家画像与购买路径 | C20: 年龄/性别/收入等特征 | D20: ⑫扩展 ABA 全维度 + 行为路径 + Persona画像分析
A21: 市场细分 | B21: ③市场细分与竞争格局 商家探测器 选品指南针 | C21: 细分市场品牌与自营份额 商家探测器 选品指南针 | D21: ③含搜索量/增速/退货/转化等大盘指标
A23: 三、官方调研问卷中“卖家最想要的额外信息”(缺口) → 模板补足
A24: 卖家缺口(官方问卷选项) | B24: 模板补足位置 | C24: 关键内容
A25: 季节性需求预测(淡旺季) | B25: ⑥季节性需求预测 | C25: 近2年销量指数 + Google趋势 + 淡旺季系数公式 + 备货节奏
A26: 预计广告费用/投入产出/难易 | B26: ⑦广告费用·投入产出预测 | C26: 目标CPC公式、盈亏平衡ACOS、预算节奏表
A27: 利润率/盈利预测(含FBA费) | B27: ⑧利润率与盈利预测 | C27: 佣金/FBA配送/仓储/头程/关税全链路单位经济 + 现金流
A28: 供应商/采购成本基准 | B28: ⑨供应商与采购成本基准 | C28: 多家询价对比 + 目标采购价上限反推
A29: “假设”情景建模(不同价格点) | B29: ⑩What-if情景建模 | C29: 低价/目标/促销/提价多情景利润与回本测算
A30: 跨市场潜力(美国→欧盟等) | B30: ⑪跨市场潜力(US→EU) | C30: 需求/竞争/合规/广告友好打分 + 分批次拓展
A31: 客户画像(人口/收入/行为/路径) | B31: ⑫买家画像与购买路径 | C31: ABA人口统计 + 搜索/点击/购买路径 + Persona
A33: 四、数据来源三通道(官方问卷: 评估新品时用过什么)
A34: 通道 | B34: 典型工具 | C34: 在模板中位置 | D34: 最适合补什么
A35: 人工调研(免费) | B35: Google Trends / 前台竞品列表 / 买家评论逐条阅读 | C35: ⑥季节、④竞品、⑤VOC | D35: 宏观趋势、一手买家语言、验证官方数据
A36: 第三方工具 | B36: SIF(历史销量/自然vs广告流量) / Helium10 / 卖家精灵 / 极目 | C36: ④竞品历史、⑦广告、⑨成本 | D36: 官方不给的细节: 竞品历史曲线、CPC、FBA利润拆分
A37: 亚马逊官方 | B37: 商机探测器(POE) / ABA品牌分析 / 选品指南针 / 广告后台 | C37: ③市场、⑤VOC、⑫画像 | D37: 搜索需求、转化率、退货率、人口统计等第一方数据
A39: 五、填表规则与图例
A40: 黄色单元格 | B40: 需要您手工填写的输入项(证据/数据/判断)
A41: 灰色单元格 | B41: 公式自动计算, 请勿覆盖
A42: 绿色 N / 黄色 U / 红色 F | B42: 状态三色: N=已验证通过; U=未知, 需人工确认后打N或F; F=否决(出现即终止)
A43: 硬否决 | B43: 知识产权与合规认证: F → 立即否决, 不做后续评分
A44: 快照日 | B44: 官方提示: 搜索量/竞争/成本持续变化, 超30天的数据需重新验证

Sheet ②产品概念输入卡
A1: ② 产品概念输入卡
A2: 对标官方「选品模拟器」输入项(店铺→语言→标题→类目→目标售价→描述→≥3要点)。黄色列=请填写; 灰色斜体=官方示例(德国站 PP+麦秸砧板, 可对照后清除)。
A4: 输入字段(官方口径) | B4: 必填 | C4: 请填写(启动时) | D4: 填写说明 | E4: 官方示例——砧板(德国站)
A5: 站点/商城 | B5: 是 | D5: 官方支持商城以您后台实际可见为准(示例为德国站) | E5: 德国(amazon.de) | F5: 工厂 提供产品模型 图片，参考图
A6: 输入语言 | B6: 是 | D6: 与站点匹配 | E6: 德语(Deutsch)
A7: 产品名称/标题 | B7: 是 | D7: ≥3个词; 官方提示: 更具描述性的标题能提高模拟精度 | E7: Original Schneidebrett aus PP & Weizenstroh, Saftrille, Frankfurter Brett, 32x20
A8: 产品类目 | B8: 是 | D8: 先定类目节点(BSR路径) | E8: 厨房、家居及生活
A9: 目标售价 | B9: 是 | D9: 当地币种; 先看③价格带再定 | E9: 30
A10: 产品描述 | B10: 是 | D10: ≥10个词, 说明材质/尺寸/结构/场景 | E10: PP材质与麦秸制成, 导流槽+把手, 法兰克福式设计, 可放入洗碗机, 抗菌, 面包板/切菜板两用 | F10: 工厂提供基本参数
A11: 要点1 | B11: 是 | D11: ≥3个要点(官方要求), 每行一条 | E11: 最佳套装: 尺寸多样、经久耐用、保护刀具
A12: 要点2 | B12: 是 | E12: 优质材料: 双面防滑, 适合水果蔬菜奶酪肉类
A13: 要点3(+4-5可选) | B13: 是 | E13: 洗碗机安全、易清洗、抗菌
A15: 目标关键词(核心+长尾) | B15: 否 | D15: 供 ABA/广告/SIF 使用 | E15: Schneidebrett / Frankfurter Brett / antibakteriell Schneidebrett
A16: 对标ASIN清单(5-10个) | B16: 否 | D16: 官方可选: 系统匹配不准时可手动指定竞品 | E16: 从④竞品清单回填
A17: 目标参数/功能清单 | B17: 否 | D17: 供④功能对比与⑮知识产权检索用 | E17: 32x20cm; 导流槽; 把手; 抗菌; 洗碗机安全
A18: 目标人群/场景 | B18: 否 | D18: 回⑫画像核对 | E18: 注重食品安全/环保的德国家庭厨房用户
A19: 概念一句话(名称+卖点+参数) | B19: 否 | D19: 项目代号, 用于汇报 | E19: PP+麦秸抗菌砧板(32x20), 法兰克福式带导流槽把手, 可洗碗机
A20: 快照日 | B20: 否 | D20: 数据抓取日期 | E20: 2026-09-09
A22: 官方工具局限提醒: 该模拟器 = 发现/验证工具而非完整决策系统; 制造成本、FBA费用、广告成本、合规、供应商交期等仍需外部尽调——本模板③-⑮正是补足这些环节。

Sheet ③市场细分与竞争格局
A1: ③ 市场细分与竞争格局
A2: 对标官方输出模块「竞争定位 + 市场细分」。数据源: 商机探测器(细分市场/商品/搜索词视图) + 卖家精灵类目分析 + 选品指南针。每个数值注明来源与快照日。
A4: 一、细分市场关键指标
A5: 指标 | B5: 数值(填) | C5: 口径 / 来源 / 说明
A6: 细分市场(搜索词集合) | C6: 官方口径: 把相关搜索词归为一个利基市场; 记录入口链接
A7: 月搜索量(当地) | C7: 官方数据, 记站点
A8: 搜索量同比增速 | C8: 小数: 0.2 = +20%
A9: 近12个月阶段判断 | C9: 爬坡 / 平稳 / 衰退
A10: 在售商品链接数(剔除变体) | C10: 供给密度判断用
A11: 子类目月销售额估算 | C11: 当地币种, 注明估算方法
A12: 头部商品月销中位数 | C12: 件/月; 判断容量下限
A13: 平均售价 | C13: 当地币种
A14: 平均评分 / 中位评论数 | C14: 评论壁垒判断用
A15: 新品销量占比(近6月/近1年) | C15: 标注插件口径, 官方新品占比可另记
A16: 自营占比: 链接数 / 销量 | C16: 两个口径分开记
A17: 集中度 CR5: 卖家 / 品牌 / 商品 | C17: 三层分开, 禁止合并成一个数
... A21: 快照日 | C21: yyyy-mm-dd
A23: 二、结构体检结论(状态 N=通过 / U=待确认 / F=否决)
A24: 体检项 | B24: 状态(N/U/F) | C24: 结论与依据(引用上方数据)
A25: 类目容量与增速 | B25: U | C25: 市场是否足够大且向上(容量不足或明确衰退 → F)
A26: 集中度(卖家/品牌/商品三层) | B26: U | C26: CR5 过高 → 突破成本高 → 预警
A27: 供给密度 | B27: U | C27: 链接过多而有效流量有限 → 新品难获曝光
A28: 新品友好度 | B28: U | C28: 新品销量占比过低 → 类目对新品不友好
A29: 退货与转化 | B29: U | C29: 决定⑦广告模型是否成立
A30: 结构体检小结 | B30: U | C30: 一段话总结可进/慎进/不进

Sheet ④相似产品分析与功能对比
A1: ④ 相似产品分析与功能对比
A2: 对标官方「相似产品分析——逐项功能对比」: 表一为竞品清单(行=竞品ASIN), 表二为功能逐项对比矩阵(我方 vs 类目热销平均 vs 主要竞品)。蓝色行按②输入自动带出。
A4: ASIN | B4: 品牌 | C4: 标题摘要 | D4: 售价 | E4: 评分 | F4: 评论数 | G4: BSR | H4: 月销(官方) | I4: Score效率 | J4: 上架时间 | K4: 核心卖点 | L4: 主要差评点 | M4: 与我差异化机会
A16: 二、逐项功能对比矩阵: 我方概念 vs 类目热销平均(官方模式: 绿=我优 红=我劣)
A17: 功能/规格项 | B17: 我方概念 | C17: 类目热销平均 | D17: 竞品1 | E17: 竞品2 | F17: 竞品3 | G17: 竞品4 | H17: 竞品5 | M17: 状态(优/劣/持平/不适用)
A18: 材质
A19: 尺寸/规格(cm)
A20: 重量
A21: 核心功能1
A22: 核心功能2
A23: 附加功能/配件
A24: 包装与说明书
A25: 认证与合规(食品接触/CE等)
A29: 记分提示: 行数不够自行插入; 功能项按②“目标参数/功能清单”展开。Score效率 = 官方月销 ÷ 评论数(蓝海度排序键, 自动计算)。

Sheet ⑤VOC客户反馈·评论洞察
A1: ⑤ VOC 客户反馈 · 评论洞察
A2: 对标官方「买家满意度/评论洞察」: 官方会统计评论高频优点、刚需功能与竞品高频差评痛点。样本=TOP10竞品及核心ASIN的当前可见评论, 原话逐字引用不改写, 频次=该点出现数÷样本评论数。
A4: 一、样本与评分分布
A5: 项目 | B5: 数量 | C5: 占比(自动) | F5: 说明
A6: 样本评论总数 | F6: 统计范围: 哪些ASIN的多少条评论
A8: 5星 | C8: =IF($B$7="","",IFERROR($B8/$B$7,"")) | D8: 评价分布用于判断质量结构, 若样本=竞品合并评论请注明
A9: 4星 | C9: =IF($B$7="","",IFERROR($B9/$B$7,"")) | D9: 评价分布用于判断质量结构, 若样本=竞品合并评论请注明
A10: 3星 | C10: =IF($B$7="","",IFERROR($B10/$B$7,"")) | D10: 评价分布用于判断质量结构, 若样本=竞品合并评论请注明
A11: 2星 | C11: =IF($B$7="","",IFERROR($B11/$B$7,"")) | D11: 评价分布用于判断质量结构, 若样本=竞品合并评论请注明
A12: 1星 | C12: =IF($B$7="","",IFERROR($B12/$B$7,"")) | D12: 评价分布用于判断质量结构, 若样本=竞品合并评论请注明
A14: 二、差评TOP痛点(机会点来源)
A15: 痛点聚类 | B15: 提及次数 | C15: 样本占比 | D15: 买家原话(逐字引用) | E15: 能否设计规避(是/否) | F15: 机会点/对应优化
A23: 三、好评TOP卖点(买家用语 = 最强文案)
A24: 卖点聚类 | B24: 提及次数 | C24: 样本占比 | D24: 买家原话(逐字引用) | E24: 可用作(Listing/广告/包装) | F24: 对应的功能证据
A32: 结论输出格式(照抄成卡): 差评TOP1 痛点[频次%] 原话:“…” / 好评TOP1 卖点[频次%] 原话:“…” → 差评机会代表ASIN回填④。

Sheet ⑥季节性需求预测
A1: ⑥ 季节性需求预测
A2: 对标官方输出模块「季节性(全年流量/需求/点击份额)」+ 官方问卷缺口。数据: 竞品历史销量指数(SIF) + Google Trends(3-5年曲线) + 类目点击份额。系数=各列平均, ≥1.15旺季 ≤0.85淡季。
A4: 月份 | B4: 2024销量指数 | C4: 2025销量指数 | D4: Google趋势(近3年典型) | E4: 类目点击份额/需求指数 | F4: 淡旺季系数(自动) | G4: 判定(自动) | H4: 备货/广告备注
A5: 1月 | F5: =IF(COUNT(B5:E5)=0,"",ROUND(AVERAGE(B5:E5),2)) | G5: =IF($F5="","",IF($F5>=1.15,"旺季",IF($F5<=0.85,"淡季","平季")))
A6: 2月 | F6: =IF(COUNT(B6:E6)=0,"",ROUND(AVERAGE(B6:E6),2)) | G6: =IF($F6="","",IF($F6>=1.15,"旺季",IF($F6<=0.85,"淡季","平季")))
A7: 3月 | F7: =IF(COUNT(B7:E7)=0,"",ROUND(AVERAGE(B7:E7),2)) | G7: =IF($F7="","",IF($F7>=1.15,"旺季",IF($F7<=0.85,"淡季","平季")))
A8: 4月 | F8: =IF(COUNT(B8:E8)=0,"",ROUND(AVERAGE(B8:E8),2)) | G8: =IF($F8="","",IF($F8>=1.15,"旺季",IF($F8<=0.85,"淡季","平季")))
A9: 5月 | F9: =IF(COUNT(B9:E9)=0,"",ROUND(AVERAGE(B9:E9),2)) | G9: =IF($F9="","",IF($F9>=1.15,"旺季",IF($F9<=0.85,"淡季","平季")))
A10: 6月 | F10: =IF(COUNT(B10:E10)=0,"",ROUND(AVERAGE(B10:E10),2)) | G10: =IF($F10="","",IF($F10>=1.15,"旺季",IF($F10<=0.85,"淡季","平季")))
A11: 7月 | F11: =IF(COUNT(B11:E11)=0,"",ROUND(AVERAGE(B11:E11),2)) | G11: =IF($F11="","",IF($F11>=1.15,"旺季",IF($F11<=0.85,"淡季","平季")))
A12: 8月 | F12: =IF(COUNT(B12:E12)=0,"",ROUND(AVERAGE(B12:E12),2)) | G12: =IF($F12="","",IF($F12>=1.15,"旺季",IF($F12<=0.85,"淡季","平季")))
A13: 9月 | F13: =IF(COUNT(B13:E13)=0,"",ROUND(AVERAGE(B13:E13),2)) | G13: =IF($F13="","",IF($F13>=1.15,"旺季",IF($F13<=0.85,"淡季","平季")))
A14: 10月 | F14: =IF(COUNT(B14:E14)=0,"",ROUND(AVERAGE(B14:E14),2)) | G14: =IF($F14="","",IF($F14>=1.15,"旺季",IF($F14<=0.85,"淡季","平季")))
A15: 11月 | F15: =IF(COUNT(B15:E15)=0,"",ROUND(AVERAGE(B15:E15),2)) | G15: =IF($F15="","",IF($F15>=1.15,"旺季",IF($F15<=0.85,"淡季","平季")))
A16: 12月 | F16: =IF(COUNT(B16:E16)=0,"",ROUND(AVERAGE(B16:E16),2)) | G16: =IF($F16="","",IF($F16>=1.15,"旺季",IF($F16<=0.85,"淡季","平季")))
A18: 结论区
A19: 判断项 | B19: 结论/值 | C19: 依据(哪条曲线/口径)
A20: 旺季窗口(月份)
A21: 离旺季提前备货月数 | C21: 采购交期+头程时间(对接⑨)
A22: 淡季资金占用预警 | C22: 淡季销量倍数, 占压资金金额
A23: 季节判定(N/U/F) | C23: 强季节品若错过窗口 → 慎重
A24: 进场时机结论 | C24: 现在入场距旺季还有几个月, 是否赶得上

Sheet ⑦广告费用·投入产出
A1: ⑦ 广告费用 · 投入产出预测
A2: 公式(本模板标准口径): 目标CPC = 目标ACOS × 客单价 × 广告点击转化率; 盈亏平衡ACOS = 单位毛利额 ÷ 售价。数据源: 广告后台建议竞价(≠实际CPC, 需观察实际值) + 卖家精灵 + 商机探测器转化率。
A4: 参数 | B4: 值 | C4: 口径 / 说明
A5: 目标售价(当地币) | C5: 与②同步
A6: 盈亏平衡ACOS
A7: 目标ACOS(经营目标) | C7: 新品期可放宽, 放量期收紧
A8: 类目平均点击转化率 | C8: 来自③; 商品与搜索词口径交叉
A9: 新品转化折扣系数 | C9: 新品listing通常低于类目均值, 经验值0.5-0.8
A10: 预估新品点击转化率(自动) | B10: =IF(OR($B$8="",$B$9=""),"",$B$8*$B$9) | C10: 类目转化率 × 新品折扣系数
A11: 核心词CPC取值(实际观察/估算) | C11: 建议竞价≠实际CPC: 请填广告后台实际观察或估算中值
A12: 预估实际CPC(自动) | B12: =IF($B$11="","",$B$11) | C12: =上格观察值(建议竞价仅为参考) -> #NAME?
A13: 目标CPC(自动) | B13: =IF(OR($B$5="",$B$7="",$B$10=""),"",$B$7*$B$5*$B$10) | C13: =目标ACOS × 售价 × 预估转化率 -> #NAME?
A14: CPA(自动) | B14: =IF(OR($B$13="",$B$10=""),"",IFERROR($B$13/$B$10,"")) | C14: =目标CPC ÷ 预估转化率 -> #NAME?
A15: 广告经济性判定(自动) | B15: =IF(OR($B$12="",$B$13=""),"",IF($B$12<=$B$13,"可行: 实际CPC≤目标CPC","不可行: 需降价/优化转化率/换词再测")) | C15: 实际CPC ≤ 目标CPC 才可行
A16: 广告难度(1-5)与理由 | C16: 5=极难
A18: 推广预算节奏
A19: 阶段 | B19: 周期 | C19: 预算安排与目标
A20: 冷启动期 | B20: 0-30天 | C20: 自动+精准手动跑收录; 合规积累评论(Vine等); 盯自然位起量; 建议日预算:____
A21: 放量期 | B21: 31-90天 | C21: 核心词卡位; Deal/促销配合冲排名与新品销量占比; 建议日预算:____
A22: 收割期 | B22: 91-180天 | C22: 预算向高ROAS词集中; ACOS回落至目标以下; 自然/广告曝光占比健康度:____
A24: 健康指标: 用SIF自然/广告曝光占比变化判断“自然承接力”; 广告占比长期>70% → 商业模式不健康(预警)。

Sheet ⑧利润率与盈利预测
A1: ⑧ 利润率与盈利预测(已计入亚马逊物流费用)
A2: 全链路单位经济: 售价 − 佣金 − FBA配送 − 仓储 − 广告 − 头程 − 关税 − 采购 − 包装 = 单位毛利。黄色填, 灰色自动。佣金/FBA按您站点最新官方费率表核对(尺寸分段决定配送费)。
A4: 项目 | B4: 金额/率 | C4: 口径说明
A5: 售价(当地币) | C5: 与②同步; 注意含税口径
A6: 销售佣金率 | C6: 按官方最新费率(参考类目15%), 填小数0.15
A7: 佣金金额 | B7: =IF($B$5="","",$B$5*$B$6)
A8: FBA配送费(件) | C8: 按尺寸分段查官方费率表
A9: 月度仓储费(件/月) | C9: 淡旺季仓储费率不同, 取均值
A10: 广告费分摊(件) | C10: ≈ 预算期广告总花费 ÷ 期销量, 从⑦反推
A11: 头程物流(件) | C11: 含本地拖车/尾程
A12: 关税及其他税费(件) | C12: 按申报与税则核实
A13: 采购成本(件) | C13: 取⑨基准价
A14: 包装与配件(件) | C14: 含说明书/彩盒
A15: 可变费用合计 | B15: =IF(COUNT($B$7:$B$14)=0,"",SUM($B$7:$B$14)) | C15: 佣金+FBA+仓储+广告+头程+关税+采购+包装
A16: 单位毛利额 | B16: =IF(OR($B$5="",$B$15=""),"",$B$5-$B$15) | C16: 售价 − 可变费用合计
A17: 毛利率 | B17: =IF(OR($B$16="",$B$5=""),"",$B$16/$B$5) | C17: 单位毛利 ÷ 售价
A18: 固定成本/月 | C18: 团队/工具/账号等, 不计可变
A19: 月销量假设(件) | C19: 基于③头部中位数与④对标, 分乐观/保守
A20: 月净利(费用前) | B20: =IF(OR($B$16="",$B$18="",$B$19=""),"",$B$16*$B$19-$B$18) | C20: 单位毛利×月销 − 固定成本
A21: 盈亏平衡月销量 | B21: =IF($B$16="","",IF($B$16<=0,"售价低于可变成本",ROUND($B$18/$B$16,0))) | C21: 固定成本 ÷ 单位毛利
A23: 现金流与备货(财务问题/现金流)
A24: 项目 | B24: 金额/值 | C24: 口径说明
A25: 首批备货量(件) | C25: 按⑥旺季系数与⑨交期定
A26: 首批备货现金占用(自动) | B26: =IF(COUNT($B$25,$B$12,$B$13,$B$11)=0,"",($B$13+$B$11+$B$12)*$B$25) | C26: (采购+头程+关税) × 首批量
A27: 首批备货现金占用公式行
A28: 推广准备金(前3月广告) | C28: 从⑦预算节奏取
A29: 回款周期(天) | C29: 3P约14天滚动; VC按PO/账期(Net-XX)填实际
A30: 现金流峰值(自动) | B30: =IF(COUNT($B$26,$B$28,$B$18)=0,"",$B$26+$B$28+$B$18*3) | C30: 备货占用 + 推广准备金 + 3个月固定成本
A31: 预计回本周期(月, 自动) | B31: =IF($B$30="","",IF($B$20<=0,"未盈利无法回本",ROUND($B$30/$B$20,1))) | C31: 现金流峰值 ÷ 月净利
A32: 止损线(最大可亏损) | C32: 触发即退出, 提前定
A34: VC视角提示: 若为 Vendor Central 供货, 替换采购价=PO出厂价口径, 回款周期按账期填写, 并与您的毛利协议(如Net 成本加成/贸易条款)对齐。

Sheet ⑨供应商采购成本基准
A1: ⑨ 供应商与采购成本基准
A2: 至少询价3家(不同产业带/渠道)。把单价、MOQ、交期、打样、认证写清楚; 用“目标采购价上限”反推能接受的采购价, 供谈判。
A4: 供应商/渠道 | B4: 地区/产业带 | C4: 采购价 | D4: MOQ | E4: 打样费/周期 | F4: 大货交期 | G4: 定制/包装能力 | H4: 质量与认证 | I4: 付款条款 | J4: 响应 | K4: 评分(1-5) | L4: 备注
A11: 成本基准反推(供应链/采购成本基准)
A12: 项目 | B12: 值 | C12: 说明
A13: 最低询价(自动) | B13: =IF(COUNT(C5:C9)=0,"",MIN(C5:C9)) | C13: 5家询价中的最低价
A14: 建议计划采购价 | C14: 最低价×(1+5%容差)或直接写
A15: 头程+关税(件) | C15: 从⑧取
A16: 目标售价(当地币) | C16: 与②同步
A17: 目标毛利率(小数0.40=40%) | C17: 经营目标
A18: 允许单件总成本上限(自动) | B18: =IF(OR($B$16="",$B$17=""),"",$B$16*(1-$B$17)) | C18: 售价×(1−目标毛利率)
A19: 采购价上限(自动) | B19: =IF(COUNT($B$18,$B$15,$C5)=0,"",$B$18-$B$15-0-0) | C19: 总成本上限 − 头程关税 − FBA配送 − 包装广告
A20: 采购价达标判定(自动) | B20: =IF(OR($B$13="",$B$19=""),"",IF($B$13<=$B$19,"达标","超标: 需谈判降价或上调售价/毛利目标")) | C20: 最低询价 ≤ 采购价上限?
A21: 综合评分最优供应商(结论) | C21: 质量×交期×价格综合, 写名字
A23: 注: 采购价上限公式里的“FBA配送+包装广告”两项请在⑧取值后手工并入判断; 表格含公式演示, 不替代财务精确测算。

Sheet ⑩What-if情景建模
A1: ⑩ What-if 情景建模(不同价格点/销量)
A2: 回答“不同价格点下赚不赚钱、回本要多久”。灰色列自动计算; 黄色填写。单位可变成本从⑧“可变费用合计”取数(不含广告与固定成本则直接引用)。
A4: 共用假设(所有情景一致)
A5: 项目 | B5: 值 | C5: 说明
A6: 固定成本/月(从⑧) | C6: 团队/工具等
A8: 首批投入(备货+前3月推广) | C8: 从⑧现金流取
A10: 情景 | B10: 售价 | C10: 月销量(件) | D10: 单位可变成本(件) | E10: 单位毛利(自动) | F10: 月收入(自动) | G10: 月可变总成本(自动) | H10: 月毛利(自动) | I10: 广告费率 | J10: 月广告费(自动) | K10: 月固定成本(自动) | L10: 月净利(自动) | M10: 毛利率(自动) | N10: 回本周期(月, 自动) | O10: 备注/建议
A11: 基准(当前目标定价) | E11: =IF(OR($B11="",$D11=""),"",$B11-$D11) | F11: =IF(OR($B11="",$C11=""),"",$B11*$C11) | G11: =IF(OR($D11="",$C11=""),"",$D11*$C11) | H11: =IF(OR($B11="",$D11="",$C11=""),"",($B11-$D11)*$C11) | J11: =IF(OR($I11="",$F11=""),"",$F11*$I11) | K11: =$C$7 -> 0 | L11: =IF(COUNT($H11,$J11,$K11)<2,"",$H11-$J11-$K11) | M11: =IF($E11="","",IF($B11=0,"",$E11/$B11)) | N11: =IF($L11="","",IF($L11<=0,"无法回本",ROUND($C$9/$L11,1)))
A12: 低价走量(−15%) | E12: =IF(OR($B12="",$D12=""),"",$B12-$D12) | F12: =IF(OR($B12="",$C12=""),"",$B12*$C12) | G12: =IF(OR($D12="",$C12=""),"",$D12*$C12) | H12: =IF(OR($B12="",$D12="",$C12=""),"",($B12-$D12)*$C12) | J12: =IF(OR($I12="",$F12=""),"",$F12*$I12) | K12: =$C$7 -> 0 | L12: =IF(COUNT($H12,$J12,$K12)<2,"",$H12-$J12-$K12) | M12: =IF($E12="","",IF($B12=0,"",$E12/$B12)) | N12: =IF($L12="","",IF($L12<=0,"无法回本",ROUND($C$9/$L12,1)))
A13: 促销/大促价(−20%) | E13: =IF(OR($B13="",$D13=""),"",$B13-$D13) | F13: =IF(OR($B13="",$C13=""),"",$B13*$C13) | G13: =IF(OR($D13="",$C13=""),"",$D13*$C13) | H13: =IF(OR($B13="",$D13="",$C13=""),"",($B13-$D13)*$C13) | J13: =IF(OR($I13="",$F13=""),"",$F13*$I13) | K13: =$C$7 -> 0 | L13: =IF(COUNT($H13,$J13,$K13)<2,"",$H13-$J13-$K13) | M13: =IF($E13="","",IF($B13=0,"",$E13/$B13)) | N13: =IF($L13="","",IF($L13<=0,"无法回本",ROUND($C$9/$L13,1)))
A14: 适度提价(+10%) | E14: =IF(OR($B14="",$D14=""),"",$B14-$D14) | F14: =IF(OR($B14="",$C14=""),"",$B14*$C14) | G14: =IF(OR($D14="",$C14=""),"",$D14*$C14) | H14: =IF(OR($B14="",$D14="",$C14=""),"",($B14-$D14)*$C14) | J14: =IF(OR($I14="",$F14=""),"",$F14*$I14) | K14: =$C$7 -> 0 | L14: =IF(COUNT($H14,$J14,$K14)<2,"",$H14-$J14-$K14) | M14: =IF($E14="","",IF($B14=0,"",$E14/$B14)) | N14: =IF($L14="","",IF($L14<=0,"无法回本",ROUND($C$9/$L14,1)))
A15: 防御价(跟竞品) | E15: =IF(OR($B15="",$D15=""),"",$B15-$D15) | F15: =IF(OR($B15="",$C15=""),"",$B15*$C15) | G15: =IF(OR($D15="",$C15=""),"",$D15*$C15) | H15: =IF(OR($B15="",$D15="",$C15=""),"",($B15-$D15)*$C15) | J15: =IF(OR($I15="",$F15=""),"",$F15*$I15) | K15: =$C$7 -> 0 | L15: =IF(COUNT($H15,$J15,$K15)<2,"",$H15-$J15-$K15) | M15: =IF($E15="","",IF($B15=0,"",$E15/$B15)) | N15: =IF($L15="","",IF($L15<=0,"无法回本",ROUND($C$9/$L15,1)))
A17: 读法: 基准情景为正且回本周期可接受 → 通过; 只有促销价才盈利 → 定价偏低或成本偏高; 全部为负 → 回⑧找成本项。

Sheet ⑪跨市场潜力US-EU
A1: ⑪ 跨市场潜力(美国推出 → 拓展欧盟及其他)
A2: 官方问卷缺口“跨市场潜力”。规则: 美国站先验证; 每站打4个分(1-5), 加权潜力分 = 需求0.35+竞争友好0.25+合规友好0.20+广告友好0.20。合规要求以欧盟官方最新执行为准(如GPSR、EPR/包装法、WEEE、电池法规、VAT/EORI)。
A4: 目标市场 | B4: 主语言 | C4: 需求信号分 (1-5) | D4: 竞争友好分 (1-5高=友好) | E4: 合规友好分 (1-5) | F4: 广告友好分 (1-5) | G4: 加权潜力分 (自动) | H4: 建议(自动) | I4: 认证/合规差异点 | J4: 税务与进口要点 | K4: 本地化要点 | L4: 优先级(第几批)
A5: 美国(基准站) | B5: 英语 | G5: =IF(COUNT(C5:F5)<4,"",ROUND(0.35*C5+0.25*D5+0.2*E5+0.2*F5,2)) | H5: =IF($G5="","",IF($G5>=4,"优先扩展",IF($G5>=3,"观察/第二批","暂缓"))) | J5: 先在美站验证, 数据从③-⑧回填 | K5: 基准 | L5: US: 消费类标准(FCC/CPC按品类)
A6: 德国 | B6: 德语 | G6: =IF(COUNT(C6:F6)<4,"",ROUND(0.35*C6+0.25*D6+0.2*E6+0.2*F6,2)) | H6: =IF($G6="","",IF($G6>=4,"优先扩展",IF($G6>=3,"观察/第二批","暂缓"))) | J6: EU最大站, 广告成本高但容量大 | K6: 观察 | L6: GPSR责任人/包装法EPR/WEEE按品类
A7: 英国 | B7: 英语 | G7: =IF(COUNT(C7:F7)<4,"",ROUND(0.35*C7+0.25*D7+0.2*E7+0.2*F7,2)) | H7: =IF($G7="","",IF($G7>=4,"优先扩展",IF($G7>=3,"观察/第二批","暂缓"))) | J7: 脱欧后独立关税区 | K7: 观察 | L7: UKCA/包装法EPR
A8: 法国 | B8: 法语 | G8: =IF(COUNT(C8:F8)<4,"",ROUND(0.35*C8+0.25*D8+0.2*E8+0.2*F8,2)) | H8: =IF($G8="","",IF($G8>=4,"优先扩展",IF($G8>=3,"观察/第二批","暂缓"))) | J8: 语言本地化要求高 | K8: 观察 | L8: EPR/Triman标识
A9: 意大利 | B9: 意大利语 | G9: =IF(COUNT(C9:F9)<4,"",ROUND(0.35*C9+0.25*D9+0.2*E9+0.2*F9,2)) | H9: =IF($G9="","",IF($G9>=4,"优先扩展",IF($G9>=3,"观察/第二批","暂缓"))) | K9: 观察 | L9: EPR包装法
A10: 西班牙 | B10: 西班牙语 | G10: =IF(COUNT(C10:F10)<4,"",ROUND(0.35*C10+0.25*D10+0.2*E10+0.2*F10,2)) | H10: =IF($G10="","",IF($G10>=4,"优先扩展",IF($G10>=3,"观察/第二批","暂缓"))) | K10: 观察 | L10: EPR
A11: 日本 | B11: 日语 | G11: =IF(COUNT(C11:F11)<4,"",ROUND(0.35*C11+0.25*D11+0.2*E11+0.2*F11,2)) | H11: =IF($G11="","",IF($G11>=4,"优先扩展",IF($G11>=3,"观察/第二批","暂缓"))) | J11: 认证门槛高(PSE/食品卫生按品类) | K11: 观察 | L11: PSE/药机法等按品类
A12: 加拿大 | B12: 英语/法语 | G12: =IF(COUNT(C12:F12)<4,"",ROUND(0.35*C12+0.25*D12+0.2*E12+0.2*F12,2)) | H12: =IF($G12="","",IF($G12>=4,"优先扩展",IF($G12>=3,"观察/第二批","暂缓"))) | K12: 观察 | L12: 双语包装(魁北克)
A13: 澳大利亚 | B13: 英语 | G13: =IF(COUNT(C13:F13)<4,"",ROUND(0.35*C13+0.25*D13+0.2*E13+0.2*F13,2)) | H13: =IF($G13="","",IF($G13>=4,"优先扩展",IF($G13>=3,"观察/第二批","暂缓"))) | K13: 观察 | L13: 清洁产品/食品接触认证
A15: 递进逻辑: 美国测概念与评论模型 → 德国验证欧洲(合规成本最高者先行) → 同模板再跑英/法/意/西 → 再看日/加/澳。每站必须重跑③⑤⑥⑧(需求/评论/季节/费用不同), 不要直接平移结论。

Sheet ⑫买家画像购买路径
A1: ⑫ 买家画像与购买路径(最可能的历史购买者)
A2: 对标官方「买家画像」+ 官方问卷缺口“人口统计/收入/行为/购买路径/购物旅途”。数据源: ABA品牌分析(人口统计/搜索词/购物篮/比较替代) + 商机探测器买家洞察。
A4: 一、ABA 人口统计(占比%)
A5: 维度 | B5: 值(占比%) | C5: 解读/对决策的影响 | D5: 广告用途
A6: 年龄 18-24 | D6: 年轻组低价敏感, 社媒触达
A7: 年龄 25-34 | D7: 核心家庭决策组
A8: 年龄 35-44
A9: 年龄 45-54
A10: 年龄 55+
A11: 性别占比
A12: 家庭收入区间 | D12: 定价与高端线判断
A13: 教育程度
A15: 二、行为数据: 购买路径与购物旅途(ABA/商机探测器)
A16: 行为维度 | B16: 关键证据(词/ASIN/数据) | C16: 洞察与用途
A17: 高频搜索词TOP(搜索频率排名) | C17: 核心入口词 → 写标题/广告
A18: 高点击份额词 | C18: 买家在比什么
A19: 高转化份额词 | C19: 下单意图最强的词 → 优先卡位
A20: 关联购买(市场购物篮分析) | C20: 还买了什么 → 捆绑/交叉
A21: 商品比较与替代购买 | C21: 和谁比、替代了谁 → ④竞品名单依据
A22: 重复购买行为 | C22: 是否易复购 → 老客营销
A23: 搜索→点击→购买路径特征 | C23: 决策链长度, 在哪个节点流失
A25: 三、Persona 画像卡(3类典型买家)
A26: 画像名称 | B26: 人口特征 | C26: 场景/触发点/为什么买 | D26: 在意功能(引⑤VOC)与定向
A31: 画像要回答: 谁买 / 什么场景 / 为什么买 / 在意什么 → 直接决定 Listing 文案第一屏与广告定向受众。

Sheet ⑬数据源与工具矩阵
A1: ⑬ 数据源与工具矩阵(证据台账)
A2: 每次执行把用到的渠道打勾并记快照日, 保证“任何结论可回溯”。官方>插件估算>推算, 分层标注。
A4: 决策维度 | B4: 亚马逊官方工具 | C4: 第三方工具 | D4: 人工/免费方法 | E4: 模板表 | F4: 备注(分层/时效)
A5: 需求规模与增速 | B5: 商机探测器(细分市场搜索量/增速) | C5: SIF类目趋势, Helium10 Black Box | D5: Google Trends, 前台搜索结果量 | E5: ③ | F5: 官方>估算
A6: 关键词与流量入口 | B6: ABA搜索词(频率/点击/转化份额) | C6: SIF关键词反查, 卖家精灵, Helium10 Cerebro/Magnet | D6: 亚马逊搜索框联想 | E6: ③④⑫
A7: 竞品销售与历史 | B7: 商机探测器商品数据 | C7: SIF历史销量/自然vs广告流量, 卖家精灵 | D7: 前台月销下限值“X+ bought” | E7: ④ | F7: 官方月销为下限值口径
A8: 结构/集中度(三层) | B8: 商机探测器 | C8: 卖家精灵类目分析 | D8: 手动数头部品牌 | E8: ③ | F8: 卖家/品牌/商品分开
A9: 季节与宏观趋势 | B9: 商机探测器需求趋势 | C9: SIF历史曲线(12月+) | D9: Google Trends 3-5年曲线 | E9: ⑥ | F9: 看多年, 别看3个月
A10: 客户反馈VOC | B10: 商机探测器评论洞察 | C10: 卖家精灵评论分析/选评 | D10: 逐条读差评原文 | E10: ⑤ | F10: 原话引用不改写
A11: 买家画像 | B11: ABA人口统计/购物篮/比较替代 | C11: Helium10/卖家精灵人群推测 | D11: 问卷/客服记录 | E11: ⑫ | F11: 官方为第一方数据
A12: 广告竞价与难度 | B12: 广告后台建议竞价/实际CPC | C12: 卖家精灵CPC, Helium10 | D12: 手动投小预算实测 | E12: ⑦ | F12: 实际CPC≠建议竞价
A13: 利润率/FBA费用 | B13: 官方FBA费用计算器/费率表 | C13: Helium10利润计算器 | D13: 按尺寸段手动核算 | E13: ⑧ | F13: 以官方费率表为准
A14: 退货与转化 | B14: 商机探测器退货率/转化率, 选品指南针 | C14: 极目转化率 | D14: —— | E14: ③ | F14: 子类目口径
A15: 价格带 | B15: 商机探测器价格数据 | C15: 卖家精灵价格分布 | D15: 前台比价 | E15: ④⑩
A16: 知识产权与合规 | B16: 官方无检索工具(需外部) | C16: Google Patents/Espacenet/EUIPO | D16: 专利律师复核 | E16: ⑮ | F16: 硬否决: F即终止
A18: 官方工具定位: 商机探测器=发现市场机会; 选品模拟器(Validate Product Ideas)=把具体创意与类目优秀产品对比做验证; ABA=已上架品牌做精细化(词/画像/购物篮)。三者配合本模板的财务/供应链/合规环节才构成完整决策。

Sheet ⑭概念概要优化建议
A1: ⑭ 产品概念概要 + 产品优化建议
A2: 对标官方报告里最有价值的两块: “产品概念概要”把创意一句话讲清楚; “产品优化建议”给出可执行动作(官方示例话术: 差异化有限则突出最大优势、加大质量与广告投入)。
A4: 一、产品概念概要
A5: 要素 | B5: 内容
A6: 一句话概念
A7: 目标用户/使用场景
A8: 核心差异化卖点TOP3
A9: 价格带定位
A10: 信任与冷启动策略
A11: 风险TOP3
A13: 二、产品优化建议(每条必须可执行、可验证)
A14: 优化建议 | B14: 信息来源模块(④竞品/⑤VOC/⑥季节/⑨供应商等) / 优先级(高/中/低) / 预期影响
A23: 写建议的公式: 证据(差评/功能差距/季节窗口/成本空间) → 动作(改功能/改文案/改价格/改供应链) → 预期(提升转化/降低退货/节省成本)。

Sheet ⑮评分与决策
A1: ⑮ 15项审核 + 10项加权评分
A2: 规则: 状态 N=已验证 / U=未知需人工确认 / F=否决。任何F → 整体否决; U项不得猜着打分, 转为待确认。知识产权与合规为硬否决(标红行)。
A4: 一、15项审核(N/U/F)
A5: # | B5: 审核项 | C5: 对应表 | D5: 验证标准(示例) | E5: 状态 | F5: 证据 / 快照日
A6: 1 | B6: 团队资源与进入策略 | C6: ⑭ | D6: 预算/能力/切入点明确 | E6: U
A7: 2 | B7: 需求规模与容量 | C7: ③ | D7: 头部月销中位数达标(按类目定阈值) | E7: U
A8: 3 | B8: 增长与季节阶段 | C8: ⑥ | D8: 同比为正, 无致命季节陷阱 | E8: U
A9: 4 | B9: 商品/品牌集中度 | C9: ③ | D9: CR10未过度垄断(三层分开看) | E9: U
A10: 5 | B10: 卖家结构与自营 | C10: ③ | D10: 自营占比可接受 | E10: U
A11: 6 | B11: 供给密度 | C11: ③ | D11: 在售链接未过度饱和 | E11: U
A12: 7 | B12: 新品友好度 | C12: ③ | D12: 新品有起量先例 | E12: U
A13: 8 | B13: 评论壁垒 | C13: ④ | D13: 中位评论量可实现(Vine+时间) | E13: U
A14: 9 | B14: 价格带缺口 | C14: ④⑩ | D14: 存在可切入价格带且利润成立 | E14: U
A15: 10 | B15: 差异化与竞品矩阵 | C15: ④⑭ | D15: 差异化切口成立(逐项对比有绿区) | E15: U
A16: 11 | B16: VOC痛点可规避 | C16: ⑤ | D16: TOP3痛点能设计规避 | E16: U
A17: 12 | B17: 类目流量与关键词入口 | C17: ⑦⑬ | D17: 核心词有规模、入口清晰 | E17: U
... A20: 15 | B20: 单位经济与资金效率 | C20: ⑧⑩ | D20: 净利与回本周期达标 | E20: U
A21: 16 | B21: 知识产权检索(硬否决) 合规排查（专利检索） | C21: ⑮下方说明 | D21: 有效相关专利族=0(DE/EP/RCD, 同族去重) | E21: U | F21: ⑭合规排查（专利检索）
A22: 17 | B22: 产品上市时间 | E22: U
A23: 18 | B23: 产品立项表 | E23: U
A24: 19 | B24: 产品规格书 | E24: U
A25: 20 | B25: 财务 项目ROI核算（产品名称） | E25: U
A26: 21 | B26: 单品利润测算 | E26: U
A27: 22 | B27: 亚马逊评论，QA&RV分析 | E27: U
A28: 23 | B28: 竞品分析 | E28: U
A29: 24 | B29: 市场大盘分析 | E29: U
A30: 25 | B30: 类目top100打标数据 | E30: U
A31: 26 | B31: 类目top200数据 | E31: U
A32: 27 | B32: 站内竞争情况 | E32: U
A33: 28 | B33: 站外竞争情况 | E33: U
... A35: 30 | B35: 谷歌趋势 | E35: U
A37: 硬否决行出现F → 终止并出具否决报告; 出现U → 必须先人工确认(检索由用户或专业法务复核)才可进入评分。
A39: 二、10项加权评分(得分1-5, 满分5)
A40: # | B40: 评分项 | C40: 权重 | D40: 数据来源 | E40: 得分(1-5) | F40: 加权分(自动)
A41: 1 | B41: 市场机会与增速 | C41: 0.15 | D41: ③⑥ | F41: =IF($E41="","",ROUND($E41*$C41,2))
A42: 2 | B42: 竞争结构与难度 | C42: 0.1 | D42: ③④ | F42: =IF($E42="","",ROUND($E42*$C42,2))
A43: 3 | B43: 类目流量与关键词入口 | C43: 0.08 | D43: ⑦⑬ | F43: =IF($E43="","",ROUND($E43*$C43,2))
A44: 4 | B44: 差异化与功能领先 | C44: 0.1 | D44: ④ | F44: =IF($E44="","",ROUND($E44*$C44,2))
A45: 5 | B45: VOC痛点覆盖 | C45: 0.1 | D45: ⑤ | F45: =IF($E45="","",ROUND($E45*$C45,2))
A46: 6 | B46: 广告经济可行性 | C46: 0.1 | D46: ⑦ | F46: =IF($E46="","",ROUND($E46*$C46,2))
...

Sheet ⑯总结与决策
A1: ⑯ 研究结果总结 · 决策(对标官方“研究结果总结”)
A2: 把前面所有表的结论汇总成一张卡: 三色状态 → 加权总分 → 通过/待确认/否决。名称/类目/售价自动引用②, 总分与否决项自动引用⑮。
A4: 一、产品身份(自动引用②)
A5: 要素 | B5: 值(自动引用)
A6: 产品名称 | B6: =②产品概念输入卡!C7
A7: 产品类目 | B7: =②产品概念输入卡!C8
A8: 目标售价 | B8: =②产品概念输入卡!C9
A9: 一句话概念 | B9: =②产品概念输入卡!C19
A11: 二、10项模块状态卡(官方三卡=竞争定位/功能完善度/买家满意度, 此处扩展)
A12: 模块 | B12: 状态(N/U/F) | C12: 结论要点 | D12: 主要依据表
A13: 竞争定位 | B13: U | C13: 与④头部对比: 价格/评论/份额处在什么位置; 打不打得过
A14: 功能完善度 | B14: U | C14: ④逐项对比: 绿区几个(我方优势), 红区几个(短板)
A15: 买家满意度 | B15: U | C15: ⑤好评/差评: 满意点在什么, 最大抱怨能否规避
A16: 市场机会与容量 | B16: U | C16: ③: 市场大不大、集中不集中、新品友好否
A17: 季节与时机 | B17: U | C17: ⑥: 是否强季节品; 现在入场是否赶得上
A18: 广告经济性 | B18: U | C18: ⑦: 实际CPC vs 目标CPC, 广告模型是否成立
A19: 单位利润与现金流 | B19: U | C19: ⑧: 毛利率、回本周期、现金流峰值是否可承受
A20: 供应链 | B20: U | C20: ⑨: 采购价达标否、交期/质量是否可靠
A21: 跨市场潜力 | B21: U | C21: ⑪: 美国→EU的加权分与批次
A22: 合规与知识产权(硬门槛) | B22: U | C22: ⑮硬否决行: 检索与认证结论
A24: 三、评分与最终裁决
A25: 指标 | B25: 值(自动) | C25: 档位/含义
A26: 加权总分(满分5) | B26: =⑮评分与决策!F51 | C26: ≥3.8 通过 / 3.0-3.79 待确认 / <3.0 建议否决
A27: 否决项数量(F) | B27: =COUNTIF(⑮评分与决策!E6:E22,"F") -> 0 | C27: >0 → 直接否决(含硬门槛)
A28: 待确认项数量(U) | B28: =COUNTIF(⑮评分与决策!E6:E22,"U") -> 17 | C28: 关键U项必须人工确认后才能决策
A29: 最终裁决(自动) | B29: =IF(B27>0,"否决: 存在F级否决项(见⑮审核表)",IF(B26>=3.8,"通过 —— 建议启动",IF(B26>=3,"待人工确认 —— 补齐U项证据后复评","建议否决 —— 机会分不足"))) -> 通过 —— 建议启动
A31: 四、决策卡(由您拍板)
A32: 要素 | B32: 填写/选择
A33: 最终结论(拍板)
A35: 决策理由(3点以内)
A37: 需要先解决的U项清单
A38: 五、行动清单(结论 → 动作)
A39: # | B39: 行动项 | C39: 负责人 | D39: 截止/前置条件
A40: 1 | B40: 定稿概念与定价(依据⑩情景)
A41: 2 | B41: 供应商打样与成本谈判(⑨)
A42: 3 | B42: 知识产权最终复核(⑮硬否决)
A43: 4 | B43: 广告与推广计划(⑦)
A44: 5 | B44: 备货与头程排期(⑥⑧)
A45: 6 | B45: 评论/信任冷启动(Vine等)
A47: 决策纪律: 本表是决策支持不是决策本身; 所有数值带快照日, 超过30天的数据重验(官方提示); 商业模式/报价/备货由您拍板。
