Workbook

Sheet 阶段实际盈亏
A1: 时间 | B1: 实际 | C1: 价格 | D1: 站内 coupon | E1: 站内 code | F1: 站外 折扣 | G1: 站外 订单 | H1: 站内 自然单 | I1: 站内 广告单 | J1: 阶段 销售 订单 | K1: 时间 /天 | L1: 阶段广告费 （出1单广告单预估） | M1: 阶段站外费用 （5美金/单） | N1: 阶段订单 盈亏 | O1: 阶段亏损 /美金 | P1: 六阶段 总亏损 | R1: 阶段日均 订单 | S1: 阶段日均 广告订单 | T1: 阶段日均 自然订单 | U1: 新品 排行榜 | V1: 小类目 排名
A2: 9月7-9月12 | B2: 第一阶段 | C2: 99.99 | D2: 0.05 | E2: 0.5 | F2: 0.68 | G2: =SUM(#REF!) -> #REF! | H2: 0 | I2: 0 | J2: =SUM(G2:I2) -> #REF! | K2: 6 | L2: 0 | M2: =SUM(#REF!) -> #REF! | N2: =SUM(#REF!) -> #REF! | O2: =SUM(L2:N2) -> #REF!
A3: 9月13-9月21 | B3: 第二阶段 | C3: 79.99 | D3: 0.3 | E3: 0.2 | F3: 0.3 | G3: 81 | H3: 14 | I3: 0 | J3: =SUM(G3:I3) -> 95 | K3: 9 | L3: =SUM(#REF!) -> #REF! | M3: =SUM(#REF!) -> #REF! | N3: =SUM(#REF!) -> #REF! | O3: =SUM(L3:N3) -> #REF!
A4: 9月22-10月1 | B4: 第三阶段 | C4: 69.99 | D4: 0.3 | E4: 0.2 | F4: 0.25 | G4: 45 | H4: 60 | I4: 3 | J4: =SUM(G4:I4) -> 108 | K4: 10 | L4: =SUM(#REF!) -> #REF! | M4: =SUM(#REF!) -> #REF! | N4: =SUM(#REF!) -> #REF! | O4: =SUM(L4:N4) -> #REF!
A5: 10月2-10月11 | B5: 第四阶段 | C5: 69.99 | D5: 0.3 | E5: 0 | F5: 0.25
A6: 10月12-10月21 | B6: 第五阶段 | C6: 69.99 | D6: 0.3 | E6: 0 | F6: 0.25
A7: 10月22-10月31 | B7: 第六阶段 | C7: 69.99 | D7: 0.3 | E7: 0 | F7: 0
A9: 11月1-11月30 | B9: 十一月份 | C9: 69.99 | D9: 0.2 | E9: 0 | F9: 0
A10: 12月1-12月31 | B10: 十二月份 | C10: 69.99 | D10: 0.2 | E10: 0 | F10: 0
A11: 1月1-1月31 | B11: 一月份 | C11: 69.99 | D11: 0.2 | E11: 0 | F11: 0

Sheet 时间节点+发货表格
Q1: 出货时间表 | R1: 数量 | S1: 颜色 | T1: 占比 | U1: 实际数量 | V1: 1箱8个装
Q2: 45627 | R2: 150 | S2: 不锈钢色 | T2: 1 | U2: 150
S3: 种子链接
Q5: 45632 | R5: 640 | S5: 不锈钢色 | T5: 0.9 | U5: 544 | V5: 184
S6: 磨砂黑 | T6: 0.08 | U6: 64 | V6: 16
S7: 金色 | T7: 0.02 | U7: 32 | V7: 8
Q8: 45672 | R8: 4456 | S8: 不锈钢色 | T8: 0.9 | U8: 4048 | V8: 大货3696 | W8: 种子352
S9: 磨砂黑 | T9: 0.08 | U9: 328
S10: 金色 | T10: 0.02 | U10: 80
Q11: 45731 | R11: 3992 | S11: 不锈钢色 | T11: 0.9 | U11: 3600 | V11: 大货3344 | W11: 种子256
S12: 磨砂黑 | T12: 0.08 | U12: 320
S13: 金色 | T13: 0.02 | U13: 72
T17: 2月开始推广，考虑到过年+物流时效，11.19此次下采购单需要下3个月量，即2月+3月+4月的量 2月推广所需640个，何杰已下432个，现还需204个，银色184个，黑色16个，金色8个； 3月推广所需1536个，银色1376个，黑色128个，金色32个 4月推广所需2568个，银色2320个，黑色200个，金色48个 种子链接：2月150个何杰已下，3月+4月种子链接352个银色 银色共：184+1376+2320+352=4232个 黑色共：16+128+200=344个 金色共：8+32+48=88个
Q19: 银色 | R19: 黑色 | S19: 金色
Q20: 184+3696+352 | R20: 16+328 | S20: 8+80
Q21: 4232 | R21: 344 | S21: 88
Q36: 父ASIN
Q37: B0DJW7214X
Q38: MSKU | R38: SKU | S38: FNSKU | T38: 数量
Q39: AZ-US-SOEBIZ-CFSLT-BN-01 | R39: 420F0013BN1 | S39: X004GZH2GB | T39: 4232
Q40: AZ-US-SOEBIZ-CFSLT-BK-02 | R40: 420F0013BK1 | S40: X004GZH3BF | T40: 344
Q41: AZ-US-SOEBIZ-CFSLT-GD-03 | R41: 420F0013BG1 | S41: X004GZPR6D | T41: 88

Sheet 一、竞品对比&定位
A1: 竞品分析（厨房水龙头）
A2: 产品基础信息 | B2: 品牌 | C2: FORIOUS | D2: IBOFYY | E2: BASDEHEN | F2: HOTIS HOME | G2: Hiokay | H2: WEWE | I2: 供应商产品
B3: 图片
B4: 链接 | C4: https://www.amazon.com/dp/B0CPDHBCC6?th=1 | D4: https://www.amazon.com/Pull-Down-Commercial-Stainless-Suitable-Farmhouse/dp/B0BV2NVH1N/ref=cm_cr_arp_d_product_top?ie=UTF8&th=1 | E4: https://www.amazon.com/dp/B0CD25DR34?th=1 | F4: https://www.amazon.com/dp/B0CFX9CK5R?th=1 | G4: https://www.amazon.com/dp/B0BY8K99BW?th=1 | H4: https://www.amazon.com/WEWE-Brushed-Kitchen-Stainless-Faucets/dp/B01H3OMH7Y/ref=sr_1_5?th=1 | I4: /
B5: ASIN | C5: B0CPDHBCC6 | D5: B0BV2NVH1N | E5: B0CD25DR34 | F5: B0CFX9CK5R | G5: B0BY8K99BW | H5: B01H3OMH7Y | I5: /
B6: 卖家 | C6: FORIOUS-USA | D6: Hengzhi Sanitary Ware | E6: chenfeng Store | F6: Hotis home | G6: Hiokay Hardware | H6: MAYYAYA-Direct | I6: /
B7: 库存 | C7: 474 | D7: 限购10 | E7: 限购10 | F7: 1000+ | G7: 限购5 | H7: 限购20 | I7: /
B8: 价格 | C8: 54.99 | D8: 29.99 | E8: 29.99 | F8: 23.99 | G8: 25.99 | H8: 49.88 | I8: 建议定价25.99-35.99
B9: 优惠卷 | C9: 0.2 | D9: 0 | E9: 0 | F9: 0 | G9: 0 | H9: 0 | I9: 0.1
B10: keepa分析 | C10: 24.2.1开售价54.99，通过Vine Voice获得初始评论，大类22489 BS79，3.22断货 大类32912 BS121，5.11Coupon价格48.39-46.74 大类17046 BS52，7.16Coupon价格43.99 大类14607 BS41，8.14-28期间开了2长Deal 售价46.74 大类10440 BS30， -通过绿标获取评论+通过Coupon降价出单+秒杀促销冲排名+合理价格维持 | D10: 23.7.25开售价29.99，通过Vine Voice获得初始评论，23.8.4划线价39.99-29.99，大类8777，BS26 11.19做Deal 售价25.49 大类6827 BS22，1.19涨价31.99-29.99，大类1099，BS4 -通过绿标获取评论+通过小号进行测评+秒杀促销冲排名+合理价格维持 | E10: 23.9.18上架销售售价29.99，通过Vine Voice获得初始评论，11.7划线价59 购物车价格29-31.99-34.99-28.99-29.99 -通过绿标获取评论+通过划线价降价+广告 | F10: 23.10.11上架销售24.99（划线价39.99），通过合并变体获得评价 大类73187 BS249，24.3.8-16断货 大类156104 BS614，7.16-21Coupon价23.49 大类32714 BS100，8.29划线价32.99 售价23.98 大类37897 BS115 -通过和变体获取评论+通过划线价降价+广告 | G10: 23.5.20上架销售28.99，通过Vine Voice获得初始评论，8.4划现价后27.49 大类64896 BS198，10.20划线价25.99 大类23764 BS77，11.22Prime价格20.99 大类57707 BS167，11.22-12.22Prime价格20.99 大类114376 BS400，12.23Prime价格18.62 大类4933 BS18，24.1.5购物车价格21.69-31.99，5.19-6.25Prime价格27.19-26.87，大类10895 BS35，6.26购物车价格25.99 大类11266 BS37 -通过绿标获取评论+通过划线价降价+站内活动+广告 | H10: 24.1.23上架销售19.99，通过Vine Voice获得初始评论，3.12涨价23.99，大类93304 BS367 | I10: 前期绿标+划线价降价+Deal+广告
B11: 变体数 | C11: 8 | D11: 4 | E11: 3 | F11: 2 | G11: 2 | H11: 13 | I11: 13
B12: rating数（review） | C12: 168 | D12: 992 | E12: 751 | F12: 796 | G12: 318 | H12: 49697 | I12: 49674
B13: 星级 | C13: 4.7 | D13: 4.6 | E13: 4.6 | F13: 4.2 | G13: 4.2 | H13: 4.7 | I13: 4.7
B14: QA数 | C14: 0 | D14: 0 | E14: 0 | F14: 0 | G14: 0 | H14: 0 | I14: 0
B15: 上架时间 | C15: 2023-12-03(275天) | D15: 2023-02-06(575天) | E15: 2023-07-27(404天) | F15: 2023-08-16(385天) | G15: 2023-03-12(542天) | H15: 2016-06-14(3,009天) | I15: 2016-06-15(3,004天)
B16: 发货方式 | C16: FBA | D16: FBA | E16: FBA | F16: FBA | G16: FBA | H16: FBA | I16: FBA
B17: 类目、排名 | C17: #9,804 in Tools & Home Improvement #29 in Touch On Kitchen Sink Faucets | D17: #1,065 in Tools & Home Improvement #4 in Touch On Kitchen Sink Faucets | E17: #2,786 in Tools & Home Improvement #10 in Touch On Kitchen Sink Faucets | F17: #33,277 in Tools & Home Improvement #108 in Touch On Kitchen Sink Faucets | G17: #21,097 in Tools & Home Improvement #66 in Touch On Kitchen Sink Faucets | H17: #223 in Tools & Home Improvement #1 in Touch On Kitchen Sink Faucets | I17: #270 in Tools & Home Improvement #1 in Touch On Kitchen Sink Faucets
B18: A+/视频 | C18: 1video | D18: video | E18: video | F18: 1video | G18: 无 | I18: video
A19: 月销量及趋势 | B19: 月销量 | C19: 500+ | D19: 2000+ | E19: 1000+ | F19: 300+ | G19: 200 | H19: 6000 | I19: 5000+
B20: 月销售额 | C20: 49491 | D20: 121010 | E20: 76115 | F20: 9880 | G20: 13905 | H20: =H19*H8 -> 299280 | I20: 379000
B21: 月销量趋势图
A22: 功能 | B22: 应用场景 | C22: 酒吧、房车、厨房和户外 | D22: 厨房水槽 | E22: 厨房 | F22: 厨房 | G22: 厨房 | H22: 厨房 | I22: 酒吧、房车、厨房和户外
A23: 材质 | B23: 材质 | C23: 不锈钢 | D23: 不锈钢、黄铜 | E23: 不锈钢 | F23: 不锈钢 | G23: 不锈钢 | H23: 不锈钢 | I23: 不锈钢
A24: 配件 | B24: 配件 | C24: 喷头、台面板、皂液器、安装五金件、使用说明书 | D24: 喷头、冷热水供应软管、台面板、水龙头本体、使用说明书 | E24: 喷头、台面板、安装硬件、使用说明书 | F24: 水龙头 | G24: 水龙头 | H24: 厨房水龙头、台面板、安装配件、使用说明书、保修卡 | I24: 喷头、台面板、皂液器、安装五金件、使用说明书
A25: 使用方法 | B25: 安装使用方法 | C25: 台面安装 | D25: 台面安装 | E25: 台面安装 | F25: 台面安装 | G25: 嵌入式单孔台面安装 | H25: 单孔或三孔台面安装 | I25: 台面安装
A26: 产品参数 | B26: 1.手柄数量 | C26: 1 | D26: 1 | E26: 1 | F26: 1 | G26: 1 | H26: 1 | I26: 1
B27: 2.孔洞数 | C27: 1 | D27: 1 | E27: / | F27: 1 | G27: 1 | H27: 1 | I27: 1
B28: 3.把手类型 | C28: 杠杆式 | D28: 杠杆式 | E28: 杠杆式 | F28: 杠杆式 | G28: 旋钮 | H28: 杠杆式 | I28: 杠杆式
B29: 4.每分钟最大流量 | C29: 1.8加仑 | D29: / | E29: 1.75加仑 | F29: 1.8加仑 | G29: / | H29: 1.8加仑 | I29: 1.8加仑
B30: 5.阀门类型 | C30: 筒式阀芯阀门 | D30: / | E30: / | F30: / | G30: / | H30: 陶瓷阀芯 | I30: 陶瓷阀芯
B31: 6.出水口高度 | C31: 6.69inch | D31: 8inch | E31: 8inch | F31: 8.5inch | G31: 8.75inch | H31: 8.5inches | I31: 8.5inch
B32: 7.出水口伸展长度 | C32: 8.27inch | D32: 23inch | E32: / | F32: 8.54inch | G32: / | H32: 8.5inches | I32: 8.5inch
B33: 8.伸缩软管长度 | C33: 27.56inch | D33: 31inch | E33: 17inch | F33: 22inch | G33: 20.5inch | H33: 70.9inches | I33: 71inch
B34: 9.水管长度 | H34: 冷：33.5/热：31.5inches
B35: 10.安装孔尺寸 | H35: 1.5inches
B36: 11.特殊功能 | C36: 可拉出式喷头、可下拉式喷头、易于安装、360 度旋转、无铅 | D36: 可拉出式喷头、360 度旋转 | E36: 可拉出式喷头、可下拉式喷头、360 度旋转 | F36: 易于安装 | G36: 可抽出式喷头、易于安装、360 度旋转、双功能喷头。 | H36: 安静关闭，高弧度可下拉式 - 360° 旋转 | I36: 静音闭合
A37: 包装 | B37: 包装尺寸 | C37: 9.84×10.04 ×14.76inch （24.99 x 25.50 x 37.49cm） | D37: 3 x 10 x 15.3 inch（7.62x25.4x38.86cm） | E37: 10.24 x 10.24x 15.35incH (41.4X32.89X11.99CM) | F37: 8.5 x 7.8 x 14.5incH (21.59 x 19.81 x 36.83 CM) | G37: 7.85 x 10x 15.75 inches （19.94 x 25.40 x 40.01cm) | H37: 8.5x 10x 15.7inches （21.59 x 25.40 x 39.88 cm） | I37: 8.5x 10 x 15.7inch (21.59 x 25.40 x 39.88 cm)
B38: 重量 | C38: 3.98 Pounces(1.8KG) | D38: 4.11Pounds(1.86 kg) | E38: 4.09 Pounds(1.86 kg) | F38: 3.45 Pounds(1.56 kg) | G38: 3.06 Pounds(1.39KG) | H38: 1.84 Kilograms(1.84 kg) | I38: 1.84 Kilograms(1.84 kg)
B39: FBA fee | C39: 7.4 | D39: 7.56 | E39: 7.09 | F39: 7.32 | G39: 7.24 | H39: 7.32 | I39: 7.32
B40: 属于什么件 | C40: 大号大件 | D40: 大号标准尺寸 | E40: 大号大件 | F40: 大号大件 | G40: 大号标准尺寸 | H40: 大号标准尺寸 | I40: 大号大件
...

Sheet 流量拆解
A1: 图片 | B1: 品牌 | C1: ASIN | D1: 售价 | E1: 优惠劵 | F1: 月销 | G1: 日销目标 | H1: 子体月销 | I1: 月销售额 | J1: 上架时间 | K1: 星级 | L1: 评论 | M1: 变体 | N1: 总收录 | O1: 自然 | P1: 广告 | Q1: 推荐 | R1: 大类 | S1: 小节点 | T1: 对手流量结构 | U1: 分析1 | V1: 反查流量词 | W1: 分析2 | X1: 时光机查运营打法 | Y1: 分析3 | Z1: 广告透视仪查广告架构 | AA1: 分析4 | AB1: 广告透视仪查广告组 | AC1: 分析5
B2: FORIOUS | C2: B0CPDHBCC6 | D2: 54.99 | E2: 0.2 | F2: 949 | G2: 23.333333 | H2: 500 | I2: 52570 | K2: 4.6 | L2: 106 | M2: 8 | N2: 502 | O2: 439 | P2: 164 | Q2: 42 | R2: #9,132 in Tools & Home Improvement | S2: #25 in Touch On Kitchen Sink Faucets | U2: 黑色款流量占比94%，银色款4%，黑色为主推款 | W2: 流量结构占比 1.自然流量：51.77% 2.推荐流量：41.04% 3.广告流量：7.19% 前十流量量词占比60%，主打二级精准词，以场景词和属性词为主“厨房，水槽，带喷头/皂液器，水龙头” 结论：前期以二级三级精准词为主 | Y2: 历史广告流量走势 2月29% 3月13% 4月8% 5月9% 6月6.21% 7月8% 8月7% 8月9% 从走势看出付费流量随着排名提升比重在逐步降低，整体占比8-10% | AA2: 共计有 33 个SP广告活动、130 个投放小组，主投精准+定向 前期可以以SP广告为主，主投精准和定向，以二三级精准场景词和属性词为主 | AC2: SP广告总共有31个广告活动、66个投放小组 小组1：1*高转化词+1*产品 小组2：3-15*个精准二三级词+产品 广告词类型：场景词，属性词，品牌词 结论：主投SP广告，以二三级精准词，场景词，属性词，品牌词为主，多组投放
B3: BASDEHEN | C3: B0CD25DR34 | D3: 29.99 | E3: 0.5 | F3: 2511 | G3: 40 | H3: 1000 | I3: 75305 | K3: 4.6 | L3: 293 | M3: 3 | N3: 432 | O3: 409 | P3: 52 | Q3: 1 | R3: #2,996 in Tools & Home Improvement | S3: #9 in Touch On Kitchen Sink Faucets | U3: 银色款流量占比74%，金色款26%，银色为主推款 | W3: 流量结构占比 1.自然流量：87.5% 2.推荐流量：10.75% 3.广告流量：1.75% 前十流量量词占比70%，主打二级三级精准词，以场景词和属性词为主“厨房，水槽，带喷头/皂液器，水龙头”，也有少量一级词“faucet” 结论：以二级精准词为主 | Y3: 历史广告流量走势 集中在0.38-3.14%，平均3%，走势比较稳定 因为排名比较靠前，付费流量占比较低，占整体3%左右 | AA3: 共计有 5 个SP广告活动、5 个投放小组，主投SP精准 排名上BS，关键词收录较高的情况下可以下调广告，少量投放SP精准广告 | AC3: SP广告总共有5个广告活动、5个投放小组 小组1：3-15*个精准二三级词+1*产品 广告词类型：场景词，属性词 结论：主投SP广告，以二三级精准词，场景词，属性词，品牌词为主，多组投放
B4: BASDEHEN | C4: B0CD25DR34 | D4: 29.99 | E4: 0.5 | F4: 2511 | G4: 80 | H4: 1000 | I4: 75305 | K4: 4.6 | L4: 293 | M4: 3 | N4: 432 | O4: 409 | P4: 52 | Q4: 1 | R4: #2,996 in Tools & Home Improvement | S4: #9 in Touch On Kitchen Sink Faucets
B5: IBOFYY | C5: B0BV2NVH1N | D5: 29.99 | E5: 0 | F5: 4300 | G5: 100 | H5: 3000 | I5: 127218 | K5: 4.6 | L5: 400 | M5: 4 | N5: 470 | O5: 469 | P5: 10 | Q5: 0 | R5: #2,571 in Tools & Home Improvement | S5: #8 in Touch On Kitchen Sink Faucets | U5: 银色款流量占比95%，黑色款5%，银色为主推款 | W5: 流量结构占比 1.自然流量：79.36% 2.推荐流量：20.46% 3.广告流量：0.18% 前十流量量词占比90%，前五占80%，主打二级精准词，以场景词为主“厨房，水槽，” 结论：以1级和2级别精准词为主 | Y5: 历史广告流量走势 集中在0.28-0.36%，平均0.3%左右，走势比较稳定 因为排名比较靠前，所以付费流量占比较低，占整体0.3%左右 | AA5: 共计有 7 个SP广告活动、8 个投放小组，主投SP精准 排名上BS，关键词收录较高的情况下可以下调广告，少量投放SP精准广告 | AC5: SP广告总共有7个广告活动、7个投放小组 小组1：1*高转化词+1*产品 小组2：15-20*精准二三级词+1*产品 广告词类型：场景词，属性词 结论：主投SP广告，以二三级精准词，场景词，属性词，品牌词为主，多组投放
B6: IBOFYY | C6: B0BV2NVH1N | D6: 29.99 | E6: 0 | F6: 4300 | G6: 150 | H6: 3000 | I6: 127218 | K6: 4.6 | L6: 400 | M6: 4 | N6: 470 | O6: 469 | P6: 10 | Q6: 0 | R6: #2,571 in Tools & Home Improvement | S6: #8 in Touch On Kitchen Sink Faucets
B7: IBOFYY | C7: B0BV2NVH1N | D7: 29.99 | E7: 0 | F7: 4300 | G7: 150 | H7: 3000 | I7: 127218 | K7: 4.6 | L7: 400 | M7: 4 | N7: 470 | O7: 469 | P7: 10 | Q7: 0 | R7: #2,571 in Tools & Home Improvement | S7: #8 in Touch On Kitchen Sink Faucets

Sheet 竞品爆发力
A1: 项目 | B1: ASIN | C1: LD | D1: BD | E1: 会员日 | F1: 秋季会员日 | G1: 黑五（11.17） | H1: 网一（11.20） | I1: 圣诞节
A2: =_xlfn.DISPIMG("ID_BCC32FEA360E445B9C349589D07816E1",1) -> =DISPIMG("ID_BCC32FEA360E445B9C349589D07816E1",1) | B2: B0BV2NVH1N | C2: / | D2: / | E2: 会员两天平均199单/天，会员日前一周平均日销为68单，翻倍数为199/68=2.9倍 | F2: 秋促两天平均单 78/天，秋促前一周平均日销为44单，78/44=1.8倍 | G2: 黑五出单45/天，黑五前一周平均日销为45单，无翻倍 大类10000名，小类30名 | H2: 网一出单45/天，网一前一周平均日销为45单，无翻倍 黑五网一（11.17-11.27）共出：505单 | I2: 圣诞节出单29/天，圣诞节前一周平均日销为47单，圣诞节销量差
C3: 无LD | D3: 5月BD,136单/天，136/73=1.8倍
C4: 无LD | D4: 7月BD,121单/天，121/65=1.8倍
C5: / | D5: /
C6: / | D6: /
C7: / | D7: /
C8: 几乎每个月BD一次，1次LD
A9: =_xlfn.DISPIMG("ID_26D443FD906C4072AFAB43A781D66430",1) -> =DISPIMG("ID_26D443FD906C4072AFAB43A781D66430",1) | B9: B0CD25DR34 | C9: 无LD | D9: 5月BD,165单/天，165/103=1.6倍 | E9: 会员两天平均578单/天，会员日前一周平均日销为42单，翻倍数为578/42=13.7倍 | F9: 秋促两天平均单 89/天，秋促前一周平均日销为74单，89/74=1.2倍 | G9: 黑五出单75/天，黑五前一周平均日销为58单，翻倍数为75/58=1.3倍 大类5244名，小类20名 | H9: 网一出单75/天，网一前一周平均日销为58单，翻倍数为75/58=1.3倍 黑五网一（11.17-11.27）共出：831单 | I9: 圣诞节出单23/天，圣诞节前一周平均日销为44单，圣诞节销量差
C10: 无LD | D10: 6月BD,121单/天，121/57=2.1倍
C11: 无LD | D11: 7月BD,216单/天，216/123=1.8倍
C12: 无LD | D12: 无BD
C13: 无LD | D13: 无BD
C14: 无LD | D14: 无BD
C15: /
A16: =_xlfn.DISPIMG("ID_A9B25EA367114AC8BFB6C92ACF39AE30",1) -> =DISPIMG("ID_A9B25EA367114AC8BFB6C92ACF39AE30",1) | B16: B0CPDHBCC6 | C16: 8.14-LD-37/33=1.1倍 | D16: 6月BD,121单/天，121/57=2.1倍 | E16: 会员两天平均60单/天，会员日前一周平均日销为21单，翻倍数为60/21=2.8倍 | F16: 秋促两天平均单 97/天，秋促前一周平均日销为39单，97/39=2.5倍 | G16: / | H16: / | I16: /
C17: 8.29-LD-37/30=1.2倍 | D17: 10月BD,216单/天，216/123=1.8倍
C18: 9.26-LD-53/36=1.5倍 | D18: /
C19: / | D19: /
C20: / | D20: /
C21: / | D21: /
C22: /
C23: B0CD25DR34 | D23: B0C6JSW8PF
C24: B0CPDHBCC6 | D24: B0CN362S8M
A25: 站点 | B25: 时间 | C25: ASIN | D25: 日销量 | F25: 站点 | G25: 时间 | H25: ASIN | I25: 日销量 | N25: 站点 | O25: 时间 | P25: ASIN | Q25: 日销量
A26: US | B26: 2024/11/05 | C26: B0BV2NVH1N | D26: 106 | F26: US | G26: 2024/11/05 | H26: B0CD25DR34 | I26: 49 | N26: US | O26: 2024/11/05 | P26: B0CPDHBCC6 | Q26: 37
A27: US | B27: 2024/11/04 | C27: B0BV2NVH1N | D27: 149 | F27: US | G27: 2024/11/04 | H27: B0CD25DR34 | I27: 46 | N27: US | O27: 2024/11/04 | P27: B0CPDHBCC6 | Q27: 38
A28: US | B28: 2024/11/03 | C28: B0BV2NVH1N | D28: 131 | F28: US | G28: 2024/11/03 | H28: B0CD25DR34 | I28: 48 | N28: US | O28: 2024/11/03 | P28: B0CPDHBCC6 | Q28: 40
A29: US | B29: 2024/11/02 | C29: B0BV2NVH1N | D29: 111 | F29: US | G29: 2024/11/02 | H29: B0CD25DR34 | I29: 51 | N29: US | O29: 2024/11/02 | P29: B0CPDHBCC6 | Q29: 44
A30: US | B30: 2024/11/01 | C30: B0BV2NVH1N | D30: 95 | F30: US | G30: 2024/11/01 | H30: B0CD25DR34 | I30: 49 | N30: US | O30: 2024/11/01 | P30: B0CPDHBCC6 | Q30: 43
A31: US | B31: 2024/10/31 | C31: B0BV2NVH1N | D31: 76 | F31: US | G31: 2024/10/31 | H31: B0CD25DR34 | I31: 48 | N31: US | O31: 2024/10/31 | P31: B0CPDHBCC6 | Q31: 45
A32: US | B32: 2024/10/30 | C32: B0BV2NVH1N | D32: 73 | F32: US | G32: 2024/10/30 | H32: B0CD25DR34 | I32: 45 | N32: US | O32: 2024/10/30 | P32: B0CPDHBCC6 | Q32: 44
A33: US | B33: 2024/10/29 | C33: B0BV2NVH1N | D33: 62 | F33: US | G33: 2024/10/29 | H33: B0CD25DR34 | I33: 45 | N33: US | O33: 2024/10/29 | P33: B0CPDHBCC6 | Q33: 51
A34: US | B34: 2024/10/28 | C34: B0BV2NVH1N | D34: 57 | F34: US | G34: 2024/10/28 | H34: B0CD25DR34 | I34: 55 | N34: US | O34: 2024/10/28 | P34: B0CPDHBCC6 | Q34: 57 | R34: BD
A35: US | B35: 2024/10/27 | C35: B0BV2NVH1N | D35: 62 | F35: US | G35: 2024/10/27 | H35: B0CD25DR34 | I35: 60 | N35: US | O35: 2024/10/27 | P35: B0CPDHBCC6 | Q35: 63 | R35: BD
A36: US | B36: 2024/10/26 | C36: B0BV2NVH1N | D36: 50 | F36: US | G36: 2024/10/26 | H36: B0CD25DR34 | I36: 48 | N36: US | O36: 2024/10/26 | P36: B0CPDHBCC6 | Q36: 43 | R36: BD
A37: US | B37: 2024/10/25 | C37: B0BV2NVH1N | D37: 55 | F37: US | G37: 2024/10/25 | H37: B0CD25DR34 | I37: 46 | N37: US | O37: 2024/10/25 | P37: B0CPDHBCC6 | Q37: 53 | R37: BD
A38: US | B38: 2024/10/24 | C38: B0BV2NVH1N | D38: 60 | F38: US | G38: 2024/10/24 | H38: B0CD25DR34 | I38: 53 | N38: US | O38: 2024/10/24 | P38: B0CPDHBCC6 | Q38: 53 | R38: BD
A39: US | B39: 2024/10/23 | C39: B0BV2NVH1N | D39: 53 | F39: US | G39: 2024/10/23 | H39: B0CD25DR34 | I39: 57 | N39: US | O39: 2024/10/23 | P39: B0CPDHBCC6 | Q39: 45 | R39: BD
A40: US | B40: 2024/10/22 | C40: B0BV2NVH1N | D40: 62 | F40: US | G40: 2024/10/22 | H40: B0CD25DR34 | I40: 77 | N40: US | O40: 2024/10/22 | P40: B0CPDHBCC6 | Q40: 59 | R40: BD
...

Sheet BS1拆解
A1: =_xlfn.DISPIMG("ID_11B0E9C9CF6B4F85995A17C98EE8FEA6",1) -> =DISPIMG("ID_11B0E9C9CF6B4F85995A17C98EE8FEA6",1) | D1: 整体下来通过前期BD快速起量，积累权重且通过不断调整价格刺激链接出单，保持高评分 | I1: 产品目前的阶段 | K1: 老链接，旨在分析近一年的表现，毕竟趋于稳定，主要看产出效果，中心放在广告推广上
I2: 理想状态 | K2: 稳定状态，理想目标竞品
A3: 产品 | B3: ASIN | C3: 竞品情况 | I3: 第1，店铺实力；第2，看上新有无操作，第3，分析流量结构来源，第4，品牌效益，第5，动作跟踪
A4: 厨房水龙头 | B4: B0BV2NVH1N | C4: 核心竞品
A5: 店铺实力 | B5: =_xlfn.DISPIMG("ID_218FC67E0C504C1B90B12363E44DB4BC",1) -> =DISPIMG("ID_218FC67E0C504C1B90B12363E44DB4BC",1) | H5: =_xlfn.DISPIMG("ID_DFD78A542A25499A99DB7326D74B48C3",1) -> =DISPIMG("ID_DFD78A542A25499A99DB7326D74B48C3",1) | O5: 总结：新店铺，只有两个产品，但是有一个爆款，应该是某个大牌的小牌子来占据坑位，或者新进来的实力强悍的卖家，总结就是不简单这个店铺运营，还有实力都很OK
A6: 链接分析一 排名变化情况 | B6: =_xlfn.DISPIMG("ID_816FD132DE8B4A9895B44D1D40D4FC81",1) -> =DISPIMG("ID_816FD132DE8B4A9895B44D1D40D4FC81",1) | K6: 一上来没有合并种子链接，现在是49.99美金+20% CP (10美金折扣)，后面卖了一周之后，开始大幅度降价几乎对半砍-$29.99-BD（服务商提报预估），两周之后才开始有评价，属于无评价上线，且有不错的量，广告流量占比很少，还有自然流量暴增的情况，考虑刷单和站外的情况。也可能是价格触底反弹引起大量的自然流（这种情况可能性大） 8.14-8.27有可能是连秒BD，且从7.28开始全是自然流，一方面广告打得很少，广告单占比上很少，所以几乎自然流，但是还能保持不错的量，有可能站外或者刷单。上来撬动自然流量也有可能。 9.4号开始有广告流量，但是整体占比很低，几乎自然流 价格调整方面：7.10：$49.99+$10 CP→7.18-7.24（BD）：$29.99→7.24：$39.99→8.9：$37.99+5% CP→8.14-8.27（怀疑连秒BD）：$29.99→8.27：$35.99→8.29：$39.99→9.4：$37.99→9.5-9.19：$29.99→9.30：$37.99→10.11：$34.99+5% CP→10.18之后：$29.99 5.20-5.27,6.17-6.23,7.22-7.29每个月一次BD稳定销量排名。
A7: 链接分析二 流量结构 | B7: =_xlfn.DISPIMG("ID_81181E073A7E4BFDA581DDAE348FDDB7",1) -> =DISPIMG("ID_81181E073A7E4BFDA581DDAE348FDDB7",1) | E7: =_xlfn.DISPIMG("ID_1B6ED065D5C34582B6319A4D3BF952BB",1) -> =DISPIMG("ID_1B6ED065D5C34582B6319A4D3BF952BB",1) | I7: =_xlfn.DISPIMG("ID_AF650015AFE74AEAABCB682ECE2D624F",1) -> =DISPIMG("ID_AF650015AFE74AEAABCB682ECE2D624F",1) | M7: 推荐流量和广告流量占大头，尤其是推荐流量，所以后续要关注关联流量的布局，看广告框架是哪些？怎么打出这个推荐流量的？广告效果怎么样？
A8: 链接分析四 品牌效益 | B8: =_xlfn.DISPIMG("ID_C4B528863E04408286DE061B55472EF8",1) -> =DISPIMG("ID_C4B528863E04408286DE061B55472EF8",1) | I8: =_xlfn.DISPIMG("ID_B74CDA86B09F437B9EBC30D21FB65A43",1) -> =DISPIMG("ID_B74CDA86B09F437B9EBC30D21FB65A43",1) | Q8: 无自家品牌广告词，无品牌广告，就核心关键词，私域这块有待考究，可能没有，可能站外有放量，SP流量为主
A9: 链接分析五 增长点分析 | B9: 第一周 （7.9-7.15这周） | C9: 流量来源 | D9: 自然流 | L9: 销量情况 | M9: 平均每天3单
C10: 投放效果 | D10: 无广告投入，全部自然流，而且排名还不错，要么就是合并老链接有一定的流量，要么就是刷单做了一些站外。
B11: 第二周 （7.16-7.22这周） | C11: 广告动作 | D11: 增加了广告投放，开了4组，都是核心关键词精准 | L11: 销量情况 | M11: 7.16-4单 7.17-3单 7.18-7单 7.19-7单 7.20-26单 7.21-35单 7.22-57单 | P11: 关键词情况 | Q11: =_xlfn.DISPIMG("ID_0C40702702104A77B73EA6FFDA451033",1) -> =DISPIMG("ID_0C40702702104A77B73EA6FFDA451033",1)
C12: 链接动作 | D12: 降价或者BD，售价$29.99，无评分 Tools & Home Improvement-大类6059 Kitchen Sink Faucets-小类21（一天57单左右）
C13: 流量来源 | D13: 自然流贡献最大
C14: 投放效果 | D14: kitchen faucets贡献最多流量，必打的关键词，自然流爆发，考虑站外和BD的作用
B15: 第三周 （7.23-7.29这周） | C15: 广告动作 | D15: 广告增加7组，可能会减少一些词的投放，否定一些词 | L15: 销量情况 | M15: 7.23-63单 7.24-93单 7.25-94单 7.26-30单 7.27-59单 7.28-47单 7.29-42单 | P15: 关键词情况 | Q15: =_xlfn.DISPIMG("ID_62DBF25E293941138C3F1EDB75319C55",1) -> =DISPIMG("ID_62DBF25E293941138C3F1EDB75319C55",1)
C16: 链接动作 | D16: 售价$39.99，无优惠卷和会员折扣，这一周来评价，评分5.0 Tools & Home Improvement-大类8833 Kitchen Sink Faucets-小类32（一天42单左右）
C17: 流量来源 | D17: 自然流量+SP流量，所有流量都是暴涨状态，自然流继续暴涨，同时也带动了很多关键词自然位提升，广告位置靠后但是也在首页，整体贡献上SP流量占比还是很少。
C18: 投放效果 | D18: 上周投放的广告很好，引入了大量的流量，销量也是爆发式突进，像站外那种爆发并且持续能力很强。
B19: 第四周 （7.30-8.5这周） | C19: 广告动作 | D19: 增加一组广告两个核心关键词精准投放 | M19: 7.30-40单 7.31-42单 8.1-35单 8.2-38单 8.3-31单 8.4-27单 8.5-27单 | P19: 关键词情况 | Q19: =_xlfn.DISPIMG("ID_E75705BDD4E64593BD39A05F73E41561",1) -> =DISPIMG("ID_E75705BDD4E64593BD39A05F73E41561",1)
C20: 链接动作 | D20: 售价$39.99，无优惠卷和会员折扣，7个评价，评分4.7 Tools & Home Improvement-大类12572 Kitchen Sink Faucets-小类32（一天31单左右）
C21: 流量来源 | D21: 自然流量+SP流量，所有流量下跌，广告流量下滑严重，可能是砍广告预算或者降低CPC导致广告烧不出去。但整体上还是不错的
C22: 投放效果 | D22: 核心关键词流量词位置下降，导致流量下降不少广告位置也靠后了，证明是下调CPC这种情况比较大
A23: 链接分析六 站外 | B23: 短期站内爆款? | C23: 是 | O23: 很新的品牌，几乎没有任何平台的布局，所以TK上没有布局，全新状态能打上头部，属实是大卖下的小牌给钱，给资源，起来得快，店铺实力不一般
B24: 新媒体渠道引流
B25: FB | C25: 无FB
B26: 独立站 | C26: 无独立站

Sheet NR1拆解
A1: =_xlfn.DISPIMG("ID_13804CCF1F6F4DF2AAB44757F01DC781",1) -> =DISPIMG("ID_13804CCF1F6F4DF2AAB44757F01DC781",1) | D1: 正常新品链接推广，聚焦精准投放关键词，自然流占比大，需要进一步研究。 | I1: 产品目前的阶段 | K1: 老链接，旨在分析近一年的表现，毕竟趋于稳定，主要看产出效果，中心放在广告推广上
I2: 理想状态 | K2: 稳定状态，理想目标竞品
A3: 产品 | B3: ASIN | C3: 竞品情况 | I3: 第1，店铺实力；第2，看上新有无操作，第3，分析流量结构来源，第4，品牌效益，第5，动作跟踪
A4: 厨房水龙头 | B4: B0DCJ76VFY | C4: 核心新品
A5: 店铺实力 | B5: =_xlfn.DISPIMG("ID_72E6FE6225B04FE3A73D340F1F11CD4B",1) -> =DISPIMG("ID_72E6FE6225B04FE3A73D340F1F11CD4B",1) | H5: =_xlfn.DISPIMG("ID_069C5FE4218B4E41961822405EC99E4E",1) -> =DISPIMG("ID_069C5FE4218B4E41961822405EC99E4E",1) | O5: 总结：新店铺，只有4个产品，但是整体上没有做种子链接也没有维护好评价，店铺产品一般般，整体的实力偏弱，但也不排除是大牌下的某个小牌，需要再观察，毕竟现在也是拿到NR的标。上线时间不到一个月的时间。
A6: 链接分析一 排名变化情况 | B6: =_xlfn.DISPIMG("ID_F8F721EBDA3647738E657F6AE66EFAE7",1) -> =DISPIMG("ID_F8F721EBDA3647738E657F6AE66EFAE7",1) | K6: 一上来没有合并种子链接，现在是49.99美金+5% CP，后面卖了一周之后，开始大幅度降价-$32.99，10天左右来了一个5星评价,整体上没有太多操作，保持高评分 价格调整方面：10.2：$49.99+5% CP→10.8：$32.99→10.11-10.15：$32.99+30% CP→10.16：$32.99+10% CP→10.17-11.01：$32.99(JP $29.69)+10% CP→11.2：$32.99+15% CP→11.3-至今：$33.99+5% CP
A7: 链接分析二 流量结构 | B7: =_xlfn.DISPIMG("ID_82F0EBA1EFBC4536A987C4B401D6559C",1) -> =DISPIMG("ID_82F0EBA1EFBC4536A987C4B401D6559C",1) | M7: 自然流量占比超大，一上去就有自然流量，有点奇怪，要么就是这个类目特性，要么就是有操作手段
A8: 链接分析四 品牌效益 | B8: =_xlfn.DISPIMG("ID_185C75B0F95546BD821F5B8887D8B941",1) -> =DISPIMG("ID_185C75B0F95546BD821F5B8887D8B941",1) | I8: =_xlfn.DISPIMG("ID_CD36F4B537434C58AD83DABA155C1910",1) -> =DISPIMG("ID_CD36F4B537434C58AD83DABA155C1910",1) | Q8: 无自家品牌广告词，无品牌广告，就核心关键词SP，私域这块有待考究，可能没有，可能站外有放量，SP流量为主，再次验证小店铺不大品牌广告的情况，也可能是新品初期已精准流量SP为主。
A9: 链接分析五 增长点分析 | B9: 第一周 （9.26-10.5这周） | C9: 流量来源 | D9: 主要是广告流量，但整体不是很多，估计也没有舍得投放 | L9: 销量情况 | M9: 无出单
C10: 投放效果 | D10: 投放两组核心属性瀑布流关键词，效果一般，流量太少，因为CPC太低或者新品没有权重
B11: 第二周 （10.06-10.12这周） | C11: 广告动作 | D11: 增加了广告投放，开了4组，都是核心大词属性（颜色，瀑布流等属性+大词）精准 | L11: 销量情况 | M11: 10.06-0单 10.07-8单 10.08-16单 10.09-16单 10.10-8单 10.11-8单 10.12-6单 | P11: 关键词情况 | Q11: =_xlfn.DISPIMG("ID_E433708EF0ED487892F77A50B58B9F0E",1) -> =DISPIMG("ID_E433708EF0ED487892F77A50B58B9F0E",1)
C12: 链接动作 | D12: $49.99+5% CP降价到$32.99+30% CP，10.12来一个评价5星 Kitchen Sink Faucets-小类546（一天2单左右）
C13: 流量来源 | D13: 自然和广告对半分，各占一半，流程比上周上涨
C14: 投放效果 | D14: kitchen sink faucet贡献最多流量，必打的关键词，整体上还是有不错的效果，打的广告
B15: 第三周 （10.13-10.19这周） | C15: 广告动作 | D15: 广告关闭4组（关闭了带属性，颜色的广告），新增2组广告（1组出单品牌关键词，1组核心产品词精准） | L15: 销量情况 | M15: 10.13-9单 10.14-3单 10.15-3单 10.16-3单 10.17-6单 10.18-5单 10.19-5单 | P15: 关键词情况 | Q15: =_xlfn.DISPIMG("ID_96C51F48C9374257A0F5D8F3A0A66C1E",1) -> =DISPIMG("ID_96C51F48C9374257A0F5D8F3A0A66C1E",1)
C16: 链接动作 | D16: $32.99+30% CP改为JP$29.69+10%CP，这一周来4个五星评价，评分5.0 Tools & Home Improvement-大类100023 Kitchen Sink Faucets-小类352（一天4单左右）
C17: 流量来源 | D17: 自然流量+SP流量，所有流量都是暴涨状态，自然流暴涨，同时也带动了很多关键词自然位提升，证明广告投放有效果，位置上涨流量上涨，曝光上涨，可能转化差一些些
C18: 投放效果 | D18: 投放的广告很好，引入了大量的流量
B19: 第四周 （10.20-10.26这周） | C19: 广告动作 | D19: 关闭2组广告，开了5组广告（精准投放出单词或者是反查竞品的出单词） | M19: 10.20-5单 10.21-6单 10.22-3单 10.23-4单 10.24-6单 10.25-6单 10.26-6单 | P19: 关键词情况 | Q19: =_xlfn.DISPIMG("ID_06B5D7B4E6B74B0C95040C2D09CD3394",1) -> =DISPIMG("ID_06B5D7B4E6B74B0C95040C2D09CD3394",1)
C20: 链接动作 | D20: 保持JP$29.69+10%CP，5个评价，评分5.0 Tools & Home Improvement-大类106669 Kitchen Sink Faucets-小类351（一天4单左右）
C21: 流量来源 | D21: 自然流量+SP流量，核心自然流量，自然流量下滑，但是整体影响不是很大，属于新品的正常波动。
C22: 投放效果 | D22: 核心关键词流量词位置下降，导致流量下降不少广告位置也靠后了，证明是下调CPC
B23: 第五周 （10.27-11.2这周） | C23: 广告动作 | D23: 关闭3组广告，重开老广告4组 | M23: 10.27-6单 10.28-6单 10.29-11单 10.30-12单 10.31-12单 11.01-12单 11.02-12单 | P23: 关键词情况 | Q23: =_xlfn.DISPIMG("ID_FD8F115F67F646F29EFE33D2A61C09D5",1) -> =DISPIMG("ID_FD8F115F67F646F29EFE33D2A61C09D5",1)
C24: 链接动作 | D24: 保持JP$29.69+10%CP，6个评价，评分5.0 Tools & Home Improvement-大类30729 Kitchen Sink Faucets-小类351（一天12单左右）
C25: 流量来源 | D25: 自然流量+SP流量，核心自然流量，自然流量上升，关键词位置往前走，展示的时间长，一方面证明广告效果可能不错，一方面单量有聚焦
C26: 投放效果 | D26: 看一下投放那些词，那些是核心流量词，后面广告可以投放一下
A27: 链接分析六 站外 | B27: 短期站内爆款? | C27: 是
B28: 新媒体渠道引流 | C28: 很新的品牌，几乎没有任何平台的布局，所以TK上没有布局，全新状态能打上头部，属实是大卖下的小牌给钱，给资源，起来得快，店铺实力不一般
B29: FB | C29: 无FB
B30: 独立站 | C30: 无独立站

Sheet 可行性打法
A1: 间断流打法 | B1: 第一阶段 第一周 1.测试链接数据的第一周，测点击率，转化率，且配合大额折扣+种子链接高评分。5个买家秀，1个主图视频，5组QA全部上传完毕。 2.刷出链接新品榜（确保种子链接在1月的时候能到，这样到2月推广能有评价且还在新品期，合并起来没有影响） 3.广告只打A组精准占70%的预算，B组广泛占20%预算，自动广告D组占10%预算，精准核心关键词有效测位置转化率和点击率，所以A组核心预算。 第二周 1.上周已经测试出好的主图跟位置转化了，这周就敲到文案和图片不再做大幅度调整。 2.采用40-50%折扣做5-7天站外，通过大折扣力度促进站外出单，甚至说小爆单，这个可以让新品总CVR大于小类目平均转化率！这几天先不要给很多广告预算，让自然流为主导。控住点击率和转化率。 3.将产品权重全面拉升，让部分核心关键词有自然位，为后续降低CPC奠定基础。顺便帮链接突破单量瓶颈，拉升到20单以上。 第三周 会员折扣+优惠卷，慢慢承接住大部分关键词的自然流量了！这个阶段要把广告框架布局上来，把广告预算逐渐提升起来，自然订单/广告订单。 第四周 根据推广计划去走就行，完成指标，没有达标复盘改进。 | K1: 推新品爆款链接，一定要跟进BSR排名来推进，比如新品第一天我就要出现在小类目新品排行榜前50名，然后从新品排行榜前50名到40名到30名到20名，最后到进入前10名！ 这个过程中不一定每天都能够把排名控制好，可能某天会爆单，然后进入小类目新品排行前10名，假如这个阶段只需要小类目前30名，那么我们可以等到一两天，小类目排名掉到30多名，当天再安排站外把排名稳住在30名之前！反正一句话，就是通过站外出单不能让新品排名掉出来我们制定的排名！ | S1: 如果测试了几个站外渠道都出单很不好（几单的情况下），放弃站外方式，后续就用不了站外的方式做突破，则考虑用LD或者BD的方式去突破，调整推广计划。只能靠广告去拉升单量，加大投入。所以前期需要做测试站外渠道。
K10: 一定要重点观察新品CVR，在业务报名那里可以看到链接的总转化率。想要打造成爆款链接必须要把CVR转化率大于平均转化率，竞品的小类目平均转化率为8%，那么我们的新品必须每天平均转化率大于8%以上。是必须每天平均转化率大于8%以上，要不自然排名会非常不稳定。FB折扣小组用高折扣，其他的站外资源灵活应变，如果FB给的折扣低，一定不要进行FB投放，要不会拉低新品【总CVR】，会搞死链接的，要投放就【高价格高折扣】投放，要不就不要投放不要投放！

Sheet 二、BSR排名销量计划（日月-目标）
A1: 第一阶段20-50个评论 第二阶段50-150个评论 第三阶段150-200个评论
A2: 时间 | C2: 单量目标 | I2: 目标坑位 | J2: 库存计划 | L2: 可售天数 | M2: 备注 | N2: 目标竞对信息 | Z2: 关键词收录 | AD2: 排名 | AF2: 图片 | AG2: Keepa分析
A3: 推品阶段 | B3: 日期 | C3: 总订单 | D3: 增幅 | E3: 广告订单 | F3: 广告订单占比 | G3: 自然订单 | H3: 站外订单 | I3: 小类排名 | J3: 销量 | K3: 库存 | N3: 品牌 | O3: ASIN | P3: 售价 | Q3: 优惠劵 | R3: 月销 | S3: 子体月销 | T3: 日销目标 | U3: 月销售额 | V3: 上架时间 | W3: 星级 | X3: 评论 | Y3: 变体 | Z3: 总收录 | AA3: 自然 | AB3: 广告 | AC3: 推荐 | AD3: 大类 | AE3: 小节点
A4: 二月 | B4: 45689 | C4: 1 | D4: =C4/C4 -> 1 | E4: =C4*F4 -> 1 | F4: 1 | G4: =C4*(1-F4) -> 0 | I4: 30 | J4: =C4 -> 1 | K4: 800 | L4: =K4/J4 -> 800 | N4: FORIOUS | O4: B0CPDHBCC6 | P4: 54.99 | Q4: 0.2 | R4: 1052 | S4: 500 | T4: =K4/30 -> 26.666667 | U4: 57849 | V4: 45263 | W4: 4.5 | X4: 234 | Y4: 7 | Z4: 502 | AA4: 439 | AB4: 164 | AC4: 42 | AD4: #9,132 in Tools & Home Improvement | AE4: #25 in Touch On Kitchen Sink Faucets
A5: 二月 | B5: 45690 | C5: 2 | D5: =(C5-C4)/C5 -> 0.5 | E5: =C5*F5 -> 1.8 | F5: 0.9 | G5: =C5*(1-F5) -> 0.2 | I5: 30 | J5: =C5 -> 2 | K5: =K4-J5 -> 798 | L5: =K5/J5 -> 399 | O5: 会员折扣 | P5: 49.49
A6: 二月 | B6: 45691 | C6: 3 | D6: =(C6-C5)/C6 -> 0.33333333 | E6: =C6*F6 -> 2.4 | F6: 0.8 | G6: =C6*(1-F6) -> 0.6 | I6: 30 | J6: =C6 -> 3 | K6: =K5-J6 -> 795 | L6: =K6/J6 -> 265 | O6: 主要颜色黑+银+金
A7: 二月 | B7: 45692 | C7: 4 | D7: =(C7-C6)/C7 -> 0.25 | E7: =C7*F7 -> 3.2 | F7: 0.8 | G7: =C7*(1-F7) -> 0.8 | I7: 30 | J7: =C7 -> 4 | K7: =K6-J7 -> 791 | L7: =K7/J7 -> 197.75 | O7: 第一阶段主要第一周优化数据，调整链接，尽量测出好的数据，广告以精准为主
A8: 二月 | B8: 45693 | C8: 5 | D8: =(C8-C7)/C8 -> 0.2 | E8: =C8*F8 -> 4 | F8: 0.8 | G8: =C8*(1-F8) -> 1 | I8: 30 | J8: =C8 -> 5 | K8: =K7-J8 -> 786 | L8: =K8/J8 -> 157.2 | O8: 30单已经可以在前30名，有几率出LD，利用LD突破流量单量瓶颈，多参加几次，有就报名
A9: 二月 | B9: 45694 | C9: 6 | D9: =(C9-C8)/C9 -> 0.16666667 | E9: =C9*F9 -> 4.8 | F9: 0.8 | G9: =C9*(1-F9) -> 1.2 | I9: 30 | J9: =C9 -> 6 | K9: =K8-J9 -> 780 | L9: =K9/J9 -> 130
A10: 二月 | B10: 45695 | C10: 8 | D10: =(C10-C9)/C10 -> 0.25 | E10: =C10*F10 -> 6.4 | F10: 0.8 | G10: =C10*(1-F10) -> 1.6 | I10: 30 | J10: =C10 -> 8 | K10: =K9-J10 -> 772 | L10: =K10/J10 -> 96.5 | O10: 日销14-20单能拿到 NR
A11: 二月 | B11: 45696 | C11: 10 | D11: =(C11-C10)/C11 -> 0.2 | E11: =C11*F11 -> 7 | F11: 0.7 | G11: =C11*(1-F11) -> 3 | I11: 30 | J11: =C11 -> 10 | K11: =K10-J11 -> 762 | L11: =K11/J11 -> 76.2 | O11: 所以第一个月 | P11: 新品 排行榜 | R11: 小类目 排名 | T11: 大类目 排名
A12: 二月 | B12: 45697 | C12: 11 | D12: =(C12-C11)/C12 -> 0.090909091 | E12: =C12*F12 -> 7.7 | F12: 0.7 | G12: =C12*(1-F12) -> 3.3 | I12: 30 | J12: =C12 -> 11 | K12: =K11-J12 -> 751 | L12: =K12/J12 -> 68.272727 | O12: 第1周 | P12: 前10名 | R12: 稳定在前120名 | T12: 稳定在前120000名
A13: 二月 | B13: 45698 | C13: 13 | D13: =(C13-C12)/C13 -> 0.15384615 | E13: =C13*F13 -> 9.1 | F13: 0.7 | G13: =C13*(1-F13) -> 3.9 | I13: 30 | J13: =C13 -> 13 | K13: =K12-J13 -> 738 | L13: =K13/J13 -> 56.769231 | O13: 第2周 | P13: NR #1 | R13: 稳定在前100名 | T13: 稳定在前30000名
A14: 二月 | B14: 45699 | C14: 15 | D14: =(C14-C13)/C14 -> 0.13333333 | E14: =C14*F14 -> 10.5 | F14: 0.7 | G14: =C14*(1-F14) -> 4.5 | I14: 30 | J14: =C14 -> 15 | K14: =K13-J14 -> 723 | L14: =K14/J14 -> 48.2 | O14: 第3周 | P14: NR #1 | R14: 稳定在前50名 | T14: 稳定在前17000名
A15: 二月 | B15: 45700 | C15: 16 | D15: =(C15-C14)/C15 -> 0.0625 | E15: =C15*F15 -> 11.2 | F15: 0.7 | G15: =C15*(1-F15) -> 4.8 | I15: 30 | J15: =C15 -> 16 | K15: =K14-J15 -> 707 | L15: =K15/J15 -> 44.1875 | O15: 第4周 | P15: NR #1 | R15: 稳定在前30名 | T15: 稳定在前10000名
A16: 二月 | B16: 45701 | C16: 18 | D16: =(C16-C15)/C16 -> 0.11111111 | E16: =C16*F16 -> 12.6 | F16: 0.7 | G16: =C16*(1-F16) -> 5.4 | I16: 30 | J16: =C16 -> 18 | K16: =K15-J16 -> 689 | L16: =K16/J16 -> 38.277778
A17: 二月 | B17: 45702 | C17: 20 | D17: =(C17-C16)/C17 -> 0.1 | E17: =C17*F17 -> 14 | F17: 0.7 | G17: =C17*(1-F17) -> 6 | I17: 30 | J17: =C17 -> 20 | K17: =K16-J17 -> 669 | L17: =K17/J17 -> 33.45
A18: 二月 | B18: 45703 | C18: 23 | D18: =(C18-C17)/C18 -> 0.13043478 | E18: =C18*F18 -> 16.1 | F18: 0.7 | G18: =C18*(1-F18) -> 6.9 | I18: 30 | J18: =C18 -> 23 | K18: =K17-J18 -> 646 | L18: =K18/J18 -> 28.086957
A19: 二月 | B19: 45704 | C19: 25 | D19: =(C19-C18)/C19 -> 0.08 | E19: =C19*F19 -> 17.5 | F19: 0.7 | G19: =C19*(1-F19) -> 7.5 | I19: 30 | J19: =C19 -> 25 | K19: =K18-J19 -> 621 | L19: =K19/J19 -> 24.84
A20: 二月 | B20: 45705 | C20: 25 | D20: =(C20-C19)/C20 -> 0 | E20: =C20*F20 -> 17.5 | F20: 0.7 | G20: =C20*(1-F20) -> 7.5 | I20: 30 | J20: =C20 -> 25 | K20: =K19-J20 -> 596 | L20: =K20/J20 -> 23.84
A21: 二月 | B21: 45706 | C21: 26 | D21: =(C21-C20)/C21 -> 0.038461538 | E21: =C21*F21 -> 18.2 | F21: 0.7 | G21: =C21*(1-F21) -> 7.8 | I21: 30 | J21: =C21 -> 26 | K21: =K20-J21 -> 570 | L21: =K21/J21 -> 21.923077
A22: 二月 | B22: 45707 | C22: 26 | D22: =(C22-C21)/C22 -> 0 | E22: =C22*F22 -> 18.2 | F22: 0.7 | G22: =C22*(1-F22) -> 7.8 | I22: 30 | J22: =C22 -> 26 | K22: =K21-J22 -> 544 | L22: =K22/J22 -> 20.923077
A23: 二月 | B23: 45708 | C23: 27 | D23: =(C23-C22)/C23 -> 0.037037037 | E23: =C23*F23 -> 18.9 | F23: 0.7 | G23: =C23*(1-F23) -> 8.1 | I23: 30 | J23: =C23 -> 27 | K23: =K22-J23 -> 517 | L23: =K23/J23 -> 19.148148
A24: 二月 | B24: 45709 | C24: 27 | D24: =(C24-C23)/C24 -> 0 | E24: =C24*F24 -> 18.9 | F24: 0.7 | G24: =C24*(1-F24) -> 8.1 | I24: 30 | J24: =C24 -> 27 | K24: =K23-J24 -> 490 | L24: =K24/J24 -> 18.148148
A25: 二月 | B25: 45710 | C25: 28 | D25: =(C25-C24)/C25 -> 0.035714286 | E25: =C25*F25 -> 19.6 | F25: 0.7 | G25: =C25*(1-F25) -> 8.4 | I25: 30 | J25: =C25 -> 28 | K25: =K24-J25 -> 462 | L25: =K25/J25 -> 16.5
A26: 二月 | B26: 45711 | C26: 28 | D26: =(C26-C25)/C26 -> 0 | E26: =C26*F26 -> 19.6 | F26: 0.7 | G26: =C26*(1-F26) -> 8.4 | I26: 30 | J26: =C26 -> 28 | K26: =K25-J26 -> 434 | L26: =K26/J26 -> 15.5
A27: 二月 | B27: 45712 | C27: 29 | D27: =(C27-C26)/C27 -> 0.034482759 | E27: =C27*F27 -> 20.3 | F27: 0.7 | G27: =C27*(1-F27) -> 8.7 | I27: 30 | J27: =C27 -> 29 | K27: =K26-J27 -> 405 | L27: =K27/J27 -> 13.965517
... A31: 二月 | B31: 45716 | C31: 32 | D31: =(C31-C30)/C31 -> 0.0625 | E31: =C31*F31 -> 22.4 | F31: 0.7 | G31: =C31*(1-F31) -> 9.6 | I31: 30 | J31: =C31 -> 32 | K31: =K30-J31 -> 284 | L31: =K31/J31 -> 8.875
A32: 二月 | B32: 二月汇总 | C32: =SUM(C4:C31) -> 517 | E32: =SUM(E4:E31) -> 365.2 | F32: =E32/C32 -> 0.70638298 | G32: =SUM(G4:G31) -> 151.8 | H32: 0 | I32: / | J32: =C32 -> 517 | K32: 1316 | L32: =K32/J32 -> 2.5454545 | N32: BASDEHEN | O32: B0CD25DR34 | P32: 29.99 | Q32: 0.5 | R32: 2511 | S32: 1000 | T32: =K33/30 -> 53.333333 | U32: 75305 | V32: 45134 | W32: 4.6 | X32: 293 | Y32: 3 | Z32: 432 | AA32: 409 | AB32: 52 | AC32: 1 | AD32: #2,996 in Tools & Home Improvement | AE32: #9 in Touch On Kitchen Sink Faucets
A33: 三月 | B33: 45717 | C33: 33 | D33: =C33/C33 -> 1 | E33: =C33*F33 -> 19.8 | F33: 0.6 | G33: =C33*(1-F33) -> 13.2 | I33: 20 | J33: =C33 -> 33 | K33: =K32+K31 -> 1600 | L33: =K33/J33 -> 48.484848
A34: 三月 | B34: 45718 | C34: 34 | D34: =(C34-C33)/C34 -> 0.029411765 | E34: =C34*F34 -> 20.4 | F34: 0.6 | G34: =C34*(1-F34) -> 13.6 | I34: 20 | J34: =C34 -> 34 | K34: =K33-J34 -> 1566 | L34: =K34/J34 -> 46.058824 | O34: 第二阶段总体目标，日均41单，月1271单，具体需要根据第一阶段的推广数据调整
A35: 三月 | B35: 45719 | C35: 34 | D35: =(C35-C34)/C35 -> 0 | E35: =C35*F35 -> 20.4 | F35: 0.6 | G35: =C35*(1-F35) -> 13.6 | I35: 20 | J35: =C35 -> 34 | K35: =K34-J35 -> 1532 | L35: =K35/J35 -> 45.058824 | O35: 第二阶段是突破到前20，前20名是拿到市场差不多80%的量，所以难度成倍增加，必须要借助秒杀，最好是BD进行辅助，需要用到广告补单，甚至是站外。如果评价稳定在300个，加上种子链接，可以低价开始冲刺起量。必须要完成目标销量，多个流量入口占据，会员折扣还有优惠卷都要使用，甚至是code。核心关键词都要在首页
A36: 三月 | B36: 45720 | C36: 35 | D36: =(C36-C35)/C36 -> 0.028571429 | E36: =C36*F36 -> 21 | F36: 0.6 | G36: =C36*(1-F36) -> 14 | I36: 20 | J36: =C36 -> 35 | K36: =K35-J36 -> 1497 | L36: =K36/J36 -> 42.771429
A37: 三月 | B37: 45721 | C37: 35 | D37: =(C37-C36)/C37 -> 0 | E37: =C37*F37 -> 21 | F37: 0.6 | G37: =C37*(1-F37) -> 14 | I37: 20 | J37: =C37 -> 35 | K37: =K36-J37 -> 1462 | L37: =K37/J37 -> 41.771429
A38: 三月 | B38: 45722 | C38: 35 | D38: =(C38-C37)/C38 -> 0 | E38: =C38*F38 -> 21 | F38: 0.6 | G38: =C38*(1-F38) -> 14 | I38: 20 | J38: =C38 -> 35 | K38: =K37-J38 -> 1427 | L38: =K38/J38 -> 40.771429
A39: 三月 | B39: 45723 | C39: 36 | D39: =(C39-C38)/C39 -> 0.027777778 | E39: =C39*F39 -> 21.6 | F39: 0.6 | G39: =C39*(1-F39) -> 14.4 | I39: 20 | J39: =C39 -> 36 | K39: =K38-J39 -> 1391 | L39: =K39/J39 -> 38.638889 | O39: 所以第二个月 | P39: 新品 排行榜 | R39: 小类目 排名 | T39: 大类目 排名
A40: 三月 | B40: 45724 | C40: 36 | D40: =(C40-C39)/C40 -> 0 | E40: =C40*F40 -> 21.6 | F40: 0.6 | G40: =C40*(1-F40) -> 14.4 | I40: 20 | J40: =C40 -> 36 | K40: =K39-J40 -> 1355 | L40: =K40/J40 -> 37.638889 | O40: 第1周 | P40: NR #1 | R40: 稳定在前30名 | T40: 稳定在前10000名
A41: 三月 | B41: 45725 | C41: 36 | D41: =(C41-C40)/C41 -> 0 | E41: =C41*F41 -> 21.6 | F41: 0.6 | G41: =C41*(1-F41) -> 14.4 | I41: 20 | J41: =C41 -> 36 | K41: =K40-J41 -> 1319 | L41: =K41/J41 -> 36.638889 | O41: 第2周 | P41: NR #1 | R41: 稳定在前30名 | T41: 稳定在前10000名
A42: 三月 | B42: 45726 | C42: 36 | D42: =(C42-C41)/C42 -> 0 | E42: =C42*F42 -> 21.6 | F42: 0.6 | G42: =C42*(1-F42) -> 14.4 | I42: 20 | J42: =C42 -> 36 | K42: =K41-J42 -> 1283 | L42: =K42/J42 -> 35.638889 | O42: 第3周 | P42: NR #1 | R42: 稳定在前25名 | T42: 稳定在前8000名
A43: 三月 | B43: 45727 | C43: 37 | D43: =(C43-C42)/C43 -> 0.027027027 | E43: =C43*F43 -> 22.2 | F43: 0.6 | G43: =C43*(1-F43) -> 14.8 | I43: 20 | J43: =C43 -> 37 | K43: =K42-J43 -> 1246 | L43: =K43/J43 -> 33.675676 | O43: 第4周 | P43: NR #1 | R43: 稳定在前20名 | T43: 稳定在前7500名
...

Sheet 盈亏核算-汇总
A1: 【产品定位及销售目标预测】 | B1: 月份 | C1: 2月 | D1: 3月 | E1: 4月 | F1: 5月 | G1: 6月 | H1: 7月 | I1: 合计
A2: 产品图片 产品名称： 站点：US 品牌： lisitng负责人： listing所属团队： 开售时间：2024年11月13日 产品等级定位：头部 ASIN： 子ASIN | B2: listing售价 | C2: =阶段盈亏!C3 -> 54.99 | D2: =阶段盈亏!C7 -> 54.99 | E2: =阶段盈亏!C11 -> 54.99 | F2: =阶段盈亏!C15 -> 49.99 | G2: =阶段盈亏!C19 -> 49.99 | H2: =阶段盈亏!C23 -> 36.99 | I2: =H2 -> 36.99
B3: 净售价 | C3: =C2*(1-C4) -> 32.994 | D3: =D2*(1-D4) -> 27.495 | E3: =E2*(1-E4) -> 24.7455 | F3: =F2*(1-F4) -> 32.4935 | G3: =G2*(1-G4) -> 37.4925 | H3: =H2*(1-H4) -> 36.99 | I3: =H3 -> 36.99
B4: 折扣占比% | C4: 0.4 | D4: 0.5 | E4: 0.55 | F4: 0.35 | G4: 0.25 | H4: 0 | I4: =H4 -> 0
B5: 采购 | C5: 10 | D5: 10 | E5: 10 | F5: 10 | G5: 10 | H5: 10 | I5: =H5 -> 10
B6: 头程 | C6: 4 | D6: 4 | E6: 4 | F6: 4 | G6: 4 | H6: 4 | I6: =H6 -> 4 | K6: 填写黄色数字项
B7: AMZ佣金 | C7: 0.15 | D7: 0.15 | E7: 0.15 | F7: 0.15 | G7: 0.15 | H7: 0.15 | I7: =H7 -> 0.15
B8: FBA配送费 | C8: 7.86 | D8: 7.86 | E8: 7.86 | F8: 7.86 | G8: 7.86 | H8: 7.86 | I8: =H8 -> 7.86
B9: 仓储 | C9: 0.1 | D9: 0.1 | E9: 0.1 | F9: 0.1 | G9: 0.1 | H9: 0.1 | I9: =H9 -> 0.1
B10: 优惠劵fee | C10: 0.6 | D10: 0.6 | E10: 0.6 | F10: 0.6 | G10: 0.6 | H10: 0.6 | I10: =H10 -> 0.6
B11: 领取coupon | C11: 0.4 | D11: 0.4 | E11: 0.4 | F11: 0.3 | G11: 0.3 | H11: 0 | I11: =H11 -> 0
B12: 未领取coupon | C12: 0.6 | D12: 0.6 | E12: 0.6 | F12: 0.7 | G12: 0.7 | H12: 1 | I12: =H12 -> 1
B13: 销量 | C13: ='二、BSR排名销量计划（日月-目标）'!C32 -> 517 | D13: ='二、BSR排名销量计划（日月-目标）'!C64 -> 1271 | E13: ='二、BSR排名销量计划（日月-目标）'!C95 -> 2145 | F13: ='二、BSR排名销量计划（日月-目标）'!C127 -> 3100 | G13: ='二、BSR排名销量计划（日月-目标）'!C158 -> 4020 | H13: ='二、BSR排名销量计划（日月-目标）'!C190 -> 4650 | I13: =SUM(C13:H13) -> 15703
B14: 产品成本货值 | C14: =(C5+C6)*C13 -> 7238 | D14: =(D5+D6)*D13 -> 17794 | E14: =(E5+E6)*E13 -> 30030 | F14: =(F5+F6)*F13 -> 43400 | G14: =(G5+G6)*G13 -> 56280 | H14: =(H5+H6)*H13 -> 65100 | I14: =SUM(C14:H14) -> 219842 | J14: =I14*7 -> 1538894
B15: 净销售额 | C15: =C13*C3 -> 17057.898 | D15: =D13*D3 -> 34946.145 | E15: =E13*E3 -> 53079.098 | F15: =F13*F3 -> 100729.85 | G15: =G13*G3 -> 150719.85 | H15: =H13*H3 -> 172003.5 | I15: =SUM(C15:H15) -> 528536.34
B16: 广告花费 | C16: =-SUM(阶段盈亏!L3:L6) -> 13687.5 | D16: =-SUM(阶段盈亏!L7:L10) -> 27017 | E16: =-SUM(阶段盈亏!L11:L14) -> 26486.667 | F16: =-SUM(阶段盈亏!L15:L18) -> 22545.455 | G16: =-SUM(阶段盈亏!L19:L22) -> 18090 | H16: =-SUM(阶段盈亏!L23:L26) -> 12400 | I16: =SUM(C16:H16) -> 120226.62 | J16: =I16*7 -> 841586.35
B17: ACOAs% | C17: =C16/C15 -> 0.80241422 | D17: =D16/D15 -> 0.77310387 | E17: =E16/E15 -> 0.49900371 | F17: =F16/F15 -> 0.22382099 | G17: =G16/G15 -> 0.120024 | H17: =H16/H15 -> 0.072091556 | I17: =I16/I15 -> 0.22747087
B18: 广告单占比 | C18: =SUM(阶段盈亏!H3:H6)/SUM(阶段盈亏!I3:I6) -> 0.70599613 | D18: =SUM(阶段盈亏!H7:H10)/SUM(阶段盈亏!I7:I10) -> 0.59952793 | E18: =SUM(阶段盈亏!H11:H14)/SUM(阶段盈亏!I11:I14) -> 0.4997669 | F18: =SUM(阶段盈亏!H15:H18)/SUM(阶段盈亏!I15:I18) -> 0.4 | G18: =SUM(阶段盈亏!H19:H22)/SUM(阶段盈亏!I19:I22) -> 0.3 | H18: =SUM(阶段盈亏!H23:H26)/SUM(阶段盈亏!I23:I26) -> 0.2 | I18: =H18 -> 0.2
B19: CPC | C19: =AVERAGE(CPC表格!S4:S7) -> 3 | D19: =AVERAGE(CPC表格!S8:S11) -> 3.625 | E19: =AVERAGE(CPC表格!S12:S15) -> 3 | F19: =AVERAGE(CPC表格!S16:S19) -> 2 | G19: =AVERAGE(CPC表格!S20:S23) -> 1.5 | H19: =AVERAGE(CPC表格!S24:S27) -> 1.2 | I19: =H19 -> 1.2
B20: ACOS% | C20: =C19/C21/C3 -> 1.1365703 | D20: 0.35 | E20: 0.3 | F20: 0.25 | G20: 0.25 | H20: 0.25 | I20: =H20 -> 0.25
B21: ASIN转化率% | C21: 0.08 | D21: 0.1 | E21: 0.12 | F21: 0.11 | G21: 0.1 | H21: 0.09 | I21: =H21 -> 0.09
B22: 退款率% | C22: 0.08 | D22: 0.08 | E22: 0.08 | F22: 0.08 | G22: 0.08 | H22: 0.08 | I22: =H22 -> 0.08
B23: 种子链接成本 | C23: =五、评论策略!K2/7+600 -> 4654 | D23: =五、评论策略!K3/7 -> 4054 | E23: =五、评论策略!K4/7 -> 5422 | F23: =五、评论策略!K5/7 -> 6765 | G23: =五、评论策略!K6/7 -> 8108 | H23: =五、评论策略!K7/7 -> 8108 | I23: =SUM(C23:H23) -> 37111 | J23: =I23*7 -> 259777
B24: 净毛利润 | C24: =SUM(阶段盈亏!N3:N6) -> -12088.074 | D24: =SUM(阶段盈亏!N7:N10) -> -29024.336 | E24: =SUM(阶段盈亏!N11:N14) -> -34886.137 | F24: =SUM(阶段盈亏!N15:N18) -> -14273.582 | G24: =SUM(阶段盈亏!N19:N22) -> 9714.1397 | H24: =SUM(阶段盈亏!N23:N26) -> 20565.861 | I24: =SUM(C24:H24) -> -59992.129 | J24: 成本合计 | K24: =J23+J16+J14 -> 2640257.3
B25: 净毛利润率% | C25: =C24/C15 -> -0.70864971 | D25: =D24/D15 -> -0.83054471 | E25: =E24/E15 -> -0.65724812 | F25: =F24/F15 -> -0.14170161 | G25: =G24/G15 -> 0.064451628 | H25: =H24/H15 -> 0.11956653 | I25: =I24/I15 -> -0.11350616
B26: 平均评分及数量 | C26: 4.8/150 | D26: 4.7/300 | E26: 4.6/500 | F26: 4.5/750 | G26: 4.5/1050 | H26: 4.5/1350 | I26: =H26 -> 4.5/1350
B27: ASIN所在节点 | C27: #Touch On Kitchen Sink Faucets | D27: #Touch On Kitchen Sink Faucets | E27: #Touch On Kitchen Sink Faucets | F27: #Touch On Kitchen Sink Faucets | G27: #Touch On Kitchen Sink Faucets | H27: #Touch On Kitchen Sink Faucets | I27: =H27 -> #Touch On Kitchen Sink Faucets
B28: 排名(定位) | C28: #30 | D28: #20 | E28: #15 | F28: #10 | G28: #6 | H28: #5 | I28: =H28 -> #5
A29: 新品至少做半年6个月的销售预测数据，主要看下该项目的销售数据，以及经营数据的情况。
A30: 【新品销售趋势图】 | H30: 【新品销售额VS利润趋势图】

Sheet 阶段盈亏
A1: 阶段盈亏模拟数据
A2: 阶段 | B2: 日期 | C2: 定价 | D2: cou pon | E2: code | F2: 折后价 | G2: 自然单 | H2: 站内 广告单 | I2: 阶段 销售 订单 | J2: 时间 /天 | K2: CPA | L2: 阶段 广告费 | M2: 阶段订单 盈亏 | N2: 阶段盈亏 /美金 | O2: 评论 数量 | P2: 阶段 日均 订单 | Q2: 阶段 日均 广告单 | R2: 阶段 日均 自然单 | S2: 日均 广告费 | T2: 小类目 排名 | U2: 大类目 排名 | V2: 备注 | W2: 种子评论费/（开5条VINE，预计来150条评论）,视觉化费用预估1100美金 | X2: 前期亏损/美金 | Y2: 人民币
A3: 第一阶段 | B3: 第1周 | C3: 54.99 | D3: 0.3 | E3: 0.1 | F3: =SUM(C3*(1-D3-E3)) -> 32.994 | G3: 5 | H3: 24 | I3: =SUM(G3:H3) -> 29 | J3: 7 | K3: =CPC表格!V4 -> 37.5 | L3: =SUM(H3*-K3) -> -900 | M3: =毛利表格!T3 -> 89.716328 | N3: =SUM(L3:M3) -> -810.28367 | O3: 150 | P3: =SUM(I3/J3) -> 4.1428571 | Q3: =SUM(H3/J3) -> 3.4285714 | R3: =SUM(G3/J3) -> 0.71428571 | S3: =SUM(L3/J3) -> -128.57143 | T3: 稳定在前120名 | U3: 稳定在前120000名 | V3: 一开售投放广告 | W3: =-(10*150+1000+1100) -> -3600 | X3: =SUM(N3:N6)+W3 -> -15688.074 | Y3: =X3*7 -> -109816.52
B4: 第2周 | C4: 54.99 | D4: 0.3 | E4: 0.1 | F4: =SUM(C4*(1-D4-E4)) -> 32.994 | G4: 31 | H4: 72 | I4: =SUM(G4:H4) -> 103 | J4: 7 | K4: =CPC表格!V5 -> 37.5 | L4: =SUM(H4*-K4) -> -2700 | M4: =毛利表格!T4 -> 318.64765 | N4: =SUM(L4:M4) -> -2381.3524 | P4: =SUM(I4/J4) -> 14.714286 | Q4: =SUM(H4/J4) -> 10.285714 | R4: =SUM(G4/J4) -> 4.4285714 | S4: =SUM(L4/J4) -> -385.71429 | T4: 稳定在前100名 | U4: 稳定在前30000名 | V4: 第一个月 | W4: 视觉=拍摄+主图视频+买家秀
B5: 第3周 | C5: 54.99 | D5: 0.3 | E5: 0.1 | F5: =SUM(C5*(1-D5-E5)) -> 32.994 | G5: 54 | H5: 125 | I5: =SUM(G5:H5) -> 179 | J5: 7 | K5: =CPC表格!V6 -> 37.5 | L5: =SUM(H5*-K5) -> -4687.5 | M5: =毛利表格!T5 -> 553.7663 | N5: =SUM(L5:M5) -> -4133.7337 | P5: =SUM(I5/J5) -> 25.571429 | Q5: =SUM(H5/J5) -> 17.857143 | R5: =SUM(G5/J5) -> 7.7142857 | S5: =SUM(L5/J5) -> -669.64286 | T5: 稳定在前50名 | U5: 稳定在前17000名
B6: 第4周 | C6: 54.99 | D6: 0.3 | E6: 0.1 | F6: =SUM(C6*(1-D6-E6)) -> 32.994 | G6: 62 | H6: 144 | I6: =SUM(G6:H6) -> 206 | J6: 7 | K6: =CPC表格!V7 -> 37.5 | L6: =SUM(H6*-K6) -> -5400 | M6: =毛利表格!T6 -> 637.29529 | N6: =SUM(L6:M6) -> -4762.7047 | P6: =SUM(I6/J6) -> 29.428571 | Q6: =SUM(H6/J6) -> 20.571429 | R6: =SUM(G6/J6) -> 8.8571429 | S6: =SUM(L6/J6) -> -771.42857 | T6: 稳定在前30名 | U6: 稳定在前10000名
A7: 第二阶段 | B7: 第5周 | C7: 54.99 | D7: 0.4 | E7: 0.1 | F7: =SUM(C7*(1-D7-E7)) -> 27.495 | G7: 97 | H7: 145 | I7: =SUM(G7:H7) -> 242 | J7: 7 | K7: =CPC表格!V8 -> 40 | L7: =SUM(H7*-K7) -> -5800 | M7: =毛利表格!T7 -> -382.19929 | N7: =SUM(L7:M7) -> -6182.1993 | O7: 300 | P7: =SUM(I7/J7) -> 34.571429 | Q7: =SUM(H7/J7) -> 20.714286 | R7: =SUM(G7/J7) -> 13.857143 | S7: =SUM(L7/J7) -> -828.57143 | T7: 稳定在前30名 | U7: 稳定在前10000名 | V7: 第二个月 | W7: 上个月亏损/美金 | X7: 累计亏损/美金 | Y7: 人民币
B8: 第6周 | C8: 54.99 | D8: 0.4 | E8: 0.1 | F8: =SUM(C8*(1-D8-E8)) -> 27.495 | G8: 104 | H8: 156 | I8: =SUM(G8:H8) -> 260 | J8: 7 | K8: =CPC表格!V9 -> 38 | L8: =SUM(H8*-K8) -> -5928 | M8: =毛利表格!T8 -> -410.62734 | N8: =SUM(L8:M8) -> -6338.6273 | P8: =SUM(I8/J8) -> 37.142857 | Q8: =SUM(H8/J8) -> 22.285714 | R8: =SUM(G8/J8) -> 14.857143 | S8: =SUM(L8/J8) -> -846.85714 | T8: 稳定在前30名 | U8: 稳定在前10000名 | W8: =X3 -> -15688.074 | X8: =W8+SUM(N7:N10) -> -44712.41 | Y8: =X8*7 -> -312986.87
B9: 第7周 | C9: 54.99 | D9: 0.4 | E9: 0.1 | F9: =SUM(C9*(1-D9-E9)) -> 27.495 | G9: 120 | H9: 179 | I9: =SUM(G9:H9) -> 299 | J9: 7 | K9: =CPC表格!V10 -> 35 | L9: =SUM(H9*-K9) -> -6265 | M9: =毛利表格!T9 -> -472.22144 | N9: =SUM(L9:M9) -> -6737.2214 | P9: =SUM(I9/J9) -> 42.714286 | Q9: =SUM(H9/J9) -> 25.571429 | R9: =SUM(G9/J9) -> 17.142857 | S9: =SUM(L9/J9) -> -895 | T9: 稳定在前25名 | U9: 稳定在前8000名
B10: 第8周 | C10: 54.99 | D10: 0.4 | E10: 0.1 | F10: =SUM(C10*(1-D10-E10)) -> 27.495 | G10: 188 | H10: 282 | I10: =SUM(G10:H10) -> 470 | J10: 10 | K10: =CPC表格!V11 -> 32 | L10: =SUM(H10*-K10) -> -9024 | M10: =毛利表格!T10 -> -742.28788 | N10: =SUM(L10:M10) -> -9766.2879 | P10: =SUM(I10/J10) -> 47 | Q10: =SUM(H10/J10) -> 28.2 | R10: =SUM(G10/J10) -> 18.8 | S10: =SUM(L10/J10) -> -902.4 | T10: 稳定在前20名 | U10: 稳定在前7500名
A11: 第三阶段 | B11: 第9周 | C11: 54.99 | D11: 0.4 | E11: 0.15 | F11: =SUM(C11*(1-D11-E11)) -> 24.7455 | G11: 195 | H11: 195 | I11: =SUM(G11:H11) -> 390 | J11: 7 | K11: =CPC表格!V12 -> 26.666667 | L11: =SUM(H11*-K11) -> -5200 | M11: =毛利表格!T11 -> -1527.1765 | N11: =SUM(L11:M11) -> -6727.1765 | O11: 450 | P11: =SUM(I11/J11) -> 55.714286 | Q11: =SUM(H11/J11) -> 27.857143 | R11: =SUM(G11/J11) -> 27.857143 | S11: =SUM(L11/J11) -> -742.85714 | T11: 稳定在前20名 | U11: 稳定在前7500名 | V11: 第三个月 | W11: 上个月亏损/美金 | X11: 累计亏损/美金 | Y11: 人民币
B12: 第10周 | C12: 54.99 | D12: 0.4 | E12: 0.15 | F12: =SUM(C12*(1-D12-E12)) -> 24.7455 | G12: 248 | H12: 247 | I12: =SUM(G12:H12) -> 495 | J12: 7 | K12: =CPC表格!V13 -> 26.666667 | L12: =SUM(H12*-K12) -> -6586.6667 | M12: =毛利表格!T12 -> -1938.3394 | N12: =SUM(L12:M12) -> -8525.006 | P12: =SUM(I12/J12) -> 70.714286 | Q12: =SUM(H12/J12) -> 35.285714 | R12: =SUM(G12/J12) -> 35.428571 | S12: =SUM(L12/J12) -> -940.95238 | T12: 稳定在前20名 | U12: 稳定在前7500名 | W12: =X8 -> -44712.41 | X12: =W12+SUM(N11:N14) -> -79598.548 | Y12: =X12*7 -> -557189.83
B13: 第11周 | C13: 54.99 | D13: 0.4 | E13: 0.15 | F13: =SUM(C13*(1-D13-E13)) -> 24.7455 | G13: 270 | H13: 270 | I13: =SUM(G13:H13) -> 540 | J13: 7 | K13: =CPC表格!V14 -> 23.333333 | L13: =SUM(H13*-K13) -> -6300 | M13: =毛利表格!T13 -> -2114.552 | N13: =SUM(L13:M13) -> -8414.552 | P13: =SUM(I13/J13) -> 77.142857 | Q13: =SUM(H13/J13) -> 38.571429 | R13: =SUM(G13/J13) -> 38.571429 | S13: =SUM(L13/J13) -> -900 | T13: 稳定在前15名 | U13: 稳定在前5000名
B14: 第12周 | C14: 54.99 | D14: 0.4 | E14: 0.15 | F14: =SUM(C14*(1-D14-E14)) -> 24.7455 | G14: 360 | H14: 360 | I14: =SUM(G14:H14) -> 720 | J14: 9 | K14: =CPC表格!V15 -> 23.333333 | L14: =SUM(H14*-K14) -> -8400 | M14: =毛利表格!T14 -> -2819.4027 | N14: =SUM(L14:M14) -> -11219.403 | P14: =SUM(I14/J14) -> 80 | Q14: =SUM(H14/J14) -> 40 | R14: =SUM(G14/J14) -> 40 | S14: =SUM(L14/J14) -> -933.33333 | T14: 稳定在前15名 | U14: 稳定在前5000名
A15: 第四阶段 | B15: 第13周 | C15: 49.99 | D15: 0.35 | E15: 0 | F15: =SUM(C15*(1-D15-E15)) -> 32.4935 | G15: 420 | H15: 280 | I15: =SUM(G15:H15) -> 700 | J15: 7 | K15: =CPC表格!V16 -> 18.181818 | L15: =SUM(H15*-K15) -> -5090.9091 | M15: =毛利表格!T15 -> 1867.8421 | N15: =SUM(L15:M15) -> -3223.0669 | O15: 600 | P15: =SUM(I15/J15) -> 100 | Q15: =SUM(H15/J15) -> 40 | R15: =SUM(G15/J15) -> 60 | S15: =SUM(L15/J15) -> -727.27273 | T15: 稳定在前12名 | U15: 稳定在前4000名 | V15: 第四个月 | W15: 上个月亏损/美金 | X15: 累计亏损/美金 | Y15: 人民币
B16: 第14周 | C16: 49.99 | D16: 0.35 | E16: 0 | F16: =SUM(C16*(1-D16-E16)) -> 32.4935 | G16: 420 | H16: 280 | I16: =SUM(G16:H16) -> 700 | J16: 7 | K16: =CPC表格!V17 -> 18.181818 | L16: =SUM(H16*-K16) -> -5090.9091 | M16: =毛利表格!T16 -> 1867.8421 | N16: =SUM(L16:M16) -> -3223.0669 | P16: =SUM(I16/J16) -> 100 | Q16: =SUM(H16/J16) -> 40 | R16: =SUM(G16/J16) -> 60 | S16: =SUM(L16/J16) -> -727.27273 | T16: 稳定在前12名 | U16: 稳定在前4000名 | W16: =X12 -> -79598.548 | X16: =W16+SUM(N15:N18) -> -93872.13 | Y16: =X16*7 -> -657104.91
B17: 第15周 | C17: 49.99 | D17: 0.35 | E17: 0 | F17: =SUM(C17*(1-D17-E17)) -> 32.4935 | G17: 420 | H17: 280 | I17: =SUM(G17:H17) -> 700 | J17: 7 | K17: =CPC表格!V18 -> 18.181818 | L17: =SUM(H17*-K17) -> -5090.9091 | M17: =毛利表格!T17 -> 1867.8421 | N17: =SUM(L17:M17) -> -3223.0669 | P17: =SUM(I17/J17) -> 100 | Q17: =SUM(H17/J17) -> 40 | R17: =SUM(G17/J17) -> 60 | S17: =SUM(L17/J17) -> -727.27273 | T17: 稳定在前10名 | U17: 稳定在前3000名
B18: 第16周 | C18: 49.99 | D18: 0.35 | E18: 0 | F18: =SUM(C18*(1-D18-E18)) -> 32.4935 | G18: 600 | H18: 400 | I18: =SUM(G18:H18) -> 1000 | J18: 10 | K18: =CPC表格!V19 -> 18.181818 | L18: =SUM(H18*-K18) -> -7272.7273 | M18: =毛利表格!T18 -> 2668.3459 | N18: =SUM(L18:M18) -> -4604.3814 | P18: =SUM(I18/J18) -> 100 | Q18: =SUM(H18/J18) -> 40 | R18: =SUM(G18/J18) -> 60 | S18: =SUM(L18/J18) -> -727.27273 | T18: 稳定在前10名 | U18: 稳定在前3000名
A19: 第五阶段 | B19: 第17周 | C19: 49.99 | D19: 0.25 | E19: 0 | F19: =SUM(C19*(1-D19-E19)) -> 37.4925 | G19: 567 | H19: 243 | I19: =SUM(G19:H19) -> 810 | J19: 7 | K19: =CPC表格!V20 -> 15 | L19: =SUM(H19*-K19) -> -3645 | M19: =毛利表格!T19 -> 5602.3266 | N19: =SUM(L19:M19) -> 1957.3266 | O19: 750 | P19: =SUM(I19/J19) -> 115.71429 | Q19: =SUM(H19/J19) -> 34.714286 | R19: =SUM(G19/J19) -> 81 | S19: =SUM(L19/J19) -> -520.71429 | T19: 稳定在前10名 | U19: 稳定在前3000名 | V19: 第五个月 | W19: 上个月亏损/美金 | X19: 累计亏损/美金 | Y19: 人民币
B20: 第18周 | C20: 49.99 | D20: 0.25 | E20: 0 | F20: =SUM(C20*(1-D20-E20)) -> 37.4925 | G20: 588 | H20: 252 | I20: =SUM(G20:H20) -> 840 | J20: 7 | K20: =CPC表格!V21 -> 15 | L20: =SUM(H20*-K20) -> -3780 | M20: =毛利表格!T20 -> 5809.8202 | N20: =SUM(L20:M20) -> 2029.8202 | P20: =SUM(I20/J20) -> 120 | Q20: =SUM(H20/J20) -> 36 | R20: =SUM(G20/J20) -> 84 | S20: =SUM(L20/J20) -> -540 | T20: 稳定在前8名 | U20: 稳定在前2500名 | W20: =X16 -> -93872.13 | X20: =W20+SUM(N19:N22) -> -84157.99 | Y20: =X20*7 -> -589105.93
B21: 第19周 | C21: 49.99 | D21: 0.25 | E21: 0 | F21: =SUM(C21*(1-D21-E21)) -> 37.4925 | G21: 714 | H21: 306 | I21: =SUM(G21:H21) -> 1020 | J21: 7 | K21: =CPC表格!V22 -> 15 | L21: =SUM(H21*-K21) -> -4590 | M21: =毛利表格!T21 -> 7054.7817 | N21: =SUM(L21:M21) -> 2464.7817 | P21: =SUM(I21/J21) -> 145.71429 | Q21: =SUM(H21/J21) -> 43.714286 | R21: =SUM(G21/J21) -> 102 | S21: =SUM(L21/J21) -> -655.71429 | T21: 稳定在前5名 | U21: 稳定在前1500名
B22: 第20周 | C22: 49.99 | D22: 0.25 | E22: 0 | F22: =SUM(C22*(1-D22-E22)) -> 37.4925 | G22: 945 | H22: 405 | I22: =SUM(G22:H22) -> 1350 | J22: 9 | K22: =CPC表格!V23 -> 15 | L22: =SUM(H22*-K22) -> -6075 | M22: =毛利表格!T22 -> 9337.2111 | N22: =SUM(L22:M22) -> 3262.2111 | P22: =SUM(I22/J22) -> 150 | Q22: =SUM(H22/J22) -> 45 | R22: =SUM(G22/J22) -> 105 | S22: =SUM(L22/J22) -> -675 | T22: 稳定在前5名 | U22: 稳定在前1500名
A23: 第六阶段 | B23: 第21周 | C23: 36.99 | D23: 0 | E23: 0 | F23: =SUM(C23*(1-D23-E23)) -> 36.99 | G23: 840 | H23: 210 | I23: =SUM(G23:H23) -> 1050 | J23: 7 | K23: =CPC表格!V24 -> 13.333333 | L23: =SUM(H23*-K23) -> -2800 | M23: =毛利表格!T23 -> 7443.9041 | N23: =SUM(L23:M23) -> 4643.9041 | O23: 900 | P23: =SUM(I23/J23) -> 150 | Q23: =SUM(H23/J23) -> 30 | R23: =SUM(G23/J23) -> 120 | S23: =SUM(L23/J23) -> -400 | T23: 稳定在前5名 | U23: 稳定在前1500名 | V23: 第六个月 | W23: 上个月亏损/美金 | X23: 累计亏损/美金 | Y23: 人民币
B24: 第22周 | C24: 36.99 | D24: 0 | E24: 0 | F24: =SUM(C24*(1-D24-E24)) -> 36.99 | G24: 840 | H24: 210 | I24: =SUM(G24:H24) -> 1050 | J24: 7 | K24: =CPC表格!V25 -> 13.333333 | L24: =SUM(H24*-K24) -> -2800 | M24: =毛利表格!T24 -> 7443.9041 | N24: =SUM(L24:M24) -> 4643.9041 | P24: =SUM(I24/J24) -> 150 | Q24: =SUM(H24/J24) -> 30 | R24: =SUM(G24/J24) -> 120 | S24: =SUM(L24/J24) -> -400 | T24: 稳定在前5名 | U24: 稳定在前1500名 | W24: =X20 -> -84157.99 | X24: =W24+SUM(N23:N26) -> -63592.129 | Y24: =X24*7 -> -445144.9
B25: 第23周 | C25: 36.99 | D25: 0 | E25: 0 | F25: =SUM(C25*(1-D25-E25)) -> 36.99 | G25: 840 | H25: 210 | I25: =SUM(G25:H25) -> 1050 | J25: 7 | K25: =CPC表格!V26 -> 13.333333 | L25: =SUM(H25*-K25) -> -2800 | M25: =毛利表格!T25 -> 7443.9041 | N25: =SUM(L25:M25) -> 4643.9041 | P25: =SUM(I25/J25) -> 150 | Q25: =SUM(H25/J25) -> 30 | R25: =SUM(G25/J25) -> 120 | S25: =SUM(L25/J25) -> -400 | T25: 稳定在前5名 | U25: 稳定在前1500名 | W25: 第5个月开始挣钱，第9个月回本
B26: 第24周 | C26: 36.99 | D26: 0 | E26: 0 | F26: =SUM(C26*(1-D26-E26)) -> 36.99 | G26: 1200 | H26: 300 | I26: =SUM(G26:H26) -> 1500 | J26: 10 | K26: =CPC表格!V27 -> 13.333333 | L26: =SUM(H26*-K26) -> -4000 | M26: =毛利表格!T26 -> 10634.149 | N26: =SUM(L26:M26) -> 6634.1488 | P26: =SUM(I26/J26) -> 150 | Q26: =SUM(H26/J26) -> 30 | R26: =SUM(G26/J26) -> 120 | S26: =SUM(L26/J26) -> -400 | T26: 稳定在前5名 | U26: 稳定在前1500名

Sheet 价格策略模拟
A1: 产品名 | B1: 推品时间 | C1: 订单类型 | D1: 定价 | E1: 会员折扣/7天秒杀 | F1: coupon/code/LD | G1: 折扣价 | H1: FBA配送费 | I1: 佣金 | J1: 每单账号回款 | K1: 仓储费 | L1: coupon费用 | M1: 产品成本 | N1: 海运费 | O1: 退货成本 | P1: 退货率 | Q1: 每单平摊 退货成本 | R1: 每单毛利 (不含广告） | S1: 毛利率 （最高ACOS) | T1: 广告占比 | U1: 广告花费 | V1: 广告花费占比 | W1: 毛利盈亏 （包含广告） | X1: 毛利盈亏 （包含广告）
B2: 定价表 | C2: 正常价 | D2: 54.99 | E2: 0 | F2: 0.4 | G2: =(D2*(1-E2))*(1-F2) -> 32.994 | H2: 7.86 | I2: =G2*0.15 -> 4.9491 | J2: =G2-H2-I2 -> 20.1849 | K2: 0.3 | L2: 0.6 | M2: 10 | N2: 4 | O2: =M2+N2+I2*20%+H2+L2+K2 -> 23.74982 | P2: 0.08 | Q2: =O2*P2 -> 1.8999856 | R2: =G2-H2-I2-K2-L2-M2-N2-Q2 -> 3.3849144 | S2: =R2/G2 -> 0.10259182 | T2: 0.05 | U2: =T2*G2 -> 1.6497 | V2: =U2/G2 -> 0.05 | W2: =R2-U2 -> 1.7352144 | X2: =W2/G2 -> 0.052591817
C3: 秒杀价 | D3: 54.99 | E3: 0.15 | F3: 0.4 | G3: =D3-(D3*E3)-(D3*F3) -> 24.7455 | H3: 7.86 | I3: =G3*0.15 -> 3.711825 | J3: =G3-H3-I3 -> 13.173675 | K3: 0.3 | L3: 0.6 | M3: 10 | N3: 4 | O3: =M3+N3+I3*20%+H3+L3+K3 -> 23.502365 | P3: 0.08 | Q3: =O3*P3 -> 1.8801892 | R3: =G3-H3-I3-K3-L3-M3-N3-Q3 -> -3.6065142 | S3: =R3/G3 -> -0.14574424 | T3: 0.05 | U3: =T3*G3 -> 1.237275 | V3: =U3/G3 -> 0.05 | W3: =R3-U3 -> -4.8437892 | X3: =W3/G3 -> -0.19574424
C4: 平本价 | D4: 54.99 | E4: 0 | F4: 0.5 | G4: =D4-(D4*E4)-(D4*F4) -> 27.495 | H4: 7.86 | I4: =G4*0.15 -> 4.12425 | J4: =G4-H4-I4 -> 15.51075 | K4: 0.3 | L4: 0.6 | M4: 10 | N4: 4 | O4: =M4+N4+I4*20%+H4+L4+K4 -> 23.58485 | P4: 0.08 | Q4: =O4*P4 -> 1.886788 | R4: =G4-H4-I4-K4-L4-M4-N4-Q4 -> -1.276038 | S4: =R4/G4 -> -0.04640982 | T4: 0 | U4: =T4*G4 -> 0 | V4: =U4/G4 -> 0 | W4: =R4-U4 -> -1.276038 | X4: =W4/G4 -> -0.04640982
A6: 阶段 | B6: 定价 | C6: coupon | D6: code/JP | E6: 折后价 | F6: FBA 配送费 | G6: 亚马逊 佣金 | H6: 账号 回款 | I6: 仓储费+入库配置费 | J6: coupon 费用 | K6: 产品 成本 | L6: 物流费 | M6: 退货成本(公式后面加的是单套产品的移除费） | N6: 退货率 | O6: 每单平摊 退货成本 | P6: 每单 毛利 | Q6: 毛利率 | R6: 订单 数量 | S6: 阶段 订单 亏损 | T6: 阶段 订单 总盈亏
A7: 第一阶段 | B7: 54.99 | C7: 0.3 | D7: 0.1 | E7: =SUM(B7*(1-C7-D7)) -> 32.994 | F7: 7.86 | G7: =SUM(E7*15%) -> 4.9491 | H7: =SUM(E7-F7-G7) -> 20.1849 | I7: =0.08+0.34 -> 0.42 | J7: 0.6 | K7: 10 | L7: 4 | M7: =SUM(20%*N7*G7+F7+I7+K7+L7+1.46) -> 23.819186 | N7: 0.08 | O7: =SUM(M7*N7/(1-N7)) -> 2.0712335 | P7: =SUM(H7-I7-J7-K7-L7-O7) -> 3.0936665 | Q7: =SUM(P7/B7) -> 0.05625871 | R7: 1 | S7: =SUM(P7*R7) -> 3.0936665 | T7: =SUM(S7:S7) -> 3.0936665
A8: 第二阶段 | B8: 54.99 | C8: 0.4 | D8: 0.1 | E8: =SUM(B8*(1-C8-D8)) -> 27.495 | F8: 7.86 | G8: =SUM(E8*15%) -> 4.12425 | H8: =SUM(E8-F8-G8) -> 15.51075 | I8: =0.08+0.34 -> 0.42 | J8: 0.6 | K8: 10 | L8: 4 | M8: =SUM(20%*N8*G8+F8+I8+K8+L8+1.46) -> 23.805988 | N8: 0.08 | O8: =SUM(M8*N8/(1-N8)) -> 2.0700859 | P8: =SUM(H8-I8-J8-K8-L8-O8) -> -1.5793359 | Q8: =SUM(P8/B8) -> -0.02872042 | R8: 1 | S8: =SUM(P8*R8) -> -1.5793359 | T8: =SUM(S8:S8) -> -1.5793359
A9: 第三阶段 | B9: 54.99 | C9: 0.4 | D9: 0.15 | E9: =SUM(B9*(1-C9-D9)) -> 24.7455 | F9: 7.86 | G9: =SUM(E9*15%) -> 3.711825 | H9: =SUM(E9-F9-G9) -> 13.173675 | I9: =0.08+0.34 -> 0.42 | J9: 0.6 | K9: 10 | L9: 4 | M9: =SUM(20%*N9*G9+F9+I9+K9+L9+1.46) -> 23.799389 | N9: 0.08 | O9: =SUM(M9*N9/(1-N9)) -> 2.0695121 | P9: =SUM(H9-I9-J9-K9-L9-O9) -> -3.9158371 | Q9: =SUM(P9/B9) -> -0.071209986 | R9: 1 | S9: =SUM(P9*R9) -> -3.9158371 | T9: =SUM(S9:S9) -> -3.9158371
A10: 第四阶段 | B10: 49.99 | C10: 0.35 | D10: 0 | E10: =SUM(B10*(1-C10-D10)) -> 32.4935 | F10: 7.86 | G10: =SUM(E10*15%) -> 4.874025 | H10: =SUM(E10-F10-G10) -> 19.759475 | I10: =0.08+0.34 -> 0.42 | J10: 0.6 | K10: 10 | L10: 4 | M10: =SUM(20%*N10*G10+F10+I10+K10+L10+1.46) -> 23.817984 | N10: 0.08 | O10: =SUM(M10*N10/(1-N10)) -> 2.0711291 | P10: =SUM(H10-I10-J10-K10-L10-O10) -> 2.6683459 | Q10: =SUM(P10/B10) -> 0.053377594 | R10: 1 | S10: =SUM(P10*R10) -> 2.6683459 | T10: =SUM(S10:S10) -> 2.6683459
A11: 第五阶段 | B11: 49.99 | C11: 0.25 | D11: 0 | E11: =SUM(B11*(1-C11-D11)) -> 37.4925 | F11: 7.86 | G11: =SUM(E11*15%) -> 5.623875 | H11: =SUM(E11-F11-G11) -> 24.008625 | I11: =0.08+0.34 -> 0.42 | J11: 0.6 | K11: 10 | L11: 4 | M11: =SUM(20%*N11*G11+F11+I11+K11+L11+1.46) -> 23.829982 | N11: 0.08 | O11: =SUM(M11*N11/(1-N11)) -> 2.0721723 | P11: =SUM(H11-I11-J11-K11-L11-O11) -> 6.9164527 | Q11: =SUM(P11/B11) -> 0.13835672 | R11: 1 | S11: =SUM(P11*R11) -> 6.9164527 | T11: =SUM(S11:S11) -> 6.9164527
A12: 第六阶段 | B12: 36.99 | C12: 0 | D12: 0 | E12: =SUM(B12*(1-C12-D12)) -> 36.99 | F12: 7.86 | G12: =SUM(E12*15%) -> 5.5485 | H12: =SUM(E12-F12-G12) -> 23.5815 | I12: =0.08+0.34 -> 0.42 | J12: 0 | K12: 10 | L12: 4 | M12: =SUM(20%*N12*G12+F12+I12+K12+L12+1.46) -> 23.828776 | N12: 0.08 | O12: =SUM(M12*N12/(1-N12)) -> 2.0720675 | P12: =SUM(H12-I12-J12-K12-L12-O12) -> 7.0894325 | Q12: =SUM(P12/B12) -> 0.19165808 | R12: 1 | S12: =SUM(P12*R12) -> 7.0894325 | T12: =SUM(S12:S12) -> 7.0894325
A15: 竞品日常价格 | B15: 65.51 | C15: 0.1 | D15: 0.23 | E15: 44.97 | F15: 7.86 | G15: =SUM(E15*15%) -> 6.7455 | H15: =SUM(E15-F15-G15) -> 30.3645 | I15: =0.08+0.34 -> 0.42 | J15: 0 | K15: 40 | L15: 3 | M15: =SUM(20%*N15*G15+F15+I15+K15+L15+1.46) -> 52.942365 | N15: 0.15 | O15: =SUM(M15*N15/(1-N15)) -> 9.3427703 | P15: =SUM(H15-I15-J15-K15-L15-O15) -> -22.39827 | Q15: =SUM(P15/B15) -> -0.34190613 | R15: 1 | S15: =SUM(P15*R15) -> -22.39827 | T15: =SUM(S15:S15) -> -22.39827
A16: 竞品活动价格 | B16: 49.98 | C16: 0 | D16: 0 | E16: =SUM(B16*(1-C16-D16)) -> 49.98 | F16: 7.86 | G16: =SUM(E16*15%) -> 7.497 | H16: =SUM(E16-F16-G16) -> 34.623 | I16: =0.08+0.34 -> 0.42 | J16: 0 | K16: 40 | L16: 3 | M16: =SUM(20%*N16*G16+F16+I16+K16+L16+1.46) -> 52.96491 | N16: 0.15 | O16: =SUM(M16*N16/(1-N16)) -> 9.3467488 | P16: =SUM(H16-I16-J16-K16-L16-O16) -> -18.143749 | Q16: =SUM(P16/B16) -> -0.36302018 | R16: 1 | S16: =SUM(P16*R16) -> -18.143749 | T16: =SUM(S16:S16) -> -18.143749
A17: 竞品链接 | B17: https://www.amazon.com/WEWE-Brushed-Kitchen-Stainless-Faucets/dp/B01H3OMH7Y
A20: 0013厨房水龙头（带广告） | F20: 0013厨房水龙头（带广告）
K21: 0013厨房水龙头（无广告） | P21: 0013厨房水龙头（无广告）
A22: 成本价 | C22: 70 | D22: =C22/C24 -> 10 | F22: 成本价 | H22: 70
A23: 头程费用 | C23: 28 | F23: 头程费用 | H23: 28 | K23: 成本价 | M23: 70 | P23: 成本价 | R23: 70
A24: 汇率 | C24: 7 | F24: 汇率 | H24: 7 | K24: 头程费用 | M24: 28 | P24: 头程费用 | R24: 28
A25: 佣金比例 | C25: 0.15 | D25: 0.15 | F25: 佣金比例 | H25: 0.15 | I25: 0.15 | K25: 汇率 | M25: 7 | P25: 汇率 | R25: 7
A26: FBA配送费 | C26: 7.86 | F26: FBA配送费 | H26: 7.86 | K26: 佣金比例 | M26: 0.15 | P26: 佣金比例 | R26: 0.15
A27: 退货率（8%） | C27: =C33*0.08 -> 3.9992 | D27: 0.08 | F27: 退货率（8%） | H27: =H33*0.08 -> 2.6392 | I27: 0.15 | K27: FBA配送费 | M27: 7.86 | P27: FBA配送费 | R27: 7.86
A28: 广告成本 | C28: =C33*D28 -> 7.4985 | D28: 0.15 | F28: 广告成本 | H28: =H33*I28 -> 4.9485 | I28: 0.15 | K28: 退货率（8%） | M28: =M34*0.08 -> 4.3992 | P28: 退货率（8%） | R28: =R34*0.08 -> 3.9992
A29: 仓储成本 | C29: 0.3 | F29: 仓储成本 | H29: 0.3 | K29: 广告成本 | M29: =M34*N29 -> 0 | P29: 广告成本 | R29: =R34*S29 -> 0
A30: 促销成本 （34%领取率） | C30: 0.6 | F30: 促销成本 （34%领取率） | H30: 0.6 | K30: 仓储成本 | M30: 0.3 | P30: 仓储成本 | R30: 0.3
A31: 配置费 | C31: 0.3 | F31: 配置费 | H31: 0.3 | K31: 促销成本 （34%领取率） | M31: 0.6 | P31: 促销成本 （34%领取率） | R31: 0.6
A32: 最低售价 | C32: 49.99 | F32: 最低售价 | H32: 32.99 | K32: 配置费 | M32: 0.3 | P32: 配置费 | R32: 0.3
A33: 平均售价 | C33: 49.99 | F33: 平均售价 | H33: 32.99 | K33: 最低售价 | M33: 54.99 | P33: 最低售价 | R33: 49.99
A34: 利润 | C34: =(C33-C26-C27-C28-C29-C30-C31-C33*C25)*C24-C23-C22 -> 55.5366 | F34: 利润 | H34: =(H33-H26-H27-H28-H29-H30-H31-H33*H25)*H24-H23-H22 -> -18.2434 | K34: 平均售价 | M34: 54.99 | P34: 平均售价 | R34: 49.99
A35: 利润率 | C35: =C34/(C33*C24) -> 0.15870774 | F35: 利润率 | H35: =H34/(H33*H24) -> -0.078999697 | K35: 利润 | M35: =(M34-M27-M28-M29-M30-M31-M32-M34*M26)*M25-M24-M23 -> 134.9761 | P35: 利润 | R35: =(R34-R27-R28-R29-R30-R31-R32-R34*R26)*R25-R24-R23 -> 108.0261
A36: 盈亏平衡 | C36: =(C22+C23)/C24+C33*C25+C26+C29+C31 -> 29.9585 | F36: 盈亏平衡 | H36: =(H22+H23)/H24+H33*H25+H26+H29+H31 -> 27.4085 | K36: 利润率 | M36: =M35/(M34*M25) -> 0.35065103 | P36: 利润率 | R36: =R35/(R34*R25) -> 0.30870774
A37: 盈亏平衡 （头尾程+成本+佣金） | C37: =(C22+C23)/C24+C33*C25+C26 -> 29.3585 | F37: 盈亏平衡 （头尾程+成本+佣金） | H37: =(H22+H23)/H24+H33*H25+H26 -> 26.8085 | K37: 盈亏平衡 | M37: =(M23+M24)/M25+M34*M26+M27+M30+M32 -> 30.7085 | P37: 盈亏平衡 | R37: =(R23+R24)/R25+R34*R26+R27+R30+R32 -> 29.9585
K38: 盈亏平衡 （头尾程+成本+佣金） | M38: =(M23+M24)/M25+M34*M26+M27 -> 30.1085 | P38: 盈亏平衡 （头尾程+成本+佣金） | R38: =(R23+R24)/R25+R34*R26+R27 -> 29.3585
F40: 产品交期 | G40: 35天 | H40: 前期时间
A41: 广告占比10-15% | F41: 海运时间 | G41: 45天 | H41: 75天-90天 (保守得下这么多天的量)
A42: 淋浴类利润率在10%以上 | F42: 上架时间（旺季） | G42: 5天

Sheet 毛利表格
A1: 每日盈亏数据预估
A2: 阶段 | B2: 日期 | C2: 定价 | D2: coupon | E2: code | F2: 折后价 | G2: FBA 配送费 | H2: 亚马逊 佣金 | I2: 账号 回款 | J2: 仓储费+入库配置费 | K2: coupon 费用 | L2: 产品 成本 | M2: 物流费 | N2: 退货成本(公式后面加的是单套产品的移除费） | O2: 退货率 | P2: 每单平摊 退货成本 | Q2: 每单 毛利 | R2: 毛利率 | S2: 订单 数量 | T2: 阶段 订单 亏损 | U2: 阶段 订单 总盈亏
A3: 第一阶段 | B3: 第1周 | C3: 54.99 | D3: 0.3 | E3: 0.1 | F3: =SUM(C3*(1-D3-E3)) -> 32.994 | G3: 7.86 | H3: =SUM(F3*15%) -> 4.9491 | I3: =SUM(F3-G3-H3) -> 20.1849 | J3: =0.08+0.34 -> 0.42 | K3: 0.6 | L3: 10 | M3: 4 | N3: =SUM(20%*O3*H3+G3+J3+L3+M3+1.46) -> 23.819186 | O3: 0.08 | P3: =SUM(N3*O3/(1-O3)) -> 2.0712335 | Q3: =SUM(I3-J3-K3-L3-M3-P3) -> 3.0936665 | R3: =SUM(Q3/C3) -> 0.05625871 | S3: =阶段盈亏!I3 -> 29 | T3: =SUM(Q3*S3) -> 89.716328 | U3: =SUM(T3:T3) -> 89.716328
